File: log/20221016.dat
[Header]
; Displex Transport Data File (default extension .dat)
; Copyright 2016, Hechang LEI, hlei@ruc.edu.cn. All rights reserved.
BYAPP, Displex, 2.0
INFO, 9T mag, Release 2.0.
INFO, Channel 1, Temperature Sensor
INFO, Sample 1 Length (cm): 0.000000; Width (cm): 0.000000; Thickness (cm): 0.000000.

[Data]
Timestamp(s),Field(Oe),Field Status,TempA(K),TempB(K),TempC(K),TempD(K),Ramp1,Ramp2,Setpoint1,Setpoint2,Output1(%),Output2(%),Temp Status
3748740486.327000,0.000,Standby,300.001,300.000,0.000,0.000,0,0,300.000,300.000,1,0,1
3748740636.327000,0.000,Standby,300.000,299.998,0.000,0.000,0,0,300.000,300.000,1,0,1
3748740786.327000,0.000,Standby,299.999,299.998,0.000,0.000,0,0,300.000,300.000,1,0,1
3748740991.301000,0.000,Standby,300.002,300.000,0.000,0.000,0,0,300.000,300.000,1,0,1
3748741267.034000,0.000,5000k,300.000,300.000,0.000,0.000,0,0,300.000,300.000,1,0,4
3748741959.718000,GPIB0::1::INSTR,Standby,300.002,300.001,0.000,0.000,0,0,300.000,300.000,1,0,1
3748742109.718000,GPIB0::1::INSTR,Standby,300.002,300.000,0.000,0.000,0,0,300.000,300.000,1,0,1
3748742259.718000,GPIB0::1::INSTR,Standby,300.001,299.999,0.000,0.000,0,0,300.000,300.000,1,0,1
3748742409.718000,GPIB0::1::INSTR,Standby,300.003,300.000,0.000,0.000,0,0,300.000,300.000,1,0,1
3748742559.718000,GPIB0::1::INSTR,Standby,300.002,299.999,0.000,0.000,0,0,300.000,300.000,1,0,1
3748742709.718000,GPIB0::1::INSTR,Standby,300.003,299.999,0.000,0.000,0,0,300.000,300.000,1,0,1
3748742859.718000,GPIB0::1::INSTR,Standby,300.000,300.000,0.000,0.000,0,0,300.000,300.000,1,0,1
3748743009.718000,GPIB0::1::INSTR,Standby,300.001,299.999,0.000,0.000,0,0,300.000,300.000,1,0,1
3748743159.718000,GPIB0::1::INSTR,Standby,299.999,299.998,0.000,0.000,0,0,300.000,300.000,1,0,1
3748743309.718000,GPIB0::1::INSTR,Standby,300.000,299.999,0.000,0.000,0,0,300.000,300.000,1,0,1
3748743459.718000,GPIB0::1::INSTR,Standby,300.002,300.000,0.000,0.000,0,0,300.000,300.000,1,0,1
3748743609.718000,GPIB0::1::INSTR,Standby,300.001,300.000,0.000,0.000,0,0,300.000,300.000,1,0,1
3748743759.718000,GPIB0::1::INSTR,Standby,300.002,300.001,0.000,0.000,0,0,300.000,300.000,1,0,1
3748743909.718000,GPIB0::1::INSTR,Standby,300.000,300.001,0.000,0.000,0,0,300.000,300.000,1,0,1
3748744059.718000,GPIB0::1::INSTR,Standby,300.000,299.999,0.000,0.000,0,0,300.000,300.000,1,0,1
3748744209.718000,GPIB0::1::INSTR,Standby,300.002,300.001,0.000,0.000,0,0,300.000,300.000,1,0,1
3748744359.718000,GPIB0::1::INSTR,Standby,300.001,300.001,0.000,0.000,0,0,300.000,300.000,1,0,1
3748744509.718000,GPIB0::1::INSTR,Standby,300.001,299.999,0.000,0.000,0,0,300.000,300.000,1,0,1
3748744659.718000,GPIB0::1::INSTR,Standby,300.002,299.998,0.000,0.000,0,0,300.000,300.000,1,0,1
3748744809.718000,GPIB0::1::INSTR,Standby,300.001,300.000,0.000,0.000,0,0,300.000,300.000,1,0,1
3748744959.718000,GPIB0::1::INSTR,Standby,300.001,300.000,0.000,0.000,0,0,300.000,300.000,1,0,1
3748745109.718000,GPIB0::1::INSTR,Standby,300.001,300.000,0.000,0.000,0,0,300.000,300.000,1,0,1
3748745259.718000,GPIB0::1::INSTR,Standby,300.001,300.000,0.000,0.000,0,0,300.000,300.000,1,0,1
3748745409.718000,GPIB0::1::INSTR,Standby,300.003,300.000,0.000,0.000,0,0,300.000,300.000,1,0,1
3748745559.718000,GPIB0::1::INSTR,Standby,300.001,300.000,0.000,0.000,0,0,300.000,300.000,1,0,1
3748745709.718000,GPIB0::1::INSTR,Standby,300.000,299.998,0.000,0.000,0,0,300.000,300.000,1,0,1
3748745859.718000,GPIB0::1::INSTR,Standby,300.001,299.998,0.000,0.000,0,0,300.000,300.000,1,0,1
3748746009.718000,GPIB0::1::INSTR,Standby,300.001,299.999,0.000,0.000,0,0,300.000,300.000,1,0,1
3748746159.718000,GPIB0::1::INSTR,Standby,300.003,300.000,0.000,0.000,0,0,300.000,300.000,1,0,1
3748746309.718000,GPIB0::1::INSTR,Standby,300.003,299.998,0.000,0.000,0,0,300.000,300.000,1,0,1
3748746459.718000,GPIB0::1::INSTR,Standby,300.001,299.998,0.000,0.000,0,0,300.000,300.000,1,0,1
3748746609.718000,GPIB0::1::INSTR,Standby,300.002,300.001,0.000,0.000,0,0,300.000,300.000,1,0,1
3748746759.718000,GPIB0::1::INSTR,Standby,300.001,299.999,0.000,0.000,0,0,300.000,300.000,1,0,1
3748746909.718000,GPIB0::1::INSTR,Standby,300.000,300.000,0.000,0.000,0,0,300.000,300.000,1,0,1
3748747059.718000,GPIB0::1::INSTR,Standby,300.001,300.000,0.000,0.000,0,0,300.000,300.000,1,0,1
3748747209.718000,GPIB0::1::INSTR,Standby,300.002,299.999,0.000,0.000,0,0,300.000,300.000,1,0,1
3748747359.718000,GPIB0::1::INSTR,Standby,300.002,300.000,0.000,0.000,0,0,300.000,300.000,1,0,1
3748747509.718000,GPIB0::1::INSTR,Standby,300.001,299.999,0.000,0.000,0,0,300.000,300.000,1,0,1
3748747659.718000,GPIB0::1::INSTR,Standby,300.003,300.000,0.000,0.000,0,0,300.000,300.000,1,0,1
3748747809.718000,GPIB0::1::INSTR,Standby,300.000,299.999,0.000,0.000,0,0,300.000,300.000,1,0,1
3748747959.718000,GPIB0::1::INSTR,Standby,300.003,300.000,0.000,0.000,0,0,300.000,300.000,1,0,1
3748748109.718000,GPIB0::1::INSTR,Standby,300.002,299.998,0.000,0.000,0,0,300.000,300.000,1,0,1
3748748259.718000,GPIB0::1::INSTR,Standby,300.000,299.999,0.000,0.000,0,0,300.000,300.000,1,0,1
3748748409.718000,GPIB0::1::INSTR,Standby,300.002,299.999,0.000,0.000,0,0,300.000,300.000,1,0,1
3748748559.718000,GPIB0::1::INSTR,Standby,300.000,299.999,0.000,0.000,0,0,300.000,300.000,1,0,1
3748748709.718000,GPIB0::1::INSTR,Standby,300.000,299.999,0.000,0.000,0,0,300.000,300.000,1,0,1
3748748859.718000,GPIB0::1::INSTR,Standby,300.001,300.001,0.000,0.000,0,0,300.000,300.000,1,0,1
3748749009.718000,GPIB0::1::INSTR,Standby,300.001,300.000,0.000,0.000,0,0,300.000,300.000,1,0,1
3748749159.718000,GPIB0::1::INSTR,Standby,300.002,299.999,0.000,0.000,0,0,300.000,300.000,1,0,1
3748749309.718000,GPIB0::1::INSTR,Standby,300.001,300.000,0.000,0.000,0,0,300.000,300.000,1,0,1
3748749459.718000,GPIB0::1::INSTR,Standby,300.002,300.000,0.000,0.000,0,0,300.000,300.000,1,0,1
3748749609.718000,GPIB0::1::INSTR,Standby,300.003,299.999,0.000,0.000,0,0,300.000,300.000,1,0,1
3748749759.718000,GPIB0::1::INSTR,Standby,300.002,299.999,0.000,0.000,0,0,300.000,300.000,1,0,1
3748749909.718000,GPIB0::1::INSTR,Standby,300.002,299.998,0.000,0.000,0,0,300.000,300.000,1,0,1
3748750059.718000,GPIB0::1::INSTR,Standby,300.001,300.000,0.000,0.000,0,0,300.000,300.000,1,0,1
3748750209.718000,GPIB0::1::INSTR,Standby,299.999,299.999,0.000,0.000,0,0,300.000,300.000,1,0,1
3748750359.718000,GPIB0::1::INSTR,Standby,299.999,299.998,0.000,0.000,0,0,300.000,300.000,1,0,1
3748750509.718000,GPIB0::1::INSTR,Standby,300.002,300.000,0.000,0.000,0,0,300.000,300.000,1,0,1
3748750659.718000,GPIB0::1::INSTR,Standby,300.000,299.999,0.000,0.000,0,0,300.000,300.000,1,0,1
3748750809.718000,GPIB0::1::INSTR,Standby,300.002,299.999,0.000,0.000,0,0,300.000,300.000,1,0,1
3748750959.718000,GPIB0::1::INSTR,Standby,300.002,300.000,0.000,0.000,0,0,300.000,300.000,1,0,1
3748751109.718000,GPIB0::1::INSTR,Standby,300.002,300.000,0.000,0.000,0,0,300.000,300.000,1,0,1
3748751259.718000,GPIB0::1::INSTR,Standby,300.001,300.000,0.000,0.000,0,0,300.000,300.000,1,0,1
3748751409.718000,GPIB0::1::INSTR,Standby,300.000,300.003,0.000,0.000,0,0,300.000,300.000,1,0,1
3748751559.718000,GPIB0::1::INSTR,Standby,300.001,300.000,0.000,0.000,0,0,300.000,300.000,1,0,1
3748751709.718000,GPIB0::1::INSTR,Standby,300.002,299.998,0.000,0.000,0,0,300.000,300.000,1,0,1
3748751859.718000,GPIB0::1::INSTR,Standby,300.002,300.000,0.000,0.000,0,0,300.000,300.000,1,0,1
3748752009.718000,GPIB0::1::INSTR,Standby,300.001,300.001,0.000,0.000,0,0,300.000,300.000,1,0,1
3748752159.718000,GPIB0::1::INSTR,Standby,300.001,300.000,0.000,0.000,0,0,300.000,300.000,1,0,1
3748752309.718000,GPIB0::1::INSTR,Standby,300.000,300.002,0.000,0.000,0,0,300.000,300.000,1,0,1
3748752459.718000,GPIB0::1::INSTR,Standby,300.000,299.999,0.000,0.000,0,0,300.000,300.000,1,0,1
3748752609.718000,GPIB0::1::INSTR,Standby,300.003,299.999,0.000,0.000,0,0,300.000,300.000,1,0,1
3748752759.718000,GPIB0::1::INSTR,Standby,300.002,299.999,0.000,0.000,0,0,300.000,300.000,1,0,1
3748752909.718000,GPIB0::1::INSTR,Standby,300.003,300.002,0.000,0.000,0,0,300.000,300.000,1,0,1
3748753059.718000,GPIB0::1::INSTR,Standby,300.002,300.000,0.000,0.000,0,0,300.000,300.000,1,0,1
3748753209.718000,GPIB0::1::INSTR,Standby,300.002,299.998,0.000,0.000,0,0,300.000,300.000,1,0,1
3748753359.718000,GPIB0::1::INSTR,Standby,300.000,300.000,0.000,0.000,0,0,300.000,300.000,1,0,1
3748753509.718000,GPIB0::1::INSTR,Standby,300.002,300.000,0.000,0.000,0,0,300.000,300.000,1,0,1
3748753659.718000,GPIB0::1::INSTR,Standby,300.000,299.999,0.000,0.000,0,0,300.000,300.000,1,0,1
3748753809.718000,GPIB0::1::INSTR,Standby,300.000,300.000,0.000,0.000,0,0,300.000,300.000,1,0,1
3748753959.718000,GPIB0::1::INSTR,Standby,300.001,300.001,0.000,0.000,0,0,300.000,300.000,1,0,1
3748754109.718000,GPIB0::1::INSTR,Standby,300.001,300.000,0.000,0.000,0,0,300.000,300.000,1,0,1
3748754259.718000,GPIB0::1::INSTR,Standby,300.002,300.000,0.000,0.000,0,0,300.000,300.000,1,0,1
3748754409.718000,GPIB0::1::INSTR,Standby,299.999,299.999,0.000,0.000,0,0,300.000,300.000,1,0,1
3748754559.718000,GPIB0::1::INSTR,Standby,300.000,300.001,0.000,0.000,0,0,300.000,300.000,1,0,1
3748754709.718000,GPIB0::1::INSTR,Standby,300.002,300.002,0.000,0.000,0,0,300.000,300.000,1,0,1
3748754859.718000,GPIB0::1::INSTR,Standby,300.000,299.999,0.000,0.000,0,0,300.000,300.000,1,0,1
3748755009.718000,GPIB0::1::INSTR,Standby,300.001,300.000,0.000,0.000,0,0,300.000,300.000,1,0,1
3748755159.718000,GPIB0::1::INSTR,Standby,300.002,299.998,0.000,0.000,0,0,300.000,300.000,1,0,1
3748755309.718000,GPIB0::1::INSTR,Standby,299.999,300.001,0.000,0.000,0,0,300.000,300.000,1,0,1
3748755459.718000,GPIB0::1::INSTR,Standby,300.001,299.999,0.000,0.000,0,0,300.000,300.000,1,0,1
3748755609.718000,GPIB0::1::INSTR,Standby,300.001,299.999,0.000,0.000,0,0,300.000,300.000,1,0,1
3748755759.718000,GPIB0::1::INSTR,Standby,300.001,299.998,0.000,0.000,0,0,300.000,300.000,1,0,1
3748755909.718000,GPIB0::1::INSTR,Standby,300.004,300.000,0.000,0.000,0,0,300.000,300.000,1,0,1
3748756059.718000,GPIB0::1::INSTR,Standby,300.003,299.999,0.000,0.000,0,0,300.000,300.000,1,0,1
3748756209.718000,GPIB0::1::INSTR,Standby,299.998,299.999,0.000,0.000,0,0,300.000,300.000,1,0,1
3748756359.718000,GPIB0::1::INSTR,Standby,300.000,300.000,0.000,0.000,0,0,300.000,300.000,1,0,1
3748756509.718000,GPIB0::1::INSTR,Standby,300.000,300.000,0.000,0.000,0,0,300.000,300.000,1,0,1
3748756659.718000,GPIB0::1::INSTR,Standby,300.000,299.999,0.000,0.000,0,0,300.000,300.000,1,0,1
3748756809.718000,GPIB0::1::INSTR,Standby,299.998,300.000,0.000,0.000,0,0,300.000,300.000,1,0,1
3748756959.718000,GPIB0::1::INSTR,Standby,300.000,300.002,0.000,0.000,0,0,300.000,300.000,1,0,1
3748757109.718000,GPIB0::1::INSTR,Standby,300.001,300.001,0.000,0.000,0,0,300.000,300.000,1,0,1
3748757259.718000,GPIB0::1::INSTR,Standby,300.000,300.000,0.000,0.000,0,0,300.000,300.000,1,0,1
3748757409.718000,GPIB0::1::INSTR,Standby,300.001,300.001,0.000,0.000,0,0,300.000,300.000,1,0,1
3748757559.718000,GPIB0::1::INSTR,Standby,300.000,299.999,0.000,0.000,0,0,300.000,300.000,1,0,1
3748757709.718000,GPIB0::1::INSTR,Standby,300.001,300.000,0.000,0.000,0,0,300.000,300.000,1,0,1
3748757859.718000,GPIB0::1::INSTR,Standby,300.002,300.000,0.000,0.000,0,0,300.000,300.000,1,0,1
3748758009.718000,GPIB0::1::INSTR,Standby,299.999,300.000,0.000,0.000,0,0,300.000,300.000,1,0,1
3748758159.718000,GPIB0::1::INSTR,Standby,300.001,300.000,0.000,0.000,0,0,300.000,300.000,1,0,1
3748758309.718000,GPIB0::1::INSTR,Standby,300.001,300.000,0.000,0.000,0,0,300.000,300.000,1,0,1
3748758459.718000,GPIB0::1::INSTR,Standby,299.999,300.000,0.000,0.000,0,0,300.000,300.000,1,0,1
3748758609.718000,GPIB0::1::INSTR,Standby,300.001,300.001,0.000,0.000,0,0,300.000,300.000,1,0,1
3748758759.718000,GPIB0::1::INSTR,Standby,300.001,300.001,0.000,0.000,0,0,300.000,300.000,1,0,1
3748758909.718000,GPIB0::1::INSTR,Standby,300.003,300.000,0.000,0.000,0,0,300.000,300.000,1,0,1
3748759059.718000,GPIB0::1::INSTR,Standby,300.002,300.000,0.000,0.000,0,0,300.000,300.000,1,0,1
3748759209.718000,GPIB0::1::INSTR,Standby,300.001,300.000,0.000,0.000,0,0,300.000,300.000,1,0,1
3748759359.718000,GPIB0::1::INSTR,Standby,300.000,300.000,0.000,0.000,0,0,300.000,300.000,1,0,1
3748759509.718000,GPIB0::1::INSTR,Standby,300.000,299.999,0.000,0.000,0,0,300.000,300.000,1,0,1
3748759659.718000,GPIB0::1::INSTR,Standby,300.000,300.000,0.000,0.000,0,0,300.000,300.000,1,0,1
3748759809.718000,GPIB0::1::INSTR,Standby,300.001,300.000,0.000,0.000,0,0,300.000,300.000,1,0,1
3748759959.718000,GPIB0::1::INSTR,Standby,300.000,299.999,0.000,0.000,0,0,300.000,300.000,1,0,1
3748760109.718000,GPIB0::1::INSTR,Standby,300.002,299.999,0.000,0.000,0,0,300.000,300.000,1,0,1
3748760259.718000,GPIB0::1::INSTR,Standby,299.999,300.000,0.000,0.000,0,0,300.000,300.000,1,0,1
3748760409.718000,GPIB0::1::INSTR,Standby,300.000,300.002,0.000,0.000,0,0,300.000,300.000,1,0,1
3748760559.718000,GPIB0::1::INSTR,Standby,300.001,299.998,0.000,0.000,0,0,300.000,300.000,1,0,1
3748760709.718000,GPIB0::1::INSTR,Standby,300.001,299.999,0.000,0.000,0,0,300.000,300.000,1,0,1
3748760859.718000,GPIB0::1::INSTR,Standby,300.000,300.000,0.000,0.000,0,0,300.000,300.000,1,0,1
3748761009.718000,GPIB0::1::INSTR,Standby,300.000,300.000,0.000,0.000,0,0,300.000,300.000,1,0,1
3748761159.718000,GPIB0::1::INSTR,Standby,300.000,300.001,0.000,0.000,0,0,300.000,300.000,1,0,1
3748761309.718000,GPIB0::1::INSTR,Standby,300.003,300.000,0.000,0.000,0,0,300.000,300.000,1,0,1
3748761459.718000,GPIB0::1::INSTR,Standby,300.001,300.000,0.000,0.000,0,0,300.000,300.000,1,0,1
3748761609.718000,GPIB0::1::INSTR,Standby,300.000,300.000,0.000,0.000,0,0,300.000,300.000,1,0,1
3748761759.718000,GPIB0::1::INSTR,Standby,300.001,300.002,0.000,0.000,0,0,300.000,300.000,1,0,1
3748761909.718000,GPIB0::1::INSTR,Standby,300.002,300.001,0.000,0.000,0,0,300.000,300.000,1,0,1
3748762059.718000,GPIB0::1::INSTR,Standby,300.000,299.999,0.000,0.000,0,0,300.000,300.000,1,0,1
3748762209.718000,GPIB0::1::INSTR,Standby,300.000,300.000,0.000,0.000,0,0,300.000,300.000,1,0,1
3748762359.718000,GPIB0::1::INSTR,Standby,300.002,299.999,0.000,0.000,0,0,300.000,300.000,1,0,1
3748762509.718000,GPIB0::1::INSTR,Standby,300.002,300.000,0.000,0.000,0,0,300.000,300.000,1,0,1
3748762659.718000,GPIB0::1::INSTR,Standby,300.000,299.999,0.000,0.000,0,0,300.000,300.000,1,0,1
3748762809.718000,GPIB0::1::INSTR,Standby,299.999,300.000,0.000,0.000,0,0,300.000,300.000,1,0,1
3748762959.718000,GPIB0::1::INSTR,Standby,300.002,299.998,0.000,0.000,0,0,300.000,300.000,1,0,1
3748763109.718000,GPIB0::1::INSTR,Standby,300.000,300.000,0.000,0.000,0,0,300.000,300.000,1,0,1
3748763259.718000,GPIB0::1::INSTR,Standby,300.002,300.000,0.000,0.000,0,0,300.000,300.000,1,0,1
3748763409.718000,GPIB0::1::INSTR,Standby,300.000,299.999,0.000,0.000,0,0,300.000,300.000,1,0,1
3748763559.718000,GPIB0::1::INSTR,Standby,300.002,300.001,0.000,0.000,0,0,300.000,300.000,1,0,1
3748763709.718000,GPIB0::1::INSTR,Standby,300.000,299.998,0.000,0.000,0,0,300.000,300.000,1,0,1
3748763859.718000,GPIB0::1::INSTR,Standby,299.999,300.000,0.000,0.000,0,0,300.000,300.000,1,0,1
3748764009.718000,GPIB0::1::INSTR,Standby,300.002,300.001,0.000,0.000,0,0,300.000,300.000,1,0,1
3748764159.718000,GPIB0::1::INSTR,Standby,300.002,300.000,0.000,0.000,0,0,300.000,300.000,1,0,1
3748764309.718000,GPIB0::1::INSTR,Standby,299.999,300.000,0.000,0.000,0,0,300.000,300.000,1,0,1
3748764459.718000,GPIB0::1::INSTR,Standby,300.001,300.000,0.000,0.000,0,0,300.000,300.000,1,0,1
3748764609.718000,GPIB0::1::INSTR,Standby,299.999,299.999,0.000,0.000,0,0,300.000,300.000,1,0,1
3748764759.718000,GPIB0::1::INSTR,Standby,300.000,300.000,0.000,0.000,0,0,300.000,300.000,1,0,1
3748764909.718000,GPIB0::1::INSTR,Standby,300.000,300.001,0.000,0.000,0,0,300.000,300.000,1,0,1
3748765059.718000,GPIB0::1::INSTR,Standby,300.000,299.999,0.000,0.000,0,0,300.000,300.000,1,0,1
3748765209.718000,GPIB0::1::INSTR,Standby,300.000,299.999,0.000,0.000,0,0,300.000,300.000,1,0,1
3748765359.718000,GPIB0::1::INSTR,Standby,299.999,299.998,0.000,0.000,0,0,300.000,300.000,1,0,1
3748765509.718000,GPIB0::1::INSTR,Standby,299.999,300.000,0.000,0.000,0,0,300.000,300.000,1,0,1
3748765659.718000,GPIB0::1::INSTR,Standby,300.000,299.999,0.000,0.000,0,0,300.000,300.000,1,0,1
3748765809.718000,GPIB0::1::INSTR,Standby,300.000,299.999,0.000,0.000,0,0,300.000,300.000,1,0,1
3748765959.718000,GPIB0::1::INSTR,Standby,299.999,299.999,0.000,0.000,0,0,300.000,300.000,1,0,1
3748766109.718000,GPIB0::1::INSTR,Standby,300.001,299.999,0.000,0.000,0,0,300.000,300.000,1,0,1
3748766259.718000,GPIB0::1::INSTR,Standby,300.001,299.998,0.000,0.000,0,0,300.000,300.000,1,0,1
3748766409.718000,GPIB0::1::INSTR,Standby,300.000,300.001,0.000,0.000,0,0,300.000,300.000,1,0,1
3748766559.718000,GPIB0::1::INSTR,Standby,300.000,299.998,0.000,0.000,0,0,300.000,300.000,1,0,1
3748766709.718000,GPIB0::1::INSTR,Standby,300.001,300.001,0.000,0.000,0,0,300.000,300.000,1,0,1
3748766859.718000,GPIB0::1::INSTR,Standby,300.002,300.000,0.000,0.000,0,0,300.000,300.000,1,0,1
3748767009.718000,GPIB0::1::INSTR,Standby,300.000,300.001,0.000,0.000,0,0,300.000,300.000,1,0,1
3748767159.718000,GPIB0::1::INSTR,Standby,300.001,299.999,0.000,0.000,0,0,300.000,300.000,1,0,1
3748767309.718000,GPIB0::1::INSTR,Standby,300.002,300.001,0.000,0.000,0,0,300.000,300.000,1,0,1
3748767459.718000,GPIB0::1::INSTR,Standby,300.000,299.999,0.000,0.000,0,0,300.000,300.000,1,0,1
3748767609.718000,GPIB0::1::INSTR,Standby,300.000,300.000,0.000,0.000,0,0,300.000,300.000,1,0,1
3748767759.718000,GPIB0::1::INSTR,Standby,300.002,300.002,0.000,0.000,0,0,300.000,300.000,1,0,1
3748767909.718000,GPIB0::1::INSTR,Standby,300.000,300.001,0.000,0.000,0,0,300.000,300.000,1,0,1
3748768059.718000,GPIB0::1::INSTR,Standby,300.000,299.999,0.000,0.000,0,0,300.000,300.000,1,0,1
3748768209.718000,GPIB0::1::INSTR,Standby,300.000,300.000,0.000,0.000,0,0,300.000,300.000,1,0,1
3748768359.718000,GPIB0::1::INSTR,Standby,299.999,300.000,0.000,0.000,0,0,300.000,300.000,1,0,1
3748768509.718000,GPIB0::1::INSTR,Standby,300.002,299.999,0.000,0.000,0,0,300.000,300.000,1,0,1
3748768659.718000,GPIB0::1::INSTR,Standby,300.000,299.999,0.000,0.000,0,0,300.000,300.000,1,0,1
3748768809.718000,GPIB0::1::INSTR,Standby,300.000,300.001,0.000,0.000,0,0,300.000,300.000,1,0,1
3748768959.718000,GPIB0::1::INSTR,Standby,300.000,300.000,0.000,0.000,0,0,300.000,300.000,1,0,1
3748769109.718000,GPIB0::1::INSTR,Standby,300.000,300.000,0.000,0.000,0,0,300.000,300.000,1,0,1
3748769259.718000,GPIB0::1::INSTR,Standby,300.001,300.001,0.000,0.000,0,0,300.000,300.000,1,0,1
3748769409.718000,GPIB0::1::INSTR,Standby,300.001,300.001,0.000,0.000,0,0,300.000,300.000,1,0,1
3748769559.718000,GPIB0::1::INSTR,Standby,300.000,300.000,0.000,0.000,0,0,300.000,300.000,1,0,1
3748769709.718000,GPIB0::1::INSTR,Standby,300.000,299.999,0.000,0.000,0,0,300.000,300.000,1,0,1
3748769859.718000,GPIB0::1::INSTR,Standby,300.001,300.000,0.000,0.000,0,0,300.000,300.000,1,0,1
3748770009.718000,GPIB0::1::INSTR,Standby,300.000,300.000,0.000,0.000,0,0,300.000,300.000,1,0,1
3748770159.718000,GPIB0::1::INSTR,Standby,300.002,299.998,0.000,0.000,0,0,300.000,300.000,1,0,1
3748770309.718000,GPIB0::1::INSTR,Standby,300.002,300.001,0.000,0.000,0,0,300.000,300.000,1,0,1
3748770459.718000,GPIB0::1::INSTR,Standby,300.002,300.001,0.000,0.000,0,0,300.000,300.000,1,0,1
3748770609.718000,GPIB0::1::INSTR,Standby,300.000,300.001,0.000,0.000,0,0,300.000,300.000,1,0,1
3748770759.718000,GPIB0::1::INSTR,Standby,300.002,300.001,0.000,0.000,0,0,300.000,300.000,1,0,1
3748770909.718000,GPIB0::1::INSTR,Standby,299.999,300.000,0.000,0.000,0,0,300.000,300.000,1,0,1
3748771059.718000,GPIB0::1::INSTR,Standby,300.001,300.002,0.000,0.000,0,0,300.000,300.000,1,0,1
3748771209.718000,GPIB0::1::INSTR,Standby,300.000,299.998,0.000,0.000,0,0,300.000,300.000,1,0,1
3748771359.718000,GPIB0::1::INSTR,Standby,300.002,300.000,0.000,0.000,0,0,300.000,300.000,1,0,1
3748771509.718000,GPIB0::1::INSTR,Standby,300.000,299.999,0.000,0.000,0,0,300.000,300.000,1,0,1
3748771659.718000,GPIB0::1::INSTR,Standby,299.999,299.998,0.000,0.000,0,0,300.000,300.000,1,0,1
3748771809.718000,GPIB0::1::INSTR,Standby,299.999,299.998,0.000,0.000,0,0,300.000,300.000,1,0,1
3748771959.718000,GPIB0::1::INSTR,Standby,300.002,300.000,0.000,0.000,0,0,300.000,300.000,1,0,1
3748772109.718000,GPIB0::1::INSTR,Standby,300.000,300.000,0.000,0.000,0,0,300.000,300.000,1,0,1
3748772259.718000,GPIB0::1::INSTR,Standby,300.001,299.999,0.000,0.000,0,0,300.000,300.000,1,0,1
3748772409.718000,GPIB0::1::INSTR,Standby,300.002,299.999,0.000,0.000,0,0,300.000,300.000,1,0,1
3748772559.718000,GPIB0::1::INSTR,Standby,300.001,300.001,0.000,0.000,0,0,300.000,300.000,1,0,1
3748772709.718000,GPIB0::1::INSTR,Standby,300.001,300.000,0.000,0.000,0,0,300.000,300.000,1,0,1
3748772859.718000,GPIB0::1::INSTR,Standby,300.000,300.001,0.000,0.000,0,0,300.000,300.000,1,0,1
3748773009.718000,GPIB0::1::INSTR,Standby,300.003,300.000,0.000,0.000,0,0,300.000,300.000,1,0,1
3748773159.718000,GPIB0::1::INSTR,Standby,300.002,299.999,0.000,0.000,0,0,300.000,300.000,1,0,1
3748773309.718000,GPIB0::1::INSTR,Standby,299.999,299.999,0.000,0.000,0,0,300.000,300.000,1,0,1
3748773459.718000,GPIB0::1::INSTR,Standby,300.000,300.000,0.000,0.000,0,0,300.000,300.000,1,0,1
3748773609.718000,GPIB0::1::INSTR,Standby,300.000,299.999,0.000,0.000,0,0,300.000,300.000,1,0,1
3748773759.718000,GPIB0::1::INSTR,Standby,300.000,300.000,0.000,0.000,0,0,300.000,300.000,1,0,1
3748773909.718000,GPIB0::1::INSTR,Standby,300.001,300.000,0.000,0.000,0,0,300.000,300.000,1,0,1
3748774059.718000,GPIB0::1::INSTR,Standby,300.002,299.999,0.000,0.000,0,0,300.000,300.000,1,0,1
3748774209.718000,GPIB0::1::INSTR,Standby,300.000,300.002,0.000,0.000,0,0,300.000,300.000,1,0,1
3748774359.718000,GPIB0::1::INSTR,Standby,300.001,300.002,0.000,0.000,0,0,300.000,300.000,1,0,1
3748774509.718000,GPIB0::1::INSTR,Standby,299.998,300.000,0.000,0.000,0,0,300.000,300.000,1,0,1
3748774659.718000,GPIB0::1::INSTR,Standby,300.000,299.998,0.000,0.000,0,0,300.000,300.000,1,0,1
3748774809.718000,GPIB0::1::INSTR,Standby,300.001,300.000,0.000,0.000,0,0,300.000,300.000,1,0,1
3748774959.718000,GPIB0::1::INSTR,Standby,300.000,299.999,0.000,0.000,0,0,300.000,300.000,1,0,1
3748775109.718000,GPIB0::1::INSTR,Standby,300.002,299.998,0.000,0.000,0,0,300.000,300.000,1,0,1
3748775259.718000,GPIB0::1::INSTR,Standby,300.002,300.000,0.000,0.000,0,0,300.000,300.000,1,0,1
3748775409.718000,GPIB0::1::INSTR,Standby,300.000,299.999,0.000,0.000,0,0,300.000,300.000,1,0,1
3748775559.718000,GPIB0::1::INSTR,Standby,300.002,300.001,0.000,0.000,0,0,300.000,300.000,1,0,1
3748775709.718000,GPIB0::1::INSTR,Standby,300.002,300.000,0.000,0.000,0,0,300.000,300.000,1,0,1
3748775859.718000,GPIB0::1::INSTR,Standby,299.999,300.001,0.000,0.000,0,0,300.000,300.000,1,0,1
3748776009.718000,GPIB0::1::INSTR,Standby,300.000,300.001,0.000,0.000,0,0,300.000,300.000,1,0,1
3748776159.718000,GPIB0::1::INSTR,Standby,300.001,299.998,0.000,0.000,0,0,300.000,300.000,1,0,1
3748776309.718000,GPIB0::1::INSTR,Standby,299.999,300.000,0.000,0.000,0,0,300.000,300.000,1,0,1
3748776459.718000,GPIB0::1::INSTR,Standby,300.002,300.001,0.000,0.000,0,0,300.000,300.000,1,0,1
3748776609.718000,GPIB0::1::INSTR,Standby,300.000,300.002,0.000,0.000,0,0,300.000,300.000,1,0,1
3748776759.718000,GPIB0::1::INSTR,Standby,299.999,300.000,0.000,0.000,0,0,300.000,300.000,1,0,1
3748776909.718000,GPIB0::1::INSTR,Standby,300.001,299.999,0.000,0.000,0,0,300.000,300.000,1,0,1
3748777059.718000,GPIB0::1::INSTR,Standby,300.001,300.000,0.000,0.000,0,0,300.000,300.000,1,0,1
3748777209.718000,GPIB0::1::INSTR,Standby,300.002,299.999,0.000,0.000,0,0,300.000,300.000,1,0,1
3748777359.718000,GPIB0::1::INSTR,Standby,300.000,300.000,0.000,0.000,0,0,300.000,300.000,1,0,1
3748777509.718000,GPIB0::1::INSTR,Standby,300.001,299.999,0.000,0.000,0,0,300.000,300.000,1,0,1
3748777659.718000,GPIB0::1::INSTR,Standby,300.001,299.997,0.000,0.000,0,0,300.000,300.000,1,0,1
3748777809.718000,GPIB0::1::INSTR,Standby,299.998,299.998,0.000,0.000,0,0,300.000,300.000,1,0,1
3748777959.718000,GPIB0::1::INSTR,Standby,300.001,299.999,0.000,0.000,0,0,300.000,300.000,1,0,1
3748778109.718000,GPIB0::1::INSTR,Standby,300.000,299.999,0.000,0.000,0,0,300.000,300.000,1,0,1
3748778259.718000,GPIB0::1::INSTR,Standby,300.001,300.000,0.000,0.000,0,0,300.000,300.000,1,0,1
3748778409.718000,GPIB0::1::INSTR,Standby,299.999,299.999,0.000,0.000,0,0,300.000,300.000,1,0,1
3748778559.718000,GPIB0::1::INSTR,Standby,300.001,300.001,0.000,0.000,0,0,300.000,300.000,1,0,1
3748778709.718000,GPIB0::1::INSTR,Standby,300.000,299.998,0.000,0.000,0,0,300.000,300.000,1,0,1
3748778859.718000,GPIB0::1::INSTR,Standby,300.001,300.000,0.000,0.000,0,0,300.000,300.000,1,0,1
3748779009.718000,GPIB0::1::INSTR,Standby,300.002,299.999,0.000,0.000,0,0,300.000,300.000,1,0,1
3748779159.718000,GPIB0::1::INSTR,Standby,300.001,300.000,0.000,0.000,0,0,300.000,300.000,1,0,1
3748779309.718000,GPIB0::1::INSTR,Standby,299.999,300.000,0.000,0.000,0,0,300.000,300.000,1,0,1
3748779459.718000,GPIB0::1::INSTR,Standby,300.001,299.999,0.000,0.000,0,0,300.000,300.000,1,0,1
3748779609.718000,GPIB0::1::INSTR,Standby,300.000,300.000,0.000,0.000,0,0,300.000,300.000,1,0,1
3748779759.718000,GPIB0::1::INSTR,Standby,300.001,300.002,0.000,0.000,0,0,300.000,300.000,1,0,1
3748779909.718000,GPIB0::1::INSTR,Standby,300.001,300.000,0.000,0.000,0,0,300.000,300.000,1,0,1
3748780059.718000,GPIB0::1::INSTR,Standby,300.001,300.000,0.000,0.000,0,0,300.000,300.000,1,0,1
3748780209.718000,GPIB0::1::INSTR,Standby,300.000,299.999,0.000,0.000,0,0,300.000,300.000,1,0,1
3748780359.718000,GPIB0::1::INSTR,Standby,300.000,300.000,0.000,0.000,0,0,300.000,300.000,1,0,1
3748780509.718000,GPIB0::1::INSTR,Standby,300.001,299.999,0.000,0.000,0,0,300.000,300.000,1,0,1
3748780659.718000,GPIB0::1::INSTR,Standby,300.001,300.002,0.000,0.000,0,0,300.000,300.000,1,0,1
3748780809.718000,GPIB0::1::INSTR,Standby,300.001,299.999,0.000,0.000,0,0,300.000,300.000,1,0,1
3748780959.718000,GPIB0::1::INSTR,Standby,300.001,299.998,0.000,0.000,0,0,300.000,300.000,1,0,1
3748781109.718000,GPIB0::1::INSTR,Standby,300.000,300.000,0.000,0.000,0,0,300.000,300.000,1,0,1
3748781259.718000,GPIB0::1::INSTR,Standby,300.000,299.998,0.000,0.000,0,0,300.000,300.000,1,0,1
3748781409.718000,GPIB0::1::INSTR,Standby,300.002,299.998,0.000,0.000,0,0,300.000,300.000,1,0,1
3748781559.718000,GPIB0::1::INSTR,Standby,300.000,299.999,0.000,0.000,0,0,300.000,300.000,1,0,1
3748781709.718000,GPIB0::1::INSTR,Standby,300.002,300.000,0.000,0.000,0,0,300.000,300.000,1,0,1
3748781859.718000,GPIB0::1::INSTR,Standby,299.999,299.998,0.000,0.000,0,0,300.000,300.000,1,0,1
3748782009.718000,GPIB0::1::INSTR,Standby,300.001,300.000,0.000,0.000,0,0,300.000,300.000,1,0,1
3748782159.718000,GPIB0::1::INSTR,Standby,299.999,299.999,0.000,0.000,0,0,300.000,300.000,1,0,1
3748782309.718000,GPIB0::1::INSTR,Standby,300.000,300.000,0.000,0.000,0,0,300.000,300.000,1,0,1
3748782459.718000,GPIB0::1::INSTR,Standby,299.998,299.999,0.000,0.000,0,0,300.000,300.000,1,0,1
3748782609.718000,GPIB0::1::INSTR,Standby,300.000,300.001,0.000,0.000,0,0,300.000,300.000,1,0,1
3748782759.718000,GPIB0::1::INSTR,Standby,300.000,299.999,0.000,0.000,0,0,300.000,300.000,1,0,1
3748782909.718000,GPIB0::1::INSTR,Standby,300.001,300.000,0.000,0.000,0,0,300.000,300.000,1,0,1
3748783059.718000,GPIB0::1::INSTR,Standby,299.999,300.001,0.000,0.000,0,0,300.000,300.000,1,0,1
3748783209.718000,GPIB0::1::INSTR,Standby,300.000,300.001,0.000,0.000,0,0,300.000,300.000,1,0,1
3748783359.718000,GPIB0::1::INSTR,Standby,299.999,299.999,0.000,0.000,0,0,300.000,300.000,1,0,1
3748783509.718000,GPIB0::1::INSTR,Standby,300.000,300.000,0.000,0.000,0,0,300.000,300.000,1,0,1
3748783659.718000,GPIB0::1::INSTR,Standby,300.000,300.000,0.000,0.000,0,0,300.000,300.000,1,0,1
3748783809.718000,GPIB0::1::INSTR,Standby,299.999,300.000,0.000,0.000,0,0,300.000,300.000,1,0,1
3748783959.718000,GPIB0::1::INSTR,Standby,299.999,300.000,0.000,0.000,0,0,300.000,300.000,1,0,1
3748784109.718000,GPIB0::1::INSTR,Standby,300.000,299.999,0.000,0.000,0,0,300.000,300.000,1,0,1
3748784259.718000,GPIB0::1::INSTR,Standby,300.002,299.999,0.000,0.000,0,0,300.000,300.000,1,0,1
3748784409.718000,GPIB0::1::INSTR,Standby,300.001,299.999,0.000,0.000,0,0,300.000,300.000,1,0,1
3748784559.718000,GPIB0::1::INSTR,Standby,300.000,300.000,0.000,0.000,0,0,300.000,300.000,1,0,1
3748784709.718000,GPIB0::1::INSTR,Standby,300.000,299.999,0.000,0.000,0,0,300.000,300.000,1,0,1
3748784859.718000,GPIB0::1::INSTR,Standby,300.000,300.001,0.000,0.000,0,0,300.000,300.000,1,0,1
3748785009.718000,GPIB0::1::INSTR,Standby,300.000,300.000,0.000,0.000,0,0,300.000,300.000,1,0,1
3748785159.718000,GPIB0::1::INSTR,Standby,299.999,299.998,0.000,0.000,0,0,300.000,300.000,1,0,1
3748785309.718000,GPIB0::1::INSTR,Standby,300.000,300.000,0.000,0.000,0,0,300.000,300.000,1,0,1
3748785459.718000,GPIB0::1::INSTR,Standby,300.000,300.000,0.000,0.000,0,0,300.000,300.000,1,0,1
3748785609.718000,GPIB0::1::INSTR,Standby,300.000,299.999,0.000,0.000,0,0,300.000,300.000,1,0,1
3748785759.718000,GPIB0::1::INSTR,Standby,300.001,300.001,0.000,0.000,0,0,300.000,300.000,1,0,1
3748785909.718000,GPIB0::1::INSTR,Standby,300.002,300.000,0.000,0.000,0,0,300.000,300.000,1,0,1
3748786059.718000,GPIB0::1::INSTR,Standby,300.001,299.999,0.000,0.000,0,0,300.000,300.000,1,0,1
3748786209.718000,GPIB0::1::INSTR,Standby,299.999,300.001,0.000,0.000,0,0,300.000,300.000,1,0,1
3748786359.718000,GPIB0::1::INSTR,Standby,300.000,300.000,0.000,0.000,0,0,300.000,300.000,1,0,1
3748786509.718000,GPIB0::1::INSTR,Standby,300.001,300.001,0.000,0.000,0,0,300.000,300.000,1,0,1
3748786659.718000,GPIB0::1::INSTR,Standby,299.999,299.999,0.000,0.000,0,0,300.000,300.000,1,0,1
3748786809.718000,GPIB0::1::INSTR,Standby,300.000,299.998,0.000,0.000,0,0,300.000,300.000,1,0,1
3748786959.718000,GPIB0::1::INSTR,Standby,300.000,299.999,0.000,0.000,0,0,300.000,300.000,1,0,1
3748787109.718000,GPIB0::1::INSTR,Standby,300.002,300.000,0.000,0.000,0,0,300.000,300.000,1,0,1
3748787259.718000,GPIB0::1::INSTR,Standby,299.999,300.000,0.000,0.000,0,0,300.000,300.000,1,0,1
3748787409.718000,GPIB0::1::INSTR,Standby,300.000,300.000,0.000,0.000,0,0,300.000,300.000,0,0,1
3748787559.718000,GPIB0::1::INSTR,Standby,299.999,300.001,0.000,0.000,0,0,300.000,300.000,1,0,1
3748787709.718000,GPIB0::1::INSTR,Standby,300.000,299.999,0.000,0.000,0,0,300.000,300.000,1,0,1
3748787859.718000,GPIB0::1::INSTR,Standby,299.997,299.999,0.000,0.000,0,0,300.000,300.000,1,0,1
3748788009.718000,GPIB0::1::INSTR,Standby,300.000,300.001,0.000,0.000,0,0,300.000,300.000,0,0,1
3748788159.718000,GPIB0::1::INSTR,Standby,300.001,300.001,0.000,0.000,0,0,300.000,300.000,1,0,1
3748788309.718000,GPIB0::1::INSTR,Standby,300.000,300.000,0.000,0.000,0,0,300.000,300.000,1,0,1
3748788459.718000,GPIB0::1::INSTR,Standby,299.998,300.000,0.000,0.000,0,0,300.000,300.000,1,0,1
3748788609.718000,GPIB0::1::INSTR,Standby,299.999,299.999,0.000,0.000,0,0,300.000,300.000,1,0,1
3748788759.718000,GPIB0::1::INSTR,Standby,300.000,300.001,0.000,0.000,0,0,300.000,300.000,1,0,1
3748788909.718000,GPIB0::1::INSTR,Standby,300.000,300.002,0.000,0.000,0,0,300.000,300.000,1,0,1
3748789059.718000,GPIB0::1::INSTR,Standby,300.000,300.000,0.000,0.000,0,0,300.000,300.000,1,0,1
3748789209.718000,GPIB0::1::INSTR,Standby,300.000,300.000,0.000,0.000,0,0,300.000,300.000,1,0,1
3748789359.718000,GPIB0::1::INSTR,Standby,300.000,299.998,0.000,0.000,0,0,300.000,300.000,1,0,1
3748789509.718000,GPIB0::1::INSTR,Standby,300.001,299.999,0.000,0.000,0,0,300.000,300.000,0,0,1
3748789659.718000,GPIB0::1::INSTR,Standby,300.000,299.999,0.000,0.000,0,0,300.000,300.000,1,0,1
3748789809.718000,GPIB0::1::INSTR,Standby,300.000,300.000,0.000,0.000,0,0,300.000,300.000,0,0,1
3748789959.718000,GPIB0::1::INSTR,Standby,299.999,299.999,0.000,0.000,0,0,300.000,300.000,0,0,1
3748790109.718000,GPIB0::1::INSTR,Standby,300.000,300.000,0.000,0.000,0,0,300.000,300.000,0,0,1
3748790259.718000,GPIB0::1::INSTR,Standby,299.999,300.001,0.000,0.000,0,0,300.000,300.000,1,0,1
3748790409.718000,GPIB0::1::INSTR,Standby,299.998,299.999,0.000,0.000,0,0,300.000,300.000,0,0,1
3748790559.718000,GPIB0::1::INSTR,Standby,299.997,299.998,0.000,0.000,0,0,300.000,300.000,0,0,1
3748790709.718000,GPIB0::1::INSTR,Standby,300.000,300.000,0.000,0.000,0,0,300.000,300.000,1,0,1
3748790859.718000,GPIB0::1::INSTR,Standby,299.998,299.999,0.000,0.000,0,0,300.000,300.000,0,0,1
3748791009.718000,GPIB0::1::INSTR,Standby,300.001,300.002,0.000,0.000,0,0,300.000,300.000,1,0,1
3748791159.718000,GPIB0::1::INSTR,Standby,299.999,299.998,0.000,0.000,0,0,300.000,300.000,0,0,1
3748791309.718000,GPIB0::1::INSTR,Standby,300.001,300.000,0.000,0.000,0,0,300.000,300.000,1,0,1
3748791459.718000,GPIB0::1::INSTR,Standby,299.999,300.001,0.000,0.000,0,0,300.000,300.000,0,0,1
3748791609.718000,GPIB0::1::INSTR,Standby,299.999,299.999,0.000,0.000,0,0,300.000,300.000,0,0,1
3748791759.718000,GPIB0::1::INSTR,Standby,300.002,300.001,0.000,0.000,0,0,300.000,300.000,0,0,1
3748791909.718000,GPIB0::1::INSTR,Standby,300.001,300.000,0.000,0.000,0,0,300.000,300.000,1,0,1
3748792059.718000,GPIB0::1::INSTR,Standby,300.000,299.999,0.000,0.000,0,0,300.000,300.000,1,0,1
3748792209.718000,GPIB0::1::INSTR,Standby,299.999,299.998,0.000,0.000,0,0,300.000,300.000,0,0,1
3748792359.718000,GPIB0::1::INSTR,Standby,300.000,300.001,0.000,0.000,0,0,300.000,300.000,0,0,1
3748792509.718000,GPIB0::1::INSTR,Standby,300.001,300.000,0.000,0.000,0,0,300.000,300.000,0,0,1
3748792659.718000,GPIB0::1::INSTR,Standby,300.000,300.000,0.000,0.000,0,0,300.000,300.000,0,0,1
3748792809.718000,GPIB0::1::INSTR,Standby,300.000,299.999,0.000,0.000,0,0,300.000,300.000,0,0,1
3748792959.718000,GPIB0::1::INSTR,Standby,299.999,299.999,0.000,0.000,0,0,300.000,300.000,0,0,1
3748793109.718000,GPIB0::1::INSTR,Standby,300.001,300.000,0.000,0.000,0,0,300.000,300.000,0,0,1
3748793259.718000,GPIB0::1::INSTR,Standby,300.000,300.000,0.000,0.000,0,0,300.000,300.000,0,0,1
3748793409.718000,GPIB0::1::INSTR,Standby,300.000,300.000,0.000,0.000,0,0,300.000,300.000,0,0,1
3748793559.718000,GPIB0::1::INSTR,Standby,299.999,299.999,0.000,0.000,0,0,300.000,300.000,0,0,1
3748793709.718000,GPIB0::1::INSTR,Standby,300.000,299.998,0.000,0.000,0,0,300.000,300.000,0,0,1
3748793859.718000,GPIB0::1::INSTR,Standby,300.000,300.000,0.000,0.000,0,0,300.000,300.000,0,0,1
3748794009.718000,GPIB0::1::INSTR,Standby,300.000,299.999,0.000,0.000,0,0,300.000,300.000,1,0,1
3748794159.718000,GPIB0::1::INSTR,Standby,299.999,300.000,0.000,0.000,0,0,300.000,300.000,0,0,1
3748794309.718000,GPIB0::1::INSTR,Standby,300.001,299.999,0.000,0.000,0,0,300.000,300.000,0,0,1
3748794459.718000,GPIB0::1::INSTR,Standby,299.999,299.999,0.000,0.000,0,0,300.000,300.000,0,0,1
3748794609.718000,GPIB0::1::INSTR,Standby,299.999,300.001,0.000,0.000,0,0,300.000,300.000,0,0,1
3748794759.718000,GPIB0::1::INSTR,Standby,300.001,299.999,0.000,0.000,0,0,300.000,300.000,0,0,1
3748794909.718000,GPIB0::1::INSTR,Standby,300.001,300.001,0.000,0.000,0,0,300.000,300.000,1,0,1
3748795059.718000,GPIB0::1::INSTR,Standby,300.000,300.001,0.000,0.000,0,0,300.000,300.000,0,0,1
3748795209.718000,GPIB0::1::INSTR,Standby,300.000,300.000,0.000,0.000,0,0,300.000,300.000,0,0,1
3748795359.718000,GPIB0::1::INSTR,Standby,299.999,299.999,0.000,0.000,0,0,300.000,300.000,0,0,1
3748795509.718000,GPIB0::1::INSTR,Standby,300.000,300.001,0.000,0.000,0,0,300.000,300.000,0,0,1
3748795659.718000,GPIB0::1::INSTR,Standby,300.000,299.999,0.000,0.000,0,0,300.000,300.000,0,0,1
3748795809.718000,GPIB0::1::INSTR,Standby,300.000,300.001,0.000,0.000,0,0,300.000,300.000,1,0,1
3748795959.718000,GPIB0::1::INSTR,Standby,299.999,300.000,0.000,0.000,0,0,300.000,300.000,0,0,1
3748796109.718000,GPIB0::1::INSTR,Standby,299.999,300.001,0.000,0.000,0,0,300.000,300.000,0,0,1
3748796259.718000,GPIB0::1::INSTR,Standby,300.000,300.000,0.000,0.000,0,0,300.000,300.000,0,0,1
3748796409.718000,GPIB0::1::INSTR,Standby,300.001,299.998,0.000,0.000,0,0,300.000,300.000,0,0,1
3748796559.718000,GPIB0::1::INSTR,Standby,300.000,300.000,0.000,0.000,0,0,300.000,300.000,0,0,1
3748796709.718000,GPIB0::1::INSTR,Standby,300.003,300.002,0.000,0.000,0,0,300.000,300.000,0,0,1
3748796859.718000,GPIB0::1::INSTR,Standby,300.000,300.000,0.000,0.000,0,0,300.000,300.000,0,0,1
3748797009.718000,GPIB0::1::INSTR,Standby,299.998,300.000,0.000,0.000,0,0,300.000,300.000,0,0,1
3748797159.718000,GPIB0::1::INSTR,Standby,299.998,300.001,0.000,0.000,0,0,300.000,300.000,0,0,1
3748797309.718000,GPIB0::1::INSTR,Standby,299.999,299.999,0.000,0.000,0,0,300.000,300.000,0,0,1
3748797459.718000,GPIB0::1::INSTR,Standby,299.999,300.000,0.000,0.000,0,0,300.000,300.000,0,0,1
3748797609.718000,GPIB0::1::INSTR,Standby,300.001,300.001,0.000,0.000,0,0,300.000,300.000,0,0,1
3748797759.718000,GPIB0::1::INSTR,Standby,300.000,299.998,0.000,0.000,0,0,300.000,300.000,0,0,1
3748797909.718000,GPIB0::1::INSTR,Standby,300.003,300.000,0.000,0.000,0,0,300.000,300.000,0,0,1
3748798059.718000,GPIB0::1::INSTR,Standby,299.998,299.999,0.000,0.000,0,0,300.000,300.000,0,0,1
3748798209.718000,GPIB0::1::INSTR,Standby,299.999,299.999,0.000,0.000,0,0,300.000,300.000,0,0,1
3748798359.718000,GPIB0::1::INSTR,Standby,300.002,300.001,0.000,0.000,0,0,300.000,300.000,0,0,1
3748798509.718000,GPIB0::1::INSTR,Standby,300.000,300.000,0.000,0.000,0,0,300.000,300.000,0,0,1
3748798659.718000,GPIB0::1::INSTR,Standby,299.999,300.002,0.000,0.000,0,0,300.000,300.000,0,0,1
3748798809.718000,GPIB0::1::INSTR,Standby,299.999,300.000,0.000,0.000,0,0,300.000,300.000,0,0,1
3748798959.718000,GPIB0::1::INSTR,Standby,299.999,299.999,0.000,0.000,0,0,300.000,300.000,0,0,1
3748799109.718000,GPIB0::1::INSTR,Standby,299.999,300.000,0.000,0.000,0,0,300.000,300.000,0,0,1
3748799259.718000,GPIB0::1::INSTR,Standby,299.999,300.001,0.000,0.000,0,0,300.000,300.000,0,0,1
3748799409.718000,GPIB0::1::INSTR,Standby,299.999,300.001,0.000,0.000,0,0,300.000,300.000,0,0,1
3748799559.718000,GPIB0::1::INSTR,Standby,299.998,299.998,0.000,0.000,0,0,300.000,300.000,0,0,1
3748799709.718000,GPIB0::1::INSTR,Standby,300.002,300.000,0.000,0.000,0,0,300.000,300.000,0,0,1
3748799859.718000,GPIB0::1::INSTR,Standby,300.000,299.999,0.000,0.000,0,0,300.000,300.000,0,0,1
3748800009.718000,GPIB0::1::INSTR,Standby,300.000,300.000,0.000,0.000,0,0,300.000,300.000,0,0,1
3748800159.718000,GPIB0::1::INSTR,Standby,299.999,300.001,0.000,0.000,0,0,300.000,300.000,0,0,1
3748800309.718000,GPIB0::1::INSTR,Standby,299.998,299.998,0.000,0.000,0,0,300.000,300.000,0,0,1
3748800459.718000,GPIB0::1::INSTR,Standby,300.000,300.000,0.000,0.000,0,0,300.000,300.000,0,0,1
3748800609.718000,GPIB0::1::INSTR,Standby,300.001,299.998,0.000,0.000,0,0,300.000,300.000,0,0,1
3748800759.718000,GPIB0::1::INSTR,Standby,299.999,299.999,0.000,0.000,0,0,300.000,300.000,0,0,1
3748800909.718000,GPIB0::1::INSTR,Standby,299.998,299.999,0.000,0.000,0,0,300.000,300.000,0,0,1
3748801059.718000,GPIB0::1::INSTR,Standby,300.000,300.000,0.000,0.000,0,0,300.000,300.000,0,0,1
3748801209.718000,GPIB0::1::INSTR,Standby,300.000,300.001,0.000,0.000,0,0,300.000,300.000,0,0,1
3748801359.719000,GPIB0::1::INSTR,Standby,300.000,300.000,0.000,0.000,0,0,300.000,300.000,0,0,1
3748801509.719000,GPIB0::1::INSTR,Standby,299.998,300.000,0.000,0.000,0,0,300.000,300.000,0,0,1
3748801659.719000,GPIB0::1::INSTR,Standby,300.001,299.999,0.000,0.000,0,0,300.000,300.000,0,0,1
3748801809.719000,GPIB0::1::INSTR,Standby,299.999,299.998,0.000,0.000,0,0,300.000,300.000,0,0,1
3748801959.719000,GPIB0::1::INSTR,Standby,299.999,300.000,0.000,0.000,0,0,300.000,300.000,0,0,1
3748802109.719000,GPIB0::1::INSTR,Standby,300.001,300.000,0.000,0.000,0,0,300.000,300.000,0,0,1
3748802259.719000,GPIB0::1::INSTR,Standby,299.999,299.998,0.000,0.000,0,0,300.000,300.000,0,0,1
3748802409.719000,GPIB0::1::INSTR,Standby,299.998,300.001,0.000,0.000,0,0,300.000,300.000,0,0,1
3748802559.719000,GPIB0::1::INSTR,Standby,300.000,300.000,0.000,0.000,0,0,300.000,300.000,0,0,1
3748802709.719000,GPIB0::1::INSTR,Standby,300.000,300.001,0.000,0.000,0,0,300.000,300.000,0,0,1
3748802859.719000,GPIB0::1::INSTR,Standby,300.000,299.997,0.000,0.000,0,0,300.000,300.000,0,0,1
3748803009.719000,GPIB0::1::INSTR,Standby,300.000,299.998,0.000,0.000,0,0,300.000,300.000,0,0,1
3748803159.719000,GPIB0::1::INSTR,Standby,299.999,300.001,0.000,0.000,0,0,300.000,300.000,0,0,1
3748803309.719000,GPIB0::1::INSTR,Standby,299.998,300.000,0.000,0.000,0,0,300.000,300.000,0,0,1
3748803459.719000,GPIB0::1::INSTR,Standby,299.999,299.999,0.000,0.000,0,0,300.000,300.000,0,0,1
3748803609.719000,GPIB0::1::INSTR,Standby,300.000,300.000,0.000,0.000,0,0,300.000,300.000,0,0,1
3748803759.719000,GPIB0::1::INSTR,Standby,299.998,299.998,0.000,0.000,0,0,300.000,300.000,0,0,1
3748803909.719000,GPIB0::1::INSTR,Standby,300.000,299.999,0.000,0.000,0,0,300.000,300.000,0,0,1
3748804059.719000,GPIB0::1::INSTR,Standby,300.001,300.000,0.000,0.000,0,0,300.000,300.000,0,0,1
3748804209.719000,GPIB0::1::INSTR,Standby,300.001,300.000,0.000,0.000,0,0,300.000,300.000,0,0,1
3748804359.719000,GPIB0::1::INSTR,Standby,299.998,299.998,0.000,0.000,0,0,300.000,300.000,0,0,1
3748804509.719000,GPIB0::1::INSTR,Standby,300.000,299.998,0.000,0.000,0,0,300.000,300.000,0,0,1
3748804659.719000,GPIB0::1::INSTR,Standby,300.000,300.000,0.000,0.000,0,0,300.000,300.000,0,0,1
3748804809.719000,GPIB0::1::INSTR,Standby,300.001,300.000,0.000,0.000,0,0,300.000,300.000,0,0,1
3748804959.719000,GPIB0::1::INSTR,Standby,299.997,300.000,0.000,0.000,0,0,300.000,300.000,0,0,1
3748805109.719000,GPIB0::1::INSTR,Standby,299.999,299.999,0.000,0.000,0,0,300.000,300.000,0,0,1
3748805259.719000,GPIB0::1::INSTR,Standby,300.000,299.999,0.000,0.000,0,0,300.000,300.000,0,0,1
3748805409.719000,GPIB0::1::INSTR,Standby,300.000,300.001,0.000,0.000,0,0,300.000,300.000,0,0,1
3748805559.719000,GPIB0::1::INSTR,Standby,300.000,300.000,0.000,0.000,0,0,300.000,300.000,0,0,1
3748805709.719000,GPIB0::1::INSTR,Standby,300.000,300.000,0.000,0.000,0,0,300.000,300.000,0,0,1
3748805859.719000,GPIB0::1::INSTR,Standby,299.999,300.000,0.000,0.000,0,0,300.000,300.000,0,0,1
3748806009.719000,GPIB0::1::INSTR,Standby,299.999,299.999,0.000,0.000,0,0,300.000,300.000,0,0,1
3748806159.719000,GPIB0::1::INSTR,Standby,299.998,300.000,0.000,0.000,0,0,300.000,300.000,0,0,1
3748806309.719000,GPIB0::1::INSTR,Standby,300.000,300.001,0.000,0.000,0,0,300.000,300.000,0,0,1
3748806459.719000,GPIB0::1::INSTR,Standby,299.998,299.999,0.000,0.000,0,0,300.000,300.000,0,0,1
3748806609.720000,GPIB0::1::INSTR,Standby,300.000,300.000,0.000,0.000,0,0,300.000,300.000,0,0,1
3748806759.720000,GPIB0::1::INSTR,Standby,299.999,299.998,0.000,0.000,0,0,300.000,300.000,0,0,1
3748806909.720000,GPIB0::1::INSTR,Standby,299.999,300.001,0.000,0.000,0,0,300.000,300.000,0,0,1
3748807059.720000,GPIB0::1::INSTR,Standby,300.001,300.000,0.000,0.000,0,0,300.000,300.000,1,0,1
3748807209.720000,GPIB0::1::INSTR,Standby,300.000,300.000,0.000,0.000,0,0,300.000,300.000,1,0,1
3748807359.720000,GPIB0::1::INSTR,Standby,300.000,300.001,0.000,0.000,0,0,300.000,300.000,1,0,1
3748807509.720000,GPIB0::1::INSTR,Standby,300.000,299.998,0.000,0.000,0,0,300.000,300.000,0,0,1
3748807659.720000,GPIB0::1::INSTR,Standby,300.000,300.000,0.000,0.000,0,0,300.000,300.000,0,0,1
3748807809.720000,GPIB0::1::INSTR,Standby,300.001,300.000,0.000,0.000,0,0,300.000,300.000,1,0,1
3748807959.720000,GPIB0::1::INSTR,Standby,300.000,300.000,0.000,0.000,0,0,300.000,300.000,0,0,1
3748808109.720000,GPIB0::1::INSTR,Standby,299.999,300.000,0.000,0.000,0,0,300.000,300.000,1,0,1
3748808259.720000,GPIB0::1::INSTR,Standby,300.001,299.999,0.000,0.000,0,0,300.000,300.000,0,0,1
3748808409.720000,GPIB0::1::INSTR,Standby,300.001,300.000,0.000,0.000,0,0,300.000,300.000,0,0,1
3748808559.720000,GPIB0::1::INSTR,Standby,299.999,300.000,0.000,0.000,0,0,300.000,300.000,1,0,1
3748808709.720000,GPIB0::1::INSTR,Standby,300.000,300.002,0.000,0.000,0,0,300.000,300.000,0,0,1
3748808859.720000,GPIB0::1::INSTR,Standby,300.000,299.999,0.000,0.000,0,0,300.000,300.000,1,0,1
3748809009.720000,GPIB0::1::INSTR,Standby,300.000,299.998,0.000,0.000,0,0,300.000,300.000,1,0,1
3748809159.720000,GPIB0::1::INSTR,Standby,299.999,299.999,0.000,0.000,0,0,300.000,300.000,1,0,1
3748809309.720000,GPIB0::1::INSTR,Standby,299.999,299.999,0.000,0.000,0,0,300.000,300.000,0,0,1
3748809459.720000,GPIB0::1::INSTR,Standby,299.998,300.000,0.000,0.000,0,0,300.000,300.000,0,0,1
3748809609.720000,GPIB0::1::INSTR,Standby,300.000,300.000,0.000,0.000,0,0,300.000,300.000,0,0,1
3748809759.720000,GPIB0::1::INSTR,Standby,300.000,299.999,0.000,0.000,0,0,300.000,300.000,1,0,1
3748809909.720000,GPIB0::1::INSTR,Standby,299.997,300.000,0.000,0.000,0,0,300.000,300.000,1,0,1
3748810059.720000,GPIB0::1::INSTR,Standby,300.000,299.998,0.000,0.000,0,0,300.000,300.000,0,0,1
3748810209.720000,GPIB0::1::INSTR,Standby,300.000,299.998,0.000,0.000,0,0,300.000,300.000,0,0,1
3748810359.720000,GPIB0::1::INSTR,Standby,299.999,300.000,0.000,0.000,0,0,300.000,300.000,0,0,1
3748810509.720000,GPIB0::1::INSTR,Standby,300.000,300.001,0.000,0.000,0,0,300.000,300.000,1,0,1
3748810659.720000,GPIB0::1::INSTR,Standby,299.999,300.000,0.000,0.000,0,0,300.000,300.000,0,0,1
3748810809.720000,GPIB0::1::INSTR,Standby,299.999,300.000,0.000,0.000,0,0,300.000,300.000,0,0,1
3748810959.720000,GPIB0::1::INSTR,Standby,300.000,299.998,0.000,0.000,0,0,300.000,300.000,1,0,1
3748811109.720000,GPIB0::1::INSTR,Standby,300.000,300.000,0.000,0.000,0,0,300.000,300.000,1,0,1
3748811259.720000,GPIB0::1::INSTR,Standby,300.000,299.999,0.000,0.000,0,0,300.000,300.000,1,0,1
3748811409.720000,GPIB0::1::INSTR,Standby,300.000,299.999,0.000,0.000,0,0,300.000,300.000,1,0,1
3748811559.720000,GPIB0::1::INSTR,Standby,299.999,299.999,0.000,0.000,0,0,300.000,300.000,1,0,1
3748811709.720000,GPIB0::1::INSTR,Standby,300.000,299.999,0.000,0.000,0,0,300.000,300.000,0,0,1
3748811859.720000,GPIB0::1::INSTR,Standby,299.999,299.999,0.000,0.000,0,0,300.000,300.000,1,0,1
3748812009.720000,GPIB0::1::INSTR,Standby,299.998,299.999,0.000,0.000,0,0,300.000,300.000,1,0,1
3748812159.720000,GPIB0::1::INSTR,Standby,300.001,300.000,0.000,0.000,0,0,300.000,300.000,1,0,1
3748812309.720000,GPIB0::1::INSTR,Standby,300.001,299.999,0.000,0.000,0,0,300.000,300.000,1,0,1
3748812459.720000,GPIB0::1::INSTR,Standby,299.998,300.001,0.000,0.000,0,0,300.000,300.000,1,0,1
3748812609.720000,GPIB0::1::INSTR,Standby,300.000,300.000,0.000,0.000,0,0,300.000,300.000,1,0,1
3748812759.720000,GPIB0::1::INSTR,Standby,299.999,300.001,0.000,0.000,0,0,300.000,300.000,1,0,1
3748812909.720000,GPIB0::1::INSTR,Standby,300.000,299.998,0.000,0.000,0,0,300.000,300.000,1,0,1
3748813059.720000,GPIB0::1::INSTR,Standby,299.999,300.000,0.000,0.000,0,0,300.000,300.000,0,0,1
3748813209.720000,GPIB0::1::INSTR,Standby,299.999,300.000,0.000,0.000,0,0,300.000,300.000,1,0,1
3748813359.720000,GPIB0::1::INSTR,Standby,300.001,299.999,0.000,0.000,0,0,300.000,300.000,1,0,1
3748813509.720000,GPIB0::1::INSTR,Standby,300.000,300.001,0.000,0.000,0,0,300.000,300.000,0,0,1
3748813659.720000,GPIB0::1::INSTR,Standby,300.002,300.000,0.000,0.000,0,0,300.000,300.000,1,0,1
3748813809.720000,GPIB0::1::INSTR,Standby,300.002,300.000,0.000,0.000,0,0,300.000,300.000,1,0,1
3748813959.720000,GPIB0::1::INSTR,Standby,300.002,299.999,0.000,0.000,0,0,300.000,300.000,1,0,1
3748814109.720000,GPIB0::1::INSTR,Standby,300.001,300.000,0.000,0.000,0,0,300.000,300.000,1,0,1
3748814259.720000,GPIB0::1::INSTR,Standby,299.999,300.001,0.000,0.000,0,0,300.000,300.000,1,0,1
3748814409.720000,GPIB0::1::INSTR,Standby,299.997,300.001,0.000,0.000,0,0,300.000,300.000,1,0,1
3748814559.720000,GPIB0::1::INSTR,Standby,299.997,300.000,0.000,0.000,0,0,300.000,300.000,1,0,1
3748814709.720000,GPIB0::1::INSTR,Standby,300.001,299.999,0.000,0.000,0,0,300.000,300.000,1,0,1
3748814859.720000,GPIB0::1::INSTR,Standby,300.000,300.001,0.000,0.000,0,0,300.000,300.000,1,0,1
3748815009.720000,GPIB0::1::INSTR,Standby,299.997,299.999,0.000,0.000,0,0,300.000,300.000,1,0,1
3748815159.720000,GPIB0::1::INSTR,Standby,300.001,300.000,0.000,0.000,0,0,300.000,300.000,1,0,1
3748815309.720000,GPIB0::1::INSTR,Standby,299.998,300.000,0.000,0.000,0,0,300.000,300.000,1,0,1
3748815459.720000,GPIB0::1::INSTR,Standby,300.002,300.000,0.000,0.000,0,0,300.000,300.000,1,0,1
3748815609.720000,GPIB0::1::INSTR,Standby,300.000,300.000,0.000,0.000,0,0,300.000,300.000,1,0,1
3748815759.720000,GPIB0::1::INSTR,Standby,300.002,300.000,0.000,0.000,0,0,300.000,300.000,1,0,1
3748815909.720000,GPIB0::1::INSTR,Standby,300.002,300.001,0.000,0.000,0,0,300.000,300.000,1,0,1
3748816059.720000,GPIB0::1::INSTR,Standby,299.953,300.011,0.000,0.000,0,0,300.000,300.000,1,0,4
3748816209.720000,GPIB0::1::INSTR,Standby,299.675,299.842,0.000,0.000,0,0,2.000,2.000,0,0,4
3748816359.720000,GPIB0::1::INSTR,Standby,299.332,299.604,0.000,0.000,0,0,2.000,2.000,0,0,4
3748816509.720000,GPIB0::1::INSTR,Standby,299.049,299.383,0.000,0.000,0,0,2.000,2.000,0,0,4
3748816659.720000,GPIB0::1::INSTR,Standby,298.818,299.175,0.000,0.000,0,0,2.000,2.000,0,0,4
3748816689.720000,GPIB0::1::INSTR,Standby,298.776,299.135,0.000,0.000,0,0,2.000,2.000,0,0,4