File: log/20221017.dat
[Header]
; Displex Transport Data File (default extension .dat)
; Copyright 2016, Hechang LEI, hlei@ruc.edu.cn. All rights reserved.
BYAPP, Displex, 2.0
INFO, 9T mag, Release 2.0.
INFO, Channel 1, Temperature Sensor
INFO, Sample 1 Length (cm): 0.000000; Width (cm): 0.000000; Thickness (cm): 0.000000.

[Data]
Timestamp(s),Field(Oe),Field Status,TempA(K),TempB(K),TempC(K),TempD(K),Ramp1,Ramp2,Setpoint1,Setpoint2,Output1(%),Output2(%),Temp Status
3748816722.372000,GPIB0::1::INSTR,Standby,298.731,299.096,0.000,0.000,0,0,2.000,2.000,0,0,4
3748816938.559000,GPIB0::1::INSTR,Standby,298.475,298.837,0.000,0.000,1,1,2.000,2.000,0,0,0
3748817036.536000,GPIB0::1::INSTR,Standby,298.371,298.731,0.000,0.000,1,1,2.000,2.000,0,0,3
3748817221.096000,GPIB0::1::INSTR,Standby,298.195,298.546,0.000,0.000,1,1,2.000,2.000,0,0,0
3748817341.096000,GPIB0::1::INSTR,Standby,298.096,298.436,0.000,0.000,1,1,2.000,2.000,0,0,0
3748817461.096000,GPIB0::1::INSTR,Standby,298.002,298.335,0.000,0.000,1,1,2.000,2.000,0,0,0
3748817581.096000,GPIB0::1::INSTR,Standby,297.908,298.235,0.000,0.000,1,1,2.000,2.000,0,0,0
3748817701.096000,GPIB0::1::INSTR,Standby,297.817,298.139,0.000,0.000,1,1,2.000,2.000,0,0,3
3748817821.096000,GPIB0::1::INSTR,Standby,297.724,298.043,0.000,0.000,1,1,2.000,2.000,0,0,3
3748817941.096000,GPIB0::1::INSTR,Standby,297.628,297.945,0.000,0.000,1,1,2.000,2.000,0,0,0
3748818061.096000,GPIB0::1::INSTR,Standby,297.525,297.843,0.000,0.000,1,1,2.000,2.000,0,0,3
3748818181.096000,GPIB0::1::INSTR,Standby,297.419,297.739,0.000,0.000,0,0,2.000,2.000,0,0,4
3748818301.096000,GPIB0::1::INSTR,Standby,297.313,297.636,0.000,0.000,0,0,2.000,2.000,0,0,4
3748818421.096000,GPIB0::1::INSTR,Standby,297.206,297.530,0.000,0.000,0,0,2.000,2.000,0,0,4
3748818541.096000,GPIB0::1::INSTR,Standby,297.094,297.422,0.000,0.000,0,0,2.000,2.000,0,0,4
3748818661.096000,GPIB0::1::INSTR,Standby,296.983,297.313,0.000,0.000,0,0,2.000,2.000,0,0,4
3748818781.096000,GPIB0::1::INSTR,Standby,296.871,297.204,0.000,0.000,0,0,2.000,2.000,0,0,4
3748818901.096000,GPIB0::1::INSTR,Standby,296.760,297.094,0.000,0.000,0,0,2.000,2.000,0,0,4
3748819021.096000,GPIB0::1::INSTR,Standby,312.036,297.208,0.000,0.000,0,0,296.000,2.000,0,0,4
3748819141.096000,GPIB0::1::INSTR,Standby,308.238,298.081,0.000,0.000,0,0,296.000,2.000,0,0,4
3748819261.096000,GPIB0::1::INSTR,Standby,305.880,298.776,0.000,0.000,0,0,296.000,2.000,0,0,4
3748819381.096000,GPIB0::1::INSTR,Standby,304.108,299.177,0.000,0.000,0,0,296.000,2.000,0,0,4
3748819501.096000,GPIB0::1::INSTR,Standby,302.709,299.348,0.000,0.000,0,0,296.000,2.000,0,0,4
3748819621.096000,GPIB0::1::INSTR,Standby,302.969,299.402,0.000,0.000,0,0,296.000,2.000,0,0,4
3748819741.096000,GPIB0::1::INSTR,Standby,301.995,299.413,0.000,0.000,0,0,310.000,310.000,0,0,4
3748819861.096000,GPIB0::1::INSTR,Standby,300.973,299.337,0.000,0.000,0,0,310.000,310.000,0,0,4
3748819981.096000,GPIB0::1::INSTR,Standby,302.181,302.494,0.000,0.000,0,0,296.000,296.000,0,0,4
3748820101.096000,GPIB0::1::INSTR,Standby,302.791,302.194,0.000,0.000,0,0,296.000,296.000,0,0,4
3748820221.096000,GPIB0::1::INSTR,Standby,303.595,301.570,0.000,0.000,0,0,296.000,296.000,0,0,4
3748820341.096000,GPIB0::1::INSTR,Standby,305.737,301.206,0.000,0.000,0,0,296.000,296.000,0,0,4
3748820461.096000,GPIB0::1::INSTR,Standby,303.921,301.019,0.000,0.000,0,0,296.000,296.000,0,0,4
3748820581.096000,GPIB0::1::INSTR,Standby,302.541,300.789,0.000,0.000,0,0,296.000,296.000,0,0,4
3748820748.633000,GPIB0::1::INSTR,Standby,302.258,300.416,0.000,0.000,0,0,296.000,296.000,0,0,4
3748820868.633000,GPIB0::1::INSTR,Standby,301.178,300.155,0.000,0.000,0,0,296.000,296.000,0,0,4
3748820988.633000,GPIB0::1::INSTR,Standby,300.302,299.851,0.000,0.000,1,1,300.000,300.000,0,0,3
3748821108.633000,GPIB0::1::INSTR,Standby,300.199,299.998,0.000,0.000,0,0,300.000,300.000,1,0,1
3748821231.359000,GPIB0::1::INSTR,Standby,300.130,300.000,0.000,0.000,0,0,300.000,300.000,1,0,1
3748821390.658000,0.000,Standby,299.981,300.001,0.000,0.000,0,0,300.000,300.000,1,0,1
3748821510.658000,0.000,Standby,299.919,300.000,0.000,0.000,0,0,300.000,300.000,1,0,1
3748821630.658000,0.000,Standby,299.923,300.000,0.000,0.000,0,0,300.000,300.000,1,0,1
3748821750.658000,0.000,Standby,299.957,300.000,0.000,0.000,0,0,300.000,300.000,2,1,1
3748821870.658000,0.000,Standby,299.992,300.002,0.000,0.000,0,0,300.000,300.000,2,0,1
3748821990.658000,0.000,Standby,300.006,300.000,0.000,0.000,0,0,300.000,300.000,2,0,1
3748822110.658000,0.000,Standby,300.006,299.999,0.000,0.000,0,0,300.000,300.000,2,1,1
3748850882.321000,0.000,Standby,300.001,299.996,0.000,0.000,0,0,300.000,300.000,1,0,1
3748851002.321000,0.000,Standby,300.002,300.001,0.000,0.000,0,0,300.000,300.000,1,0,1
3748851122.321000,0.000,Standby,300.001,299.998,0.000,0.000,0,0,300.000,300.000,1,0,1
3748851286.128000,0.000,Standby,300.002,300.000,0.000,0.000,0,0,300.000,300.000,1,0,1
3748851423.025000,0.000,Standby,300.003,299.998,0.000,0.000,0,0,300.000,300.000,1,0,1
3748851556.351000,0.000,Standby,300.075,299.983,0.000,0.000,0,0,300.000,300.000,1,0,1
3748851676.351000,0.000,Standby,300.058,300.000,0.000,0.000,0,0,300.000,300.000,1,0,1
3748851964.802000,0.000,Standby,300.033,300.643,0.000,0.000,1,1,310.000,310.000,2,4,2
3748852084.802000,0.000,Standby,300.992,302.668,0.000,0.000,1,1,310.000,310.000,5,5,2
3748852204.802000,0.000,Standby,303.098,304.661,0.000,0.000,1,1,310.000,310.000,8,6,2
3748852324.802000,0.000,Standby,305.763,306.658,0.000,0.000,1,1,310.000,310.000,10,6,2
3748852444.802000,0.000,Standby,308.361,308.652,0.000,0.000,1,1,310.000,310.000,11,7,2
3748852564.802000,0.000,Standby,310.551,310.042,0.000,0.000,0,0,310.000,310.000,10,4,4
3748852684.802000,0.000,Standby,311.531,310.005,0.000,0.000,0,0,310.000,310.000,7,2,1
3748852804.802000,0.000,Standby,311.256,310.002,0.000,0.000,0,0,310.000,310.000,4,2,1
3748852924.802000,0.000,Standby,310.482,309.999,0.000,0.000,0,0,310.000,310.000,3,2,1
3748853044.802000,0.000,Standby,309.843,310.000,0.000,0.000,0,0,310.000,310.000,4,2,1
3748853164.802000,0.000,Standby,309.613,309.997,0.000,0.000,0,0,310.000,310.000,4,2,1
3748853284.802000,0.000,Standby,309.715,310.000,0.000,0.000,0,0,310.000,310.000,5,2,1
3748853404.802000,0.000,Standby,309.931,310.001,0.000,0.000,0,0,310.000,310.000,5,2,1
3748853524.802000,0.000,Standby,310.094,310.001,0.000,0.000,0,0,310.000,310.000,5,2,1
3748858038.346000,0.000,Standby,309.781,309.186,0.000,0.000,1,1,300.000,300.000,2,0,3
3748858158.346000,0.000,Standby,308.501,308.370,0.000,0.000,1,1,300.000,300.000,0,0,3
3748858278.346000,0.000,Standby,307.156,307.625,0.000,0.000,1,1,300.000,300.000,0,0,3
3748858398.346000,0.000,Standby,306.066,306.916,0.000,0.000,1,1,300.000,300.000,0,0,3
3748858518.346000,0.000,Standby,305.148,306.237,0.000,0.000,1,1,300.000,300.000,0,0,3
3748858638.346000,0.000,Standby,304.370,305.605,0.000,0.000,0,0,300.000,300.000,0,0,4
3748858758.346000,0.000,Standby,303.706,305.015,0.000,0.000,0,0,300.000,300.000,0,0,4
3748858878.346000,0.000,Standby,303.138,304.477,0.000,0.000,0,0,300.000,300.000,0,0,4
3748858998.346000,0.000,Standby,302.638,303.974,0.000,0.000,0,0,300.000,300.000,0,0,4
3748859118.346000,0.000,Standby,302.198,303.513,0.000,0.000,0,0,300.000,300.000,0,0,4
3748859238.346000,0.000,Standby,301.814,303.094,0.000,0.000,0,0,300.000,300.000,0,0,4
3748859358.346000,0.000,Standby,301.472,302.711,0.000,0.000,0,0,300.000,300.000,0,0,4
3748859478.346000,0.000,Standby,301.166,302.356,0.000,0.000,0,0,300.000,300.000,0,0,4
3748859598.346000,0.000,Standby,300.885,302.029,0.000,0.000,0,0,300.000,300.000,0,0,4
3748859718.346000,0.000,Standby,300.638,301.732,0.000,0.000,0,0,300.000,300.000,0,0,4
3748859838.346000,0.000,Standby,300.411,301.454,0.000,0.000,0,0,300.000,300.000,0,0,4
3748859958.346000,0.000,Standby,300.201,301.199,0.000,0.000,0,0,300.000,300.000,0,0,4
3748860078.346000,0.000,Standby,300.008,300.964,0.000,0.000,0,0,300.000,300.000,0,0,4
3748860198.346000,0.000,Standby,299.868,300.743,0.000,0.000,0,0,300.000,300.000,0,0,4
3748860318.346000,0.000,Standby,299.828,300.540,0.000,0.000,0,0,300.000,300.000,0,0,4
3748860438.346000,0.000,Standby,299.878,300.364,0.000,0.000,0,0,300.000,300.000,0,0,4
3748860558.346000,0.000,Standby,299.950,300.215,0.000,0.000,0,0,300.000,300.000,0,0,4
3748860678.346000,0.000,Standby,300.001,300.084,0.000,0.000,0,0,300.000,300.000,0,0,4
3748860798.346000,0.000,Standby,300.017,299.994,0.000,0.000,0,0,300.000,300.000,0,0,1
3748860918.346000,0.000,Standby,300.008,300.001,0.000,0.000,0,0,300.000,300.000,0,0,1
3748861038.346000,0.000,Standby,299.989,300.000,0.000,0.000,0,0,300.000,300.000,0,0,1
3748861158.346000,0.000,Standby,299.982,299.999,0.000,0.000,0,0,300.000,300.000,0,0,1
3748861278.346000,0.000,Standby,299.980,299.999,0.000,0.000,0,0,300.000,300.000,0,0,1
3748861398.346000,0.000,Standby,299.983,300.001,0.000,0.000,0,0,300.000,300.000,0,0,1
3748861518.346000,0.000,Standby,299.988,299.999,0.000,0.000,0,0,300.000,300.000,0,0,1
3748861638.346000,0.000,Standby,299.991,299.998,0.000,0.000,0,0,300.000,300.000,0,0,1
3748861758.346000,0.000,Standby,299.994,300.000,0.000,0.000,0,0,300.000,300.000,0,0,1
3748861878.346000,0.000,Standby,299.994,300.000,0.000,0.000,0,0,300.000,300.000,0,0,1
3748861998.346000,0.000,Standby,299.991,299.999,0.000,0.000,0,0,300.000,300.000,0,0,1
3748862118.346000,0.000,Standby,299.990,299.998,0.000,0.000,0,0,300.000,300.000,0,0,1
3748862238.346000,0.000,Standby,299.991,300.000,0.000,0.000,0,0,300.000,300.000,0,0,1
3748862358.346000,0.000,Standby,299.993,300.002,0.000,0.000,0,0,300.000,300.000,0,0,1
3748862478.346000,0.000,Standby,299.995,300.000,0.000,0.000,0,0,300.000,300.000,0,0,1
3748862598.346000,0.000,Standby,299.994,299.998,0.000,0.000,0,0,300.000,300.000,0,0,1
3748862718.346000,0.000,Standby,299.993,299.999,0.000,0.000,0,0,300.000,300.000,1,0,1
3748862838.346000,0.000,Standby,299.995,300.000,0.000,0.000,0,0,300.000,300.000,1,0,1
3748862958.346000,0.000,Standby,299.993,299.999,0.000,0.000,0,0,300.000,300.000,1,0,1
3748863078.346000,0.000,Standby,299.996,300.000,0.000,0.000,0,0,300.000,300.000,1,0,1
3748863198.346000,0.000,Standby,299.995,300.001,0.000,0.000,0,0,300.000,300.000,1,0,1
3748863318.346000,0.000,Standby,299.995,299.999,0.000,0.000,0,0,300.000,300.000,1,0,1
3748863438.346000,0.000,Standby,299.995,300.000,0.000,0.000,0,0,300.000,300.000,1,0,1
3748863558.346000,0.000,Standby,299.997,299.998,0.000,0.000,0,0,300.000,300.000,1,0,1
3748863678.346000,0.000,Standby,299.996,299.999,0.000,0.000,0,0,300.000,300.000,1,0,1
3748863798.346000,0.000,Standby,299.998,299.999,0.000,0.000,0,0,300.000,300.000,1,0,1
3748863918.346000,0.000,Standby,299.997,300.000,0.000,0.000,0,0,300.000,300.000,1,0,1
3748864038.346000,0.000,Standby,299.997,299.998,0.000,0.000,0,0,300.000,300.000,1,0,1
3748864158.346000,0.000,Standby,300.000,300.000,0.000,0.000,0,0,300.000,300.000,1,0,1
3748864278.346000,0.000,Standby,299.996,299.999,0.000,0.000,0,0,300.000,300.000,1,0,1
3748864398.346000,0.000,Standby,299.996,300.000,0.000,0.000,0,0,300.000,300.000,1,0,1
3748864518.346000,0.000,Standby,299.997,300.000,0.000,0.000,0,0,300.000,300.000,1,0,1
3748864638.346000,0.000,Standby,299.997,300.000,0.000,0.000,0,0,300.000,300.000,1,0,1
3748864758.346000,0.000,Standby,299.997,299.999,0.000,0.000,0,0,300.000,300.000,1,0,1
3748864878.346000,0.000,Standby,299.999,300.001,0.000,0.000,0,0,300.000,300.000,1,0,1
3748864998.346000,0.000,Standby,299.998,300.001,0.000,0.000,0,0,300.000,300.000,1,0,1
3748865118.346000,0.000,Standby,299.998,300.000,0.000,0.000,0,0,300.000,300.000,1,0,1
3748865238.346000,0.000,Standby,299.998,300.000,0.000,0.000,0,0,300.000,300.000,1,0,1
3748865358.346000,0.000,Standby,299.999,300.000,0.000,0.000,0,0,300.000,300.000,1,0,1
3748865478.346000,0.000,Standby,299.999,300.000,0.000,0.000,0,0,300.000,300.000,1,0,1
3748865598.346000,0.000,Standby,299.997,300.000,0.000,0.000,0,0,300.000,300.000,1,0,1
3748865718.346000,0.000,Standby,299.998,299.999,0.000,0.000,0,0,300.000,300.000,1,0,1
3748865838.346000,0.000,Standby,300.001,299.999,0.000,0.000,0,0,300.000,300.000,1,0,1
3748865958.346000,0.000,Standby,299.999,300.001,0.000,0.000,0,0,300.000,300.000,1,0,1
3748866078.346000,0.000,Standby,299.999,300.001,0.000,0.000,0,0,300.000,300.000,1,0,1
3748866198.346000,0.000,Standby,300.000,300.000,0.000,0.000,0,0,300.000,300.000,1,0,1
3748866318.346000,0.000,Standby,299.998,300.003,0.000,0.000,0,0,300.000,300.000,1,0,1
3748866438.346000,0.000,Standby,300.000,300.000,0.000,0.000,0,0,300.000,300.000,1,0,1
3748866558.346000,0.000,Standby,300.000,300.000,0.000,0.000,0,0,300.000,300.000,1,0,1
3748866678.346000,0.000,Standby,299.999,300.000,0.000,0.000,0,0,300.000,300.000,1,0,1
3748866798.346000,0.000,Standby,300.001,300.000,0.000,0.000,0,0,300.000,300.000,1,0,1
3748866918.346000,0.000,Standby,299.999,299.999,0.000,0.000,0,0,300.000,300.000,1,0,1
3748867038.346000,0.000,Standby,299.999,300.002,0.000,0.000,0,0,300.000,300.000,1,0,1
3748867158.346000,0.000,Standby,299.999,299.998,0.000,0.000,0,0,300.000,300.000,1,0,1
3748867278.346000,0.000,Standby,299.999,300.000,0.000,0.000,0,0,300.000,300.000,1,0,1
3748867398.346000,0.000,Standby,299.998,299.999,0.000,0.000,0,0,300.000,300.000,1,0,1
3748867518.346000,0.000,Standby,299.997,300.000,0.000,0.000,0,0,300.000,300.000,1,0,1
3748867638.346000,0.000,Standby,300.002,299.999,0.000,0.000,0,0,300.000,300.000,1,0,1
3748867758.346000,0.000,Standby,299.998,299.999,0.000,0.000,0,0,300.000,300.000,1,0,1
3748867878.346000,0.000,Standby,300.000,300.000,0.000,0.000,0,0,300.000,300.000,1,0,1
3748867998.346000,0.000,Standby,300.000,300.002,0.000,0.000,0,0,300.000,300.000,1,0,1
3748868118.346000,0.000,Standby,300.000,299.999,0.000,0.000,0,0,300.000,300.000,1,0,1
3748868238.346000,0.000,Standby,299.999,300.002,0.000,0.000,0,0,300.000,300.000,1,0,1
3748868358.346000,0.000,Standby,299.998,300.000,0.000,0.000,0,0,300.000,300.000,1,0,1
3748868478.346000,0.000,Standby,300.000,300.000,0.000,0.000,0,0,300.000,300.000,1,0,1
3748868598.346000,0.000,Standby,299.999,300.000,0.000,0.000,0,0,300.000,300.000,1,0,1
3748868718.346000,0.000,Standby,299.999,300.000,0.000,0.000,0,0,300.000,300.000,1,0,1
3748868838.346000,0.000,Standby,300.000,299.999,0.000,0.000,0,0,300.000,300.000,1,0,1
3748868958.346000,0.000,Standby,300.000,299.999,0.000,0.000,0,0,300.000,300.000,1,0,1
3748869078.346000,0.000,Standby,299.999,300.000,0.000,0.000,0,0,300.000,300.000,1,0,1
3748869198.346000,0.000,Standby,300.002,299.999,0.000,0.000,0,0,300.000,300.000,1,0,1
3748869318.346000,0.000,Standby,300.000,300.000,0.000,0.000,0,0,300.000,300.000,1,0,1
3748869438.346000,0.000,Standby,300.001,300.000,0.000,0.000,0,0,300.000,300.000,1,0,1
3748869558.346000,0.000,Standby,300.000,300.000,0.000,0.000,0,0,300.000,300.000,1,0,1
3748869678.346000,0.000,Standby,299.999,299.999,0.000,0.000,0,0,300.000,300.000,1,0,1
3748869798.346000,0.000,Standby,299.999,299.999,0.000,0.000,0,0,300.000,300.000,1,0,1
3748869918.346000,0.000,Standby,300.000,300.000,0.000,0.000,0,0,300.000,300.000,1,0,1
3748870038.346000,0.000,Standby,300.001,299.999,0.000,0.000,0,0,300.000,300.000,1,0,1
3748870158.346000,0.000,Standby,299.999,300.002,0.000,0.000,0,0,300.000,300.000,1,0,1
3748870278.346000,0.000,Standby,300.001,299.998,0.000,0.000,0,0,300.000,300.000,1,0,1
3748870398.346000,0.000,Standby,300.001,300.000,0.000,0.000,0,0,300.000,300.000,1,0,1
3748870518.346000,0.000,Standby,300.000,300.001,0.000,0.000,0,0,300.000,300.000,1,0,1
3748870638.346000,0.000,Standby,300.001,300.000,0.000,0.000,0,0,300.000,300.000,1,0,1
3748870758.346000,0.000,Standby,300.000,300.001,0.000,0.000,0,0,300.000,300.000,1,0,1
3748870878.346000,0.000,Standby,300.001,299.999,0.000,0.000,0,0,300.000,300.000,1,0,1
3748870998.346000,0.000,Standby,300.002,300.000,0.000,0.000,0,0,300.000,300.000,1,0,1
3748871118.346000,0.000,Standby,300.002,300.000,0.000,0.000,0,0,300.000,300.000,1,0,1
3748871238.346000,0.000,Standby,300.001,300.000,0.000,0.000,0,0,300.000,300.000,1,0,1
3748871358.346000,0.000,Standby,300.000,299.999,0.000,0.000,0,0,300.000,300.000,1,0,1
3748871478.346000,0.000,Standby,299.998,299.999,0.000,0.000,0,0,300.000,300.000,1,0,1
3748871598.346000,0.000,Standby,299.998,300.000,0.000,0.000,0,0,300.000,300.000,1,0,1
3748871718.346000,0.000,Standby,300.000,300.000,0.000,0.000,0,0,300.000,300.000,1,0,1
3748871838.346000,0.000,Standby,300.000,299.999,0.000,0.000,0,0,300.000,300.000,1,0,1
3748871958.346000,0.000,Standby,300.002,299.999,0.000,0.000,0,0,300.000,300.000,1,0,1
3748872078.346000,0.000,Standby,300.000,300.000,0.000,0.000,0,0,300.000,300.000,1,0,1
3748872198.346000,0.000,Standby,300.000,300.000,0.000,0.000,0,0,300.000,300.000,1,0,1
3748872318.346000,0.000,Standby,300.000,300.002,0.000,0.000,0,0,300.000,300.000,1,0,1
3748872438.346000,0.000,Standby,299.999,300.000,0.000,0.000,0,0,300.000,300.000,1,0,1
3748872558.346000,0.000,Standby,300.000,300.000,0.000,0.000,0,0,300.000,300.000,1,0,1
3748872678.346000,0.000,Standby,300.000,300.001,0.000,0.000,0,0,300.000,300.000,1,0,1
3748872798.346000,0.000,Standby,299.998,300.000,0.000,0.000,0,0,300.000,300.000,1,0,1
3748872918.346000,0.000,Standby,300.001,300.000,0.000,0.000,0,0,300.000,300.000,1,0,1
3748873038.346000,0.000,Standby,300.001,300.000,0.000,0.000,0,0,300.000,300.000,1,0,1
3748873158.346000,0.000,Standby,300.002,300.001,0.000,0.000,0,0,300.000,300.000,1,0,1
3748873278.346000,0.000,Standby,299.999,300.000,0.000,0.000,0,0,300.000,300.000,1,0,1
3748873398.346000,0.000,Standby,300.000,299.999,0.000,0.000,0,0,300.000,300.000,1,0,1
3748873518.346000,0.000,Standby,299.998,299.999,0.000,0.000,0,0,300.000,300.000,1,0,1
3748873638.346000,0.000,Standby,300.001,300.000,0.000,0.000,0,0,300.000,300.000,1,0,1
3748873758.346000,0.000,Standby,300.000,300.001,0.000,0.000,0,0,300.000,300.000,1,0,1
3748873878.346000,0.000,Standby,299.999,300.002,0.000,0.000,0,0,300.000,300.000,1,0,1
3748873998.346000,0.000,Standby,300.001,300.000,0.000,0.000,0,0,300.000,300.000,1,0,1
3748874118.346000,0.000,Standby,300.001,299.999,0.000,0.000,0,0,300.000,300.000,1,0,1
3748874238.346000,0.000,Standby,299.999,300.000,0.000,0.000,0,0,300.000,300.000,1,0,1
3748874358.346000,0.000,Standby,300.000,300.000,0.000,0.000,0,0,300.000,300.000,1,0,1
3748874478.346000,0.000,Standby,300.000,300.001,0.000,0.000,0,0,300.000,300.000,1,0,1
3748874598.346000,0.000,Standby,300.002,299.999,0.000,0.000,0,0,300.000,300.000,1,0,1
3748874718.346000,0.000,Standby,300.000,300.000,0.000,0.000,0,0,300.000,300.000,1,0,1
3748874838.346000,0.000,Standby,299.998,299.998,0.000,0.000,0,0,300.000,300.000,1,0,1
3748874958.346000,0.000,Standby,300.000,300.000,0.000,0.000,0,0,300.000,300.000,1,0,1
3748875078.346000,0.000,Standby,299.999,300.000,0.000,0.000,0,0,300.000,300.000,1,0,1
3748875198.346000,0.000,Standby,300.000,299.999,0.000,0.000,0,0,300.000,300.000,1,0,1
3748875318.346000,0.000,Standby,299.997,299.998,0.000,0.000,0,0,300.000,300.000,1,0,1
3748875438.346000,0.000,Standby,300.001,300.000,0.000,0.000,0,0,300.000,300.000,1,0,1
3748875558.346000,0.000,Standby,300.000,299.999,0.000,0.000,0,0,300.000,300.000,1,0,1
3748875678.346000,0.000,Standby,300.000,300.000,0.000,0.000,0,0,300.000,300.000,1,0,1
3748875798.346000,0.000,Standby,299.999,299.999,0.000,0.000,0,0,300.000,300.000,1,0,1
3748875918.346000,0.000,Standby,300.000,299.999,0.000,0.000,0,0,300.000,300.000,1,0,1
3748876038.346000,0.000,Standby,299.999,300.000,0.000,0.000,0,0,300.000,300.000,1,0,1
3748876158.346000,0.000,Standby,299.999,299.999,0.000,0.000,0,0,300.000,300.000,1,0,1
3748876278.346000,0.000,Standby,299.999,300.000,0.000,0.000,0,0,300.000,300.000,1,0,1
3748876398.346000,0.000,Standby,300.001,299.999,0.000,0.000,0,0,300.000,300.000,1,0,1
3748876518.346000,0.000,Standby,300.000,300.001,0.000,0.000,0,0,300.000,300.000,1,0,1
3748876638.346000,0.000,Standby,300.000,300.000,0.000,0.000,0,0,300.000,300.000,1,0,1
3748876758.346000,0.000,Standby,300.000,300.000,0.000,0.000,0,0,300.000,300.000,1,0,1
3748876878.346000,0.000,Standby,299.999,300.000,0.000,0.000,0,0,300.000,300.000,1,0,1
3748876998.346000,0.000,Standby,300.002,299.999,0.000,0.000,0,0,300.000,300.000,1,0,1
3748877118.346000,0.000,Standby,300.001,300.001,0.000,0.000,0,0,300.000,300.000,1,0,1
3748877238.346000,0.000,Standby,300.000,300.000,0.000,0.000,0,0,300.000,300.000,1,0,1
3748877358.346000,0.000,Standby,300.001,300.001,0.000,0.000,0,0,300.000,300.000,1,0,1
3748877478.346000,0.000,Standby,300.001,299.999,0.000,0.000,0,0,300.000,300.000,1,0,1
3748877598.346000,0.000,Standby,300.000,300.000,0.000,0.000,0,0,300.000,300.000,1,0,1
3748877718.346000,0.000,Standby,300.000,299.997,0.000,0.000,0,0,300.000,300.000,1,0,1
3748877838.346000,0.000,Standby,300.002,300.000,0.000,0.000,0,0,300.000,300.000,1,0,1
3748877958.346000,0.000,Standby,300.001,300.001,0.000,0.000,0,0,300.000,300.000,1,0,1
3748878078.346000,0.000,Standby,300.002,300.001,0.000,0.000,0,0,300.000,300.000,1,0,1
3748878198.346000,0.000,Standby,299.998,300.000,0.000,0.000,0,0,300.000,300.000,1,0,1
3748878318.346000,0.000,Standby,299.998,300.000,0.000,0.000,0,0,300.000,300.000,1,0,1
3748878438.346000,0.000,Standby,299.999,299.999,0.000,0.000,0,0,300.000,300.000,1,0,1
3748878558.346000,0.000,Standby,300.001,300.001,0.000,0.000,0,0,300.000,300.000,1,0,1
3748878678.346000,0.000,Standby,300.000,299.999,0.000,0.000,0,0,300.000,300.000,1,0,1
3748878798.346000,0.000,Standby,300.000,299.999,0.000,0.000,0,0,300.000,300.000,1,0,1
3748878918.346000,0.000,Standby,299.998,300.000,0.000,0.000,0,0,300.000,300.000,1,0,1
3748879038.346000,0.000,Standby,299.998,300.000,0.000,0.000,0,0,300.000,300.000,1,0,1
3748879158.346000,0.000,Standby,300.002,300.001,0.000,0.000,0,0,300.000,300.000,1,0,1
3748879278.346000,0.000,Standby,300.001,300.001,0.000,0.000,0,0,300.000,300.000,1,0,1
3748879398.346000,0.000,Standby,300.000,300.000,0.000,0.000,0,0,300.000,300.000,1,0,1
3748879518.346000,0.000,Standby,299.998,300.001,0.000,0.000,0,0,300.000,300.000,1,0,1
3748879638.346000,0.000,Standby,300.002,300.000,0.000,0.000,0,0,300.000,300.000,1,0,1
3748879758.346000,0.000,Standby,300.001,300.000,0.000,0.000,0,0,300.000,300.000,1,0,1
3748879878.346000,0.000,Standby,300.001,299.998,0.000,0.000,0,0,300.000,300.000,1,0,1
3748879998.346000,0.000,Standby,300.000,300.002,0.000,0.000,0,0,300.000,300.000,1,0,1
3748880118.346000,0.000,Standby,300.001,299.999,0.000,0.000,0,0,300.000,300.000,1,0,1
3748880238.346000,0.000,Standby,300.001,299.998,0.000,0.000,0,0,300.000,300.000,1,0,1
3748880358.346000,0.000,Standby,300.000,299.999,0.000,0.000,0,0,300.000,300.000,1,0,1
3748880478.346000,0.000,Standby,300.002,300.000,0.000,0.000,0,0,300.000,300.000,1,0,1
3748880598.346000,0.000,Standby,300.000,300.000,0.000,0.000,0,0,300.000,300.000,1,0,1
3748880718.346000,0.000,Standby,300.001,300.000,0.000,0.000,0,0,300.000,300.000,1,0,1
3748880838.346000,0.000,Standby,299.998,300.001,0.000,0.000,0,0,300.000,300.000,1,0,1
3748880958.346000,0.000,Standby,300.000,300.000,0.000,0.000,0,0,300.000,300.000,1,0,1
3748881078.346000,0.000,Standby,300.000,300.000,0.000,0.000,0,0,300.000,300.000,1,0,1
3748881198.346000,0.000,Standby,300.000,300.001,0.000,0.000,0,0,300.000,300.000,1,0,1
3748881318.346000,0.000,Standby,300.000,300.000,0.000,0.000,0,0,300.000,300.000,1,0,1
3748881438.346000,0.000,Standby,300.000,300.000,0.000,0.000,0,0,300.000,300.000,1,0,1
3748881558.346000,0.000,Standby,300.002,300.000,0.000,0.000,0,0,300.000,300.000,1,0,1
3748881678.346000,0.000,Standby,299.999,300.000,0.000,0.000,0,0,300.000,300.000,1,0,1
3748881798.346000,0.000,Standby,300.000,300.000,0.000,0.000,0,0,300.000,300.000,1,0,1
3748881918.346000,0.000,Standby,300.002,299.999,0.000,0.000,0,0,300.000,300.000,1,0,1
3748882038.346000,0.000,Standby,300.001,300.002,0.000,0.000,0,0,300.000,300.000,1,0,1
3748882158.346000,0.000,Standby,300.000,300.001,0.000,0.000,0,0,300.000,300.000,1,0,1
3748882278.346000,0.000,Standby,299.999,299.999,0.000,0.000,0,0,300.000,300.000,1,0,1
3748882398.346000,0.000,Standby,300.000,299.998,0.000,0.000,0,0,300.000,300.000,1,0,1
3748882518.346000,0.000,Standby,300.001,300.000,0.000,0.000,0,0,300.000,300.000,1,0,1
3748882638.346000,0.000,Standby,300.000,299.999,0.000,0.000,0,0,300.000,300.000,1,0,1
3748882758.346000,0.000,Standby,299.999,300.000,0.000,0.000,0,0,300.000,300.000,1,0,1
3748882878.346000,0.000,Standby,299.999,300.001,0.000,0.000,0,0,300.000,300.000,1,0,1
3748882998.346000,0.000,Standby,299.999,300.000,0.000,0.000,0,0,300.000,300.000,1,0,1
3748883118.346000,0.000,Standby,300.001,299.999,0.000,0.000,0,0,300.000,300.000,1,0,1
3748883238.346000,0.000,Standby,300.001,299.999,0.000,0.000,0,0,300.000,300.000,1,0,1
3748883358.346000,0.000,Standby,300.002,299.999,0.000,0.000,0,0,300.000,300.000,1,0,1
3748883478.346000,0.000,Standby,299.998,299.998,0.000,0.000,0,0,300.000,300.000,1,0,1
3748883598.346000,0.000,Standby,299.999,299.999,0.000,0.000,0,0,300.000,300.000,1,0,1
3748883718.346000,0.000,Standby,300.000,300.001,0.000,0.000,0,0,300.000,300.000,1,0,1
3748883838.346000,0.000,Standby,300.002,300.000,0.000,0.000,0,0,300.000,300.000,1,0,1
3748883958.346000,0.000,Standby,300.000,300.001,0.000,0.000,0,0,300.000,300.000,1,0,1
3748884078.346000,0.000,Standby,299.999,300.000,0.000,0.000,0,0,300.000,300.000,1,0,1
3748884198.346000,0.000,Standby,299.999,300.000,0.000,0.000,0,0,300.000,300.000,1,0,1
3748884318.346000,0.000,Standby,300.000,299.999,0.000,0.000,0,0,300.000,300.000,1,0,1
3748884438.346000,0.000,Standby,300.000,299.999,0.000,0.000,0,0,300.000,300.000,1,0,1
3748884558.346000,0.000,Standby,300.001,300.002,0.000,0.000,0,0,300.000,300.000,1,0,1
3748884678.346000,0.000,Standby,299.999,300.000,0.000,0.000,0,0,300.000,300.000,1,0,1
3748884798.346000,0.000,Standby,299.999,299.999,0.000,0.000,0,0,300.000,300.000,1,0,1
3748884918.346000,0.000,Standby,300.001,300.001,0.000,0.000,0,0,300.000,300.000,1,0,1
3748885038.346000,0.000,Standby,300.000,299.999,0.000,0.000,0,0,300.000,300.000,1,0,1
3748885158.346000,0.000,Standby,299.999,299.997,0.000,0.000,0,0,300.000,300.000,1,0,1
3748885278.346000,0.000,Standby,300.000,300.002,0.000,0.000,0,0,300.000,300.000,1,0,1
3748885398.346000,0.000,Standby,299.999,300.000,0.000,0.000,0,0,300.000,300.000,1,0,1
3748885518.346000,0.000,Standby,300.000,300.002,0.000,0.000,0,0,300.000,300.000,1,0,1
3748885638.346000,0.000,Standby,300.000,299.998,0.000,0.000,0,0,300.000,300.000,1,0,1
3748885758.346000,0.000,Standby,299.998,300.000,0.000,0.000,0,0,300.000,300.000,1,0,1
3748885878.346000,0.000,Standby,299.998,300.000,0.000,0.000,0,0,300.000,300.000,1,0,1
3748885998.346000,0.000,Standby,300.001,300.000,0.000,0.000,0,0,300.000,300.000,1,0,1
3748886118.346000,0.000,Standby,299.999,299.998,0.000,0.000,0,0,300.000,300.000,1,0,1
3748886238.346000,0.000,Standby,299.999,300.000,0.000,0.000,0,0,300.000,300.000,1,0,1
3748886358.346000,0.000,Standby,300.000,299.999,0.000,0.000,0,0,300.000,300.000,1,0,1
3748886478.346000,0.000,Standby,299.999,299.999,0.000,0.000,0,0,300.000,300.000,1,0,1
3748886598.346000,0.000,Standby,299.999,300.002,0.000,0.000,0,0,300.000,300.000,1,0,1
3748886718.346000,0.000,Standby,300.000,299.998,0.000,0.000,0,0,300.000,300.000,1,0,1
3748886838.346000,0.000,Standby,299.998,299.999,0.000,0.000,0,0,300.000,300.000,1,0,1
3748886958.346000,0.000,Standby,299.998,300.000,0.000,0.000,0,0,300.000,300.000,1,0,1
3748887078.346000,0.000,Standby,300.001,300.001,0.000,0.000,0,0,300.000,300.000,1,0,1
3748887198.346000,0.000,Standby,300.001,300.000,0.000,0.000,0,0,300.000,300.000,1,0,1
3748887318.346000,0.000,Standby,300.000,300.000,0.000,0.000,0,0,300.000,300.000,1,0,1
3748887438.346000,0.000,Standby,299.999,300.000,0.000,0.000,0,0,300.000,300.000,1,0,1
3748887558.346000,0.000,Standby,300.000,300.002,0.000,0.000,0,0,300.000,300.000,1,0,1
3748887678.346000,0.000,Standby,300.000,300.000,0.000,0.000,0,0,300.000,300.000,1,0,1
3748887798.346000,0.000,Standby,299.999,300.000,0.000,0.000,0,0,300.000,300.000,1,0,1
3748887918.346000,0.000,Standby,299.999,300.000,0.000,0.000,0,0,300.000,300.000,1,0,1
3748888038.346000,0.000,Standby,300.000,299.998,0.000,0.000,0,0,300.000,300.000,1,0,1
3748888158.346000,0.000,Standby,300.000,299.999,0.000,0.000,0,0,300.000,300.000,1,0,1
3748888278.346000,0.000,Standby,300.002,300.000,0.000,0.000,0,0,300.000,300.000,1,0,1
3748888398.346000,0.000,Standby,299.999,299.999,0.000,0.000,0,0,300.000,300.000,1,0,1
3748888518.346000,0.000,Standby,300.000,299.999,0.000,0.000,0,0,300.000,300.000,1,0,1
3748888638.346000,0.000,Standby,299.998,299.999,0.000,0.000,0,0,300.000,300.000,1,0,1
3748888758.346000,0.000,Standby,299.998,300.000,0.000,0.000,0,0,300.000,300.000,1,0,1
3748888878.346000,0.000,Standby,300.000,299.999,0.000,0.000,0,0,300.000,300.000,1,0,1
3748888998.346000,0.000,Standby,300.001,299.998,0.000,0.000,0,0,300.000,300.000,1,0,1
3748889118.346000,0.000,Standby,299.998,300.000,0.000,0.000,0,0,300.000,300.000,1,0,1
3748889238.346000,0.000,Standby,299.998,300.000,0.000,0.000,0,0,300.000,300.000,1,0,1
3748889358.346000,0.000,Standby,299.997,299.998,0.000,0.000,0,0,300.000,300.000,1,0,1
3748889478.346000,0.000,Standby,300.000,300.000,0.000,0.000,0,0,300.000,300.000,1,0,1
3748889598.346000,0.000,Standby,299.999,300.002,0.000,0.000,0,0,300.000,300.000,1,0,1
3748889718.346000,0.000,Standby,300.000,299.999,0.000,0.000,0,0,300.000,300.000,1,0,1
3748889838.346000,0.000,Standby,299.999,300.000,0.000,0.000,0,0,300.000,300.000,1,0,1
3748889958.346000,0.000,Standby,299.998,299.999,0.000,0.000,0,0,300.000,300.000,1,0,1
3748890078.346000,0.000,Standby,299.999,299.998,0.000,0.000,0,0,300.000,300.000,1,0,1
3748890198.346000,0.000,Standby,299.999,300.001,0.000,0.000,0,0,300.000,300.000,1,0,1
3748890318.346000,0.000,Standby,299.999,300.000,0.000,0.000,0,0,300.000,300.000,1,0,1
3748890438.346000,0.000,Standby,300.000,300.001,0.000,0.000,0,0,300.000,300.000,1,0,1
3748890558.346000,0.000,Standby,299.997,299.999,0.000,0.000,0,0,300.000,300.000,1,0,1
3748890678.346000,0.000,Standby,299.999,299.999,0.000,0.000,0,0,300.000,300.000,1,0,1
3748890798.346000,0.000,Standby,300.000,300.000,0.000,0.000,0,0,300.000,300.000,1,0,1
3748890918.346000,0.000,Standby,300.000,299.999,0.000,0.000,0,0,300.000,300.000,1,0,1
3748891038.346000,0.000,Standby,299.999,300.000,0.000,0.000,0,0,300.000,300.000,1,0,1
3748891158.346000,0.000,Standby,299.998,299.999,0.000,0.000,0,0,300.000,300.000,1,0,1
3748891278.346000,0.000,Standby,300.000,300.000,0.000,0.000,0,0,300.000,300.000,1,0,1
3748891398.346000,0.000,Standby,300.001,299.999,0.000,0.000,0,0,300.000,300.000,1,0,1
3748891518.346000,0.000,Standby,300.001,300.000,0.000,0.000,0,0,300.000,300.000,1,0,1
3748891638.346000,0.000,Standby,299.999,299.999,0.000,0.000,0,0,300.000,300.000,1,0,1
3748891758.346000,0.000,Standby,300.000,300.000,0.000,0.000,0,0,300.000,300.000,1,0,1
3748891878.346000,0.000,Standby,300.000,300.002,0.000,0.000,0,0,300.000,300.000,1,0,1
3748891998.346000,0.000,Standby,299.999,300.001,0.000,0.000,0,0,300.000,300.000,1,0,1
3748892118.346000,0.000,Standby,300.000,299.998,0.000,0.000,0,0,300.000,300.000,1,0,1
3748892238.346000,0.000,Standby,299.999,299.998,0.000,0.000,0,0,300.000,300.000,1,0,1
3748892358.346000,0.000,Standby,300.000,300.001,0.000,0.000,0,0,300.000,300.000,1,0,1
3748892478.346000,0.000,Standby,300.000,299.999,0.000,0.000,0,0,300.000,300.000,1,0,1
3748892598.346000,0.000,Standby,300.000,300.000,0.000,0.000,0,0,300.000,300.000,1,0,1
3748892718.346000,0.000,Standby,300.000,299.999,0.000,0.000,0,0,300.000,300.000,1,0,1
3748892838.346000,0.000,Standby,300.001,300.000,0.000,0.000,0,0,300.000,300.000,1,0,1
3748892958.346000,0.000,Standby,299.999,300.000,0.000,0.000,0,0,300.000,300.000,1,0,1
3748893078.346000,0.000,Standby,300.000,300.001,0.000,0.000,0,0,300.000,300.000,1,0,1
3748893198.346000,0.000,Standby,299.999,299.999,0.000,0.000,0,0,300.000,300.000,1,0,1
3748893318.346000,0.000,Standby,300.000,299.999,0.000,0.000,0,0,300.000,300.000,1,0,1
3748893438.346000,0.000,Standby,299.999,300.000,0.000,0.000,0,0,300.000,300.000,1,0,1
3748893558.346000,0.000,Standby,299.999,300.000,0.000,0.000,0,0,300.000,300.000,1,0,1
3748893678.346000,0.000,Standby,300.000,300.001,0.000,0.000,0,0,300.000,300.000,1,0,1
3748893798.346000,0.000,Standby,299.999,300.000,0.000,0.000,0,0,300.000,300.000,1,0,1
3748893918.346000,0.000,Standby,300.000,300.000,0.000,0.000,0,0,300.000,300.000,1,0,1
3748894038.346000,0.000,Standby,299.999,300.000,0.000,0.000,0,0,300.000,300.000,1,0,1
3748894158.346000,0.000,Standby,300.000,299.999,0.000,0.000,0,0,300.000,300.000,1,0,1
3748894278.346000,0.000,Standby,300.002,299.999,0.000,0.000,0,0,300.000,300.000,1,0,1
3748894398.346000,0.000,Standby,299.999,299.999,0.000,0.000,0,0,300.000,300.000,1,0,1
3748894518.346000,0.000,Standby,299.999,299.999,0.000,0.000,0,0,300.000,300.000,1,0,1
3748894638.346000,0.000,Standby,300.000,299.999,0.000,0.000,0,0,300.000,300.000,1,0,1
3748894758.346000,0.000,Standby,300.000,300.000,0.000,0.000,0,0,300.000,300.000,1,0,1
3748894878.346000,0.000,Standby,299.999,300.000,0.000,0.000,0,0,300.000,300.000,1,0,1
3748894998.346000,0.000,Standby,300.000,299.999,0.000,0.000,0,0,300.000,300.000,1,0,1
3748895118.346000,0.000,Standby,300.000,300.000,0.000,0.000,0,0,300.000,300.000,1,0,1
3748895238.346000,0.000,Standby,300.001,300.001,0.000,0.000,0,0,300.000,300.000,1,0,1
3748895358.346000,0.000,Standby,300.000,300.000,0.000,0.000,0,0,300.000,300.000,1,0,1
3748895478.346000,0.000,Standby,299.998,299.999,0.000,0.000,0,0,300.000,300.000,1,0,1
3748895598.346000,0.000,Standby,300.000,299.999,0.000,0.000,0,0,300.000,300.000,1,0,1
3748895718.346000,0.000,Standby,300.000,299.998,0.000,0.000,0,0,300.000,300.000,1,0,1
3748895838.346000,0.000,Standby,299.999,300.000,0.000,0.000,0,0,300.000,300.000,1,0,1
3748895958.346000,0.000,Standby,300.000,300.000,0.000,0.000,0,0,300.000,300.000,1,0,1
3748896078.346000,0.000,Standby,300.000,300.000,0.000,0.000,0,0,300.000,300.000,1,0,1
3748896198.346000,0.000,Standby,300.000,300.001,0.000,0.000,0,0,300.000,300.000,1,0,1
3748896318.346000,0.000,Standby,299.998,300.001,0.000,0.000,0,0,300.000,300.000,1,0,1
3748896438.346000,0.000,Standby,300.002,300.000,0.000,0.000,0,0,300.000,300.000,1,0,1
3748896558.346000,0.000,Standby,300.001,300.000,0.000,0.000,0,0,300.000,300.000,1,0,1
3748896678.346000,0.000,Standby,299.999,300.000,0.000,0.000,0,0,300.000,300.000,1,0,1
3748896798.346000,0.000,Standby,300.000,300.000,0.000,0.000,0,0,300.000,300.000,1,0,1
3748896918.346000,0.000,Standby,299.998,300.000,0.000,0.000,0,0,300.000,300.000,1,0,1
3748897038.346000,0.000,Standby,300.001,300.002,0.000,0.000,0,0,300.000,300.000,1,0,1
3748897158.346000,0.000,Standby,299.997,300.001,0.000,0.000,0,0,300.000,300.000,1,0,1
3748897278.346000,0.000,Standby,299.999,299.998,0.000,0.000,0,0,300.000,300.000,1,0,1
3748897398.346000,0.000,Standby,300.002,299.999,0.000,0.000,0,0,300.000,300.000,1,0,1
3748897518.346000,0.000,Standby,300.000,299.999,0.000,0.000,0,0,300.000,300.000,1,0,1
3748897638.346000,0.000,Standby,299.998,299.999,0.000,0.000,0,0,300.000,300.000,1,0,1
3748897758.346000,0.000,Standby,300.000,300.000,0.000,0.000,0,0,300.000,300.000,1,0,1
3748897878.346000,0.000,Standby,300.000,300.000,0.000,0.000,0,0,300.000,300.000,1,0,1
3748897998.346000,0.000,Standby,300.001,300.000,0.000,0.000,0,0,300.000,300.000,1,0,1
3748898118.346000,0.000,Standby,300.000,300.000,0.000,0.000,0,0,300.000,300.000,1,0,1
3748898238.346000,0.000,Standby,300.000,300.000,0.000,0.000,0,0,300.000,300.000,1,0,1
3748898358.346000,0.000,Standby,300.000,300.000,0.000,0.000,0,0,300.000,300.000,1,0,1
3748898478.346000,0.000,Standby,300.000,300.000,0.000,0.000,0,0,300.000,300.000,1,0,1
3748898598.346000,0.000,Standby,300.000,299.998,0.000,0.000,0,0,300.000,300.000,1,0,1
3748898718.346000,0.000,Standby,300.001,300.002,0.000,0.000,0,0,300.000,300.000,1,0,1
3748898838.346000,0.000,Standby,300.000,299.999,0.000,0.000,0,0,300.000,300.000,1,0,1
3748898958.346000,0.000,Standby,300.000,300.002,0.000,0.000,0,0,300.000,300.000,1,0,1
3748899078.346000,0.000,Standby,299.999,299.999,0.000,0.000,0,0,300.000,300.000,1,0,1
3748899198.346000,0.000,Standby,299.998,299.999,0.000,0.000,0,0,300.000,300.000,1,0,1
3748899318.346000,0.000,Standby,299.999,300.000,0.000,0.000,0,0,300.000,300.000,1,0,1
3748899438.346000,0.000,Standby,299.999,299.998,0.000,0.000,0,0,300.000,300.000,1,0,1
3748899558.346000,0.000,Standby,300.001,299.998,0.000,0.000,0,0,300.000,300.000,1,0,1
3748899678.346000,0.000,Standby,299.998,300.003,0.000,0.000,0,0,300.000,300.000,1,0,1
3748899798.346000,0.000,Standby,300.000,299.999,0.000,0.000,0,0,300.000,300.000,1,0,1
3748899918.346000,0.000,Standby,299.999,299.999,0.000,0.000,0,0,300.000,300.000,1,0,1
3748900038.346000,0.000,Standby,300.000,300.000,0.000,0.000,0,0,300.000,300.000,1,0,1
3748900158.346000,0.000,Standby,299.999,300.001,0.000,0.000,0,0,300.000,300.000,1,0,1
3748900278.346000,0.000,Standby,300.002,299.999,0.000,0.000,0,0,300.000,300.000,1,0,1
3748900398.346000,0.000,Standby,300.001,300.000,0.000,0.000,0,0,300.000,300.000,1,0,1
3748900518.346000,0.000,Standby,299.999,300.000,0.000,0.000,0,0,300.000,300.000,1,0,1
3748900638.346000,0.000,Standby,299.998,300.000,0.000,0.000,0,0,300.000,300.000,1,0,1
3748900758.346000,0.000,Standby,300.000,300.000,0.000,0.000,0,0,300.000,300.000,1,0,1
3748900878.346000,0.000,Standby,299.998,300.000,0.000,0.000,0,0,300.000,300.000,1,0,1
3748900998.346000,0.000,Standby,300.000,299.998,0.000,0.000,0,0,300.000,300.000,1,0,1
3748901118.346000,0.000,Standby,300.000,300.000,0.000,0.000,0,0,300.000,300.000,1,0,1
3748901238.346000,0.000,Standby,300.001,300.000,0.000,0.000,0,0,300.000,300.000,1,0,1
3748901358.346000,0.000,Standby,299.999,299.999,0.000,0.000,0,0,300.000,300.000,1,0,1
3748901478.346000,0.000,Standby,299.999,300.000,0.000,0.000,0,0,300.000,300.000,1,0,1
3748901598.346000,0.000,Standby,300.001,300.002,0.000,0.000,0,0,300.000,300.000,1,0,1
3748901718.346000,0.000,Standby,299.998,299.999,0.000,0.000,0,0,300.000,300.000,1,0,1
3748901838.346000,0.000,Standby,300.000,299.999,0.000,0.000,0,0,300.000,300.000,1,0,1
3748901958.346000,0.000,Standby,299.999,300.000,0.000,0.000,0,0,300.000,300.000,1,0,1
3748902078.346000,0.000,Standby,300.001,299.998,0.000,0.000,0,0,300.000,300.000,1,0,1
3748902198.346000,0.000,Standby,300.000,299.999,0.000,0.000,0,0,300.000,300.000,1,0,1
3748902318.346000,0.000,Standby,300.000,300.001,0.000,0.000,0,0,300.000,300.000,1,0,1
3748902438.346000,0.000,Standby,299.999,300.001,0.000,0.000,0,0,300.000,300.000,1,0,1
3748902558.346000,0.000,Standby,300.000,300.001,0.000,0.000,0,0,300.000,300.000,1,0,1
3748902678.346000,0.000,Standby,300.001,300.000,0.000,0.000,0,0,300.000,300.000,1,0,1
3748902798.346000,0.000,Standby,300.001,300.000,0.000,0.000,0,0,300.000,300.000,1,0,1
3748902918.346000,0.000,Standby,299.942,299.913,0.000,0.000,1,1,2.000,2.000,0,0,3
3748903038.346000,0.000,Standby,299.548,299.690,0.000,0.000,1,1,2.000,2.000,0,0,0
3748903158.346000,0.000,Standby,299.192,299.396,0.000,0.000,1,1,2.000,2.000,0,0,3
3748903278.346000,0.000,Standby,298.938,299.272,0.000,0.000,1,1,2.000,2.000,0,0,0
3748903398.346000,0.000,Standby,298.814,299.232,0.000,0.000,1,1,2.000,2.000,0,0,3
3748903518.346000,0.000,Standby,298.630,299.060,0.000,0.000,1,1,2.000,2.000,0,0,3
3748903638.346000,0.000,Standby,298.469,298.900,0.000,0.000,1,1,2.000,2.000,0,0,3
3748903758.346000,0.000,Standby,298.326,298.751,0.000,0.000,1,1,2.000,2.000,0,0,3
3748903878.346000,0.000,Standby,298.201,298.618,0.000,0.000,1,1,2.000,2.000,0,0,0
3748903998.346000,0.000,Standby,298.079,298.488,0.000,0.000,1,1,2.000,2.000,0,0,0
3748904118.346000,0.000,Standby,297.966,298.362,0.000,0.000,1,1,2.000,2.000,0,0,0
3748904238.346000,0.000,Standby,297.861,298.246,0.000,0.000,1,1,2.000,2.000,0,0,0
3748904358.346000,0.000,Standby,297.755,298.134,0.000,0.000,1,1,2.000,2.000,0,0,3
3748904478.346000,0.000,Standby,297.654,298.024,0.000,0.000,1,1,2.000,2.000,0,0,0
3748904598.346000,0.000,Standby,297.548,297.914,0.000,0.000,1,1,2.000,2.000,0,0,3
3748904718.346000,0.000,Standby,297.443,297.807,0.000,0.000,0,0,2.000,2.000,0,0,4
3748904838.346000,0.000,Standby,297.335,297.698,0.000,0.000,0,0,2.000,2.000,0,0,4
3748904958.346000,0.000,Standby,297.220,297.582,0.000,0.000,0,0,2.000,2.000,0,0,4
3748905078.346000,0.000,Standby,297.103,297.468,0.000,0.000,0,0,2.000,2.000,0,0,4
3748905198.346000,0.000,Standby,296.982,297.350,0.000,0.000,0,0,2.000,2.000,0,0,4