File: log/20221129.dat
[Header]
; Displex Transport Data File (default extension .dat)
; Copyright 2016, Hechang LEI, hlei@ruc.edu.cn. All rights reserved.
BYAPP, Displex, 2.0
INFO, 9T mag, Release 2.0.
INFO, Channel 1, Temperature Sensor
INFO, Sample 1 Length (cm): 0.000000; Width (cm): 0.000000; Thickness (cm): 0.000000.

[Data]
Timestamp(s),Field(Oe),Field Status,TempA(K),TempB(K),TempC(K),TempD(K),Ramp1,Ramp2,Setpoint1,Setpoint2,Output1(%),Output2(%),Temp Status
3752565416.154000,,,300.012,0.000,36.938,3.014,0,0,300.000,300.000,9.840,0.000,4
3752565536.154000,,,300.092,0.000,36.960,3.013,0,0,300.000,300.000,8.060,0.000,4
3752565656.154000,,,300.048,0.000,36.977,3.014,0,0,300.000,300.000,6.950,0.000,4
3752565776.154000,,,297.275,0.000,38.846,5.126,1,1,2.000,2.000,0.000,0.000,0
3752565896.154000,,,294.007,0.000,43.037,5.299,1,1,2.000,2.000,0.000,19.950,0
3752566016.154000,,,290.197,289.784,46.175,5.416,1,1,2.000,2.000,0.000,0.000,0
3752566136.154000,,,285.884,285.924,48.417,5.521,1,1,287.000,287.000,0.000,0.000,3
3752566256.154000,,,288.993,287.339,50.160,5.620,0,0,287.000,287.000,0.000,10.340,4
3752566376.154000,,,286.058,284.755,51.596,5.718,1,1,2.000,2.000,0.000,1.170,0
3752566496.154000,,,279.129,278.784,52.842,5.797,1,1,2.000,2.000,0.000,0.000,3
3752566616.154000,,,272.644,273.031,53.955,5.876,1,1,2.000,2.000,1.920,0.000,3
3752566736.154000,,,266.741,267.130,54.968,5.946,1,1,2.000,2.000,2.550,0.000,3
3752566856.154000,,,261.432,261.164,55.891,6.012,1,1,2.000,2.000,0.000,0.000,3
3752566976.154000,,,254.771,255.162,56.737,6.076,1,1,2.000,2.000,2.920,0.000,3
3752567096.154000,,,248.925,249.198,57.512,6.134,1,1,2.000,2.000,2.930,0.000,3
3752567216.154000,,,243.033,243.313,58.224,6.194,1,1,2.000,2.000,1.680,0.000,3
3752567336.154000,,,237.070,237.544,58.878,6.250,1,1,2.000,2.000,0.660,0.000,3
3752567456.154000,,,231.073,231.878,59.477,6.305,1,1,2.000,2.000,0.490,0.000,3
3752567576.154000,,,225.083,226.277,60.030,6.364,1,1,2.000,2.000,0.790,0.000,3
3752567696.154000,,,219.158,220.768,60.535,6.420,1,1,2.000,2.000,0.840,0.000,3
3752567816.154000,,,213.233,215.228,60.999,6.472,1,1,2.000,2.000,0.600,0.000,3
3752567936.154000,,,207.302,209.778,61.422,6.521,1,1,2.000,2.000,0.000,0.000,3
3752568056.154000,,,201.470,204.358,61.808,6.572,1,1,2.000,2.000,0.000,0.000,3
3752568176.154000,,,195.791,198.991,62.160,6.616,1,1,2.000,2.000,0.000,0.000,3
3752568296.154000,,,190.256,193.687,62.481,6.653,1,1,2.000,2.000,0.000,0.000,3
3752568416.154000,,,184.843,188.451,62.771,6.679,1,1,2.000,2.000,0.000,0.000,3
3752568536.154000,,,179.546,183.290,63.033,6.713,1,1,2.000,2.000,0.000,0.000,3
3752568656.154000,,,174.366,178.199,63.272,6.743,1,1,2.000,2.000,0.000,0.000,3
3752568776.154000,,,169.293,173.195,63.485,6.769,1,1,2.000,2.000,0.000,0.000,3
3752568896.154000,,,164.331,168.290,63.678,6.796,1,1,2.000,2.000,0.000,0.000,3
3752569016.154000,,,159.467,163.468,63.851,6.818,1,1,2.000,2.000,0.000,0.000,3
3752569136.154000,,,154.694,158.745,64.004,6.829,1,1,2.000,2.000,0.000,0.000,3
3752569256.154000,,,150.013,154.036,64.140,6.848,1,1,2.000,2.000,0.000,0.000,3
3752569376.154000,,,145.419,149.428,64.258,6.857,1,1,2.000,2.000,0.000,0.000,3
3752569496.154000,,,140.908,144.898,64.361,6.870,1,1,2.000,2.000,0.000,0.000,3
3752569616.154000,,,136.460,140.481,64.449,6.879,1,1,2.000,2.000,0.000,0.000,3
3752569736.154000,,,132.085,136.127,64.524,6.890,1,1,2.000,2.000,0.000,0.000,3
3752569856.154000,,,127.766,131.811,64.586,6.895,1,1,2.000,2.000,0.000,0.000,3
3752569976.154000,,,123.499,127.563,64.635,6.900,1,1,2.000,2.000,0.000,0.000,3
3752570096.154000,,,119.293,123.346,64.673,6.908,1,1,2.000,2.000,0.000,0.000,3
3752570216.154000,,,115.118,119.171,64.699,6.920,1,1,2.000,2.000,0.000,0.000,3
3752570336.154000,,,110.985,115.094,64.715,6.927,1,1,2.000,2.000,0.000,0.000,3
3752570456.154000,,,106.873,110.966,64.720,6.930,1,1,2.000,2.000,0.000,0.000,3
3752570576.154000,,,102.790,106.863,64.715,6.927,1,1,2.000,2.000,0.000,0.000,3
3752570696.154000,,,98.712,102.806,64.701,6.934,1,1,2.000,2.000,0.000,0.000,3
3752570816.154000,,,94.653,98.735,64.678,6.939,1,1,2.000,2.000,0.000,0.000,3
3752570936.154000,,,90.575,94.685,64.645,6.940,1,1,2.000,2.000,0.000,0.000,3
3752571056.154000,,,86.482,90.617,64.603,6.940,1,1,2.000,2.000,0.000,0.000,3
3752571176.154000,,,82.359,86.507,64.553,6.936,1,1,2.000,2.000,0.000,0.000,3
3752571296.154000,,,78.160,82.381,64.496,6.929,1,1,2.000,2.000,0.000,0.000,3
3752571416.154000,,,73.897,78.131,64.431,7.285,1,1,2.000,2.000,0.000,0.000,3
3752571536.154000,,,69.412,73.686,64.393,8.470,1,1,2.000,2.000,0.000,0.000,3
3752571656.154000,,,64.415,68.769,64.507,8.987,1,1,2.000,2.000,0.000,0.000,3
3752571776.154000,,,58.959,63.475,64.654,9.328,1,1,2.000,2.000,0.000,0.000,3
3752571896.154000,,,53.057,57.661,64.785,9.543,1,1,2.000,2.000,0.000,0.000,3
3752572016.154000,,,46.622,51.255,64.888,9.693,1,1,2.000,2.000,0.000,0.000,3
3752572136.154000,,,39.453,43.849,64.959,9.791,0,0,2.000,2.000,0.000,0.000,4
3752572256.154000,,,31.079,34.497,64.996,9.852,0,0,2.000,2.000,0.000,0.000,4
3752572376.154000,,,20.602,21.192,64.997,9.874,0,0,2.000,2.000,0.000,0.000,4
3752572496.154000,,,12.420,11.701,64.952,9.864,0,0,2.000,2.000,0.000,0.000,4
3752572616.154000,,,11.216,10.617,64.852,9.808,0,0,2.000,2.000,0.000,0.000,4
3752572736.154000,,,10.841,10.349,64.715,9.746,0,0,2.000,2.000,0.000,0.000,4
3752572856.154000,,,10.592,10.157,64.575,9.680,0,0,2.000,2.000,0.000,0.000,4
3752572976.154000,,,10.453,10.048,64.448,9.626,0,0,2.000,2.000,0.000,0.000,4
3752573096.154000,,,10.328,9.951,64.339,9.583,0,0,2.000,2.000,0.000,0.000,4
3752573216.154000,,,10.243,9.890,64.246,9.546,0,0,2.000,2.000,0.000,0.000,4
3752573336.154000,,,10.153,9.843,64.168,9.508,0,0,2.000,2.000,0.000,0.000,4
3752573456.154000,,,10.105,9.777,64.102,9.483,0,0,2.000,2.000,0.000,0.000,4
3752573576.154000,,,10.043,9.727,64.045,9.465,0,0,2.000,2.000,0.000,0.000,4
3752573696.154000,,,9.980,9.707,63.998,9.442,0,0,2.000,2.000,0.000,0.000,4
3752573816.154000,,,9.948,9.679,63.957,9.434,0,0,2.000,2.000,0.000,0.000,4
3752573936.154000,,,9.885,9.648,63.923,9.018,0,0,2.000,2.000,0.000,0.000,4
3752574056.154000,,,6.856,6.528,63.897,5.381,0,0,2.000,2.000,0.000,0.000,4
3752574176.154000,,,4.354,3.949,63.481,4.436,0,0,2.000,2.000,0.000,0.000,4
3752574296.154000,,,3.206,2.765,62.732,4.300,0,0,2.000,2.000,0.000,0.000,4
3752574416.154000,,,2.814,2.351,61.828,4.248,0,0,2.000,2.000,0.000,0.000,4
3752574536.154000,,,2.795,2.333,60.872,4.216,0,0,2.000,2.000,0.000,0.000,4
3752574656.154000,,,2.765,2.337,59.918,4.185,0,0,2.000,2.000,0.000,0.000,4
3752574776.154000,,,2.714,2.285,58.986,4.151,0,0,2.000,2.000,0.000,0.000,4
3752574896.154000,,,2.683,2.274,58.084,4.112,0,0,2.000,2.000,0.000,0.000,4
3752575016.154000,,,2.660,2.270,57.212,4.071,0,0,2.000,2.000,0.000,0.000,4
3752575136.154000,,,2.652,2.244,56.371,4.028,0,0,2.000,2.000,0.000,0.000,4
3752575256.154000,,,2.067,2.000,55.606,3.403,0,0,2.000,2.000,0.070,0.030,4
3752575376.154000,,,2.076,2.000,54.536,3.295,0,0,2.000,2.000,0.110,0.020,4
3752575496.154000,,,2.087,2.000,53.297,3.295,0,0,2.000,2.000,0.200,0.020,4
3752575616.154000,,,2.086,2.000,52.099,3.288,0,0,2.000,2.000,0.090,0.020,1
3752575736.154000,,,2.083,2.000,50.984,3.279,0,0,2.000,2.000,0.080,0.020,1
3752575856.154000,,,2.084,2.000,49.952,3.275,0,0,2.000,2.000,0.230,0.020,1
3752575976.154000,,,2.082,2.000,48.999,3.271,0,0,2.000,2.000,0.250,0.020,1
3752576096.154000,,,2.074,2.000,48.118,3.268,0,0,2.000,2.000,0.240,0.020,1
3752576216.154000,,,2.070,2.000,47.308,3.267,0,0,2.000,2.000,0.000,0.020,1
3752576336.154000,,,2.078,2.000,46.566,3.264,0,0,2.000,2.000,0.000,0.020,1
3752576456.154000,,,2.082,2.000,45.883,3.263,0,0,2.000,2.000,0.190,0.020,1
3752576576.154000,,,2.070,2.001,45.259,3.258,0,0,2.000,2.000,0.000,0.020,1
3752576696.154000,,,2.068,2.000,44.687,3.254,0,0,2.000,2.000,0.000,0.020,1
3752576816.154000,,,2.081,2.000,44.161,3.251,0,0,2.000,2.000,0.250,0.020,1
3752576936.154000,,,2.069,2.000,43.680,3.250,0,0,2.000,2.000,0.140,0.020,1
3752577056.154000,,,2.071,2.000,43.241,3.246,0,0,2.000,2.000,0.070,0.020,1
3752577176.154000,,,2.083,2.000,42.836,3.244,0,0,2.000,2.000,0.290,0.020,1
3752577296.154000,,,2.065,2.000,42.466,3.241,0,0,2.000,2.000,0.000,0.020,1
3752577416.154000,,,2.076,2.000,42.124,3.238,0,0,2.000,2.000,0.090,0.020,1
3752577536.154000,,,2.077,2.000,41.808,3.237,0,0,2.000,2.000,0.250,0.020,1
3752577656.154000,,,2.068,2.000,41.513,3.234,0,0,2.000,2.000,0.040,0.020,1
3752577776.154000,,,2.088,2.000,41.239,3.233,0,0,2.000,2.000,0.220,0.020,1
3752577896.154000,,,2.079,2.000,40.984,3.231,0,0,2.000,2.000,0.280,0.020,1
3752578016.154000,,,2.065,2.001,40.743,3.232,0,0,2.000,2.000,0.000,0.020,1
3752578136.154000,,,2.088,2.000,40.517,3.230,0,0,2.000,2.000,0.020,0.020,1
3752578256.154000,,,2.084,2.000,40.303,3.226,0,0,2.000,2.000,0.050,0.020,1
3752578376.154000,,,2.068,2.000,40.098,3.224,0,0,2.000,2.000,0.000,0.020,1
3752578496.154000,,,2.086,2.001,39.903,3.224,0,0,2.000,2.000,0.000,0.020,1
3752578616.154000,,,2.088,2.000,39.718,3.222,0,0,2.000,2.000,0.230,0.020,1
3752578736.154000,,,2.069,2.000,39.541,3.219,0,0,2.000,2.000,0.000,0.020,1
3752578856.154000,,,2.072,2.000,39.368,3.217,0,0,2.000,2.000,0.000,0.020,1
3752578976.154000,,,2.082,2.000,39.203,3.214,0,0,2.000,2.000,0.230,0.020,1
3752579096.154000,,,2.071,2.000,39.044,3.212,0,0,2.000,2.000,0.000,0.020,1
3752579216.154000,,,2.092,2.000,38.890,3.209,0,0,2.000,2.000,0.310,0.020,1
3752579336.154000,,,2.071,2.001,38.739,3.207,0,0,2.000,2.000,0.000,0.020,1
3752579456.154000,,,2.078,2.000,38.594,3.207,0,0,2.000,2.000,0.000,0.020,1
3752579576.154000,,,2.077,2.000,38.452,3.207,0,0,2.000,2.000,0.080,0.020,1
3752579696.154000,,,2.072,2.000,38.316,3.203,0,0,2.000,2.000,0.000,0.020,1
3752579816.154000,,,2.091,1.999,38.184,3.200,0,0,2.000,2.000,0.310,0.020,1
3752579936.154000,,,2.069,2.000,38.055,3.199,0,0,2.000,2.000,0.000,0.020,1
3752580056.154000,,,2.082,2.000,37.930,3.199,0,0,2.000,2.000,0.000,0.020,1
3752580176.154000,,,2.082,2.000,37.812,3.198,0,0,2.000,2.000,0.200,0.020,1
3752580296.154000,,,2.070,1.999,37.696,3.195,0,0,2.000,2.000,0.000,0.020,1
3752580416.154000,,,2.093,2.000,37.582,3.193,0,0,2.000,2.000,0.270,0.020,1
3752580536.154000,,,2.085,2.000,37.472,3.193,0,0,2.000,2.000,0.210,0.020,1
3752580656.154000,,,2.071,2.000,37.368,3.188,0,0,2.000,2.000,0.000,0.020,1
3752580776.154000,,,2.090,2.000,37.267,3.191,0,0,2.000,2.000,0.310,0.020,1
3752580896.154000,,,2.071,2.000,37.171,3.190,0,0,2.000,2.000,0.000,0.020,1
3752581016.154000,,,2.088,2.000,37.076,3.189,0,0,2.000,2.000,0.220,0.020,1
3752581136.154000,,,2.072,2.000,36.985,3.185,0,0,2.000,2.000,0.000,0.020,1
3752581256.154000,,,2.099,2.000,36.895,3.183,0,0,2.000,2.000,0.090,0.020,1
3752581376.154000,,,2.091,2.000,36.811,3.180,0,0,2.000,2.000,0.170,0.020,1
3752581496.154000,,,2.089,2.000,36.733,3.177,0,0,2.000,2.000,0.190,0.020,1
3752581616.154000,,,2.077,2.000,36.657,3.176,0,0,2.000,2.000,0.010,0.020,1
3752581736.154000,,,2.099,2.000,36.583,3.176,0,0,2.000,2.000,0.110,0.020,1
3752581856.154000,,,2.098,1.999,36.513,3.173,0,0,2.000,2.000,0.310,0.020,1
3752581976.154000,,,2.095,1.999,36.446,3.168,0,0,2.000,2.000,0.150,0.020,1
3752582096.154000,,,2.075,2.001,36.380,3.168,0,0,2.000,2.000,0.000,0.020,1
3752582216.154000,,,2.079,2.000,36.316,3.168,0,0,2.000,2.000,0.000,0.020,1
3752582336.154000,,,2.103,2.000,36.255,3.165,0,0,2.000,2.000,0.130,0.020,1
3752582456.154000,,,2.093,2.000,36.195,3.162,0,0,2.000,2.000,0.300,0.020,1
3752582576.154000,,,2.095,2.000,36.139,3.159,0,0,2.000,2.000,0.010,0.020,1
3752582696.154000,,,2.073,2.000,36.088,3.157,0,0,2.000,2.000,0.000,0.020,1
3752582816.154000,,,2.100,2.000,36.036,3.158,0,0,2.000,2.000,0.320,0.020,1
3752582936.154000,,,2.105,2.000,35.985,3.156,0,0,2.000,2.000,0.290,0.020,1
3752583056.154000,,,2.092,2.000,35.935,3.155,0,0,2.000,2.000,0.140,0.020,1
3752583176.154000,,,2.085,2.000,35.890,3.154,0,0,2.000,2.000,0.000,0.020,1
3752583296.154000,,,2.098,2.000,35.847,3.153,0,0,2.000,2.000,0.000,0.020,1
3752583416.154000,,,2.110,2.000,35.804,3.149,0,0,2.000,2.000,0.300,0.020,1
3752583536.154000,,,2.102,2.000,35.763,3.150,0,0,2.000,2.000,0.250,0.020,1
3752583656.154000,,,2.085,2.000,35.724,3.151,0,0,2.000,2.000,0.000,0.020,1
3752583776.154000,,,2.082,2.000,35.688,3.151,0,0,2.000,2.000,0.000,0.020,1
3752583896.154000,,,2.104,2.000,35.653,3.148,0,0,2.000,2.000,0.010,0.020,1
3752584016.154000,,,2.106,2.000,35.618,3.147,0,0,2.000,2.000,0.030,0.020,1
3752584136.154000,,,2.094,1.999,35.583,3.147,0,0,2.000,2.000,0.170,0.020,1
3752584256.154000,,,2.080,2.000,35.551,3.146,0,0,2.000,2.000,0.000,0.020,1
3752584376.154000,,,2.081,1.999,35.521,3.146,0,0,2.000,2.000,0.000,0.020,1
3752584496.154000,,,2.103,2.000,35.492,3.144,0,0,2.000,2.000,0.030,0.020,1
3752584616.154000,,,2.105,2.000,35.465,3.143,0,0,2.000,2.000,0.050,0.020,1
3752584736.154000,,,2.102,1.999,35.441,3.140,0,0,2.000,2.000,0.250,0.020,1
3752584856.154000,,,2.087,2.000,35.418,3.139,0,0,2.000,2.000,0.020,0.020,1
3752584976.154000,,,2.073,2.000,35.393,3.142,0,0,2.000,2.000,0.000,0.020,1
3752585096.154000,,,2.090,2.000,35.369,3.142,0,0,2.000,2.000,0.000,0.020,1
3752585216.154000,,,2.098,2.000,35.349,3.140,0,0,2.000,2.000,0.000,0.020,1
3752585336.154000,,,2.103,2.000,35.330,3.137,0,0,2.000,2.000,0.310,0.020,1
3752585456.154000,,,2.095,2.000,35.313,3.137,0,0,2.000,2.000,0.230,0.020,1
3752585576.154000,,,2.096,2.000,35.297,3.134,0,0,2.000,2.000,0.000,0.020,1
3752585696.154000,,,2.085,2.000,35.279,3.135,0,0,2.000,2.000,0.000,0.020,1
3752585816.154000,,,2.086,1.999,35.262,3.135,0,0,2.000,2.000,0.000,0.020,1
3752585936.154000,,,2.109,2.000,35.248,3.136,0,0,2.000,2.000,0.100,0.020,1
3752586056.154000,,,2.111,2.000,35.232,3.134,0,0,2.000,2.000,0.260,0.020,1
3752586176.154000,,,2.105,2.000,35.219,3.133,0,0,2.000,2.000,0.180,0.020,1
3752586296.154000,,,2.098,2.000,35.206,3.132,0,0,2.000,2.000,0.140,0.020,1
3752586416.154000,,,2.106,2.000,35.194,3.131,0,0,2.000,2.000,0.280,0.020,1
3752586536.154000,,,2.088,2.000,35.184,3.131,0,0,2.000,2.000,0.000,0.020,1
3752586656.154000,,,2.095,2.000,35.172,3.131,0,0,2.000,2.000,0.000,0.020,1
3752586776.154000,,,2.089,2.001,35.160,3.130,0,0,2.000,2.000,0.000,0.020,1
3752586896.154000,,,2.096,2.000,35.149,3.131,0,0,2.000,2.000,0.000,0.020,1
3752587016.154000,,,2.103,2.000,35.139,3.132,0,0,2.000,2.000,0.000,0.020,1
3752587136.154000,,,2.106,2.000,35.130,3.129,0,0,2.000,2.000,0.210,0.020,1
3752587256.154000,,,2.110,2.000,35.121,3.129,0,0,2.000,2.000,0.200,0.020,1
3752587376.154000,,,2.109,2.000,35.113,3.128,0,0,2.000,2.000,0.150,0.020,1
3752587496.154000,,,2.106,2.000,35.105,3.125,0,0,2.000,2.000,0.290,0.020,1
3752587616.154000,,,2.096,1.999,35.098,3.125,0,0,2.000,2.000,0.220,0.020,1
3752587736.154000,,,2.098,2.000,35.090,3.124,0,0,2.000,2.000,0.000,0.020,1
3752587856.154000,,,2.085,2.000,35.082,3.125,0,0,2.000,2.000,0.000,0.020,1
3752587976.154000,,,2.091,2.000,35.076,3.126,0,0,2.000,2.000,0.030,0.020,1
3752588096.154000,,,2.106,2.000,35.072,3.126,0,0,2.000,2.000,0.020,0.020,1
3752588216.154000,,,2.108,2.000,35.067,3.126,0,0,2.000,2.000,0.170,0.020,1
3752588336.154000,,,2.111,2.000,35.062,3.124,0,0,2.000,2.000,0.310,0.020,1
3752588456.154000,,,2.110,2.000,35.058,3.123,0,0,2.000,2.000,0.300,0.020,1
3752588576.154000,,,2.093,2.000,35.053,3.124,0,0,2.000,2.000,0.000,0.020,1
3752588696.154000,,,2.096,2.000,35.049,3.124,0,0,2.000,2.000,0.040,0.020,1
3752588816.154000,,,2.089,2.000,35.044,3.123,0,0,2.000,2.000,0.020,0.020,1
3752588936.154000,,,2.091,2.000,35.039,3.122,0,0,2.000,2.000,0.000,0.020,1
3752589056.154000,,,2.087,2.000,35.034,3.121,0,0,2.000,2.000,0.000,0.020,1
3752589176.154000,,,2.086,2.000,35.030,3.119,0,0,2.000,2.000,0.000,0.020,1
3752589296.154000,,,2.095,2.000,35.025,3.120,0,0,2.000,2.000,0.000,0.020,1
3752589416.154000,,,2.096,2.000,35.022,3.120,0,0,2.000,2.000,0.000,0.020,1
3752589536.154000,,,2.102,2.000,35.019,3.119,0,0,2.000,2.000,0.040,0.020,1
3752589656.154000,,,2.106,2.001,35.015,3.119,0,0,2.000,2.000,0.000,0.020,1
3752589776.154000,,,2.095,2.000,35.011,3.118,0,0,2.000,2.000,0.000,0.020,1
3752589896.154000,,,2.111,2.000,35.009,3.121,0,0,2.000,2.000,0.120,0.020,1
3752590016.154000,,,2.107,2.000,35.009,3.123,0,0,2.000,2.000,0.130,0.020,1
3752590136.154000,,,2.106,2.000,35.007,3.122,0,0,2.000,2.000,0.220,0.020,1
3752590256.154000,,,2.110,2.000,35.006,3.121,0,0,2.000,2.000,0.200,0.020,1
3752590376.154000,,,2.106,2.000,35.005,3.121,0,0,2.000,2.000,0.000,0.020,1
3752590496.154000,,,2.107,2.000,35.003,3.121,0,0,2.000,2.000,0.300,0.020,1
3752590616.154000,,,2.113,1.999,35.000,3.121,0,0,2.000,2.000,0.290,0.020,1
3752590736.154000,,,2.110,2.000,35.001,3.119,0,0,2.000,2.000,0.290,0.020,1
3752590856.154000,,,2.109,2.000,34.999,3.119,0,0,2.000,2.000,0.290,0.020,1
3752590976.154000,,,2.113,2.000,34.997,3.118,0,0,2.000,2.000,0.120,0.020,1
3752591096.154000,,,2.107,2.000,34.993,3.120,0,0,2.000,2.000,0.270,0.020,1
3752591216.154000,,,2.112,2.000,34.993,3.120,0,0,2.000,2.000,0.290,0.020,1
3752591336.154000,,,2.115,2.000,34.992,3.121,0,0,2.000,2.000,0.200,0.020,1
3752591456.154000,,,2.109,2.000,34.991,3.119,0,0,2.000,2.000,0.290,0.020,1
3752591576.154000,,,2.109,2.000,34.989,3.119,0,0,2.000,2.000,0.210,0.020,1
3752591696.154000,,,2.108,2.000,34.987,3.118,0,0,2.000,2.000,0.280,0.020,1
3752591816.154000,,,2.108,2.000,34.985,3.119,0,0,2.000,2.000,0.290,0.020,1
3752591936.154000,,,2.113,2.000,34.983,3.119,0,0,2.000,2.000,0.290,0.020,1
3752592056.154000,,,2.097,2.000,34.981,3.119,0,0,2.000,2.000,0.320,0.020,1
3752592176.154000,,,2.114,2.000,34.981,3.117,0,0,2.000,2.000,0.180,0.020,1
3752592296.154000,,,2.111,2.000,34.980,3.115,0,0,2.000,2.000,0.270,0.020,1
3752592416.154000,,,2.111,2.000,34.979,3.115,0,0,2.000,2.000,0.110,0.020,1
3752592536.154000,,,2.116,2.000,34.979,3.117,0,0,2.000,2.000,0.280,0.020,1
3752592656.154000,,,2.115,2.000,34.977,3.116,0,0,2.000,2.000,0.240,0.020,1
3752592776.154000,,,2.115,2.000,34.977,3.114,0,0,2.000,2.000,0.170,0.020,1
3752592896.154000,,,2.110,2.000,34.976,3.114,0,0,2.000,2.000,0.220,0.020,1
3752593016.154000,,,2.113,2.000,34.976,3.114,0,0,2.000,2.000,0.040,0.020,1
3752593136.154000,,,2.105,2.000,34.974,3.114,0,0,2.000,2.000,0.260,0.020,1
3752593256.154000,,,2.107,2.000,34.972,3.113,0,0,2.000,2.000,0.010,0.020,1
3752593376.154000,,,2.105,1.999,34.971,3.115,0,0,2.000,2.000,0.000,0.020,1
3752593496.154000,,,2.101,1.999,34.971,3.114,0,0,2.000,2.000,0.000,0.020,1
3752593616.154000,,,2.102,2.000,34.972,3.113,0,0,2.000,2.000,0.000,0.020,1
3752593736.154000,,,2.101,2.000,34.971,3.115,0,0,2.000,2.000,0.090,0.020,1
3752593856.154000,,,2.101,2.000,34.971,3.116,0,0,2.000,2.000,0.000,0.020,1
3752593976.154000,,,2.093,2.001,34.973,3.116,0,0,2.000,2.000,0.000,0.020,1
3752594096.154000,,,2.091,2.000,34.973,3.114,0,0,2.000,2.000,0.000,0.020,1
3752594216.154000,,,2.092,2.000,34.972,3.114,0,0,2.000,2.000,0.000,0.020,1
3752594336.154000,,,2.080,1.999,34.972,3.111,0,0,2.000,2.000,0.000,0.020,1
3752594456.154000,,,2.087,1.999,34.972,3.112,0,0,2.000,2.000,0.000,0.020,1
3752594576.154000,,,2.090,2.000,34.971,3.113,0,0,2.000,2.000,0.020,0.020,1
3752594696.154000,,,2.099,2.000,34.971,3.112,0,0,2.000,2.000,0.000,0.020,1
3752594816.154000,,,2.097,2.000,34.972,3.109,0,0,2.000,2.000,0.190,0.020,1
3752594936.154000,,,2.111,2.000,34.972,3.109,0,0,2.000,2.000,0.280,0.020,1
3752595056.154000,,,2.107,2.000,34.970,3.112,0,0,2.000,2.000,0.290,0.020,1
3752595176.154000,,,2.110,2.000,34.973,3.111,0,0,2.000,2.000,0.240,0.020,1
3752595296.154000,,,2.110,1.999,34.973,3.112,0,0,2.000,2.000,0.210,0.020,1
3752595416.154000,,,2.111,2.000,34.972,3.114,0,0,2.000,2.000,0.090,0.020,1
3752595536.154000,,,2.096,2.000,34.973,3.109,0,0,2.000,2.000,0.000,0.020,1
3752595656.154000,,,2.104,2.000,34.973,3.108,0,0,2.000,2.000,0.000,0.020,1
3752595776.154000,,,2.096,2.000,34.972,3.107,0,0,2.000,2.000,0.000,0.020,1
3752595896.154000,,,2.088,2.000,34.970,3.106,0,0,2.000,2.000,0.000,0.020,1
3752596016.154000,,,2.090,2.000,34.970,3.108,0,0,2.000,2.000,0.000,0.020,1
3752596136.154000,,,2.096,2.000,34.971,3.108,0,0,2.000,2.000,0.160,0.020,1
3752596256.154000,,,2.094,2.000,34.970,3.108,0,0,2.000,2.000,0.000,0.020,1
3752596376.154000,,,2.096,1.999,34.969,3.107,0,0,2.000,2.000,0.110,0.020,1
3752596496.154000,,,2.109,2.000,34.969,3.109,0,0,2.000,2.000,0.140,0.020,1
3752596616.154000,,,2.108,2.000,34.971,3.109,0,0,2.000,2.000,0.270,0.020,1
3752596736.154000,,,2.117,1.999,34.972,3.108,0,0,2.000,2.000,0.060,0.020,1
3752596856.154000,,,2.114,2.000,34.970,3.108,0,0,2.000,2.000,0.220,0.020,1
3752596976.154000,,,2.109,2.000,34.970,3.109,0,0,2.000,2.000,0.120,0.020,1
3752597096.154000,,,2.102,2.000,34.971,3.109,0,0,2.000,2.000,0.050,0.020,1
3752597216.154000,,,2.102,1.999,34.971,3.108,0,0,2.000,2.000,0.000,0.020,1
3752597336.154000,,,2.090,2.001,34.971,3.107,0,0,2.000,2.000,0.000,0.020,1
3752597456.154000,,,2.093,2.000,34.970,3.108,0,0,2.000,2.000,0.000,0.020,1
3752597576.154000,,,2.094,2.000,34.970,3.108,0,0,2.000,2.000,0.000,0.020,1
3752597696.154000,,,2.089,2.000,34.970,3.108,0,0,2.000,2.000,0.000,0.020,1
3752597816.154000,,,2.102,2.000,34.970,3.106,0,0,2.000,2.000,0.210,0.020,1
3752597936.154000,,,2.108,2.000,34.969,3.107,0,0,2.000,2.000,0.270,0.020,1
3752598056.154000,,,2.109,2.000,34.970,3.108,0,0,2.000,2.000,0.270,0.020,1
3752598176.154000,,,2.112,2.000,34.969,3.108,0,0,2.000,2.000,0.110,0.020,1
3752598296.154000,,,2.110,2.000,34.970,3.106,0,0,2.000,2.000,0.320,0.020,1
3752598416.154000,,,2.101,2.000,34.968,3.106,0,0,2.000,2.000,0.000,0.020,1
3752598536.154000,,,2.092,2.001,34.968,3.107,0,0,2.000,2.000,0.000,0.020,1
3752598656.154000,,,2.094,2.000,34.967,3.108,0,0,2.000,2.000,0.000,0.020,1
3752598776.154000,,,2.095,2.001,34.967,3.106,0,0,2.000,2.000,0.030,0.020,1
3752598896.154000,,,2.094,2.000,34.970,3.104,0,0,2.000,2.000,0.000,0.020,1
3752599016.154000,,,2.108,2.000,34.968,3.106,0,0,2.000,2.000,0.180,0.020,1
3752599136.154000,,,2.106,2.000,34.969,3.105,0,0,2.000,2.000,0.280,0.020,1
3752599256.154000,,,2.113,2.000,34.969,3.105,0,0,2.000,2.000,0.280,0.020,1
3752599376.154000,,,2.116,2.000,34.969,3.107,0,0,2.000,2.000,0.100,0.020,1
3752599496.154000,,,2.110,2.000,34.969,3.107,0,0,2.000,2.000,0.240,0.020,1
3752599616.154000,,,2.092,2.000,34.968,3.106,0,0,2.000,2.000,0.000,0.020,1
3752599736.154000,,,2.089,2.000,34.968,3.106,0,0,2.000,2.000,0.000,0.020,1
3752599856.154000,,,2.107,2.000,34.969,3.105,0,0,2.000,2.000,0.050,0.020,1
3752599976.154000,,,2.105,2.000,34.969,3.106,0,0,2.000,2.000,0.270,0.020,1
3752600096.154000,,,2.113,2.000,34.970,3.104,0,0,2.000,2.000,0.000,0.020,1
3752600216.154000,,,2.109,2.000,34.971,3.104,0,0,2.000,2.000,0.080,0.020,1
3752600336.154000,,,2.103,2.000,34.970,3.104,0,0,2.000,2.000,0.000,0.020,1
3752600456.154000,,,2.092,2.000,34.970,3.105,0,0,2.000,2.000,0.000,0.020,1
3752600576.154000,,,2.093,2.000,34.970,3.106,0,0,2.000,2.000,0.000,0.020,1
3752600696.154000,,,2.108,1.999,34.970,3.105,0,0,2.000,2.000,0.280,0.020,1
3752600816.154000,,,2.108,2.000,34.970,3.104,0,0,2.000,2.000,0.240,0.020,1
3752600936.154000,,,2.113,2.000,34.970,3.105,0,0,2.000,2.000,0.200,0.020,1
3752601056.154000,,,2.098,2.000,34.971,3.104,0,0,2.000,2.000,0.010,0.020,1
3752601176.154000,,,2.092,2.000,34.971,3.101,0,0,2.000,2.000,0.000,0.020,1
3752601296.154000,,,2.097,2.000,34.972,3.100,0,0,2.000,2.000,0.150,0.020,1
3752601416.154000,,,2.098,2.000,34.972,3.101,0,0,2.000,2.000,0.020,0.020,1
3752601536.154000,,,2.110,2.000,34.972,3.101,0,0,2.000,2.000,0.280,0.020,1
3752601656.154000,,,2.116,2.000,34.972,3.102,0,0,2.000,2.000,0.240,0.020,1
3752601776.154000,,,2.106,2.000,34.971,3.102,0,0,2.000,2.000,0.000,0.020,1
3752601896.154000,,,2.088,2.000,34.970,3.101,0,0,2.000,2.000,0.000,0.020,1
3752602016.154000,,,2.091,2.001,34.969,3.101,0,0,2.000,2.000,0.000,0.020,1
3752602136.154000,,,2.092,2.000,34.970,3.101,0,0,2.000,2.000,0.000,0.020,1
3752602256.154000,,,2.109,2.000,34.970,3.101,0,0,2.000,2.000,0.150,0.020,1
3752602376.154000,,,2.114,2.000,34.969,3.101,0,0,2.000,2.000,0.250,0.020,1
3752602496.154000,,,2.105,2.000,34.968,3.101,0,0,2.000,2.000,0.000,0.020,1
3752602616.154000,,,2.106,2.000,34.968,3.101,0,0,2.000,2.000,0.000,0.020,1
3752602736.154000,,,2.090,2.000,34.967,3.101,0,0,2.000,2.000,0.000,0.020,1
3752602856.154000,,,2.095,2.000,34.968,3.100,0,0,2.000,2.000,0.000,0.020,1
3752602976.154000,,,2.109,2.000,34.968,3.101,0,0,2.000,2.000,0.260,0.020,1
3752603096.154000,,,2.115,2.000,34.967,3.100,0,0,2.000,2.000,0.200,0.020,1
3752603216.154000,,,2.101,2.000,34.968,3.099,0,0,2.000,2.000,0.040,0.020,1
3752603336.154000,,,2.099,2.000,34.971,3.101,0,0,2.000,2.000,0.000,0.020,1
3752603456.154000,,,2.093,2.001,34.972,3.101,0,0,2.000,2.000,0.000,0.020,1
3752603576.154000,,,2.094,2.000,34.970,3.100,0,0,2.000,2.000,0.030,0.020,1
3752603696.154000,,,2.107,2.000,34.969,3.101,0,0,2.000,2.000,0.260,0.020,1
3752603816.154000,,,2.113,2.000,34.970,3.101,0,0,2.000,2.000,0.200,0.020,1
3752603936.154000,,,2.107,2.000,34.971,3.100,0,0,2.000,2.000,0.000,0.020,1
3752604056.154000,,,2.094,2.000,34.970,3.099,0,0,2.000,2.000,0.020,0.020,1
3752604176.154000,,,2.094,2.000,34.970,3.098,0,0,2.000,2.000,0.000,0.020,1
3752604296.154000,,,2.104,2.000,34.970,3.093,0,0,2.000,2.000,0.250,0.020,1
3752604416.154000,,,2.110,2.000,34.969,3.097,0,0,2.000,2.000,0.260,0.020,1
3752604536.154000,,,2.112,2.000,34.969,3.096,0,0,2.000,2.000,0.000,0.020,1
3752604656.154000,,,2.098,2.000,34.966,3.097,0,0,2.000,2.000,0.100,0.020,1
3752604776.154000,,,2.092,2.000,34.967,3.096,0,0,2.000,2.000,0.000,0.020,1
3752604896.154000,,,2.096,2.000,34.964,3.099,0,0,2.000,2.000,0.120,0.020,1
3752605016.154000,,,2.114,2.000,34.960,3.100,0,0,2.000,2.000,0.270,0.020,1
3752605136.154000,,,2.114,2.000,34.959,3.103,0,0,2.000,2.000,0.050,0.020,1
3752605256.154000,,,2.096,2.000,34.961,3.102,0,0,2.000,2.000,0.100,0.020,1
3752605376.154000,,,2.095,1.999,34.961,3.102,0,0,2.000,2.000,0.000,0.020,1
3752605496.154000,,,2.098,2.000,34.963,3.101,0,0,2.000,2.000,0.170,0.020,1
3752605616.154000,,,2.114,1.999,34.963,3.101,0,0,2.000,2.000,0.270,0.020,1
3752605736.154000,,,2.112,1.999,34.964,3.099,0,0,2.000,2.000,0.120,0.020,1
3752605856.154000,,,2.091,1.999,34.966,3.099,0,0,2.000,2.000,0.000,0.020,1
3752605976.154000,,,2.091,2.001,34.966,3.098,0,0,2.000,2.000,0.000,0.020,1
3752606096.154000,,,2.098,2.000,34.966,3.099,0,0,2.000,2.000,0.030,0.020,1
3752606216.154000,,,2.116,2.001,34.966,3.101,0,0,2.000,2.000,0.250,0.020,1
3752606336.154000,,,2.113,2.000,34.967,3.100,0,0,2.000,2.000,0.100,0.020,1
3752606456.154000,,,2.089,2.000,34.966,3.101,0,0,2.000,2.000,0.000,0.020,1
3752606576.154000,,,2.096,2.000,34.963,3.101,0,0,2.000,2.000,0.000,0.020,1
3752606696.154000,,,2.091,2.000,34.962,3.102,0,0,2.000,2.000,0.110,0.020,1
3752606816.154000,,,2.116,2.000,34.962,3.102,0,0,2.000,2.000,0.290,0.020,1
3752606936.154000,,,2.110,2.000,34.963,3.100,0,0,2.000,2.000,0.000,0.020,1
3752607056.154000,,,2.089,2.000,34.964,3.098,0,0,2.000,2.000,0.020,0.020,1
3752607176.154000,,,2.095,2.000,34.963,3.099,0,0,2.000,2.000,0.000,0.020,1
3752607296.154000,,,2.114,2.000,34.962,3.098,0,0,2.000,2.000,0.270,0.020,1
3752607416.154000,,,2.101,2.000,34.962,3.098,0,0,2.000,2.000,0.020,0.020,1
3752607536.154000,,,2.092,1.999,34.961,3.097,0,0,2.000,2.000,0.000,0.020,1
3752607656.154000,,,2.111,2.000,34.961,3.098,0,0,2.000,2.000,0.280,0.020,1
3752607776.154000,,,2.111,2.000,34.962,3.098,0,0,2.000,2.000,0.290,0.020,1
3752607896.154000,,,2.111,2.000,34.961,3.098,0,0,2.000,2.000,0.000,0.020,1
3752608016.154000,,,2.093,2.000,34.961,3.097,0,0,2.000,2.000,0.000,0.020,1
3752608136.154000,,,2.094,2.000,34.961,3.097,0,0,2.000,2.000,0.000,0.020,1
3752608256.154000,,,2.113,2.000,34.961,3.097,0,0,2.000,2.000,0.230,0.020,1
3752608376.154000,,,2.096,2.000,34.960,3.096,0,0,2.000,2.000,0.000,0.020,1
3752608496.154000,,,2.090,2.000,34.960,3.095,0,0,2.000,2.000,0.000,0.020,1
3752608616.154000,,,2.095,2.000,34.962,3.096,0,0,2.000,2.000,0.000,0.020,1
3752608736.154000,,,2.113,2.000,34.962,3.096,0,0,2.000,2.000,0.280,0.020,1
3752608856.154000,,,2.112,2.000,34.962,3.096,0,0,2.000,2.000,0.000,0.020,1
3752608976.154000,,,2.095,2.000,34.963,3.097,0,0,2.000,2.000,0.000,0.020,1
3752609096.154000,,,2.094,2.000,34.964,3.096,0,0,2.000,2.000,0.040,0.020,1
3752609216.154000,,,2.115,2.001,34.963,3.097,0,0,2.000,2.000,0.190,0.020,1
3752609336.154000,,,2.111,2.000,34.962,3.096,0,0,2.000,2.000,0.040,0.020,1
3752609456.154000,,,2.093,2.001,34.962,3.097,0,0,2.000,2.000,0.000,0.020,1
3752609576.154000,,,2.099,2.000,34.962,3.094,0,0,2.000,2.000,0.010,0.020,1
3752609696.154000,,,2.115,2.000,34.962,3.095,0,0,2.000,2.000,0.210,0.020,1
3752609816.154000,,,2.108,2.000,34.962,3.093,0,0,2.000,2.000,0.220,0.020,1
3752609936.154000,,,2.089,1.999,34.962,3.094,0,0,2.000,2.000,0.000,0.020,1
3752610056.154000,,,2.099,2.000,34.961,3.094,0,0,2.000,2.000,0.100,0.020,1
3752610176.154000,,,2.116,2.000,34.960,3.094,0,0,2.000,2.000,0.270,0.020,1
3752610296.154000,,,2.108,2.001,34.960,3.093,0,0,2.000,2.000,0.000,0.020,1
3752610416.154000,,,2.094,2.000,34.961,3.093,0,0,2.000,2.000,0.000,0.020,1
3752610536.154000,,,2.100,2.000,34.959,3.093,0,0,2.000,2.000,0.030,0.020,1
3752610656.154000,,,2.110,2.000,34.958,3.093,0,0,2.000,2.000,0.290,0.020,1
3752610776.154000,,,2.110,2.000,34.957,3.094,0,0,2.000,2.000,0.100,0.020,1
3752610896.154000,,,2.095,2.000,34.957,3.093,0,0,2.000,2.000,0.000,0.020,1
3752611016.154000,,,2.104,2.000,34.958,3.091,0,0,2.000,2.000,0.260,0.020,1
3752611136.154000,,,2.111,2.000,34.958,3.092,0,0,2.000,2.000,0.240,0.020,1
3752611256.154000,,,2.113,2.000,34.958,3.092,0,0,2.000,2.000,0.030,0.020,1
3752611376.154000,,,2.090,2.000,34.957,3.093,0,0,2.000,2.000,0.000,0.020,1
3752611496.154000,,,2.094,2.000,34.957,3.092,0,0,2.000,2.000,0.010,0.020,1
3752611616.154000,,,2.113,2.000,34.958,3.090,0,0,2.000,2.000,0.200,0.020,1
3752611736.154000,,,2.117,2.000,34.957,3.091,0,0,2.000,2.000,0.050,0.020,1
3752611856.154000,,,2.095,2.000,34.957,3.091,0,0,2.000,2.000,0.000,0.020,1
3752611976.154000,,,2.103,2.000,34.955,3.090,0,0,2.000,2.000,0.000,0.020,1
3752612096.154000,,,2.113,2.000,34.952,3.090,0,0,2.000,2.000,0.280,0.020,1
3752612216.154000,,,2.096,1.999,34.954,3.090,0,0,2.000,2.000,0.000,0.020,1
3752612336.154000,,,2.095,2.001,34.955,3.091,0,0,2.000,2.000,0.000,0.020,1
3752612456.154000,,,2.105,2.000,34.954,3.090,0,0,2.000,2.000,0.240,0.020,1
3752612576.154000,,,2.105,2.000,34.953,3.090,0,0,2.000,2.000,0.210,0.020,1
3752612696.154000,,,2.095,2.000,34.954,3.090,0,0,2.000,2.000,0.000,0.020,1
3752612816.154000,,,2.106,1.999,34.954,3.090,0,0,2.000,2.000,0.240,0.020,1
3752612936.154000,,,2.114,1.999,34.954,3.090,0,0,2.000,2.000,0.270,0.020,1
3752613056.154000,,,2.105,2.000,34.953,3.091,0,0,2.000,2.000,0.000,0.020,1
3752613176.154000,,,2.094,2.000,34.952,3.090,0,0,2.000,2.000,0.000,0.020,1
3752613296.154000,,,2.110,2.000,34.953,3.090,0,0,2.000,2.000,0.270,0.020,1
3752613416.154000,,,2.101,2.000,34.954,3.089,0,0,2.000,2.000,0.000,0.020,1
3752613536.154000,,,2.094,2.001,34.953,3.089,0,0,2.000,2.000,0.000,0.020,1
3752613656.154000,,,2.098,1.999,34.952,3.089,0,0,2.000,2.000,0.120,0.020,1
3752613776.154000,,,2.113,1.999,34.951,3.089,0,0,2.000,2.000,0.290,0.020,1
3752613896.154000,,,2.095,2.000,34.952,3.089,0,0,2.000,2.000,0.000,0.020,1
3752614016.154000,,,2.101,2.000,34.952,3.090,0,0,2.000,2.000,0.220,0.020,1
3752614136.154000,,,2.112,2.000,34.951,3.090,0,0,2.000,2.000,0.240,0.020,1
3752614256.154000,,,2.100,2.000,34.950,3.091,0,0,2.000,2.000,0.000,0.020,1
3752614376.154000,,,2.097,2.000,34.951,3.089,0,0,2.000,2.000,0.000,0.020,1
3752614496.154000,,,2.114,2.000,34.950,3.090,0,0,2.000,2.000,0.290,0.020,1
3752614616.154000,,,2.113,1.999,34.950,3.089,0,0,2.000,2.000,0.000,0.020,1
3752614736.154000,,,2.093,2.000,34.949,3.089,0,0,2.000,2.000,0.000,0.020,1
3752614856.154000,,,2.106,2.000,34.948,3.089,0,0,2.000,2.000,0.240,0.020,1
3752614976.154000,,,2.117,2.000,34.947,3.089,0,0,2.000,2.000,0.240,0.020,1
3752615096.154000,,,2.097,2.000,34.947,3.088,0,0,2.000,2.000,0.000,0.020,1
3752615216.154000,,,2.097,2.000,34.946,3.090,0,0,2.000,2.000,0.070,0.020,1
3752615336.154000,,,2.117,2.001,34.947,3.089,0,0,2.000,2.000,0.270,0.020,1
3752615456.154000,,,2.106,2.000,34.947,3.089,0,0,2.000,2.000,0.000,0.020,1
3752615576.154000,,,2.091,1.999,34.948,3.088,0,0,2.000,2.000,0.000,0.020,1
3752615696.154000,,,2.108,2.000,34.948,3.088,0,0,2.000,2.000,0.220,0.020,1
3752615816.154000,,,2.117,2.000,34.948,3.089,0,0,2.000,2.000,0.060,0.020,1
3752615936.154000,,,2.092,2.000,34.948,3.088,0,0,2.000,2.000,0.000,0.020,1
3752616056.154000,,,2.100,2.000,34.947,3.088,0,0,2.000,2.000,0.140,0.020,1
3752616176.154000,,,2.117,2.000,34.948,3.089,0,0,2.000,2.000,0.060,0.020,1
3752616296.154000,,,2.108,2.000,34.948,3.088,0,0,2.000,2.000,0.000,0.020,1
3752616416.154000,,,2.092,2.000,34.948,3.088,0,0,2.000,2.000,0.000,0.020,1
3752616536.154000,,,2.117,2.000,34.949,3.087,0,0,2.000,2.000,0.290,0.020,1
3752616656.154000,,,2.101,2.000,34.949,3.087,0,0,2.000,2.000,0.000,0.020,1
3752616776.154000,,,2.098,2.000,34.950,3.087,0,0,2.000,2.000,0.190,0.020,1
3752616896.154000,,,2.113,2.000,34.949,3.089,0,0,2.000,2.000,0.230,0.020,1
3752617016.154000,,,2.102,2.000,34.949,3.089,0,0,2.000,2.000,0.000,0.020,1
3752617136.154000,,,2.091,2.000,34.951,3.086,0,0,2.000,2.000,0.000,0.020,1
3752617256.154000,,,2.101,2.000,34.951,3.088,0,0,2.000,2.000,0.150,0.020,1
3752617376.154000,,,2.114,2.000,34.950,3.086,0,0,2.000,2.000,0.000,0.020,1
3752617496.154000,,,2.101,2.000,34.950,3.087,0,0,2.000,2.000,0.000,0.020,1
3752617616.154000,,,2.096,2.000,34.950,3.087,0,0,2.000,2.000,0.030,0.020,1
3752617736.154000,,,2.117,1.999,34.949,3.088,0,0,2.000,2.000,0.290,0.020,1
3752617856.154000,,,2.108,2.000,34.950,3.086,0,0,2.000,2.000,0.000,0.020,1
3752617976.154000,,,2.099,2.000,34.950,3.087,0,0,2.000,2.000,0.120,0.020,1
3752618096.154000,,,2.109,2.000,34.949,3.085,0,0,2.000,2.000,0.220,0.020,1
3752618216.154000,,,2.106,2.000,34.950,3.083,0,0,2.000,2.000,0.010,0.020,1
3752618336.154000,,,2.096,2.001,34.950,3.081,0,0,2.000,2.000,0.000,0.020,1
3752618456.154000,,,2.103,2.000,34.950,3.079,0,0,2.000,2.000,0.200,0.020,1
3752618576.154000,,,2.105,2.000,34.948,3.077,0,0,2.000,2.000,0.000,0.020,1
3752618696.154000,,,2.095,2.001,34.946,3.076,0,0,2.000,2.000,0.000,0.020,1
3752618816.154000,,,2.110,1.999,34.943,3.078,0,0,2.000,2.000,0.260,0.020,1
3752618936.154000,,,2.112,2.000,34.942,3.076,0,0,2.000,2.000,0.270,0.020,1
3752619056.154000,,,2.090,2.000,34.941,3.076,0,0,2.000,2.000,0.000,0.020,1
3752619176.154000,,,2.106,2.000,34.939,3.078,0,0,2.000,2.000,0.220,0.020,1
3752619296.154000,,,2.109,2.000,34.940,3.079,0,0,2.000,2.000,0.220,0.020,1
3752619416.154000,,,2.096,2.000,34.940,3.078,0,0,2.000,2.000,0.000,0.020,1
3752619536.154000,,,2.097,1.999,34.940,3.078,0,0,2.000,2.000,0.000,0.020,1
3752619656.154000,,,2.116,2.000,34.939,3.077,0,0,2.000,2.000,0.230,0.020,1
3752619776.154000,,,2.102,2.000,34.939,3.078,0,0,2.000,2.000,0.000,0.020,1
3752619896.154000,,,2.103,2.000,34.940,3.078,0,0,2.000,2.000,0.000,0.020,1
3752620016.154000,,,2.115,2.000,34.941,3.080,0,0,2.000,2.000,0.230,0.020,1
3752620136.154000,,,2.102,2.000,34.941,3.081,0,0,2.000,2.000,0.080,0.020,1
3752620256.154000,,,2.097,2.001,34.941,3.079,0,0,2.000,2.000,0.000,0.020,1
3752620376.154000,,,2.113,2.001,34.941,3.078,0,0,2.000,2.000,0.190,0.020,1
3752620496.154000,,,2.092,2.001,34.942,3.080,0,0,2.000,2.000,0.000,0.020,1
3752620616.154000,,,2.095,2.000,34.943,3.082,0,0,2.000,2.000,0.060,0.020,1
3752620736.154000,,,2.116,2.000,34.945,3.078,0,0,2.000,2.000,0.190,0.020,1
3752620856.154000,,,2.105,2.000,34.946,3.079,0,0,2.000,2.000,0.000,0.020,1
3752620976.154000,,,2.097,1.999,34.947,3.077,0,0,2.000,2.000,0.000,0.020,1
3752621096.154000,,,2.114,2.000,34.946,3.078,0,0,2.000,2.000,0.260,0.020,1
3752621216.154000,,,2.105,2.000,34.946,3.078,0,0,2.000,2.000,0.000,0.020,1
3752621336.154000,,,2.100,2.000,34.946,3.076,0,0,2.000,2.000,0.210,0.020,1
3752621456.154000,,,2.117,2.001,34.945,3.080,0,0,2.000,2.000,0.260,0.020,1
3752621576.154000,,,2.104,2.000,34.944,3.079,0,0,2.000,2.000,0.000,0.020,1
3752621696.154000,,,2.097,2.000,34.945,3.079,0,0,2.000,2.000,0.000,0.020,1
3752621816.154000,,,2.111,2.000,34.943,3.079,0,0,2.000,2.000,0.260,0.020,1
3752621936.154000,,,2.098,2.000,34.943,3.077,0,0,2.000,2.000,0.000,0.020,1
3752622056.154000,,,2.091,1.999,34.941,3.078,0,0,2.000,2.000,0.000,0.020,1
3752622176.154000,,,2.115,2.000,34.941,3.079,0,0,2.000,2.000,0.280,0.020,1
3752622296.154000,,,2.106,2.000,34.941,3.080,0,0,2.000,2.000,0.080,0.020,1
3752622416.154000,,,2.093,2.000,34.942,3.080,0,0,2.000,2.000,0.000,0.020,1
3752622536.154000,,,2.114,2.001,34.941,3.078,0,0,2.000,2.000,0.240,0.020,1
3752622656.154000,,,2.113,1.999,34.940,3.081,0,0,2.000,2.000,0.120,0.020,1
3752622776.154000,,,2.088,2.000,34.940,3.078,0,0,2.000,2.000,0.000,0.020,1
3752622896.154000,,,2.111,1.999,34.939,3.076,0,0,2.000,2.000,0.150,0.020,1
3752623016.154000,,,2.115,1.999,34.937,3.077,0,0,2.000,2.000,0.060,0.020,1
3752623136.154000,,,2.088,2.000,34.936,3.077,0,0,2.000,2.000,0.000,0.020,1
3752623256.154000,,,2.102,2.000,34.934,3.077,0,0,2.000,2.000,0.060,0.020,1
3752623376.154000,,,2.116,2.000,34.933,3.078,0,0,2.000,2.000,0.220,0.020,1
3752623496.154000,,,2.092,2.000,34.931,3.077,0,0,2.000,2.000,0.000,0.020,1
3752623616.154000,,,2.099,2.000,34.932,3.079,0,0,2.000,2.000,0.110,0.020,1
3752623736.154000,,,2.114,2.000,34.933,3.080,0,0,2.000,2.000,0.000,0.020,1
3752623856.154000,,,2.100,2.000,34.932,3.082,0,0,2.000,2.000,0.000,0.020,1
3752623976.154000,,,2.098,2.000,34.933,3.083,0,0,2.000,2.000,0.110,0.020,1
3752624096.154000,,,2.112,2.000,34.934,3.081,0,0,2.000,2.000,0.270,0.020,1
3752624216.154000,,,2.090,1.999,34.936,3.079,0,0,2.000,2.000,0.000,0.020,1
3752624336.154000,,,2.105,2.000,34.938,3.079,0,0,2.000,2.000,0.220,0.020,1
3752624456.154000,,,2.105,2.000,34.941,3.081,0,0,2.000,2.000,0.220,0.020,1
3752624576.154000,,,2.097,2.000,34.943,3.080,0,0,2.000,2.000,0.000,0.020,1
3752624696.154000,,,2.100,2.000,34.945,3.078,0,0,2.000,2.000,0.000,0.020,1
3752624816.154000,,,2.114,2.000,34.946,3.079,0,0,2.000,2.000,0.100,0.020,1
3752624936.154000,,,2.094,2.000,34.946,3.078,0,0,2.000,2.000,0.000,0.020,1
3752625056.154000,,,2.105,2.000,34.945,3.082,0,0,2.000,2.000,0.200,0.020,1
3752625176.154000,,,2.113,2.000,34.945,3.082,0,0,2.000,2.000,0.000,0.020,1
3752625296.154000,,,2.092,2.000,34.945,3.082,0,0,2.000,2.000,0.000,0.020,1
3752625416.154000,,,2.110,2.000,34.946,3.082,0,0,2.000,2.000,0.250,0.020,1
3752625536.154000,,,2.106,2.000,34.947,3.082,0,0,2.000,2.000,0.000,0.020,1
3752625656.154000,,,2.094,2.000,34.947,3.083,0,0,2.000,2.000,0.000,0.020,1
3752625776.154000,,,2.110,2.000,34.949,3.081,0,0,2.000,2.000,0.260,0.020,1
3752625896.154000,,,2.098,2.000,34.950,3.080,0,0,2.000,2.000,0.010,0.020,1
3752626016.154000,,,2.103,2.000,34.951,3.082,0,0,2.000,2.000,0.160,0.020,1
3752626136.154000,,,2.114,2.000,34.951,3.083,0,0,2.000,2.000,0.090,0.020,1
3752626256.154000,,,2.092,2.000,34.951,3.084,0,0,2.000,2.000,0.000,0.020,1
3752626376.154000,,,2.107,2.000,34.951,3.080,0,0,2.000,2.000,0.250,0.020,1
3752626496.154000,,,2.108,1.999,34.950,3.081,0,0,2.000,2.000,0.260,0.020,1
3752626616.154000,,,2.092,2.000,34.949,3.081,0,0,2.000,2.000,0.000,0.020,1
3752626736.154000,,,2.108,2.000,34.947,3.081,0,0,2.000,2.000,0.270,0.020,1
3752626856.154000,,,2.098,2.000,34.945,3.081,0,0,2.000,2.000,0.010,0.020,1
3752626976.154000,,,2.100,2.000,34.943,3.083,0,0,2.000,2.000,0.000,0.020,1
3752627096.154000,,,2.116,2.000,34.942,3.085,0,0,2.000,2.000,0.090,0.020,1
3752627216.154000,,,2.104,2.000,34.940,3.083,0,0,2.000,2.000,0.000,0.020,1
3752627336.154000,,,2.097,2.000,34.939,3.085,0,0,2.000,2.000,0.070,0.020,1
3752627456.154000,,,2.111,2.000,34.938,3.084,0,0,2.000,2.000,0.230,0.020,1
3752627576.154000,,,2.095,2.000,34.936,3.084,0,0,2.000,2.000,0.000,0.020,1
3752627696.154000,,,2.109,2.000,34.937,3.083,0,0,2.000,2.000,0.270,0.020,1
3752627816.154000,,,2.117,2.000,34.937,3.078,0,0,2.000,2.000,0.230,0.020,1
3752627936.154000,,,2.093,2.000,34.936,3.081,0,0,2.000,2.000,0.000,0.020,1
3752628056.154000,,,2.108,2.000,34.935,3.083,0,0,2.000,2.000,0.120,0.020,1
3752628176.154000,,,2.117,2.000,34.934,3.082,0,0,2.000,2.000,0.140,0.020,1
3752628296.154000,,,2.094,2.000,34.933,3.082,0,0,2.000,2.000,0.000,0.020,1
3752628416.154000,,,2.104,2.000,34.933,3.083,0,0,2.000,2.000,0.130,0.020,1
3752628536.154000,,,2.109,2.000,34.933,3.083,0,0,2.000,2.000,0.040,0.020,1
3752628656.154000,,,2.097,2.000,34.935,3.084,0,0,2.000,2.000,0.000,0.020,1
3752628776.154000,,,2.110,2.000,34.934,3.087,0,0,2.000,2.000,0.290,0.020,1
3752628896.154000,,,2.097,2.000,34.936,3.085,0,0,2.000,2.000,0.000,0.020,1
3752629016.154000,,,2.091,2.000,34.939,3.085,0,0,2.000,2.000,0.000,0.020,1
3752629136.154000,,,2.117,2.000,34.940,3.085,0,0,2.000,2.000,0.270,0.020,1
3752629256.154000,,,2.101,2.000,34.942,3.085,0,0,2.000,2.000,0.000,0.020,1
3752629376.154000,,,2.101,1.999,34.945,3.086,0,0,2.000,2.000,0.030,0.020,1
3752629496.154000,,,2.114,2.000,34.946,3.086,0,0,2.000,2.000,0.060,0.020,1
3752629616.154000,,,2.094,2.000,34.946,3.087,0,0,2.000,2.000,0.000,0.020,1
3752629736.154000,,,2.111,2.000,34.946,3.087,0,0,2.000,2.000,0.270,0.020,1
3752629856.154000,,,2.105,2.000,34.946,3.086,0,0,2.000,2.000,0.210,0.020,1
3752629976.154000,,,2.091,2.000,34.948,3.087,0,0,2.000,2.000,0.000,0.020,1
3752630096.154000,,,2.112,1.999,34.947,3.087,0,0,2.000,2.000,0.270,0.020,1
3752630216.154000,,,2.104,2.000,34.947,3.087,0,0,2.000,2.000,0.010,0.020,1
3752630336.154000,,,2.092,2.000,34.948,3.086,0,0,2.000,2.000,0.000,0.020,1
3752630456.154000,,,2.111,2.000,34.949,3.085,0,0,2.000,2.000,0.080,0.020,1
3752630576.154000,,,2.107,2.000,34.949,3.086,0,0,2.000,2.000,0.000,0.020,1
3752630696.154000,,,2.097,2.000,34.950,3.087,0,0,2.000,2.000,0.000,0.020,1
3752630816.154000,,,2.115,2.000,34.952,3.084,0,0,2.000,2.000,0.250,0.020,1
3752630936.154000,,,2.096,2.000,34.953,3.085,0,0,2.000,2.000,0.000,0.020,1
3752631056.154000,,,2.104,2.000,34.955,3.080,0,0,2.000,2.000,0.000,0.020,1
3752631176.154000,,,2.118,2.000,34.956,3.082,0,0,2.000,2.000,0.190,0.020,1
3752631296.154000,,,2.090,2.000,34.956,3.081,0,0,2.000,2.000,0.000,0.020,1
3752631416.154000,,,2.107,2.001,34.955,3.082,0,0,2.000,2.000,0.110,0.020,1
3752631536.154000,,,2.115,2.001,34.953,3.082,0,0,2.000,2.000,0.120,0.020,1
3752631656.154000,,,2.095,2.000,34.952,3.079,0,0,2.000,2.000,0.000,0.020,1
3752631776.154000,,,2.109,1.999,34.949,3.081,0,0,2.000,2.000,0.200,0.020,1
3752631896.154000,,,2.115,1.999,34.949,3.080,0,0,2.000,2.000,0.030,0.020,1
3752632016.154000,,,2.095,2.000,34.949,3.080,0,0,2.000,2.000,0.000,0.020,1
3752632136.154000,,,2.113,2.000,34.947,3.083,0,0,2.000,2.000,0.260,0.020,1
3752632256.154000,,,2.096,2.000,34.947,3.086,0,0,2.000,2.000,0.000,0.020,1
3752632376.154000,,,2.095,2.000,34.948,3.082,0,0,2.000,2.000,0.000,0.020,1
3752632496.154000,,,2.116,2.000,34.948,3.080,0,0,2.000,2.000,0.260,0.020,1
3752632616.154000,,,2.097,2.000,34.949,3.080,0,0,2.000,2.000,0.000,0.020,1
3752632736.154000,,,2.094,2.000,34.948,3.077,0,0,2.000,2.000,0.040,0.020,1
3752632856.154000,,,2.115,2.000,34.947,3.077,0,0,2.000,2.000,0.040,0.020,1
3752632976.154000,,,2.100,2.000,34.946,3.078,0,0,2.000,2.000,0.000,0.020,1
3752633096.154000,,,2.099,2.000,34.945,3.078,0,0,2.000,2.000,0.030,0.020,1
3752633216.154000,,,2.115,2.000,34.944,3.079,0,0,2.000,2.000,0.250,0.020,1
3752633336.154000,,,2.097,2.000,34.942,3.079,0,0,2.000,2.000,0.000,0.020,1
3752633456.154000,,,2.111,1.999,34.937,3.086,0,0,2.000,2.000,0.290,0.020,1
3752633576.154000,,,2.115,2.000,34.934,3.087,0,0,2.000,2.000,0.230,0.020,1
3752633696.154000,,,2.092,1.999,34.934,3.085,0,0,2.000,2.000,0.000,0.020,1
3752633816.154000,,,2.107,2.000,34.932,3.087,0,0,2.000,2.000,0.100,0.020,1
3752633936.154000,,,2.117,2.000,34.933,3.085,0,0,2.000,2.000,0.120,0.020,1
3752634056.154000,,,2.093,2.000,34.931,3.084,0,0,2.000,2.000,0.000,0.020,1
3752634176.154000,,,2.118,1.999,34.929,3.080,0,0,2.000,2.000,0.280,0.020,1
3752634296.154000,,,2.106,2.000,34.926,3.081,0,0,2.000,2.000,0.000,0.020,1
3752634416.154000,,,2.097,2.000,34.924,3.079,0,0,2.000,2.000,0.000,0.020,1
3752634536.154000,,,2.116,2.000,34.923,3.080,0,0,2.000,2.000,0.270,0.020,1
3752634656.154000,,,2.104,2.000,34.923,3.084,0,0,2.000,2.000,0.000,0.020,1
3752634776.154000,,,2.097,2.000,34.924,3.087,0,0,2.000,2.000,0.000,0.020,1
3752634896.154000,,,2.115,2.000,34.927,3.083,0,0,2.000,2.000,0.190,0.020,1
3752635016.154000,,,2.101,2.000,34.927,3.084,0,0,2.000,2.000,0.070,0.020,1
3752635136.154000,,,2.100,2.001,34.926,3.084,0,0,2.000,2.000,0.090,0.020,1
3752635256.154000,,,2.115,2.000,34.926,3.084,0,0,2.000,2.000,0.080,0.020,1
3752635376.154000,,,2.092,2.000,34.926,3.089,0,0,2.000,2.000,0.000,0.020,1
3752635496.154000,,,2.106,2.000,34.926,3.088,0,0,2.000,2.000,0.260,0.020,1
3752635616.154000,,,2.113,2.000,34.926,3.090,0,0,2.000,2.000,0.240,0.020,1
3752635736.154000,,,2.094,2.000,34.927,3.088,0,0,2.000,2.000,0.000,0.020,1
3752635856.154000,,,2.113,2.000,34.927,3.088,0,0,2.000,2.000,0.270,0.020,1
3752635976.154000,,,2.097,2.000,34.926,3.089,0,0,2.000,2.000,0.000,0.020,1
3752636096.154000,,,2.100,2.000,34.928,3.085,0,0,2.000,2.000,0.170,0.020,1
3752636216.154000,,,2.114,2.000,34.928,3.084,0,0,2.000,2.000,0.270,0.020,1