File: log/20221130.dat
[Header]
; Displex Transport Data File (default extension .dat)
; Copyright 2016, Hechang LEI, hlei@ruc.edu.cn. All rights reserved.
BYAPP, Displex, 2.0
INFO, 9T mag, Release 2.0.
INFO, Channel 1, Temperature Sensor
INFO, Sample 1 Length (cm): 0.000000; Width (cm): 0.000000; Thickness (cm): 0.000000.

[Data]
Timestamp(s),Field(Oe),Field Status,TempA(K),TempB(K),TempC(K),TempD(K),Ramp1,Ramp2,Setpoint1,Setpoint2,Output1(%),Output2(%),Temp Status
3752640913.802800,,,1.506,1.536,35.138,2.977,0,0,2.000,2.000,0.000,0.000,4
3752641004.275800,,,1.505,1.535,35.133,2.979,0,0,2.000,2.000,0.000,0.000,4
3752641034.275800,,,1.505,1.535,35.132,2.978,0,0,2.000,2.000,0.000,0.000,4
3752641064.275800,,,1.505,1.535,35.130,2.978,0,0,2.000,2.000,0.000,0.000,4
3752641094.275800,,,1.505,1.540,35.128,2.984,0,0,2.000,2.000,0.000,0.000,4
3752641124.275800,,,1.506,1.545,35.127,3.388,0,0,2.000,2.000,0.000,0.000,4
3752641154.275800,,,1.506,1.553,35.121,3.908,0,0,2.000,2.000,0.000,0.000,4
3752641184.275800,,,1.507,1.563,35.112,3.938,0,0,2.000,2.000,0.000,0.000,4
3752641214.275800,,,1.508,1.573,35.105,3.895,0,0,2.000,2.000,0.000,0.000,4
3752641244.275800,,,1.510,1.586,35.105,3.846,0,0,2.000,2.000,0.000,0.000,4
3752641274.275800,,,1.512,1.596,35.110,3.799,0,0,2.000,2.000,0.000,0.000,4
3752641304.275800,,,1.515,1.607,35.118,3.760,0,0,2.000,2.000,0.000,0.000,4
3752641334.275800,,,1.516,1.615,35.126,3.723,0,0,2.000,2.000,0.000,0.000,4
3752641364.275800,,,1.518,1.622,35.135,3.691,0,0,2.000,2.000,0.000,0.000,4
3752641394.275800,,,1.519,1.629,35.144,3.662,0,0,2.000,2.000,0.000,0.000,4
3752641424.275800,,,1.520,1.634,35.153,3.635,0,0,2.000,2.000,0.000,0.000,4
3752641454.275800,,,1.521,1.638,35.160,3.611,0,0,2.000,2.000,0.000,0.000,4
3752641484.275800,,,1.522,1.642,35.166,3.591,0,0,2.000,2.000,0.000,0.000,4
3752641514.275800,,,1.523,1.646,35.173,3.570,0,0,2.000,2.000,0.000,0.000,4
3752641544.275800,,,1.524,1.649,35.179,3.554,0,0,2.000,2.000,0.000,0.000,4
3752641574.275800,,,1.525,1.652,35.188,3.535,0,0,2.000,2.000,0.000,0.000,4
3752641604.275800,,,1.526,1.653,35.196,3.482,0,0,2.000,2.000,0.000,0.000,4
3752641634.275800,,,1.526,1.653,35.206,3.352,0,0,2.000,2.000,0.000,0.000,4
3752641664.275800,,,1.526,1.654,35.217,3.295,0,0,2.000,2.000,0.000,0.000,4
3752641694.275800,,,1.527,1.655,35.228,3.269,0,0,2.000,2.000,0.000,0.000,4
3752641724.275800,,,1.527,1.656,35.239,3.257,0,0,2.000,2.000,0.000,0.000,4
3752641754.275800,,,1.527,1.652,35.250,3.248,0,0,2.000,2.000,0.000,0.000,4
3752641784.275800,,,1.528,1.658,35.260,3.243,0,0,2.000,2.000,0.000,0.000,4
3752641814.275800,,,1.528,1.659,35.271,3.239,0,0,2.000,2.000,0.000,0.000,4
3752641844.275800,,,1.529,1.660,35.281,3.235,0,0,2.000,2.000,0.000,0.000,4
3752641874.275800,,,1.530,1.661,35.293,3.231,0,0,2.000,2.000,0.000,0.000,4
3752641904.275800,,,1.531,1.662,35.305,3.227,0,0,2.000,2.000,0.000,0.000,4
3752641934.275800,,,1.532,1.664,35.318,3.225,0,0,2.000,2.000,0.000,0.000,4
3752641964.275800,,,1.533,1.665,35.331,3.221,0,0,2.000,2.000,0.000,0.000,4
3752641994.275800,,,1.535,1.666,35.345,3.217,0,0,2.000,2.000,0.000,0.000,4
3752642024.275800,,,1.536,1.668,35.359,3.214,0,0,2.000,2.000,0.000,0.000,4
3752642054.275800,,,1.537,1.669,35.374,3.211,0,0,2.000,2.000,0.000,0.000,4
3752642084.275800,,,1.538,1.670,35.390,3.206,0,0,2.000,2.000,0.000,0.000,4
3752642114.275800,,,1.539,1.672,35.406,3.204,0,0,2.000,2.000,0.000,0.000,4
3752642144.275800,,,1.540,1.673,35.423,3.201,0,0,2.000,2.000,0.000,0.000,4
3752642174.275800,,,1.542,1.674,35.441,3.197,0,0,2.000,2.000,0.000,0.000,4
3752642204.275800,,,1.543,1.675,35.459,3.197,0,0,2.000,2.000,0.000,0.000,4
3752642234.275800,,,1.544,1.676,35.478,3.194,0,0,2.000,2.000,0.000,0.000,4
3752642264.275800,,,1.544,1.676,35.499,3.146,0,0,2.000,2.000,0.000,0.000,4
3752642294.275800,,,1.544,1.676,35.520,3.058,0,0,2.000,2.000,0.000,0.000,4
3752642324.275800,,,1.544,1.676,35.541,3.054,0,0,2.000,2.000,0.000,0.000,4
3752642354.275800,,,1.543,1.675,35.560,3.122,0,0,2.000,2.000,0.000,0.000,4
3752642384.275800,,,1.542,1.674,35.575,3.157,0,0,2.000,2.000,0.000,0.000,4
3752642414.275800,,,1.540,1.673,35.590,3.173,0,0,2.000,2.000,0.000,0.000,4
3752642444.275800,,,1.539,1.671,35.602,3.182,0,0,2.000,2.000,0.000,0.000,4
3752642474.275800,,,1.539,1.670,35.611,3.190,0,0,2.000,2.000,0.000,0.000,4
3752642504.275800,,,1.538,1.669,35.619,3.194,0,0,2.000,2.000,0.000,0.000,4
3752642534.275800,,,1.537,1.669,35.624,3.199,0,0,2.000,2.000,0.000,0.000,4
3752642564.275800,,,1.537,1.668,35.627,3.202,0,0,2.000,2.000,0.000,0.000,4
3752642594.275800,,,1.536,1.667,35.628,3.208,0,0,2.000,2.000,0.000,0.000,4
3752642624.275800,,,1.535,1.666,35.628,3.212,0,0,2.000,2.000,0.000,0.000,4
3752642654.275800,,,1.534,1.665,35.626,3.216,0,0,2.000,2.000,0.000,0.000,4
3752642684.275800,,,1.534,1.664,35.622,3.218,0,0,2.000,2.000,0.000,0.000,4
3752642714.275800,,,1.533,1.663,35.617,3.223,0,0,2.000,2.000,0.000,0.000,4
3752642744.275800,,,1.532,1.661,35.611,3.227,0,0,2.000,2.000,0.000,0.000,4
3752642774.275800,,,1.531,1.660,35.603,3.232,0,0,2.000,2.000,0.000,0.000,4
3752642804.275800,,,1.530,1.659,35.595,3.233,0,0,2.000,2.000,0.000,0.000,4
3752642834.275800,,,1.529,1.658,35.587,3.236,0,0,2.000,2.000,0.000,0.000,4
3752642864.275800,,,1.528,1.656,35.577,3.240,0,0,2.000,2.000,0.000,0.000,4
3752642894.275800,,,1.527,1.655,35.568,3.243,0,0,2.000,2.000,0.000,0.000,4
3752642924.275800,,,1.527,1.653,35.557,3.247,0,0,2.000,2.000,0.000,0.000,4
3752642954.275800,,,1.526,1.651,35.546,3.164,0,0,2.000,2.000,0.000,0.000,4
3752642984.275800,,,1.526,1.652,35.536,3.053,0,0,2.000,2.000,0.000,0.000,4
3752643014.275800,,,1.526,1.651,35.528,3.129,0,0,2.000,2.000,0.000,0.000,4
3752643044.275800,,,1.524,1.651,35.517,3.319,0,0,2.000,2.000,0.000,0.000,4
3752643074.275800,,,1.523,1.648,35.503,3.440,0,0,2.000,2.000,0.000,0.000,4
3752643104.275800,,,1.520,1.644,35.486,3.495,0,0,2.000,2.000,0.000,0.000,4
3752643134.275800,,,1.519,1.640,35.471,3.528,0,0,2.000,2.000,0.000,0.000,4
3752643164.275800,,,1.517,1.635,35.455,3.555,0,0,2.000,2.000,0.000,0.000,4
3752643194.275800,,,1.516,1.630,35.440,3.575,0,0,2.000,2.000,0.000,0.000,4
3752643224.275800,,,1.515,1.625,35.426,3.596,0,0,2.000,2.000,0.000,0.000,4
3752643254.275800,,,1.514,1.619,35.411,3.619,0,0,2.000,2.000,0.000,0.000,4
3752643284.275800,,,1.513,1.613,35.397,3.642,0,0,2.000,2.000,0.000,0.000,4
3752643314.275800,,,1.512,1.605,35.383,3.666,0,0,2.000,2.000,0.000,0.000,4
3752643344.275800,,,1.511,1.596,35.370,3.691,0,0,2.000,2.000,0.000,0.000,4
3752643374.275800,,,1.510,1.586,35.357,3.720,0,0,2.000,2.000,0.000,0.000,4
3752643404.275800,,,1.510,1.577,35.343,3.754,0,0,2.000,2.000,0.000,0.000,4
3752643434.275800,,,1.510,1.566,35.331,3.795,0,0,2.000,2.000,0.000,0.000,4
3752643464.275800,,,1.510,1.557,35.319,3.845,0,0,2.000,2.000,0.000,0.000,4
3752643494.275800,,,1.510,1.551,35.307,3.906,0,0,2.000,2.000,0.000,0.000,4
3752643524.275800,,,1.511,1.549,35.294,3.974,0,0,2.000,2.000,0.000,0.000,4
3752643554.275800,,,1.511,1.550,35.281,4.192,0,0,2.000,2.000,0.000,0.000,4
3752643584.275800,,,1.511,1.557,35.261,4.202,0,0,2.000,2.000,0.000,0.000,4
3752643614.275800,,,1.511,1.566,35.236,4.075,0,0,2.000,2.000,0.000,0.000,4
3752643644.275800,,,1.512,1.576,35.219,3.978,0,0,2.000,2.000,0.000,0.000,4
3752643674.275800,,,1.512,1.586,35.213,3.908,0,0,2.000,2.000,0.000,0.000,4
3752643704.275800,,,1.513,1.596,35.217,3.855,0,0,2.000,2.000,0.000,0.000,4
3752643734.275800,,,1.513,1.604,35.228,3.811,0,0,2.000,2.000,0.000,0.000,4
3752643764.275800,,,1.514,1.612,35.240,3.775,0,0,2.000,2.000,0.000,0.000,4
3752643794.275800,,,1.514,1.618,35.253,3.740,0,0,2.000,2.000,0.000,0.000,4
3752643824.275800,,,1.515,1.624,35.266,3.703,0,0,2.000,2.000,0.000,0.000,4
3752643854.275800,,,1.516,1.629,35.275,3.668,0,0,2.000,2.000,0.000,0.000,4
3752643884.275800,,,1.517,1.634,35.282,3.633,0,0,2.000,2.000,0.000,0.000,4
3752643914.275800,,,1.518,1.638,35.287,3.604,0,0,2.000,2.000,0.000,0.000,4
3752643944.275800,,,1.518,1.641,35.290,3.578,0,0,2.000,2.000,0.000,0.000,4
3752643974.275800,,,1.520,1.645,35.292,3.558,0,0,2.000,2.000,0.000,0.000,4
3752644004.275800,,,1.521,1.648,35.295,3.538,0,0,2.000,2.000,0.000,0.000,4
3752644034.275800,,,1.522,1.649,35.298,3.503,0,0,2.000,2.000,0.000,0.000,4
3752644064.275800,,,1.522,1.649,35.303,3.362,0,0,2.000,2.000,0.000,0.000,4
3752644094.275800,,,1.523,1.650,35.310,3.297,0,0,2.000,2.000,0.000,0.000,4
3752644124.275800,,,1.523,1.651,35.317,3.268,0,0,2.000,2.000,0.000,0.000,4
3752644154.275800,,,1.524,1.652,35.325,3.255,0,0,2.000,2.000,0.000,0.000,4
3752644184.275800,,,1.525,1.654,35.332,3.246,0,0,2.000,2.000,0.000,0.000,4
3752644214.275800,,,1.525,1.655,35.339,3.242,0,0,2.000,2.000,0.000,0.000,4
3752644244.275800,,,1.527,1.658,35.346,3.237,0,0,2.000,2.000,0.000,0.000,4
3752644274.275800,,,1.528,1.659,35.354,3.233,0,0,2.000,2.000,0.000,0.000,4
3752644304.275800,,,1.530,1.666,35.362,3.231,0,0,2.000,2.000,0.000,0.000,4
3752644334.275800,,,1.532,1.667,35.372,3.228,0,0,2.000,2.000,0.000,0.000,4
3752644364.275800,,,1.533,1.669,35.382,3.225,0,0,2.000,2.000,0.000,0.000,4
3752644513.560800,-80.744,Sweeping down,1.540,1.676,35.443,3.209,0,0,2.000,2.000,0.000,0.000,4
3752644543.560800,-82.385,Sweeping down,1.541,1.678,35.457,3.206,0,0,2.000,2.000,0.000,0.000,4
3752644573.560800,-83.999,Sweeping down,1.542,1.679,35.474,3.201,0,0,2.000,2.000,0.000,0.000,4
3752644603.560800,-85.613,Sweeping down,1.544,1.680,35.489,3.198,0,0,2.000,2.000,0.000,0.000,4
3752644633.560800,-87.256,Sweeping down,1.545,1.681,35.506,3.196,0,0,2.000,2.000,0.000,0.000,4
3752644663.560800,-88.869,Sweeping down,1.546,1.683,35.523,3.192,0,0,2.000,2.000,0.000,0.000,4
3752644693.560800,-89.964,Sweeping down,1.547,1.683,35.542,3.165,0,0,2.000,2.000,0.000,0.000,4
3752644723.560800,-90.000,Sweeping down,1.547,1.683,35.563,3.068,0,0,2.000,2.000,0.000,0.000,4
3752644753.560800,-90.000,Sweeping down,1.547,1.683,35.585,3.024,0,0,2.000,2.000,0.000,0.000,4
3752644791.652800,-90.000,Sweeping down,1.874,1.945,35.611,3.006,0,0,2.000,2.000,0.470,0.010,4
3752644818.993800,-90.000,Sweeping down,2.006,2.000,35.626,3.002,0,0,2.000,2.000,0.340,0.000,4
3752644848.993800,-90.000,Sweeping down,2.001,2.000,35.634,3.004,0,0,2.000,2.000,0.280,0.010,4
3752644878.993800,-89.575,Sweeping up,2.002,2.000,35.634,3.010,0,0,2.000,2.000,0.220,0.010,4
3752644908.993800,-88.011,Sweeping up,2.006,2.000,35.629,3.083,0,0,2.000,2.000,0.310,0.010,1
3752644938.993800,-86.396,Sweeping up,1.995,2.000,35.622,3.152,0,0,2.000,2.000,0.100,0.010,1
3752644968.993800,-84.780,Sweeping up,2.002,2.000,35.611,3.185,0,0,2.000,2.000,0.080,0.010,1
3752644998.993800,-83.135,Sweeping up,2.010,2.000,35.599,3.203,0,0,2.000,2.000,0.390,0.010,1
3752645028.993800,-81.519,Sweeping up,1.999,2.000,35.585,3.213,0,0,2.000,2.000,0.000,0.010,1
3752645058.993800,-79.905,Sweeping up,2.004,2.000,35.570,3.223,0,0,2.000,2.000,0.000,0.010,1
3752645088.993800,-78.259,Sweeping up,2.014,2.000,35.552,3.230,0,0,2.000,2.000,0.220,0.010,1
3752645118.993800,-76.645,Sweeping up,2.027,2.000,35.534,3.237,0,0,2.000,2.000,0.070,0.010,1
3752645148.993800,-75.029,Sweeping up,2.031,2.000,35.513,3.243,0,0,2.000,2.000,0.390,0.010,1
3752645178.993800,-73.413,Sweeping up,2.029,2.000,35.491,3.249,0,0,2.000,2.000,0.310,0.010,1
3752645208.993800,-71.797,Sweeping up,2.021,2.000,35.468,3.256,0,0,2.000,2.000,0.020,0.010,1
3752645238.993800,-70.155,Sweeping up,2.025,2.000,35.445,3.261,0,0,2.000,2.000,0.000,0.010,1
3752645268.993800,-68.542,Sweeping up,2.035,2.000,35.420,3.268,0,0,2.000,2.000,0.040,0.010,1
3752645298.993800,-66.927,Sweeping up,2.034,2.000,35.396,3.272,0,0,2.000,2.000,0.000,0.010,1
3752645328.993800,-65.313,Sweeping up,2.048,2.000,35.371,3.279,0,0,2.000,2.000,0.210,0.010,1
3752645358.993800,-63.668,Sweeping up,2.052,2.000,35.347,3.284,0,0,2.000,2.000,0.320,0.010,1
3752645388.993800,-62.053,Sweeping up,2.044,2.000,35.321,3.290,0,0,2.000,2.000,0.280,0.010,1
3752645418.993800,-60.439,Sweeping up,2.030,2.000,35.297,3.295,0,0,2.000,2.000,0.000,0.010,1
3752645448.993800,-58.823,Sweeping up,2.038,2.000,35.273,3.300,0,0,2.000,2.000,0.000,0.010,1
3752645478.993800,-57.179,Sweeping up,2.036,2.000,35.249,3.305,0,0,2.000,2.000,0.000,0.010,1
3752645508.993800,-55.563,Sweeping up,2.038,2.000,35.225,3.311,0,0,2.000,2.000,0.000,0.010,1
3752645538.993800,-53.899,Sweeping up,2.045,2.000,35.202,3.316,0,0,2.000,2.000,0.000,0.010,1
3752645568.993800,-50.869,Sweeping up,2.053,2.000,35.179,3.460,0,0,2.000,2.000,0.060,0.010,1
3752645598.993800,-47.582,Sweeping up,2.065,2.000,35.154,3.540,0,0,2.000,2.000,0.220,0.010,1
3752645628.993800,-44.353,Sweeping up,2.063,2.000,35.129,3.580,0,0,2.000,2.000,0.350,0.010,1
3752645658.993800,-41.125,Sweeping up,2.064,2.000,35.105,3.607,0,0,2.000,2.000,0.290,0.010,1
3752645688.993800,-37.898,Sweeping up,2.070,2.000,35.081,3.628,0,0,2.000,2.000,0.340,0.010,1
3752645718.993800,-34.614,Sweeping up,2.060,2.000,35.058,3.649,0,0,2.000,2.000,0.290,0.010,1
3752645748.993800,-31.385,Sweeping up,2.056,2.000,35.036,3.668,0,0,2.000,2.000,0.000,0.010,1
3752645778.993800,-28.159,Sweeping up,2.056,2.000,35.015,3.689,0,0,2.000,2.000,0.000,0.010,1
3752645808.993800,-24.933,Sweeping up,2.062,2.000,34.994,3.712,0,0,2.000,2.000,0.000,0.020,1
3752645838.993800,-21.649,Sweeping up,2.059,2.000,34.974,3.735,0,0,2.000,2.000,0.000,0.020,1
3752645868.993800,-18.424,Sweeping up,2.062,2.000,34.955,3.762,0,0,2.000,2.000,0.000,0.020,1
3752645898.993800,-15.198,Sweeping up,2.063,2.000,34.937,3.792,0,0,2.000,2.000,0.000,0.020,1
3752645928.993800,-11.973,Sweeping up,2.060,2.000,34.920,3.827,0,0,2.000,2.000,0.000,0.020,1
3752645958.993800,-8.691,Sweeping up,2.064,2.000,34.903,3.871,0,0,2.000,2.000,0.000,0.020,1
3752645988.993800,-5.469,Sweeping up,2.065,2.000,34.887,3.925,0,0,2.000,2.000,0.000,0.020,1
3752646018.993800,-2.250,Sweeping up,2.063,2.000,34.872,3.998,0,0,2.000,2.000,0.000,0.020,1
3752646048.993800,0.858,Sweeping up,2.066,2.000,34.857,4.073,0,0,2.000,2.000,0.000,0.020,1
3752646078.993800,4.074,Sweeping up,2.062,2.000,34.844,4.359,0,0,2.000,2.000,0.000,0.020,1
3752646108.993800,7.310,Sweeping up,2.073,2.000,34.829,4.295,0,0,2.000,2.000,0.200,0.020,1
3752646138.993800,10.534,Sweeping up,2.078,2.000,34.818,4.152,0,0,2.000,2.000,0.100,0.020,1
3752646168.993800,13.758,Sweeping up,2.084,2.000,34.811,4.031,0,0,2.000,2.000,0.290,0.020,1
3752646198.993800,17.040,Sweeping up,2.090,2.001,34.807,3.942,0,0,2.000,2.000,0.340,0.020,1
3752646228.993800,20.265,Sweeping up,2.090,2.000,34.803,3.876,0,0,2.000,2.000,0.320,0.010,1
3752646258.993800,23.492,Sweeping up,2.089,2.001,34.800,3.825,0,0,2.000,2.000,0.340,0.010,1
3752646288.993800,26.717,Sweeping up,2.081,2.000,34.795,3.788,0,0,2.000,2.000,0.120,0.010,1
3752646318.993800,30.002,Sweeping up,2.082,2.000,34.792,3.758,0,0,2.000,2.000,0.340,0.010,1
3752646348.993800,33.230,Sweeping up,2.076,2.000,34.789,3.731,0,0,2.000,2.000,0.350,0.010,1
3752646378.993800,36.456,Sweeping up,2.059,2.000,34.787,3.709,0,0,2.000,2.000,0.000,0.010,1
3752646408.993800,39.685,Sweeping up,2.052,2.000,34.785,3.688,0,0,2.000,2.000,0.000,0.010,1
3752646438.993800,42.970,Sweeping up,2.049,2.000,34.786,3.669,0,0,2.000,2.000,0.000,0.010,1
3752646468.993800,46.198,Sweeping up,2.054,2.000,34.787,3.654,0,0,2.000,2.000,0.140,0.010,1
3752646498.993800,49.427,Sweeping up,2.065,2.000,34.790,3.637,0,0,2.000,2.000,0.000,0.010,1
3752646528.993800,52.656,Sweeping up,2.063,2.000,34.793,3.622,0,0,2.000,2.000,0.350,0.010,1
3752646558.993800,55.279,Sweeping up,2.050,2.000,34.798,3.556,0,0,2.000,2.000,0.220,0.010,1
3752646588.993800,56.906,Sweeping up,2.045,2.000,34.806,3.440,0,0,2.000,2.000,0.000,0.010,1
3752646618.993800,58.524,Sweeping up,2.062,2.000,34.815,3.386,0,0,2.000,2.000,0.100,0.010,1
3752646648.993800,60.142,Sweeping up,2.064,2.000,34.823,3.364,0,0,2.000,2.000,0.350,0.010,1
3752646678.993800,61.788,Sweeping up,2.045,1.999,34.831,3.353,0,0,2.000,2.000,0.000,0.010,1
3752646708.993800,63.406,Sweeping up,2.038,2.000,34.840,3.346,0,0,2.000,2.000,0.000,0.010,1
3752646738.993800,65.023,Sweeping up,2.058,2.000,34.848,3.343,0,0,2.000,2.000,0.280,0.010,1
3752646768.993800,66.638,Sweeping up,2.051,2.000,34.856,3.339,0,0,2.000,2.000,0.220,0.010,1
3752646798.993800,68.284,Sweeping up,2.040,2.001,34.866,3.336,0,0,2.000,2.000,0.000,0.010,1
3752646828.993800,69.902,Sweeping up,2.050,2.000,34.876,3.332,0,0,2.000,2.000,0.120,0.010,1
3752646858.993800,71.515,Sweeping up,2.049,2.000,34.887,3.330,0,0,2.000,2.000,0.170,0.010,1
3752646888.993800,73.130,Sweeping up,2.034,2.000,34.898,3.326,0,0,2.000,2.000,0.000,0.010,1
3752646918.993800,74.772,Sweeping up,2.050,2.000,34.911,3.322,0,0,2.000,2.000,0.190,0.010,1
3752646948.993800,76.386,Sweeping up,2.044,2.000,34.924,3.319,0,0,2.000,2.000,0.300,0.010,1
3752646978.993800,78.002,Sweeping up,2.039,2.000,34.937,3.317,0,0,2.000,2.000,0.000,0.010,1
3752647008.993800,79.617,Sweeping up,2.055,2.000,34.952,3.313,0,0,2.000,2.000,0.310,0.010,1
3752647038.993800,81.260,Sweeping up,2.049,2.000,34.967,3.312,0,0,2.000,2.000,0.190,0.010,1
3752647068.993800,82.878,Sweeping up,2.035,2.000,34.983,3.309,0,0,2.000,2.000,0.040,0.010,1
3752647098.993800,84.494,Sweeping up,2.051,2.000,34.999,3.306,0,0,2.000,2.000,0.160,0.010,1
3752647128.993800,86.107,Sweeping up,2.085,2.000,35.017,3.302,0,0,2.000,2.000,0.000,0.010,1
3752647158.993800,87.753,Sweeping up,2.091,2.000,35.037,3.299,0,0,2.000,2.000,0.270,0.010,1
3752647188.993800,89.368,Sweeping up,2.078,2.000,35.060,3.297,0,0,2.000,2.000,0.000,0.010,1
3752647218.993800,90.001,Sweeping up,2.092,2.000,35.087,3.237,0,0,2.000,2.000,0.040,0.010,1
3752647248.993800,90.000,Sweeping up,2.085,2.000,35.117,3.164,0,0,2.000,2.000,0.010,0.010,1
3752647278.993800,90.000,Sweeping up,2.077,2.000,35.147,3.134,0,0,2.000,2.000,0.000,0.010,1
3752647308.993800,90.000,Sweeping up,2.089,2.000,35.175,3.122,0,0,2.000,2.000,0.270,0.010,1
3752647338.993800,90.000,Sweeping up,2.084,2.000,35.203,3.116,0,0,2.000,2.000,0.000,0.010,1
3752647368.993800,90.000,Sweeping up,2.086,2.000,35.229,3.116,0,0,2.000,2.000,0.230,0.010,1
3752647398.993800,90.000,Sweeping up,2.084,2.000,35.253,3.115,0,0,2.000,2.000,0.000,0.010,1
3752647428.993800,90.000,Sweeping up,2.093,2.000,35.275,3.115,0,0,2.000,2.000,0.240,0.010,1
3752647458.993800,90.000,Sweeping up,2.078,2.000,35.297,3.115,0,0,2.000,2.000,0.010,0.010,1
3752647488.993800,90.000,Sweeping up,2.088,2.000,35.317,3.115,0,0,2.000,2.000,0.270,0.010,1
3752647518.993800,90.000,Sweeping up,2.087,2.000,35.337,3.116,0,0,2.000,2.000,0.000,0.010,1
3752647548.993800,90.000,Sweeping up,2.080,2.000,35.356,3.114,0,0,2.000,2.000,0.160,0.010,1
3752647578.993800,90.000,Sweeping up,2.086,2.000,35.374,3.115,0,0,2.000,2.000,0.000,0.010,1
3752647608.993800,90.000,Sweeping up,2.068,2.000,35.391,3.115,0,0,2.000,2.000,0.000,0.010,1
3752647638.993800,90.000,Sweeping up,2.087,2.000,35.407,3.116,0,0,2.000,2.000,0.170,0.010,1
3752647668.993800,90.000,Sweeping up,2.073,2.000,35.423,3.117,0,0,2.000,2.000,0.000,0.010,1
3752647698.993800,90.000,Sweeping up,2.086,2.000,35.439,3.115,0,0,2.000,2.000,0.000,0.010,1
3752647728.993800,90.000,Sweeping up,2.072,2.000,35.454,3.115,0,0,2.000,2.000,0.000,0.010,1
3752647758.993800,90.000,Sweeping up,2.095,2.000,35.468,3.116,0,0,2.000,2.000,0.110,0.010,1
3752647788.993800,90.000,Sweeping up,2.067,2.000,35.482,3.115,0,0,2.000,2.000,0.000,0.010,1
3752647818.993800,90.000,Sweeping up,2.090,2.000,35.495,3.115,0,0,2.000,2.000,0.120,0.010,1
3752647848.993800,90.000,Sweeping up,2.071,2.000,35.507,3.115,0,0,2.000,2.000,0.000,0.010,1
3752647878.993800,90.000,Sweeping up,2.091,2.000,35.520,3.116,0,0,2.000,2.000,0.000,0.010,1
3752647908.993800,90.000,Sweeping up,2.070,2.000,35.532,3.115,0,0,2.000,2.000,0.000,0.010,1
3752647938.993800,90.000,Sweeping up,2.088,2.000,35.543,3.115,0,0,2.000,2.000,0.210,0.010,1
3752647968.993800,90.000,Sweeping up,2.075,2.000,35.553,3.114,0,0,2.000,2.000,0.000,0.010,1
3752647998.993800,90.000,Sweeping up,2.086,2.000,35.564,3.115,0,0,2.000,2.000,0.200,0.010,1
3752648028.993800,90.000,Sweeping up,2.073,2.000,35.574,3.114,0,0,2.000,2.000,0.000,0.010,1
3752648058.993800,90.000,Sweeping up,2.081,2.000,35.585,3.114,0,0,2.000,2.000,0.030,0.010,1
3752648088.993800,90.000,Sweeping up,2.073,2.000,35.595,3.114,0,0,2.000,2.000,0.000,0.010,1
3752648118.993800,90.000,Sweeping up,2.077,2.000,35.603,3.113,0,0,2.000,2.000,0.190,0.010,1
3752648148.993800,90.000,Sweeping up,2.083,2.000,35.613,3.114,0,0,2.000,2.000,0.000,0.010,1
3752648178.993800,90.000,Sweeping up,2.074,2.000,35.622,3.114,0,0,2.000,2.000,0.060,0.010,1
3752648208.993800,90.000,Sweeping up,2.081,2.000,35.629,3.115,0,0,2.000,2.000,0.020,0.010,1
3752648238.993800,90.000,Sweeping up,2.068,2.000,35.637,3.114,0,0,2.000,2.000,0.000,0.010,1
3752648268.993800,90.000,Sweeping up,2.092,2.000,35.645,3.116,0,0,2.000,2.000,0.260,0.010,1
3752648298.993800,90.000,Sweeping up,2.069,2.000,35.653,3.115,0,0,2.000,2.000,0.000,0.010,1
3752648328.993800,90.000,Sweeping up,2.087,2.000,35.659,3.116,0,0,2.000,2.000,0.270,0.010,1
3752648358.993800,90.000,Sweeping up,2.072,2.000,35.667,3.114,0,0,2.000,2.000,0.000,0.010,1
3752648388.993800,90.000,Sweeping up,2.093,2.000,35.673,3.114,0,0,2.000,2.000,0.270,0.010,1
3752648418.993800,90.000,Sweeping up,2.066,2.000,35.680,3.115,0,0,2.000,2.000,0.000,0.010,1
3752648448.993800,90.000,Sweeping up,2.090,2.000,35.686,3.115,0,0,2.000,2.000,0.160,0.010,1
3752648478.993800,90.000,Sweeping up,2.071,2.000,35.692,3.115,0,0,2.000,2.000,0.000,0.010,1
3752648508.993800,90.000,Sweeping up,2.082,2.000,35.698,3.115,0,0,2.000,2.000,0.230,0.010,1
3752648538.993800,90.000,Sweeping up,2.083,2.000,35.704,3.114,0,0,2.000,2.000,0.000,0.010,1
3752648568.993800,90.000,Sweeping up,2.074,2.000,35.710,3.114,0,0,2.000,2.000,0.060,0.010,1
3752648598.993800,90.000,Sweeping up,2.087,2.000,35.715,3.115,0,0,2.000,2.000,0.160,0.010,1
3752648628.993800,90.000,Sweeping up,2.074,2.000,35.721,3.113,0,0,2.000,2.000,0.000,0.010,1
3752648658.993800,90.000,Sweeping up,2.086,2.000,35.726,3.113,0,0,2.000,2.000,0.250,0.010,1
3752648688.993800,90.000,Sweeping up,2.074,2.001,35.732,3.114,0,0,2.000,2.000,0.100,0.010,1
3752648718.993800,90.000,Sweeping up,2.088,2.000,35.738,3.114,0,0,2.000,2.000,0.200,0.010,1
3752648748.993800,90.000,Sweeping up,2.074,2.000,35.743,3.114,0,0,2.000,2.000,0.000,0.010,1
3752648778.993800,90.000,Sweeping up,2.091,2.000,35.749,3.112,0,0,2.000,2.000,0.240,0.010,1
3752648808.993800,90.000,Sweeping up,2.068,2.000,35.753,3.113,0,0,2.000,2.000,0.000,0.010,1
3752648838.993800,90.000,Sweeping up,2.080,2.000,35.758,3.114,0,0,2.000,2.000,0.210,0.010,1
3752648868.993800,90.000,Sweeping up,2.068,2.000,35.762,3.115,0,0,2.000,2.000,0.000,0.010,1
3752648898.993800,90.000,Sweeping up,2.083,2.000,35.768,3.115,0,0,2.000,2.000,0.240,0.010,1
3752648928.993800,90.000,Sweeping up,2.076,2.000,35.773,3.115,0,0,2.000,2.000,0.000,0.010,1
3752648958.993800,90.000,Sweeping up,2.076,2.000,35.777,3.115,0,0,2.000,2.000,0.120,0.010,1
3752648988.993800,90.000,Sweeping up,2.087,2.000,35.780,3.115,0,0,2.000,2.000,0.070,0.010,1
3752649018.993800,90.000,Sweeping up,2.078,2.000,35.784,3.116,0,0,2.000,2.000,0.030,0.010,1
3752649048.993800,90.000,Sweeping up,2.087,2.000,35.788,3.116,0,0,2.000,2.000,0.270,0.010,1
3752649078.993800,90.000,Sweeping up,2.071,2.000,35.792,3.116,0,0,2.000,2.000,0.040,0.010,1
3752649108.993800,90.000,Sweeping up,2.086,2.000,35.795,3.115,0,0,2.000,2.000,0.270,0.010,1
3752649138.993800,90.000,Sweeping up,2.073,2.000,35.799,3.116,0,0,2.000,2.000,0.000,0.010,1
3752649168.993800,90.000,Sweeping up,2.081,2.000,35.804,3.114,0,0,2.000,2.000,0.230,0.010,1
3752649198.993800,90.000,Sweeping up,2.087,2.000,35.808,3.115,0,0,2.000,2.000,0.200,0.010,1
3752649228.993800,90.000,Sweeping up,2.071,2.000,35.812,3.115,0,0,2.000,2.000,0.000,0.010,1
3752649258.993800,90.000,Sweeping up,2.088,2.000,35.816,3.115,0,0,2.000,2.000,0.250,0.010,1
3752649288.993800,90.000,Sweeping up,2.062,2.000,35.820,3.115,0,0,2.000,2.000,0.000,0.010,1
3752649318.993800,90.000,Sweeping up,2.086,2.000,35.824,3.116,0,0,2.000,2.000,0.270,0.010,1
3752649348.993800,90.000,Sweeping up,2.072,2.000,35.827,3.115,0,0,2.000,2.000,0.000,0.010,1
3752649378.993800,90.000,Sweeping up,2.083,2.000,35.830,3.116,0,0,2.000,2.000,0.150,0.010,1
3752649408.993800,89.444,Sweeping to zero,2.074,2.000,35.833,3.118,0,0,2.000,2.000,0.000,0.010,1
3752649438.993800,87.869,Sweeping to zero,2.071,2.000,35.836,3.189,0,0,2.000,2.000,0.000,0.010,1
3752649468.993800,86.226,Sweeping to zero,2.085,2.001,35.839,3.245,0,0,2.000,2.000,0.000,0.010,1
3752649498.993800,84.608,Sweeping to zero,2.070,2.000,35.839,3.271,0,0,2.000,2.000,0.000,0.010,1
3752649528.993800,82.993,Sweeping to zero,2.094,2.000,35.837,3.286,0,0,2.000,2.000,0.160,0.010,1
3752649558.993800,81.378,Sweeping to zero,2.075,2.000,35.834,3.294,0,0,2.000,2.000,0.000,0.010,1
3752649588.993800,79.733,Sweeping to zero,2.095,2.000,35.829,3.299,0,0,2.000,2.000,0.260,0.010,1
3752649618.993800,78.328,Sweeping up,2.074,2.000,35.822,3.299,0,0,2.000,2.000,0.000,0.010,1
3752649648.993800,79.656,Sweeping up,2.097,2.000,35.814,3.229,0,0,2.000,2.000,0.230,0.010,1
3752649678.993800,80.003,Pause,2.077,1.999,35.804,3.188,0,0,2.000,2.000,0.000,0.010,1
3752649708.993800,79.972,Pause,2.096,2.000,35.798,3.142,0,0,2.000,2.000,0.270,0.010,1
3752649738.993800,79.974,Pause,2.076,2.000,35.792,3.123,0,0,2.000,2.000,0.000,0.010,1
3752649768.993800,79.974,Pause,2.094,2.000,35.786,3.116,0,0,2.000,2.000,0.280,0.010,1
3752649798.993800,79.974,Pause,2.070,2.000,35.781,3.112,0,0,2.000,2.000,0.000,0.010,1
3752649828.993800,79.974,Pause,2.084,2.000,35.774,3.111,0,0,2.000,2.000,0.150,0.010,1
3752649858.993800,79.974,Pause,2.075,2.000,35.769,3.110,0,0,2.000,2.000,0.000,0.010,1
3752649888.993800,79.974,Pause,2.079,2.000,35.764,3.110,0,0,2.000,2.000,0.180,0.010,1
3752649918.993800,79.974,Pause,2.094,2.000,35.759,3.111,0,0,2.000,2.000,0.150,0.010,1
3752649948.993800,79.974,Pause,2.073,2.000,35.755,3.110,0,0,2.000,2.000,0.000,0.010,1
3752649978.993800,80.001,Pause,2.094,2.000,35.751,3.111,0,0,2.000,2.000,0.270,0.010,1
3752650008.993800,80.003,Pause,2.074,2.000,35.747,3.110,0,0,2.000,2.000,0.000,0.010,1
3752650038.993800,80.002,Pause,2.091,2.000,35.743,3.110,0,0,2.000,2.000,0.160,0.010,1
3752650068.993800,80.002,Pause,2.079,2.000,35.740,3.111,0,0,2.000,2.000,0.000,0.010,1
3752650098.993800,80.002,Pause,2.073,2.000,35.737,3.110,0,0,2.000,2.000,0.100,0.010,1
3752650128.993800,80.002,Pause,2.087,2.000,35.734,3.110,0,0,2.000,2.000,0.010,0.010,1
3752650158.993800,80.002,Pause,2.070,2.000,35.732,3.110,0,0,2.000,2.000,0.000,0.010,1
3752650188.993800,80.002,Pause,2.088,2.000,35.730,3.110,0,0,2.000,2.000,0.260,0.010,1
3752650218.993800,80.002,Pause,2.074,2.000,35.728,3.109,0,0,2.000,2.000,0.000,0.010,1
3752650248.993800,80.002,Pause,2.084,2.000,35.726,3.110,0,0,2.000,2.000,0.020,0.010,1
3752650278.993800,80.002,Pause,2.079,2.000,35.724,3.110,0,0,2.000,2.000,0.000,0.010,1
3752650308.993800,80.003,Pause,2.069,2.000,35.722,3.110,0,0,2.000,2.000,0.000,0.010,1
3752650338.993800,80.002,Pause,2.095,2.000,35.721,3.110,0,0,2.000,2.000,0.150,0.010,1
3752650368.993800,80.002,Pause,2.073,2.000,35.719,3.111,0,0,2.000,2.000,0.000,0.010,1
3752650398.993800,80.002,Pause,2.089,2.000,35.719,3.111,0,0,2.000,2.000,0.240,0.010,1
3752650428.993800,80.002,Pause,2.075,2.000,35.718,3.112,0,0,2.000,2.000,0.000,0.010,1
3752650458.993800,80.002,Pause,2.094,2.000,35.718,3.110,0,0,2.000,2.000,0.240,0.010,1
3752650488.993800,80.002,Pause,2.082,2.000,35.717,3.111,0,0,2.000,2.000,0.000,0.010,1
3752650518.993800,80.002,Pause,2.081,2.000,35.717,3.110,0,0,2.000,2.000,0.210,0.010,1
3752650548.993800,80.002,Pause,2.089,2.000,35.715,3.111,0,0,2.000,2.000,0.160,0.010,1
3752650578.993800,80.002,Pause,2.071,2.000,35.714,3.111,0,0,2.000,2.000,0.000,0.010,1
3752650608.993800,80.002,Pause,2.089,2.000,35.714,3.110,0,0,2.000,2.000,0.270,0.010,1
3752650638.993800,80.002,Pause,2.071,2.000,35.713,3.111,0,0,2.000,2.000,0.000,0.010,1
3752650668.993800,80.002,Pause,2.092,2.000,35.714,3.110,0,0,2.000,2.000,0.230,0.010,1
3752650698.993800,80.002,Pause,2.081,2.000,35.714,3.110,0,0,2.000,2.000,0.000,0.010,1
3752650728.993800,80.002,Pause,2.079,2.000,35.713,3.111,0,0,2.000,2.000,0.210,0.010,1
3752650758.993800,80.002,Pause,2.088,2.000,35.713,3.110,0,0,2.000,2.000,0.000,0.010,1
3752650788.993800,80.003,Pause,2.071,2.000,35.712,3.110,0,0,2.000,2.000,0.000,0.010,1
3752650818.993800,80.002,Pause,2.088,2.000,35.712,3.109,0,0,2.000,2.000,0.260,0.010,1
3752650848.993800,80.002,Pause,2.072,2.000,35.712,3.109,0,0,2.000,2.000,0.000,0.010,1
3752650878.993800,80.002,Pause,2.091,2.000,35.711,3.109,0,0,2.000,2.000,0.270,0.010,1
3752650908.993800,80.002,Pause,2.084,2.000,35.711,3.108,0,0,2.000,2.000,0.000,0.010,1
3752650938.993800,80.002,Pause,2.078,2.000,35.711,3.108,0,0,2.000,2.000,0.090,0.010,1
3752650968.993800,80.002,Pause,2.089,2.000,35.710,3.110,0,0,2.000,2.000,0.210,0.010,1
3752650998.993800,80.002,Pause,2.069,2.000,35.709,3.111,0,0,2.000,2.000,0.000,0.010,1
3752651028.993800,80.002,Pause,2.082,2.001,35.710,3.110,0,0,2.000,2.000,0.230,0.010,1
3752651058.993800,80.003,Pause,2.069,2.000,35.709,3.109,0,0,2.000,2.000,0.000,0.010,1
3752651088.993800,80.003,Pause,2.085,2.000,35.709,3.109,0,0,2.000,2.000,0.240,0.010,1
3752651118.993800,80.003,Pause,2.089,2.000,35.708,3.109,0,0,2.000,2.000,0.000,0.010,1
3752651148.993800,80.002,Pause,2.072,2.000,35.707,3.110,0,0,2.000,2.000,0.000,0.010,1
3752651178.993800,80.002,Pause,2.088,2.000,35.707,3.110,0,0,2.000,2.000,0.260,0.010,1
3752651208.993800,80.002,Pause,2.073,2.000,35.707,3.109,0,0,2.000,2.000,0.000,0.010,1
3752651238.993800,80.002,Pause,2.088,2.000,35.707,3.110,0,0,2.000,2.000,0.070,0.010,1
3752651268.993800,80.002,Pause,2.077,2.001,35.708,3.109,0,0,2.000,2.000,0.000,0.010,1
3752651298.993800,80.002,Pause,2.076,2.001,35.707,3.110,0,0,2.000,2.000,0.060,0.010,1
3752651328.993800,80.002,Pause,2.091,2.000,35.707,3.110,0,0,2.000,2.000,0.010,0.010,1
3752651358.993800,80.002,Pause,2.072,2.000,35.706,3.110,0,0,2.000,2.000,0.000,0.010,1
3752651388.993800,80.002,Pause,2.092,2.000,35.707,3.110,0,0,2.000,2.000,0.240,0.010,1
3752651418.993800,80.003,Pause,2.074,2.000,35.706,3.110,0,0,2.000,2.000,0.000,0.010,1
3752651448.993800,80.002,Pause,2.089,2.000,35.706,3.110,0,0,2.000,2.000,0.220,0.010,1
3752651478.993800,80.002,Pause,2.084,2.000,35.706,3.109,0,0,2.000,2.000,0.170,0.010,1
3752651508.993800,80.002,Pause,2.077,2.000,35.707,3.109,0,0,2.000,2.000,0.180,0.010,1
3752651538.993800,80.002,Pause,2.089,2.000,35.707,3.111,0,0,2.000,2.000,0.220,0.010,1
3752651568.993800,80.002,Pause,2.073,1.999,35.708,3.109,0,0,2.000,2.000,0.000,0.010,1
3752651598.993800,80.002,Pause,2.085,2.000,35.709,3.109,0,0,2.000,2.000,0.260,0.010,1
3752651628.993800,80.002,Pause,2.087,2.000,35.709,3.109,0,0,2.000,2.000,0.050,0.010,1
3752651658.993800,80.002,Pause,2.074,2.000,35.710,3.109,0,0,2.000,2.000,0.000,0.010,1
3752651688.993800,80.002,Pause,2.093,2.000,35.709,3.110,0,0,2.000,2.000,0.270,0.010,1
3752651718.993800,80.002,Pause,2.070,2.001,35.709,3.109,0,0,2.000,2.000,0.000,0.010,1
3752651748.993800,80.002,Pause,2.088,2.000,35.709,3.111,0,0,2.000,2.000,0.270,0.010,1
3752651778.993800,80.002,Pause,2.083,2.000,35.709,3.111,0,0,2.000,2.000,0.000,0.010,1
3752651808.993800,80.002,Pause,2.078,2.000,35.708,3.110,0,0,2.000,2.000,0.090,0.010,1
3752651838.993800,80.002,Pause,2.089,2.000,35.707,3.111,0,0,2.000,2.000,0.270,0.010,1
3752651868.993800,80.003,Pause,2.070,1.999,35.707,3.112,0,0,2.000,2.000,0.000,0.010,1
3752651898.993800,80.003,Pause,2.084,2.000,35.708,3.111,0,0,2.000,2.000,0.080,0.010,1
3752651928.993800,80.002,Pause,2.077,2.000,35.708,3.111,0,0,2.000,2.000,0.000,0.010,1
3752651958.993800,80.002,Pause,2.072,2.000,35.709,3.110,0,0,2.000,2.000,0.130,0.010,1
3752651988.993800,80.002,Pause,2.088,2.000,35.709,3.111,0,0,2.000,2.000,0.040,0.010,1
3752652018.993800,80.002,Pause,2.074,2.000,35.709,3.111,0,0,2.000,2.000,0.000,0.010,1
3752652048.993800,80.002,Pause,2.093,2.000,35.709,3.111,0,0,2.000,2.000,0.230,0.010,1
3752652078.993800,80.002,Pause,2.075,2.000,35.709,3.111,0,0,2.000,2.000,0.000,0.010,1
3752652108.993800,80.002,Pause,2.094,2.000,35.709,3.110,0,0,2.000,2.000,0.190,0.010,1
3752652138.993800,80.002,Pause,2.086,2.000,35.708,3.111,0,0,2.000,2.000,0.000,0.010,1
3752652168.993800,80.002,Pause,2.078,2.000,35.708,3.110,0,0,2.000,2.000,0.190,0.010,1
3752652198.993800,80.002,Pause,2.091,2.001,35.708,3.110,0,0,2.000,2.000,0.190,0.010,1
3752652228.993800,80.002,Pause,2.074,2.000,35.708,3.111,0,0,2.000,2.000,0.000,0.010,1
3752652258.993800,80.002,Pause,2.092,2.000,35.708,3.111,0,0,2.000,2.000,0.270,0.010,1
3752652288.993800,80.002,Pause,2.077,2.000,35.708,3.110,0,0,2.000,2.000,0.050,0.010,1
3752652318.993800,80.002,Pause,2.082,2.000,35.708,3.107,0,0,2.000,2.000,0.270,0.010,1
3752652348.993800,80.002,Pause,2.086,2.000,35.708,3.106,0,0,2.000,2.000,0.000,0.010,1
3752652378.993800,80.002,Pause,2.073,2.000,35.708,3.107,0,0,2.000,2.000,0.040,0.010,1
3752652408.993800,80.002,Pause,2.093,2.000,35.707,3.108,0,0,2.000,2.000,0.240,0.010,1
3752652438.993800,80.002,Pause,2.075,2.000,35.707,3.108,0,0,2.000,2.000,0.000,0.010,1
3752652468.993800,80.002,Pause,2.081,2.000,35.707,3.109,0,0,2.000,2.000,0.140,0.010,1
3752652498.993800,80.002,Pause,2.086,2.000,35.707,3.109,0,0,2.000,2.000,0.220,0.010,1
3752652528.993800,80.002,Pause,2.075,2.000,35.708,3.109,0,0,2.000,2.000,0.150,0.010,1
3752652558.993800,80.003,Pause,2.093,2.000,35.708,3.108,0,0,2.000,2.000,0.010,0.010,1
3752652588.993800,80.002,Pause,2.074,2.000,35.707,3.110,0,0,2.000,2.000,0.000,0.010,1
3752652618.993800,80.002,Pause,2.082,2.000,35.707,3.112,0,0,2.000,2.000,0.240,0.010,1
3752652648.993800,80.002,Pause,2.075,2.000,35.707,3.111,0,0,2.000,2.000,0.000,0.010,1
3752652678.993800,80.002,Pause,2.078,1.999,35.706,3.112,0,0,2.000,2.000,0.000,0.010,1
3752652708.993800,80.002,Pause,2.086,2.000,35.707,3.110,0,0,2.000,2.000,0.000,0.010,1
3752652738.993800,80.002,Pause,2.075,2.000,35.707,3.111,0,0,2.000,2.000,0.010,0.010,1
3752652768.993800,80.002,Pause,2.093,2.000,35.707,3.112,0,0,2.000,2.000,0.110,0.010,1
3752652798.993800,80.002,Pause,2.074,2.000,35.708,3.111,0,0,2.000,2.000,0.000,0.010,1
3752652828.993800,80.002,Pause,2.084,2.000,35.707,3.111,0,0,2.000,2.000,0.160,0.010,1
3752652858.993800,80.002,Pause,2.080,2.000,35.708,3.111,0,0,2.000,2.000,0.040,0.010,1
3752652888.993800,80.002,Pause,2.077,2.000,35.707,3.111,0,0,2.000,2.000,0.000,0.010,1
3752652918.993800,80.002,Pause,2.096,2.000,35.709,3.112,0,0,2.000,2.000,0.030,0.010,1
3752652948.993800,80.002,Pause,2.072,2.000,35.708,3.112,0,0,2.000,2.000,0.000,0.010,1
3752652978.993800,80.002,Pause,2.091,2.000,35.708,3.113,0,0,2.000,2.000,0.270,0.010,1
3752653008.993800,80.002,Pause,2.082,2.000,35.708,3.111,0,0,2.000,2.000,0.000,0.010,1
3752653038.993800,80.002,Pause,2.087,2.000,35.709,3.113,0,0,2.000,2.000,0.150,0.010,1
3752653068.993800,80.002,Pause,2.088,2.000,35.709,3.112,0,0,2.000,2.000,0.220,0.010,1
3752653098.993800,80.002,Pause,2.073,2.000,35.709,3.112,0,0,2.000,2.000,0.100,0.010,1
3752653128.993800,80.002,Pause,2.087,2.000,35.710,3.113,0,0,2.000,2.000,0.270,0.010,1
3752653158.993800,80.002,Pause,2.078,2.000,35.710,3.113,0,0,2.000,2.000,0.000,0.010,1
3752653188.993800,80.002,Pause,2.081,2.000,35.711,3.112,0,0,2.000,2.000,0.170,0.010,1
3752653218.993800,80.002,Pause,2.096,2.000,35.711,3.112,0,0,2.000,2.000,0.170,0.010,1
3752653248.993800,80.002,Pause,2.072,2.000,35.712,3.112,0,0,2.000,2.000,0.000,0.010,1
3752653278.993800,80.003,Pause,2.095,2.000,35.712,3.111,0,0,2.000,2.000,0.240,0.010,1
3752653308.993800,80.003,Pause,2.070,2.000,35.712,3.112,0,0,2.000,2.000,0.000,0.010,1
3752653338.993800,80.002,Pause,2.086,2.000,35.713,3.111,0,0,2.000,2.000,0.230,0.010,1
3752653368.993800,80.002,Pause,2.089,2.000,35.713,3.111,0,0,2.000,2.000,0.000,0.010,1
3752653398.993800,80.002,Pause,2.070,2.000,35.713,3.112,0,0,2.000,2.000,0.000,0.010,1
3752653428.993800,80.002,Pause,2.090,2.000,35.714,3.112,0,0,2.000,2.000,0.280,0.010,1
3752653458.993800,80.002,Pause,2.071,2.000,35.714,3.113,0,0,2.000,2.000,0.000,0.010,1
3752653488.993800,80.002,Pause,2.091,2.000,35.715,3.112,0,0,2.000,2.000,0.150,0.010,1
3752653518.993800,80.002,Pause,2.077,2.000,35.715,3.112,0,0,2.000,2.000,0.000,0.010,1
3752653548.993800,80.002,Pause,2.075,2.000,35.715,3.112,0,0,2.000,2.000,0.030,0.010,1
3752653578.993800,80.002,Pause,2.085,2.000,35.715,3.112,0,0,2.000,2.000,0.010,0.010,1
3752653608.993800,80.002,Pause,2.072,1.999,35.715,3.111,0,0,2.000,2.000,0.000,0.010,1
3752653638.993800,80.003,Pause,2.090,2.000,35.715,3.112,0,0,2.000,2.000,0.200,0.010,1
3752653668.993800,80.002,Pause,2.066,2.000,35.715,3.112,0,0,2.000,2.000,0.000,0.010,1
3752653698.993800,80.002,Pause,2.091,2.000,35.715,3.112,0,0,2.000,2.000,0.200,0.010,1
3752653728.993800,80.002,Pause,2.082,2.000,35.715,3.112,0,0,2.000,2.000,0.000,0.010,1
3752653758.993800,80.002,Pause,2.082,2.000,35.714,3.112,0,0,2.000,2.000,0.260,0.010,1
3752653788.993800,80.002,Pause,2.087,2.000,35.714,3.112,0,0,2.000,2.000,0.010,0.010,1
3752653818.993800,80.002,Pause,2.072,2.000,35.714,3.112,0,0,2.000,2.000,0.000,0.010,1
3752653848.993800,80.002,Pause,2.091,2.000,35.714,3.111,0,0,2.000,2.000,0.270,0.010,1
3752653878.993800,80.002,Pause,2.074,2.000,35.714,3.112,0,0,2.000,2.000,0.000,0.010,1
3752653908.993800,80.002,Pause,2.090,2.000,35.715,3.111,0,0,2.000,2.000,0.280,0.010,1
3752653938.993800,80.002,Pause,2.086,2.000,35.716,3.111,0,0,2.000,2.000,0.030,0.010,1
3752653968.993800,80.002,Pause,2.066,2.000,35.716,3.110,0,0,2.000,2.000,0.000,0.010,1
3752653998.993800,80.002,Pause,2.094,2.000,35.716,3.111,0,0,2.000,2.000,0.240,0.010,1
3752654028.993800,80.002,Pause,2.075,2.001,35.717,3.111,0,0,2.000,2.000,0.000,0.010,1
3752654058.993800,80.002,Pause,2.087,2.000,35.717,3.112,0,0,2.000,2.000,0.170,0.010,1
3752654088.993800,80.002,Pause,2.076,2.000,35.717,3.111,0,0,2.000,2.000,0.000,0.010,1
3752654118.993800,80.002,Pause,2.071,2.000,35.717,3.111,0,0,2.000,2.000,0.190,0.010,1
3752654148.993800,80.002,Pause,2.087,2.000,35.717,3.111,0,0,2.000,2.000,0.000,0.010,1
3752654178.993800,80.002,Pause,2.071,2.000,35.717,3.111,0,0,2.000,2.000,0.000,0.010,1
3752654208.993800,80.002,Pause,2.087,1.999,35.717,3.112,0,0,2.000,2.000,0.250,0.010,1
3752654238.993800,80.002,Pause,2.074,2.000,35.718,3.110,0,0,2.000,2.000,0.000,0.010,1
3752654268.993800,80.002,Pause,2.082,2.000,35.717,3.110,0,0,2.000,2.000,0.000,0.010,1
3752654298.993800,80.002,Pause,2.086,2.000,35.717,3.111,0,0,2.000,2.000,0.000,0.010,1
3752654328.993800,80.002,Pause,2.071,2.000,35.717,3.112,0,0,2.000,2.000,0.000,0.010,1
3752654358.993800,80.002,Pause,2.091,2.000,35.718,3.112,0,0,2.000,2.000,0.220,0.010,1
3752654388.993800,80.002,Pause,2.075,2.000,35.717,3.112,0,0,2.000,2.000,0.000,0.010,1
3752654418.993800,80.002,Pause,2.078,2.000,35.717,3.111,0,0,2.000,2.000,0.000,0.010,1
3752654448.993800,80.002,Pause,2.089,2.000,35.718,3.112,0,0,2.000,2.000,0.200,0.010,1
3752654478.993800,80.002,Pause,2.069,2.000,35.717,3.111,0,0,2.000,2.000,0.000,0.010,1
3752654508.993800,80.002,Pause,2.093,2.000,35.717,3.112,0,0,2.000,2.000,0.090,0.010,1
3752654538.993800,80.002,Pause,2.074,2.000,35.718,3.111,0,0,2.000,2.000,0.000,0.010,1
3752654568.993800,80.002,Pause,2.089,2.000,35.718,3.112,0,0,2.000,2.000,0.270,0.010,1
3752654598.993800,80.002,Pause,2.087,2.000,35.719,3.112,0,0,2.000,2.000,0.000,0.010,1
3752654628.993800,80.002,Pause,2.086,2.000,35.720,3.111,0,0,2.000,2.000,0.100,0.010,1
3752654658.993800,80.002,Pause,2.090,2.000,35.719,3.111,0,0,2.000,2.000,0.260,0.010,1
3752654688.993800,80.002,Pause,2.074,2.000,35.719,3.112,0,0,2.000,2.000,0.090,0.010,1
3752654718.993800,80.002,Pause,2.092,2.000,35.719,3.111,0,0,2.000,2.000,0.250,0.010,1
3752654748.993800,80.003,Pause,2.078,2.000,35.719,3.110,0,0,2.000,2.000,0.000,0.010,1
3752654778.993800,80.003,Pause,2.072,2.001,35.720,3.112,0,0,2.000,2.000,0.060,0.010,1
3752654808.993800,80.002,Pause,2.097,2.000,35.720,3.111,0,0,2.000,2.000,0.230,0.010,1
3752654838.993800,80.002,Pause,2.073,2.000,35.720,3.111,0,0,2.000,2.000,0.000,0.010,1
3752654868.993800,80.002,Pause,2.089,2.000,35.720,3.111,0,0,2.000,2.000,0.140,0.010,1
3752654898.993800,80.002,Pause,2.079,2.000,35.720,3.112,0,0,2.000,2.000,0.000,0.010,1
[...]
3752682449.172800,0.000,Standby,2.116,2.000,34.969,3.089,0,0,2.000,2.000,0.250,0.020,1
3752682539.172800,0.000,Standby,2.101,2.001,34.969,3.090,0,0,2.000,2.000,0.000,0.020,1
3752682629.172800,0.000,Standby,2.091,2.000,34.969,3.089,0,0,2.000,2.000,0.000,0.020,1
3752682719.172800,0.000,Standby,2.095,2.000,34.969,3.089,0,0,2.000,2.000,0.000,0.020,1
3752682809.172800,0.000,Standby,2.114,2.000,34.969,3.089,0,0,2.000,2.000,0.250,0.020,1
3752682899.172800,0.000,Standby,2.116,2.000,34.969,3.090,0,0,2.000,2.000,0.260,0.020,1
3752682989.172800,0.000,Standby,2.116,2.001,34.970,3.090,0,0,2.000,2.000,0.200,0.020,1
3752683079.172800,0.000,Standby,2.100,2.000,34.969,3.091,0,0,2.000,2.000,0.000,0.020,1
3752683169.172800,0.000,Standby,2.094,2.000,34.970,3.090,0,0,2.000,2.000,0.000,0.020,1
3752683259.172800,0.000,Standby,2.095,2.000,34.970,3.089,0,0,2.000,2.000,0.000,0.020,1
3752683349.172800,0.000,Standby,2.103,2.000,34.970,3.089,0,0,2.000,2.000,0.110,0.020,1
3752683439.172800,0.000,Standby,2.112,2.000,34.969,3.090,0,0,2.000,2.000,0.150,0.020,1
3752683529.172800,0.000,Standby,2.117,2.000,34.968,3.091,0,0,2.000,2.000,0.090,0.020,1
3752683619.172800,0.000,Standby,2.106,2.000,34.968,3.090,0,0,2.000,2.000,0.060,0.020,1
3752683709.172800,0.000,Standby,2.097,2.000,34.967,3.089,0,0,2.000,2.000,0.000,0.020,1
3752683799.172800,0.000,Standby,2.097,2.000,34.967,3.091,0,0,2.000,2.000,0.000,0.020,1
3752683889.172800,0.000,Standby,2.102,2.000,34.967,3.092,0,0,2.000,2.000,0.140,0.020,1
3752683979.172800,0.000,Standby,2.108,2.000,34.967,3.093,0,0,2.000,2.000,0.210,0.020,1
3752684069.172800,0.000,Standby,2.113,2.001,34.968,3.091,0,0,2.000,2.000,0.030,0.020,1
3752684159.172800,0.000,Standby,2.104,2.000,34.968,3.091,0,0,2.000,2.000,0.000,0.020,1
3752684249.172800,0.000,Standby,2.097,2.000,34.968,3.093,0,0,2.000,2.000,0.000,0.020,1
3752684339.172800,0.000,Standby,2.097,2.001,34.968,3.093,0,0,2.000,2.000,0.000,0.020,1
3752684429.172800,0.000,Standby,2.109,2.000,34.969,3.093,0,0,2.000,2.000,0.060,0.020,1
3752684519.172800,0.000,Standby,2.116,1.999,34.969,3.092,0,0,2.000,2.000,0.150,0.020,1
3752684609.172800,0.000,Standby,2.111,2.000,34.969,3.093,0,0,2.000,2.000,0.040,0.020,1
3752684699.172800,0.000,Standby,2.099,2.000,34.969,3.094,0,0,2.000,2.000,0.000,0.020,1
3752684789.172800,0.000,Standby,2.097,2.000,34.970,3.092,0,0,2.000,2.000,0.000,0.020,1
3752684879.172800,0.000,Standby,2.094,2.000,34.969,3.092,0,0,2.000,2.000,0.160,0.020,1
3752684969.172800,0.000,Standby,2.110,2.000,34.968,3.092,0,0,2.000,2.000,0.230,0.020,1
3752685059.172800,0.000,Standby,2.113,2.000,34.968,3.092,0,0,2.000,2.000,0.020,0.020,1
3752685149.172800,0.000,Standby,2.115,2.000,34.969,3.092,0,0,2.000,2.000,0.090,0.020,1
3752685239.172800,0.000,Standby,2.097,1.999,34.968,3.094,0,0,2.000,2.000,0.030,0.020,1
3752685329.172800,0.000,Standby,2.091,2.000,34.968,3.092,0,0,2.000,2.000,0.000,0.020,1
3752685419.172800,0.000,Standby,2.100,2.000,34.968,3.093,0,0,2.000,2.000,0.000,0.020,1
3752685509.172800,0.000,Standby,2.102,2.000,34.968,3.094,0,0,2.000,2.000,0.160,0.020,1
3752685599.172800,0.000,Standby,2.113,2.000,34.969,3.094,0,0,2.000,2.000,0.250,0.020,1
3752685689.172800,0.000,Standby,2.113,2.001,34.969,3.093,0,0,2.000,2.000,0.070,0.020,1
3752685779.172800,0.000,Standby,2.106,2.000,34.968,3.092,0,0,2.000,2.000,0.000,0.020,1
3752685869.172800,0.000,Standby,2.093,1.999,34.968,3.092,0,0,2.000,2.000,0.000,0.020,1
3752685959.172800,0.000,Standby,2.097,2.000,34.968,3.091,0,0,2.000,2.000,0.030,0.020,1
3752686049.172800,0.000,Standby,2.118,2.000,34.969,3.091,0,0,2.000,2.000,0.220,0.020,1
3752686139.172800,0.000,Standby,2.119,2.000,34.968,3.091,0,0,2.000,2.000,0.230,0.020,1
3752686229.172800,0.000,Standby,2.097,2.000,34.968,3.092,0,0,2.000,2.000,0.000,0.020,1
3752686319.172800,0.000,Standby,2.093,2.000,34.969,3.091,0,0,2.000,2.000,0.000,0.020,1
3752686409.172800,0.000,Standby,2.095,2.000,34.969,3.092,0,0,2.000,2.000,0.000,0.020,1
3752686499.172800,0.000,Standby,2.106,2.000,34.968,3.091,0,0,2.000,2.000,0.140,0.020,1
3752686589.172800,0.000,Standby,2.118,2.000,34.968,3.091,0,0,2.000,2.000,0.250,0.020,1
3752686679.172800,0.000,Standby,2.115,2.000,34.969,3.089,0,0,2.000,2.000,0.060,0.020,1
3752686769.172800,0.000,Standby,2.108,2.000,34.969,3.087,0,0,2.000,2.000,0.000,0.020,1
3752686859.172800,0.000,Standby,2.097,2.000,34.969,3.087,0,0,2.000,2.000,0.000,0.020,1
3752686949.172800,0.000,Standby,2.099,2.000,34.968,3.083,0,0,2.000,2.000,0.000,0.020,1
3752687039.172800,0.000,Standby,2.119,2.001,34.967,3.081,0,0,2.000,2.000,0.230,0.020,1
3752687129.172800,0.000,Standby,2.117,2.000,34.965,3.082,0,0,2.000,2.000,0.260,0.020,1
3752687219.172800,0.000,Standby,2.108,2.000,34.963,3.083,0,0,2.000,2.000,0.220,0.020,1
3752687309.172800,0.000,Standby,2.102,1.999,34.963,3.084,0,0,2.000,2.000,0.000,0.020,1
3752687399.172800,0.000,Standby,2.092,2.000,34.961,3.086,0,0,2.000,2.000,0.000,0.020,1
3752687489.172800,0.000,Standby,2.099,2.000,34.960,3.084,0,0,2.000,2.000,0.000,0.020,1
3752687579.172800,0.000,Standby,2.115,1.999,34.960,3.080,0,0,2.000,2.000,0.210,0.020,1
3752687669.172800,0.000,Standby,2.115,2.000,34.959,3.079,0,0,2.000,2.000,0.230,0.020,1
3752687759.172800,0.000,Standby,2.119,2.001,34.958,3.083,0,0,2.000,2.000,0.180,0.020,1
3752687849.172800,0.000,Standby,2.100,2.000,34.958,3.079,0,0,2.000,2.000,0.000,0.020,1
3752687939.172800,0.000,Standby,2.095,2.000,34.958,3.081,0,0,2.000,2.000,0.000,0.020,1
3752688029.172800,0.000,Standby,2.103,2.000,34.958,3.082,0,0,2.000,2.000,0.190,0.020,1
3752688119.172800,0.000,Standby,2.098,2.000,34.957,3.082,0,0,2.000,2.000,0.020,0.020,1
3752688209.172800,0.000,Standby,2.116,1.999,34.955,3.081,0,0,2.000,2.000,0.140,0.020,1
3752688299.172800,0.000,Standby,2.117,2.000,34.954,3.077,0,0,2.000,2.000,0.190,0.020,1
3752688389.172800,0.000,Standby,2.114,2.000,34.954,3.078,0,0,2.000,2.000,0.190,0.020,1
3752688479.172800,0.000,Standby,2.103,2.000,34.953,3.080,0,0,2.000,2.000,0.000,0.020,1
3752688569.172800,0.000,Standby,2.097,2.000,34.951,3.078,0,0,2.000,2.000,0.000,0.020,1
3752688659.172800,0.000,Standby,2.097,2.000,34.951,3.077,0,0,2.000,2.000,0.040,0.020,1
3752688749.172800,0.000,Standby,2.104,2.001,34.950,3.077,0,0,2.000,2.000,0.140,0.020,1
3752688839.172800,0.000,Standby,2.113,2.000,34.949,3.079,0,0,2.000,2.000,0.110,0.020,1
3752688929.172800,0.000,Standby,2.112,2.000,34.950,3.078,0,0,2.000,2.000,0.070,0.020,1
3752689019.172800,0.000,Standby,2.108,2.000,34.948,3.077,0,0,2.000,2.000,0.130,0.020,1
3752689109.172800,0.000,Standby,2.097,2.000,34.947,3.077,0,0,2.000,2.000,0.000,0.020,1
3752689199.172800,0.000,Standby,2.098,2.000,34.946,3.076,0,0,2.000,2.000,0.000,0.020,1
3752689289.172800,0.000,Standby,2.106,2.000,34.946,3.075,0,0,2.000,2.000,0.230,0.020,1
3752689379.172800,0.000,Standby,2.116,2.000,34.946,3.076,0,0,2.000,2.000,0.260,0.020,1
3752689469.172800,0.000,Standby,2.114,2.000,34.946,3.076,0,0,2.000,2.000,0.110,0.020,1
3752689559.172800,0.000,Standby,2.092,2.000,34.946,3.076,0,0,2.000,2.000,0.000,0.020,1
3752689649.172800,0.000,Standby,2.089,2.000,34.945,3.077,0,0,2.000,2.000,0.000,0.020,1
3752689739.172800,0.000,Standby,2.097,2.000,34.945,3.079,0,0,2.000,2.000,0.000,0.020,1
3752689829.172800,0.000,Standby,2.114,2.000,34.944,3.079,0,0,2.000,2.000,0.270,0.020,1
3752689919.172800,0.000,Standby,2.115,2.000,34.945,3.078,0,0,2.000,2.000,0.260,0.020,1
3752690009.172800,0.000,Standby,2.115,1.999,34.946,3.077,0,0,2.000,2.000,0.240,0.020,1
3752690099.172800,0.000,Standby,2.110,2.000,34.946,3.076,0,0,2.000,2.000,0.000,0.020,1
3752690189.172800,0.000,Standby,2.099,2.000,34.946,3.076,0,0,2.000,2.000,0.000,0.020,1
3752690279.172800,0.000,Standby,2.092,2.000,34.945,3.079,0,0,2.000,2.000,0.000,0.020,1
3752690369.172800,0.000,Standby,2.101,1.999,34.946,3.078,0,0,2.000,2.000,0.000,0.020,1
3752690459.172800,0.000,Standby,2.104,2.000,34.947,3.078,0,0,2.000,2.000,0.150,0.020,1
3752690549.172800,0.000,Standby,2.110,2.000,34.947,3.080,0,0,2.000,2.000,0.230,0.020,1
3752690639.172800,0.000,Standby,2.115,2.000,34.946,3.079,0,0,2.000,2.000,0.000,0.020,1
3752690729.172800,0.000,Standby,2.106,2.000,34.945,3.079,0,0,2.000,2.000,0.000,0.020,1
3752690819.172800,0.000,Standby,2.094,2.000,34.945,3.081,0,0,2.000,2.000,0.000,0.020,1
3752690909.172800,0.000,Standby,2.101,2.000,34.945,3.082,0,0,2.000,2.000,0.020,0.020,1
3752690999.172800,0.000,Standby,2.106,2.000,34.944,3.085,0,0,2.000,2.000,0.000,0.020,1
3752691089.172800,0.000,Standby,2.114,2.000,34.946,3.082,0,0,2.000,2.000,0.260,0.020,1
3752691179.172800,0.000,Standby,2.111,1.999,34.948,3.081,0,0,2.000,2.000,0.160,0.020,1
3752691269.172800,0.000,Standby,2.098,2.000,34.948,3.083,0,0,2.000,2.000,0.000,0.020,1
3752691359.172800,0.000,Standby,2.095,2.000,34.948,3.084,0,0,2.000,2.000,0.000,0.020,1
3752691449.172800,0.000,Standby,2.097,2.000,34.948,3.083,0,0,2.000,2.000,0.000,0.020,1
3752691539.172800,0.000,Standby,2.093,2.000,34.949,3.084,0,0,2.000,2.000,0.020,0.020,1
3752691629.172800,0.000,Standby,2.118,2.000,34.949,3.083,0,0,2.000,2.000,0.210,0.020,1
3752691719.172800,0.000,Standby,2.114,2.000,34.948,3.085,0,0,2.000,2.000,0.170,0.020,1
3752691809.172800,0.000,Standby,2.105,2.000,34.948,3.082,0,0,2.000,2.000,0.000,0.020,1
3752691899.172800,0.000,Standby,2.104,2.000,34.949,3.083,0,0,2.000,2.000,0.000,0.020,1
3752691989.172800,0.000,Standby,2.094,2.000,34.947,3.083,0,0,2.000,2.000,0.000,0.020,1
3752692079.172800,0.000,Standby,2.098,1.999,34.945,3.084,0,0,2.000,2.000,0.030,0.020,1
3752692169.172800,0.000,Standby,2.109,2.000,34.943,3.085,0,0,2.000,2.000,0.150,0.020,1
3752692259.172800,0.000,Standby,2.118,1.999,34.941,3.084,0,0,2.000,2.000,0.050,0.020,1
3752692349.172800,0.000,Standby,2.102,2.001,34.940,3.085,0,0,2.000,2.000,0.000,0.020,1
3752692439.172800,0.000,Standby,2.096,2.000,34.940,3.084,0,0,2.000,2.000,0.000,0.020,1
3752692529.172800,0.000,Standby,2.091,2.000,34.941,3.084,0,0,2.000,2.000,0.000,0.020,1
3752692619.172800,0.000,Standby,2.105,2.000,34.941,3.083,0,0,2.000,2.000,0.200,0.020,1
3752692709.172800,0.000,Standby,2.111,2.001,34.941,3.080,0,0,2.000,2.000,0.250,0.020,1
3752692799.172800,0.000,Standby,2.111,2.000,34.942,3.081,0,0,2.000,2.000,0.000,0.020,1
3752692889.172800,0.000,Standby,2.113,2.000,34.940,3.084,0,0,2.000,2.000,0.040,0.020,1
3752692979.172800,0.000,Standby,2.095,2.001,34.940,3.083,0,0,2.000,2.000,0.000,0.020,1
3752693069.172800,0.000,Standby,2.093,2.000,34.941,3.081,0,0,2.000,2.000,0.000,0.020,1
3752693159.172800,0.000,Standby,2.110,2.000,34.941,3.082,0,0,2.000,2.000,0.030,0.020,1
3752693249.172800,0.000,Standby,2.114,2.000,34.940,3.083,0,0,2.000,2.000,0.240,0.020,1
3752693339.172800,0.000,Standby,2.111,2.001,34.941,3.081,0,0,2.000,2.000,0.100,0.020,1
3752693429.172800,0.000,Standby,2.103,2.000,34.943,3.079,0,0,2.000,2.000,0.000,0.020,1
3752693519.172800,0.000,Standby,2.100,2.000,34.944,3.082,0,0,2.000,2.000,0.000,0.020,1
3752693609.172800,0.000,Standby,2.094,2.000,34.944,3.081,0,0,2.000,2.000,0.000,0.020,1
3752693699.172800,0.000,Standby,2.099,2.000,34.945,3.083,0,0,2.000,2.000,0.060,0.020,1
3752693789.172800,0.000,Standby,2.118,2.000,34.945,3.085,0,0,2.000,2.000,0.220,0.020,1
3752693879.172800,0.000,Standby,2.114,2.000,34.945,3.082,0,0,2.000,2.000,0.240,0.020,1
3752693969.172800,0.000,Standby,2.110,2.000,34.946,3.085,0,0,2.000,2.000,0.260,0.020,1
3752694059.172800,0.000,Standby,2.097,2.000,34.946,3.086,0,0,2.000,2.000,0.000,0.020,1
3752694149.172800,0.000,Standby,2.092,2.000,34.947,3.086,0,0,2.000,2.000,0.000,0.020,1
3752694239.172800,0.000,Standby,2.099,2.000,34.948,3.084,0,0,2.000,2.000,0.110,0.020,1
3752694329.172800,0.000,Standby,2.113,2.000,34.949,3.083,0,0,2.000,2.000,0.150,0.020,1
3752694419.172800,0.000,Standby,2.111,2.000,34.950,3.084,0,0,2.000,2.000,0.260,0.020,1
3752694509.172800,0.000,Standby,2.117,2.000,34.951,3.083,0,0,2.000,2.000,0.210,0.020,1
3752694599.172800,0.000,Standby,2.107,2.000,34.951,3.084,0,0,2.000,2.000,0.000,0.020,1
3752694689.172800,0.000,Standby,2.098,2.000,34.950,3.086,0,0,2.000,2.000,0.000,0.020,1
3752694779.172800,0.000,Standby,2.097,2.000,34.950,3.085,0,0,2.000,2.000,0.090,0.020,1
3752694869.172800,0.000,Standby,2.099,1.999,34.952,3.084,0,0,2.000,2.000,0.000,0.020,1
3752694959.172800,0.000,Standby,2.110,2.000,34.952,3.083,0,0,2.000,2.000,0.100,0.020,1
3752695049.172800,0.000,Standby,2.117,2.000,34.952,3.085,0,0,2.000,2.000,0.140,0.020,1
3752695139.172800,0.000,Standby,2.106,2.000,34.952,3.083,0,0,2.000,2.000,0.010,0.020,1
3752695229.172800,0.000,Standby,2.099,2.000,34.952,3.085,0,0,2.000,2.000,0.000,0.020,1
3752695319.172800,0.000,Standby,2.100,2.000,34.952,3.085,0,0,2.000,2.000,0.000,0.020,1
3752695409.172800,0.000,Standby,2.099,2.000,34.952,3.086,0,0,2.000,2.000,0.130,0.020,1
3752695499.172800,0.000,Standby,2.103,2.000,34.952,3.087,0,0,2.000,2.000,0.160,0.020,1
3752695589.172800,0.000,Standby,2.117,2.000,34.953,3.085,0,0,2.000,2.000,0.100,0.020,1
3752695679.172800,0.000,Standby,2.111,1.999,34.952,3.086,0,0,2.000,2.000,0.010,0.020,1
3752695769.172800,0.000,Standby,2.092,2.000,34.952,3.087,0,0,2.000,2.000,0.000,0.020,1
3752695859.172800,0.000,Standby,2.095,2.000,34.953,3.086,0,0,2.000,2.000,0.000,0.020,1
3752695949.172800,0.000,Standby,2.098,2.000,34.952,3.086,0,0,2.000,2.000,0.000,0.020,1
3752696039.172800,0.000,Standby,2.106,2.000,34.953,3.087,0,0,2.000,2.000,0.240,0.020,1
3752696129.172800,0.000,Standby,2.117,2.000,34.954,3.086,0,0,2.000,2.000,0.260,0.020,1
3752696219.172800,0.000,Standby,2.117,2.000,34.955,3.085,0,0,2.000,2.000,0.070,0.020,1
3752696309.172800,0.000,Standby,2.097,2.000,34.954,3.086,0,0,2.000,2.000,0.000,0.020,1
3752696399.172800,0.000,Standby,2.093,2.000,34.954,3.087,0,0,2.000,2.000,0.000,0.020,1
3752696489.172800,0.000,Standby,2.098,2.000,34.953,3.087,0,0,2.000,2.000,0.040,0.020,1
3752696579.172800,0.000,Standby,2.118,2.000,34.953,3.087,0,0,2.000,2.000,0.200,0.020,1
3752696669.172800,0.000,Standby,2.115,2.000,34.952,3.086,0,0,2.000,2.000,0.070,0.020,1
3752696759.172800,0.000,Standby,2.105,2.000,34.953,3.087,0,0,2.000,2.000,0.150,0.020,1
3752696849.172800,0.000,Standby,2.089,2.001,34.954,3.085,0,0,2.000,2.000,0.000,0.020,1
3752696939.172800,0.000,Standby,2.098,2.000,34.956,3.086,0,0,2.000,2.000,0.000,0.020,1
3752697029.172800,0.000,Standby,2.107,2.000,34.956,3.086,0,0,2.000,2.000,0.240,0.020,1
3752697119.172800,0.000,Standby,2.117,2.000,34.956,3.086,0,0,2.000,2.000,0.280,0.020,1
3752697209.172800,0.000,Standby,2.116,2.000,34.956,3.087,0,0,2.000,2.000,0.120,0.020,1
3752697299.172800,0.000,Standby,2.090,2.000,34.956,3.086,0,0,2.000,2.000,0.000,0.020,1
3752697389.172800,0.000,Standby,2.091,2.000,34.955,3.087,0,0,2.000,2.000,0.000,0.020,1
3752697479.172800,0.000,Standby,2.096,2.000,34.955,3.088,0,0,2.000,2.000,0.000,0.020,1
3752697569.172800,0.000,Standby,2.112,1.999,34.955,3.086,0,0,2.000,2.000,0.240,0.020,1
3752697659.172800,0.000,Standby,2.114,2.000,34.956,3.085,0,0,2.000,2.000,0.170,0.020,1
3752697749.172800,0.000,Standby,2.114,2.000,34.955,3.086,0,0,2.000,2.000,0.250,0.020,1
3752697839.172800,0.000,Standby,2.101,2.000,34.956,3.085,0,0,2.000,2.000,0.000,0.020,1
3752697929.172800,0.000,Standby,2.096,2.000,34.956,3.085,0,0,2.000,2.000,0.000,0.020,1
3752698019.172800,0.000,Standby,2.101,2.000,34.957,3.083,0,0,2.000,2.000,0.160,0.020,1
3752698109.172800,0.000,Standby,2.113,1.999,34.956,3.085,0,0,2.000,2.000,0.200,0.020,1
3752698199.172800,0.000,Standby,2.116,1.999,34.956,3.086,0,0,2.000,2.000,0.230,0.020,1
3752698289.172800,0.000,Standby,2.098,2.000,34.956,3.087,0,0,2.000,2.000,0.000,0.020,1
3752698379.172800,0.000,Standby,2.094,2.000,34.956,3.088,0,0,2.000,2.000,0.000,0.020,1
3752698469.172800,0.000,Standby,2.095,2.000,34.956,3.086,0,0,2.000,2.000,0.000,0.020,1
3752698559.172800,0.000,Standby,2.111,1.999,34.957,3.085,0,0,2.000,2.000,0.250,0.020,1
3752698649.172800,0.000,Standby,2.117,2.000,34.956,3.087,0,0,2.000,2.000,0.190,0.020,1
3752698739.172800,0.000,Standby,2.114,2.000,34.956,3.087,0,0,2.000,2.000,0.270,0.020,1
3752698829.172800,0.000,Standby,2.102,2.000,34.956,3.087,0,0,2.000,2.000,0.000,0.020,1
3752698919.172800,0.000,Standby,2.096,2.000,34.956,3.086,0,0,2.000,2.000,0.000,0.020,1
3752699009.172800,0.000,Standby,2.097,2.000,34.956,3.087,0,0,2.000,2.000,0.040,0.020,1
3752699099.172800,0.000,Standby,2.110,2.000,34.955,3.087,0,0,2.000,2.000,0.110,0.020,1
3752699189.172800,0.000,Standby,2.112,2.000,34.955,3.087,0,0,2.000,2.000,0.260,0.020,1
3752699279.172800,0.000,Standby,2.114,1.999,34.954,3.085,0,0,2.000,2.000,0.260,0.020,1
3752699369.172800,0.000,Standby,2.110,2.000,34.954,3.085,0,0,2.000,2.000,0.000,0.020,1
3752699459.172800,0.000,Standby,2.098,2.000,34.956,3.085,0,0,2.000,2.000,0.000,0.020,1
3752699549.172800,0.000,Standby,2.096,2.001,34.954,3.087,0,0,2.000,2.000,0.000,0.020,1
3752699639.172800,0.000,Standby,2.106,2.000,34.954,3.087,0,0,2.000,2.000,0.190,0.020,1
3752699729.172800,0.000,Standby,2.114,2.000,34.954,3.088,0,0,2.000,2.000,0.140,0.020,1
3752699819.172800,0.000,Standby,2.116,2.000,34.954,3.086,0,0,2.000,2.000,0.160,0.020,1
3752699909.172800,0.000,Standby,2.106,2.000,34.955,3.085,0,0,2.000,2.000,0.140,0.020,1
3752699999.172800,0.000,Standby,2.100,2.000,34.956,3.089,0,0,2.000,2.000,0.000,0.020,1
3752700089.172800,0.000,Standby,2.093,2.000,34.957,3.090,0,0,2.000,2.000,0.000,0.020,1
3752700179.172800,0.000,Standby,2.095,2.000,34.957,3.087,0,0,2.000,2.000,0.000,0.020,1
3752700269.172800,0.000,Standby,2.101,2.000,34.958,3.084,0,0,2.000,2.000,0.090,0.020,1
3752700359.172800,0.000,Standby,2.115,2.000,34.958,3.086,0,0,2.000,2.000,0.150,0.020,1
3752700449.172800,0.000,Standby,2.113,2.000,34.958,3.087,0,0,2.000,2.000,0.180,0.020,1
3752700539.172800,0.000,Standby,2.094,2.000,34.957,3.089,0,0,2.000,2.000,0.000,0.020,1
3752700629.172800,0.000,Standby,2.094,2.000,34.957,3.089,0,0,2.000,2.000,0.000,0.020,1
3752700719.172800,0.000,Standby,2.098,1.999,34.958,3.089,0,0,2.000,2.000,0.000,0.020,1
3752700809.172800,0.000,Standby,2.108,2.000,34.958,3.089,0,0,2.000,2.000,0.260,0.020,1
3752700899.172800,0.000,Standby,2.116,1.999,34.958,3.088,0,0,2.000,2.000,0.240,0.020,1
3752700989.172800,0.000,Standby,2.101,2.000,34.959,3.088,0,0,2.000,2.000,0.000,0.020,1
3752701079.172800,0.000,Standby,2.099,2.000,34.959,3.088,0,0,2.000,2.000,0.000,0.020,1
3752701169.172800,0.000,Standby,2.097,2.000,34.960,3.089,0,0,2.000,2.000,0.000,0.020,1
3752701259.172800,0.000,Standby,2.102,2.000,34.961,3.088,0,0,2.000,2.000,0.090,0.020,1
3752701349.172800,0.000,Standby,2.113,2.000,34.960,3.089,0,0,2.000,2.000,0.140,0.020,1
3752701439.172800,0.000,Standby,2.112,2.000,34.960,3.088,0,0,2.000,2.000,0.030,0.020,1
3752701529.172800,0.000,Standby,2.095,2.000,34.960,3.090,0,0,2.000,2.000,0.000,0.020,1
3752701619.172800,0.000,Standby,2.094,2.000,34.960,3.089,0,0,2.000,2.000,0.000,0.020,1
3752701709.172800,0.000,Standby,2.106,2.001,34.960,3.088,0,0,2.000,2.000,0.000,0.020,1
3752701799.172800,0.000,Standby,2.113,2.000,34.960,3.088,0,0,2.000,2.000,0.280,0.020,1
3752701889.172800,0.000,Standby,2.117,2.000,34.959,3.088,0,0,2.000,2.000,0.230,0.020,1
3752701979.172800,0.000,Standby,2.102,2.000,34.960,3.088,0,0,2.000,2.000,0.000,0.020,1
3752702069.172800,0.000,Standby,2.094,2.000,34.962,3.090,0,0,2.000,2.000,0.000,0.020,1
3752702159.172800,0.000,Standby,2.091,2.000,34.963,3.091,0,0,2.000,2.000,0.000,0.020,1
3752702249.172800,0.000,Standby,2.096,2.000,34.963,3.089,0,0,2.000,2.000,0.000,0.020,1
3752702339.172800,0.000,Standby,2.114,2.001,34.962,3.089,0,0,2.000,2.000,0.230,0.020,1
3752702429.172800,0.000,Standby,2.116,2.000,34.962,3.089,0,0,2.000,2.000,0.200,0.020,1
3752702519.172800,0.000,Standby,2.100,2.000,34.962,3.090,0,0,2.000,2.000,0.000,0.020,1
3752702609.172800,0.000,Standby,2.095,2.000,34.963,3.089,0,0,2.000,2.000,0.000,0.020,1
3752702699.172800,0.000,Standby,2.094,2.000,34.962,3.089,0,0,2.000,2.000,0.000,0.020,1
3752702789.172800,0.000,Standby,2.101,2.000,34.961,3.089,0,0,2.000,2.000,0.160,0.020,1
3752702879.172800,0.000,Standby,2.115,2.000,34.962,3.087,0,0,2.000,2.000,0.240,0.020,1
3752702919.172800,0.000,Standby,2.114,2.000,34.962,3.089,0,0,2.000,2.000,0.060,0.020,1