File: log/20221023.dat
[Header]
; Displex Transport Data File (default extension .dat)
; Copyright 2016, Hechang LEI, hlei@ruc.edu.cn. All rights reserved.
BYAPP, Displex, 2.0
INFO, 9T mag, Release 2.0.
INFO, Channel 1, Temperature Sensor
INFO, Sample 1 Length (cm): 0.000000; Width (cm): 0.000000; Thickness (cm): 0.000000.

[Data]
Timestamp(s),Field(Oe),Field Status,TempA(K),TempB(K),TempC(K),TempD(K),Ramp1,Ramp2,Setpoint1,Setpoint2,Output1(%),Output2(%),Temp Status
3749334415.505400,,,2.008,1.999,0.000,0.000,0,0,2.000,2.000,0,0,1
3749334550.505400,,,2.004,2.000,0.000,0.000,0,0,2.000,2.000,0,0,1
3749334685.505400,,,2.003,2.000,0.000,0.000,0,0,2.000,2.000,0,0,1
3749334820.505400,,,1.999,2.000,0.000,0.000,0,0,2.000,2.000,0,0,1
3749334955.505400,,,2.005,1.999,0.000,0.000,0,0,2.000,2.000,0,0,1
3749335090.505400,,,1.993,2.000,0.000,0.000,0,0,2.000,2.000,0,0,1
3749335225.505400,,,1.998,2.000,0.000,0.000,0,0,2.000,2.000,0,0,1
3749335360.505400,,,2.000,2.001,0.000,0.000,0,0,2.000,2.000,0,0,1
3749335495.505400,,,2.006,2.000,0.000,0.000,0,0,2.000,2.000,0,0,1
3749335630.505400,,,2.007,2.000,0.000,0.000,0,0,2.000,2.000,0,0,1
3749335765.505400,,,2.004,2.000,0.000,0.000,0,0,2.000,2.000,0,0,1
3749335900.505400,,,2.006,2.000,0.000,0.000,0,0,2.000,2.000,0,0,1
3749336035.505400,,,2.002,2.000,0.000,0.000,0,0,2.000,2.000,0,0,1
3749336170.505400,,,2.000,2.000,0.000,0.000,0,0,2.000,2.000,0,0,1
3749336305.505400,,,1.997,2.000,0.000,0.000,0,0,2.000,2.000,0,0,1
3749336440.505400,,,2.004,2.000,0.000,0.000,0,0,2.000,2.000,0,0,1
3749336575.505400,,,1.995,2.000,0.000,0.000,0,0,2.000,2.000,0,0,1
3749336710.505400,,,1.997,2.000,0.000,0.000,0,0,2.000,2.000,0,0,1
3749336845.505400,,,1.997,2.000,0.000,0.000,0,0,2.000,2.000,0,0,1
3749336980.505400,,,2.000,2.000,0.000,0.000,0,0,2.000,2.000,0,0,1
3749337115.505400,,,1.994,2.000,0.000,0.000,0,0,2.000,2.000,0,0,1
3749337250.505400,,,1.999,2.000,0.000,0.000,0,0,2.000,2.000,0,0,1
3749337385.505400,,,1.994,2.000,0.000,0.000,0,0,2.000,2.000,0,0,1
3749337520.505400,,,2.002,2.000,0.000,0.000,0,0,2.000,2.000,0,0,1
3749337655.505400,,,2.005,2.000,0.000,0.000,0,0,2.000,2.000,0,0,1
3749337790.505400,,,1.998,1.999,0.000,0.000,0,0,2.000,2.000,0,0,1
3749337925.505400,,,2.003,2.000,0.000,0.000,0,0,2.000,2.000,0,0,1
3749338060.505400,,,2.002,2.000,0.000,0.000,0,0,2.000,2.000,0,0,1
3749338195.505400,,,2.000,2.000,0.000,0.000,0,0,2.000,2.000,0,0,1
3749338330.505400,,,2.002,2.000,0.000,0.000,0,0,2.000,2.000,0,0,1
3749338465.505400,,,1.989,2.001,0.000,0.000,0,0,2.000,2.000,0,0,1
3749338600.505400,,,1.997,2.000,0.000,0.000,0,0,2.000,2.000,0,0,1
3749338735.505400,,,1.997,2.000,0.000,0.000,0,0,2.000,2.000,0,0,1
3749338870.505400,,,2.003,1.999,0.000,0.000,0,0,2.000,2.000,0,0,1
3749339005.505400,,,1.993,2.000,0.000,0.000,0,0,2.000,2.000,0,0,1
3749339140.505400,,,2.001,2.000,0.000,0.000,0,0,2.000,2.000,0,0,1
3749339275.505400,,,2.001,2.001,0.000,0.000,0,0,2.000,2.000,0,0,1
3749339410.505400,,,2.003,2.001,0.000,0.000,0,0,2.000,2.000,0,0,1
3749339545.505400,,,1.997,2.000,0.000,0.000,0,0,2.000,2.000,0,0,1
3749339680.505400,,,2.001,2.000,0.000,0.000,0,0,2.000,2.000,0,0,1
3749339815.505400,,,1.996,2.000,0.000,0.000,0,0,2.000,2.000,0,0,1
3749339950.505400,,,2.003,1.999,0.000,0.000,0,0,2.000,2.000,0,0,1
3749340085.505400,,,2.000,1.999,0.000,0.000,0,0,2.000,2.000,0,0,1
3749340220.505400,,,1.999,2.001,0.000,0.000,0,0,2.000,2.000,0,0,1
3749340355.505400,,,1.993,2.000,0.000,0.000,0,0,2.000,2.000,0,0,1
3749340490.505400,,,1.997,2.000,0.000,0.000,0,0,2.000,2.000,0,0,1
3749340625.505400,,,2.001,2.000,0.000,0.000,0,0,2.000,2.000,0,0,1
3749340760.505400,,,2.001,2.000,0.000,0.000,0,0,2.000,2.000,0,0,1
3749340895.505400,,,1.995,2.000,0.000,0.000,0,0,2.000,2.000,0,0,1
3749341030.505400,,,2.005,2.000,0.000,0.000,0,0,2.000,2.000,0,0,1
3749341165.505400,,,1.997,2.000,0.000,0.000,0,0,2.000,2.000,0,0,1
3749341300.505400,,,1.998,2.000,0.000,0.000,0,0,2.000,2.000,0,0,1
3749341435.505400,,,2.005,2.000,0.000,0.000,0,0,2.000,2.000,0,0,1
3749341570.505400,,,2.003,2.000,0.000,0.000,0,0,2.000,2.000,0,0,1
3749341705.505400,,,2.001,2.000,0.000,0.000,0,0,2.000,2.000,0,0,1
3749341840.505400,,,2.003,2.000,0.000,0.000,0,0,2.000,2.000,0,0,1
3749341975.505400,,,1.997,2.001,0.000,0.000,0,0,2.000,2.000,0,0,1
3749342110.505400,,,1.999,2.000,0.000,0.000,0,0,2.000,2.000,0,0,1
3749342245.505400,,,1.998,2.001,0.000,0.000,0,0,2.000,2.000,0,0,1
3749342380.505400,,,2.005,2.000,0.000,0.000,0,0,2.000,2.000,0,0,1
3749342515.505400,,,2.000,2.000,0.000,0.000,0,0,2.000,2.000,0,0,1
3749342650.505400,,,1.998,2.001,0.000,0.000,0,0,2.000,2.000,0,0,1
3749342785.505400,,,1.992,2.000,0.000,0.000,0,0,2.000,2.000,0,0,1
3749342920.505400,,,2.009,2.000,0.000,0.000,0,0,2.000,2.000,0,0,1
3749343055.505400,,,2.000,2.000,0.000,0.000,0,0,2.000,2.000,0,0,1
3749343190.505400,,,2.001,2.000,0.000,0.000,0,0,2.000,2.000,0,0,1
3749343325.505400,,,2.004,2.000,0.000,0.000,0,0,2.000,2.000,0,0,1
3749343460.505400,,,2.002,2.000,0.000,0.000,0,0,2.000,2.000,0,0,1
3749343595.505400,,,2.005,2.000,0.000,0.000,0,0,2.000,2.000,0,0,1
3749343730.505400,,,2.006,2.000,0.000,0.000,0,0,2.000,2.000,0,0,1
3749343865.505400,,,1.994,2.000,0.000,0.000,0,0,2.000,2.000,0,0,1
3749344000.505400,,,2.003,2.000,0.000,0.000,0,0,2.000,2.000,0,0,1
3749344135.505400,,,2.001,2.000,0.000,0.000,0,0,2.000,2.000,0,0,1
3749344270.505400,,,1.999,2.000,0.000,0.000,0,0,2.000,2.000,0,0,1
3749344405.505400,,,2.003,2.000,0.000,0.000,0,0,2.000,2.000,0,0,1
3749344540.505400,,,2.001,2.000,0.000,0.000,0,0,2.000,2.000,0,0,1
3749344675.505400,,,1.993,2.000,0.000,0.000,0,0,2.000,2.000,0,0,1
3749344810.505400,,,2.001,2.000,0.000,0.000,0,0,2.000,2.000,0,0,1
3749344945.505400,,,1.992,2.000,0.000,0.000,0,0,2.000,2.000,0,0,1
3749345080.505400,,,2.001,2.000,0.000,0.000,0,0,2.000,2.000,0,0,1
3749345215.505400,,,1.990,2.001,0.000,0.000,0,0,2.000,2.000,0,0,1
3749345350.505400,,,1.998,2.000,0.000,0.000,0,0,2.000,2.000,0,0,1
3749345485.505400,,,1.992,2.000,0.000,0.000,0,0,2.000,2.000,0,0,1
3749345620.505400,,,1.991,2.001,0.000,0.000,0,0,2.000,2.000,0,0,1
3749345755.505400,,,1.999,2.000,0.000,0.000,0,0,2.000,2.000,0,0,1
3749345890.505400,,,1.997,2.000,0.000,0.000,0,0,2.000,2.000,0,0,1
3749346025.505400,,,1.996,2.000,0.000,0.000,0,0,2.000,2.000,0,0,1
3749346160.505400,,,1.999,2.000,0.000,0.000,0,0,2.000,2.000,0,0,1
3749346295.505400,,,2.003,2.000,0.000,0.000,0,0,2.000,2.000,0,0,1
3749346430.505400,,,1.994,2.000,0.000,0.000,0,0,2.000,2.000,0,0,1
3749346565.505400,,,1.999,2.000,0.000,0.000,0,0,2.000,2.000,0,0,1
3749346700.505400,,,1.996,2.000,0.000,0.000,0,0,2.000,2.000,0,0,1
3749346835.505400,,,2.000,2.000,0.000,0.000,0,0,2.000,2.000,0,0,1
3749346970.505400,,,2.003,2.000,0.000,0.000,0,0,2.000,2.000,0,0,1
3749347105.505400,,,1.999,2.000,0.000,0.000,0,0,2.000,2.000,0,0,1
3749347240.505400,,,2.002,2.000,0.000,0.000,0,0,2.000,2.000,0,0,1
3749347375.505400,,,2.005,2.000,0.000,0.000,0,0,2.000,2.000,0,0,1
3749347510.505400,,,1.999,2.000,0.000,0.000,0,0,2.000,2.000,0,0,1
3749347645.505400,,,2.003,2.000,0.000,0.000,0,0,2.000,2.000,0,0,1
3749347780.505400,,,1.996,2.000,0.000,0.000,0,0,2.000,2.000,0,0,1
3749347915.505400,,,2.006,2.000,0.000,0.000,0,0,2.000,2.000,0,0,1
3749348050.505400,,,1.991,2.000,0.000,0.000,0,0,2.000,2.000,0,0,1
3749348185.505400,,,1.996,2.000,0.000,0.000,0,0,2.000,2.000,0,0,1
3749348320.505400,,,2.000,1.999,0.000,0.000,0,0,2.000,2.000,0,0,1
3749348455.505400,,,2.006,2.001,0.000,0.000,0,0,2.000,2.000,0,0,1
3749348590.505400,,,1.996,2.000,0.000,0.000,0,0,2.000,2.000,0,0,1
3749348725.505400,,,1.991,1.999,0.000,0.000,0,0,2.000,2.000,0,0,1
3749348860.505400,,,2.003,2.000,0.000,0.000,0,0,2.000,2.000,0,0,1
3749348995.505400,,,2.000,1.999,0.000,0.000,0,0,2.000,2.000,0,0,1
3749349130.505400,,,1.990,2.000,0.000,0.000,0,0,2.000,2.000,0,0,1
3749349265.505400,,,2.003,2.000,0.000,0.000,0,0,2.000,2.000,0,0,1
3749349400.505400,,,2.008,2.000,0.000,0.000,0,0,2.000,2.000,0,0,1
3749349535.505400,,,2.000,1.999,0.000,0.000,0,0,2.000,2.000,0,0,1
3749349670.505400,,,1.995,2.000,0.000,0.000,0,0,2.000,2.000,0,0,1
3749349805.505400,,,1.994,2.000,0.000,0.000,0,0,2.000,2.000,0,0,1
3749349940.505400,,,2.000,2.000,0.000,0.000,0,0,2.000,2.000,0,0,1
3749350075.505400,,,1.998,2.000,0.000,0.000,0,0,2.000,2.000,0,0,1
3749350210.505400,,,1.994,2.000,0.000,0.000,0,0,2.000,2.000,0,0,1
3749350345.505400,,,2.006,2.000,0.000,0.000,0,0,2.000,2.000,0,0,1
3749350480.505400,,,1.996,2.000,0.000,0.000,0,0,2.000,2.000,0,0,1
3749350615.505400,,,2.005,2.000,0.000,0.000,0,0,2.000,2.000,0,0,1
3749350750.505400,,,2.001,2.000,0.000,0.000,0,0,2.000,2.000,0,0,1
3749350885.505400,,,1.997,2.000,0.000,0.000,0,0,2.000,2.000,0,0,1
3749351020.505400,,,1.999,2.000,0.000,0.000,0,0,2.000,2.000,0,0,1
3749351155.505400,,,1.995,2.000,0.000,0.000,0,0,2.000,2.000,0,0,1
3749351290.505400,,,1.996,2.000,0.000,0.000,0,0,2.000,2.000,0,0,1
3749351425.505400,,,2.002,2.000,0.000,0.000,0,0,2.000,2.000,0,0,1
3749351560.505400,,,1.992,2.000,0.000,0.000,0,0,2.000,2.000,0,0,1
3749351695.505400,,,2.004,1.999,0.000,0.000,0,0,2.000,2.000,0,0,1
3749351830.505400,,,2.003,2.000,0.000,0.000,0,0,2.000,2.000,0,0,1
3749351965.505400,,,2.000,2.000,0.000,0.000,0,0,2.000,2.000,0,0,1
3749352100.505400,,,2.006,2.000,0.000,0.000,0,0,2.000,2.000,0,0,1
3749352235.505400,,,2.002,2.000,0.000,0.000,0,0,2.000,2.000,0,0,1
3749352370.505400,,,2.008,2.000,0.000,0.000,0,0,2.000,2.000,0,0,1
3749352505.505400,,,2.000,1.999,0.000,0.000,0,0,2.000,2.000,0,0,1
3749352640.505400,,,2.003,2.000,0.000,0.000,0,0,2.000,2.000,0,0,1
3749352775.505400,,,2.001,2.000,0.000,0.000,0,0,2.000,2.000,0,0,1
3749352910.505400,,,1.998,2.000,0.000,0.000,0,0,2.000,2.000,0,0,1
3749353045.505400,,,2.006,2.000,0.000,0.000,0,0,2.000,2.000,0,0,1
3749353180.505400,,,1.990,2.000,0.000,0.000,0,0,2.000,2.000,0,0,1
3749353315.505400,,,2.006,2.000,0.000,0.000,0,0,2.000,2.000,0,0,1
3749353450.505400,,,2.001,2.000,0.000,0.000,0,0,2.000,2.000,0,0,1
3749353585.505400,,,2.001,2.000,0.000,0.000,0,0,2.000,2.000,0,0,1
3749353720.505400,,,1.999,1.999,0.000,0.000,0,0,2.000,2.000,0,0,1
3749353855.505400,,,1.992,2.000,0.000,0.000,0,0,2.000,2.000,0,0,1
3749353990.505400,,,1.993,2.000,0.000,0.000,0,0,2.000,2.000,0,0,1
3749354125.505400,,,2.008,2.001,0.000,0.000,0,0,2.000,2.000,0,0,1
3749354260.505400,,,1.996,2.000,0.000,0.000,0,0,2.000,2.000,0,0,1
3749354395.505400,,,1.997,2.000,0.000,0.000,0,0,2.000,2.000,0,0,1
3749354530.505400,,,2.005,2.000,0.000,0.000,0,0,2.000,2.000,0,0,1
3749354665.505400,,,1.997,2.000,0.000,0.000,0,0,2.000,2.000,0,0,1
3749354800.505400,,,2.002,2.000,0.000,0.000,0,0,2.000,2.000,0,0,1
3749354935.505400,,,1.997,2.000,0.000,0.000,0,0,2.000,2.000,0,0,1
3749355070.505400,,,2.004,2.000,0.000,0.000,0,0,2.000,2.000,0,0,1
3749355205.505400,,,2.006,2.000,0.000,0.000,0,0,2.000,2.000,0,0,1
3749355340.505400,,,1.999,2.000,0.000,0.000,0,0,2.000,2.000,0,0,1
3749355475.505400,,,2.002,2.000,0.000,0.000,0,0,2.000,2.000,0,0,1
3749355610.505400,,,2.004,2.000,0.000,0.000,0,0,2.000,2.000,0,0,1
3749355745.505400,,,2.002,2.000,0.000,0.000,0,0,2.000,2.000,0,0,1
3749355880.505400,,,2.003,2.001,0.000,0.000,0,0,2.000,2.000,0,0,1
3749356015.505400,,,2.000,1.999,0.000,0.000,0,0,2.000,2.000,0,0,1
3749356150.505400,,,2.004,2.000,0.000,0.000,0,0,2.000,2.000,0,0,1
3749356285.505400,,,2.005,2.000,0.000,0.000,0,0,2.000,2.000,0,0,1
3749356420.505400,,,2.003,2.000,0.000,0.000,0,0,2.000,2.000,0,0,1
3749356555.505400,,,2.001,2.000,0.000,0.000,0,0,2.000,2.000,0,0,1
3749356690.505400,,,1.994,2.001,0.000,0.000,0,0,2.000,2.000,0,0,1
3749356825.505400,,,1.998,2.000,0.000,0.000,0,0,2.000,2.000,0,0,1
3749356960.505400,,,2.003,2.000,0.000,0.000,0,0,2.000,2.000,0,0,1
3749357095.505400,,,1.996,2.000,0.000,0.000,0,0,2.000,2.000,0,0,1
3749357230.505400,,,2.000,1.999,0.000,0.000,0,0,2.000,2.000,0,0,1
3749357365.505400,,,1.995,1.999,0.000,0.000,0,0,2.000,2.000,0,0,1
3749357500.505400,,,1.993,2.000,0.000,0.000,0,0,2.000,2.000,0,0,1
3749357635.505400,,,1.998,2.000,0.000,0.000,0,0,2.000,2.000,0,0,1
3749357770.505400,,,2.000,2.000,0.000,0.000,0,0,2.000,2.000,0,0,1
3749357905.505400,,,1.996,2.000,0.000,0.000,0,0,2.000,2.000,0,0,1
3749358040.505400,,,2.000,2.000,0.000,0.000,0,0,2.000,2.000,0,0,1
3749358175.505400,,,1.995,2.000,0.000,0.000,0,0,2.000,2.000,0,0,1
3749358310.505400,,,2.002,2.001,0.000,0.000,0,0,2.000,2.000,0,0,1
3749358445.505400,,,2.000,2.000,0.000,0.000,0,0,2.000,2.000,0,0,1
3749358580.505400,,,1.997,2.000,0.000,0.000,0,0,2.000,2.000,0,0,1
3749358715.505400,,,2.000,2.000,0.000,0.000,0,0,2.000,2.000,0,0,1
3749358850.505400,,,2.001,2.000,0.000,0.000,0,0,2.000,2.000,0,0,1
3749358985.505400,,,2.003,2.000,0.000,0.000,0,0,2.000,2.000,0,0,1
3749359120.505400,,,2.005,2.000,0.000,0.000,0,0,2.000,2.000,0,0,1
3749359255.505400,,,2.005,2.000,0.000,0.000,0,0,2.000,2.000,0,0,1
3749359390.505400,,,1.994,2.000,0.000,0.000,0,0,2.000,2.000,0,0,1
3749359525.505400,,,1.999,2.000,0.000,0.000,0,0,2.000,2.000,0,0,1
3749359660.505400,,,2.003,2.000,0.000,0.000,0,0,2.000,2.000,0,0,1
3749359795.505400,,,1.996,1.999,0.000,0.000,0,0,2.000,2.000,0,0,1
3749359930.505400,,,1.996,2.000,0.000,0.000,0,0,2.000,2.000,0,0,1
3749360065.505400,,,1.993,2.000,0.000,0.000,0,0,2.000,2.000,0,0,1
3749360200.505400,,,2.005,2.000,0.000,0.000,0,0,2.000,2.000,0,0,1
3749360335.505400,,,2.001,2.000,0.000,0.000,0,0,2.000,2.000,0,0,1
3749360470.505400,,,2.001,2.001,0.000,0.000,0,0,2.000,2.000,0,0,1
3749360605.505400,,,2.001,2.000,0.000,0.000,0,0,2.000,2.000,0,0,1
3749360740.505400,,,1.999,2.000,0.000,0.000,0,0,2.000,2.000,0,0,1
3749360875.505400,,,2.006,2.000,0.000,0.000,0,0,2.000,2.000,0,0,1
3749361010.505400,,,2.000,2.000,0.000,0.000,0,0,2.000,2.000,0,0,1
3749361145.505400,,,1.991,1.999,0.000,0.000,0,0,2.000,2.000,0,0,1
3749361280.505400,,,2.005,2.000,0.000,0.000,0,0,2.000,2.000,0,0,1
3749361415.505400,,,1.992,2.000,0.000,0.000,0,0,2.000,2.000,0,0,1
3749361550.505400,,,2.002,2.001,0.000,0.000,0,0,2.000,2.000,0,0,1
3749361685.505400,,,2.005,2.000,0.000,0.000,0,0,2.000,2.000,0,0,1
3749361820.505400,,,2.001,2.000,0.000,0.000,0,0,2.000,2.000,0,0,1
3749361955.505400,,,2.006,2.000,0.000,0.000,0,0,2.000,2.000,0,0,1
3749362090.505400,,,2.004,2.000,0.000,0.000,0,0,2.000,2.000,0,0,1
3749362225.505400,,,2.002,2.000,0.000,0.000,0,0,2.000,2.000,0,0,1
3749362360.505400,,,2.000,2.000,0.000,0.000,0,0,2.000,2.000,0,0,1
3749362495.505400,,,2.002,2.000,0.000,0.000,0,0,2.000,2.000,0,0,1
3749362630.505400,,,1.995,1.999,0.000,0.000,0,0,2.000,2.000,0,0,1
3749362765.505400,,,2.001,2.000,0.000,0.000,0,0,2.000,2.000,0,0,1
3749362900.505400,,,1.997,1.999,0.000,0.000,0,0,2.000,2.000,0,0,1
3749363035.505400,,,1.999,2.000,0.000,0.000,0,0,2.000,2.000,0,0,1
3749363170.505400,,,2.003,2.001,0.000,0.000,0,0,2.000,2.000,0,0,1
3749363305.505400,,,2.004,2.000,0.000,0.000,0,0,2.000,2.000,0,0,1
3749363440.505400,,,2.004,2.000,0.000,0.000,0,0,2.000,2.000,0,0,1
3749363575.505400,,,2.001,2.000,0.000,0.000,0,0,2.000,2.000,0,0,1
3749363710.505400,,,2.003,1.999,0.000,0.000,0,0,2.000,2.000,0,0,1
3749363845.505400,,,2.002,2.000,0.000,0.000,0,0,2.000,2.000,0,0,1
3749363980.505400,,,2.004,2.000,0.000,0.000,0,0,2.000,2.000,0,0,1
3749364115.505400,,,1.996,1.999,0.000,0.000,0,0,2.000,2.000,0,0,1
3749364250.505400,,,2.003,2.000,0.000,0.000,0,0,2.000,2.000,0,0,1
3749364385.505400,,,2.005,2.000,0.000,0.000,0,0,2.000,2.000,0,0,1
3749364520.505400,,,2.005,2.000,0.000,0.000,0,0,2.000,2.000,0,0,1
3749364655.505400,,,2.002,2.000,0.000,0.000,0,0,2.000,2.000,0,0,1
3749364790.505400,,,2.000,2.000,0.000,0.000,0,0,2.000,2.000,0,0,1
3749364925.505400,,,2.004,2.000,0.000,0.000,0,0,2.000,2.000,0,0,1
3749365060.505400,,,2.003,2.000,0.000,0.000,0,0,2.000,2.000,0,0,1
3749365195.505400,,,2.001,2.000,0.000,0.000,0,0,2.000,2.000,0,0,1
3749365330.505400,,,2.002,2.000,0.000,0.000,0,0,2.000,2.000,0,0,1
3749365465.505400,,,2.005,2.000,0.000,0.000,0,0,2.000,2.000,0,0,1
3749365600.505400,,,1.998,2.000,0.000,0.000,0,0,2.000,2.000,0,0,1
3749365735.505400,,,1.993,2.000,0.000,0.000,0,0,2.000,2.000,0,0,1
3749365870.505400,,,2.000,2.000,0.000,0.000,0,0,2.000,2.000,0,0,1
3749366005.505400,,,1.991,2.000,0.000,0.000,0,0,2.000,2.000,0,0,1
3749366140.505400,,,1.993,2.000,0.000,0.000,0,0,2.000,2.000,0,0,1
3749366275.505400,,,2.001,1.999,0.000,0.000,0,0,2.000,2.000,0,0,1
3749366410.505400,,,1.999,2.000,0.000,0.000,0,0,2.000,2.000,0,0,1
3749366545.505400,,,1.998,2.000,0.000,0.000,0,0,2.000,2.000,0,0,1
3749366680.505400,,,2.002,1.999,0.000,0.000,0,0,2.000,2.000,0,0,1
3749366815.505400,,,2.006,2.000,0.000,0.000,0,0,2.000,2.000,0,0,1
3749366950.505400,,,2.001,2.000,0.000,0.000,0,0,2.000,2.000,0,0,1
3749367085.505400,,,2.008,2.000,0.000,0.000,0,0,2.000,2.000,0,0,1
3749367220.505400,,,2.004,2.000,0.000,0.000,0,0,2.000,2.000,0,0,1
3749367355.505400,,,2.006,2.000,0.000,0.000,0,0,2.000,2.000,0,0,1
3749367490.505400,,,2.003,2.000,0.000,0.000,0,0,2.000,2.000,0,0,1
3749367625.505400,,,1.998,2.000,0.000,0.000,0,0,2.000,2.000,0,0,1
3749367760.505400,,,2.007,2.000,0.000,0.000,0,0,2.000,2.000,0,0,1
3749367895.505400,,,2.002,2.000,0.000,0.000,0,0,2.000,2.000,0,0,1
3749368030.505400,,,1.999,2.000,0.000,0.000,0,0,2.000,2.000,0,0,1
3749368165.505400,,,2.002,2.000,0.000,0.000,0,0,2.000,2.000,0,0,1
3749368300.505400,,,1.998,2.000,0.000,0.000,0,0,2.000,2.000,0,0,1
3749368435.505400,,,2.006,2.000,0.000,0.000,0,0,2.000,2.000,0,0,1
3749368570.505400,,,1.997,2.000,0.000,0.000,0,0,2.000,2.000,0,0,1
3749368705.505400,,,1.999,2.000,0.000,0.000,0,0,2.000,2.000,0,0,1
3749368840.505400,,,1.999,2.000,0.000,0.000,0,0,2.000,2.000,0,0,1
3749368975.505400,,,1.997,2.000,0.000,0.000,0,0,2.000,2.000,0,0,1
3749369110.505400,,,2.008,2.000,0.000,0.000,0,0,2.000,2.000,0,0,1
3749369245.505400,,,2.004,2.001,0.000,0.000,0,0,2.000,2.000,0,0,1
3749369380.505400,,,2.002,2.000,0.000,0.000,0,0,2.000,2.000,0,0,1
3749369515.505400,,,1.992,2.000,0.000,0.000,0,0,2.000,2.000,0,0,1
3749369650.505400,,,1.999,2.000,0.000,0.000,0,0,2.000,2.000,0,0,1
3749369785.505400,,,2.003,2.000,0.000,0.000,0,0,2.000,2.000,0,0,1
3749369920.505400,,,2.000,2.000,0.000,0.000,0,0,2.000,2.000,0,0,1
3749370055.505400,,,1.998,1.999,0.000,0.000,0,0,2.000,2.000,0,0,1
3749370190.505400,,,1.998,2.000,0.000,0.000,0,0,2.000,2.000,0,0,1
3749370325.505400,,,2.004,2.000,0.000,0.000,0,0,2.000,2.000,0,0,1
3749370460.505400,,,2.001,2.000,0.000,0.000,0,0,2.000,2.000,0,0,1
3749370595.505400,,,1.998,2.000,0.000,0.000,0,0,2.000,2.000,0,0,1
3749370730.505400,,,2.002,2.001,0.000,0.000,0,0,2.000,2.000,0,0,1
3749370865.505400,,,2.006,2.000,0.000,0.000,0,0,2.000,2.000,0,0,1
3749371000.505400,,,1.999,1.999,0.000,0.000,0,0,2.000,2.000,0,0,1
3749371135.505400,,,2.003,1.999,0.000,0.000,0,0,2.000,2.000,0,0,1
3749371270.505400,,,1.999,2.000,0.000,0.000,0,0,2.000,2.000,0,0,1
3749371405.505400,,,1.992,2.000,0.000,0.000,0,0,2.000,2.000,0,0,1
3749371540.505400,,,1.998,1.999,0.000,0.000,0,0,2.000,2.000,0,0,1
3749371675.505400,,,1.999,2.000,0.000,0.000,0,0,2.000,2.000,0,0,1
3749371810.505400,,,1.997,2.000,0.000,0.000,0,0,2.000,2.000,0,0,1
3749371945.505400,,,1.994,2.000,0.000,0.000,0,0,2.000,2.000,0,0,1
3749372080.505400,,,2.002,2.000,0.000,0.000,0,0,2.000,2.000,0,0,1
3749372215.505400,,,1.999,2.000,0.000,0.000,0,0,2.000,2.000,0,0,1
3749372350.505400,,,1.999,2.000,0.000,0.000,0,0,2.000,2.000,0,0,1
3749372485.505400,,,2.006,2.000,0.000,0.000,0,0,2.000,2.000,0,0,1
3749372620.505400,,,2.003,1.999,0.000,0.000,0,0,2.000,2.000,0,0,1
3749372755.505400,,,2.000,2.000,0.000,0.000,0,0,2.000,2.000,0,0,1
3749372890.505400,,,1.993,2.000,0.000,0.000,0,0,2.000,2.000,0,0,1
3749373025.505400,,,2.004,2.000,0.000,0.000,0,0,2.000,2.000,0,0,1
3749373160.505400,,,2.007,2.001,0.000,0.000,0,0,2.000,2.000,0,0,1
3749373295.505400,,,2.004,2.000,0.000,0.000,0,0,2.000,2.000,0,0,1
3749373430.505400,,,2.001,2.001,0.000,0.000,0,0,2.000,2.000,0,0,1
3749373565.505400,,,1.999,2.000,0.000,0.000,0,0,2.000,2.000,0,0,1
3749373700.505400,,,1.997,2.000,0.000,0.000,0,0,2.000,2.000,0,0,1
3749373835.505400,,,2.001,2.000,0.000,0.000,0,0,2.000,2.000,0,0,1
3749373970.505400,,,2.005,2.000,0.000,0.000,0,0,2.000,2.000,0,0,1
3749374105.505400,,,1.996,2.000,0.000,0.000,0,0,2.000,2.000,0,0,1
3749374240.505400,,,2.000,2.000,0.000,0.000,0,0,2.000,2.000,0,0,1
3749374375.505400,,,1.999,2.000,0.000,0.000,0,0,2.000,2.000,0,0,1
3749374510.505400,,,1.993,2.000,0.000,0.000,0,0,2.000,2.000,0,0,1
3749374645.505400,,,1.998,1.999,0.000,0.000,0,0,2.000,2.000,0,0,1
3749374780.505400,,,2.006,2.000,0.000,0.000,0,0,2.000,2.000,0,0,1
3749374915.505400,,,1.999,2.000,0.000,0.000,0,0,2.000,2.000,0,0,1
3749375050.505400,,,2.001,2.000,0.000,0.000,0,0,2.000,2.000,0,0,1
3749375185.505400,,,2.004,1.999,0.000,0.000,0,0,2.000,2.000,0,0,1
3749375320.505400,,,2.004,2.000,0.000,0.000,0,0,2.000,2.000,0,0,1
3749375455.505400,,,1.990,2.000,0.000,0.000,0,0,2.000,2.000,0,0,1
3749375590.505400,,,2.002,2.000,0.000,0.000,0,0,2.000,2.000,0,0,1
3749375725.505400,,,1.994,2.000,0.000,0.000,0,0,2.000,2.000,0,0,1
3749375860.505400,,,2.002,2.000,0.000,0.000,0,0,2.000,2.000,0,0,1
3749375995.505400,,,2.004,2.000,0.000,0.000,0,0,2.000,2.000,0,0,1
3749376130.505400,,,1.996,2.000,0.000,0.000,0,0,2.000,2.000,0,0,1
3749376265.505400,,,2.001,2.000,0.000,0.000,0,0,2.000,2.000,0,0,1
3749376400.505400,,,2.003,1.999,0.000,0.000,0,0,2.000,2.000,0,0,1
3749376535.505400,,,2.000,1.999,0.000,0.000,0,0,2.000,2.000,0,0,1
3749376670.505400,,,2.000,2.000,0.000,0.000,0,0,2.000,2.000,0,0,1
3749376805.505400,,,2.002,2.000,0.000,0.000,0,0,2.000,2.000,0,0,1
3749376940.505400,,,2.000,1.999,0.000,0.000,0,0,2.000,2.000,0,0,1
3749377075.505400,,,1.995,2.000,0.000,0.000,0,0,2.000,2.000,0,0,1
3749377210.505400,,,2.005,2.001,0.000,0.000,0,0,2.000,2.000,0,0,1
3749377345.505400,,,1.995,2.000,0.000,0.000,0,0,2.000,2.000,0,0,1
3749377480.505400,,,2.008,2.001,0.000,0.000,0,0,2.000,2.000,0,0,1
3749377615.505400,,,2.002,2.000,0.000,0.000,0,0,2.000,2.000,0,0,1
3749377750.505400,,,2.004,2.000,0.000,0.000,0,0,2.000,2.000,0,0,1
3749377885.505400,,,1.997,2.000,0.000,0.000,0,0,2.000,2.000,0,0,1
3749378020.505400,,,1.992,2.000,0.000,0.000,0,0,2.000,2.000,0,0,1
3749378155.505400,,,1.998,2.000,0.000,0.000,0,0,2.000,2.000,0,0,1
3749378290.505400,,,1.997,2.000,0.000,0.000,0,0,2.000,2.000,0,0,1
3749378425.505400,,,1.995,2.000,0.000,0.000,0,0,2.000,2.000,0,0,1
3749378560.505400,,,1.998,2.000,0.000,0.000,0,0,2.000,2.000,0,0,1
3749378695.505400,,,1.994,2.000,0.000,0.000,0,0,2.000,2.000,0,0,1
3749378830.505400,,,2.003,2.000,0.000,0.000,0,0,2.000,2.000,0,0,1
3749378965.505400,,,1.995,2.000,0.000,0.000,0,0,2.000,2.000,0,0,1
3749379100.505400,,,2.001,2.000,0.000,0.000,0,0,2.000,2.000,0,0,1
3749379235.505400,,,1.999,2.000,0.000,0.000,0,0,2.000,2.000,0,0,1
3749379370.505400,,,2.003,2.000,0.000,0.000,0,0,2.000,2.000,0,0,1
3749379505.505400,,,1.998,2.000,0.000,0.000,0,0,2.000,2.000,0,0,1
3749379640.505400,,,2.006,2.000,0.000,0.000,0,0,2.000,2.000,0,0,1
3749379775.505400,,,1.989,2.001,0.000,0.000,0,0,2.000,2.000,0,0,1
3749379910.505400,,,2.000,2.000,0.000,0.000,0,0,2.000,2.000,0,0,1
3749380045.505400,,,1.995,2.001,0.000,0.000,0,0,2.000,2.000,0,0,1
3749380180.505400,,,2.005,2.000,0.000,0.000,0,0,2.000,2.000,0,0,1
3749380315.505400,,,1.994,2.000,0.000,0.000,0,0,2.000,2.000,0,0,1
3749380450.505400,,,1.994,2.000,0.000,0.000,0,0,2.000,2.000,0,0,1
3749380585.505400,,,2.003,2.000,0.000,0.000,0,0,2.000,2.000,0,0,1
3749380720.505400,,,1.994,2.000,0.000,0.000,0,0,2.000,2.000,0,0,1
3749380855.505400,,,2.005,2.000,0.000,0.000,0,0,2.000,2.000,0,0,1
3749380990.505400,,,1.992,2.000,0.000,0.000,0,0,2.000,2.000,0,0,1
3749381125.505400,,,2.003,2.000,0.000,0.000,0,0,2.000,2.000,0,0,1
3749381260.505400,,,1.997,2.000,0.000,0.000,0,0,2.000,2.000,0,0,1
3749381395.505400,,,2.001,2.000,0.000,0.000,0,0,2.000,2.000,0,0,1
3749381530.505400,,,2.005,2.000,0.000,0.000,0,0,2.000,2.000,0,0,1
3749381665.505400,,,1.998,2.001,0.000,0.000,0,0,2.000,2.000,0,0,1
3749381800.505400,,,1.997,2.000,0.000,0.000,0,0,2.000,2.000,0,0,1
3749381935.505400,,,1.992,2.000,0.000,0.000,0,0,2.000,2.000,0,0,1
3749382070.505400,,,2.006,2.000,0.000,0.000,0,0,2.000,2.000,0,0,1
3749382205.505400,,,2.005,2.000,0.000,0.000,0,0,2.000,2.000,0,0,1
3749382340.505400,,,1.997,2.000,0.000,0.000,0,0,2.000,2.000,0,0,1
3749382475.505400,,,2.001,2.000,0.000,0.000,0,0,2.000,2.000,0,0,1
3749382610.505400,,,2.003,2.000,0.000,0.000,0,0,2.000,2.000,0,0,1
3749382745.505400,,,2.004,2.000,0.000,0.000,0,0,2.000,2.000,0,0,1
3749382880.505400,,,1.998,2.000,0.000,0.000,0,0,2.000,2.000,0,0,1
3749383015.505400,,,2.000,2.000,0.000,0.000,0,0,2.000,2.000,0,0,1
3749383150.505400,,,1.998,2.000,0.000,0.000,0,0,2.000,2.000,0,0,1
3749383285.505400,,,1.998,2.001,0.000,0.000,0,0,2.000,2.000,0,0,1
3749383420.505400,,,2.002,1.999,0.000,0.000,0,0,2.000,2.000,0,0,1
3749383555.505400,,,2.005,2.000,0.000,0.000,0,0,2.000,2.000,0,0,1
3749383690.505400,,,2.004,2.001,0.000,0.000,0,0,2.000,2.000,0,0,1
3749383825.505400,,,2.002,2.000,0.000,0.000,0,0,2.000,2.000,0,0,1
3749383960.505400,,,2.004,2.000,0.000,0.000,0,0,2.000,2.000,0,0,1
3749384095.505400,,,1.998,1.999,0.000,0.000,0,0,2.000,2.000,0,0,1
3749384230.505400,,,1.999,2.000,0.000,0.000,0,0,2.000,2.000,0,0,1
3749384365.505400,,,2.001,1.999,0.000,0.000,0,0,2.000,2.000,0,0,1
3749384500.505400,,,1.998,2.001,0.000,0.000,0,0,2.000,2.000,0,0,1
3749384635.505400,,,2.004,2.000,0.000,0.000,0,0,2.000,2.000,0,0,1
3749384770.505400,,,2.005,2.000,0.000,0.000,0,0,2.000,2.000,0,0,1
3749384905.505400,,,1.999,2.000,0.000,0.000,0,0,2.000,2.000,0,0,1
3749385040.505400,,,1.994,2.000,0.000,0.000,0,0,2.000,2.000,0,0,1
3749385175.505400,,,2.001,2.000,0.000,0.000,0,0,2.000,2.000,0,0,1
3749385310.505400,,,1.998,2.000,0.000,0.000,0,0,2.000,2.000,0,0,1
3749385445.505400,,,1.993,2.000,0.000,0.000,0,0,2.000,2.000,0,0,1
3749385580.505400,,,1.995,2.001,0.000,0.000,0,0,2.000,2.000,0,0,1
3749385715.505400,,,2.005,2.000,0.000,0.000,0,0,2.000,2.000,0,0,1
3749385850.505400,,,2.001,2.000,0.000,0.000,0,0,2.000,2.000,0,0,1
3749385985.505400,,,2.003,2.000,0.000,0.000,0,0,2.000,2.000,0,0,1
3749386120.505400,,,2.004,2.000,0.000,0.000,0,0,2.000,2.000,0,0,1
3749386255.505400,,,2.004,2.000,0.000,0.000,0,0,2.000,2.000,0,0,1
3749386390.505400,,,2.004,2.001,0.000,0.000,0,0,2.000,2.000,0,0,1
3749386525.505400,,,2.004,2.000,0.000,0.000,0,0,2.000,2.000,0,0,1
3749386660.505400,,,1.999,2.000,0.000,0.000,0,0,2.000,2.000,0,0,1
3749386795.505400,,,1.992,2.000,0.000,0.000,0,0,2.000,2.000,0,0,1
3749386930.505400,,,1.996,2.001,0.000,0.000,0,0,2.000,2.000,0,0,1
3749387065.505400,,,1.999,2.000,0.000,0.000,0,0,2.000,2.000,0,0,1
3749387200.505400,,,2.001,2.000,0.000,0.000,0,0,2.000,2.000,0,0,1
3749387335.505400,,,2.003,2.000,0.000,0.000,0,0,2.000,2.000,0,0,1
3749387470.505400,,,2.005,1.999,0.000,0.000,0,0,2.000,2.000,0,0,1
3749387605.505400,,,1.999,2.000,0.000,0.000,0,0,2.000,2.000,0,0,1
3749387740.505400,,,2.000,2.000,0.000,0.000,0,0,2.000,2.000,0,0,1
3749387875.505400,,,2.004,2.000,0.000,0.000,0,0,2.000,2.000,0,0,1
3749388010.505400,,,1.992,2.000,0.000,0.000,0,0,2.000,2.000,0,0,1
3749388145.505400,,,2.002,2.001,0.000,0.000,0,0,2.000,2.000,0,0,1
3749388280.505400,,,2.006,2.000,0.000,0.000,0,0,2.000,2.000,0,0,1
3749388415.505400,,,1.996,2.000,0.000,0.000,0,0,2.000,2.000,0,0,1
3749388550.505400,,,2.006,2.000,0.000,0.000,0,0,2.000,2.000,0,0,1
3749388685.505400,,,2.005,2.000,0.000,0.000,0,0,2.000,2.000,0,0,1
3749388820.505400,,,1.996,2.000,0.000,0.000,0,0,2.000,2.000,0,0,1
3749388955.505400,,,2.000,2.000,0.000,0.000,0,0,2.000,2.000,0,0,1
3749389090.505400,,,2.001,2.000,0.000,0.000,0,0,2.000,2.000,0,0,1
3749389225.505400,,,1.997,2.000,0.000,0.000,0,0,2.000,2.000,0,0,1
3749389360.505400,,,2.003,2.000,0.000,0.000,0,0,2.000,2.000,0,0,1
3749389495.505400,,,1.999,2.000,0.000,0.000,0,0,2.000,2.000,0,0,1
3749389630.505400,,,2.005,2.000,0.000,0.000,0,0,2.000,2.000,0,0,1
3749389765.505400,,,1.999,1.999,0.000,0.000,0,0,2.000,2.000,0,0,1
3749389900.505400,,,2.004,1.999,0.000,0.000,0,0,2.000,2.000,0,0,1
3749390035.505400,,,1.995,2.000,0.000,0.000,0,0,2.000,2.000,0,0,1
3749390170.505400,,,2.007,2.001,0.000,0.000,0,0,2.000,2.000,0,0,1
3749390305.505400,,,2.004,2.000,0.000,0.000,0,0,2.000,2.000,0,0,1
3749390440.505400,,,1.999,2.000,0.000,0.000,0,0,2.000,2.000,0,0,1
3749390575.505400,,,1.994,2.000,0.000,0.000,0,0,2.000,2.000,0,0,1
3749390710.505400,,,2.006,2.000,0.000,0.000,0,0,2.000,2.000,0,0,1
3749390845.505400,,,1.999,2.000,0.000,0.000,0,0,2.000,2.000,0,0,1
3749390980.505400,,,1.993,2.001,0.000,0.000,0,0,2.000,2.000,0,0,1
3749391115.505400,,,1.990,2.000,0.000,0.000,0,0,2.000,2.000,0,0,1
3749391250.505400,,,1.992,2.000,0.000,0.000,0,0,2.000,2.000,0,0,1
3749391385.505400,,,2.004,2.000,0.000,0.000,0,0,2.000,2.000,0,0,1
3749391520.505400,,,2.005,1.999,0.000,0.000,0,0,2.000,2.000,0,0,1
3749391655.505400,,,1.997,2.000,0.000,0.000,0,0,2.000,2.000,0,0,1
3749391790.505400,,,2.007,2.000,0.000,0.000,0,0,2.000,2.000,0,0,1
3749391925.505400,,,1.998,2.000,0.000,0.000,0,0,2.000,2.000,0,0,1
3749392060.505400,,,2.005,2.000,0.000,0.000,0,0,2.000,2.000,0,0,1
3749392195.505400,,,2.003,2.000,0.000,0.000,0,0,2.000,2.000,0,0,1
3749392330.505400,,,1.991,2.000,0.000,0.000,0,0,2.000,2.000,0,0,1
3749392465.505400,,,1.998,2.000,0.000,0.000,0,0,2.000,2.000,0,0,1
3749392600.505400,,,2.001,2.000,0.000,0.000,0,0,2.000,2.000,0,0,1
3749392735.505400,,,2.002,2.000,0.000,0.000,0,0,2.000,2.000,0,0,1
3749392870.505400,,,2.006,2.001,0.000,0.000,0,0,2.000,2.000,0,0,1
3749393005.505400,,,2.007,2.000,0.000,0.000,0,0,2.000,2.000,0,0,1
3749393140.505400,,,2.004,2.000,0.000,0.000,0,0,2.000,2.000,0,0,1
3749393275.505400,,,1.990,2.000,0.000,0.000,0,0,2.000,2.000,0,0,1
3749393410.505400,,,2.002,2.000,0.000,0.000,0,0,2.000,2.000,0,0,1
3749393545.505400,,,2.007,2.000,0.000,0.000,0,0,2.000,2.000,0,0,1
3749393680.505400,,,2.000,2.000,0.000,0.000,0,0,2.000,2.000,0,0,1
3749393815.505400,,,1.999,2.000,0.000,0.000,0,0,2.000,2.000,0,0,1
3749393950.505400,,,2.005,2.000,0.000,0.000,0,0,2.000,2.000,0,0,1
3749394085.505400,,,2.005,2.000,0.000,0.000,0,0,2.000,2.000,0,0,1
3749394220.505400,,,2.005,2.000,0.000,0.000,0,0,2.000,2.000,0,0,1
3749394355.505400,,,2.004,2.000,0.000,0.000,0,0,2.000,2.000,0,0,1
3749394490.505400,,,2.003,2.000,0.000,0.000,0,0,2.000,2.000,0,0,1
3749394625.505400,,,2.000,2.000,0.000,0.000,0,0,2.000,2.000,0,0,1
3749394760.505400,,,2.003,2.000,0.000,0.000,0,0,2.000,2.000,0,0,1
3749394895.505400,,,2.002,2.000,0.000,0.000,0,0,2.000,2.000,0,0,1
3749395030.505400,,,1.997,2.000,0.000,0.000,0,0,2.000,2.000,0,0,1
3749395165.505400,,,2.002,1.999,0.000,0.000,0,0,2.000,2.000,0,0,1
3749395300.505400,,,2.005,2.000,0.000,0.000,0,0,2.000,2.000,0,0,1
3749395435.505400,,,2.000,2.000,0.000,0.000,0,0,2.000,2.000,0,0,1
3749395570.505400,,,2.002,1.999,0.000,0.000,0,0,2.000,2.000,0,0,1
3749395705.505400,,,2.002,2.000,0.000,0.000,0,0,2.000,2.000,0,0,1
3749395840.505400,,,1.991,2.001,0.000,0.000,0,0,2.000,2.000,0,0,1
3749395975.505400,,,1.998,2.000,0.000,0.000,0,0,2.000,2.000,0,0,1
3749396110.505400,,,2.003,2.000,0.000,0.000,0,0,2.000,2.000,0,0,1
3749396245.505400,,,1.997,2.000,0.000,0.000,0,0,2.000,2.000,0,0,1
3749396380.505400,,,2.003,2.000,0.000,0.000,0,0,2.000,2.000,0,0,1
3749396515.505400,,,1.993,2.000,0.000,0.000,0,0,2.000,2.000,0,0,1
3749396650.505400,,,1.994,2.000,0.000,0.000,0,0,2.000,2.000,0,0,1
3749396785.505400,,,1.998,2.000,0.000,0.000,0,0,2.000,2.000,0,0,1
3749396920.505400,,,1.994,2.000,0.000,0.000,0,0,2.000,2.000,0,0,1
3749397055.505400,,,2.001,2.000,0.000,0.000,0,0,2.000,2.000,0,0,1
3749397190.505400,,,2.005,2.000,0.000,0.000,0,0,2.000,2.000,0,0,1
3749397325.505400,,,1.994,2.001,0.000,0.000,0,0,2.000,2.000,0,0,1
3749397460.505400,,,1.998,2.000,0.000,0.000,0,0,2.000,2.000,0,0,1
3749397595.505400,,,1.996,2.000,0.000,0.000,0,0,2.000,2.000,0,0,1
3749397730.505400,,,2.002,1.999,0.000,0.000,0,0,2.000,2.000,0,0,1
3749397865.505400,,,2.003,2.000,0.000,0.000,0,0,2.000,2.000,0,0,1
3749398000.505400,,,2.003,1.999,0.000,0.000,0,0,2.000,2.000,0,0,1
3749398135.505400,,,2.004,2.000,0.000,0.000,0,0,2.000,2.000,0,0,1
3749398270.505400,,,2.003,1.999,0.000,0.000,0,0,2.000,2.000,0,0,1
3749398405.505400,,,1.993,2.000,0.000,0.000,0,0,2.000,2.000,0,0,1
3749398540.505400,,,1.998,2.000,0.000,0.000,0,0,2.000,2.000,0,0,1
3749398675.505400,,,1.998,2.000,0.000,0.000,0,0,2.000,2.000,0,0,1
3749398810.505400,,,1.993,2.000,0.000,0.000,0,0,2.000,2.000,0,0,1
3749398945.505400,,,2.003,2.000,0.000,0.000,0,0,2.000,2.000,0,0,1
3749399080.505400,,,1.998,2.001,0.000,0.000,0,0,2.000,2.000,0,0,1
3749399215.505400,,,2.000,2.000,0.000,0.000,0,0,2.000,2.000,0,0,1
3749399350.505400,,,2.007,2.000,0.000,0.000,0,0,2.000,2.000,0,0,1
3749399485.505400,,,2.006,2.000,0.000,0.000,0,0,2.000,2.000,0,0,1
3749399620.505400,,,2.002,2.000,0.000,0.000,0,0,2.000,2.000,0,0,1
3749399755.505400,,,2.004,2.000,0.000,0.000,0,0,2.000,2.000,0,0,1
3749399890.505400,,,2.002,2.000,0.000,0.000,0,0,2.000,2.000,0,0,1
3749400025.505400,,,2.001,2.000,0.000,0.000,0,0,2.000,2.000,0,0,1
3749400160.505400,,,2.004,2.001,0.000,0.000,0,0,2.000,2.000,0,0,1
3749400295.505400,,,1.989,2.000,0.000,0.000,0,0,2.000,2.000,0,0,1
3749400430.505400,,,2.004,2.000,0.000,0.000,0,0,2.000,2.000,0,0,1
3749400565.505400,,,1.997,2.000,0.000,0.000,0,0,2.000,2.000,0,0,1
3749400700.505400,,,1.999,2.001,0.000,0.000,0,0,2.000,2.000,0,0,1
3749400835.505400,,,1.991,2.000,0.000,0.000,0,0,2.000,2.000,0,0,1
3749400970.505400,,,1.999,2.000,0.000,0.000,0,0,2.000,2.000,0,0,1
3749401105.505400,,,2.001,2.000,0.000,0.000,0,0,2.000,2.000,0,0,1
3749401240.505400,,,1.994,2.000,0.000,0.000,0,0,2.000,2.000,0,0,1
3749401375.505400,,,1.990,2.000,0.000,0.000,0,0,2.000,2.000,0,0,1
3749401510.505400,,,1.994,2.000,0.000,0.000,0,0,2.000,2.000,0,0,1
3749401645.505400,,,2.003,2.000,0.000,0.000,0,0,2.000,2.000,0,0,1
3749401780.505400,,,2.004,2.000,0.000,0.000,0,0,2.000,2.000,0,0,1
3749401915.505400,,,2.002,2.000,0.000,0.000,0,0,2.000,2.000,0,0,1
3749402050.505400,,,2.004,2.001,0.000,0.000,0,0,2.000,2.000,0,0,1
3749402185.505400,,,1.994,2.000,0.000,0.000,0,0,2.000,2.000,0,0,1
3749402320.505400,,,2.002,2.000,0.000,0.000,0,0,2.000,2.000,0,0,1
3749402455.505400,,,1.989,2.000,0.000,0.000,0,0,2.000,2.000,0,0,1
3749402590.505400,,,1.996,2.000,0.000,0.000,0,0,2.000,2.000,0,0,1
3749402725.505400,,,2.005,1.999,0.000,0.000,0,0,2.000,2.000,0,0,1
3749402860.505400,,,1.996,2.000,0.000,0.000,0,0,2.000,2.000,0,0,1
3749402995.505400,,,2.006,2.000,0.000,0.000,0,0,2.000,2.000,0,0,1
3749403130.505400,,,2.003,2.000,0.000,0.000,0,0,2.000,2.000,0,0,1
3749403265.505400,,,2.005,1.999,0.000,0.000,0,0,2.000,2.000,0,0,1
3749403400.505400,,,1.999,2.001,0.000,0.000,0,0,2.000,2.000,0,0,1
3749403535.505400,,,2.000,2.000,0.000,0.000,0,0,2.000,2.000,0,0,1
3749403670.505400,,,1.998,2.000,0.000,0.000,0,0,2.000,2.000,0,0,1
3749403805.505400,,,2.000,2.001,0.000,0.000,0,0,2.000,2.000,0,0,1
3749403940.505400,,,1.994,2.000,0.000,0.000,0,0,2.000,2.000,0,0,1
3749404075.505400,,,2.005,2.000,0.000,0.000,0,0,2.000,2.000,0,0,1
3749404210.505400,,,1.995,2.000,0.000,0.000,0,0,2.000,2.000,0,0,1
3749404345.505400,,,2.004,2.000,0.000,0.000,0,0,2.000,2.000,0,0,1
3749404480.505400,,,1.999,2.000,0.000,0.000,0,0,2.000,2.000,0,0,1
3749404615.505400,,,1.999,2.000,0.000,0.000,0,0,2.000,2.000,0,0,1
3749404750.505400,,,1.996,2.000,0.000,0.000,0,0,2.000,2.000,0,0,1
3749404885.505400,,,1.996,2.000,0.000,0.000,0,0,2.000,2.000,0,0,1
3749405020.505400,,,2.002,2.000,0.000,0.000,0,0,2.000,2.000,0,0,1
3749405155.505400,,,2.004,2.000,0.000,0.000,0,0,2.000,2.000,0,0,1
3749405290.505400,,,2.005,2.000,0.000,0.000,0,0,2.000,2.000,0,0,1
3749405425.505400,,,1.999,2.000,0.000,0.000,0,0,2.000,2.000,0,0,1
3749405560.505400,,,2.002,2.000,0.000,0.000,0,0,2.000,2.000,0,0,1
3749405695.505400,,,2.004,2.000,0.000,0.000,0,0,2.000,2.000,0,0,1
3749405830.505400,,,1.999,1.999,0.000,0.000,0,0,2.000,2.000,0,0,1
3749405965.505400,,,2.000,2.000,0.000,0.000,0,0,2.000,2.000,0,0,1
3749406100.505400,,,1.996,2.000,0.000,0.000,0,0,2.000,2.000,0,0,1
3749406235.505400,,,2.002,2.000,0.000,0.000,0,0,2.000,2.000,0,0,1
3749406370.505400,,,2.001,2.000,0.000,0.000,0,0,2.000,2.000,0,0,1
3749406505.505400,,,2.004,2.000,0.000,0.000,0,0,2.000,2.000,0,0,1
3749406640.505400,,,1.999,2.000,0.000,0.000,0,0,2.000,2.000,0,0,1
3749406775.505400,,,1.990,2.000,0.000,0.000,0,0,2.000,2.000,0,0,1
3749406910.505400,,,2.005,2.000,0.000,0.000,0,0,2.000,2.000,0,0,1
3749407045.505400,,,2.001,2.000,0.000,0.000,0,0,2.000,2.000,0,0,1
3749407180.505400,,,2.003,2.001,0.000,0.000,0,0,2.000,2.000,0,0,1
3749407315.505400,,,2.001,2.000,0.000,0.000,0,0,2.000,2.000,0,0,1
3749407450.505400,,,1.991,1.999,0.000,0.000,0,0,2.000,2.000,0,0,1
3749407585.505400,,,1.998,2.001,0.000,0.000,0,0,2.000,2.000,0,0,1
3749407720.505400,,,2.006,2.001,0.000,0.000,0,0,2.000,2.000,0,0,1
3749407855.505400,,,2.003,2.000,0.000,0.000,0,0,2.000,2.000,0,0,1
3749407990.505400,,,2.000,2.000,0.000,0.000,0,0,2.000,2.000,0,0,1
3749408125.505400,,,2.007,2.000,0.000,0.000,0,0,2.000,2.000,0,0,1
3749408260.505400,,,1.997,2.000,0.000,0.000,0,0,2.000,2.000,0,0,1
3749408395.505400,,,2.004,2.000,0.000,0.000,0,0,2.000,2.000,0,0,1
3749408530.505400,,,2.004,1.999,0.000,0.000,0,0,2.000,2.000,0,0,1
3749408665.505400,,,2.002,2.000,0.000,0.000,0,0,2.000,2.000,0,0,1
3749408800.505400,,,2.001,2.000,0.000,0.000,0,0,2.000,2.000,0,0,1
3749408935.505400,,,1.992,2.000,0.000,0.000,0,0,2.000,2.000,0,0,1
3749409070.505400,,,1.999,2.000,0.000,0.000,0,0,2.000,2.000,0,0,1
3749409205.505400,,,2.001,2.000,0.000,0.000,0,0,2.000,2.000,0,0,1
3749409340.505400,,,2.003,2.000,0.000,0.000,0,0,2.000,2.000,0,0,1
3749409475.505400,,,1.991,2.000,0.000,0.000,0,0,2.000,2.000,0,0,1
3749409610.505400,,,2.005,2.000,0.000,0.000,0,0,2.000,2.000,0,0,1
3749409745.505400,,,2.002,2.000,0.000,0.000,0,0,2.000,2.000,0,0,1
3749409880.505400,,,2.003,2.001,0.000,0.000,0,0,2.000,2.000,0,0,1
3749410015.505400,,,2.003,2.000,0.000,0.000,0,0,2.000,2.000,0,0,1
3749410150.505400,,,2.000,1.999,0.000,0.000,0,0,2.000,2.000,0,0,1
3749410285.505400,,,2.002,2.000,0.000,0.000,0,0,2.000,2.000,0,0,1
3749410420.505400,,,2.004,1.999,0.000,0.000,0,0,2.000,2.000,0,0,1
3749410555.505400,,,1.998,2.000,0.000,0.000,0,0,2.000,2.000,0,0,1
3749410690.505400,,,1.990,2.000,0.000,0.000,0,0,2.000,2.000,0,0,1
3749410825.505400,,,1.992,2.001,0.000,0.000,0,0,2.000,2.000,0,0,1
3749410960.505400,,,2.006,2.000,0.000,0.000,0,0,2.000,2.000,0,0,1
3749411095.505400,,,2.000,1.999,0.000,0.000,0,0,2.000,2.000,0,0,1
3749411230.505400,,,2.001,2.000,0.000,0.000,0,0,2.000,2.000,0,0,1
3749411365.505400,,,2.001,2.000,0.000,0.000,0,0,2.000,2.000,0,0,1
3749411500.505400,,,1.999,2.000,0.000,0.000,0,0,2.000,2.000,0,0,1
3749411635.505400,,,2.005,2.000,0.000,0.000,0,0,2.000,2.000,0,0,1
3749411770.505400,,,2.001,2.000,0.000,0.000,0,0,2.000,2.000,0,0,1
3749411905.505400,,,2.003,2.000,0.000,0.000,0,0,2.000,2.000,0,0,1
3749412040.505400,,,2.000,2.000,0.000,0.000,0,0,2.000,2.000,0,0,1
3749412175.505400,,,1.998,2.001,0.000,0.000,0,0,2.000,2.000,0,0,1
3749412310.505400,,,2.003,2.000,0.000,0.000,0,0,2.000,2.000,0,0,1
3749412445.505400,,,2.000,2.000,0.000,0.000,0,0,2.000,2.000,0,0,1
3749412580.505400,,,2.000,2.000,0.000,0.000,0,0,2.000,2.000,0,0,1
3749412715.505400,,,1.999,2.000,0.000,0.000,0,0,2.000,2.000,0,0,1
3749412850.505400,,,1.998,2.000,0.000,0.000,0,0,2.000,2.000,0,0,1
3749412985.505400,,,1.997,2.000,0.000,0.000,0,0,2.000,2.000,0,0,1
3749413120.505400,,,2.003,2.000,0.000,0.000,0,0,2.000,2.000,0,0,1
3749413255.505400,,,2.008,2.000,0.000,0.000,0,0,2.000,2.000,0,0,1
3749413390.505400,,,2.004,1.999,0.000,0.000,0,0,2.000,2.000,0,0,1
3749413525.505400,,,2.005,1.999,0.000,0.000,0,0,2.000,2.000,0,0,1
3749413660.505400,,,1.994,2.001,0.000,0.000,0,0,2.000,2.000,0,0,1
3749413795.505400,,,1.999,2.000,0.000,0.000,0,0,2.000,2.000,0,0,1
3749413930.505400,,,1.998,2.000,0.000,0.000,0,0,2.000,2.000,0,0,1
3749414065.505400,,,2.000,2.000,0.000,0.000,0,0,2.000,2.000,0,0,1
3749414200.505400,,,2.000,2.000,0.000,0.000,0,0,2.000,2.000,0,0,1
3749414335.505400,,,2.000,2.000,0.000,0.000,0,0,2.000,2.000,0,0,1
3749414470.505400,,,2.005,1.999,0.000,0.000,0,0,2.000,2.000,0,0,1
3749414605.505400,,,2.001,2.000,0.000,0.000,0,0,2.000,2.000,0,0,1
3749414740.505400,,,2.000,2.000,0.000,0.000,0,0,2.000,2.000,0,0,1
3749414875.505400,,,1.999,2.000,0.000,0.000,0,0,2.000,2.000,0,0,1
3749415010.505400,,,2.002,2.000,0.000,0.000,0,0,2.000,2.000,0,0,1
3749415145.505400,,,2.005,2.000,0.000,0.000,0,0,2.000,2.000,0,0,1
3749415280.505400,,,2.005,1.999,0.000,0.000,0,0,2.000,2.000,0,0,1
3749415415.505400,,,2.002,2.000,0.000,0.000,0,0,2.000,2.000,0,0,1
3749415550.505400,,,1.995,2.000,0.000,0.000,0,0,2.000,2.000,0,0,1
3749415685.505400,,,1.999,2.000,0.000,0.000,0,0,2.000,2.000,0,0,1
3749415820.505400,,,1.999,2.000,0.000,0.000,0,0,2.000,2.000,0,0,1
3749415955.505400,,,2.000,2.000,0.000,0.000,0,0,2.000,2.000,0,0,1
3749416090.505400,,,1.999,2.000,0.000,0.000,0,0,2.000,2.000,0,0,1
3749416225.505400,,,1.999,2.000,0.000,0.000,0,0,2.000,2.000,0,0,1
3749416360.505400,,,1.994,2.000,0.000,0.000,0,0,2.000,2.000,0,0,1
3749416495.505400,,,2.001,2.001,0.000,0.000,0,0,2.000,2.000,0,0,1
3749416630.505400,,,2.007,2.000,0.000,0.000,0,0,2.000,2.000,0,0,1
3749416765.505400,,,1.993,2.000,0.000,0.000,0,0,2.000,2.000,0,0,1
3749416900.505400,,,1.994,2.000,0.000,0.000,0,0,2.000,2.000,0,0,1
3749417035.505400,,,9.288,9.258,0.000,0.000,1,1,150.000,150.000,0,0,2
3749417170.505400,,,20.437,20.383,0.000,0.000,1,1,150.000,150.000,1,1,2
3749417305.505400,,,31.602,31.581,0.000,0.000,1,1,150.000,150.000,4,3,2
3749417440.505400,,,42.774,42.751,0.000,0.000,1,1,150.000,150.000,8,5,2
3749417575.505400,,,53.943,53.909,0.000,0.000,1,1,150.000,150.000,13,8,2
3749417710.505400,,,65.119,65.110,0.000,0.000,1,1,150.000,150.000,17,11,2
3749417845.505400,,,76.303,76.278,0.000,0.000,1,1,150.000,150.000,22,14,2
3749417980.505400,,,87.481,87.464,0.000,0.000,1,1,150.000,150.000,26,17,2
3749418115.505400,,,98.688,98.649,0.000,0.000,1,1,150.000,150.000,29,19,2
3749418250.505400,,,109.847,109.813,0.000,0.000,1,1,150.000,150.000,33,22,2
3749418385.505400,,,121.043,121.015,0.000,0.000,1,1,150.000,150.000,35,25,2
3749418520.505400,,,132.220,132.181,0.000,0.000,1,1,150.000,150.000,38,27,2
3749418655.505400,,,143.386,143.363,0.000,0.000,1,1,150.000,150.000,41,29,2
3749418790.505400,,,149.422,150.029,0.000,0.000,0,0,150.000,150.000,12,15,4
3749418925.505400,,,150.418,150.010,0.000,0.000,0,0,150.000,150.000,31,13,4
3749419060.505400,,,149.803,150.016,0.000,0.000,0,0,150.000,150.000,6,12,4
3749419195.505400,,,150.036,150.003,0.000,0.000,0,0,150.000,150.000,30,11,4
3749419330.505400,,,150.146,150.011,0.000,0.000,0,0,150.000,150.000,4,10,1
3749419465.505400,,,149.734,150.010,0.000,0.000,0,0,150.000,150.000,28,10,4
3749419600.505400,,,150.383,150.000,0.000,0.000,0,0,150.000,150.000,5,10,1
3749419735.505400,,,149.534,149.986,0.000,0.000,0,0,150.000,150.000,24,9,4
3749419870.505400,,,150.522,150.004,0.000,0.000,0,0,150.000,150.000,6,9,4
3749420005.505400,,,149.443,150.001,0.000,0.000,0,0,150.000,150.000,20,9,1
3749420140.505400,,,150.562,150.007,0.000,0.000,0,0,150.000,150.000,8,8,1
3749420275.505400,,,149.456,150.006,0.000,0.000,0,0,150.000,150.000,16,8,1
3749420410.505400,,,150.509,150.008,0.000,0.000,0,0,150.000,150.000,11,8,1
3749420545.505400,,,149.552,150.001,0.000,0.000,0,0,150.000,150.000,12,8,1
3749420680.505400,,,150.381,150.006,0.000,0.000,0,0,150.000,150.000,14,7,1
3749420815.505400,,,149.704,150.000,0.000,0.000,0,0,150.000,150.000,9,7,1
3749420950.505400,,,150.217,149.995,0.000,0.000,0,0,150.000,150.000,15,7,1
3749421085.505400,,,149.880,149.996,0.000,0.000,0,0,150.000,150.000,7,7,1
3749421220.505400,,,150.036,150.003,0.000,0.000,0,0,150.000,150.000,16,7,1
3749421355.505400,,,150.056,150.004,0.000,0.000,0,0,150.000,150.000,6,7,1
3749421490.505400,,,149.874,149.999,0.000,0.000,0,0,150.000,150.000,16,6,1
3749421625.505400,,,150.193,150.003,0.000,0.000,0,0,150.000,150.000,6,6,1
3749421760.505400,,,149.750,150.001,0.000,0.000,0,0,150.000,150.000,15,6,1
3749421895.505400,,,150.286,150.002,0.000,0.000,0,0,150.000,150.000,6,6,1
3749422030.505400,,,149.692,150.000,0.000,0.000,0,0,150.000,150.000,13,6,1
3749422165.505400,,,150.310,150.001,0.000,0.000,0,0,150.000,150.000,8,6,1
3749422300.505400,,,149.704,150.001,0.000,0.000,0,0,150.000,150.000,10,6,1
3749422435.505400,,,150.267,150.000,0.000,0.000,0,0,150.000,150.000,10,6,1
3749422570.505400,,,149.784,150.003,0.000,0.000,0,0,150.000,150.000,8,6,1
3749422705.505400,,,150.164,150.002,0.000,0.000,0,0,150.000,150.000,12,6,1
3749422840.505400,,,149.908,150.002,0.000,0.000,0,0,150.000,150.000,6,5,1
3749422975.505400,,,150.026,150.000,0.000,0.000,0,0,150.000,150.000,13,5,1
3749423110.505400,,,150.050,150.001,0.000,0.000,0,0,150.000,150.000,5,5,1
3749423245.505400,,,149.883,150.000,0.000,0.000,0,0,150.000,150.000,13,5,1
3749423380.505400,,,150.175,150.001,0.000,0.000,0,0,150.000,150.000,5,5,1
3749423515.505400,,,149.776,150.000,0.000,0.000,0,0,150.000,150.000,12,5,1
3749423650.505400,,,150.253,150.001,0.000,0.000,0,0,150.000,150.000,6,5,1
3749423785.505400,,,149.731,150.000,0.000,0.000,0,0,150.000,150.000,10,5,1
3749423920.505400,,,150.265,150.000,0.000,0.000,0,0,150.000,150.000,8,5,1
3749424055.505400,,,149.760,150.001,0.000,0.000,0,0,150.000,150.000,8,5,1
3749424190.505400,,,150.203,150.000,0.000,0.000,0,0,150.000,150.000,10,5,1
3749424325.505400,,,149.857,150.001,0.000,0.000,0,0,150.000,150.000,6,5,1
3749424460.505400,,,150.076,149.999,0.000,0.000,0,0,150.000,150.000,11,5,1
3749424595.505400,,,149.999,150.002,0.000,0.000,0,0,150.000,150.000,4,5,1
3749424730.505400,,,149.929,150.000,0.000,0.000,0,0,150.000,150.000,12,5,1
3749424865.505400,,,150.142,150.001,0.000,0.000,0,0,150.000,150.000,4,5,1
3749425000.505400,,,149.802,149.999,0.000,0.000,0,0,150.000,150.000,11,4,1
3749425135.505400,,,150.240,150.000,0.000,0.000,0,0,150.000,150.000,5,5,1
3749425270.505400,,,149.731,150.000,0.000,0.000,0,0,150.000,150.000,10,4,1
3749425405.505400,,,150.274,150.000,0.000,0.000,0,0,150.000,150.000,7,4,1
3749425540.505400,,,149.746,150.001,0.000,0.000,0,0,150.000,150.000,8,4,1
3749425675.505400,,,150.220,150.000,0.000,0.000,0,0,150.000,150.000,9,4,1
3749425810.505400,,,149.839,150.001,0.000,0.000,0,0,150.000,150.000,5,4,1
3749425945.505400,,,150.094,150.000,0.000,0.000,0,0,150.000,150.000,11,4,1
3749426080.505400,,,149.991,150.000,0.000,0.000,0,0,150.000,150.000,4,4,1
3749426215.505400,,,149.930,150.000,0.000,0.000,0,0,150.000,150.000,12,4,1
3749426350.505400,,,150.145,150.000,0.000,0.000,0,0,150.000,150.000,3,4,1
3749426485.505400,,,149.784,149.999,0.000,0.000,0,0,150.000,150.000,11,4,1
3749426620.505400,,,150.263,150.000,0.000,0.000,0,0,150.000,150.000,4,4,1
3749426755.505400,,,149.706,149.999,0.000,0.000,0,0,150.000,150.000,10,4,1
3749426890.505400,,,150.298,150.001,0.000,0.000,0,0,150.000,150.000,6,4,1
3749427025.505400,,,149.725,150.001,0.000,0.000,0,0,150.000,150.000,7,4,1
3749427160.505400,,,150.233,150.001,0.000,0.000,0,0,150.000,150.000,9,4,1
3749427295.505400,,,149.836,150.000,0.000,0.000,0,0,150.000,150.000,5,4,1
3749427430.505400,,,150.086,149.999,0.000,0.000,0,0,150.000,150.000,11,4,1
3749427565.505400,,,150.006,150.000,0.000,0.000,0,0,150.000,150.000,3,4,1
3749427700.505400,,,149.903,150.000,0.000,0.000,0,0,150.000,150.000,12,4,1
3749427835.505400,,,150.182,150.000,0.000,0.000,0,0,150.000,150.000,3,4,1
3749427970.505400,,,149.742,150.000,0.000,0.000,0,0,150.000,150.000,11,4,1
3749428105.505400,,,150.303,150.001,0.000,0.000,0,0,150.000,150.000,4,4,1
3749428240.505400,,,149.669,150.001,0.000,0.000,0,0,150.000,150.000,9,4,1
3749428375.505400,,,150.324,150.000,0.000,0.000,0,0,150.000,150.000,6,4,1
3749428510.505400,,,149.712,150.000,0.000,0.000,0,0,150.000,150.000,6,4,1
3749428645.505400,,,150.233,149.999,0.000,0.000,0,0,150.000,150.000,9,4,1
3749428780.505400,,,149.856,150.000,0.000,0.000,0,0,150.000,150.000,4,4,1
3749428915.505400,,,150.054,150.000,0.000,0.000,0,0,150.000,150.000,11,4,1
3749429050.505400,,,150.052,150.001,0.000,0.000,0,0,150.000,150.000,2,4,1
3749429185.505400,,,149.848,149.999,0.000,0.000,0,0,150.000,150.000,12,4,1
3749429320.505400,,,150.241,150.000,0.000,0.000,0,0,150.000,150.000,2,4,1
3749429455.505400,,,149.685,149.999,0.000,0.000,0,0,150.000,150.000,11,4,1
3749429590.505400,,,150.351,149.999,0.000,0.000,0,0,150.000,150.000,4,4,1
3749429725.505400,,,149.633,150.000,0.000,0.000,0,0,150.000,150.000,8,4,1
3749429860.505400,,,150.343,149.999,0.000,0.000,0,0,150.000,150.000,7,4,1
3749429995.505400,,,149.715,150.000,0.000,0.000,0,0,150.000,150.000,5,4,1
3749430130.505400,,,150.207,149.999,0.000,0.000,0,0,150.000,150.000,10,4,1
3749430265.505400,,,149.901,150.001,0.000,0.000,0,0,150.000,150.000,2,4,1
3749430400.505400,,,149.987,149.999,0.000,0.000,0,0,150.000,150.000,12,4,1
3749430535.505400,,,150.129,150.001,0.000,0.000,0,0,150.000,150.000,1,4,1
3749430670.505400,,,149.763,149.999,0.000,0.000,0,0,150.000,150.000,12,4,1
3749430805.505400,,,150.319,150.001,0.000,0.000,0,0,150.000,150.000,2,4,1
3749430940.505400,,,149.618,150.001,0.000,0.000,0,0,150.000,150.000,10,4,1
3749431075.505400,,,150.396,150.000,0.000,0.000,0,0,150.000,150.000,5,4,1
3749431210.505400,,,149.618,150.001,0.000,0.000,0,0,150.000,150.000,7,4,1
3749431345.505400,,,150.335,149.999,0.000,0.000,0,0,150.000,150.000,8,4,1
3749431480.505400,,,149.762,150.001,0.000,0.000,0,0,150.000,150.000,3,4,1
3749431615.505400,,,150.131,149.999,0.000,0.000,0,0,150.000,150.000,11,4,1
3749431750.505400,,,149.996,150.001,0.000,0.000,0,0,150.000,150.000,1,4,1
3749431885.505400,,,149.872,149.998,0.000,0.000,0,0,150.000,150.000,13,4,1
3749432020.505400,,,150.239,150.001,0.000,0.000,0,0,150.000,150.000,1,4,1
3749432155.505400,,,149.651,149.998,0.000,0.000,0,0,150.000,150.000,12,4,1
3749432290.505400,,,150.407,150.001,0.000,0.000,0,0,150.000,150.000,3,4,1
3749432425.505400,,,149.559,150.000,0.000,0.000,0,0,150.000,150.000,9,4,1
3749432560.505400,,,150.423,150.000,0.000,0.000,0,0,150.000,150.000,6,4,1
3749432695.505400,,,149.640,150.001,0.000,0.000,0,0,150.000,150.000,5,4,1
3749432830.505400,,,150.270,150.000,0.000,0.000,0,0,150.000,150.000,10,4,1
3749432965.505400,,,149.870,150.002,0.000,0.000,0,0,150.000,150.000,1,4,1
3749433100.505400,,,149.998,149.999,0.000,0.000,0,0,150.000,150.000,13,4,1
3749433235.505400,,,150.150,150.001,0.000,0.000,0,0,150.000,150.000,0,4,1
3749433370.505400,,,149.712,149.999,0.000,0.000,0,0,150.000,150.000,13,4,1
3749433505.505400,,,150.380,150.001,0.000,0.000,0,0,150.000,150.000,1,4,1
3749433640.505400,,,149.540,149.999,0.000,0.000,0,0,150.000,150.000,11,4,1
3749433775.505400,,,150.473,150.000,0.000,0.000,0,0,150.000,150.000,4,4,1
3749433910.505400,,,149.560,150.000,0.000,0.000,0,0,150.000,150.000,6,4,1
3749434045.505400,,,150.370,150.000,0.000,0.000,0,0,150.000,150.000,9,4,1
3749434180.505400,,,149.765,150.001,0.000,0.000,0,0,150.000,150.000,2,4,1
3749434315.505400,,,150.097,149.999,0.000,0.000,0,0,150.000,150.000,13,4,1
3749434410.505400,,,153.746,152.987,0.000,0.000,1,1,200.000,200.000,28,13,2