File: log/20221230.dat
[Header]
; Displex Transport Data File (default extension .dat)
; Copyright 2016, Hechang LEI, hlei@ruc.edu.cn. All rights reserved.
BYAPP, Displex, 2.0
INFO, 9T mag, Release 2.0.
INFO, Channel 1, Temperature Sensor
INFO, Sample 1 Length (cm): 0.000000; Width (cm): 0.000000; Thickness (cm): 0.000000.

[Data]
Timestamp(s),Field(Oe),Field Status,TempA(K),TempB(K),TempC(K),TempD(K),Ramp1,Ramp2,Setpoint1,Setpoint2,Output1(%),Output2(%),Temp Status
3755242795.228238,400.000000,Tracking,0.000000,MagnetUnknown,ChamberUnknown
3755242987.370453,400.000000,Tracking,0.000000,Charging,PurgedAndSealed
3755243069.140079,400.000000,Tracking,0.000000,Charging,PurgedAndSealed
3755243099.140830,400.000000,Tracking,0.000000,Charging,PurgedAndSealed
3755243103.355840,400.000000,Tracking,0.000000,Charging,PurgedAndSealed
3755243133.355884,400.000000,Tracking,0.000000,Charging,PurgedAndSealed
3755248900.812400,1000,2,2.105,2.001,36.664,3.045,0,0,2.000,2.000,0.040,0.020,4
3755249050.812400,1000,1,2.110,2.000,36.578,3.043,0,0,2.000,2.000,0.000,0.020,1
3755249200.812400,1000,1,2.114,2.000,36.496,3.042,0,0,2.000,2.000,0.000,0.020,1
3755249350.812400,1000,1,2.104,2.000,36.416,3.042,0,0,2.000,2.000,0.000,0.020,1
3755249500.812400,1000,1,2.102,2.001,36.341,3.041,0,0,2.000,2.000,0.010,0.020,1
3755249650.812400,0,1,2.189,2.000,36.315,3.046,0,0,2.000,2.000,0.000,0.020,1
3755249800.812400,0,1,2.193,2.000,36.192,3.042,0,0,2.000,2.000,0.000,0.020,1
3755249950.812400,4282,2,2.190,2.001,35.998,3.472,0,0,2.000,2.000,0.000,0.020,1
3755250130.812400,22237,2,2.192,2.000,35.776,3.697,0,0,2.000,2.000,0.000,0.020,1
3755250280.812400,37215,2,2.172,2.000,35.663,3.540,0,0,2.000,2.000,0.260,0.020,1
3755250430.812400,52253,2,2.182,1.999,35.577,3.442,0,0,2.000,2.000,0.000,0.020,1
3755250580.812400,61413,2,2.183,2.000,35.533,3.201,0,0,2.000,2.000,0.030,0.010,1
3755250730.812400,69564,2,2.170,2.000,35.499,3.150,0,0,2.000,2.000,0.010,0.010,1
3755250880.812400,77646,2,2.157,2.000,35.478,3.127,0,0,2.000,2.000,0.290,0.010,1
3755251030.812400,85809,2,2.170,2.000,35.482,3.107,0,0,2.000,2.000,0.000,0.010,1
3755251180.812400,90000,1,2.178,2.000,35.509,2.913,0,0,2.000,2.000,0.110,0.010,1
3755251330.812400,83549,3,2.171,2.000,35.526,3.080,0,0,2.000,2.000,0.000,0.010,1
3755251480.812400,75464,3,2.186,2.000,35.497,3.107,0,0,2.000,2.000,0.090,0.010,1
3755251630.812400,67323,3,2.159,2.000,35.425,3.123,0,0,2.000,2.000,0.240,0.010,1
3755251780.812400,59215,3,2.808,2.745,35.353,3.140,0,0,2.000,2.000,0.000,0.000,4
3755251930.812400,48771,3,5.410,5.315,35.241,3.331,0,0,2.000,2.000,0.000,0.000,4
3755252080.812400,33837,3,8.377,8.266,35.102,3.447,0,0,2.000,2.000,0.000,0.000,4
3755252230.812400,18803,3,5.574,5.232,35.065,3.942,0,0,2.000,2.000,0.000,0.000,4
3755252380.812400,3885,3,2.454,2.303,35.359,3.978,0,0,2.000,2.000,0.000,0.000,4
3755252530.812400,-11018,3,2.133,2.000,35.450,4.138,0,0,2.000,2.000,0.050,0.020,1
3755252680.812400,-25939,3,2.139,2.000,35.525,3.811,0,0,2.000,2.000,0.060,0.010,1
3755252830.812400,-40863,3,2.123,2.001,35.596,3.703,0,0,2.000,2.000,0.000,0.010,1
3755252980.812400,-55284,3,2.126,1.999,35.674,3.581,0,0,2.000,2.000,0.100,0.010,1
3755253130.812400,-63457,3,2.147,1.999,35.762,3.396,0,0,2.000,2.000,0.000,0.010,1
3755253280.812400,-71564,3,2.129,2.000,35.846,3.370,0,0,2.000,2.000,0.120,0.010,1
3755253430.812400,-79637,3,2.150,2.000,35.939,3.344,0,0,2.000,2.000,0.000,0.010,1
3755253580.812400,-87706,3,2.153,2.000,36.041,3.320,0,0,2.000,2.000,0.000,0.010,1
3755253730.812400,-87317,4,2.160,2.000,36.154,3.232,0,0,2.000,2.000,0.000,0.010,1
3755253880.812400,-79205,4,2.157,1.999,36.221,3.311,0,0,2.000,2.000,0.000,0.010,1
3755254030.812400,-71069,4,2.162,2.000,36.227,3.325,0,0,2.000,2.000,0.000,0.010,1
3755254180.812400,-62966,4,2.140,2.001,36.191,3.340,0,0,2.000,2.000,0.000,0.010,1
3755254330.812400,-54859,4,2.157,2.000,36.132,3.352,0,0,2.000,2.000,0.000,0.010,1
3755254480.812400,-40774,4,2.161,1.999,36.052,3.602,0,0,2.000,2.000,0.000,0.010,1
3755254630.812400,-25743,4,2.143,2.000,35.959,3.682,0,0,2.000,2.000,0.110,0.010,1
3755254780.812400,-10768,4,2.154,2.000,35.869,3.808,0,0,2.000,2.000,0.020,0.020,1
3755254930.812400,1,4,2.138,1.999,35.791,3.514,0,0,2.000,2.000,0.000,0.020,1
3755255080.812400,0,1,10.510,10.513,35.725,3.082,1,1,20.000,20.000,0.560,0.560,2
3755255230.812400,0,1,20.009,20.022,35.208,3.151,0,0,20.000,20.000,1.140,0.620,4
3755255380.812400,8076,2,19.999,19.995,35.044,4.210,0,0,20.000,20.000,0.770,0.430,4
3755255530.812400,23154,2,19.998,19.996,35.097,3.840,0,0,20.000,20.000,0.710,0.380,1
3755255680.812400,38080,2,20.001,19.992,35.160,3.720,0,0,20.000,20.000,0.700,0.400,1
3755255830.812400,53121,2,19.998,19.999,35.232,3.649,0,0,20.000,20.000,0.700,0.390,1
3755255980.812400,61880,2,20.002,20.002,35.319,3.423,0,0,20.000,20.000,0.680,0.370,1
3755256130.812400,70022,2,19.999,19.999,35.405,3.400,0,0,20.000,20.000,0.700,0.380,1
3755256280.812400,78099,2,19.999,19.995,35.497,3.382,0,0,20.000,20.000,0.700,0.400,1
3755256430.812400,86231,2,20.002,20.018,35.604,3.363,0,0,20.000,20.000,0.680,0.320,1
3755256580.812400,90000,1,19.995,19.987,35.729,3.197,0,0,20.000,20.000,0.710,0.420,1
3755256730.812400,82832,3,20.001,20.011,35.830,3.348,0,0,20.000,20.000,0.700,0.340,4
3755256880.812400,74690,3,20.001,20.004,35.873,3.375,0,0,20.000,20.000,0.680,0.360,1
3755257030.812400,66604,3,19.998,20.000,35.867,3.396,0,0,20.000,20.000,0.700,0.370,1
3755257180.812400,58440,3,19.999,19.994,35.832,3.413,0,0,20.000,20.000,0.690,0.380,1
3755257330.812400,47447,3,20.003,20.008,35.781,3.616,0,0,20.000,20.000,0.680,0.360,1
3755257480.812400,32401,3,20.002,20.009,35.714,3.708,0,0,20.000,20.000,0.670,0.350,1
3755257630.812400,17422,3,20.002,19.997,35.649,3.799,0,0,20.000,20.000,0.670,0.370,1
3755257780.812400,2402,3,19.999,19.995,35.590,4.011,0,0,20.000,20.000,0.670,0.370,1
3755257930.812400,-12342,3,19.999,20.003,35.545,4.075,0,0,20.000,20.000,0.670,0.360,1
3755258080.812400,-27369,3,20.001,20.007,35.540,3.795,0,0,20.000,20.000,0.660,0.360,1
3755258230.812400,-42346,3,20.000,20.001,35.543,3.696,0,0,20.000,20.000,0.680,0.380,1
3755258380.812400,-56096,3,19.999,20.008,35.566,3.536,0,0,20.000,20.000,0.690,0.350,1
3755258530.812400,-64176,3,20.001,20.005,35.613,3.413,0,0,20.000,20.000,0.700,0.360,1
3755258680.812400,-72253,3,20.002,20.005,35.665,3.395,0,0,20.000,20.000,0.670,0.370,1
3755258830.812400,-80414,3,19.998,20.002,35.731,3.376,0,0,20.000,20.000,0.680,0.360,1
3755258980.812400,-88539,3,20.003,20.002,35.820,3.360,0,0,20.000,20.000,0.670,0.360,1
3755259120.959400,-87518,4,20.002,19.990,35.920,3.270,0,0,20.000,20.000,0.680,0.380,1
3755259294.119400,-78109,2,20.003,19.993,35.989,3.367,0,0,20.000,20.000,0.680,0.390,1
3755259444.119400,-70032,2,19.997,20.007,35.990,3.387,0,0,20.000,20.000,0.700,0.360,1
3755259594.119400,-61926,2,20.004,20.014,35.955,3.406,0,0,20.000,20.000,0.650,0.310,1
3755259744.119400,-53648,2,20.001,19.994,35.900,3.430,0,0,20.000,20.000,0.670,0.380,1
3755259894.119400,-38751,2,20.002,20.005,35.827,3.675,0,0,20.000,20.000,0.670,0.350,1
3755260044.119400,-23825,2,20.001,19.997,35.750,3.753,0,0,20.000,20.000,0.670,0.380,1
3755260194.119400,-8852,2,20.000,20.005,35.678,3.892,0,0,20.000,20.000,0.670,0.350,1
3755260344.119400,6045,2,20.000,20.004,35.618,4.348,0,0,20.000,20.000,0.660,0.360,1
3755260494.119400,4804,3,19.998,19.994,35.599,3.657,0,0,20.000,20.000,0.670,0.380,1
3755260644.119400,-6996,3,20.002,20.007,35.552,3.861,0,0,20.000,20.000,0.660,0.340,1
3755260794.119400,4888,2,20.000,20.005,35.541,4.194,0,0,20.000,20.000,0.680,0.360,1
3755260944.119400,-2750,2,19.999,20.004,35.527,3.861,0,0,20.000,20.000,0.670,0.350,1
3755261094.119400,-1508,3,20.000,20.001,35.518,3.420,0,0,20.000,20.000,0.670,0.370,1
3755261244.119400,-771,3,19.999,19.994,35.503,3.202,0,0,20.000,20.000,0.690,0.390,1
3755261394.119400,-403,3,20.000,20.001,35.484,3.165,0,0,20.000,20.000,0.690,0.380,1
3755261544.119400,0,4,20.002,20.004,35.469,3.161,0,0,20.000,20.000,0.680,0.380,1
3755261694.119400,0,1,20.003,20.004,35.455,3.161,0,0,20.000,20.000,0.680,0.400,1
3755261844.119400,0,1,20.001,19.993,35.442,3.162,0,0,20.000,20.000,0.700,0.410,1
3755261994.119400,0,1,19.998,19.996,35.433,3.160,0,0,20.000,20.000,0.710,0.400,1
3755262144.119400,0,1,17.258,17.898,35.423,3.161,1,1,2.000,2.000,0.000,0.000,3
3755262294.119400,0,1,4.274,3.860,35.418,3.162,0,0,2.000,2.000,0.000,0.000,4
3755262444.119400,0,4,2.094,2.000,35.434,3.158,0,0,2.000,2.000,0.090,0.020,1
3755262594.119400,13528,2,2.035,2.000,35.464,3.978,0,0,2.000,2.000,0.000,0.020,1
3755262744.119400,28448,2,2.032,2.000,35.524,3.767,0,0,2.000,2.000,0.020,0.010,1
3755262894.119400,43536,2,2.049,2.000,35.583,3.666,0,0,2.000,2.000,0.040,0.010,1
3755263044.119400,56719,2,2.084,1.999,35.647,3.467,0,0,2.000,2.000,0.000,0.010,1
3755263194.119400,64811,2,2.100,2.000,35.719,3.368,0,0,2.000,2.000,0.000,0.010,1
3755263344.119400,72986,2,2.112,2.000,35.791,3.343,0,0,2.000,2.000,0.030,0.010,1
3755263494.119400,81067,2,2.126,1.999,35.872,3.320,0,0,2.000,2.000,0.000,0.010,1
3755263644.119400,89137,2,2.120,2.000,35.967,3.298,0,0,2.000,2.000,0.000,0.010,1
3755263794.119400,88131,3,2.120,2.000,36.077,3.172,0,0,2.000,2.000,0.000,0.010,1
3755263944.119400,80043,3,2.127,2.000,36.138,3.288,0,0,2.000,2.000,0.000,0.010,1
3755264094.119400,71870,3,2.135,2.000,36.139,3.308,0,0,2.000,2.000,0.040,0.010,1
3755264244.119400,63787,3,2.126,1.999,36.098,3.320,0,0,2.000,2.000,0.020,0.010,1
3755264394.119400,55682,3,2.144,2.000,36.038,3.336,0,0,2.000,2.000,0.130,0.010,1
3755264544.119400,42238,3,2.154,2.000,35.956,3.580,0,0,2.000,2.000,0.000,0.010,1
3755264694.119400,27307,3,2.140,2.000,35.865,3.662,0,0,2.000,2.000,0.020,0.020,1
3755264844.119400,12221,3,2.134,2.000,35.776,3.781,0,0,2.000,2.000,0.050,0.020,1
3755264994.119400,-2559,3,2.141,2.000,35.700,4.140,0,0,2.000,2.000,0.000,0.020,1
3755265144.119400,-17488,3,2.140,2.000,35.648,3.869,0,0,2.000,2.000,0.000,0.020,1
3755265294.119400,-32570,3,2.137,2.000,35.625,3.676,0,0,2.000,2.000,0.130,0.010,1
3755265444.119400,-47495,3,2.146,2.000,35.614,3.584,0,0,2.000,2.000,0.120,0.010,1
3755265594.119400,-58853,3,2.154,2.000,35.631,3.343,0,0,2.000,2.000,0.150,0.010,1
3755265744.119400,-66992,3,2.172,2.000,35.662,3.301,0,0,2.000,2.000,0.000,0.010,1
3755265894.119400,-75094,3,2.167,2.000,35.706,3.281,0,0,2.000,2.000,0.000,0.010,1
3755266044.119400,-83253,3,2.160,2.000,35.768,3.262,0,0,2.000,2.000,0.000,0.010,1
3755266194.119400,-90000,3,2.166,2.000,35.851,3.170,0,0,2.000,2.000,0.130,0.010,1
3755266344.119400,-83956,3,2.168,2.000,35.937,3.231,0,0,2.000,2.000,0.120,0.010,1
3755266494.119400,-75873,3,2.173,2.000,35.966,3.259,0,0,2.000,2.000,0.000,0.010,1
3755266644.119400,-67711,3,2.175,2.000,35.943,3.278,0,0,2.000,2.000,0.000,0.010,1
3755266794.119400,-59604,3,2.170,2.000,35.893,3.295,0,0,2.000,2.000,0.000,0.010,1
3755266944.119400,-49547,3,2.154,2.000,35.826,3.468,0,0,2.000,2.000,0.000,0.010,1
3755267094.119400,-34619,3,2.165,2.000,35.742,3.597,0,0,2.000,2.000,0.000,0.010,1
3755267244.119400,-19534,3,2.162,2.000,35.658,3.693,0,0,2.000,2.000,0.000,0.020,1
3755267394.119400,-9802,2,2.162,2.000,35.587,3.246,0,0,2.000,2.000,0.000,0.020,1
3755267544.119400,4855,2,2.165,2.001,35.518,4.275,0,0,2.000,2.000,0.000,0.020,1
3755267694.119400,-898,3,2.146,2.000,35.499,3.822,0,0,2.000,2.000,0.090,0.020,1
3755267844.119400,1133,2,2.143,2.000,35.467,3.630,0,0,2.000,2.000,0.000,0.020,1
3755267994.119400,-2401,2,2.155,2.000,35.437,3.297,0,0,2.000,2.000,0.000,0.020,1
3755268144.119400,-1170,3,2.168,1.999,35.414,3.089,0,0,2.000,2.000,0.000,0.020,1
3755268294.119400,-548,2,2.172,2.001,35.383,3.040,0,0,2.000,2.000,0.120,0.020,1
3755268444.119400,193,2,2.171,2.001,35.359,3.034,0,0,2.000,2.000,0.000,0.020,1
3755268594.119400,0,1,7.231,7.204,35.335,3.035,1,1,20.000,20.000,0.360,0.380,2
3755268744.119400,0,1,19.647,19.599,35.047,3.094,1,1,20.000,20.000,1.970,1.480,2
3755268894.119400,392,2,20.001,20.010,34.628,3.168,0,0,20.000,20.000,0.860,0.440,1
3755269044.119400,15249,2,19.999,19.986,34.709,3.957,0,0,20.000,20.000,0.720,0.400,1
3755269194.119400,30172,2,19.999,19.997,34.815,3.771,0,0,20.000,20.000,0.700,0.370,1
3755269344.119400,45152,2,20.001,19.996,34.917,3.681,0,0,20.000,20.000,0.700,0.380,1
3755269494.119400,57622,2,20.002,20.003,35.024,3.469,0,0,20.000,20.000,0.690,0.360,1
3755269644.119400,65742,2,20.001,20.003,35.134,3.408,0,0,20.000,20.000,0.700,0.360,1
3755269794.119400,73888,2,19.999,19.999,35.240,3.389,0,0,20.000,20.000,0.700,0.370,1
3755269944.119400,81998,2,20.001,20.002,35.356,3.370,0,0,20.000,20.000,0.680,0.370,1
3755270094.119400,89839,2,19.998,19.998,35.482,3.352,0,0,20.000,20.000,0.690,0.380,1
3755270244.119400,87439,3,19.996,19.991,35.620,3.266,0,0,20.000,20.000,0.720,0.410,1
3755270394.119400,79294,3,19.999,19.997,35.707,3.361,0,0,20.000,20.000,0.690,0.380,1
3755270544.119400,71183,3,20.001,20.002,35.734,3.384,0,0,20.000,20.000,0.680,0.350,1
3755270694.119400,63100,3,20.002,20.010,35.722,3.402,0,0,20.000,20.000,0.680,0.360,1
3755270844.119400,54937,3,19.999,20.000,35.691,3.422,0,0,20.000,20.000,0.680,0.390,1
3755270994.119400,40967,3,19.996,19.997,35.642,3.664,0,0,20.000,20.000,0.700,0.380,1
3755271144.119400,25984,3,20.004,20.015,35.583,3.742,0,0,20.000,20.000,0.670,0.360,1
3755271294.119400,10951,3,20.002,20.015,35.527,3.865,0,0,20.000,20.000,0.670,0.340,1
3755271444.119400,-3775,3,20.000,20.006,35.480,4.363,0,0,20.000,20.000,0.670,0.350,1
3755271594.119400,-18865,3,20.001,20.012,35.461,3.906,0,0,20.000,20.000,0.670,0.320,1
3755271744.119400,-33840,3,20.004,20.012,35.459,3.746,0,0,20.000,20.000,0.660,0.330,1
3755271894.119400,-48765,3,20.000,20.004,35.476,3.667,0,0,20.000,20.000,0.680,0.350,1
3755272044.119400,-59571,3,20.004,20.006,35.516,3.436,0,0,20.000,20.000,0.660,0.340,1
3755272194.119400,-67681,3,20.000,20.002,35.567,3.405,0,0,20.000,20.000,0.680,0.360,1
3755272344.119400,-75811,3,20.001,20.012,35.627,3.387,0,0,20.000,20.000,0.670,0.340,1
3755272494.119400,-83915,3,19.999,19.989,35.705,3.368,0,0,20.000,20.000,0.690,0.410,1
3755272644.119400,-90000,3,20.000,19.983,35.805,3.246,0,0,20.000,20.000,0.690,0.410,1
3755272794.119400,-83912,3,20.002,19.992,35.902,3.341,0,0,20.000,20.000,0.690,0.390,1
3755272944.119400,-75800,3,19.999,19.996,35.941,3.374,0,0,20.000,20.000,0.700,0.400,1
3755273094.119400,-67699,3,20.000,20.001,35.930,3.393,0,0,20.000,20.000,0.690,0.380,1
3755273244.119400,-59620,3,19.999,19.989,35.890,3.413,0,0,20.000,20.000,0.690,0.400,4
3755273394.119400,-49468,3,19.997,19.987,35.835,3.584,0,0,20.000,20.000,0.720,0.410,1
3755273544.119400,-34488,3,19.998,20.005,35.761,3.699,0,0,20.000,20.000,0.690,0.380,1
3755273694.119400,-19512,3,20.000,20.001,35.689,3.785,0,0,20.000,20.000,0.670,0.380,1
3755273844.119400,-9801,2,20.002,20.009,35.629,3.356,0,0,20.000,20.000,0.670,0.360,1
3755273994.119400,4683,2,19.999,19.992,35.573,4.380,0,0,20.000,20.000,0.670,0.390,1
3755274144.119400,-706,3,20.000,20.001,35.556,3.892,0,0,20.000,20.000,0.660,0.370,1
3755274294.119400,824,2,20.001,20.000,35.532,3.690,0,0,20.000,20.000,0.670,0.370,1
3755274444.119400,-2401,3,19.996,20.002,35.513,3.444,0,0,20.000,20.000,0.710,0.380,1
3755274594.119400,-1169,3,20.001,20.001,35.500,3.221,0,0,20.000,20.000,0.680,0.380,1
3755274744.119400,-577,2,20.000,20.005,35.479,3.168,0,0,20.000,20.000,0.680,0.370,1
3755274894.119400,194,2,19.999,20.002,35.460,3.164,0,0,20.000,20.000,0.700,0.370,1
3755275044.119400,0,1,14.845,15.325,35.446,3.162,1,1,2.000,2.000,0.000,0.000,3
3755275194.119400,0,1,3.219,2.835,35.436,3.162,1,1,2.000,2.000,0.000,0.000,3
3755275344.119400,0,1,6.962,6.922,35.451,3.158,1,1,300.000,300.000,0.540,0.460,2
3755275494.119400,0,1,31.785,31.777,35.398,3.161,1,1,300.000,300.000,6.970,4.560,2
3755275644.119400,0,1,56.522,56.516,35.373,3.161,1,1,300.000,300.000,22.800,14.310,2
3755275794.119400,0,1,81.317,81.257,35.382,3.161,1,1,300.000,300.000,38.250,23.800,2
3755275944.119400,0,1,106.103,106.076,35.418,3.162,1,1,300.000,300.000,50.460,32.140,2
3755276094.119400,0,1,130.869,130.834,35.476,3.165,1,1,300.000,300.000,60.500,39.060,2
3755276244.119400,0,1,155.795,155.766,35.549,3.167,1,1,300.000,300.000,68.800,45.170,2
3755276394.119400,0,1,180.574,180.547,35.634,3.169,1,1,300.000,300.000,75.720,50.550,2
3755276544.119400,0,1,205.335,205.311,35.726,3.170,1,1,300.000,300.000,82.160,55.490,2
3755276694.119400,0,1,230.091,230.062,35.823,3.172,1,1,300.000,300.000,88.160,60.220,2
3755276844.119400,0,1,253.788,254.802,35.925,3.173,1,1,300.000,300.000,87.370,65.560,2
3755276994.119400,0,1,275.161,279.727,36.029,3.173,1,1,300.000,300.000,90.450,70.870,2
3755277144.119400,0,1,294.296,301.399,36.133,3.177,0,0,300.000,300.000,85.520,49.010,4
3755277294.119400,0,1,300.208,300.050,36.234,3.173,0,0,300.000,300.000,84.510,35.050,4
3755277444.119400,0,1,299.817,300.027,36.316,3.173,0,0,300.000,300.000,15.130,32.380,4
3755277594.119400,0,1,300.314,300.008,36.391,3.172,0,0,300.000,300.000,72.220,31.060,1
3755277744.119400,0,1,299.655,300.017,36.469,3.172,0,0,300.000,300.000,17.490,29.720,1
3755277894.119400,0,1,300.531,300.007,36.543,3.172,0,0,300.000,300.000,61.860,28.880,1
3755278044.119400,0,1,299.467,300.012,36.620,3.173,0,0,300.000,300.000,20.700,27.770,1
3755278194.119400,0,1,300.564,300.005,36.697,3.172,0,0,300.000,300.000,54.630,26.990,1
3755278344.119400,0,1,299.455,300.012,36.778,3.174,0,0,300.000,300.000,22.190,26.080,1
3755278494.119400,0,1,300.555,300.006,36.858,3.172,0,0,300.000,300.000,48.540,25.420,1
3755278644.119400,0,1,299.413,300.010,36.935,3.173,0,0,300.000,300.000,24.150,24.590,1
3755278794.119400,0,1,300.570,300.003,37.011,3.173,0,0,300.000,300.000,42.710,24.030,1
3755278944.119400,0,1,299.474,300.011,37.085,3.176,0,0,300.000,300.000,24.620,23.300,1
3755279094.119400,0,1,300.512,300.006,37.161,3.174,0,0,300.000,300.000,38.840,22.750,1
3755279244.119400,0,1,299.532,300.008,37.235,3.177,0,0,300.000,300.000,24.620,22.120,1
3755279394.119400,0,1,300.483,300.002,37.307,3.177,0,0,300.000,300.000,35.010,21.580,1
3755279544.119400,0,1,299.562,300.007,37.376,3.176,0,0,300.000,300.000,25.060,20.990,1
3755279694.119400,0,1,300.415,300.008,37.442,3.178,0,0,300.000,300.000,32.530,20.540,1
3755279844.119400,0,1,299.629,300.006,37.510,3.179,0,0,300.000,300.000,24.490,20.020,1
3755279994.119400,0,1,300.351,300.002,37.577,3.179,0,0,300.000,300.000,30.390,19.630,1
3755280144.119400,0,1,299.669,300.008,37.644,3.179,0,0,300.000,300.000,24.350,19.170,1
3755280294.119400,0,1,300.311,300.002,37.710,3.179,0,0,300.000,300.000,28.320,18.810,1
3755280444.119400,0,1,299.723,300.004,37.779,3.180,0,0,300.000,300.000,23.640,18.410,1
3755280594.119400,0,1,300.260,300.002,37.844,3.182,0,0,300.000,300.000,26.930,18.060,1
3755280744.119400,0,1,299.756,300.004,37.909,3.181,0,0,300.000,300.000,23.380,17.680,1
3755280894.119400,0,1,300.229,300.002,37.975,3.184,0,0,300.000,300.000,25.330,17.360,1
3755281044.119400,0,1,299.796,300.005,38.040,3.184,0,0,300.000,300.000,22.730,17.120,1
3755281194.119400,0,1,300.190,300.003,38.104,3.185,0,0,300.000,300.000,24.320,16.780,1
3755281344.119400,0,1,299.823,300.004,38.169,3.185,0,0,300.000,300.000,22.190,16.510,1
3755281494.119400,0,1,300.163,300.002,38.233,3.187,0,0,300.000,300.000,23.210,16.230,1
3755281644.119400,0,1,299.853,300.002,38.294,3.187,0,0,300.000,300.000,21.560,15.940,1
3755281794.119400,0,1,300.135,300.002,38.355,3.188,0,0,300.000,300.000,22.470,15.740,1
3755281944.119400,0,1,299.878,300.005,38.417,3.189,0,0,300.000,300.000,21.110,15.510,1
3755282094.119400,0,1,300.115,300.000,38.478,3.189,0,0,300.000,300.000,21.660,15.290,1
3755282244.119400,0,1,299.897,300.001,38.537,3.190,0,0,300.000,300.000,20.520,15.110,1
3755282394.119400,0,1,300.098,300.002,38.597,3.190,0,0,300.000,300.000,21.060,14.880,1
3755282544.119400,0,1,299.914,300.002,38.654,3.194,0,0,300.000,300.000,20.180,14.710,1
3755282694.119400,0,1,300.080,300.001,38.711,3.194,0,0,300.000,300.000,20.430,14.570,1
3755282844.119400,0,1,299.928,300.004,38.769,3.195,0,0,300.000,300.000,19.690,14.330,1
3755282994.119400,0,1,300.067,300.002,38.829,3.195,0,0,300.000,300.000,19.960,14.170,1
3755283144.119400,0,1,299.941,300.003,38.884,3.196,0,0,300.000,300.000,19.390,14.020,1
3755283294.119400,0,1,300.053,300.001,38.938,3.197,0,0,300.000,300.000,19.430,13.880,1
3755283444.119400,0,1,299.953,300.001,38.991,3.197,0,0,300.000,300.000,18.990,13.730,1
3755283594.119400,0,1,300.044,300.003,39.043,3.198,0,0,300.000,300.000,19.020,13.610,1
3755283744.119400,0,1,299.963,300.002,39.096,3.198,0,0,300.000,300.000,18.630,13.440,1
3755283894.119400,0,1,300.034,300.000,39.149,3.199,0,0,300.000,300.000,18.690,13.370,1
3755284044.119400,0,1,299.970,300.000,39.203,3.200,0,0,300.000,300.000,18.220,13.210,1
3755284194.119400,0,1,300.026,300.000,39.256,3.200,0,0,300.000,300.000,18.370,13.080,1
3755284344.119400,0,1,299.981,300.002,39.309,3.202,0,0,300.000,300.000,17.930,12.990,1
3755284494.119400,0,1,300.017,299.999,39.359,3.202,0,0,300.000,300.000,18.120,12.900,1
3755284644.119400,0,1,299.986,300.001,39.409,3.201,0,0,300.000,300.000,17.680,12.770,1
3755284794.119400,0,1,300.013,300.000,39.452,3.203,0,0,300.000,300.000,17.870,12.670,1
3755284944.119400,0,1,299.987,299.999,39.498,3.202,0,0,300.000,300.000,17.370,12.580,1
3755285094.119400,0,1,300.014,300.001,39.546,3.203,0,0,300.000,300.000,17.570,12.530,1
3755285244.119400,0,1,299.988,300.001,39.592,3.203,0,0,300.000,300.000,17.240,12.380,1
3755285394.119400,0,1,300.011,300.002,39.637,3.203,0,0,300.000,300.000,17.280,12.340,1
3755285544.119400,0,1,299.992,300.000,39.682,3.204,0,0,300.000,300.000,16.990,12.250,1
3755285694.119400,0,1,300.010,299.999,39.727,3.205,0,0,300.000,300.000,16.990,12.160,1
3755285844.119400,0,1,299.990,300.000,39.771,3.205,0,0,300.000,300.000,16.850,12.130,1
3755285994.119400,0,1,300.009,300.004,39.814,3.207,0,0,300.000,300.000,16.830,12.020,1
3755286144.119400,0,1,299.989,299.999,39.854,3.207,0,0,300.000,300.000,16.670,11.980,1
3755286294.119400,0,1,300.010,300.000,39.898,3.207,0,0,300.000,300.000,16.690,11.890,1
3755286444.119400,0,1,299.993,299.999,39.940,3.205,0,0,300.000,300.000,16.430,11.840,1
3755286594.119400,0,1,300.009,300.003,39.979,3.207,0,0,300.000,300.000,16.490,11.770,1
3755286744.119400,0,1,299.993,300.000,40.017,3.208,0,0,300.000,300.000,16.310,11.720,1
3755286894.119400,0,1,300.005,299.999,40.058,3.208,0,0,300.000,300.000,16.310,11.640,1
3755287044.119400,0,1,299.998,300.001,40.099,3.210,0,0,300.000,300.000,16.170,11.590,1
3755287194.119400,0,1,300.002,300.000,40.135,3.209,0,0,300.000,300.000,16.150,11.540,1
3755287344.119400,0,1,300.000,299.999,40.173,3.209,0,0,300.000,300.000,16.030,11.490,1
3755287494.119400,0,1,300.001,300.001,40.210,3.210,0,0,300.000,300.000,16.010,11.450,1
3755287644.119400,0,1,300.000,300.000,40.246,3.209,0,0,300.000,300.000,15.950,11.420,1
3755287794.119400,0,1,300.001,300.001,40.283,3.209,0,0,300.000,300.000,15.950,11.380,1
3755287944.119400,0,1,300.002,300.000,40.316,3.210,0,0,300.000,300.000,15.790,11.290,1
3755288094.119400,0,1,300.000,300.000,40.351,3.210,0,0,300.000,300.000,15.770,11.240,1
3755288244.119400,0,1,300.000,300.001,40.382,3.211,0,0,300.000,300.000,15.730,11.240,1
3755288394.119400,0,1,299.999,300.001,40.411,3.212,0,0,300.000,300.000,15.630,11.170,1
3755288544.119400,0,1,299.996,300.001,40.443,3.213,0,0,300.000,300.000,15.630,11.150,1
3755288694.119400,0,1,300.003,300.000,40.477,3.212,0,0,300.000,300.000,15.570,11.100,1
3755288844.119400,0,1,299.995,299.998,40.507,3.212,0,0,300.000,300.000,15.530,11.070,1
3755288994.119400,0,1,300.001,299.999,40.535,3.215,0,0,300.000,300.000,15.480,11.030,1
3755289144.119400,0,1,300.001,299.998,40.564,3.213,0,0,300.000,300.000,15.420,11.020,1
3755289294.119400,0,1,300.002,300.000,40.589,3.214,0,0,300.000,300.000,15.420,10.970,1
3755289444.119400,0,1,299.998,300.000,40.618,3.214,0,0,300.000,300.000,15.340,10.970,1
3755289594.119400,0,1,300.003,300.000,40.647,3.214,0,0,300.000,300.000,15.260,10.950,1
3755289744.119400,0,1,299.994,300.003,40.674,3.214,0,0,300.000,300.000,15.340,10.900,1
3755289894.119400,0,1,300.004,300.003,40.703,3.215,0,0,300.000,300.000,15.220,10.860,1
3755290044.119400,0,1,299.995,300.002,40.730,3.213,0,0,300.000,300.000,15.260,10.850,1
3755290194.119400,0,1,300.002,300.000,40.755,3.216,0,0,300.000,300.000,15.220,10.830,1
3755290344.119400,0,1,299.996,299.999,40.781,3.215,0,0,300.000,300.000,15.130,10.790,1
3755290494.119400,0,1,300.005,300.000,40.805,3.215,0,0,300.000,300.000,15.130,10.760,1
3755290644.119400,0,1,299.997,300.000,40.828,3.217,0,0,300.000,300.000,15.050,10.740,1
3755290794.119400,0,1,299.999,300.000,40.849,3.217,0,0,300.000,300.000,15.070,10.760,1
3755290944.119400,0,1,299.999,300.001,40.871,3.216,0,0,300.000,300.000,15.070,10.730,1
3755291094.119400,0,1,299.998,300.000,40.891,3.217,0,0,300.000,300.000,14.950,10.680,1
3755291244.119400,0,1,300.002,300.000,40.914,3.216,0,0,300.000,300.000,14.990,10.660,1
3755291394.119400,0,1,299.998,299.999,40.934,3.217,0,0,300.000,300.000,14.930,10.660,1
3755291544.119400,0,1,300.000,299.998,40.957,3.216,0,0,300.000,300.000,14.930,10.620,1
3755291694.119400,0,1,299.997,300.000,40.979,3.217,0,0,300.000,300.000,14.860,10.610,1
3755291844.119400,0,1,300.002,300.000,41.001,3.217,0,0,300.000,300.000,14.890,10.610,1
3755291994.119400,0,1,299.998,300.000,41.022,3.217,0,0,300.000,300.000,14.840,10.610,1
3755292144.119400,0,1,300.002,300.000,41.043,3.218,0,0,300.000,300.000,14.820,10.570,1
3755292294.119400,0,1,299.999,299.998,41.062,3.217,0,0,300.000,300.000,14.820,10.560,1
3755292444.119400,0,1,300.002,299.999,41.081,3.218,0,0,300.000,300.000,14.780,10.540,1
3755292594.119400,0,1,299.999,300.000,41.099,3.218,0,0,300.000,300.000,14.760,10.510,1
3755292744.119400,0,1,299.999,299.998,41.114,3.219,0,0,300.000,300.000,14.740,10.520,1
3755292894.119400,0,1,300.000,300.002,41.134,3.220,0,0,300.000,300.000,14.680,10.490,1
3755293044.119400,0,1,300.000,300.001,41.155,3.219,0,0,300.000,300.000,14.760,10.490,1
3755293194.119400,0,1,299.999,300.001,41.173,3.219,0,0,300.000,300.000,14.630,10.490,1
3755293344.119400,0,1,299.999,300.001,41.191,3.218,0,0,300.000,300.000,14.760,10.470,1
3755293494.119400,0,1,300.002,300.001,41.207,3.218,0,0,300.000,300.000,14.610,10.440,1
3755293644.119400,0,1,300.001,299.997,41.219,3.219,0,0,300.000,300.000,14.650,10.420,1
3755293794.119400,0,1,300.001,299.998,41.231,3.219,0,0,300.000,300.000,14.570,10.410,1
3755293944.119400,0,1,300.001,299.999,41.242,3.220,0,0,300.000,300.000,14.670,10.420,1
3755294094.119400,0,1,299.997,300.000,41.253,3.218,0,0,300.000,300.000,14.570,10.410,1
3755294244.119400,0,1,299.999,299.999,41.261,3.219,0,0,300.000,300.000,14.680,10.370,1
3755294394.119400,0,1,300.002,300.000,41.271,3.222,0,0,300.000,300.000,14.550,10.370,1
3755294544.119400,0,1,299.998,299.998,41.281,3.221,0,0,300.000,300.000,14.650,10.390,1
3755294694.119400,0,1,300.000,299.998,41.291,3.219,0,0,300.000,300.000,14.510,10.370,1
3755294844.119400,0,1,300.000,299.999,41.299,3.220,0,0,300.000,300.000,14.590,10.340,1
3755294994.119400,0,1,300.000,300.000,41.309,3.221,0,0,300.000,300.000,14.500,10.340,1
3755295144.119400,0,1,299.997,299.999,41.315,3.221,0,0,300.000,300.000,14.570,10.360,1
3755295294.119400,0,1,300.001,300.000,41.323,3.223,0,0,300.000,300.000,14.480,10.320,1
3755295444.119400,0,1,300.002,300.000,41.332,3.222,0,0,300.000,300.000,14.630,10.320,1
3755295594.119400,0,1,299.998,300.000,41.347,3.221,0,0,300.000,300.000,14.380,10.310,1
3755295744.119400,0,1,300.001,300.001,41.357,3.221,0,0,300.000,300.000,14.550,10.310,1
3755295894.119400,0,1,299.999,299.999,41.366,3.222,0,0,300.000,300.000,14.360,10.290,1
3755296044.119400,0,1,300.003,299.999,41.376,3.222,0,0,300.000,300.000,14.480,10.290,1
3755296194.119400,0,1,299.996,300.000,41.386,3.221,0,0,300.000,300.000,14.440,10.270,1
3755296344.119400,0,1,300.004,299.999,41.394,3.222,0,0,300.000,300.000,14.460,10.260,1
3755296494.119400,0,1,299.996,299.999,41.404,3.221,0,0,300.000,300.000,14.380,10.270,1
3755296644.119400,0,1,300.004,299.997,41.413,3.222,0,0,300.000,300.000,14.400,10.260,1
3755296794.119400,0,1,299.997,300.000,41.424,3.223,0,0,300.000,300.000,14.380,10.260,1
3755296944.119400,0,1,300.003,299.999,41.435,3.223,0,0,300.000,300.000,14.440,10.260,1
3755297094.119400,0,1,299.998,300.000,41.444,3.222,0,0,300.000,300.000,14.360,10.240,1
3755297244.119400,0,1,299.999,300.000,41.453,3.225,0,0,300.000,300.000,14.420,10.220,1
3755297394.119400,0,1,300.000,300.001,41.462,3.224,0,0,300.000,300.000,14.400,10.260,1
3755297544.119400,0,1,299.998,299.998,41.471,3.223,0,0,300.000,300.000,14.360,10.210,1
3755297694.119400,0,1,300.004,300.001,41.482,3.223,0,0,300.000,300.000,14.330,10.210,1
3755297844.119400,0,1,299.998,300.000,41.491,3.224,0,0,300.000,300.000,14.360,10.210,1
3755297994.119400,0,1,300.002,300.001,41.501,3.223,0,0,300.000,300.000,14.340,10.190,1
3755298144.119400,0,1,300.000,299.999,41.509,3.224,0,0,300.000,300.000,14.330,10.220,1
3755298294.119400,0,1,300.004,299.999,41.518,3.223,0,0,300.000,300.000,14.330,10.210,1
3755298444.119400,0,1,299.998,299.999,41.525,3.223,0,0,300.000,300.000,14.290,10.190,1
3755298594.119400,0,1,300.002,300.000,41.532,3.223,0,0,300.000,300.000,14.310,10.210,1
3755298744.119400,0,1,299.997,300.000,41.539,3.224,0,0,300.000,300.000,14.290,10.160,1
3755298894.119400,0,1,300.002,300.001,41.547,3.224,0,0,300.000,300.000,14.330,10.160,1
3755299044.119400,0,1,299.999,300.000,41.556,3.223,0,0,300.000,300.000,14.250,10.160,1
3755299194.119400,0,1,300.003,300.002,41.563,3.224,0,0,300.000,300.000,14.310,10.170,1
3755299344.119400,0,1,299.999,300.002,41.572,3.223,0,0,300.000,300.000,14.270,10.160,1
3755299494.119400,0,1,299.999,300.000,41.578,3.224,0,0,300.000,300.000,14.290,10.140,1
3755299644.119400,0,1,299.999,300.001,41.584,3.224,0,0,300.000,300.000,14.210,10.160,1
3755299794.119400,0,1,300.001,300.001,41.591,3.224,0,0,300.000,300.000,14.310,10.140,1
3755299944.119400,0,1,299.995,299.999,41.597,3.224,0,0,300.000,300.000,14.210,10.160,1
3755300094.119400,0,1,300.005,300.000,41.603,3.225,0,0,300.000,300.000,14.290,10.140,1
3755300244.119400,0,1,299.997,299.998,41.609,3.225,0,0,300.000,300.000,14.230,10.160,1
3755300394.119400,0,1,300.005,300.003,41.615,3.224,0,0,300.000,300.000,14.210,10.140,1
3755300544.119400,0,1,299.995,299.998,41.620,3.224,0,0,300.000,300.000,14.330,10.160,1
3755300694.119400,0,1,300.005,300.000,41.626,3.225,0,0,300.000,300.000,14.210,10.120,1
3755300844.119400,0,1,299.998,300.002,41.632,3.224,0,0,300.000,300.000,14.210,10.120,1
3755300994.119400,0,1,300.001,300.000,41.637,3.223,0,0,300.000,300.000,14.290,10.110,1
3755301144.119400,0,1,299.996,300.000,41.645,3.224,0,0,300.000,300.000,14.230,10.110,1
3755301294.119400,0,1,300.002,299.999,41.649,3.224,0,0,300.000,300.000,14.230,10.110,1
3755301444.119400,0,1,299.999,299.999,41.654,3.224,0,0,300.000,300.000,14.180,10.140,1
3755301594.119400,0,1,299.999,299.998,41.659,3.224,0,0,300.000,300.000,14.250,10.060,1
3755301744.119400,0,1,300.003,300.001,41.663,3.225,0,0,300.000,300.000,14.160,10.060,1
3755301894.119400,0,1,299.997,299.998,41.666,3.225,0,0,300.000,300.000,14.250,10.090,1
3755302044.119400,0,1,300.001,300.000,41.670,3.224,0,0,300.000,300.000,14.160,10.090,1
3755302194.119400,0,1,299.995,300.001,41.674,3.225,0,0,300.000,300.000,14.230,10.090,1
3755302344.119400,0,1,300.003,299.997,41.675,3.227,0,0,300.000,300.000,14.190,10.090,1
3755302494.119400,0,1,299.995,300.000,41.677,3.228,0,0,300.000,300.000,14.230,10.090,1
3755302644.119400,0,1,300.004,300.001,41.680,3.228,0,0,300.000,300.000,14.140,10.090,1
3755302794.119400,0,1,299.992,300.003,41.684,3.228,0,0,300.000,300.000,14.230,10.090,1
3755302944.119400,0,1,300.006,300.001,41.689,3.225,0,0,300.000,300.000,14.140,10.070,1
3755303094.119400,0,1,299.990,299.999,41.693,3.226,0,0,300.000,300.000,14.230,10.090,1
3755303244.119400,0,1,300.007,299.999,41.698,3.227,0,0,300.000,300.000,14.030,10.090,1
3755303394.119400,0,1,299.990,299.998,41.703,3.226,0,0,300.000,300.000,14.230,10.060,1
3755303544.119400,0,1,300.009,300.000,41.709,3.226,0,0,300.000,300.000,14.080,10.070,1
3755303694.119400,0,1,299.988,300.001,41.715,3.226,0,0,300.000,300.000,14.250,10.070,1
3755303844.119400,0,1,300.011,299.999,41.720,3.226,0,0,300.000,300.000,14.140,10.090,1
3755303994.119400,0,1,299.992,300.000,41.725,3.226,0,0,300.000,300.000,14.210,10.070,1
3755304144.119400,0,1,300.005,300.000,41.728,3.227,0,0,300.000,300.000,14.140,10.070,1
3755304294.119400,0,1,299.994,300.000,41.731,3.226,0,0,300.000,300.000,14.140,10.040,1
3755304444.119400,0,1,300.005,299.998,41.735,3.226,0,0,300.000,300.000,14.230,10.070,1
3755304594.119400,0,1,299.997,300.000,41.738,3.226,0,0,300.000,300.000,14.140,10.070,1
3755304744.119400,0,1,300.002,300.003,41.742,3.227,0,0,300.000,300.000,14.190,10.040,1
3755304894.119400,0,1,299.998,299.999,41.745,3.225,0,0,300.000,300.000,14.100,10.070,1
3755305044.119400,0,1,300.000,300.000,41.748,3.226,0,0,300.000,300.000,14.210,10.070,1
3755305194.119400,0,1,299.998,300.000,41.751,3.227,0,0,300.000,300.000,14.100,10.040,1
3755305344.119400,0,1,300.002,299.999,41.752,3.227,0,0,300.000,300.000,14.140,10.060,1
3755305494.119400,0,1,299.997,299.999,41.755,3.228,0,0,300.000,300.000,14.140,10.040,1
3755305644.119400,0,1,300.002,300.000,41.757,3.228,0,0,300.000,300.000,14.140,10.060,1
3755305794.119400,0,1,299.997,299.998,41.761,3.226,0,0,300.000,300.000,14.100,10.040,1
3755305944.119400,0,1,300.003,299.998,41.764,3.227,0,0,300.000,300.000,14.140,10.070,1
3755306094.119400,0,1,300.001,300.001,41.767,3.228,0,0,300.000,300.000,14.080,10.060,1
3755306244.119400,0,1,299.998,300.000,41.770,3.229,0,0,300.000,300.000,14.140,9.990,1
3755306394.119400,0,1,300.002,299.999,41.773,3.230,0,0,300.000,300.000,14.120,10.040,1
3755306544.119400,0,1,299.998,299.999,41.775,3.230,0,0,300.000,300.000,14.120,10.030,1
3755306694.119400,0,1,299.999,300.000,41.773,3.230,0,0,300.000,300.000,14.060,10.030,1
3755306844.119400,0,1,300.002,299.999,41.772,3.230,0,0,300.000,300.000,14.160,10.030,1
3755306994.119400,0,1,299.997,300.001,41.775,3.230,0,0,300.000,300.000,14.140,10.060,1
3755307144.119400,0,1,300.002,300.000,41.780,3.228,0,0,300.000,300.000,14.080,10.030,1
3755307294.119400,0,1,299.995,300.001,41.785,3.227,0,0,300.000,300.000,14.210,10.060,1
3755307444.119400,0,1,300.003,300.000,41.786,3.228,0,0,300.000,300.000,14.100,10.040,1
3755307594.119400,0,1,299.996,299.998,41.791,3.228,0,0,300.000,300.000,14.140,10.030,1
3755307744.119400,0,1,300.004,300.001,41.792,3.227,0,0,300.000,300.000,14.060,10.060,1
3755307894.119400,0,1,299.994,299.998,41.794,3.227,0,0,300.000,300.000,14.160,10.030,1
3755308044.119400,0,1,300.005,299.999,41.796,3.228,0,0,300.000,300.000,14.030,10.030,1
3755308194.119400,0,1,299.992,299.998,41.799,3.228,0,0,300.000,300.000,14.140,10.030,1
3755308344.119400,0,1,300.004,300.000,41.799,3.230,0,0,300.000,300.000,14.120,10.030,1
3755308494.119400,0,1,299.995,300.002,41.800,3.230,0,0,300.000,300.000,14.100,10.060,1
3755308644.119400,0,1,300.004,299.999,41.805,3.228,0,0,300.000,300.000,14.060,10.010,1
3755308794.119400,0,1,299.993,300.000,41.810,3.228,0,0,300.000,300.000,14.160,10.030,1
3755308944.119400,0,1,300.003,300.001,41.813,3.230,0,0,300.000,300.000,14.030,10.030,1
3755309094.119400,0,1,299.994,299.998,41.815,3.230,0,0,300.000,300.000,14.140,10.040,1
3755309244.119400,0,1,300.004,299.999,41.816,3.228,0,0,300.000,300.000,14.060,10.040,1
3755309394.119400,0,1,299.995,300.000,41.819,3.228,0,0,300.000,300.000,14.140,10.030,1
3755309544.119400,0,1,300.001,300.000,41.820,3.227,0,0,300.000,300.000,14.080,10.060,1
3755309694.119400,0,1,299.998,299.998,41.820,3.227,0,0,300.000,300.000,14.080,10.060,1
3755309844.119400,0,1,300.002,299.999,41.823,3.227,0,0,300.000,300.000,14.140,10.030,1
3755309994.119400,0,1,300.000,300.001,41.823,3.227,0,0,300.000,300.000,14.060,10.040,1
3755310144.119400,0,1,300.001,299.999,41.826,3.227,0,0,300.000,300.000,14.160,10.030,1
3755310294.119400,0,1,300.001,299.999,41.829,3.227,0,0,300.000,300.000,14.050,10.030,1
3755310444.119400,0,1,299.999,300.000,41.830,3.229,0,0,300.000,300.000,14.080,10.030,1
3755310594.119400,0,1,300.002,299.998,41.833,3.227,0,0,300.000,300.000,14.100,10.040,1
3755310744.119400,0,1,299.998,299.998,41.832,3.229,0,0,300.000,300.000,14.080,10.030,1
3755310894.119400,0,1,300.000,300.001,41.835,3.229,0,0,300.000,300.000,14.080,9.990,1
3755311044.119400,0,1,299.998,299.998,41.837,3.228,0,0,300.000,300.000,14.120,10.030,1
3755311194.119400,0,1,300.003,300.000,41.839,3.228,0,0,300.000,300.000,14.060,10.030,1
3755311344.119400,0,1,299.998,300.000,41.840,3.228,0,0,300.000,300.000,14.180,10.010,1
3755311494.119400,0,1,300.002,300.000,41.842,3.228,0,0,300.000,300.000,14.030,10.030,1
3755311644.119400,0,1,299.997,300.000,41.844,3.227,0,0,300.000,300.000,14.140,10.040,1
3755311794.119400,0,1,300.000,300.002,41.845,3.228,0,0,300.000,300.000,14.010,10.040,1
3755311944.119400,0,1,299.999,300.001,41.846,3.228,0,0,300.000,300.000,14.140,10.040,1
3755312094.119400,0,1,300.003,300.000,41.848,3.227,0,0,300.000,300.000,14.050,10.040,1
3755312244.119400,0,1,300.000,300.000,41.848,3.227,0,0,300.000,300.000,14.060,10.040,1
3755312394.119400,0,1,300.001,300.000,41.848,3.230,0,0,300.000,300.000,14.080,10.010,1
3755312544.119400,0,1,300.000,300.000,41.849,3.228,0,0,300.000,300.000,14.080,10.030,1
3755312694.119400,0,1,300.000,300.000,41.850,3.228,0,0,300.000,300.000,14.080,9.990,1
3755312844.119400,0,1,299.998,300.001,41.850,3.229,0,0,300.000,300.000,14.060,10.010,1
3755312994.119400,0,1,300.002,300.000,41.849,3.229,0,0,300.000,300.000,14.120,10.030,1
3755313144.119400,0,1,299.999,300.000,41.849,3.229,0,0,300.000,300.000,14.080,10.010,1
3755313294.119400,0,1,300.005,300.001,41.846,3.230,0,0,300.000,300.000,14.100,10.010,1
3755313444.119400,0,1,299.996,300.000,41.846,3.229,0,0,300.000,300.000,14.080,10.010,1
3755313594.119400,0,1,300.005,299.998,41.848,3.228,0,0,300.000,300.000,14.050,10.030,1
3755313744.119400,0,1,299.995,300.000,41.852,3.228,0,0,300.000,300.000,14.100,10.010,1
3755313894.119400,0,1,300.006,299.998,41.855,3.226,0,0,300.000,300.000,14.080,10.030,1
3755314044.119400,0,1,299.996,299.999,41.856,3.227,0,0,300.000,300.000,14.100,10.010,1
3755314194.119400,0,1,300.004,300.000,41.858,3.228,0,0,300.000,300.000,14.080,10.030,1
3755314344.119400,0,1,299.998,300.001,41.855,3.229,0,0,300.000,300.000,14.100,10.030,1
3755314494.119400,0,1,300.003,299.999,41.855,3.229,0,0,300.000,300.000,14.120,10.030,1
3755314644.119400,0,1,300.000,300.001,41.857,3.228,0,0,300.000,300.000,14.050,10.030,1
3755314794.119400,0,1,299.998,299.998,41.855,3.229,0,0,300.000,300.000,14.140,10.010,1
3755314944.119400,0,1,300.000,300.001,41.855,3.228,0,0,300.000,300.000,14.030,10.040,1
3755315094.119400,0,1,300.000,299.999,41.855,3.227,0,0,300.000,300.000,14.120,10.010,1
3755315244.119400,0,1,300.004,300.001,41.856,3.229,0,0,300.000,300.000,14.050,10.010,1
3755315394.119400,0,1,299.996,300.000,41.856,3.227,0,0,300.000,300.000,14.160,10.040,1
3755315544.119400,0,1,300.001,300.002,41.858,3.227,0,0,300.000,300.000,14.140,10.030,1
3755315694.119400,0,1,299.998,300.000,41.857,3.228,0,0,300.000,300.000,14.100,10.010,1
3755315844.119400,0,1,300.001,299.998,41.854,3.229,0,0,300.000,300.000,14.060,10.010,1
3755315994.119400,0,1,299.998,299.999,41.856,3.227,0,0,300.000,300.000,14.080,10.040,1
3755316144.119400,0,1,300.001,300.000,41.856,3.227,0,0,300.000,300.000,14.060,10.030,1
3755316294.119400,0,1,300.000,299.999,41.859,3.226,0,0,300.000,300.000,14.120,9.990,1
3755316444.119400,0,1,300.001,299.999,41.859,3.227,0,0,300.000,300.000,14.010,10.030,1
3755316594.119400,0,1,300.000,299.999,41.859,3.227,0,0,300.000,300.000,14.060,10.030,1
3755316744.119400,0,1,299.997,299.998,41.858,3.227,0,0,300.000,300.000,14.080,10.010,1
3755316894.119400,0,1,300.002,299.998,41.860,3.227,0,0,300.000,300.000,14.060,10.040,1
3755317044.119400,0,1,299.997,300.002,41.859,3.227,0,0,300.000,300.000,14.190,10.010,1
3755317194.119400,0,1,300.003,299.999,41.859,3.226,0,0,300.000,300.000,14.030,10.010,1
3755317344.119400,0,1,299.999,300.002,41.858,3.226,0,0,300.000,300.000,14.140,10.010,1
3755317494.119400,0,1,300.001,300.001,41.859,3.225,0,0,300.000,300.000,14.030,10.010,1
3755317644.119400,0,1,300.001,299.999,41.859,3.225,0,0,300.000,300.000,14.140,10.030,1
3755317794.119400,0,1,299.995,299.998,41.858,3.226,0,0,300.000,300.000,14.050,10.010,1
3755317944.119400,0,1,300.002,299.998,41.858,3.225,0,0,300.000,300.000,14.140,10.030,1
3755318094.119400,0,1,300.000,300.002,41.861,3.225,0,0,300.000,300.000,14.010,10.030,1
3755318244.119400,0,1,300.000,300.000,41.861,3.225,0,0,300.000,300.000,14.160,10.040,1
3755318394.119400,0,1,300.000,300.000,41.858,3.229,0,0,300.000,300.000,14.050,10.030,1
3755318544.119400,0,1,299.998,299.999,41.858,3.228,0,0,300.000,300.000,14.100,10.040,1
3755318694.119400,0,1,300.001,300.000,41.861,3.227,0,0,300.000,300.000,14.030,10.030,1
3755318844.119400,0,1,300.000,300.001,41.862,3.229,0,0,300.000,300.000,14.160,10.010,1
3755318994.119400,0,1,299.998,299.998,41.865,3.227,0,0,300.000,300.000,13.990,10.030,1
3755319144.119400,0,1,300.005,299.999,41.866,3.228,0,0,300.000,300.000,14.160,10.010,1
3755319294.119400,0,1,299.996,300.000,41.864,3.228,0,0,300.000,300.000,14.050,10.040,1
3755319444.119400,0,1,299.999,300.001,41.867,3.226,0,0,300.000,300.000,14.120,10.040,1
3755319594.119400,0,1,299.996,299.999,41.868,3.227,0,0,300.000,300.000,14.030,9.960,1
3755319744.119400,0,1,300.006,300.000,41.871,3.225,0,0,300.000,300.000,14.100,10.010,1
3755319894.119400,0,1,299.996,300.002,41.872,3.228,0,0,300.000,300.000,14.080,9.990,1
3755320044.119400,0,1,300.002,300.001,41.873,3.230,0,0,300.000,300.000,14.080,10.030,1
3755320194.119400,0,1,299.999,300.003,41.873,3.229,0,0,300.000,300.000,14.060,10.010,1
3755320344.119400,0,1,300.002,300.001,41.874,3.227,0,0,300.000,300.000,14.060,10.010,1
3755320494.119400,0,1,299.998,300.000,41.878,3.227,0,0,300.000,300.000,14.080,10.030,1
3755320644.119400,0,1,300.002,300.000,41.880,3.227,0,0,300.000,300.000,14.100,9.990,1
3755320794.119400,0,1,300.001,299.999,41.882,3.228,0,0,300.000,300.000,14.030,10.030,1
3755320944.119400,0,1,300.001,299.999,41.883,3.229,0,0,300.000,300.000,14.160,10.010,1
3755321094.119400,0,1,300.000,300.000,41.881,3.228,0,0,300.000,300.000,14.030,10.010,1
3755321244.119400,0,1,300.004,300.000,41.885,3.229,0,0,300.000,300.000,14.100,10.010,1
3755321394.119400,0,1,299.994,299.998,41.887,3.229,0,0,300.000,300.000,14.030,10.030,1
3755321544.119400,0,1,300.003,300.000,41.889,3.228,0,0,300.000,300.000,14.080,10.040,1
3755321694.119400,0,1,299.999,300.001,41.890,3.227,0,0,300.000,300.000,14.060,9.960,1
3755321844.119400,0,1,300.001,299.998,41.890,3.228,0,0,300.000,300.000,14.080,10.010,1
3755321994.119400,0,1,300.001,299.999,41.891,3.228,0,0,300.000,300.000,14.100,10.010,1
3755322144.119400,0,1,300.002,299.999,41.892,3.229,0,0,300.000,300.000,14.060,10.030,1
3755322294.119400,0,1,299.999,300.000,41.893,3.228,0,0,300.000,300.000,14.100,10.030,1
3755322444.119400,0,1,300.000,300.000,41.895,3.227,0,0,300.000,300.000,14.060,10.030,1
3755322594.119400,0,1,299.997,300.001,41.894,3.228,0,0,300.000,300.000,14.060,9.990,1
3755322744.119400,0,1,300.002,299.999,41.895,3.228,0,0,300.000,300.000,14.100,10.010,1
3755322894.119400,0,1,299.997,299.999,41.895,3.229,0,0,300.000,300.000,14.050,10.010,1
3755323044.119400,0,1,300.001,300.001,41.896,3.229,0,0,300.000,300.000,14.080,10.030,1
3755323194.119400,0,1,299.996,300.000,41.897,3.228,0,0,300.000,300.000,14.060,10.010,1
3755323344.119400,0,1,300.001,300.001,41.897,3.230,0,0,300.000,300.000,14.080,9.990,1
3755323494.119400,0,1,299.998,300.000,41.899,3.230,0,0,300.000,300.000,14.060,10.010,1
3755323644.119400,0,1,300.004,300.000,41.900,3.228,0,0,300.000,300.000,14.100,10.030,1
3755323794.119400,0,1,299.996,300.000,41.902,3.229,0,0,300.000,300.000,14.140,10.010,1
3755323944.119400,0,1,300.004,299.997,41.902,3.229,0,0,300.000,300.000,14.030,10.030,1
3755324094.119400,0,1,299.996,300.004,41.903,3.229,0,0,300.000,300.000,14.100,10.010,1
3755324244.119400,0,1,300.003,300.001,41.903,3.229,0,0,300.000,300.000,14.050,10.030,1
3755324394.119400,0,1,299.999,299.998,41.902,3.228,0,0,300.000,300.000,14.120,10.010,1
3755324544.119400,0,1,300.001,300.001,41.902,3.227,0,0,300.000,300.000,14.030,10.010,1
3755324694.119400,0,1,299.999,299.999,41.901,3.228,0,0,300.000,300.000,14.080,10.010,1
3755324844.119400,0,1,299.999,299.999,41.901,3.229,0,0,300.000,300.000,14.080,10.030,1
3755324994.119400,0,1,300.003,299.998,41.903,3.228,0,0,300.000,300.000,14.100,10.030,1
3755325144.119400,0,1,299.998,300.000,41.903,3.230,0,0,300.000,300.000,14.060,10.010,1
3755325294.119400,0,1,300.001,300.000,41.904,3.230,0,0,300.000,300.000,14.060,9.990,1
3755325444.119400,0,1,300.000,299.998,41.905,3.228,0,0,300.000,300.000,14.060,9.990,1
3755325594.119400,0,1,299.998,300.001,41.906,3.229,0,0,300.000,300.000,14.160,10.010,1
3755325744.119400,0,1,300.001,300.002,41.906,3.229,0,0,300.000,300.000,14.030,10.010,1
3755325894.119400,0,1,299.998,299.999,41.907,3.229,0,0,300.000,300.000,14.080,10.040,1
3755326044.119400,0,1,300.001,299.999,41.907,3.228,0,0,300.000,300.000,14.100,9.990,1
3755326194.119400,0,1,299.999,299.999,41.908,3.229,0,0,300.000,300.000,14.060,10.030,1
3755326344.119400,0,1,300.000,300.000,41.908,3.228,0,0,300.000,300.000,14.100,10.030,1
3755326494.119400,0,1,299.998,299.999,41.908,3.230,0,0,300.000,300.000,14.050,10.040,1
3755326644.119400,0,1,300.002,299.999,41.907,3.228,0,0,300.000,300.000,14.100,10.040,1
3755326794.119400,0,1,300.000,299.998,41.904,3.229,0,0,300.000,300.000,13.990,9.990,1
3755326944.119400,0,1,300.001,299.998,41.904,3.229,0,0,300.000,300.000,14.160,10.040,1
3755327094.119400,0,1,299.997,299.999,41.902,3.229,0,0,300.000,300.000,14.100,9.980,1
3755327244.119400,0,1,300.001,299.999,41.902,3.229,0,0,300.000,300.000,14.050,10.030,1
3755327394.119400,0,1,299.998,300.003,41.902,3.229,0,0,300.000,300.000,14.060,10.030,1
3755327544.119400,0,1,299.998,300.000,41.903,3.230,0,0,300.000,300.000,13.990,10.030,1
3755327694.119400,0,1,299.997,299.999,41.904,3.230,0,0,300.000,300.000,14.140,10.010,1
3755327844.119400,0,1,300.002,300.000,41.904,3.229,0,0,300.000,300.000,14.060,10.030,1
3755327994.119400,0,1,299.903,0.000,41.907,3.229,0,0,300.000,300.000,18.630,0.000,4
3755328144.119400,0,1,300.084,0.000,41.963,3.230,0,0,300.000,300.000,15.400,0.000,4
3755328294.119400,0,1,299.921,0.000,41.992,3.230,0,0,300.000,300.000,17.800,0.000,4
3755328444.119400,0,1,300.077,0.000,41.977,3.228,0,0,300.000,300.000,15.770,0.000,4
3755328594.119400,0,1,299.931,0.000,41.946,3.229,0,0,300.000,300.000,17.820,0.000,4
3755328744.119400,0,1,300.064,0.000,41.912,3.231,0,0,300.000,300.000,16.030,0.000,4
3755328894.119400,0,1,299.942,0.000,41.881,3.229,0,0,300.000,300.000,17.640,0.000,4
3755329044.119400,0,1,300.055,0.000,41.850,3.229,0,0,300.000,300.000,16.310,0.000,4
3755329194.119400,0,1,299.951,0.000,41.827,3.229,0,0,300.000,300.000,17.700,0.000,4
3755329344.119400,0,1,300.043,0.000,41.806,3.229,0,0,300.000,300.000,16.610,0.000,4
3755329494.119400,0,1,299.959,0.000,41.788,3.229,0,0,300.000,300.000,17.610,0.000,4
3755329644.119400,0,1,300.034,0.000,41.773,3.230,0,0,300.000,300.000,16.670,0.000,4
3755329794.119400,0,1,299.969,0.000,41.759,3.229,0,0,300.000,300.000,17.640,0.000,4
3755329944.119400,0,1,300.028,0.000,41.748,3.229,0,0,300.000,300.000,16.810,0.000,4
3755330094.119400,0,1,299.974,0.000,41.740,3.228,0,0,300.000,300.000,17.640,0.000,4
3755330244.119400,0,1,300.026,0.000,41.733,3.229,0,0,300.000,300.000,16.950,0.000,4
3755330394.119400,0,1,299.976,0.000,41.724,3.228,0,0,300.000,300.000,17.660,0.000,4
3755330544.119400,0,1,300.019,0.000,41.717,3.229,0,0,300.000,300.000,17.040,0.000,4
3755330694.119400,0,1,299.981,0.000,41.711,3.229,0,0,300.000,300.000,17.640,0.000,4
3755330844.119400,0,1,300.017,0.000,41.703,3.230,0,0,300.000,300.000,17.200,0.000,4
3755330994.119400,0,1,299.984,0.000,41.698,3.229,0,0,300.000,300.000,17.660,0.000,4
3755331144.119400,0,1,300.012,0.000,41.695,3.229,0,0,300.000,300.000,17.240,0.000,4
3755331294.119400,0,1,299.988,0.000,41.694,3.229,0,0,300.000,300.000,17.700,0.000,4
3755331444.119400,0,1,300.011,0.000,41.696,3.227,0,0,300.000,300.000,17.300,0.000,4
3755331594.119400,0,1,299.991,0.000,41.693,3.228,0,0,300.000,300.000,17.680,0.000,4
3755331744.119400,0,1,300.006,0.000,41.692,3.229,0,0,300.000,300.000,17.340,0.000,4
3755331894.119400,0,1,300.053,0.000,41.750,3.228,0,0,300.000,300.000,15.710,0.000,4
3755332044.119400,0,1,299.959,0.000,42.058,3.229,0,0,300.000,300.000,17.140,0.000,4
3755332194.119400,0,1,300.101,298.502,42.367,3.228,0,0,300.000,300.000,14.630,9.750,4
3755332284.119400,0,1,300.091,299.917,42.531,3.230,0,0,300.000,300.000,14.800,12.110,4