File: log/20221125.dat
[Header]
; Displex Transport Data File (default extension .dat)
; Copyright 2016, Hechang LEI, hlei@ruc.edu.cn. All rights reserved.
BYAPP, Displex, 2.0
INFO, 9T mag, Release 2.0.
INFO, Channel 1, Temperature Sensor
INFO, Sample 1 Length (cm): 0.000000; Width (cm): 0.000000; Thickness (cm): 0.000000.

[Data]
Timestamp(s),Field(Oe),Field Status,TempA(K),TempB(K),TempC(K),TempD(K),Ramp1,Ramp2,Setpoint1,Setpoint2,Output1(%),Output2(%),Temp Status
3752209091.734000,,,299.861,301.203,42.068,3.208,0,0,300.000,300.000,17.450,0.000,4
3752209535.298000,,,288.822,289.043,47.226,4.503,1,1,2.000,2.000,0.000,0.000,3
3752209985.298000,,,268.292,269.806,51.559,4.585,1,1,2.000,2.000,0.000,0.000,3
3752210435.298000,,,248.427,250.753,54.083,4.672,1,1,2.000,2.000,0.000,0.000,3
3752210885.298000,,,229.466,232.525,55.848,4.740,1,1,2.000,2.000,0.000,0.000,3
3752211335.298000,,,211.683,215.375,57.120,4.803,1,1,2.000,2.000,0.000,0.000,3
3752211785.298000,,,195.036,199.180,58.038,4.842,1,1,2.000,2.000,0.000,0.000,3
3752212235.298000,,,179.450,183.829,58.697,4.875,1,1,2.000,2.000,0.000,0.000,3
3752212685.298000,,,164.869,169.523,59.143,4.899,1,1,2.000,2.000,0.000,0.000,3
3752213135.298000,,,151.138,156.122,59.411,4.916,1,1,2.000,2.000,0.000,0.000,3
3752213585.298000,,,138.123,143.318,59.536,4.925,1,1,2.000,2.000,0.000,0.000,3
3752214035.298000,,,125.605,130.314,59.543,4.929,1,1,2.000,2.000,0.000,0.000,3
3752214485.298000,,,113.562,118.459,59.447,4.937,1,1,2.000,2.000,0.000,0.000,3
3752214935.298000,,,101.813,106.859,59.263,4.929,1,1,2.000,2.000,0.000,0.000,3
3752215385.298000,,,90.135,95.268,59.003,4.925,0,0,2.000,2.000,0.000,0.000,4
3752215835.298000,,,78.240,83.450,58.671,4.916,0,0,2.000,2.000,0.000,0.000,4
3752216285.298000,,,65.695,70.913,58.273,4.905,0,0,2.000,2.000,0.000,0.000,4
3752216735.298000,,,51.467,56.571,57.803,4.889,0,0,2.000,2.000,0.000,0.000,4
3752217185.298000,,,31.226,35.105,57.242,4.870,0,0,2.000,2.000,0.000,0.000,4
3752217635.298000,,,6.603,6.049,56.451,4.825,0,0,2.000,2.000,0.000,0.000,4
3752218085.298000,,,5.271,4.781,55.348,4.736,0,0,2.000,2.000,0.000,0.000,4
3752218535.298000,,,5.003,4.616,54.323,4.671,0,0,2.000,2.000,0.000,0.000,4
3752218985.298000,,,4.807,4.464,53.556,4.636,0,0,2.000,2.000,0.000,0.000,4
3752219435.298000,,,4.676,4.362,52.963,4.610,0,0,2.000,2.000,0.000,0.000,4
3752219885.298000,,,4.578,4.309,52.488,4.589,0,0,2.000,2.000,0.000,0.000,4
3752220335.298000,,,4.512,4.260,52.090,4.572,0,0,2.000,2.000,0.000,0.000,4
3752220785.298000,,,3.960,3.709,51.798,3.754,0,0,2.000,2.000,0.000,0.000,4
3752221235.298000,,,2.238,2.000,48.711,3.456,0,0,2.000,2.000,0.000,0.000,1
3752221685.298000,,,2.029,2.000,45.465,3.355,0,0,2.000,2.000,0.010,0.020,1
3752222135.298000,,,2.108,2.000,43.048,3.277,0,0,2.000,2.000,0.000,0.020,1
3752222559.371000,,,1.525,1.542,40.978,3.074,1,1,2.000,2.000,0.000,0.000,3
3752223009.371000,,,8.253,8.252,39.698,3.076,1,1,300.000,300.000,0.390,0.530,2
3752223459.371000,,,30.568,30.555,38.245,3.181,1,1,300.000,300.000,3.110,1.860,2
3752223909.371000,,,52.879,52.857,38.019,3.177,1,1,300.000,300.000,9.180,5.410,2
3752224359.371000,,,75.189,75.157,37.831,3.173,1,1,300.000,300.000,15.510,9.320,2
3752224809.371000,,,97.482,97.453,37.679,3.172,1,1,300.000,300.000,21.060,12.950,2
3752225259.371000,,,119.765,119.748,37.552,3.166,1,1,300.000,300.000,25.760,16.230,2
3752225709.371000,,,142.052,142.027,37.449,3.161,1,1,300.000,300.000,29.980,19.170,2
3752226159.371000,,,164.340,164.316,37.371,3.161,1,1,300.000,300.000,33.840,21.970,2
3752226609.371000,,,186.625,186.607,37.333,3.157,1,1,300.000,300.000,37.460,24.520,2
3752227059.371000,,,208.905,208.889,37.322,3.155,1,1,300.000,300.000,40.780,27.100,2
3752227509.371000,,,231.199,231.172,37.351,3.155,1,1,300.000,300.000,44.050,29.750,2
3752227959.371000,,,253.483,253.455,37.414,3.153,1,1,300.000,300.000,47.160,33.000,2
3752228409.371000,,,275.673,275.662,37.510,3.154,1,1,300.000,300.000,49.750,35.550,2
3752228859.371000,,,298.154,297.852,37.641,3.155,1,1,300.000,300.000,54.150,38.090,2
3752229309.371000,,,300.056,300.007,37.781,3.156,0,0,300.000,300.000,39.120,24.260,4
3752229759.371000,,,299.943,300.007,37.919,3.156,0,0,300.000,300.000,27.270,22.290,1
3752230209.371000,,,300.071,300.005,38.062,3.155,0,0,300.000,300.000,31.270,20.800,1
3752230659.371000,,,299.940,300.006,38.208,3.157,0,0,300.000,300.000,25.110,19.400,1
3752231109.371000,,,300.058,300.005,38.358,3.156,0,0,300.000,300.000,26.370,18.190,1
3752231559.371000,,,299.958,300.003,38.505,3.163,0,0,300.000,300.000,22.990,17.190,1
3752232009.371000,,,300.042,300.002,38.653,3.159,0,0,300.000,300.000,22.950,16.320,1
3752232459.371000,,,299.971,300.004,38.790,3.165,0,0,300.000,300.000,21.200,15.530,1
3752232909.371000,,,300.019,300.002,38.926,3.165,0,0,300.000,300.000,20.830,14.860,1
3752233359.371000,,,299.988,300.002,39.057,3.168,0,0,300.000,300.000,19.630,14.330,1
3752233809.371000,,,300.012,300.002,39.188,3.171,0,0,300.000,300.000,19.210,13.790,1
3752234259.371000,,,299.995,300.002,39.317,3.173,0,0,300.000,300.000,18.480,13.330,1
3752234709.371000,,,300.003,300.001,39.439,3.173,0,0,300.000,300.000,18.050,12.970,1
3752235159.371000,,,299.994,300.001,39.552,3.176,0,0,300.000,300.000,17.510,12.640,1
3752235609.371000,,,300.008,300.002,39.662,3.178,0,0,300.000,300.000,17.140,12.330,1
3752236059.371000,,,299.998,300.001,39.773,3.178,0,0,300.000,300.000,16.750,12.090,1
3752236509.371000,,,300.006,300.000,39.880,3.175,0,0,300.000,300.000,16.450,11.820,1
3752236959.371000,,,299.996,300.000,39.980,3.177,0,0,300.000,300.000,16.190,11.640,1
3752237409.371000,,,299.998,300.001,40.081,3.180,0,0,300.000,300.000,15.970,11.470,1
3752237859.371000,,,300.005,300.000,40.173,3.182,0,0,300.000,300.000,15.630,11.310,1
3752238309.371000,,,299.999,299.999,40.264,3.185,0,0,300.000,300.000,15.530,11.150,1
3752238759.371000,,,300.002,300.001,40.354,3.186,0,0,300.000,300.000,15.320,11.020,1
3752239209.371000,,,299.996,300.002,40.437,3.185,0,0,300.000,300.000,15.240,10.950,4
3752239659.371000,,,300.000,299.999,40.519,3.187,0,0,300.000,300.000,15.050,10.810,1
3752240109.371000,,,300.004,299.999,40.597,3.187,0,0,300.000,300.000,14.890,10.710,1
3752240559.371000,,,299.998,300.000,40.665,3.189,0,0,300.000,300.000,14.840,10.620,1
3752241009.371000,,,300.001,300.000,40.732,3.189,0,0,300.000,300.000,14.670,10.540,1
3752241459.371000,,,299.999,299.999,40.789,3.190,0,0,300.000,300.000,14.570,10.510,1
3752241909.371000,,,299.997,300.002,40.846,3.192,0,0,300.000,300.000,14.550,10.390,1
3752242359.371000,,,300.004,300.002,40.903,3.189,0,0,300.000,300.000,14.360,10.340,1
3752242809.371000,,,300.000,300.000,40.955,3.190,0,0,300.000,300.000,14.420,10.310,1
3752243259.371000,,,300.001,300.000,40.999,3.194,0,0,300.000,300.000,14.290,10.240,1
3752243709.371000,,,300.001,300.001,41.044,3.194,0,0,300.000,300.000,14.210,10.190,1
3752244159.371000,,,300.004,299.999,41.088,3.192,0,0,300.000,300.000,14.190,10.160,1
3752244609.371000,,,299.998,299.998,41.127,3.192,0,0,300.000,300.000,14.120,10.120,1
3752245059.371000,,,300.000,299.999,41.166,3.193,0,0,300.000,300.000,14.140,10.070,1
3752245509.371000,,,299.996,299.999,41.205,3.194,0,0,300.000,300.000,13.950,10.070,1
3752245959.371000,,,300.003,300.000,41.237,3.196,0,0,300.000,300.000,13.990,10.030,1
3752246409.371000,,,300.003,300.001,41.270,3.197,0,0,300.000,300.000,13.970,9.990,1
3752246859.371000,,,299.997,300.001,41.305,3.196,0,0,300.000,300.000,13.880,9.980,1
3752247309.371000,,,300.002,300.000,41.323,3.194,0,0,300.000,300.000,13.970,9.930,1
3752247759.371000,,,300.003,300.001,41.348,3.196,0,0,300.000,300.000,13.770,9.960,1
3752248209.371000,,,299.997,299.999,41.373,3.198,0,0,300.000,300.000,13.920,9.890,1
3752248659.371000,,,300.004,300.000,41.403,3.200,0,0,300.000,300.000,13.770,9.910,1
3752249109.371000,,,299.998,300.000,41.426,3.198,0,0,300.000,300.000,13.820,9.880,1
3752249559.371000,,,300.000,299.999,41.436,3.200,0,0,300.000,300.000,13.770,9.810,1
3752250009.371000,,,299.998,299.998,41.448,3.197,0,0,300.000,300.000,13.790,9.860,1
3752250459.371000,,,300.000,300.000,41.461,3.197,0,0,300.000,300.000,13.770,9.860,1
3752250909.371000,,,300.005,300.000,41.473,3.196,0,0,300.000,300.000,13.710,9.830,1
3752251359.371000,,,299.994,300.002,41.481,3.195,0,0,300.000,300.000,13.770,9.830,1
3752251809.371000,,,300.004,300.001,41.493,3.194,0,0,300.000,300.000,13.730,9.800,1
3752252259.371000,,,299.998,300.000,41.502,3.195,0,0,300.000,300.000,13.680,9.810,1
3752252709.371000,,,300.000,300.000,41.512,3.196,0,0,300.000,300.000,13.710,9.810,1
3752253159.371000,,,300.000,299.997,41.520,3.194,0,0,300.000,300.000,13.660,9.800,1
3752253609.371000,,,299.999,300.002,41.529,3.195,0,0,300.000,300.000,13.710,9.760,1
3752254059.371000,,,299.997,300.001,41.538,3.194,0,0,300.000,300.000,13.680,9.760,1
3752254509.371000,,,300.001,299.999,41.542,3.196,0,0,300.000,300.000,13.680,9.760,1
3752254959.371000,,,300.000,300.002,41.547,3.198,0,0,300.000,300.000,13.600,9.750,1
3752255409.371000,,,299.997,299.999,41.555,3.197,0,0,300.000,300.000,13.710,9.760,1
3752255859.371000,,,300.004,299.999,41.563,3.197,0,0,300.000,300.000,13.620,9.730,1
3752256309.371000,,,300.004,300.002,41.565,3.195,0,0,300.000,300.000,13.580,9.730,1
3752256759.371000,,,299.996,299.998,41.566,3.197,0,0,300.000,300.000,13.640,9.780,1
3752257209.371000,,,300.000,299.998,41.569,3.196,0,0,300.000,300.000,13.600,9.750,1
3752257659.371000,,,299.999,300.000,41.572,3.197,0,0,300.000,300.000,13.690,9.750,1
3752258109.371000,,,300.004,300.001,41.573,3.196,0,0,300.000,300.000,13.570,9.730,1
3752258559.371000,,,299.997,300.001,41.578,3.194,0,0,300.000,300.000,13.680,9.730,1
3752259009.371000,,,300.003,299.999,41.575,3.196,0,0,300.000,300.000,13.640,9.750,1
3752259459.371000,,,299.998,299.999,41.575,3.196,0,0,300.000,300.000,13.600,9.750,1
3752259909.371000,,,299.999,299.997,41.577,3.196,0,0,300.000,300.000,13.580,9.730,1
3752260359.371000,,,299.998,300.000,41.579,3.196,0,0,300.000,300.000,13.620,9.720,1
3752260809.371000,,,300.003,299.999,41.579,3.194,0,0,300.000,300.000,13.510,9.750,1
3752261259.371000,,,299.995,299.999,41.577,3.193,0,0,300.000,300.000,13.640,9.730,1
3752261709.371000,,,300.005,300.000,41.574,3.193,0,0,300.000,300.000,13.510,9.720,1
3752262159.371000,,,299.996,300.000,41.566,3.192,0,0,300.000,300.000,13.580,9.730,1
3752262609.371000,,,300.002,299.998,41.567,3.193,0,0,300.000,300.000,13.510,9.730,1
3752263059.371000,,,299.998,299.999,41.566,3.192,0,0,300.000,300.000,13.690,9.720,1
3752263509.371000,,,300.002,299.999,41.566,3.193,0,0,300.000,300.000,13.510,9.750,1
3752263959.371000,,,299.997,300.000,41.570,3.193,0,0,300.000,300.000,13.600,9.730,1
3752264409.371000,,,300.001,300.000,41.570,3.192,0,0,300.000,300.000,13.580,9.700,1
3752264859.371000,,,300.000,300.000,41.571,3.193,0,0,300.000,300.000,13.600,9.730,1
3752265309.371000,,,300.001,300.001,41.572,3.191,0,0,300.000,300.000,13.550,9.720,1
3752265759.371000,,,300.000,300.001,41.572,3.194,0,0,300.000,300.000,13.550,9.700,1
3752266209.371000,,,300.003,300.000,41.574,3.193,0,0,300.000,300.000,13.580,9.720,1
3752266659.371000,,,299.998,299.997,41.575,3.194,0,0,300.000,300.000,13.570,9.720,1
3752267109.371000,,,300.004,300.000,41.577,3.195,0,0,300.000,300.000,13.600,9.720,1
3752267559.371000,,,299.998,300.000,41.577,3.194,0,0,300.000,300.000,13.490,9.720,1
3752268009.371000,,,300.000,300.000,41.575,3.194,0,0,300.000,300.000,13.600,9.700,1
3752268459.371000,,,300.001,299.998,41.571,3.194,0,0,300.000,300.000,13.490,9.720,1
3752268909.371000,,,299.999,300.001,41.568,3.194,0,0,300.000,300.000,13.620,9.720,1
3752269359.371000,,,300.001,300.000,41.571,3.194,0,0,300.000,300.000,13.530,9.730,1
3752269809.371000,,,299.996,300.001,41.570,3.195,0,0,300.000,300.000,13.600,9.700,1
3752270259.371000,,,300.002,299.999,41.570,3.194,0,0,300.000,300.000,13.490,9.730,1
3752270709.371000,,,299.996,300.000,41.573,3.194,0,0,300.000,300.000,13.640,9.720,1
3752271159.371000,,,300.002,300.000,41.576,3.194,0,0,300.000,300.000,13.490,9.720,1
3752271609.371000,,,299.998,299.999,41.574,3.193,0,0,300.000,300.000,13.620,9.700,1
3752272059.371000,,,300.000,299.998,41.576,3.195,0,0,300.000,300.000,13.510,9.700,1
3752272509.371000,,,300.004,299.998,41.583,3.194,0,0,300.000,300.000,13.490,9.700,1
3752272959.371000,,,299.999,300.000,41.587,3.195,0,0,300.000,300.000,13.510,9.720,1
3752273409.371000,,,300.004,300.001,41.585,3.196,0,0,300.000,300.000,13.550,9.700,1
3752273859.371000,,,299.997,299.999,41.581,3.193,0,0,300.000,300.000,13.600,9.730,1
3752274309.371000,,,300.004,299.998,41.579,3.193,0,0,300.000,300.000,13.440,9.700,1
3752274759.371000,,,299.997,300.000,41.578,3.193,0,0,300.000,300.000,13.580,9.720,1
3752275209.371000,,,300.002,300.000,41.582,3.193,0,0,300.000,300.000,13.580,9.700,1
3752275659.371000,,,299.997,300.001,41.581,3.192,0,0,300.000,300.000,13.570,9.700,1
3752276109.371000,,,300.006,300.002,41.582,3.193,0,0,300.000,300.000,13.530,9.700,1
3752276559.371000,,,299.997,300.001,41.586,3.192,0,0,300.000,300.000,13.550,9.700,1
3752277009.371000,,,300.009,300.001,41.585,3.191,0,0,300.000,300.000,13.510,9.720,1
3752277459.371000,,,299.992,300.001,41.582,3.192,0,0,300.000,300.000,13.620,9.720,1
3752277909.371000,,,300.005,300.001,41.582,3.194,0,0,300.000,300.000,13.530,9.670,1
3752278359.371000,,,299.995,299.998,41.582,3.193,0,0,300.000,300.000,13.580,9.700,1
3752278809.371000,,,300.004,299.998,41.583,3.192,0,0,300.000,300.000,13.600,9.720,1
3752279259.371000,,,299.997,299.999,41.582,3.193,0,0,300.000,300.000,13.580,9.720,1
3752279709.371000,,,300.002,300.001,41.584,3.192,0,0,300.000,300.000,13.490,9.700,1
3752280159.371000,,,299.998,299.999,41.582,3.193,0,0,300.000,300.000,13.680,9.700,1
3752280609.371000,,,300.003,300.001,41.587,3.194,0,0,300.000,300.000,13.550,9.720,1
3752281059.371000,,,299.998,300.001,41.585,3.193,0,0,300.000,300.000,13.660,9.720,1
3752281509.371000,,,300.002,300.001,41.585,3.192,0,0,300.000,300.000,13.470,9.700,1
3752281959.371000,,,299.996,299.999,41.586,3.194,0,0,300.000,300.000,13.600,9.700,1
3752282409.371000,,,300.002,299.999,41.586,3.194,0,0,300.000,300.000,13.570,9.700,1
3752282859.371000,,,299.998,300.000,41.587,3.191,0,0,300.000,300.000,13.510,9.730,1
3752283309.371000,,,299.999,299.998,41.590,3.191,0,0,300.000,300.000,13.600,9.720,1
3752283759.371000,,,300.003,300.000,41.592,3.190,0,0,300.000,300.000,13.440,9.700,1
3752284209.371000,,,299.999,300.000,41.596,3.190,0,0,300.000,300.000,13.620,9.720,1
3752284659.371000,,,300.001,299.999,41.597,3.190,0,0,300.000,300.000,13.530,9.720,1
3752285109.371000,,,299.999,300.000,41.595,3.187,0,0,300.000,300.000,13.580,9.700,1
3752285559.371000,,,300.001,300.000,41.593,3.193,0,0,300.000,300.000,13.620,9.720,1
3752286009.371000,,,299.999,299.999,41.593,3.194,0,0,300.000,300.000,13.570,9.700,1
3752286459.371000,,,299.998,299.999,41.593,3.194,0,0,300.000,300.000,13.550,9.730,1
3752286909.371000,,,300.001,299.999,41.589,3.194,0,0,300.000,300.000,13.530,9.720,1
3752287359.371000,,,299.999,299.998,41.589,3.194,0,0,300.000,300.000,13.640,9.730,1
3752287809.371000,,,299.999,300.001,41.590,3.193,0,0,300.000,300.000,13.510,9.730,1
3752288259.371000,,,300.002,300.001,41.590,3.194,0,0,300.000,300.000,13.570,9.720,1
3752288709.371000,,,299.996,299.998,41.588,3.194,0,0,300.000,300.000,13.660,9.700,1
3752289159.371000,,,300.002,300.001,41.588,3.193,0,0,300.000,300.000,13.530,9.700,1
3752289609.371000,,,299.998,299.999,41.589,3.193,0,0,300.000,300.000,13.620,9.700,1
3752290059.371000,,,299.999,299.998,41.589,3.192,0,0,300.000,300.000,13.600,9.700,1
3752290509.371000,,,300.000,300.000,41.589,3.192,0,0,300.000,300.000,13.600,9.720,1
3752290959.371000,,,300.002,299.998,41.587,3.191,0,0,300.000,300.000,13.550,9.700,1
3752291409.371000,,,299.994,300.000,41.586,3.192,0,0,300.000,300.000,13.620,9.700,1
3752291859.371000,,,300.001,299.999,41.587,3.192,0,0,300.000,300.000,13.510,9.720,1
3752292309.371000,,,300.000,300.000,41.590,3.192,0,0,300.000,300.000,13.600,9.700,1
3752292759.371000,,,300.001,299.999,41.595,3.188,0,0,300.000,300.000,13.530,9.720,1
3752293209.371000,,,299.995,300.001,41.594,3.186,0,0,300.000,300.000,13.600,9.720,1
3752293659.371000,,,300.000,300.002,41.589,3.186,0,0,300.000,300.000,13.620,9.700,1
3752294109.371000,,,299.996,299.998,41.589,3.190,0,0,300.000,300.000,13.570,9.730,1
3752294559.371000,,,300.000,300.000,41.592,3.185,0,0,300.000,300.000,13.580,9.720,1
3752295009.371000,,,300.000,299.999,41.593,3.186,0,0,300.000,300.000,13.470,9.720,1
3752295459.371000,,,299.998,300.001,41.594,3.186,0,0,300.000,300.000,13.710,9.700,1
3752295909.371000,,,300.005,299.998,41.594,3.190,0,0,300.000,300.000,13.380,9.720,1
3752296359.371000,,,299.995,299.999,41.593,3.191,0,0,300.000,300.000,13.710,9.700,1
3752296809.371000,,,300.004,300.000,41.593,3.193,0,0,300.000,300.000,13.420,9.720,1
3752297259.371000,,,299.999,300.000,41.597,3.189,0,0,300.000,300.000,13.660,9.720,1
3752297709.371000,,,300.003,300.001,41.594,3.190,0,0,300.000,300.000,13.550,9.720,1
3752298159.371000,,,299.998,300.001,41.593,3.190,0,0,300.000,300.000,13.580,9.720,1
3752298609.371000,,,300.001,299.998,41.592,3.188,0,0,300.000,300.000,13.510,9.720,1
3752299059.371000,,,299.999,300.001,41.587,3.189,0,0,300.000,300.000,13.680,9.720,1
3752299509.371000,,,300.002,300.000,41.586,3.191,0,0,300.000,300.000,13.470,9.730,1
3752299959.371000,,,299.999,299.999,41.586,3.193,0,0,300.000,300.000,13.640,9.720,1
3752300409.371000,,,300.000,299.999,41.588,3.190,0,0,300.000,300.000,13.530,9.720,1
3752300859.371000,,,300.000,300.000,41.588,3.193,0,0,300.000,300.000,13.620,9.700,1
3752301309.371000,,,299.997,300.000,41.592,3.195,0,0,300.000,300.000,13.640,9.720,1
3752301759.371000,,,300.003,300.000,41.596,3.194,0,0,300.000,300.000,13.570,9.720,1
3752302209.371000,,,299.996,300.002,41.596,3.195,0,0,300.000,300.000,13.570,9.730,1
3752302659.371000,,,300.002,299.997,41.596,3.195,0,0,300.000,300.000,13.570,9.730,1
3752303109.371000,,,299.999,299.997,41.596,3.198,0,0,300.000,300.000,13.570,9.720,1
3752303559.371000,,,299.998,300.000,41.595,3.194,0,0,300.000,300.000,13.620,9.700,1
3752304009.371000,,,300.000,299.998,41.597,3.192,0,0,300.000,300.000,13.550,9.700,1
3752304459.371000,,,300.003,299.999,41.593,3.192,0,0,300.000,300.000,13.580,9.720,1
3752304909.371000,,,299.999,299.998,41.595,3.194,0,0,300.000,300.000,13.570,9.650,1
3752305359.371000,,,300.000,299.997,41.594,3.194,0,0,300.000,300.000,13.580,9.730,1
3752305809.371000,,,300.000,299.998,41.596,3.194,0,0,300.000,300.000,13.550,9.700,1
3752306259.371000,,,300.001,300.000,41.600,3.196,0,0,300.000,300.000,13.640,9.720,1
3752306709.371000,,,300.000,300.000,41.602,3.194,0,0,300.000,300.000,13.570,9.700,1
3752307159.371000,,,300.006,299.999,41.603,3.195,0,0,300.000,300.000,13.530,9.720,1
3752307609.371000,,,299.997,299.999,41.604,3.196,0,0,300.000,300.000,13.580,9.720,1
3752308059.371000,,,300.001,300.000,41.608,3.195,0,0,300.000,300.000,13.620,9.700,1
3752308509.371000,,,300.001,299.997,41.604,3.197,0,0,300.000,300.000,13.470,9.730,1
3752308959.371000,,,300.000,300.001,41.607,3.193,0,0,300.000,300.000,13.680,9.720,1
3752309409.371000,,,300.002,300.000,41.609,3.192,0,0,300.000,300.000,13.420,9.700,1
3752309859.371000,,,299.997,299.999,41.608,3.196,0,0,300.000,300.000,13.660,9.730,1
3752310309.371000,,,300.003,300.001,41.609,3.194,0,0,300.000,300.000,13.570,9.720,1
3752310759.371000,,,299.999,299.999,41.611,3.197,0,0,300.000,300.000,13.640,9.730,1
3752311209.371000,,,300.000,300.000,41.609,3.196,0,0,300.000,300.000,13.550,9.730,1
3752311659.371000,,,300.000,300.000,41.611,3.195,0,0,300.000,300.000,13.580,9.700,1
3752312109.371000,,,300.001,300.000,41.607,3.198,0,0,300.000,300.000,13.580,9.680,1
3752312559.371000,,,299.998,300.002,41.609,3.198,0,0,300.000,300.000,13.620,9.680,1
3752313009.371000,,,300.002,299.999,41.606,3.197,0,0,300.000,300.000,13.530,9.720,1
3752313459.371000,,,300.000,299.999,41.602,3.197,0,0,300.000,300.000,13.620,9.720,1
3752313909.371000,,,299.998,299.998,41.597,3.194,0,0,300.000,300.000,13.490,9.700,1
3752314359.371000,,,300.003,299.999,41.591,3.196,0,0,300.000,300.000,13.580,9.700,1
3752314809.371000,,,299.997,300.000,41.586,3.199,0,0,300.000,300.000,13.570,9.700,1
3752315259.371000,,,300.003,299.999,41.585,3.198,0,0,300.000,300.000,13.580,9.700,1
3752315709.371000,,,299.994,300.001,41.580,3.198,0,0,300.000,300.000,13.600,9.730,1
3752316159.371000,,,300.003,299.998,41.578,3.196,0,0,300.000,300.000,13.550,9.700,1
3752316609.371000,,,299.999,300.001,41.573,3.196,0,0,300.000,300.000,13.570,9.700,1
3752317059.371000,,,299.998,300.000,41.569,3.197,0,0,300.000,300.000,13.570,9.720,1
3752317509.371000,,,299.998,299.997,41.566,3.198,0,0,300.000,300.000,13.550,9.700,1
3752317959.371000,,,299.999,300.000,41.571,3.195,0,0,300.000,300.000,13.570,9.700,1
3752318409.371000,,,299.997,300.001,41.573,3.195,0,0,300.000,300.000,13.600,9.700,1
3752318859.371000,,,299.999,299.998,41.571,3.195,0,0,300.000,300.000,13.570,9.700,1
3752319309.371000,,,300.000,299.999,41.571,3.194,0,0,300.000,300.000,13.600,9.720,1
3752319759.371000,,,300.000,300.001,41.573,3.194,0,0,300.000,300.000,13.550,9.700,1
3752320209.371000,,,300.000,300.000,41.574,3.193,0,0,300.000,300.000,13.550,9.700,1
3752320659.371000,,,299.999,299.999,41.569,3.194,0,0,300.000,300.000,13.620,9.700,1
3752321109.371000,,,300.000,300.000,41.567,3.194,0,0,300.000,300.000,13.490,9.720,1
3752321559.371000,,,300.004,299.998,41.567,3.192,0,0,300.000,300.000,13.530,9.700,1
3752322009.371000,,,299.995,299.999,41.562,3.194,0,0,300.000,300.000,13.530,9.720,1
3752322459.371000,,,300.002,300.001,41.555,3.193,0,0,300.000,300.000,13.570,9.730,1
3752322909.371000,,,299.999,300.001,41.549,3.193,0,0,300.000,300.000,13.550,9.700,1
3752323359.371000,,,300.001,300.000,41.549,3.194,0,0,300.000,300.000,13.510,9.700,1
3752323809.371000,,,299.997,300.000,41.549,3.193,0,0,300.000,300.000,13.580,9.720,1
3752324259.371000,,,300.000,299.998,41.546,3.192,0,0,300.000,300.000,13.580,9.750,1
3752324709.371000,,,299.998,300.001,41.541,3.192,0,0,300.000,300.000,13.550,9.700,1
3752325159.371000,,,300.004,300.001,41.542,3.192,0,0,300.000,300.000,13.550,9.700,1
3752325609.371000,,,299.997,299.999,41.540,3.192,0,0,300.000,300.000,13.580,9.730,1
3752326059.371000,,,300.001,299.999,41.539,3.193,0,0,300.000,300.000,13.570,9.730,1
3752326509.371000,,,299.999,300.001,41.537,3.195,0,0,300.000,300.000,13.600,9.680,1
3752326959.371000,,,300.001,300.001,41.540,3.197,0,0,300.000,300.000,13.530,9.680,1
3752327409.371000,,,300.000,299.998,41.541,3.196,0,0,300.000,300.000,13.550,9.720,1
3752327859.371000,,,300.002,299.999,41.539,3.192,0,0,300.000,300.000,13.550,9.730,1
3752328309.371000,,,300.000,299.998,41.538,3.195,0,0,300.000,300.000,13.570,9.720,1
3752328759.371000,,,299.997,300.001,41.537,3.195,0,0,300.000,300.000,13.580,9.700,1
3752329209.371000,,,299.997,299.999,41.539,3.197,0,0,300.000,300.000,13.510,9.670,1
3752329659.371000,,,300.004,300.001,41.537,3.190,0,0,300.000,300.000,13.580,9.680,1
3752330109.371000,,,300.000,300.001,41.534,3.191,0,0,300.000,300.000,13.490,9.720,1
3752330559.371000,,,299.997,300.000,41.535,3.189,0,0,300.000,300.000,13.580,9.700,1
3752331009.371000,,,300.000,299.999,41.532,3.188,0,0,300.000,300.000,13.550,9.700,1
3752331459.371000,,,299.996,299.999,41.529,3.190,0,0,300.000,300.000,13.600,9.720,1
3752331909.371000,,,300.000,300.001,41.530,3.188,0,0,300.000,300.000,13.570,9.720,1
3752332359.371000,,,299.998,300.000,41.534,3.191,0,0,300.000,300.000,13.530,9.720,1
3752332809.371000,,,300.002,299.999,41.535,3.187,0,0,300.000,300.000,13.580,9.700,1
3752333259.371000,,,299.995,300.002,41.531,3.190,0,0,300.000,300.000,13.570,9.700,1
3752333709.371000,,,299.999,300.001,41.526,3.190,0,0,300.000,300.000,13.570,9.700,1
3752334159.371000,,,300.001,299.998,41.524,3.190,0,0,300.000,300.000,13.550,9.700,1
3752334609.371000,,,299.999,300.000,41.525,3.187,0,0,300.000,300.000,13.530,9.720,1
3752335059.371000,,,300.003,299.996,41.522,3.190,0,0,300.000,300.000,13.530,9.720,1
3752335509.371000,,,300.004,300.003,41.523,3.186,0,0,300.000,300.000,13.510,9.680,1
3752335959.371000,,,299.997,300.001,41.521,3.186,0,0,300.000,300.000,13.570,9.720,1
3752336409.371000,,,299.999,300.000,41.522,3.185,0,0,300.000,300.000,13.510,9.680,1
3752336859.371000,,,299.996,299.997,41.521,3.185,0,0,300.000,300.000,13.620,9.720,1
3752337309.371000,,,300.002,300.000,41.522,3.186,0,0,300.000,300.000,13.490,9.720,1
3752337759.371000,,,299.996,299.999,41.521,3.186,0,0,300.000,300.000,13.640,9.700,1
3752338209.371000,,,300.000,299.999,41.523,3.185,0,0,300.000,300.000,13.510,9.700,1
3752338659.371000,,,299.995,300.001,41.527,3.187,0,0,300.000,300.000,13.620,9.720,1
3752339109.371000,,,300.003,299.997,41.525,3.186,0,0,300.000,300.000,13.530,9.670,1
3752339559.371000,,,299.996,300.000,41.524,3.187,0,0,300.000,300.000,13.570,9.700,1
3752340009.371000,,,300.005,300.001,41.522,3.186,0,0,300.000,300.000,13.570,9.700,1
3752340459.371000,,,300.002,299.998,41.524,3.189,0,0,300.000,300.000,13.580,9.720,1
3752340909.371000,,,299.997,299.999,41.524,3.188,0,0,300.000,300.000,13.660,9.720,1
3752341359.371000,,,300.006,300.000,41.524,3.190,0,0,300.000,300.000,13.510,9.650,1
3752341809.371000,,,299.997,300.001,41.527,3.188,0,0,300.000,300.000,13.620,9.700,1
3752342259.371000,,,300.003,300.000,41.527,3.189,0,0,300.000,300.000,13.490,9.720,1
3752342709.371000,,,299.998,299.999,41.528,3.188,0,0,300.000,300.000,13.570,9.730,1
3752343159.371000,,,300.000,300.002,41.528,3.187,0,0,300.000,300.000,13.580,9.720,1
3752343609.371000,,,300.000,300.001,41.529,3.187,0,0,300.000,300.000,13.570,9.720,1
3752344059.371000,,,299.999,299.998,41.534,3.186,0,0,300.000,300.000,13.530,9.700,1
3752344509.371000,,,299.999,299.999,41.535,3.187,0,0,300.000,300.000,13.600,9.700,1
3752344959.371000,,,300.002,300.000,41.536,3.188,0,0,300.000,300.000,13.570,9.700,1
3752345409.371000,,,299.998,299.999,41.536,3.188,0,0,300.000,300.000,13.550,9.720,1
3752345859.371000,,,299.999,299.999,41.538,3.187,0,0,300.000,300.000,13.620,9.700,1
3752346309.371000,,,300.004,300.002,41.539,3.187,0,0,300.000,300.000,13.490,9.720,1
3752346759.371000,,,300.002,300.000,41.537,3.193,0,0,300.000,300.000,13.550,9.700,1
3752347209.371000,,,300.000,300.002,41.544,3.190,0,0,300.000,300.000,13.570,9.720,1
3752347659.371000,,,300.000,300.000,41.547,3.192,0,0,300.000,300.000,13.660,9.700,1
3752348109.371000,,,299.999,299.998,41.549,3.192,0,0,300.000,300.000,13.490,9.720,1
3752348559.371000,,,300.000,299.997,41.553,3.189,0,0,300.000,300.000,13.680,9.720,1
3752349009.371000,,,300.000,300.001,41.556,3.193,0,0,300.000,300.000,13.550,9.700,1
3752349459.371000,,,299.997,299.999,41.557,3.195,0,0,300.000,300.000,13.600,9.750,1
3752349909.371000,,,300.005,300.001,41.557,3.195,0,0,300.000,300.000,13.510,9.730,1
3752350359.371000,,,299.999,300.001,41.560,3.198,0,0,300.000,300.000,13.600,9.700,1
3752350809.371000,,,300.000,299.999,41.564,3.198,0,0,300.000,300.000,13.550,9.700,1
3752351259.371000,,,299.999,300.001,41.563,3.200,0,0,300.000,300.000,13.600,9.700,1
3752351709.371000,,,299.998,299.998,41.566,3.198,0,0,300.000,300.000,13.580,9.720,1
3752352159.371000,,,299.998,300.000,41.564,3.197,0,0,300.000,300.000,13.570,9.700,1
3752352609.371000,,,300.003,299.998,41.567,3.199,0,0,300.000,300.000,13.570,9.700,1
3752353059.371000,,,299.997,300.001,41.567,3.197,0,0,300.000,300.000,13.600,9.700,1
3752353509.371000,,,300.000,300.001,41.564,3.197,0,0,300.000,300.000,13.580,9.700,1
3752353959.371000,,,299.999,299.999,41.564,3.196,0,0,300.000,300.000,13.550,9.730,1
3752354409.371000,,,300.002,300.003,41.561,3.193,0,0,300.000,300.000,13.580,9.680,1
3752354859.371000,,,299.999,300.001,41.559,3.193,0,0,300.000,300.000,13.530,9.700,1
3752355309.371000,,,300.003,300.002,41.556,3.192,0,0,300.000,300.000,13.600,9.720,1
3752355759.371000,,,300.000,300.000,41.555,3.192,0,0,300.000,300.000,13.530,9.730,1
3752356209.371000,,,300.003,299.999,41.554,3.193,0,0,300.000,300.000,13.580,9.730,1
3752356659.371000,,,299.998,299.999,41.561,3.192,0,0,300.000,300.000,13.570,9.700,1
3752357109.371000,,,299.997,300.001,41.558,3.195,0,0,300.000,300.000,13.580,9.720,1
3752357559.371000,,,300.005,299.998,41.560,3.196,0,0,300.000,300.000,13.510,9.730,1
3752358009.371000,,,299.994,300.001,41.564,3.194,0,0,300.000,300.000,13.620,9.670,1
3752358459.371000,,,300.005,300.003,41.565,3.194,0,0,300.000,300.000,13.510,9.680,1
3752358909.371000,,,299.998,300.000,41.563,3.194,0,0,300.000,300.000,13.530,9.680,1
3752359359.371000,,,300.000,299.998,41.564,3.194,0,0,300.000,300.000,13.640,9.720,1
3752359809.371000,,,300.000,299.998,41.566,3.193,0,0,300.000,300.000,13.550,9.720,1
3752360259.371000,,,300.000,300.000,41.568,3.193,0,0,300.000,300.000,13.570,9.720,1
3752360709.371000,,,300.000,300.000,41.568,3.191,0,0,300.000,300.000,13.570,9.700,1
3752361159.371000,,,299.998,299.998,41.570,3.191,0,0,300.000,300.000,13.600,9.720,1
3752361609.371000,,,300.000,299.999,41.571,3.194,0,0,300.000,300.000,13.580,9.700,1
3752362059.371000,,,299.997,300.000,41.576,3.193,0,0,300.000,300.000,13.570,9.700,1
3752362509.371000,,,300.003,299.999,41.576,3.192,0,0,300.000,300.000,13.550,9.720,1
3752362959.371000,,,299.997,299.999,41.578,3.192,0,0,300.000,300.000,13.530,9.720,1
3752363409.371000,,,300.002,300.001,41.575,3.190,0,0,300.000,300.000,13.620,9.720,1
3752363859.371000,,,299.998,299.998,41.575,3.190,0,0,300.000,300.000,13.570,9.700,1
3752364309.371000,,,300.000,300.001,41.574,3.189,0,0,300.000,300.000,13.570,9.700,1
3752364759.371000,,,299.998,299.997,41.568,3.190,0,0,300.000,300.000,13.570,9.700,1
3752365209.371000,,,300.005,299.998,41.571,3.188,0,0,300.000,300.000,13.570,9.700,1
3752365659.371000,,,299.995,300.001,41.576,3.190,0,0,300.000,300.000,13.640,9.650,1
3752366109.371000,,,300.002,300.000,41.578,3.189,0,0,300.000,300.000,13.570,9.680,1
3752366559.371000,,,299.998,300.000,41.576,3.188,0,0,300.000,300.000,13.570,9.700,1
3752367009.371000,,,300.003,299.999,41.580,3.189,0,0,300.000,300.000,13.530,9.700,1
3752367459.371000,,,300.001,300.002,41.578,3.186,0,0,300.000,300.000,13.470,9.700,1
3752367909.371000,,,299.999,299.998,41.577,3.186,0,0,300.000,300.000,13.570,9.680,1
3752368359.371000,,,299.998,300.001,41.578,3.190,0,0,300.000,300.000,13.570,9.680,1
3752368809.371000,,,300.000,300.000,41.584,3.191,0,0,300.000,300.000,13.580,9.680,1
3752369259.371000,,,300.002,300.000,41.583,3.189,0,0,300.000,300.000,13.550,9.700,1
3752369709.371000,,,299.999,299.999,41.587,3.190,0,0,300.000,300.000,13.600,9.680,1
3752370159.371000,,,300.003,300.000,41.589,3.190,0,0,300.000,300.000,13.530,9.670,1
3752370609.371000,,,300.000,300.000,41.592,3.191,0,0,300.000,300.000,13.600,9.680,1
3752371059.371000,,,300.003,299.999,41.588,3.190,0,0,300.000,300.000,13.530,9.700,1
3752371509.371000,,,300.000,299.999,41.590,3.189,0,0,300.000,300.000,13.470,9.700,1
3752371959.371000,,,300.001,299.998,41.586,3.188,0,0,300.000,300.000,13.490,9.700,1
3752372409.371000,,,300.002,299.998,41.585,3.188,0,0,300.000,300.000,13.550,9.700,1
3752372859.371000,,,299.996,299.998,41.585,3.187,0,0,300.000,300.000,13.550,9.700,1
3752373309.371000,,,300.002,299.999,41.586,3.188,0,0,300.000,300.000,13.550,9.680,1
3752373759.371000,,,300.002,300.000,41.586,3.189,0,0,300.000,300.000,13.490,9.700,1
3752374209.371000,,,299.996,300.000,41.584,3.191,0,0,300.000,300.000,13.570,9.700,1
3752374659.371000,,,300.009,300.001,41.591,3.192,0,0,300.000,300.000,13.470,9.670,1
3752375109.371000,,,299.992,299.999,41.592,3.192,0,0,300.000,300.000,13.530,9.700,1
3752375559.371000,,,300.001,300.002,41.596,3.193,0,0,300.000,300.000,13.600,9.650,1
3752376009.371000,,,299.999,299.999,41.594,3.190,0,0,300.000,300.000,13.470,9.680,1
3752376459.371000,,,299.997,299.998,41.590,3.188,0,0,300.000,300.000,13.620,9.670,1
3752376909.371000,,,300.001,300.004,41.584,3.192,0,0,300.000,300.000,13.490,9.670,1
3752377359.371000,,,299.998,299.998,41.584,3.195,0,0,300.000,300.000,13.640,9.640,1
3752377809.371000,,,300.005,300.000,41.589,3.191,0,0,300.000,300.000,13.440,9.680,1
3752378259.371000,,,299.998,299.998,41.589,3.194,0,0,300.000,300.000,13.620,9.700,1
3752378709.371000,,,300.003,299.999,41.588,3.195,0,0,300.000,300.000,13.490,9.700,1
3752379159.371000,,,299.998,300.002,41.586,3.195,0,0,300.000,300.000,13.600,9.670,1
3752379609.371000,,,300.002,299.998,41.587,3.196,0,0,300.000,300.000,13.510,9.680,1
3752380059.371000,,,299.999,300.000,41.587,3.192,0,0,300.000,300.000,13.530,9.680,1
3752380509.371000,,,300.005,300.000,41.581,3.195,0,0,300.000,300.000,13.510,9.680,1
3752380959.371000,,,299.999,300.000,41.584,3.194,0,0,300.000,300.000,13.580,9.700,1
3752381409.371000,,,300.002,300.000,41.585,3.193,0,0,300.000,300.000,13.460,9.700,1
3752381859.371000,,,299.998,300.000,41.584,3.192,0,0,300.000,300.000,13.510,9.700,1
3752382309.371000,,,300.004,300.002,41.585,3.195,0,0,300.000,300.000,13.530,9.680,1
3752382759.371000,,,300.000,300.000,41.587,3.193,0,0,300.000,300.000,13.460,9.680,1
3752383209.371000,,,300.003,300.000,41.587,3.194,0,0,300.000,300.000,13.530,9.670,1
3752383659.371000,,,299.998,300.000,41.591,3.194,0,0,300.000,300.000,13.490,9.670,1
3752384109.371000,,,300.000,300.001,41.593,3.194,0,0,300.000,300.000,13.550,9.670,1
3752384559.371000,,,300.002,299.999,41.597,3.194,0,0,300.000,300.000,13.550,9.670,1
3752385009.371000,,,300.001,300.000,41.600,3.194,0,0,300.000,300.000,13.510,9.680,1
3752385459.371000,,,300.003,300.001,41.601,3.191,0,0,300.000,300.000,13.530,9.700,1
3752385909.371000,,,299.997,300.003,41.597,3.194,0,0,300.000,300.000,13.570,9.680,1
3752386359.371000,,,300.000,300.000,41.602,3.194,0,0,300.000,300.000,13.550,9.680,1
3752386809.371000,,,300.002,300.002,41.605,3.195,0,0,300.000,300.000,13.510,9.700,1
3752387259.371000,,,299.998,299.999,41.608,3.196,0,0,300.000,300.000,13.570,9.680,1
3752387709.371000,,,300.000,300.001,41.605,3.196,0,0,300.000,300.000,13.530,9.670,1
3752388159.371000,,,300.002,300.001,41.611,3.195,0,0,300.000,300.000,13.510,9.700,1
3752388609.371000,,,299.998,299.998,41.608,3.195,0,0,300.000,300.000,13.550,9.680,1
3752389059.371000,,,299.999,300.000,41.604,3.195,0,0,300.000,300.000,13.530,9.670,1
3752389509.371000,,,300.003,299.999,41.603,3.195,0,0,300.000,300.000,13.490,9.680,1
3752389959.371000,,,300.001,299.999,41.604,3.194,0,0,300.000,300.000,13.530,9.700,1
3752390409.371000,,,300.000,299.999,41.603,3.193,0,0,300.000,300.000,13.600,9.700,1
3752390859.371000,,,300.000,299.999,41.606,3.195,0,0,300.000,300.000,13.510,9.680,1
3752391309.371000,,,299.998,299.999,41.606,3.196,0,0,300.000,300.000,13.580,9.670,1
3752391759.371000,,,300.000,300.001,41.601,3.196,0,0,300.000,300.000,13.470,9.680,1
3752392209.371000,,,299.999,299.999,41.602,3.187,0,0,300.000,300.000,13.570,9.680,1
3752392659.371000,,,300.004,300.001,41.597,3.195,0,0,300.000,300.000,13.470,9.680,1
3752393109.371000,,,299.998,300.000,41.600,3.195,0,0,300.000,300.000,13.510,9.650,1
3752393559.371000,,,300.003,300.001,41.600,3.196,0,0,300.000,300.000,13.550,9.700,1
3752394009.371000,,,299.997,300.001,41.603,3.196,0,0,300.000,300.000,13.510,9.670,1
3752394459.371000,,,300.000,300.000,41.606,3.196,0,0,300.000,300.000,13.530,9.700,1
3752394909.371000,,,299.996,299.999,41.607,3.197,0,0,300.000,300.000,13.510,9.680,1
3752395359.371000,,,300.000,300.000,41.609,3.197,0,0,300.000,300.000,13.580,9.680,1
3752395809.371000,,,299.999,299.999,41.610,3.196,0,0,300.000,300.000,13.470,9.680,1
3752396259.371000,,,299.998,299.999,41.609,3.196,0,0,300.000,300.000,13.600,9.720,1
3752396709.371000,,,300.002,300.002,41.610,3.197,0,0,300.000,300.000,13.510,9.680,1
3752397159.371000,,,299.998,300.001,41.606,3.195,0,0,300.000,300.000,13.600,9.680,1
3752397609.371000,,,300.001,299.999,41.605,3.197,0,0,300.000,300.000,13.460,9.680,1
3752398059.371000,,,300.005,299.997,41.609,3.194,0,0,300.000,300.000,13.490,9.700,1
3752398509.371000,,,300.002,300.002,41.615,3.195,0,0,300.000,300.000,13.490,9.670,1
3752398959.371000,,,299.994,300.001,41.614,3.196,0,0,300.000,300.000,13.570,9.720,1
3752399409.371000,,,300.005,299.998,41.608,3.196,0,0,300.000,300.000,13.550,9.670,1
3752399859.371000,,,299.996,300.000,41.610,3.197,0,0,300.000,300.000,13.600,9.670,1
3752400309.371000,,,300.001,300.002,41.612,3.195,0,0,300.000,300.000,13.530,9.670,1
3752400759.371000,,,300.003,300.000,41.617,3.196,0,0,300.000,300.000,13.530,9.640,1
3752401209.371000,,,299.992,299.999,41.616,3.197,0,0,300.000,300.000,13.530,9.700,1
3752401659.371000,,,300.004,299.999,41.618,3.197,0,0,300.000,300.000,13.530,9.670,1
3752402109.371000,,,299.999,300.000,41.620,3.196,0,0,300.000,300.000,13.490,9.680,1
3752402559.371000,,,299.997,299.998,41.621,3.195,0,0,300.000,300.000,13.600,9.680,1
3752403009.371000,,,300.002,300.001,41.623,3.196,0,0,300.000,300.000,13.530,9.650,1
3752403459.371000,,,299.998,299.998,41.622,3.196,0,0,300.000,300.000,13.530,9.670,1
3752403909.371000,,,299.998,300.000,41.623,3.195,0,0,300.000,300.000,13.570,9.680,1
3752404359.371000,,,300.005,299.998,41.625,3.196,0,0,300.000,300.000,13.440,9.680,1
3752404809.371000,,,299.995,299.998,41.626,3.196,0,0,300.000,300.000,13.580,9.700,1
3752405259.371000,,,300.002,300.000,41.629,3.197,0,0,300.000,300.000,13.530,9.680,1
3752405709.371000,,,299.997,299.998,41.629,3.195,0,0,300.000,300.000,13.570,9.670,1
3752406159.371000,,,300.001,300.000,41.628,3.194,0,0,300.000,300.000,13.490,9.670,1
3752406609.371000,,,299.997,299.998,41.628,3.196,0,0,300.000,300.000,13.580,9.680,1
3752407059.371000,,,300.001,300.000,41.630,3.196,0,0,300.000,300.000,13.510,9.670,1
3752407509.371000,,,299.998,300.000,41.630,3.197,0,0,300.000,300.000,13.600,9.670,1
3752407959.371000,,,299.999,299.998,41.625,3.197,0,0,300.000,300.000,13.470,9.700,1
3752408409.371000,,,299.998,299.996,41.622,3.196,0,0,300.000,300.000,13.620,9.680,1
3752408859.371000,,,300.000,300.000,41.625,3.197,0,0,300.000,300.000,13.510,9.670,1
3752409309.371000,,,300.001,299.999,41.626,3.195,0,0,300.000,300.000,13.510,9.670,1
3752409759.371000,,,299.998,300.001,41.627,3.197,0,0,300.000,300.000,13.510,9.650,1
3752410209.371000,,,299.999,300.001,41.629,3.197,0,0,300.000,300.000,13.530,9.670,1
3752410659.371000,,,299.999,300.001,41.628,3.194,0,0,300.000,300.000,13.510,9.700,1
3752411109.371000,,,299.999,300.000,41.628,3.196,0,0,300.000,300.000,13.600,9.700,1
3752411559.371000,,,300.001,300.000,41.627,3.197,0,0,300.000,300.000,13.470,9.680,1
3752412009.371000,,,299.998,300.000,41.630,3.198,0,0,300.000,300.000,13.490,9.700,1
3752412459.371000,,,300.001,300.000,41.631,3.196,0,0,300.000,300.000,13.530,9.670,1
3752412909.371000,,,299.998,300.000,41.632,3.196,0,0,300.000,300.000,13.470,9.680,1
3752413359.371000,,,299.997,300.000,41.635,3.196,0,0,300.000,300.000,13.550,9.680,1
3752413809.371000,,,300.001,300.000,41.630,3.197,0,0,300.000,300.000,13.490,9.670,1
3752414259.371000,,,299.995,300.000,41.628,3.197,0,0,300.000,300.000,13.600,9.700,1
3752414709.371000,,,300.005,300.000,41.630,3.198,0,0,300.000,300.000,13.400,9.680,1
3752415159.371000,,,299.992,299.999,41.631,3.197,0,0,300.000,300.000,13.640,9.700,1
3752415609.371000,,,300.008,300.001,41.630,3.197,0,0,300.000,300.000,13.400,9.670,1
3752416059.371000,,,299.993,299.997,41.630,3.197,0,0,300.000,300.000,13.600,9.670,1
3752416509.371000,,,300.002,300.000,41.633,3.196,0,0,300.000,300.000,13.470,9.680,1
3752416959.371000,,,299.997,299.998,41.634,3.196,0,0,300.000,300.000,13.550,9.650,1
3752417409.371000,,,300.000,299.999,41.636,3.197,0,0,300.000,300.000,13.600,9.680,1
3752417859.371000,,,299.997,300.001,41.634,3.197,0,0,300.000,300.000,13.490,9.680,1
3752418309.371000,,,300.004,300.002,41.637,3.196,0,0,300.000,300.000,13.490,9.670,1
3752418759.371000,,,299.998,299.999,41.636,3.196,0,0,300.000,300.000,13.550,9.680,1
3752419209.371000,,,299.998,299.999,41.634,3.196,0,0,300.000,300.000,13.490,9.650,1
3752419659.371000,,,299.998,299.999,41.634,3.199,0,0,300.000,300.000,13.490,9.680,1
3752420109.371000,,,300.000,300.001,41.638,3.198,0,0,300.000,300.000,13.570,9.680,1
3752420559.371000,,,299.998,299.999,41.636,3.199,0,0,300.000,300.000,13.510,9.700,1
3752421009.371000,,,299.998,299.998,41.634,3.198,0,0,300.000,300.000,13.550,9.680,1
3752421459.371000,,,300.003,300.003,41.633,3.197,0,0,300.000,300.000,13.440,9.650,1
3752421909.371000,,,299.998,300.000,41.631,3.197,0,0,300.000,300.000,13.570,9.680,1
3752422359.371000,,,300.000,299.999,41.629,3.197,0,0,300.000,300.000,13.440,9.670,1
3752422809.371000,,,299.999,299.997,41.630,3.198,0,0,300.000,300.000,13.580,9.700,1
3752423259.371000,,,300.000,299.998,41.631,3.197,0,0,300.000,300.000,13.470,9.680,1
3752423709.371000,,,300.000,300.000,41.631,3.197,0,0,300.000,300.000,13.620,9.650,1
3752424159.371000,,,300.000,300.001,41.631,3.198,0,0,300.000,300.000,13.460,9.670,1
3752424609.371000,,,300.000,300.000,41.630,3.200,0,0,300.000,300.000,13.620,9.670,1
3752425059.371000,,,300.002,300.000,41.631,3.201,0,0,300.000,300.000,13.470,9.680,1
3752425509.371000,,,299.999,300.000,41.634,3.200,0,0,300.000,300.000,13.580,9.680,1
3752425959.371000,,,300.002,299.999,41.636,3.199,0,0,300.000,300.000,13.460,9.680,1
3752426409.371000,,,300.001,300.000,41.642,3.199,0,0,300.000,300.000,13.600,9.680,1
3752426859.371000,,,299.996,299.998,41.646,3.198,0,0,300.000,300.000,13.510,9.680,1
3752427309.371000,,,300.004,300.001,41.647,3.198,0,0,300.000,300.000,13.470,9.670,1
3752427759.371000,,,299.999,300.001,41.646,3.198,0,0,300.000,300.000,13.570,9.700,1
3752428209.371000,,,300.000,300.000,41.648,3.198,0,0,300.000,300.000,13.460,9.680,1
3752428659.371000,,,299.996,300.000,41.648,3.199,0,0,300.000,300.000,13.620,9.680,1
3752429109.371000,,,300.003,300.001,41.647,3.199,0,0,300.000,300.000,13.470,9.670,1
3752429559.371000,,,299.997,299.998,41.647,3.200,0,0,300.000,300.000,13.570,9.670,1
3752430009.371000,,,299.998,300.000,41.651,3.199,0,0,300.000,300.000,13.580,9.650,1
3752430459.371000,,,300.000,300.000,41.651,3.200,0,0,300.000,300.000,13.530,9.670,1
3752430909.371000,,,300.003,300.000,41.651,3.198,0,0,300.000,300.000,13.580,9.680,1
3752431359.371000,,,299.996,299.999,41.652,3.198,0,0,300.000,300.000,13.550,9.670,1
3752431809.371000,,,300.001,299.999,41.653,3.199,0,0,300.000,300.000,13.550,9.680,1
3752432259.371000,,,299.998,300.000,41.652,3.200,0,0,300.000,300.000,13.530,9.680,1
3752432709.371000,,,299.997,299.999,41.653,3.200,0,0,300.000,300.000,13.550,9.670,1
3752433159.371000,,,300.002,300.000,41.652,3.200,0,0,300.000,300.000,13.530,9.680,1
3752433609.371000,,,300.001,299.997,41.652,3.200,0,0,300.000,300.000,13.460,9.680,1
3752434059.371000,,,300.001,299.997,41.651,3.198,0,0,300.000,300.000,13.510,9.680,1
3752434509.371000,,,299.998,300.000,41.651,3.197,0,0,300.000,300.000,13.530,9.670,1
3752434959.371000,,,300.002,300.000,41.646,3.198,0,0,300.000,300.000,13.470,9.670,1
3752435409.371000,,,299.995,300.003,41.649,3.196,0,0,300.000,300.000,13.530,9.670,1
3752435859.371000,,,300.002,300.000,41.650,3.198,0,0,300.000,300.000,13.550,9.670,1
3752436309.371000,,,299.999,300.002,41.650,3.198,0,0,300.000,300.000,13.510,9.670,1
3752436759.371000,,,300.000,300.000,41.649,3.198,0,0,300.000,300.000,13.550,9.680,1
3752437209.371000,,,299.998,299.999,41.648,3.197,0,0,300.000,300.000,13.530,9.620,1
3752437659.371000,,,300.001,300.000,41.644,3.196,0,0,300.000,300.000,13.490,9.670,1
3752438109.371000,,,299.999,300.000,41.648,3.196,0,0,300.000,300.000,13.510,9.670,1
3752438559.371000,,,300.003,299.999,41.644,3.196,0,0,300.000,300.000,13.510,9.680,1
3752439009.371000,,,299.999,300.000,41.643,3.197,0,0,300.000,300.000,13.510,9.680,1
3752439459.371000,,,300.002,300.000,41.643,3.196,0,0,300.000,300.000,13.530,9.650,1
3752439909.371000,,,300.001,300.001,41.644,3.196,0,0,300.000,300.000,13.460,9.670,1
3752440359.371000,,,300.004,299.999,41.643,3.195,0,0,300.000,300.000,13.580,9.670,1
3752440809.371000,,,300.000,299.999,41.639,3.197,0,0,300.000,300.000,13.490,9.670,1
3752441259.371000,,,299.997,299.998,41.641,3.197,0,0,300.000,300.000,13.530,9.670,1
3752441709.371000,,,300.004,300.000,41.643,3.197,0,0,300.000,300.000,13.490,9.670,1
3752442159.371000,,,299.997,300.000,41.643,3.199,0,0,300.000,300.000,13.530,9.670,1
3752442609.371000,,,300.000,299.998,41.643,3.196,0,0,300.000,300.000,13.510,9.670,1
3752443059.371000,,,300.000,300.000,41.644,3.197,0,0,300.000,300.000,13.510,9.670,1
3752443509.371000,,,299.995,300.000,41.644,3.198,0,0,300.000,300.000,13.580,9.670,1
3752443959.371000,,,300.008,300.001,41.647,3.198,0,0,300.000,300.000,13.440,9.670,1
3752444409.371000,,,299.991,300.001,41.651,3.197,0,0,300.000,300.000,13.600,9.670,1
3752444859.371000,,,300.005,299.999,41.649,3.199,0,0,300.000,300.000,13.470,9.670,1
3752445309.371000,,,299.998,300.000,41.651,3.198,0,0,300.000,300.000,13.510,9.670,1
3752445759.371000,,,300.001,300.000,41.651,3.200,0,0,300.000,300.000,13.570,9.670,1
3752446209.371000,,,299.999,300.001,41.654,3.198,0,0,300.000,300.000,13.510,9.650,1
3752446659.371000,,,300.002,300.000,41.653,3.199,0,0,300.000,300.000,13.490,9.700,1
3752447109.371000,,,299.994,299.998,41.655,3.196,0,0,300.000,300.000,13.640,9.670,1
3752447559.371000,,,300.005,300.000,41.656,3.196,0,0,300.000,300.000,13.440,9.670,1
3752448009.371000,,,299.996,300.001,41.657,3.197,0,0,300.000,300.000,13.620,9.680,1
3752448459.371000,,,300.000,300.000,41.657,3.198,0,0,300.000,300.000,13.470,9.670,1
3752448909.371000,,,300.001,300.000,41.658,3.197,0,0,300.000,300.000,13.580,9.620,1
3752449359.371000,,,300.000,300.003,41.651,3.197,0,0,300.000,300.000,13.460,9.650,1
3752449809.371000,,,300.003,300.000,41.652,3.197,0,0,300.000,300.000,13.620,9.670,1
3752450259.371000,,,300.000,299.999,41.654,3.198,0,0,300.000,300.000,13.380,9.700,1
3752450709.371000,,,300.003,299.998,41.656,3.198,0,0,300.000,300.000,13.620,9.670,1
3752451159.371000,,,299.997,300.000,41.658,3.197,0,0,300.000,300.000,13.490,9.700,1
3752451609.371000,,,300.000,299.999,41.662,3.198,0,0,300.000,300.000,13.580,9.670,1
3752452059.371000,,,300.002,300.001,41.665,3.198,0,0,300.000,300.000,13.490,9.650,1
3752452509.371000,,,299.999,299.999,41.664,3.197,0,0,300.000,300.000,13.580,9.680,1
3752452959.371000,,,299.999,300.001,41.663,3.199,0,0,300.000,300.000,13.490,9.700,1
3752453409.371000,,,299.998,300.001,41.661,3.200,0,0,300.000,300.000,13.620,9.670,1
3752453859.371000,,,299.999,300.001,41.663,3.199,0,0,300.000,300.000,13.470,9.670,1
3752454309.371000,,,300.000,300.001,41.667,3.199,0,0,300.000,300.000,13.550,9.680,1
3752454759.371000,,,299.999,300.002,41.673,3.199,0,0,300.000,300.000,13.470,9.670,1
3752455209.371000,,,300.001,300.000,41.679,3.199,0,0,300.000,300.000,13.530,9.670,1
3752455659.371000,,,299.995,299.998,41.676,3.198,0,0,300.000,300.000,13.600,9.670,1
3752456109.371000,,,300.002,299.999,41.677,3.199,0,0,300.000,300.000,13.510,9.720,1
3752456559.371000,,,299.998,300.000,41.680,3.199,0,0,300.000,300.000,13.530,9.680,1
3752457009.371000,,,300.001,300.001,41.681,3.199,0,0,300.000,300.000,13.530,9.670,1
3752457459.371000,,,300.001,299.999,41.682,3.199,0,0,300.000,300.000,13.530,9.670,1
3752457909.371000,,,300.002,300.000,41.682,3.198,0,0,300.000,300.000,13.470,9.680,1
3752458359.371000,,,299.998,300.001,41.687,3.199,0,0,300.000,300.000,13.510,9.680,1
3752458809.371000,,,300.000,300.000,41.690,3.199,0,0,300.000,300.000,13.550,9.680,1
3752459259.371000,,,300.000,299.999,41.695,3.198,0,0,300.000,300.000,13.460,9.670,1
3752459709.371000,,,299.998,300.002,41.697,3.200,0,0,300.000,300.000,13.620,9.650,1
3752460159.371000,,,299.998,299.998,41.701,3.198,0,0,300.000,300.000,13.490,9.670,1
3752460609.371000,,,300.000,300.000,41.708,3.199,0,0,300.000,300.000,13.550,9.680,1
3752461059.371000,,,300.000,299.998,41.710,3.199,0,0,300.000,300.000,13.470,9.700,1
3752461509.371000,,,299.999,299.999,41.712,3.199,0,0,300.000,300.000,13.510,9.670,1
3752461959.371000,,,299.999,299.999,41.713,3.199,0,0,300.000,300.000,13.510,9.700,1
3752462409.371000,,,300.000,300.002,41.711,3.198,0,0,300.000,300.000,13.490,9.670,1
3752462859.371000,,,300.002,300.001,41.715,3.199,0,0,300.000,300.000,13.510,9.670,1
3752463309.371000,,,299.997,299.998,41.712,3.197,0,0,300.000,300.000,13.490,9.680,1
3752463759.371000,,,299.997,299.999,41.716,3.198,0,0,300.000,300.000,13.580,9.680,1
3752464209.371000,,,300.003,300.001,41.713,3.201,0,0,300.000,300.000,13.420,9.670,1
3752464659.371000,,,300.000,300.000,41.712,3.197,0,0,300.000,300.000,13.550,9.700,1
3752465109.371000,,,299.998,299.999,41.716,3.199,0,0,300.000,300.000,13.550,9.670,1
3752465559.371000,,,299.998,300.000,41.720,3.199,0,0,300.000,300.000,13.530,9.680,1
3752466009.371000,,,299.999,299.999,41.723,3.199,0,0,300.000,300.000,13.530,9.680,1
3752466459.371000,,,300.005,300.000,41.729,3.198,0,0,300.000,300.000,13.510,9.670,1
3752466909.371000,,,299.993,299.998,41.730,3.199,0,0,300.000,300.000,13.470,9.670,1
3752467359.371000,,,300.007,299.998,41.730,3.198,0,0,300.000,300.000,13.530,9.680,1
3752467809.371000,,,299.994,299.997,41.731,3.200,0,0,300.000,300.000,13.470,9.670,1
3752468259.371000,,,300.005,300.000,41.734,3.199,0,0,300.000,300.000,13.550,9.680,1
3752468709.371000,,,299.996,300.000,41.736,3.198,0,0,300.000,300.000,13.460,9.680,1
3752469159.371000,,,300.002,299.998,41.735,3.197,0,0,300.000,300.000,13.550,9.700,1
3752469609.371000,,,300.001,300.000,41.729,3.197,0,0,300.000,300.000,13.440,9.700,1
3752470059.371000,,,299.999,299.999,41.728,3.198,0,0,300.000,300.000,13.550,9.670,1
3752470509.371000,,,300.000,299.998,41.724,3.198,0,0,300.000,300.000,13.470,9.670,1
3752470959.371000,,,299.995,299.999,41.720,3.196,0,0,300.000,300.000,13.620,9.700,1
3752471409.371000,,,300.006,300.002,41.722,3.200,0,0,300.000,300.000,13.470,9.670,1
3752471859.371000,,,299.996,299.999,41.722,3.199,0,0,300.000,300.000,13.510,9.670,1
3752472309.371000,,,300.003,299.999,41.716,3.198,0,0,300.000,300.000,13.530,9.670,1
3752472759.371000,,,299.999,300.001,41.710,3.196,0,0,300.000,300.000,13.490,9.680,1
3752473209.371000,,,300.000,300.000,41.708,3.196,0,0,300.000,300.000,13.530,9.670,1
3752473659.371000,,,299.998,300.000,41.707,3.193,0,0,300.000,300.000,13.470,9.670,1
3752474109.371000,,,300.003,300.000,41.699,3.194,0,0,300.000,300.000,13.490,9.670,1
3752474559.371000,,,299.998,300.000,41.693,3.196,0,0,300.000,300.000,13.510,9.650,1
3752475009.371000,,,300.003,300.002,41.688,3.196,0,0,300.000,300.000,13.530,9.650,1
3752475459.371000,,,299.997,300.002,41.683,3.195,0,0,300.000,300.000,13.490,9.640,1
3752475909.371000,,,300.002,299.999,41.679,3.196,0,0,300.000,300.000,13.490,9.670,1
3752476359.371000,,,299.999,299.999,41.678,3.195,0,0,300.000,300.000,13.530,9.670,1
3752476809.371000,,,300.079,0.000,41.733,3.197,0,0,300.000,300.000,14.360,0.000,4
3752477259.371000,,,299.934,0.000,41.632,3.195,0,0,300.000,300.000,17.340,0.000,4
3752477709.371000,,,299.956,300.005,41.862,3.195,0,0,300.000,300.000,15.610,1.220,4
3752477739.371000,,,300.005,300.007,41.913,3.195,0,0,300.000,300.000,16.030,1.220,4