File: log/20221123.dat
[Header]
; Displex Transport Data File (default extension .dat)
; Copyright 2016, Hechang LEI, hlei@ruc.edu.cn. All rights reserved.
BYAPP, Displex, 2.0
INFO, 9T mag, Release 2.0.
INFO, Channel 1, Temperature Sensor
INFO, Sample 1 Length (cm): 0.000000; Width (cm): 0.000000; Thickness (cm): 0.000000.

[Data]
Timestamp(s),Field(Oe),Field Status,TempA(K),TempB(K),TempC(K),TempD(K),Ramp1,Ramp2,Setpoint1,Setpoint2,Output1(%),Output2(%),Temp Status
3752033532.268000,,,299.996,0.000,52.603,4.194,0,0,300.000,300.000,39.550,0.000,4
3752043083.550000,,,300.066,300.122,53.414,4.201,0,0,300.000,300.000,42.160,2.700,4
3752043363.923000,,,299.740,299.928,53.613,4.335,0,0,300.000,300.000,36.880,26.610,4
3752043663.923000,,,299.791,299.997,54.605,4.423,0,0,300.000,300.000,36.250,25.760,4
3752043963.923000,,,299.832,299.998,55.502,4.458,0,0,300.000,300.000,36.220,26.130,1
3752044263.923000,,,299.867,299.998,56.161,4.483,0,0,300.000,300.000,36.250,26.350,1
3752044563.923000,,,299.903,299.997,56.656,4.499,0,0,300.000,300.000,36.020,26.510,1
3752044863.923000,,,299.929,300.001,57.049,4.513,0,0,300.000,300.000,35.900,26.670,1
3752045163.923000,,,299.942,299.999,57.381,4.531,0,0,300.000,300.000,35.900,26.850,1
3752045463.923000,,,299.960,300.001,57.670,4.543,0,0,300.000,300.000,35.780,26.910,1
3752045763.923000,,,299.969,300.000,57.919,4.552,0,0,300.000,300.000,35.600,26.960,1
3752046061.091000,,,294.494,293.843,58.123,4.557,1,1,2.000,2.000,14.680,14.230,3
3752046361.091000,,,279.457,278.941,58.300,4.562,1,1,2.000,2.000,11.390,10.270,3
3752046661.091000,,,264.429,264.059,58.463,4.574,1,1,2.000,2.000,8.530,7.300,3
3752046961.091000,,,248.825,249.172,58.605,4.577,1,1,2.000,2.000,11.770,4.670,3
3752047261.091000,,,234.081,234.311,58.710,4.569,1,1,2.000,2.000,7.330,2.480,3
3752047561.091000,,,219.309,219.447,58.783,4.577,1,1,2.000,2.000,3.560,0.460,3
3752047861.091000,,,204.609,205.365,58.839,4.578,1,1,2.000,2.000,0.000,0.000,3
3752048161.091000,,,190.983,192.884,58.871,4.589,1,1,2.000,2.000,0.000,0.000,3
3752048461.091000,,,179.003,181.543,58.875,4.586,1,1,2.000,2.000,0.000,0.000,3
3752048761.091000,,,168.220,171.085,58.851,4.584,1,1,2.000,2.000,0.000,0.000,3
3752049061.091000,,,158.316,161.367,58.800,4.586,1,1,2.000,2.000,0.000,0.000,3
3752049361.091000,,,149.091,152.163,58.722,4.577,1,1,2.000,2.000,0.000,0.000,3
3752049661.091000,,,140.372,143.419,58.621,4.578,1,1,2.000,2.000,0.000,0.000,3
3752049961.091000,,,132.067,135.067,58.502,4.582,1,1,2.000,2.000,0.000,0.000,3
3752050261.091000,,,124.082,127.054,58.362,4.577,1,1,2.000,2.000,0.000,0.000,3
3752050561.091000,,,116.361,119.355,58.191,4.571,1,1,2.000,2.000,0.000,0.000,3
3752050861.091000,,,108.822,111.801,57.990,4.562,1,1,2.000,2.000,0.000,0.000,3
3752051161.091000,,,101.397,104.359,57.759,4.554,1,1,2.000,2.000,0.000,0.000,3
3752051461.091000,,,94.059,97.006,57.505,4.548,1,1,2.000,2.000,0.000,0.000,3
3752051761.091000,,,86.663,89.542,57.411,5.512,1,1,2.000,2.000,0.000,0.000,3
3752052061.091000,,,77.988,80.936,58.241,5.834,0,0,2.000,2.000,0.000,0.000,4
3752052361.091000,,,67.978,71.077,58.942,5.936,0,0,2.000,2.000,0.000,0.000,4
3752052661.091000,,,56.545,59.713,59.406,5.988,0,0,2.000,2.000,0.000,0.000,4
3752052961.091000,,,42.591,45.526,59.672,6.019,0,0,2.000,2.000,0.000,0.000,4
3752053261.091000,,,22.489,22.662,59.607,5.024,0,0,2.000,2.000,0.000,0.000,4
3752053561.091000,,,6.549,5.926,58.689,4.853,0,0,2.000,2.000,0.000,0.000,4
3752053861.091000,,,5.346,4.841,57.570,4.753,0,0,2.000,2.000,0.000,0.000,4
3752054161.091000,,,5.102,4.641,56.461,4.677,0,0,2.000,2.000,0.000,0.000,4
3752054461.091000,,,4.869,4.482,55.525,4.628,0,0,2.000,2.000,0.000,0.000,4
3752054761.091000,,,4.729,4.379,54.744,4.588,0,0,2.000,2.000,0.000,0.000,4
3752055061.091000,,,4.632,4.298,54.087,4.557,0,0,2.000,2.000,0.000,0.000,4
3752055361.091000,,,2.452,2.066,53.153,3.981,0,0,2.000,2.000,0.000,0.000,4
3752055661.091000,,,2.298,2.001,51.330,3.748,0,0,2.000,2.000,0.000,0.000,4
3752055961.091000,,,2.046,2.001,49.313,3.549,0,0,2.000,2.000,0.000,0.020,1
3752056261.091000,,,1.999,2.000,47.020,2.989,0,0,2.000,2.000,0.210,0.020,1
3752056561.091000,,,6.323,6.267,44.655,3.294,1,1,300.000,300.000,0.140,0.620,2
3752056861.091000,,,21.321,21.189,42.752,3.455,1,1,300.000,300.000,1.430,1.280,2
3752057161.091000,,,36.058,36.042,42.019,3.449,1,1,300.000,300.000,4.770,3.100,2
3752057461.091000,,,50.927,50.918,41.473,3.443,1,1,300.000,300.000,9.090,5.680,2
3752057761.091000,,,65.808,65.788,41.065,3.439,1,1,300.000,300.000,13.490,8.450,2
3752058061.091000,,,80.671,80.657,40.752,3.437,1,1,300.000,300.000,17.590,11.120,2
3752058361.091000,,,95.528,95.504,40.502,3.431,1,1,300.000,300.000,21.360,13.940,2
3752058661.091000,,,110.381,110.348,40.295,3.430,1,1,300.000,300.000,24.640,16.530,2
3752058961.091000,,,125.235,125.228,40.121,3.427,1,1,300.000,300.000,27.950,18.700,2
3752059261.091000,,,140.098,140.086,39.979,3.423,1,1,300.000,300.000,30.740,20.910,2
3752059561.091000,,,154.948,154.934,39.861,3.414,1,1,300.000,300.000,33.360,23.150,2
3752059861.091000,,,169.805,169.797,39.755,3.416,1,1,300.000,300.000,35.810,25.400,2
3752060161.091000,,,184.674,184.647,39.681,3.413,1,1,300.000,300.000,38.410,27.480,2
3752060461.091000,,,199.539,199.536,39.635,3.412,1,1,300.000,300.000,40.910,29.160,2
3752060761.091000,,,214.387,214.355,39.608,3.409,1,1,300.000,300.000,42.870,31.440,2
3752061061.091000,,,229.241,229.217,39.606,3.406,1,1,300.000,300.000,45.240,33.240,2
3752061361.091000,,,244.099,244.076,39.628,3.405,1,1,300.000,300.000,47.200,35.050,2
3752061661.091000,,,258.954,258.810,39.671,3.407,1,1,300.000,300.000,49.330,36.040,2
3752061961.091000,,,273.739,273.717,39.739,3.405,1,1,300.000,300.000,51.090,38.510,2
3752062261.091000,,,288.984,288.508,39.830,3.403,1,1,300.000,300.000,51.630,40.130,2
3752062561.091000,,,299.758,300.003,39.938,3.404,0,0,300.000,300.000,36.100,31.180,4
3752062861.091000,,,299.759,300.016,40.049,3.403,0,0,300.000,300.000,33.930,27.370,4
3752063161.091000,,,299.779,300.011,40.169,3.401,0,0,300.000,300.000,32.900,25.740,1
3752063461.091000,,,299.806,300.007,40.301,3.401,0,0,300.000,300.000,31.970,24.310,1
3752063761.091000,,,299.840,300.007,40.438,3.403,0,0,300.000,300.000,30.910,23.450,1
3752064061.091000,,,299.866,300.019,40.575,3.404,0,0,300.000,300.000,29.920,22.730,4
3752064361.091000,,,299.888,300.005,40.718,3.403,0,0,300.000,300.000,28.950,21.580,1
3752064661.091000,,,299.907,300.002,40.856,3.406,0,0,300.000,300.000,28.130,20.990,1
3752064961.091000,,,299.921,300.002,40.996,3.408,0,0,300.000,300.000,27.350,20.580,1
3752065261.091000,,,299.936,300.001,41.135,3.410,0,0,300.000,300.000,26.700,20.020,1
3752065561.091000,,,299.943,300.003,41.270,3.408,0,0,300.000,300.000,26.090,19.400,1
3752065861.091000,,,299.950,299.995,41.403,3.410,0,0,300.000,300.000,25.530,18.900,1
3752066161.091000,,,299.959,300.001,41.535,3.410,0,0,300.000,300.000,24.960,18.390,1
3752066461.091000,,,299.967,300.002,41.657,3.412,0,0,300.000,300.000,24.470,17.970,1
3752066761.091000,,,299.975,300.001,41.781,3.414,0,0,300.000,300.000,24.030,17.620,1
3752067061.091000,,,299.982,300.001,41.902,3.414,0,0,300.000,300.000,23.540,17.210,1
3752067361.091000,,,299.986,300.000,42.022,3.416,0,0,300.000,300.000,23.180,16.870,1
3752067661.091000,,,299.986,300.001,42.137,3.415,0,0,300.000,300.000,22.870,16.570,1
3752067961.091000,,,299.988,300.000,42.249,3.415,0,0,300.000,300.000,22.520,16.320,1
3752068261.091000,,,299.991,300.001,42.356,3.416,0,0,300.000,300.000,22.240,16.070,1
3752068561.091000,,,299.991,300.000,42.456,3.416,0,0,300.000,300.000,21.960,15.840,1
3752068861.091000,,,299.991,300.001,42.551,3.420,0,0,300.000,300.000,21.680,15.700,1
3752069161.091000,,,299.991,300.002,42.641,3.420,0,0,300.000,300.000,21.400,15.570,1
3752069461.091000,,,299.996,300.000,42.730,3.418,0,0,300.000,300.000,21.150,15.430,1
3752069761.091000,,,299.996,300.000,42.810,3.425,0,0,300.000,300.000,21.010,15.230,1
3752070061.091000,,,299.995,300.002,42.895,3.420,0,0,300.000,300.000,20.830,15.130,1
3752070361.091000,,,299.996,299.997,42.979,3.424,0,0,300.000,300.000,20.670,15.000,1
3752070661.091000,,,299.997,300.000,43.057,3.422,0,0,300.000,300.000,20.470,14.860,1
3752070961.091000,,,300.000,300.002,43.129,3.422,0,0,300.000,300.000,20.470,14.760,1
3752071261.091000,,,299.999,300.000,43.197,3.425,0,0,300.000,300.000,20.360,14.650,1
3752071561.091000,,,300.000,300.000,43.264,3.425,0,0,300.000,300.000,20.230,14.530,1
3752071861.091000,,,300.000,300.001,43.328,3.427,0,0,300.000,300.000,20.090,14.490,1
3752072161.091000,,,300.000,300.001,43.386,3.428,0,0,300.000,300.000,20.000,14.330,1
3752072461.091000,,,300.000,300.000,43.437,3.428,0,0,300.000,300.000,19.870,14.310,1
3752072761.091000,,,299.998,300.000,43.486,3.430,0,0,300.000,300.000,19.780,14.210,1
3752073061.091000,,,299.998,299.997,43.537,3.430,0,0,300.000,300.000,19.740,14.190,1
3752073361.091000,,,299.997,300.002,43.586,3.427,0,0,300.000,300.000,19.740,14.100,1
3752073661.091000,,,299.997,299.998,43.634,3.430,0,0,300.000,300.000,19.630,14.080,1
3752073961.091000,,,299.998,299.997,43.682,3.430,0,0,300.000,300.000,19.630,14.020,1
3752074261.091000,,,299.998,300.000,43.726,3.431,0,0,300.000,300.000,19.580,14.000,1
3752074561.091000,,,299.996,299.999,43.766,3.434,0,0,300.000,300.000,19.520,14.000,1
3752074861.091000,,,299.997,299.999,43.808,3.431,0,0,300.000,300.000,19.430,13.940,1
3752075161.091000,,,299.997,299.999,43.851,3.432,0,0,300.000,300.000,19.360,13.880,1
3752075461.091000,,,300.000,300.001,43.888,3.433,0,0,300.000,300.000,19.320,13.860,1
3752075761.091000,,,300.000,300.000,43.923,3.434,0,0,300.000,300.000,19.280,13.880,1
3752076061.091000,,,300.000,300.001,43.952,3.436,0,0,300.000,300.000,19.250,13.810,1
3752076361.091000,,,300.001,300.000,43.982,3.431,0,0,300.000,300.000,19.080,13.790,1
3752076661.091000,,,299.999,299.998,44.012,3.434,0,0,300.000,300.000,19.190,13.790,1
3752076961.091000,,,300.001,300.000,44.040,3.432,0,0,300.000,300.000,19.150,13.770,1
3752077261.091000,,,299.996,299.998,44.070,3.434,0,0,300.000,300.000,19.150,13.770,1
3752077561.091000,,,299.996,299.998,44.098,3.431,0,0,300.000,300.000,19.100,13.730,1
3752077861.091000,,,300.002,300.000,44.132,3.434,0,0,300.000,300.000,19.060,13.750,1
3752078161.091000,,,300.002,300.003,44.166,3.433,0,0,300.000,300.000,18.950,13.690,1
3752078461.091000,,,299.999,299.999,44.192,3.432,0,0,300.000,300.000,18.970,13.650,1
3752078761.091000,,,300.002,300.002,44.215,3.435,0,0,300.000,300.000,18.950,13.650,1
3752079061.091000,,,299.997,300.000,44.233,3.437,0,0,300.000,300.000,18.930,13.650,1
3752079361.091000,,,299.998,300.001,44.250,3.436,0,0,300.000,300.000,18.930,13.650,1
3752079661.091000,,,299.996,300.000,44.264,3.433,0,0,300.000,300.000,18.990,13.590,1
3752079961.091000,,,299.995,300.001,44.277,3.437,0,0,300.000,300.000,18.890,13.590,1
3752080261.091000,,,299.997,300.000,44.292,3.437,0,0,300.000,300.000,18.890,13.590,1
3752080561.091000,,,299.995,299.998,44.303,3.436,0,0,300.000,300.000,18.950,13.590,1
3752080861.091000,,,299.997,300.000,44.315,3.435,0,0,300.000,300.000,18.910,13.580,1
3752081161.091000,,,300.000,299.999,44.329,3.438,0,0,300.000,300.000,18.840,13.560,1
3752081461.091000,,,300.000,299.998,44.340,3.436,0,0,300.000,300.000,18.860,13.560,1
3752081761.091000,,,299.999,300.001,44.351,3.436,0,0,300.000,300.000,18.860,13.560,1
3752082061.091000,,,300.004,300.000,44.359,3.434,0,0,300.000,300.000,18.780,13.540,1
3752082361.091000,,,300.003,299.999,44.365,3.437,0,0,300.000,300.000,18.820,13.520,1
3752082661.091000,,,300.002,299.999,44.371,3.438,0,0,300.000,300.000,18.860,13.520,1
3752082961.091000,,,300.000,300.000,44.378,3.435,0,0,300.000,300.000,18.890,13.540,1
3752083261.091000,,,300.000,300.000,44.384,3.436,0,0,300.000,300.000,18.910,13.520,1
3752083561.091000,,,300.001,300.001,44.390,3.434,0,0,300.000,300.000,18.820,13.480,1
3752083861.091000,,,300.002,300.001,44.397,3.434,0,0,300.000,300.000,18.860,13.540,1
3752084161.091000,,,300.001,300.000,44.403,3.433,0,0,300.000,300.000,18.800,13.500,1
3752084461.091000,,,300.004,299.999,44.410,3.435,0,0,300.000,300.000,18.780,13.520,1
3752084761.091000,,,300.004,300.001,44.416,3.434,0,0,300.000,300.000,18.800,13.520,1
3752085061.091000,,,300.002,299.999,44.420,3.434,0,0,300.000,300.000,18.820,13.480,1
3752085361.091000,,,300.002,299.998,44.425,3.434,0,0,300.000,300.000,18.820,13.460,1
3752085661.091000,,,300.002,300.000,44.430,3.432,0,0,300.000,300.000,18.840,13.460,1
3752085961.091000,,,299.999,300.001,44.431,3.433,0,0,300.000,300.000,18.840,13.480,1
3752086261.091000,,,300.000,300.001,44.435,3.433,0,0,300.000,300.000,18.860,13.480,1
3752086561.091000,,,300.002,299.999,44.435,3.434,0,0,300.000,300.000,18.840,13.440,1
3752086861.091000,,,300.003,299.998,44.437,3.435,0,0,300.000,300.000,18.760,13.460,1
3752087161.091000,,,300.000,300.003,44.441,3.435,0,0,300.000,300.000,18.760,13.440,1
3752087461.091000,,,299.999,300.001,44.443,3.434,0,0,300.000,300.000,18.780,13.460,1
3752087761.091000,,,300.000,299.998,44.446,3.433,0,0,300.000,300.000,18.780,13.480,1
3752088061.091000,,,299.999,299.999,44.447,3.435,0,0,300.000,300.000,18.840,13.500,1
3752088361.091000,,,299.996,299.998,44.447,3.435,0,0,300.000,300.000,18.840,13.460,1
3752088661.091000,,,299.998,300.000,44.451,3.434,0,0,300.000,300.000,18.840,13.460,1
3752088961.091000,,,299.998,300.003,44.454,3.432,0,0,300.000,300.000,18.840,13.440,1
3752089261.091000,,,300.004,299.999,44.456,3.433,0,0,300.000,300.000,18.760,13.480,1
3752089561.091000,,,299.999,299.999,44.457,3.432,0,0,300.000,300.000,18.820,13.480,1
3752089861.091000,,,300.002,299.998,44.464,3.436,0,0,300.000,300.000,18.780,13.460,1
3752090161.091000,,,299.999,300.000,44.469,3.434,0,0,300.000,300.000,18.840,13.440,1
3752090461.091000,,,300.001,300.000,44.472,3.435,0,0,300.000,300.000,18.860,13.480,1
3752090761.091000,,,299.999,300.000,44.475,3.433,0,0,300.000,300.000,18.840,13.440,1
3752091061.091000,,,299.999,299.997,44.475,3.434,0,0,300.000,300.000,18.760,13.460,1
3752091361.091000,,,300.001,299.999,44.477,3.430,0,0,300.000,300.000,18.780,13.480,1
3752091661.091000,,,299.999,299.998,44.479,3.432,0,0,300.000,300.000,18.860,13.480,1
3752091961.091000,,,300.002,299.998,44.477,3.433,0,0,300.000,300.000,18.800,13.480,1
3752092261.091000,,,300.000,300.001,44.478,3.432,0,0,300.000,300.000,18.800,13.440,1
3752092561.091000,,,299.999,300.000,44.480,3.433,0,0,300.000,300.000,18.760,13.440,1
3752092861.091000,,,300.001,299.998,44.480,3.433,0,0,300.000,300.000,18.820,13.440,1
3752093161.091000,,,300.005,299.999,44.480,3.433,0,0,300.000,300.000,18.760,13.460,1
3752093461.091000,,,300.006,300.001,44.481,3.433,0,0,300.000,300.000,18.760,13.440,1
3752093761.091000,,,300.005,300.001,44.479,3.436,0,0,300.000,300.000,18.710,13.420,1
3752094061.091000,,,300.003,300.000,44.476,3.436,0,0,300.000,300.000,18.760,13.460,1
3752094361.091000,,,300.003,300.001,44.475,3.438,0,0,300.000,300.000,18.760,13.440,1
3752094661.091000,,,300.003,299.998,44.476,3.436,0,0,300.000,300.000,18.610,13.440,1
3752094961.091000,,,300.007,300.000,44.475,3.439,0,0,300.000,300.000,18.670,13.460,1
3752095261.091000,,,300.002,299.999,44.475,3.439,0,0,300.000,300.000,18.780,13.480,1
3752095561.091000,,,300.005,299.998,44.474,3.439,0,0,300.000,300.000,18.760,13.440,1
3752095861.091000,,,300.006,300.002,44.475,3.439,0,0,300.000,300.000,18.690,13.460,1
3752096161.091000,,,300.002,300.000,44.476,3.440,0,0,300.000,300.000,18.710,13.440,1
3752096461.091000,,,299.998,299.999,44.477,3.440,0,0,300.000,300.000,18.780,13.460,1
3752096761.091000,,,299.998,300.000,44.479,3.436,0,0,300.000,300.000,18.840,13.420,1
3752097061.091000,,,300.002,300.001,44.484,3.435,0,0,300.000,300.000,18.630,13.460,1
3752097361.091000,,,299.999,299.998,44.487,3.434,0,0,300.000,300.000,18.690,13.440,1
3752097661.091000,,,300.001,299.998,44.488,3.433,0,0,300.000,300.000,18.740,13.420,1
3752097961.091000,,,299.998,300.002,44.488,3.438,0,0,300.000,300.000,18.690,13.420,1
3752098261.091000,,,299.999,299.999,44.489,3.437,0,0,300.000,300.000,18.740,13.460,1
3752098561.091000,,,300.001,299.999,44.495,3.436,0,0,300.000,300.000,18.710,13.460,1
3752098861.091000,,,299.998,300.001,44.497,3.431,0,0,300.000,300.000,18.740,13.460,1
3752099161.091000,,,299.998,299.997,44.498,3.434,0,0,300.000,300.000,18.760,13.440,1
3752099461.091000,,,300.001,300.001,44.501,3.437,0,0,300.000,300.000,18.670,13.420,1
3752099761.091000,,,300.000,299.999,44.503,3.439,0,0,300.000,300.000,18.740,13.440,1
3752100061.091000,,,299.999,300.000,44.505,3.439,0,0,300.000,300.000,18.670,13.440,1
3752100361.091000,,,299.997,300.000,44.509,3.436,0,0,300.000,300.000,18.800,13.440,1
3752100661.091000,,,299.999,299.998,44.510,3.437,0,0,300.000,300.000,18.760,13.440,1
3752100961.091000,,,299.996,300.001,44.505,3.435,0,0,300.000,300.000,18.820,13.460,1
3752101261.091000,,,299.998,300.002,44.500,3.436,0,0,300.000,300.000,18.760,13.440,1
3752101561.091000,,,300.000,300.001,44.495,3.437,0,0,300.000,300.000,18.780,13.440,1
3752101861.091000,,,299.998,300.000,44.491,3.435,0,0,300.000,300.000,18.780,13.440,1
3752102161.091000,,,299.999,300.000,44.491,3.436,0,0,300.000,300.000,18.740,13.440,1
3752102461.091000,,,299.999,299.999,44.484,3.436,0,0,300.000,300.000,18.760,13.420,1
3752102761.091000,,,300.000,299.998,44.482,3.435,0,0,300.000,300.000,18.760,13.420,1
3752103061.091000,,,300.003,300.000,44.484,3.436,0,0,300.000,300.000,18.690,13.420,1
3752103361.091000,,,300.001,300.000,44.486,3.437,0,0,300.000,300.000,18.690,13.440,1
3752103661.091000,,,299.998,300.000,44.487,3.433,0,0,300.000,300.000,18.670,13.440,1
3752103961.091000,,,299.998,299.998,44.489,3.432,0,0,300.000,300.000,18.670,13.420,1
3752104261.091000,,,300.002,299.999,44.491,3.434,0,0,300.000,300.000,18.630,13.420,1
3752104561.091000,,,300.004,300.000,44.491,3.436,0,0,300.000,300.000,18.690,13.420,1
3752104861.091000,,,300.003,299.998,44.491,3.437,0,0,300.000,300.000,18.650,13.440,1
3752105161.091000,,,300.001,299.999,44.487,3.437,0,0,300.000,300.000,18.760,13.440,1
3752105461.091000,,,300.002,300.001,44.484,3.434,0,0,300.000,300.000,18.800,13.440,1
3752105761.091000,,,300.002,299.999,44.483,3.434,0,0,300.000,300.000,18.760,13.420,1
3752106061.091000,,,300.001,300.000,44.480,3.435,0,0,300.000,300.000,18.740,13.440,1
3752106361.091000,,,289.184,289.333,44.475,3.433,1,1,2.000,2.000,0.000,0.000,3
3752106661.091000,,,275.909,277.090,44.455,3.430,1,1,2.000,2.000,0.000,0.000,3
3752106961.091000,,,265.378,267.007,44.428,3.431,1,1,2.000,2.000,0.000,0.000,3
3752107261.091000,,,256.743,258.500,44.396,3.429,1,1,2.000,2.000,0.000,0.000,3
3752107561.091000,,,249.355,251.178,44.357,3.429,1,1,2.000,2.000,0.000,0.000,3
3752107861.091000,,,242.909,244.739,44.312,3.425,1,1,2.000,2.000,0.000,0.000,3
3752108161.091000,,,237.160,238.948,44.269,3.421,1,1,2.000,2.000,0.000,0.000,3
3752108461.091000,,,231.928,233.691,44.227,3.420,1,1,2.000,2.000,0.000,0.000,3
3752108761.091000,,,227.077,228.812,44.173,3.421,1,1,2.000,2.000,0.000,0.000,3
3752109061.091000,,,222.535,224.245,44.108,3.423,1,1,2.000,2.000,0.000,0.000,3
3752109361.091000,,,218.230,219.915,44.041,3.424,1,1,2.000,2.000,0.000,0.000,3
3752109661.091000,,,214.105,215.777,43.969,3.419,1,1,2.000,2.000,0.000,0.000,3
3752109961.091000,,,210.133,211.805,43.893,3.415,1,1,2.000,2.000,0.000,0.000,3
3752110261.091000,,,206.298,207.973,43.816,3.417,1,1,2.000,2.000,0.000,0.000,3
3752110561.091000,,,202.567,204.244,43.741,3.413,1,1,2.000,2.000,0.000,0.000,3
3752110861.091000,,,198.939,200.618,43.663,3.411,1,1,2.000,2.000,0.000,0.000,3
3752111161.091000,,,195.394,197.076,43.576,3.412,1,1,2.000,2.000,0.000,0.000,3
3752111461.091000,,,191.926,193.619,43.486,3.410,1,1,2.000,2.000,0.000,0.000,3
3752111761.091000,,,188.279,189.990,45.736,4.640,1,1,2.000,2.000,0.000,0.000,3
3752112061.091000,,,182.463,184.523,49.361,4.738,1,1,2.000,2.000,0.000,0.000,3
3752112361.091000,,,174.915,177.538,51.527,4.812,0,0,2.000,2.000,0.000,0.000,4
3752112661.091000,,,166.403,169.366,53.072,4.891,0,0,2.000,2.000,0.000,0.000,4
3752112961.091000,,,157.404,160.508,54.255,4.959,0,0,2.000,2.000,0.000,0.000,4
3752113261.091000,,,148.247,151.399,55.171,5.011,0,0,2.000,2.000,0.000,0.000,4
3752113561.091000,,,139.077,142.213,55.882,5.058,0,0,2.000,2.000,0.000,0.000,4
3752113861.091000,,,130.016,133.124,56.434,5.089,0,0,2.000,2.000,0.000,0.000,4
3752114161.091000,,,121.097,124.223,56.853,5.122,0,0,2.000,2.000,0.000,0.000,4
3752114461.091000,,,112.310,115.457,57.166,5.145,0,0,2.000,2.000,0.000,0.000,4
3752114761.091000,,,103.648,106.779,57.385,5.161,0,0,2.000,2.000,0.000,0.000,4
3752115061.091000,,,95.023,98.137,57.520,5.174,0,0,2.000,2.000,0.000,0.000,4
3752115361.091000,,,86.363,89.490,57.583,5.184,0,0,2.000,2.000,0.000,0.000,4
3752115661.091000,,,77.532,80.713,57.586,5.187,0,0,2.000,2.000,0.000,0.000,4
3752115961.091000,,,68.338,71.579,57.536,5.191,0,0,2.000,2.000,0.000,0.000,4
3752116261.091000,,,58.450,61.644,57.427,5.188,0,0,2.000,2.000,0.000,0.000,4
3752116561.091000,,,46.996,50.026,57.254,5.181,0,0,2.000,2.000,0.000,0.000,4
3752116861.091000,,,30.996,32.764,57.014,5.175,0,0,2.000,2.000,0.000,0.000,4
3752117161.091000,,,7.832,7.164,56.652,5.139,0,0,2.000,2.000,0.000,0.000,4
3752117461.091000,,,5.942,5.424,56.082,5.083,0,0,2.000,2.000,0.000,0.000,4
3752117761.091000,,,5.613,5.182,55.392,4.998,0,0,2.000,2.000,0.000,0.000,4
3752118061.091000,,,5.420,5.023,54.808,4.954,0,0,2.000,2.000,0.000,0.000,4
3752118361.091000,,,5.274,4.954,54.354,4.930,0,0,2.000,2.000,0.000,0.000,4
3752118661.091000,,,5.176,4.858,53.997,4.907,0,0,2.000,2.000,0.000,0.000,4
3752118961.091000,,,5.088,4.799,53.690,4.890,0,0,2.000,2.000,0.000,0.000,4
3752119261.091000,,,5.018,4.756,53.426,4.870,0,0,2.000,2.000,0.000,0.000,4
3752119561.091000,,,4.959,4.723,53.210,4.864,0,0,2.000,2.000,0.000,0.000,4
3752119861.091000,,,4.917,4.682,53.034,4.850,0,0,2.000,2.000,0.000,0.000,4
3752120161.091000,,,3.511,3.266,52.917,4.056,0,0,2.000,2.000,0.000,0.000,4
3752120461.091000,,,2.058,2.000,50.816,3.221,0,0,2.000,2.000,0.000,0.020,4
3752120761.091000,,,10.036,10.028,47.648,3.216,1,1,300.000,300.000,0.380,0.510,2
3752121061.091000,,,24.922,24.926,45.060,3.209,1,1,300.000,300.000,2.010,1.410,2
3752121361.091000,,,39.809,39.786,43.151,3.208,1,1,300.000,300.000,5.400,3.430,2
3752121661.091000,,,54.683,54.658,41.795,3.201,1,1,300.000,300.000,9.720,6.120,2
3752121961.091000,,,69.546,69.523,40.857,3.200,1,1,300.000,300.000,14.120,8.940,2
3752122261.091000,,,84.394,84.384,40.209,3.198,1,1,300.000,300.000,18.120,11.500,2
3752122561.091000,,,99.269,99.246,39.751,3.198,1,1,300.000,300.000,21.610,14.000,2
3752122861.091000,,,114.121,114.104,39.417,3.195,1,1,300.000,300.000,24.940,16.440,2
3752123161.091000,,,128.976,128.968,39.162,3.193,1,1,300.000,300.000,27.970,18.900,2
3752123461.091000,,,143.837,143.809,38.961,3.191,1,1,300.000,300.000,30.690,21.100,2
3752123761.091000,,,158.703,158.659,38.801,3.187,1,1,300.000,300.000,33.100,23.330,2
3752124061.091000,,,173.586,173.533,38.672,3.189,1,1,300.000,300.000,35.690,25.140,2
3752124361.091000,,,188.397,188.384,38.552,3.182,1,1,300.000,300.000,37.400,27.310,2
3752124661.091000,,,203.237,203.236,38.465,3.179,1,1,300.000,300.000,40.310,29.050,2
3752124961.091000,,,218.098,218.095,38.404,3.177,1,1,300.000,300.000,42.350,30.980,2
3752125261.091000,,,232.977,232.946,38.367,3.175,1,1,300.000,300.000,44.610,32.790,2
3752125561.091000,,,247.827,247.806,38.355,3.176,1,1,300.000,300.000,46.550,34.440,2
3752125861.091000,,,262.668,262.635,38.366,3.173,1,1,300.000,300.000,48.430,35.950,2
3752126161.091000,,,277.463,277.438,38.401,3.174,1,1,300.000,300.000,50.320,37.610,2
3752126461.091000,,,292.183,292.219,38.453,3.173,1,1,300.000,300.000,58.400,39.090,2
3752126761.091000,,,300.332,300.033,38.521,3.171,0,0,300.000,300.000,30.300,27.830,4
3752127061.091000,,,300.248,300.012,38.589,3.172,0,0,300.000,300.000,28.660,25.870,4
3752127361.091000,,,300.183,300.026,38.668,3.172,0,0,300.000,300.000,27.760,24.470,4
3752127661.091000,,,300.145,300.013,38.756,3.171,0,0,300.000,300.000,26.800,22.900,4
3752127961.091000,,,300.105,300.000,38.850,3.172,0,0,300.000,300.000,26.060,21.990,4
3752128261.091000,,,300.079,300.007,38.950,3.174,0,0,300.000,300.000,25.360,21.030,1
3752128561.091000,,,300.060,300.005,39.051,3.175,0,0,300.000,300.000,24.590,20.050,1
3752128861.091000,,,300.041,300.005,39.151,3.175,0,0,300.000,300.000,24.030,19.150,1
3752129161.091000,,,300.031,300.004,39.249,3.177,0,0,300.000,300.000,23.400,18.370,1
3752129461.091000,,,300.019,300.006,39.350,3.178,0,0,300.000,300.000,22.950,17.680,1
3752129761.091000,,,300.012,300.003,39.451,3.179,0,0,300.000,300.000,22.430,17.060,1
3752130061.091000,,,300.006,300.004,39.540,3.180,0,0,300.000,300.000,21.860,16.440,1
3752130361.091000,,,300.005,300.001,39.627,3.180,0,0,300.000,300.000,21.380,15.880,1
3752130661.091000,,,300.004,300.001,39.714,3.181,0,0,300.000,300.000,20.880,15.470,1
3752130961.091000,,,300.003,300.001,39.801,3.183,0,0,300.000,300.000,20.470,15.050,1
3752131261.091000,,,300.002,300.002,39.889,3.181,0,0,300.000,300.000,20.070,14.670,1
3752131561.091000,,,300.003,300.003,39.979,3.183,0,0,300.000,300.000,19.690,14.330,1
3752131861.091000,,,300.007,300.002,40.068,3.184,0,0,300.000,300.000,19.300,14.000,1
3752132161.091000,,,300.005,300.003,40.156,3.184,0,0,300.000,300.000,19.020,13.820,1
3752132461.091000,,,300.002,300.002,40.234,3.186,0,0,300.000,300.000,18.760,13.580,1
3752132761.091000,,,299.998,300.000,40.312,3.187,0,0,300.000,300.000,18.500,13.390,1
3752133061.091000,,,299.999,300.000,40.382,3.186,0,0,300.000,300.000,18.220,13.180,1
3752133361.091000,,,300.002,300.001,40.450,3.188,0,0,300.000,300.000,17.890,12.950,1
3752133661.091000,,,300.005,300.003,40.518,3.190,0,0,300.000,300.000,17.640,12.770,1
3752133961.091000,,,300.004,300.001,40.581,3.187,0,0,300.000,300.000,17.490,12.660,1
3752134261.091000,,,300.005,300.002,40.649,3.186,0,0,300.000,300.000,17.280,12.450,1
3752134561.091000,,,300.003,300.001,40.718,3.191,0,0,300.000,300.000,17.120,12.330,1
3752134861.091000,,,300.003,300.003,40.790,3.189,0,0,300.000,300.000,16.910,12.220,1
3752135161.091000,,,300.004,300.001,40.856,3.191,0,0,300.000,300.000,16.770,12.110,1
3752135461.091000,,,300.004,300.000,40.918,3.192,0,0,300.000,300.000,16.630,11.980,1
3752135761.091000,,,300.000,299.999,40.983,3.192,0,0,300.000,300.000,16.550,11.910,1
3752136061.091000,,,300.002,300.002,41.038,3.197,0,0,300.000,300.000,16.410,11.770,1
3752136361.091000,,,300.000,299.998,41.090,3.192,0,0,300.000,300.000,16.310,11.720,1
3752136661.091000,,,299.999,300.002,41.140,3.192,0,0,300.000,300.000,16.190,11.610,1
3752136961.091000,,,300.000,300.002,41.191,3.195,0,0,300.000,300.000,16.050,11.540,1
3752137261.091000,,,300.000,300.001,41.239,3.192,0,0,300.000,300.000,15.890,11.420,1
3752137561.091000,,,299.998,300.000,41.285,3.194,0,0,300.000,300.000,15.870,11.380,1
3752137861.091000,,,299.998,300.001,41.331,3.196,0,0,300.000,300.000,15.730,11.290,1
3752138161.091000,,,299.998,299.999,41.371,3.196,0,0,300.000,300.000,15.690,11.260,1
3752138461.091000,,,300.000,299.999,41.414,3.199,0,0,300.000,300.000,15.610,11.170,1
3752138761.091000,,,300.000,299.999,41.453,3.205,0,0,300.000,300.000,15.550,11.120,1
3752139061.091000,,,300.005,299.999,41.491,3.201,0,0,300.000,300.000,15.480,11.070,1
3752139361.091000,,,300.004,300.003,41.525,3.199,0,0,300.000,300.000,15.400,11.000,1
3752139661.091000,,,299.999,300.000,41.557,3.197,0,0,300.000,300.000,15.360,10.970,1
3752139961.091000,,,299.999,299.998,41.587,3.207,0,0,300.000,300.000,15.300,10.930,1
3752140261.091000,,,299.998,300.001,41.620,3.197,0,0,300.000,300.000,15.180,10.880,1
3752140561.091000,,,299.998,300.002,41.644,3.205,0,0,300.000,300.000,15.220,10.830,1
3752140861.091000,,,299.999,300.000,41.672,3.200,0,0,300.000,300.000,15.140,10.810,1
3752141161.091000,,,300.001,299.999,41.697,3.201,0,0,300.000,300.000,15.090,10.760,1
3752141461.091000,,,300.000,300.001,41.723,3.202,0,0,300.000,300.000,15.090,10.760,1
3752141761.091000,,,299.999,300.000,41.742,3.203,0,0,300.000,300.000,15.070,10.710,1
3752142061.091000,,,299.999,299.999,41.764,3.201,0,0,300.000,300.000,14.970,10.690,1
3752142361.091000,,,299.999,300.000,41.784,3.202,0,0,300.000,300.000,14.970,10.660,1
3752142661.091000,,,299.996,300.000,41.802,3.205,0,0,300.000,300.000,14.910,10.610,1
3752142961.091000,,,299.996,300.001,41.823,3.204,0,0,300.000,300.000,14.820,10.590,1
3752143261.091000,,,299.996,299.999,41.845,3.206,0,0,300.000,300.000,14.860,10.560,1
3752143561.091000,,,299.996,300.000,41.864,3.205,0,0,300.000,300.000,14.800,10.570,1
3752143861.091000,,,299.997,300.002,41.882,3.204,0,0,300.000,300.000,14.780,10.560,1
3752144161.091000,,,299.997,300.002,41.899,3.207,0,0,300.000,300.000,14.720,10.520,1
3752144461.091000,,,299.998,300.002,41.913,3.205,0,0,300.000,300.000,14.740,10.470,1
3752144761.091000,,,299.999,300.000,41.924,3.205,0,0,300.000,300.000,14.740,10.470,1
3752145061.091000,,,300.000,299.999,41.933,3.204,0,0,300.000,300.000,14.700,10.460,1
3752145361.091000,,,300.000,300.001,41.940,3.211,0,0,300.000,300.000,14.630,10.440,1
3752145661.091000,,,300.001,300.000,41.951,3.209,0,0,300.000,300.000,14.650,10.420,1
3752145961.091000,,,300.003,300.001,41.960,3.209,0,0,300.000,300.000,14.670,10.420,1
3752146261.091000,,,300.003,300.001,41.973,3.206,0,0,300.000,300.000,14.590,10.410,1
3752146561.091000,,,300.001,300.001,41.981,3.207,0,0,300.000,300.000,14.590,10.410,1
3752146861.091000,,,299.999,299.999,41.990,3.207,0,0,300.000,300.000,14.590,10.390,1
3752147161.091000,,,300.000,299.999,42.003,3.206,0,0,300.000,300.000,14.650,10.410,1
3752147461.091000,,,299.999,300.000,42.012,3.205,0,0,300.000,300.000,14.570,10.390,1
3752147761.091000,,,300.002,299.999,42.020,3.210,0,0,300.000,300.000,14.530,10.370,1
3752148061.091000,,,300.000,300.000,42.027,3.212,0,0,300.000,300.000,14.510,10.360,1
3752148361.091000,,,300.001,300.000,42.033,3.211,0,0,300.000,300.000,14.510,10.370,1
3752148661.091000,,,300.001,300.001,42.040,3.211,0,0,300.000,300.000,14.500,10.340,1
3752148961.091000,,,299.999,299.999,42.041,3.213,0,0,300.000,300.000,14.480,10.340,1
3752149261.091000,,,299.997,299.999,42.046,3.212,0,0,300.000,300.000,14.440,10.340,1
3752149561.091000,,,300.001,299.999,42.051,3.213,0,0,300.000,300.000,14.360,10.360,1
3752149861.091000,,,300.000,300.001,42.057,3.211,0,0,300.000,300.000,14.420,10.320,1
3752150161.091000,,,300.002,299.999,42.063,3.209,0,0,300.000,300.000,14.400,10.310,1
3752150461.091000,,,300.006,300.000,42.069,3.210,0,0,300.000,300.000,14.360,10.290,1
3752150761.091000,,,300.002,299.999,42.078,3.215,0,0,300.000,300.000,14.440,10.320,1
3752151061.091000,,,300.006,300.000,42.085,3.215,0,0,300.000,300.000,14.400,10.310,1
3752151361.091000,,,300.003,299.999,42.092,3.212,0,0,300.000,300.000,14.440,10.320,1
3752151661.091000,,,300.003,299.998,42.091,3.213,0,0,300.000,300.000,14.460,10.320,1
3752151961.091000,,,300.004,299.999,42.090,3.212,0,0,300.000,300.000,14.420,10.270,1
3752152261.091000,,,300.002,300.001,42.096,3.212,0,0,300.000,300.000,14.400,10.290,1
3752152561.091000,,,300.001,300.002,42.103,3.210,0,0,300.000,300.000,14.480,10.290,1
3752152861.091000,,,299.999,300.000,42.105,3.212,0,0,300.000,300.000,14.480,10.310,1
3752153161.091000,,,300.002,300.000,42.104,3.213,0,0,300.000,300.000,14.500,10.270,1
3752153461.091000,,,299.998,300.000,42.114,3.212,0,0,300.000,300.000,14.510,10.290,1
3752153761.091000,,,299.997,299.999,42.121,3.213,0,0,300.000,300.000,14.510,10.290,1
3752154061.091000,,,299.997,300.001,42.125,3.212,0,0,300.000,300.000,14.510,10.270,1
3752154361.091000,,,299.997,299.999,42.129,3.211,0,0,300.000,300.000,14.460,10.290,1
3752154661.091000,,,299.999,300.001,42.132,3.211,0,0,300.000,300.000,14.480,10.270,1
3752154961.091000,,,299.996,299.999,42.140,3.211,0,0,300.000,300.000,14.530,10.290,1
3752155261.091000,,,299.997,299.999,42.143,3.213,0,0,300.000,300.000,14.480,10.260,1
3752155561.091000,,,300.000,300.000,42.146,3.217,0,0,300.000,300.000,14.380,10.260,1
3752155861.091000,,,300.000,300.002,42.147,3.214,0,0,300.000,300.000,14.380,10.260,1
3752156161.091000,,,300.000,299.998,42.148,3.214,0,0,300.000,300.000,14.380,10.310,1
3752156461.091000,,,300.000,300.001,42.150,3.215,0,0,300.000,300.000,14.340,10.270,1
3752156761.091000,,,300.000,300.000,42.155,3.214,0,0,300.000,300.000,14.360,10.290,1
3752157061.091000,,,299.999,299.999,42.156,3.215,0,0,300.000,300.000,14.380,10.260,1
3752157361.091000,,,300.004,299.999,42.156,3.215,0,0,300.000,300.000,14.330,10.270,1
3752157661.091000,,,300.002,300.002,42.158,3.216,0,0,300.000,300.000,14.330,10.260,1
3752157961.091000,,,300.005,299.998,42.160,3.214,0,0,300.000,300.000,14.290,10.240,1
3752158261.091000,,,300.000,300.001,42.163,3.214,0,0,300.000,300.000,14.360,10.260,1
3752158561.091000,,,300.000,300.000,42.168,3.213,0,0,300.000,300.000,14.420,10.240,1
3752158861.091000,,,299.999,300.001,42.170,3.214,0,0,300.000,300.000,14.420,10.240,1
3752159161.091000,,,299.998,299.998,42.164,3.214,0,0,300.000,300.000,14.460,10.260,1
3752159461.091000,,,299.996,299.999,42.163,3.215,0,0,300.000,300.000,14.420,10.260,1
3752159761.091000,,,299.996,299.998,42.167,3.215,0,0,300.000,300.000,14.400,10.270,1
3752160061.091000,,,299.998,299.999,42.170,3.215,0,0,300.000,300.000,14.440,10.260,1
3752160361.091000,,,299.995,300.002,42.168,3.213,0,0,300.000,300.000,14.420,10.260,1
3752160661.091000,,,300.000,299.998,42.166,3.215,0,0,300.000,300.000,14.400,10.240,1
3752160961.091000,,,299.998,300.000,42.167,3.214,0,0,300.000,300.000,14.420,10.270,1
3752161261.091000,,,299.999,300.000,42.165,3.213,0,0,300.000,300.000,14.400,10.260,1
3752161561.091000,,,299.998,299.999,42.162,3.213,0,0,300.000,300.000,14.400,10.270,1
3752161861.091000,,,300.000,300.002,42.161,3.212,0,0,300.000,300.000,14.360,10.240,1
3752162161.091000,,,299.999,300.002,42.158,3.212,0,0,300.000,300.000,14.420,10.260,1
3752162461.091000,,,300.000,299.999,42.157,3.213,0,0,300.000,300.000,14.380,10.260,1
3752162761.091000,,,299.996,300.001,42.159,3.212,0,0,300.000,300.000,14.400,10.240,1
3752163061.091000,,,299.999,300.002,42.162,3.214,0,0,300.000,300.000,14.420,10.220,1
3752163361.091000,,,300.000,300.002,42.162,3.212,0,0,300.000,300.000,14.400,10.260,1
3752163661.091000,,,299.998,300.002,42.162,3.212,0,0,300.000,300.000,14.440,10.240,1
3752163961.091000,,,299.997,300.000,42.162,3.214,0,0,300.000,300.000,14.420,10.260,1
3752164261.091000,,,299.996,300.000,42.159,3.214,0,0,300.000,300.000,14.440,10.240,1
3752164561.091000,,,299.997,300.000,42.159,3.215,0,0,300.000,300.000,14.400,10.260,1
3752164861.091000,,,300.000,299.999,42.161,3.214,0,0,300.000,300.000,14.380,10.220,1
3752165161.091000,,,300.000,299.999,42.164,3.213,0,0,300.000,300.000,14.380,10.260,1
3752165461.091000,,,299.998,300.002,42.164,3.216,0,0,300.000,300.000,14.380,10.240,1
3752165761.091000,,,300.000,299.999,42.166,3.212,0,0,300.000,300.000,14.360,10.240,1
3752166061.091000,,,299.999,299.998,42.158,3.214,0,0,300.000,300.000,14.360,10.270,1
3752166361.091000,,,300.001,300.000,42.157,3.211,0,0,300.000,300.000,14.380,10.260,1
3752166661.091000,,,299.996,300.000,42.153,3.213,0,0,300.000,300.000,14.330,10.240,1
3752166961.091000,,,299.999,299.999,42.153,3.212,0,0,300.000,300.000,14.380,10.270,1
3752167261.091000,,,299.999,300.001,42.156,3.211,0,0,300.000,300.000,14.330,10.240,1
3752167561.091000,,,299.997,300.000,42.159,3.211,0,0,300.000,300.000,14.400,10.240,1
3752167861.091000,,,300.002,299.999,42.159,3.212,0,0,300.000,300.000,14.310,10.240,1
3752168161.091000,,,300.003,300.002,42.162,3.214,0,0,300.000,300.000,14.290,10.240,1
3752168461.091000,,,300.002,299.999,42.165,3.214,0,0,300.000,300.000,14.310,10.260,1
3752168761.091000,,,300.002,300.000,42.166,3.211,0,0,300.000,300.000,14.310,10.220,1
3752169061.091000,,,300.000,299.999,42.166,3.213,0,0,300.000,300.000,14.360,10.240,1
3752169361.091000,,,300.000,300.000,42.164,3.212,0,0,300.000,300.000,14.330,10.260,1
3752169661.091000,,,300.000,299.998,42.165,3.214,0,0,300.000,300.000,14.340,10.240,1
3752169961.091000,,,300.000,300.000,42.169,3.216,0,0,300.000,300.000,14.330,10.260,1
3752170261.091000,,,300.000,299.998,42.168,3.213,0,0,300.000,300.000,14.330,10.240,1
3752170561.091000,,,300.002,300.000,42.166,3.211,0,0,300.000,300.000,14.360,10.240,1
3752170861.091000,,,300.003,300.000,42.163,3.213,0,0,300.000,300.000,14.360,10.240,1
3752171161.091000,,,300.000,300.001,42.163,3.212,0,0,300.000,300.000,14.340,10.240,1
3752171461.091000,,,299.998,300.000,42.162,3.213,0,0,300.000,300.000,14.340,10.260,1
3752171761.091000,,,299.995,299.999,42.159,3.215,0,0,300.000,300.000,14.420,10.240,1
3752172061.091000,,,299.995,300.001,42.159,3.214,0,0,300.000,300.000,14.420,10.240,1
3752172361.091000,,,299.999,300.000,42.160,3.211,0,0,300.000,300.000,14.380,10.270,1
3752172661.091000,,,299.999,299.999,42.164,3.212,0,0,300.000,300.000,14.400,10.240,1
3752172961.091000,,,299.995,300.000,42.167,3.212,0,0,300.000,300.000,14.440,10.270,1
3752173261.091000,,,299.997,299.999,42.169,3.214,0,0,300.000,300.000,14.440,10.260,1
3752173561.091000,,,299.997,300.002,42.170,3.214,0,0,300.000,300.000,14.420,10.260,1
3752173861.091000,,,299.993,299.998,42.170,3.209,0,0,300.000,300.000,14.440,10.290,1
3752174161.091000,,,299.993,300.000,42.163,3.213,0,0,300.000,300.000,14.440,10.240,1
3752174461.091000,,,299.995,299.998,42.167,3.212,0,0,300.000,300.000,14.400,10.260,1
3752174761.091000,,,299.995,300.002,42.168,3.212,0,0,300.000,300.000,14.400,10.240,1
3752175061.091000,,,299.991,299.999,42.169,3.215,0,0,300.000,300.000,14.440,10.260,1
3752175361.091000,,,299.992,299.999,42.173,3.213,0,0,300.000,300.000,14.330,10.260,1
3752175661.091000,,,299.993,299.999,42.172,3.213,0,0,300.000,300.000,14.330,10.240,1
3752175961.091000,,,299.998,300.000,42.177,3.214,0,0,300.000,300.000,14.360,10.260,1
3752176261.091000,,,299.999,300.002,42.181,3.213,0,0,300.000,300.000,14.420,10.270,1
3752176561.091000,,,299.998,299.999,42.182,3.215,0,0,300.000,300.000,14.400,10.240,1
3752176861.091000,,,299.997,299.998,42.182,3.214,0,0,300.000,300.000,14.440,10.240,1
3752177161.091000,,,299.999,300.000,42.180,3.214,0,0,300.000,300.000,14.420,10.220,1
3752177461.091000,,,299.997,300.001,42.181,3.215,0,0,300.000,300.000,14.420,10.220,1
3752177761.091000,,,299.999,300.001,42.177,3.214,0,0,300.000,300.000,14.440,10.240,1
3752178061.091000,,,299.999,299.999,42.178,3.215,0,0,300.000,300.000,14.360,10.240,1
3752178361.091000,,,299.997,299.999,42.182,3.215,0,0,300.000,300.000,14.310,10.260,1
3752178661.091000,,,299.997,300.000,42.181,3.214,0,0,300.000,300.000,14.330,10.240,1
3752178961.091000,,,299.997,299.999,42.183,3.214,0,0,300.000,300.000,14.360,10.240,1
3752179261.091000,,,299.995,300.000,42.183,3.213,0,0,300.000,300.000,14.380,10.260,1
3752179561.091000,,,299.995,299.998,42.185,3.214,0,0,300.000,300.000,14.330,10.260,1
3752179861.091000,,,299.996,299.999,42.188,3.212,0,0,300.000,300.000,14.290,10.260,1
3752180161.091000,,,299.998,300.000,42.188,3.210,0,0,300.000,300.000,14.330,10.220,1
3752180461.091000,,,299.994,299.998,42.189,3.212,0,0,300.000,300.000,14.380,10.270,1
3752180761.091000,,,299.994,299.997,42.187,3.211,0,0,300.000,300.000,14.380,10.290,1
3752181061.091000,,,299.995,299.999,42.183,3.212,0,0,300.000,300.000,14.400,10.270,1
3752181361.091000,,,299.994,299.998,42.180,3.213,0,0,300.000,300.000,14.360,10.260,1
3752181661.091000,,,299.994,300.000,42.179,3.210,0,0,300.000,300.000,14.420,10.240,1
3752181961.091000,,,299.994,300.000,42.179,3.215,0,0,300.000,300.000,14.330,10.190,1
3752182261.091000,,,299.998,300.002,42.178,3.214,0,0,300.000,300.000,14.380,10.260,1
3752182561.091000,,,299.998,300.000,42.177,3.212,0,0,300.000,300.000,14.330,10.270,1
3752182861.091000,,,300.000,299.997,42.172,3.213,0,0,300.000,300.000,14.330,10.270,1
3752183161.091000,,,299.998,300.000,42.171,3.211,0,0,300.000,300.000,14.400,10.240,1
3752183461.091000,,,300.001,300.000,42.166,3.214,0,0,300.000,300.000,14.330,10.260,1
3752183761.091000,,,300.004,300.001,42.160,3.212,0,0,300.000,300.000,14.360,10.220,1
3752184061.091000,,,300.000,300.001,42.155,3.211,0,0,300.000,300.000,14.380,10.240,1
3752184361.091000,,,300.000,299.998,42.151,3.214,0,0,300.000,300.000,14.400,10.240,1
3752184661.091000,,,300.001,300.001,42.151,3.218,0,0,300.000,300.000,14.400,10.210,1
3752184961.091000,,,300.001,299.999,42.147,3.218,0,0,300.000,300.000,14.380,10.260,1
3752185261.091000,,,300.000,300.001,42.144,3.215,0,0,300.000,300.000,14.360,10.260,1
3752185561.091000,,,299.997,299.999,42.139,3.219,0,0,300.000,300.000,14.340,10.240,1
3752185861.091000,,,300.002,300.001,42.136,3.217,0,0,300.000,300.000,14.330,10.220,1
3752186161.091000,,,300.004,299.999,42.134,3.217,0,0,300.000,300.000,14.340,10.240,1
3752186461.091000,,,300.001,300.001,42.139,3.217,0,0,300.000,300.000,14.440,10.270,1
3752186761.091000,,,299.996,299.999,42.142,3.217,0,0,300.000,300.000,14.500,10.270,1
3752187061.091000,,,299.995,299.998,42.142,3.216,0,0,300.000,300.000,14.440,10.260,1
3752187361.091000,,,299.999,299.999,42.138,3.214,0,0,300.000,300.000,14.400,10.260,1
3752187661.091000,,,299.998,300.002,42.138,3.217,0,0,300.000,300.000,14.400,10.260,1
3752187961.091000,,,299.998,299.999,42.141,3.216,0,0,300.000,300.000,14.420,10.210,1
3752188261.091000,,,299.998,300.000,42.144,3.216,0,0,300.000,300.000,14.400,10.240,1
3752188561.091000,,,299.999,299.999,42.139,3.218,0,0,300.000,300.000,14.460,10.260,1
3752188861.091000,,,299.999,299.999,42.142,3.217,0,0,300.000,300.000,14.360,10.270,1
3752189161.091000,,,300.001,299.999,42.138,3.213,0,0,300.000,300.000,14.340,10.270,1
3752189461.091000,,,300.001,300.000,42.136,3.212,0,0,300.000,300.000,14.400,10.260,1
3752189761.091000,,,300.001,299.999,42.133,3.210,0,0,300.000,300.000,14.360,10.260,1
3752190061.091000,,,300.005,299.999,42.133,3.210,0,0,300.000,300.000,14.340,10.260,1
3752190361.091000,,,300.002,300.001,42.131,3.209,0,0,300.000,300.000,14.380,10.240,1
3752190661.091000,,,300.003,299.998,42.128,3.211,0,0,300.000,300.000,14.340,10.270,1
3752190961.091000,,,300.000,300.001,42.123,3.211,0,0,300.000,300.000,14.340,10.260,1
3752191261.091000,,,300.002,299.999,42.124,3.212,0,0,300.000,300.000,14.380,10.240,1
3752191561.091000,,,299.999,299.999,42.127,3.209,0,0,300.000,300.000,14.360,10.220,1
3752191861.091000,,,300.000,299.998,42.124,3.209,0,0,300.000,300.000,14.340,10.240,1
3752192161.091000,,,300.002,300.000,42.123,3.208,0,0,300.000,300.000,14.330,10.260,1
3752192461.091000,,,300.002,300.000,42.129,3.212,0,0,300.000,300.000,14.290,10.240,1
3752192761.091000,,,300.002,300.000,42.138,3.209,0,0,300.000,300.000,14.330,10.210,1
3752193061.091000,,,300.004,299.998,42.140,3.212,0,0,300.000,300.000,14.340,10.240,1
3752193361.091000,,,300.003,299.998,42.141,3.210,0,0,300.000,300.000,14.380,10.270,1
3752193661.091000,,,299.999,299.999,42.140,3.212,0,0,300.000,300.000,14.420,10.260,1
3752193961.091000,,,299.998,299.999,42.137,3.212,0,0,300.000,300.000,14.400,10.260,1
3752194261.091000,,,299.999,300.001,42.133,3.208,0,0,300.000,300.000,14.420,10.260,1
3752194561.091000,,,299.997,300.000,42.131,3.208,0,0,300.000,300.000,14.480,10.240,1
3752194861.091000,,,299.999,300.000,42.128,3.208,0,0,300.000,300.000,14.440,10.220,1
3752195161.091000,,,299.999,300.000,42.126,3.209,0,0,300.000,300.000,14.460,10.240,1
3752195461.091000,,,300.000,300.001,42.124,3.210,0,0,300.000,300.000,14.420,10.260,1
3752195761.091000,,,300.000,299.999,42.126,3.207,0,0,300.000,300.000,14.380,10.240,1
3752196061.091000,,,300.002,299.998,42.132,3.215,0,0,300.000,300.000,14.360,10.270,1
3752196361.091000,,,300.001,299.998,42.142,3.213,0,0,300.000,300.000,14.330,10.260,1
3752196661.091000,,,299.997,299.999,42.148,3.212,0,0,300.000,300.000,14.310,10.240,1
3752196961.091000,,,299.996,300.002,42.149,3.216,0,0,300.000,300.000,14.310,10.220,1
3752197261.091000,,,299.996,299.998,42.147,3.213,0,0,300.000,300.000,14.380,10.260,1
3752197561.091000,,,299.996,299.998,42.146,3.212,0,0,300.000,300.000,14.420,10.190,1
3752197861.091000,,,299.995,300.000,42.149,3.213,0,0,300.000,300.000,14.340,10.260,1
3752198161.091000,,,299.997,299.999,42.147,3.213,0,0,300.000,300.000,14.310,10.240,1
3752198461.091000,,,300.000,300.000,42.146,3.214,0,0,300.000,300.000,14.310,10.240,1
3752198761.091000,,,299.995,300.000,42.143,3.212,0,0,300.000,300.000,14.380,10.190,1
3752199061.091000,,,299.998,300.000,42.144,3.211,0,0,300.000,300.000,14.290,10.240,1
3752199361.091000,,,299.998,300.002,42.145,3.210,0,0,300.000,300.000,14.270,10.240,1
3752199661.091000,,,299.997,300.000,42.146,3.210,0,0,300.000,300.000,14.340,10.240,1
3752199961.091000,,,299.999,300.002,42.147,3.211,0,0,300.000,300.000,14.270,10.220,1
3752200261.091000,,,299.996,300.001,42.149,3.210,0,0,300.000,300.000,14.340,10.240,1
3752200561.091000,,,299.996,300.000,42.154,3.210,0,0,300.000,300.000,14.360,10.260,1
3752200861.091000,,,299.997,300.001,42.155,3.212,0,0,300.000,300.000,14.360,10.240,1
3752201161.091000,,,299.997,299.999,42.156,3.212,0,0,300.000,300.000,14.360,10.270,1
3752201461.091000,,,300.003,300.001,42.155,3.211,0,0,300.000,300.000,14.290,10.240,1
3752201761.091000,,,300.005,299.999,42.155,3.210,0,0,300.000,300.000,14.290,10.220,1
3752202061.091000,,,300.003,300.001,42.155,3.213,0,0,300.000,300.000,14.330,10.260,1
3752202361.091000,,,300.003,300.002,42.153,3.212,0,0,300.000,300.000,14.340,10.240,1
3752202661.091000,,,300.002,300.001,42.152,3.210,0,0,300.000,300.000,14.340,10.220,1
3752202961.091000,,,300.001,299.999,42.150,3.211,0,0,300.000,300.000,14.340,10.260,1
3752203261.091000,,,300.003,300.000,42.151,3.214,0,0,300.000,300.000,14.310,10.260,1
3752203561.091000,,,299.998,299.999,42.156,3.211,0,0,300.000,300.000,14.380,10.240,1
3752203861.091000,,,300.000,299.998,42.160,3.209,0,0,300.000,300.000,14.380,10.240,1
3752204161.091000,,,300.002,300.000,42.167,3.210,0,0,300.000,300.000,14.360,10.260,1
3752204461.091000,,,300.001,300.000,42.168,3.210,0,0,300.000,300.000,14.420,10.260,1
3752204761.091000,,,299.997,300.000,42.167,3.211,0,0,300.000,300.000,14.420,10.240,1
3752205061.091000,,,299.997,300.000,42.167,3.209,0,0,300.000,300.000,14.420,10.240,1
3752205361.091000,,,299.998,299.999,42.164,3.208,0,0,300.000,300.000,14.440,10.240,1
3752205661.091000,,,299.998,299.999,42.163,3.212,0,0,300.000,300.000,14.420,10.240,1
3752205961.091000,,,299.997,300.001,42.164,3.211,0,0,300.000,300.000,14.460,10.240,1
3752206261.091000,,,300.001,300.001,42.164,3.210,0,0,300.000,300.000,14.460,10.240,1
3752206561.091000,,,300.002,300.000,42.164,3.208,0,0,300.000,300.000,14.420,10.240,1
3752206861.091000,,,300.002,300.001,42.163,3.214,0,0,300.000,300.000,14.400,10.240,1
3752207161.091000,,,300.000,300.001,42.166,3.208,0,0,300.000,300.000,14.460,10.240,1
3752207461.091000,,,299.999,300.000,42.170,3.207,0,0,300.000,300.000,14.500,10.240,1
3752207761.091000,,,299.999,299.999,42.170,3.211,0,0,300.000,300.000,14.460,10.260,1
3752208061.091000,,,300.005,0.000,42.169,3.208,0,0,300.000,300.000,14.310,0.000,1
3752208361.091000,,,299.976,0.000,42.198,3.212,0,0,300.000,300.000,16.190,0.000,4
3752208661.091000,,,299.981,0.000,42.119,3.211,0,0,300.000,300.000,16.430,0.000,4
3752208961.091000,,,300.020,0.000,42.008,3.212,0,0,300.000,300.000,15.890,0.000,4
3752209051.091000,,,300.104,301.962,42.027,3.209,0,0,300.000,300.000,14.120,0.000,4