File: log/20221020.dat
[Header]
; Displex Transport Data File (default extension .dat)
; Copyright 2016, Hechang LEI, hlei@ruc.edu.cn. All rights reserved.
BYAPP, Displex, 2.0
INFO, 9T mag, Release 2.0.
INFO, Channel 1, Temperature Sensor
INFO, Sample 1 Length (cm): 0.000000; Width (cm): 0.000000; Thickness (cm): 0.000000.

[Data]
Timestamp(s),Field(Oe),Field Status,TempA(K),TempB(K),TempC(K),TempD(K),Ramp1,Ramp2,Setpoint1,Setpoint2,Output1(%),Output2(%),Temp Status
3749099864.211000,-90.000,Sweeping down,1.549,1.674,0.000,0.000,0,0,2.000,2.000,0,0,4
3749100246.002000,-87.109,Sweeping down,1.550,1.680,0.000,0.000,0,0,1.400,1.400,0,0,4
3749100666.002000,-86.409,Sweeping to zero,1.549,1.678,0.000,0.000,0,0,1.400,1.400,0,0,4
3749110343.136000,,,2.920,5.182,0.000,0.000,0,0,1.500,5.000,0,15,4
3749110455.192000,,,2.942,5.171,0.000,0.000,0,0,1.500,5.000,0,11,4
3749110567.248000,,,2.921,5.192,0.000,0.000,0,0,1.500,5.000,0,4,4
3749110659.874000,,,2.911,5.252,0.000,0.000,0,0,1.500,5.000,0,0,4
3749110688.082000,,,2.925,5.218,0.000,0.000,0,0,1.500,5.000,0,0,4
3749110716.288000,,,2.936,5.162,0.000,0.000,0,0,1.500,5.000,0,12,4
3749110744.596000,,,2.932,5.188,0.000,0.000,0,0,1.500,5.000,0,2,4
3749110772.833000,,,2.899,5.205,0.000,0.000,0,0,1.500,5.000,0,0,4
3749110801.070000,,,2.570,4.530,0.000,0.000,0,0,1.500,5.000,0,4,4
3749110829.298000,,,2.153,4.189,0.000,0.000,0,0,1.500,5.000,0,4,4
3749110857.605000,,,1.886,6.205,0.000,0.000,0,0,1.500,5.000,0,14,4
3749110885.852000,,,5.095,11.352,0.000,0.000,0,0,1.500,5.000,0,14,4
3749110914.160000,,,6.521,12.414,0.000,0.000,0,0,1.500,5.000,0,14,4
3749110942.417000,,,7.252,13.084,0.000,0.000,0,0,1.500,5.000,0,14,4
3749110970.755000,,,7.715,13.471,0.000,0.000,0,0,1.500,5.000,0,14,4
3749110999.002000,,,8.526,16.743,0.000,0.000,0,0,1.500,5.000,0,24,4
3749111027.230000,,,10.063,18.891,0.000,0.000,0,0,1.500,5.000,0,24,4
3749111055.496000,,,10.931,18.431,0.000,0.000,0,0,1.500,5.000,0,14,4
3749111083.764000,,,10.604,16.538,0.000,0.000,0,0,1.500,5.000,0,14,4
3749111112.051000,,,10.123,15.882,0.000,0.000,0,0,1.500,5.000,0,14,4
3749111140.309000,,,9.800,15.452,0.000,0.000,0,0,1.500,5.000,0,14,4
3749111168.566000,,,9.567,15.129,0.000,0.000,0,0,1.500,5.000,0,14,4
3749111196.813000,,,9.437,15.138,0.000,0.000,0,0,1.500,5.000,0,14,4
3749111225.110000,,,9.336,14.954,0.000,0.000,0,0,1.500,5.000,0,14,4
3749111253.328000,,,9.295,14.952,0.000,0.000,0,0,1.500,5.000,0,14,4
3749111281.575000,,,9.236,14.874,0.000,0.000,0,0,1.500,5.000,0,14,4
3749111309.857000,,,9.212,14.780,0.000,0.000,0,0,1.500,5.000,0,14,4
3749111338.190000,,,9.156,14.754,0.000,0.000,0,0,1.500,5.000,0,14,4
3749111366.487000,,,9.163,14.747,0.000,0.000,0,0,1.500,5.000,0,14,4
3749111394.835000,,,9.048,12.381,0.000,0.000,0,0,1.500,5.000,0,0,4
3749111423.085000,,,5.470,5.753,0.000,0.000,0,0,1.500,5.000,0,0,4
3749111451.319000,,,4.335,6.813,0.000,0.000,0,0,1.500,5.000,0,0,4
3749111479.547000,,,4.208,6.881,0.000,0.000,0,0,1.500,5.000,0,0,4
3749111507.824000,,,4.172,7.610,0.000,0.000,0,0,1.500,5.000,0,0,4
3749111536.082000,,,4.348,6.339,0.000,0.000,0,0,1.500,5.000,0,0,4
3749111564.309000,,,4.364,7.566,0.000,0.000,0,0,1.500,5.000,0,0,4
3749111592.556000,,,4.371,6.743,0.000,0.000,0,0,1.500,5.000,0,100,4
3749111620.783000,,,4.325,7.642,0.000,0.000,0,0,1.500,5.000,0,0,4
3749111648.986000,,,4.387,7.291,0.000,0.000,0,0,1.500,5.000,0,0,4
3749111677.224000,,,4.369,6.233,0.000,0.000,0,0,1.500,5.000,0,0,4
3749111705.445000,,,4.357,7.956,0.000,0.000,0,0,1.500,5.000,0,0,4
3749111733.663000,,,4.348,6.194,0.000,0.000,0,0,1.500,5.000,0,0,4
3749111761.890000,,,4.348,7.805,0.000,0.000,0,0,1.500,5.000,0,0,4
3749111790.093000,,,4.373,6.641,0.000,0.000,0,0,1.500,5.000,0,5,4
3749111818.315000,,,4.315,8.054,0.000,0.000,0,0,1.500,5.000,0,0,4
3749111846.552000,,,4.356,7.022,0.000,0.000,0,0,1.500,5.000,0,0,4
3749111874.770000,,,4.262,7.919,0.000,0.000,0,0,1.500,5.000,0,0,4
3749111902.997000,,,4.345,7.375,0.000,0.000,0,0,1.500,5.000,0,0,4
3749111931.210000,,,4.293,6.427,0.000,0.000,0,0,1.500,5.000,0,0,4
3749111959.432000,,,4.337,7.721,0.000,0.000,0,0,1.500,5.000,0,0,4
3749111987.669000,,,4.347,6.122,0.000,0.000,0,0,1.500,5.000,0,0,4
3749112015.920000,,,4.345,8.108,0.000,0.000,0,0,1.500,5.000,0,0,4
3749112044.174000,,,4.323,6.260,0.000,0.000,0,0,1.500,5.000,0,0,4
3749112072.371000,,,4.328,7.887,0.000,0.000,0,0,1.500,5.000,0,0,4
3749112100.608000,,,4.387,7.178,0.000,0.000,0,0,1.500,5.000,0,0,4
3749112128.856000,,,4.303,7.725,0.000,0.000,0,0,1.500,5.000,0,0,4
3749112157.103000,,,4.355,6.832,0.000,0.000,0,0,1.500,5.000,0,73,4
3749112185.283000,,,4.337,6.993,0.000,0.000,0,0,1.500,5.000,0,0,4
3749112213.448000,,,4.326,7.274,0.000,0.000,0,0,1.500,5.000,0,0,4
3749112241.655000,,,4.340,6.611,0.000,0.000,0,0,1.500,5.000,0,0,4
3749112269.882000,,,4.339,7.715,0.000,0.000,0,0,1.500,5.000,0,0,4
3749112298.230000,,,3.932,5.356,0.000,0.000,0,0,1.500,5.000,0,2,4
3749112326.787000,,,2.809,4.840,0.000,0.000,0,0,1.500,5.000,0,4,4
3749112355.344000,,,2.335,4.461,0.000,0.000,0,0,1.500,5.000,0,4,4
3749112383.908000,,,2.772,5.368,0.000,0.000,0,0,1.500,5.000,0,5,4
3749112412.459000,,,3.033,5.519,0.000,0.000,0,0,1.500,5.000,0,5,4
3749112441.017000,,,3.108,5.589,0.000,0.000,0,0,1.500,5.000,0,5,4
3749112469.574000,,,3.143,5.668,0.000,0.000,0,0,1.500,5.000,0,5,4
3749112498.138000,,,3.165,5.707,0.000,0.000,0,0,1.500,5.000,0,5,4
3749112526.689000,,,3.187,5.713,0.000,0.000,0,0,1.500,5.000,0,5,4
3749112555.252000,,,3.213,5.745,0.000,0.000,0,0,1.500,5.000,0,5,4
3749112583.803000,,,3.230,5.779,0.000,0.000,0,0,1.500,5.000,0,5,4
3749112612.363000,,,3.239,5.748,0.000,0.000,0,0,1.500,5.000,0,5,4
3749112640.918000,,,3.248,5.363,0.000,0.000,0,0,1.500,5.000,0,3,4
3749112669.475000,,,1.945,3.813,0.000,0.000,0,0,1.500,5.000,0,3,4
3749112698.039000,,,1.733,3.756,0.000,0.000,0,0,1.500,5.000,0,3,4
3749112726.590000,,,1.724,3.815,0.000,0.000,0,0,1.500,5.000,0,3,4
3749112755.147000,,,1.717,3.841,0.000,0.000,0,0,1.500,5.000,0,3,4
3749112783.704000,,,1.714,3.873,0.000,0.000,0,0,1.500,5.000,0,3,4
3749112812.261000,,,1.715,4.129,0.000,0.000,0,0,1.500,5.000,0,3,4
3749112840.825000,,,1.717,4.154,0.000,0.000,0,0,1.500,5.000,0,3,4
3749112869.376000,,,1.719,4.113,0.000,0.000,0,0,1.500,5.000,0,3,4
3749112897.934000,,,1.719,4.131,0.000,0.000,0,0,1.500,5.000,0,3,4
3749112926.491000,,,1.720,4.113,0.000,0.000,0,0,1.500,5.000,0,3,4
3749112955.048000,,,1.719,4.101,0.000,0.000,0,0,1.500,5.000,0,3,4
3749112983.612000,,,1.721,4.245,0.000,0.000,0,0,1.500,5.000,0,4,4
3749113012.162000,,,1.724,4.247,0.000,0.000,0,0,1.500,5.000,0,4,4
3749113040.720000,,,1.725,4.249,0.000,0.000,0,0,1.500,5.000,0,4,4
3749113069.284000,,,1.725,4.267,0.000,0.000,0,0,1.500,5.000,0,4,4
3749113097.835000,,,1.726,4.222,0.000,0.000,0,0,1.500,5.000,0,4,4
3749113126.401000,,,1.727,4.323,0.000,0.000,0,0,1.500,5.000,0,4,4
3749113154.949000,,,1.734,4.516,0.000,0.000,0,0,1.500,5.000,0,4,4
3749113183.506000,,,1.738,4.459,0.000,0.000,0,0,1.500,5.000,0,4,4
3749113212.071000,,,1.740,4.451,0.000,0.000,0,0,1.500,5.000,0,4,4
3749113240.620000,,,1.745,4.699,0.000,0.000,0,0,1.500,5.000,0,5,4
3749113269.178000,,,1.751,4.694,0.000,0.000,0,0,1.500,5.000,0,5,4
3749113297.742000,,,1.754,4.681,0.000,0.000,0,0,1.500,5.000,0,5,4
3749113326.293000,,,1.756,4.661,0.000,0.000,0,0,1.500,5.000,0,5,4
3749113354.851000,,,1.816,4.621,0.000,0.000,0,0,1.500,5.000,0,5,4
3749113383.408000,,,2.050,4.862,0.000,0.000,0,0,1.500,5.000,0,5,4
3749113411.971000,,,2.156,4.923,0.000,0.000,0,0,1.500,5.000,0,5,4
3749113440.522000,,,2.214,4.940,0.000,0.000,0,0,1.500,5.000,0,5,4
3749113469.080000,,,2.301,5.056,0.000,0.000,0,0,1.500,5.000,0,6,4
3749113497.644000,,,2.355,5.108,0.000,0.000,0,0,1.500,5.000,0,6,4
3749113526.194000,,,2.382,5.083,0.000,0.000,0,0,1.500,5.000,0,6,4
3749113554.754000,,,2.489,5.198,0.000,0.000,0,0,1.500,5.000,0,6,4
3749113583.309000,,,2.571,5.270,0.000,0.000,0,0,1.500,5.000,0,6,4
3749113611.866000,,,2.977,5.820,0.000,0.000,0,0,1.500,5.000,0,6,4
3749113640.430000,,,3.459,6.372,0.000,0.000,0,0,1.500,5.000,0,6,4
3749113668.980000,,,3.835,6.781,0.000,0.000,0,0,1.500,5.000,0,6,4
3749113697.538000,,,3.909,6.850,0.000,0.000,0,0,1.500,5.000,0,6,4
3749113726.095000,,,3.781,6.583,0.000,0.000,0,0,1.500,5.000,0,6,4
3749113754.653000,,,3.658,6.417,0.000,0.000,0,0,1.500,5.000,0,6,4
3749113783.217000,,,3.666,6.441,0.000,0.000,0,0,1.500,5.000,0,6,4
3749113811.767000,,,3.640,6.413,0.000,0.000,0,0,1.500,5.000,0,6,4
3749113840.330000,,,3.686,6.545,0.000,0.000,0,0,1.500,5.000,0,6,4
3749113868.881000,,,3.645,6.419,0.000,0.000,0,0,1.500,5.000,0,6,4
3749113897.439000,,,3.706,6.592,0.000,0.000,0,0,1.500,5.000,0,6,4
3749113925.996000,,,3.708,6.505,0.000,0.000,0,0,1.500,5.000,0,6,4
3749113954.554000,,,3.690,6.551,0.000,0.000,0,0,1.500,5.000,0,6,4
3749113983.117000,,,3.676,6.435,0.000,0.000,0,0,1.500,5.000,0,6,4
3749114011.668000,,,3.692,6.497,0.000,0.000,0,0,1.500,5.000,0,6,4
3749114040.226000,,,3.733,6.576,0.000,0.000,0,0,1.500,5.000,0,6,4
3749114068.790000,,,3.738,6.473,0.000,0.000,0,0,1.500,5.000,0,6,4
3749114097.339000,,,3.801,6.570,0.000,0.000,0,0,1.500,5.000,0,6,4
3749114125.898000,,,3.822,6.658,0.000,0.000,0,0,1.500,5.000,0,6,4
3749114154.461000,,,3.869,6.672,0.000,0.000,0,0,1.500,5.000,0,6,4
3749114183.013000,,,3.844,6.541,0.000,0.000,0,0,1.500,5.000,0,6,4
3749114211.576000,,,3.886,6.656,0.000,0.000,0,0,1.500,5.000,0,6,4
3749114240.127000,,,3.848,6.606,0.000,0.000,0,0,1.500,5.000,0,6,4
3749114268.683000,,,3.897,6.695,0.000,0.000,0,0,1.500,5.000,0,6,4
3749114297.248000,,,3.871,6.572,0.000,0.000,0,0,1.500,5.000,0,6,4
3749114325.798000,,,3.888,6.714,0.000,0.000,0,0,1.500,5.000,0,6,4
3749114354.356000,,,3.894,6.631,0.000,0.000,0,0,1.500,5.000,0,6,4
3749114382.919000,,,3.903,6.692,0.000,0.000,0,0,1.500,5.000,0,6,4
3749114411.471000,,,3.875,6.575,0.000,0.000,0,0,1.500,5.000,0,6,4
3749114440.028000,,,3.861,6.595,0.000,0.000,0,0,1.500,5.000,0,6,4
3749114468.585000,,,3.867,6.668,0.000,0.000,0,0,1.500,5.000,0,6,4
3749114497.142000,,,3.915,6.724,0.000,0.000,0,0,1.500,5.000,0,6,4
3749114525.706000,,,3.895,6.664,0.000,0.000,0,0,1.500,5.000,0,6,4
3749114554.257000,,,3.889,6.612,0.000,0.000,0,0,1.500,5.000,0,6,4
3749114582.814000,,,3.877,6.635,0.000,0.000,0,0,1.500,5.000,0,6,4
3749114611.378000,,,3.869,6.642,0.000,0.000,0,0,1.500,5.000,0,6,4
3749114639.928000,,,3.876,6.610,0.000,0.000,0,0,1.500,5.000,0,6,4
3749114668.486000,,,3.888,6.624,0.000,0.000,0,0,1.500,5.000,0,6,4
3749114697.051000,,,3.876,6.633,0.000,0.000,0,0,1.500,5.000,0,6,4
3749114725.601000,,,3.880,6.637,0.000,0.000,0,0,1.500,5.000,0,6,4
3749114754.164000,,,3.866,6.594,0.000,0.000,0,0,1.500,5.000,0,6,4
3749114782.715000,,,3.851,6.487,0.000,0.000,0,0,1.500,5.000,0,6,4
3749114811.272000,,,3.860,6.607,0.000,0.000,0,0,1.500,5.000,0,6,4
3749114839.837000,,,3.877,6.597,0.000,0.000,0,0,1.500,5.000,0,6,4
3749114868.387000,,,3.879,6.608,0.000,0.000,0,0,1.500,5.000,0,6,4
3749114896.948000,,,3.872,6.632,0.000,0.000,0,0,1.500,5.000,0,6,4
3749114925.502000,,,3.905,6.651,0.000,0.000,0,0,1.500,5.000,0,6,4
3749114954.059000,,,3.909,6.737,0.000,0.000,0,0,1.500,5.000,0,6,4
3749114982.624000,,,3.904,6.665,0.000,0.000,0,0,1.500,5.000,0,6,4
3749115011.174000,,,3.916,6.720,0.000,0.000,0,0,1.500,5.000,0,6,4
3749115039.732000,,,3.846,6.593,0.000,0.000,0,0,1.500,5.000,0,6,4
3749115068.295000,,,3.903,6.660,0.000,0.000,0,0,1.500,5.000,0,6,4
3749115096.846000,,,3.895,6.677,0.000,0.000,0,0,1.500,5.000,0,6,4
3749115125.409000,,,3.915,6.704,0.000,0.000,0,0,1.500,5.000,0,6,4
3749115153.960000,,,3.913,6.657,0.000,0.000,0,0,1.500,5.000,0,6,4
3749115182.517000,,,3.899,6.629,0.000,0.000,0,0,1.500,5.000,0,6,4
3749115211.082000,,,3.854,6.583,0.000,0.000,0,0,1.500,5.000,0,6,4
3749115239.632000,,,3.735,6.189,0.000,0.000,0,0,1.500,5.000,0,5,4
3749115268.190000,,,3.577,6.051,0.000,0.000,0,0,1.500,5.000,0,5,4
3749115296.748000,,,3.544,5.992,0.000,0.000,0,0,1.500,5.000,0,5,4
3749115325.304000,,,3.422,5.936,0.000,0.000,0,0,1.500,5.000,0,5,4
3749115353.868000,,,3.330,5.814,0.000,0.000,0,0,1.500,5.000,0,5,4
3749115382.419000,,,3.300,5.847,0.000,0.000,0,0,1.500,5.000,0,5,4
3749115410.983000,,,3.287,5.843,0.000,0.000,0,0,1.500,5.000,0,5,4
3749115439.533000,,,3.312,5.882,0.000,0.000,0,0,1.500,5.000,0,5,4
3749115468.091000,,,3.317,5.911,0.000,0.000,0,0,1.500,5.000,0,5,4
3749115496.654000,,,3.313,5.858,0.000,0.000,0,0,1.500,5.000,0,5,4
3749115525.205000,,,3.342,5.944,0.000,0.000,0,0,1.500,5.000,0,5,4
3749115553.766000,,,3.359,5.951,0.000,0.000,0,0,1.500,5.000,0,5,4
3749115582.320000,,,3.383,5.992,0.000,0.000,0,0,1.500,5.000,0,5,4
3749115610.877000,,,3.339,5.886,0.000,0.000,0,0,1.500,5.000,0,5,4
3749115639.441000,,,3.348,5.855,0.000,0.000,0,0,1.500,5.000,0,5,4
3749115667.992000,,,3.368,5.930,0.000,0.000,0,0,1.500,5.000,0,5,4
3749115696.549000,,,3.322,5.923,0.000,0.000,0,0,1.500,5.000,0,5,4
3749115725.113000,,,3.350,6.020,0.000,0.000,0,0,1.500,5.000,0,5,4
3749115753.663000,,,3.359,5.892,0.000,0.000,0,0,1.500,5.000,0,5,4
3749115782.221000,,,3.374,6.029,0.000,0.000,0,0,1.500,5.000,0,5,4
3749115810.898000,,,3.364,5.940,0.000,0.000,0,0,1.500,5.000,0,6,4
3749115839.506000,,,3.520,6.058,0.000,0.000,0,0,1.500,5.000,0,5,4
3749115868.063000,,,3.310,5.754,0.000,0.000,0,0,1.500,5.000,0,5,4
3749115896.627000,,,3.265,5.798,0.000,0.000,0,0,1.500,5.000,0,5,4
3749115925.178000,,,3.330,5.840,0.000,0.000,0,0,1.500,5.000,0,5,4
3749115953.735000,,,3.352,5.819,0.000,0.000,0,0,1.500,5.000,0,5,4
3749115982.293000,,,3.380,5.907,0.000,0.000,0,0,1.500,5.000,0,5,4
3749116010.849000,,,3.411,5.961,0.000,0.000,0,0,1.500,5.000,0,5,4
3749116039.414000,,,3.442,5.996,0.000,0.000,0,0,1.500,5.000,0,5,4
3749116067.964000,,,3.429,5.927,0.000,0.000,0,0,1.500,5.000,0,5,4
3749116096.522000,,,3.422,5.925,0.000,0.000,0,0,1.500,5.000,0,5,4
3749116125.085000,,,3.423,5.928,0.000,0.000,0,0,1.500,5.000,0,5,4
3749116153.636000,,,3.390,5.803,0.000,0.000,0,0,1.500,5.000,0,5,4
3749116182.200000,,,3.437,5.961,0.000,0.000,0,0,1.500,5.000,0,5,4
3749116210.751000,,,3.409,5.929,0.000,0.000,0,0,1.500,5.000,0,5,4
3749116239.308000,,,3.402,5.852,0.000,0.000,0,0,1.500,5.000,0,5,4
3749116267.866000,,,3.374,5.857,0.000,0.000,0,0,1.500,5.000,0,5,4
3749116296.423000,,,3.393,5.849,0.000,0.000,0,0,1.500,5.000,0,4,4
3749116324.986000,,,3.214,5.483,0.000,0.000,0,0,1.500,5.000,0,4,4
3749116353.538000,,,3.149,5.465,0.000,0.000,0,0,1.500,5.000,0,4,4
3749116382.102000,,,3.056,5.377,0.000,0.000,0,0,1.500,5.000,0,4,4
3749116410.651000,,,3.020,5.324,0.000,0.000,0,0,1.500,5.000,0,4,4
3749116439.216000,,,2.980,5.254,0.000,0.000,0,0,1.500,5.000,0,4,4
3749116467.766000,,,2.944,5.201,0.000,0.000,0,0,1.500,5.000,0,4,4
3749116496.330000,,,2.939,5.204,0.000,0.000,0,0,1.500,5.000,0,4,4
3749116524.881000,,,2.935,5.215,0.000,0.000,0,0,1.500,5.000,0,4,4
3749116553.445000,,,2.914,5.174,0.000,0.000,0,0,1.500,5.000,0,4,4
3749116581.995000,,,2.894,5.143,0.000,0.000,0,0,1.500,5.000,0,4,4
3749116610.553000,,,2.905,5.200,0.000,0.000,0,0,1.500,5.000,0,4,4
3749116639.111000,,,2.896,5.140,0.000,0.000,0,0,1.500,5.000,0,4,4
3749116667.675000,,,2.897,5.181,0.000,0.000,0,0,1.500,5.000,0,4,4
3749116696.225000,,,2.918,5.181,0.000,0.000,0,0,1.500,5.000,0,4,4
3749116724.789000,,,2.918,5.240,0.000,0.000,0,0,1.500,5.000,0,4,4
3749116753.339000,,,2.896,5.160,0.000,0.000,0,0,1.500,5.000,0,4,4
3749116781.903000,,,2.937,5.263,0.000,0.000,0,0,1.500,5.000,0,4,4
3749116810.454000,,,2.910,5.174,0.000,0.000,0,0,1.500,5.000,0,4,4
3749116839.018000,,,2.921,5.204,0.000,0.000,0,0,1.500,5.000,0,4,4
3749116867.568000,,,2.914,5.204,0.000,0.000,0,0,1.500,5.000,0,4,4
3749116896.133000,,,2.919,5.189,0.000,0.000,0,0,1.500,5.000,0,4,4
3749116924.684000,,,2.908,5.216,0.000,0.000,0,0,1.500,5.000,0,4,4
3749116953.247000,,,2.894,5.141,0.000,0.000,0,0,1.500,5.000,0,4,4
3749116981.799000,,,2.897,5.151,0.000,0.000,0,0,1.500,5.000,0,4,4
3749117010.356000,,,2.920,5.224,0.000,0.000,0,0,1.500,5.000,0,4,4
3749117038.912000,,,2.922,5.217,0.000,0.000,0,0,1.500,5.000,0,4,4
3749117067.476000,,,2.922,5.215,0.000,0.000,0,0,1.500,5.000,0,4,4
3749117096.027000,,,2.941,5.228,0.000,0.000,0,0,1.500,5.000,0,4,4
3749117124.592000,,,2.940,5.250,0.000,0.000,0,0,1.500,5.000,0,4,4
3749117153.142000,,,2.923,5.189,0.000,0.000,0,0,1.500,5.000,0,4,4
3749117181.706000,,,2.929,5.227,0.000,0.000,0,0,1.500,5.000,0,4,4
3749117210.256000,,,2.924,5.217,0.000,0.000,0,0,1.500,5.000,0,4,4
3749117238.820000,,,2.910,5.170,0.000,0.000,0,0,1.500,5.000,0,4,4
3749117267.371000,,,2.917,5.189,0.000,0.000,0,0,1.500,5.000,0,4,4
3749117295.929000,,,2.914,5.241,0.000,0.000,0,0,1.500,5.000,0,4,4
3749117324.486000,,,2.915,5.198,0.000,0.000,0,0,1.500,5.000,0,4,4
3749117353.050000,,,2.908,5.164,0.000,0.000,0,0,1.500,5.000,0,4,4
3749117381.600000,,,2.881,5.135,0.000,0.000,0,0,1.500,5.000,0,4,4
3749117410.158000,,,2.892,5.123,0.000,0.000,0,0,1.500,5.000,0,4,4
3749117438.715000,,,2.878,5.126,0.000,0.000,0,0,1.500,5.000,0,4,4
3749117467.272000,,,2.877,5.113,0.000,0.000,0,0,1.500,5.000,0,4,4
3749117495.829000,,,2.899,5.170,0.000,0.000,0,0,1.500,5.000,0,4,4
3749117524.393000,,,2.887,5.155,0.000,0.000,0,0,1.500,5.000,0,4,4
3749117552.944000,,,2.914,5.204,0.000,0.000,0,0,1.500,5.000,0,4,4
3749117581.508000,,,2.895,5.181,0.000,0.000,0,0,1.500,5.000,0,4,4
3749117610.059000,,,2.895,5.150,0.000,0.000,0,0,1.500,5.000,0,4,4
3749117638.623000,,,2.920,5.214,0.000,0.000,0,0,1.500,5.000,0,4,4
3749117667.174000,,,2.908,5.175,0.000,0.000,0,0,1.500,5.000,0,4,4
3749117695.731000,,,2.909,5.174,0.000,0.000,0,0,1.500,5.000,0,4,4
3749117724.288000,,,2.928,5.223,0.000,0.000,0,0,1.500,5.000,0,4,4
3749117752.846000,,,2.912,5.197,0.000,0.000,0,0,1.500,5.000,0,4,4
3749117781.403000,,,2.896,5.150,0.000,0.000,0,0,1.500,5.000,0,4,4
3749117809.960000,,,2.914,5.161,0.000,0.000,0,0,1.500,5.000,0,4,4
3749117838.518000,,,2.923,5.187,0.000,0.000,0,0,1.500,5.000,0,4,4
3749117867.075000,,,2.915,5.237,0.000,0.000,0,0,1.500,5.000,0,4,4
3749117895.631000,,,2.905,5.164,0.000,0.000,0,0,1.500,5.000,0,4,4
3749117924.189000,,,2.917,5.229,0.000,0.000,0,0,1.500,5.000,0,4,4
3749117952.753000,,,2.923,5.176,0.000,0.000,0,0,1.500,5.000,0,4,4
3749117981.304000,,,2.902,5.236,0.000,0.000,0,0,1.500,5.000,0,4,4
3749118009.651000,,,2.910,5.181,0.000,0.000,0,0,1.500,5.000,0,4,4
3749118037.868000,,,4.552,11.158,0.000,0.000,0,0,1.500,5.000,0,14,4
3749118066.105000,,,6.447,12.547,0.000,0.000,0,0,1.500,5.000,0,14,4
3749118094.372000,,,7.400,13.405,0.000,0.000,0,0,1.500,5.000,0,14,4
3749118122.790000,,,6.563,6.638,0.000,0.000,0,0,1.500,5.000,0,0,4
3749118151.563000,,,2.980,2.776,0.000,0.000,0,0,1.500,5.000,0,0,4
3749118180.340000,,,1.711,1.707,0.000,0.000,0,0,1.500,5.000,0,0,4
3749118209.127000,,,1.627,1.629,0.000,0.000,0,0,1.500,5.000,0,0,4
3749118237.869000,,,1.603,1.613,0.000,0.000,0,0,1.500,5.000,0,0,4
3749118266.632000,,,1.589,1.603,0.000,0.000,0,0,1.500,5.000,0,0,4
3749118295.419000,,,1.579,1.594,0.000,0.000,0,0,1.500,5.000,0,0,4
3749118324.196000,,,1.571,1.587,0.000,0.000,0,0,1.500,5.000,0,0,4
3749118352.974000,,,1.564,1.581,0.000,0.000,0,0,1.500,5.000,0,0,4
3749118381.746000,,,1.559,1.576,0.000,0.000,0,0,1.500,5.000,0,0,4
3749118410.501000,,,1.554,1.573,0.000,0.000,0,0,1.500,5.000,0,0,4
3749118439.279000,,,1.550,1.569,0.000,0.000,0,0,1.500,5.000,0,0,4
3749118468.067000,,,1.547,1.566,0.000,0.000,0,0,1.500,5.000,0,0,4
3749118496.820000,,,1.544,1.564,0.000,0.000,0,0,1.500,5.000,0,0,4
3749118525.573000,,,1.542,1.562,0.000,0.000,0,0,1.500,5.000,0,0,4
3749118554.358000,,,1.540,1.560,0.000,0.000,0,0,1.500,5.000,0,0,4
3749118583.135000,,,1.538,1.558,0.000,0.000,0,0,1.500,5.000,0,0,4
3749118611.899000,,,1.536,1.557,0.000,0.000,0,0,1.500,5.000,0,0,4
3749118640.656000,,,1.535,1.555,0.000,0.000,0,0,1.500,5.000,0,0,4
3749118669.394000,,,1.533,1.554,0.000,0.000,0,0,1.500,5.000,0,0,4
3749118698.171000,,,1.532,1.553,0.000,0.000,0,0,1.500,5.000,0,0,4
3749118726.959000,,,1.531,1.552,0.000,0.000,0,0,1.500,5.000,0,0,4
3749118755.675000,,,1.529,1.550,0.000,0.000,0,0,1.500,5.000,0,0,4
3749118784.393000,,,1.528,1.549,0.000,0.000,0,0,1.500,5.000,0,0,4
3749118813.170000,,,1.527,1.548,0.000,0.000,0,0,1.500,5.000,0,0,4
3749118841.898000,,,1.525,1.547,0.000,0.000,0,0,1.500,5.000,0,0,4
3749118870.615000,,,1.524,1.546,0.000,0.000,0,0,1.500,5.000,0,0,4
3749118899.333000,,,1.523,1.545,0.000,0.000,0,0,1.500,5.000,0,0,4
3749118928.050000,,,1.521,1.543,0.000,0.000,0,0,1.500,5.000,0,0,4
3749118956.767000,,,1.520,1.542,0.000,0.000,0,0,1.500,5.000,0,0,4
3749118985.519000,,,1.519,1.541,0.000,0.000,0,0,1.500,5.000,0,0,4
3749119014.286000,,,1.517,1.540,0.000,0.000,0,0,1.500,5.000,0,0,4
3749119043.074000,,,1.516,1.539,0.000,0.000,0,0,1.500,5.000,0,0,4
3749119071.852000,,,1.515,1.538,0.000,0.000,0,0,1.500,5.000,0,0,4
3749119100.624000,,,1.514,1.537,0.000,0.000,0,0,1.500,5.000,0,0,4
3749119129.400000,,,1.513,1.536,0.000,0.000,0,0,1.500,5.000,0,0,4
3749119158.173000,,,1.512,1.535,0.000,0.000,0,0,1.500,5.000,0,0,4
3749119186.950000,,,1.511,1.533,0.000,0.000,0,0,1.500,5.000,0,0,4
3749119215.728000,,,1.510,1.533,0.000,0.000,0,0,1.500,5.000,0,0,4
3749119244.500000,,,1.508,1.532,0.000,0.000,0,0,1.500,5.000,0,0,4
3749119273.217000,,,1.507,1.531,0.000,0.000,0,0,1.500,5.000,0,0,4
3749119301.935000,,,1.506,1.529,0.000,0.000,0,0,1.500,5.000,0,0,4
3749119330.653000,,,1.505,1.528,0.000,0.000,0,0,1.500,5.000,0,0,4
3749119359.404000,,,1.504,1.527,0.000,0.000,0,0,1.500,5.000,0,0,4
3749119388.191000,,,1.503,1.526,0.000,0.000,0,0,1.500,5.000,0,0,4
3749119416.969000,,,1.502,1.525,0.000,0.000,0,0,1.500,5.000,0,0,4
3749119445.734000,,,1.500,1.524,0.000,0.000,0,0,1.500,5.000,0,0,4
3749119474.511000,,,1.500,1.523,0.000,0.000,0,0,1.500,5.000,0,0,4
3749119503.275000,,,1.499,1.522,0.000,0.000,0,0,1.500,5.000,0,0,4
3749119532.053000,,,1.498,1.520,0.000,0.000,0,0,1.500,5.000,0,0,4
3749119560.830000,,,1.496,1.519,0.000,0.000,0,0,1.500,5.000,0,0,4
3749119589.617000,,,1.495,1.518,0.000,0.000,0,0,1.500,5.000,0,0,4
3749119618.370000,,,1.494,1.516,0.000,0.000,0,0,1.500,5.000,0,0,4
3749119647.148000,,,1.493,1.515,0.000,0.000,0,0,1.500,5.000,0,0,4
3749119675.902000,,,1.493,1.514,0.000,0.000,0,0,1.500,5.000,0,0,4
3749119704.680000,,,1.491,1.513,0.000,0.000,0,0,1.500,5.000,0,0,4
3749119733.468000,,,1.491,1.512,0.000,0.000,0,0,1.500,5.000,0,0,4
3749119762.210000,,,1.490,1.511,0.000,0.000,0,0,1.500,5.000,0,0,4
3749119790.998000,,,1.489,1.509,0.000,0.000,0,0,1.500,5.000,0,0,4
3749119819.775000,,,1.488,1.508,0.000,0.000,0,0,1.500,5.000,0,0,4
3749119848.548000,,,1.487,1.507,0.000,0.000,0,0,1.500,5.000,0,0,4
3749119877.265000,,,1.486,1.506,0.000,0.000,0,0,1.500,5.000,0,0,4
3749119905.983000,,,1.485,1.505,0.000,0.000,0,0,1.500,5.000,0,0,4
3749119934.699000,,,1.484,1.504,0.000,0.000,0,0,1.500,5.000,0,0,4
3749119963.465000,,,1.484,1.503,0.000,0.000,0,0,1.500,5.000,0,0,4
3749119992.242000,,,1.483,1.502,0.000,0.000,0,0,1.500,5.000,0,0,4
3749120021.006000,,,1.482,1.501,0.000,0.000,0,0,1.500,5.000,0,0,4
3749120049.723000,,,1.481,1.500,0.000,0.000,0,0,1.500,5.000,0,0,4
3749120078.521000,,,1.481,1.499,0.000,0.000,0,0,1.500,5.000,0,0,4
3749120107.309000,,,1.479,1.498,0.000,0.000,0,0,1.500,5.000,0,0,4
3749120136.026000,,,1.479,1.497,0.000,0.000,0,0,1.500,5.000,0,0,4
3749120164.803000,,,1.478,1.496,0.000,0.000,0,0,1.500,5.000,0,0,4
3749120193.564000,,,1.478,1.495,0.000,0.000,0,0,1.500,5.000,0,0,4
3749120222.307000,,,1.477,1.495,0.000,0.000,0,0,1.500,5.000,0,0,4
3749120251.084000,,,1.477,1.494,0.000,0.000,0,0,1.500,5.000,0,0,4
3749120279.828000,,,1.475,1.493,0.000,0.000,0,0,1.500,5.000,0,0,4
3749120308.629000,,,1.475,1.493,0.000,0.000,0,0,1.500,5.000,0,0,4
3749120337.346000,,,1.474,1.492,0.000,0.000,0,0,1.500,5.000,0,0,4
3749120366.083000,,,1.474,1.491,0.000,0.000,0,0,1.500,5.000,0,0,4
3749120394.861000,,,1.473,1.491,0.000,0.000,0,0,1.500,5.000,0,0,4
3749120423.601000,,,1.473,1.490,0.000,0.000,0,0,1.500,5.000,0,0,4
3749120452.389000,,,1.476,1.494,0.000,0.000,0,0,1.500,5.000,0,0,4
3749120481.166000,,,1.478,1.495,0.000,0.000,0,0,1.500,5.000,0,0,4
3749120509.930000,,,1.477,1.496,0.000,0.000,0,0,1.500,5.000,0,0,4
3749120538.707000,,,1.476,1.496,0.000,0.000,0,0,1.500,5.000,0,0,4
3749120567.450000,,,1.477,1.497,0.000,0.000,0,0,1.500,5.000,0,0,4
3749120596.228000,,,1.480,1.501,0.000,0.000,0,0,1.500,5.000,0,0,4
3749120625.025000,,,1.484,1.505,0.000,0.000,0,0,1.500,5.000,0,0,4
3749120653.792000,,,1.488,1.509,0.000,0.000,0,0,1.500,5.000,0,0,4
3749120682.578000,,,1.492,1.513,0.000,0.000,0,0,1.500,5.000,0,0,4
3749120711.296000,,,1.495,1.517,0.000,0.000,0,0,1.500,5.000,0,0,4
3749120740.094000,,,1.498,1.520,0.000,0.000,0,0,1.500,5.000,0,0,4
3749120768.871000,,,1.501,1.523,0.000,0.000,0,0,1.500,5.000,0,0,4
3749120797.623000,,,1.504,1.526,0.000,0.000,0,0,1.500,5.000,0,0,4
3749120826.370000,,,1.506,1.528,0.000,0.000,0,0,1.500,5.000,0,0,4
3749120855.088000,,,1.508,1.530,0.000,0.000,0,0,1.500,5.000,0,0,4
3749120883.805000,,,1.509,1.531,0.000,0.000,0,0,1.500,5.000,0,0,4
3749120912.522000,,,1.511,1.533,0.000,0.000,0,0,1.500,5.000,0,0,4
3749120941.245000,,,1.512,1.534,0.000,0.000,0,0,1.500,5.000,0,0,4
3749120970.041000,,,1.513,1.535,0.000,0.000,0,0,1.500,5.000,0,0,4
3749120998.830000,,,1.514,1.536,0.000,0.000,0,0,1.500,5.000,0,0,4
3749121027.571000,,,1.514,1.537,0.000,0.000,0,0,1.500,5.000,0,0,4
3749121056.358000,,,1.515,1.537,0.000,0.000,0,0,1.500,5.000,0,0,4
3749121085.111000,,,1.515,1.538,0.000,0.000,0,0,1.500,5.000,0,0,4
3749121113.896000,,,1.516,1.539,0.000,0.000,0,0,1.500,5.000,0,0,4
3749121142.674000,,,1.516,1.539,0.000,0.000,0,0,1.500,5.000,0,0,4
3749121171.403000,,,1.516,1.539,0.000,0.000,0,0,1.500,5.000,0,0,4
3749121200.120000,,,1.516,1.539,0.000,0.000,0,0,1.500,5.000,0,0,4
3749121228.886000,,,1.517,1.540,0.000,0.000,0,0,1.500,5.000,0,0,4
3749121257.649000,,,1.517,1.540,0.000,0.000,0,0,1.500,5.000,0,0,4
3749121286.447000,,,1.517,1.540,0.000,0.000,0,0,1.500,5.000,0,0,4
3749121315.214000,,,1.517,1.540,0.000,0.000,0,0,1.500,5.000,0,0,4
3749121343.977000,,,1.517,1.540,0.000,0.000,0,0,1.500,5.000,0,0,4
3749121372.754000,,,1.517,1.540,0.000,0.000,0,0,1.500,5.000,0,0,4
3749121401.506000,,,1.516,1.540,0.000,0.000,0,0,1.500,5.000,0,0,4
3749121430.283000,,,1.517,1.540,0.000,0.000,0,0,1.500,5.000,0,0,4
3749121459.071000,,,1.517,1.539,0.000,0.000,0,0,1.500,5.000,0,0,4
3749121487.858000,,,1.516,1.540,0.000,0.000,0,0,1.500,5.000,0,0,4
3749121516.575000,,,1.516,1.539,0.000,0.000,0,0,1.500,5.000,0,0,4
3749121545.328000,,,1.516,1.539,0.000,0.000,0,0,1.500,5.000,0,0,4
3749121574.103000,,,1.516,1.539,0.000,0.000,0,0,1.500,5.000,0,0,4
3749121602.867000,,,1.516,1.539,0.000,0.000,0,0,1.500,5.000,0,0,4
3749121631.654000,,,1.516,1.539,0.000,0.000,0,0,1.500,5.000,0,0,4
3749121660.371000,,,1.516,1.539,0.000,0.000,0,0,1.500,5.000,0,0,4
3749121689.089000,,,1.515,1.539,0.000,0.000,0,0,1.500,5.000,0,0,4
3749121717.877000,,,1.516,1.538,0.000,0.000,0,0,1.500,5.000,0,0,4
3749121746.653000,,,1.516,1.539,0.000,0.000,0,0,1.500,5.000,0,0,4
3749121775.427000,,,1.515,1.538,0.000,0.000,0,0,1.500,5.000,0,0,4
3749121804.203000,,,1.515,1.539,0.000,0.000,0,0,1.500,5.000,0,0,4
3749121833.000000,,,1.516,1.538,0.000,0.000,0,0,1.500,5.000,0,0,4
3749121861.766000,,,1.515,1.538,0.000,0.000,0,0,1.500,5.000,0,0,4
3749121890.510000,,,1.515,1.538,0.000,0.000,0,0,1.500,5.000,0,0,4
3749121919.228000,,,1.515,1.538,0.000,0.000,0,0,1.500,5.000,0,0,4
3749121947.944000,,,1.515,1.538,0.000,0.000,0,0,1.500,5.000,0,0,4
3749121976.662000,,,1.515,1.538,0.000,0.000,0,0,1.500,5.000,0,0,4
3749122005.399000,,,1.515,1.538,0.000,0.000,0,0,1.500,5.000,0,0,4
3749122034.186000,,,1.515,1.538,0.000,0.000,0,0,1.500,5.000,0,0,4
3749122062.964000,,,1.515,1.538,0.000,0.000,0,0,1.500,5.000,0,0,4
3749122091.727000,,,1.515,1.538,0.000,0.000,0,0,1.500,5.000,0,0,4
3749122120.469000,,,1.515,1.537,0.000,0.000,0,0,1.500,5.000,0,0,4
3749122149.225000,,,1.515,1.538,0.000,0.000,0,0,1.500,5.000,0,0,4
3749122177.953000,,,1.515,1.537,0.000,0.000,0,0,1.500,5.000,0,0,4
3749122206.703000,,,1.515,1.537,0.000,0.000,0,0,1.500,5.000,0,0,4
3749122235.457000,,,1.514,1.538,0.000,0.000,0,0,1.500,5.000,0,0,4
3749122264.199000,,,1.515,1.537,0.000,0.000,0,0,1.500,5.000,0,0,4
3749122292.917000,,,1.514,1.537,0.000,0.000,0,0,1.500,5.000,0,0,4
3749122321.704000,,,1.514,1.537,0.000,0.000,0,0,1.500,5.000,0,0,4
3749122350.422000,,,1.514,1.538,0.000,0.000,0,0,1.500,5.000,0,0,4
3749122379.198000,,,1.514,1.537,0.000,0.000,0,0,1.500,5.000,0,0,4
3749122407.951000,,,1.514,1.537,0.000,0.000,0,0,1.500,5.000,0,0,4
3749122436.714000,,,1.515,1.537,0.000,0.000,0,0,1.500,5.000,0,0,4
3749122465.490000,,,1.514,1.537,0.000,0.000,0,0,1.500,5.000,0,0,4
3749122494.266000,,,1.514,1.537,0.000,0.000,0,0,1.500,5.000,0,0,4
3749122523.040000,,,1.514,1.537,0.000,0.000,0,0,1.500,5.000,0,0,4
3749122551.793000,,,1.514,1.537,0.000,0.000,0,0,1.500,5.000,0,0,4
3749122580.580000,,,1.514,1.537,0.000,0.000,0,0,1.500,5.000,0,0,4
3749122609.357000,,,1.514,1.537,0.000,0.000,0,0,1.500,5.000,0,0,4
3749122638.074000,,,1.514,1.537,0.000,0.000,0,0,1.500,5.000,0,0,4
3749122666.792000,,,1.514,1.537,0.000,0.000,0,0,1.500,5.000,0,0,4
3749122695.509000,,,1.514,1.537,0.000,0.000,0,0,1.500,5.000,0,0,4
3749122724.226000,,,1.514,1.537,0.000,0.000,0,0,1.500,5.000,0,0,4
3749122753.002000,,,1.514,1.537,0.000,0.000,0,0,1.500,5.000,0,0,4
3749122781.731000,,,1.514,1.537,0.000,0.000,0,0,1.500,5.000,0,0,4
3749122810.483000,,,1.514,1.537,0.000,0.000,0,0,1.500,5.000,0,0,4
3749122839.270000,,,1.514,1.537,0.000,0.000,0,0,1.500,5.000,0,0,4
3749122868.018000,,,1.514,1.536,0.000,0.000,0,0,1.500,5.000,0,0,4
3749122896.740000,,,1.514,1.537,0.000,0.000,0,0,1.500,5.000,0,0,4
3749122925.525000,,,1.514,1.537,0.000,0.000,0,0,1.500,5.000,0,0,4
3749122954.299000,,,1.514,1.537,0.000,0.000,0,0,1.500,5.000,0,0,4
3749122983.017000,,,1.514,1.536,0.000,0.000,0,0,1.500,5.000,0,0,4
3749123011.769000,,,1.514,1.536,0.000,0.000,0,0,1.500,5.000,0,0,4
3749123040.487000,,,1.513,1.536,0.000,0.000,0,0,1.500,5.000,0,0,4
3749123069.204000,,,1.514,1.536,0.000,0.000,0,0,1.500,5.000,0,0,4
3749123097.946000,,,1.514,1.537,0.000,0.000,0,0,1.500,5.000,0,0,4
3749123126.707000,,,1.514,1.536,0.000,0.000,0,0,1.500,5.000,0,0,4
3749123155.460000,,,1.514,1.536,0.000,0.000,0,0,1.500,5.000,0,0,4
3749123184.261000,,,1.514,1.536,0.000,0.000,0,0,1.500,5.000,0,0,4
3749123213.015000,,,1.514,1.537,0.000,0.000,0,0,1.500,5.000,0,0,4
3749123241.792000,,,1.514,1.537,0.000,0.000,0,0,1.500,5.000,0,0,4
3749123270.554000,,,1.514,1.537,0.000,0.000,0,0,1.500,5.000,0,0,4
3749123299.307000,,,1.514,1.537,0.000,0.000,0,0,1.500,5.000,0,0,4
3749123328.055000,,,1.514,1.537,0.000,0.000,0,0,1.500,5.000,0,0,4
3749123356.772000,,,1.514,1.537,0.000,0.000,0,0,1.500,5.000,0,0,4
3749123385.489000,,,1.514,1.537,0.000,0.000,0,0,1.500,5.000,0,0,4
3749123414.206000,,,1.514,1.537,0.000,0.000,0,0,1.500,5.000,0,0,4
3749123442.923000,,,1.514,1.537,0.000,0.000,0,0,1.500,5.000,0,0,4
3749123471.641000,,,1.514,1.537,0.000,0.000,0,0,1.500,5.000,0,0,4
3749123500.358000,,,1.514,1.537,0.000,0.000,0,0,1.500,5.000,0,0,4
3749123529.075000,,,1.514,1.537,0.000,0.000,0,0,1.500,5.000,0,0,4
3749123557.793000,,,1.514,1.537,0.000,0.000,0,0,1.500,5.000,0,0,4
3749123586.515000,,,1.514,1.537,0.000,0.000,0,0,1.500,5.000,0,0,4
3749123615.300000,,,1.514,1.537,0.000,0.000,0,0,1.500,5.000,0,0,4
3749123644.064000,,,1.514,1.537,0.000,0.000,0,0,1.500,5.000,0,0,4
3749123672.837000,,,1.514,1.537,0.000,0.000,0,0,1.500,5.000,0,0,4
3749123701.554000,,,1.514,1.537,0.000,0.000,0,0,1.500,5.000,0,0,4
3749123730.319000,,,1.514,1.537,0.000,0.000,0,0,1.500,5.000,0,0,4
3749123759.063000,,,1.514,1.537,0.000,0.000,0,0,1.500,5.000,0,0,4
3749123787.781000,,,1.514,1.537,0.000,0.000,0,0,1.500,5.000,0,0,4
3749123816.541000,,,1.514,1.537,0.000,0.000,0,0,1.500,5.000,0,0,4
3749123845.319000,,,1.514,1.537,0.000,0.000,0,0,1.500,5.000,0,0,4
3749123874.082000,,,1.514,1.537,0.000,0.000,0,0,1.500,5.000,0,0,4
3749123902.860000,,,1.514,1.537,0.000,0.000,0,0,1.500,5.000,0,0,4
3749123931.602000,,,1.514,1.537,0.000,0.000,0,0,1.500,5.000,0,0,4
3749123960.388000,,,1.514,1.537,0.000,0.000,0,0,1.500,5.000,0,0,4
3749123989.152000,,,1.514,1.537,0.000,0.000,0,0,1.500,5.000,0,0,4
3749124017.869000,,,1.514,1.537,0.000,0.000,0,0,1.500,5.000,0,0,4
3749124046.656000,,,1.515,1.537,0.000,0.000,0,0,1.500,5.000,0,0,4
3749124075.374000,,,1.515,1.537,0.000,0.000,0,0,1.500,5.000,0,0,4
3749124104.172000,,,1.514,1.538,0.000,0.000,0,0,1.500,5.000,0,0,4
3749124132.948000,,,1.514,1.537,0.000,0.000,0,0,1.500,5.000,0,0,4
3749124161.689000,,,1.514,1.537,0.000,0.000,0,0,1.500,5.000,0,0,4
3749124190.453000,,,1.515,1.537,0.000,0.000,0,0,1.500,5.000,0,0,4
3749124219.170000,,,1.514,1.537,0.000,0.000,0,0,1.500,5.000,0,0,4
3749124247.957000,,,1.514,1.537,0.000,0.000,0,0,1.500,5.000,0,0,4
3749124276.730000,,,1.514,1.537,0.000,0.000,0,0,1.500,5.000,0,0,4
3749124305.495000,,,1.514,1.537,0.000,0.000,0,0,1.500,5.000,0,0,4
3749124334.259000,,,1.514,1.537,0.000,0.000,0,0,1.500,5.000,0,0,4
3749124363.046000,,,1.514,1.537,0.000,0.000,0,0,1.500,5.000,0,0,4
3749124391.809000,,,1.515,1.537,0.000,0.000,0,0,1.500,5.000,0,0,4
3749124420.526000,,,1.515,1.538,0.000,0.000,0,0,1.500,5.000,0,0,4
3749124449.302000,,,1.515,1.538,0.000,0.000,0,0,1.500,5.000,0,0,4
3749124478.065000,,,1.515,1.538,0.000,0.000,0,0,1.500,5.000,0,0,4
3749124506.853000,,,1.515,1.539,0.000,0.000,0,0,1.500,5.000,0,0,4
3749124535.601000,,,1.516,1.539,0.000,0.000,0,0,1.500,5.000,0,0,4
3749124564.323000,,,1.517,1.541,0.000,0.000,0,0,1.500,5.000,0,0,4
3749124593.108000,,,1.518,1.542,0.000,0.000,0,0,1.500,5.000,0,0,4
3749124621.882000,,,1.519,1.543,0.000,0.000,0,0,1.500,5.000,0,0,4
3749124650.599000,,,1.520,1.544,0.000,0.000,0,0,1.500,5.000,0,0,4
3749124679.317000,,,1.520,1.544,0.000,0.000,0,0,1.500,5.000,0,0,4
3749124708.114000,,,1.521,1.545,0.000,0.000,0,0,1.500,5.000,0,0,4
3749124736.891000,,,1.521,1.545,0.000,0.000,0,0,1.500,5.000,0,0,4
3749124765.668000,,,1.521,1.545,0.000,0.000,0,0,1.500,5.000,0,0,4
3749124794.456000,,,1.521,1.546,0.000,0.000,0,0,1.500,5.000,0,0,4
3749124823.243000,,,1.521,1.545,0.000,0.000,0,0,1.500,5.000,0,0,4
3749124851.970000,,,1.521,1.545,0.000,0.000,0,0,1.500,5.000,0,0,4
3749124880.748000,,,1.521,1.545,0.000,0.000,0,0,1.500,5.000,0,0,4
3749124909.495000,,,1.521,1.545,0.000,0.000,0,0,1.500,5.000,0,0,4
3749124938.213000,,,1.520,1.545,0.000,0.000,0,0,1.500,5.000,0,0,4
3749124966.944000,,,1.520,1.544,0.000,0.000,0,0,1.500,5.000,0,0,4
3749124995.686000,,,1.520,1.544,0.000,0.000,0,0,1.500,5.000,0,0,4
3749125024.485000,,,1.519,1.543,0.000,0.000,0,0,1.500,5.000,0,0,4
3749125053.261000,,,1.519,1.543,0.000,0.000,0,0,1.500,5.000,0,0,4
3749125082.039000,,,1.519,1.543,0.000,0.000,0,0,1.500,5.000,0,0,4
3749125110.791000,,,1.519,1.543,0.000,0.000,0,0,1.500,5.000,0,0,4
3749125139.568000,,,1.519,1.542,0.000,0.000,0,0,1.500,5.000,0,0,4
3749125168.285000,,,1.518,1.542,0.000,0.000,0,0,1.500,5.000,0,0,4
3749125197.003000,,,1.519,1.543,0.000,0.000,0,0,1.500,5.000,0,0,4
3749125225.781000,,,1.518,1.543,0.000,0.000,0,0,1.500,5.000,0,0,4
3749125254.553000,,,1.518,1.542,0.000,0.000,0,0,1.500,5.000,0,0,4
3749125283.331000,,,1.518,1.542,0.000,0.000,0,0,1.500,5.000,0,0,4
3749125312.107000,,,1.518,1.542,0.000,0.000,0,0,1.500,5.000,0,0,4
3749125340.824000,,,1.518,1.542,0.000,0.000,0,0,1.500,5.000,0,0,4
3749125369.575000,,,1.518,1.542,0.000,0.000,0,0,1.500,5.000,0,0,4
3749125398.349000,,,1.518,1.542,0.000,0.000,0,0,1.500,5.000,0,0,4
3749125427.066000,,,1.518,1.542,0.000,0.000,0,0,1.500,5.000,0,0,4
3749125455.783000,,,1.518,1.542,0.000,0.000,0,0,1.500,5.000,0,0,4
3749125484.501000,,,1.518,1.542,0.000,0.000,0,0,1.500,5.000,0,0,4
3749125513.278000,,,1.517,1.542,0.000,0.000,0,0,1.500,5.000,0,0,4
3749125542.065000,,,1.518,1.542,0.000,0.000,0,0,1.500,5.000,0,0,4
3749125570.818000,,,1.517,1.542,0.000,0.000,0,0,1.500,5.000,0,0,4
3749125599.605000,,,1.517,1.541,0.000,0.000,0,0,1.500,5.000,0,0,4
3749125628.322000,,,1.518,1.541,0.000,0.000,0,0,1.500,5.000,0,0,4
3749125657.120000,,,1.518,1.542,0.000,0.000,0,0,1.500,5.000,0,0,4
3749125685.906000,,,1.518,1.541,0.000,0.000,0,0,1.500,5.000,0,0,4
3749125714.659000,,,1.517,1.541,0.000,0.000,0,0,1.500,5.000,0,0,4
3749125743.399000,,,1.518,1.541,0.000,0.000,0,0,1.500,5.000,0,0,4
3749125772.163000,,,1.517,1.542,0.000,0.000,0,0,1.500,5.000,0,0,4
3749125800.881000,,,1.517,1.541,0.000,0.000,0,0,1.500,5.000,0,0,4
3749125829.668000,,,1.518,1.541,0.000,0.000,0,0,1.500,5.000,0,0,4
3749125858.441000,,,1.518,1.541,0.000,0.000,0,0,1.500,5.000,0,0,4
3749125887.183000,,,1.517,1.541,0.000,0.000,0,0,1.500,5.000,0,0,4
3749125915.945000,,,1.517,1.541,0.000,0.000,0,0,1.500,5.000,0,0,4
3749125944.677000,,,1.517,1.541,0.000,0.000,0,0,1.500,5.000,0,0,4
3749125973.395000,,,1.517,1.541,0.000,0.000,0,0,1.500,5.000,0,0,4
3749126002.155000,,,1.517,1.541,0.000,0.000,0,0,1.500,5.000,0,0,4
3749126030.919000,,,1.517,1.541,0.000,0.000,0,0,1.500,5.000,0,0,4
3749126059.706000,,,1.517,1.541,0.000,0.000,0,0,1.500,5.000,0,0,4
3749126088.469000,,,1.517,1.541,0.000,0.000,0,0,1.500,5.000,0,0,4
3749126117.246000,,,1.517,1.541,0.000,0.000,0,0,1.500,5.000,0,0,4
3749126145.978000,,,1.517,1.541,0.000,0.000,0,0,1.500,5.000,0,0,4
3749126174.695000,,,1.517,1.541,0.000,0.000,0,0,1.500,5.000,0,0,4
3749126203.443000,,,1.517,1.541,0.000,0.000,0,0,1.500,5.000,0,0,4
3749126232.220000,,,1.517,1.541,0.000,0.000,0,0,1.500,5.000,0,0,4
3749126260.982000,,,1.517,1.541,0.000,0.000,0,0,1.500,5.000,0,0,4
3749126289.699000,,,1.517,1.541,0.000,0.000,0,0,1.500,5.000,0,0,4
3749126318.462000,,,1.517,1.541,0.000,0.000,0,0,1.500,5.000,0,0,4
3749126347.205000,,,1.517,1.541,0.000,0.000,0,0,1.500,5.000,0,0,4
3749126375.956000,,,1.517,1.541,0.000,0.000,0,0,1.500,5.000,0,0,4
3749126404.724000,,,1.517,1.541,0.000,0.000,0,0,1.500,5.000,0,0,4
3749126433.486000,,,1.517,1.541,0.000,0.000,0,0,1.500,5.000,0,0,4
3749126462.228000,,,1.517,1.541,0.000,0.000,0,0,1.500,5.000,0,0,4
3749126490.991000,,,1.517,1.541,0.000,0.000,0,0,1.500,5.000,0,0,4
3749126519.708000,,,1.517,1.541,0.000,0.000,0,0,1.500,5.000,0,0,4
3749126548.484000,,,1.517,1.541,0.000,0.000,0,0,1.500,5.000,0,0,4
3749126577.247000,,,1.517,1.541,0.000,0.000,0,0,1.500,5.000,0,0,4
3749126605.966000,,,1.517,1.541,0.000,0.000,0,0,1.500,5.000,0,0,4
3749126634.718000,,,1.517,1.541,0.000,0.000,0,0,1.500,5.000,0,0,4
3749126663.480000,,,1.517,1.541,0.000,0.000,0,0,1.500,5.000,0,0,4
3749126692.202000,,,1.517,1.541,0.000,0.000,0,0,1.500,5.000,0,0,4
3749126720.987000,,,1.517,1.541,0.000,0.000,0,0,1.500,5.000,0,0,4
3749126749.761000,,,1.517,1.541,0.000,0.000,0,0,1.500,5.000,0,0,4
3749126778.479000,,,1.517,1.541,0.000,0.000,0,0,1.500,5.000,0,0,4
3749126807.196000,,,1.517,1.541,0.000,0.000,0,0,1.500,5.000,0,0,4
3749126835.913000,,,1.517,1.541,0.000,0.000,0,0,1.500,5.000,0,0,4
3749126864.631000,,,1.517,1.541,0.000,0.000,0,0,1.500,5.000,0,0,4
3749126893.408000,,,1.517,1.541,0.000,0.000,0,0,1.500,5.000,0,0,4
3749126922.171000,,,1.517,1.541,0.000,0.000,0,0,1.500,5.000,0,0,4
3749126950.947000,,,1.517,1.541,0.000,0.000,0,0,1.500,5.000,0,0,4
3749126979.734000,,,1.517,1.541,0.000,0.000,0,0,1.500,5.000,0,0,4
3749127008.522000,,,1.517,1.541,0.000,0.000,0,0,1.500,5.000,0,0,4
3749127037.287000,,,1.517,1.541,0.000,0.000,0,0,1.500,5.000,0,0,4
3749127066.051000,,,1.517,1.541,0.000,0.000,0,0,1.500,5.000,0,0,4
3749127094.839000,,,1.517,1.541,0.000,0.000,0,0,1.500,5.000,0,0,4
3749127123.601000,,,1.518,1.541,0.000,0.000,0,0,1.500,5.000,0,0,4
3749127152.379000,,,1.518,1.541,0.000,0.000,0,0,1.500,5.000,0,0,4
3749127181.141000,,,1.517,1.542,0.000,0.000,0,0,1.500,5.000,0,0,4
3749127209.931000,,,1.517,1.541,0.000,0.000,0,0,1.500,5.000,0,0,4
3749127238.685000,,,1.517,1.542,0.000,0.000,0,0,1.500,5.000,0,0,4
3749127267.462000,,,1.517,1.542,0.000,0.000,0,0,1.500,5.000,0,0,4
3749127296.235000,,,1.517,1.542,0.000,0.000,0,0,1.500,5.000,0,0,4
3749127325.000000,,,1.518,1.542,0.000,0.000,0,0,1.500,5.000,0,0,4
3749127353.788000,,,1.518,1.542,0.000,0.000,0,0,1.500,5.000,0,0,4
3749127382.551000,,,1.518,1.542,0.000,0.000,0,0,1.500,5.000,0,0,4
3749127411.279000,,,1.518,1.542,0.000,0.000,0,0,1.500,5.000,0,0,4
3749127440.056000,,,1.518,1.542,0.000,0.000,0,0,1.500,5.000,0,0,4
3749127468.833000,,,1.518,1.542,0.000,0.000,0,0,1.500,5.000,0,0,4
3749127497.621000,,,1.517,1.542,0.000,0.000,0,0,1.500,5.000,0,0,4
3749127526.398000,,,1.517,1.541,0.000,0.000,0,0,1.500,5.000,0,0,4
3749127555.161000,,,1.517,1.542,0.000,0.000,0,0,1.500,5.000,0,0,4
3749127583.938000,,,1.517,1.541,0.000,0.000,0,0,1.500,5.000,0,0,4
3749127612.725000,,,1.517,1.542,0.000,0.000,0,0,1.500,5.000,0,0,4
3749127641.500000,,,1.517,1.542,0.000,0.000,0,0,1.500,5.000,0,0,4
3749127670.274000,,,1.518,1.541,0.000,0.000,0,0,1.500,5.000,0,0,4
3749127699.062000,,,1.517,1.542,0.000,0.000,0,0,1.500,5.000,0,0,4
3749127727.839000,,,1.517,1.541,0.000,0.000,0,0,1.500,5.000,0,0,4
3749127756.567000,,,1.517,1.541,0.000,0.000,0,0,1.500,5.000,0,0,4
3749127785.284000,,,1.518,1.541,0.000,0.000,0,0,1.500,5.000,0,0,4
3749127814.036000,,,1.517,1.541,0.000,0.000,0,0,1.500,5.000,0,0,4
3749127842.798000,,,1.517,1.541,0.000,0.000,0,0,1.500,5.000,0,0,4
3749127871.541000,,,1.517,1.541,0.000,0.000,0,0,1.500,5.000,0,0,4
3749127900.318000,,,1.517,1.541,0.000,0.000,0,0,1.500,5.000,0,0,4
3749127929.106000,,,1.517,1.541,0.000,0.000,0,0,1.500,5.000,0,0,4
3749127957.892000,,,1.517,1.541,0.000,0.000,0,0,1.500,5.000,0,0,4
3749127986.668000,,,1.518,1.541,0.000,0.000,0,0,1.500,5.000,0,0,4
3749128015.433000,,,1.517,1.542,0.000,0.000,0,0,1.500,5.000,0,0,4
3749128044.219000,,,1.517,1.541,0.000,0.000,0,0,1.500,5.000,0,0,4
3749128072.992000,,,1.518,1.542,0.000,0.000,0,0,1.500,5.000,0,0,4
3749128101.709000,,,1.517,1.541,0.000,0.000,0,0,1.500,5.000,0,0,4
3749128130.426000,,,1.518,1.541,0.000,0.000,0,0,1.500,5.000,0,0,4
3749128159.191000,,,1.518,1.541,0.000,0.000,0,0,1.500,5.000,0,0,4
3749128187.956000,,,1.517,1.541,0.000,0.000,0,0,1.500,5.000,0,0,4
3749128216.708000,,,1.517,1.541,0.000,0.000,0,0,1.500,5.000,0,0,4
3749128245.485000,,,1.517,1.541,0.000,0.000,0,0,1.500,5.000,0,0,4
3749128274.202000,,,1.517,1.541,0.000,0.000,0,0,1.500,5.000,0,0,4
3749128302.979000,,,1.517,1.541,0.000,0.000,0,0,1.500,5.000,0,0,4
3749128331.763000,,,1.517,1.541,0.000,0.000,0,0,1.500,5.000,0,0,4
3749128360.539000,,,1.517,1.541,0.000,0.000,0,0,1.500,5.000,0,0,4
3749128389.312000,,,1.517,1.541,0.000,0.000,0,0,1.500,5.000,0,0,4
3749128418.089000,,,1.517,1.541,0.000,0.000,0,0,1.500,5.000,0,0,4
3749128446.806000,,,1.517,1.541,0.000,0.000,0,0,1.500,5.000,0,0,4
3749128475.604000,,,1.517,1.541,0.000,0.000,0,0,1.500,5.000,0,0,4
3749128504.369000,,,1.517,1.541,0.000,0.000,0,0,1.500,5.000,0,0,4
3749128533.113000,,,1.517,1.541,0.000,0.000,0,0,1.500,5.000,0,0,4
3749128561.831000,,,1.517,1.541,0.000,0.000,0,0,1.500,5.000,0,0,4
3749128590.591000,,,1.517,1.541,0.000,0.000,0,0,1.500,5.000,0,0,4
3749128619.365000,,,1.517,1.541,0.000,0.000,0,0,1.500,5.000,0,0,4
3749128648.156000,,,1.517,1.541,0.000,0.000,0,0,1.500,5.000,0,0,4
3749128676.919000,,,1.517,1.541,0.000,0.000,0,0,1.500,5.000,0,0,4
3749128705.672000,,,1.517,1.541,0.000,0.000,0,0,1.500,5.000,0,0,4
3749128734.424000,,,1.517,1.541,0.000,0.000,0,0,1.500,5.000,0,0,4
3749128763.211000,,,1.517,1.541,0.000,0.000,0,0,1.500,5.000,0,0,4
3749128791.973000,,,1.517,1.541,0.000,0.000,0,0,1.500,5.000,0,0,4
3749128820.691000,,,1.517,1.541,0.000,0.000,0,0,1.500,5.000,0,0,4
3749128849.467000,,,1.517,1.541,0.000,0.000,0,0,1.500,5.000,0,0,4
3749128878.244000,,,1.517,1.540,0.000,0.000,0,0,1.500,5.000,0,0,4
3749128906.988000,,,1.517,1.541,0.000,0.000,0,0,1.500,5.000,0,0,4
3749128935.725000,,,1.517,1.541,0.000,0.000,0,0,1.500,5.000,0,0,4
3749128964.512000,,,1.516,1.540,0.000,0.000,0,0,1.500,5.000,0,0,4
3749128993.274000,,,1.517,1.541,0.000,0.000,0,0,1.500,5.000,0,0,4
3749129021.992000,,,1.516,1.541,0.000,0.000,0,0,1.500,5.000,0,0,4
3749129050.790000,,,1.517,1.541,0.000,0.000,0,0,1.500,5.000,0,0,4
3749129079.576000,,,1.517,1.541,0.000,0.000,0,0,1.500,5.000,0,0,4
3749129108.352000,,,1.517,1.541,0.000,0.000,0,0,1.500,5.000,0,0,4
3749129137.126000,,,1.517,1.541,0.000,0.000,0,0,1.500,5.000,0,0,4
3749129165.913000,,,1.517,1.541,0.000,0.000,0,0,1.500,5.000,0,0,4
3749129194.631000,,,1.517,1.541,0.000,0.000,0,0,1.500,5.000,0,0,4
3749129223.408000,,,1.517,1.541,0.000,0.000,0,0,1.500,5.000,0,0,4
3749129252.171000,,,1.517,1.541,0.000,0.000,0,0,1.500,5.000,0,0,4
3749129280.958000,,,1.517,1.541,0.000,0.000,0,0,1.500,5.000,0,0,4
3749129309.734000,,,1.517,1.541,0.000,0.000,0,0,1.500,5.000,0,0,4
3749129338.452000,,,1.517,1.541,0.000,0.000,0,0,1.500,5.000,0,0,4
3749129367.179000,,,1.516,1.541,0.000,0.000,0,0,1.500,5.000,0,0,4
3749129395.957000,,,1.517,1.541,0.000,0.000,0,0,1.500,5.000,0,0,4
3749129424.744000,,,1.517,1.540,0.000,0.000,0,0,1.500,5.000,0,0,4
3749129453.496000,,,1.517,1.541,0.000,0.000,0,0,1.500,5.000,0,0,4
3749129482.273000,,,1.517,1.541,0.000,0.000,0,0,1.500,5.000,0,0,4
3749129511.035000,,,1.517,1.541,0.000,0.000,0,0,1.500,5.000,0,0,4
3749129539.778000,,,1.517,1.541,0.000,0.000,0,0,1.500,5.000,0,0,4
3749129568.565000,,,1.517,1.541,0.000,0.000,0,0,1.500,5.000,0,0,4
3749129597.343000,,,1.517,1.541,0.000,0.000,0,0,1.500,5.000,0,0,4
3749129626.130000,,,1.517,1.541,0.000,0.000,0,0,1.500,5.000,0,0,4
3749129654.917000,,,1.517,1.541,0.000,0.000,0,0,1.500,5.000,0,0,4
3749129683.695000,,,1.517,1.541,0.000,0.000,0,0,1.500,5.000,0,0,4
3749129712.482000,,,1.516,1.541,0.000,0.000,0,0,1.500,5.000,0,0,4
3749129741.222000,,,1.516,1.541,0.000,0.000,0,0,1.500,5.000,0,0,4
3749129769.987000,,,1.516,1.541,0.000,0.000,0,0,1.500,5.000,0,0,4
3749129798.704000,,,1.517,1.541,0.000,0.000,0,0,1.500,5.000,0,0,4
3749129827.446000,,,1.517,1.541,0.000,0.000,0,0,1.500,5.000,0,0,4
3749129856.243000,,,1.517,1.540,0.000,0.000,0,0,1.500,5.000,0,0,4
3749129885.009000,,,1.517,1.540,0.000,0.000,0,0,1.500,5.000,0,0,4
3749129913.773000,,,1.517,1.540,0.000,0.000,0,0,1.500,5.000,0,0,4
3749129942.560000,,,1.517,1.541,0.000,0.000,0,0,1.500,5.000,0,0,4
3749129971.337000,,,1.516,1.541,0.000,0.000,0,0,1.500,5.000,0,0,4
3749130000.110000,,,1.517,1.541,0.000,0.000,0,0,1.500,5.000,0,0,4
3749130028.827000,,,1.516,1.541,0.000,0.000,0,0,1.500,5.000,0,0,4
3749130057.593000,,,1.517,1.540,0.000,0.000,0,0,1.500,5.000,0,0,4
3749130086.380000,,,1.517,1.541,0.000,0.000,0,0,1.500,5.000,0,0,4
3749130115.144000,,,1.517,1.541,0.000,0.000,0,0,1.500,5.000,0,0,4
3749130143.931000,,,1.517,1.541,0.000,0.000,0,0,1.500,5.000,0,0,4
3749130172.658000,,,1.517,1.541,0.000,0.000,0,0,1.500,5.000,0,0,4
3749130201.376000,,,1.517,1.541,0.000,0.000,0,0,1.500,5.000,0,0,4
3749130230.153000,,,1.517,1.541,0.000,0.000,0,0,1.500,5.000,0,0,4
3749130258.915000,,,1.517,1.541,0.000,0.000,0,0,1.500,5.000,0,0,4
3749130287.681000,,,1.517,1.541,0.000,0.000,0,0,1.500,5.000,0,0,4
3749130316.445000,,,1.517,1.541,0.000,0.000,0,0,1.500,5.000,0,0,4
3749130345.232000,,,1.517,1.541,0.000,0.000,0,0,1.500,5.000,0,0,4
3749130373.949000,,,1.517,1.541,0.000,0.000,0,0,1.500,5.000,0,0,4
3749130402.667000,,,1.517,1.541,0.000,0.000,0,0,1.500,5.000,0,0,4
3749130431.384000,,,1.517,1.541,0.000,0.000,0,0,1.500,5.000,0,0,4
3749130460.101000,,,1.517,1.541,0.000,0.000,0,0,1.500,5.000,0,0,4
3749130488.845000,,,1.517,1.541,0.000,0.000,0,0,1.500,5.000,0,0,4
3749130517.631000,,,1.517,1.541,0.000,0.000,0,0,1.500,5.000,0,0,4
3749130546.418000,,,1.517,1.541,0.000,0.000,0,0,1.500,5.000,0,0,4
3749130575.195000,,,1.517,1.541,0.000,0.000,0,0,1.500,5.000,0,0,4
3749130603.972000,,,1.517,1.541,0.000,0.000,0,0,1.500,5.000,0,0,4
3749130632.735000,,,1.517,1.541,0.000,0.000,0,0,1.500,5.000,0,0,4
3749130661.497000,,,1.517,1.541,0.000,0.000,0,0,1.500,5.000,0,0,4
3749130690.250000,,,1.517,1.541,0.000,0.000,0,0,1.500,5.000,0,0,4
3749130719.017000,,,1.517,1.541,0.000,0.000,0,0,1.500,5.000,0,0,4
3749130747.805000,,,1.517,1.541,0.000,0.000,0,0,1.500,5.000,0,0,4
3749130776.577000,,,1.517,1.541,0.000,0.000,0,0,1.500,5.000,0,0,4
3749130805.295000,,,1.517,1.541,0.000,0.000,0,0,1.500,5.000,0,0,4
3749130834.011000,,,1.517,1.541,0.000,0.000,0,0,1.500,5.000,0,0,4
3749130862.798000,,,1.517,1.541,0.000,0.000,0,0,1.500,5.000,0,0,4
3749130891.531000,,,1.517,1.541,0.000,0.000,0,0,1.500,5.000,0,0,4
3749130920.248000,,,1.517,1.541,0.000,0.000,0,0,1.500,5.000,0,0,4
3749130948.985000,,,1.517,1.541,0.000,0.000,0,0,1.500,5.000,0,0,4
3749130977.762000,,,1.517,1.541,0.000,0.000,0,0,1.500,5.000,0,0,4
3749131006.540000,,,1.517,1.541,0.000,0.000,0,0,1.500,5.000,0,0,4
3749131035.302000,,,1.516,1.541,0.000,0.000,0,0,1.500,5.000,0,0,4
3749131064.090000,,,1.517,1.541,0.000,0.000,0,0,1.500,5.000,0,0,4
3749131092.831000,,,1.517,1.541,0.000,0.000,0,0,1.500,5.000,0,0,4
3749131111.340000,,,1.517,1.541,0.000,0.000,0,0,1.500,5.000,0,0,4