File: log/20221019.dat
[Header]
; Displex Transport Data File (default extension .dat)
; Copyright 2016, Hechang LEI, hlei@ruc.edu.cn. All rights reserved.
BYAPP, Displex, 2.0
INFO, 9T mag, Release 2.0.
INFO, Channel 1, Temperature Sensor
INFO, Sample 1 Length (cm): 0.000000; Width (cm): 0.000000; Thickness (cm): 0.000000.

[Data]
Timestamp(s),Field(Oe),Field Status,TempA(K),TempB(K),TempC(K),TempD(K),Ramp1,Ramp2,Setpoint1,Setpoint2,Output1(%),Output2(%),Temp Status
3748994590.414000,0.000,Standby,1.481,1.500,0.000,0.000,0,0,1.500,1.500,0,0,4
3748994680.414000,0.000,Standby,1.852,3.863,0.000,0.000,0,0,2.000,2.000,0,0,4
3748994770.414000,0.000,Standby,2.027,3.739,0.000,0.000,0,0,2.000,2.000,0,0,4
3748994860.414000,0.000,Standby,2.015,3.806,0.000,0.000,0,0,2.000,2.000,0,0,4
3748994950.414000,0.000,Standby,2.007,3.765,0.000,0.000,0,0,2.000,2.000,0,0,4
3748995040.414000,0.000,Standby,2.006,3.763,0.000,0.000,0,0,2.000,2.000,0,1,4
3748995130.414000,0.000,Standby,2.004,3.811,0.000,0.000,0,0,2.000,2.000,0,0,4
3748995220.414000,0.000,Standby,2.181,2.341,0.000,0.000,0,0,2.000,2.000,0,0,4
3748995310.414000,0.000,Standby,1.656,1.667,0.000,0.000,0,0,2.000,2.000,0,0,4
3748995400.414000,0.000,Standby,1.603,1.619,0.000,0.000,0,0,2.000,2.000,0,0,4
3748995490.414000,0.000,Standby,1.582,1.600,0.000,0.000,0,0,2.000,2.000,0,0,4
3748995580.414000,0.000,Standby,1.565,1.584,0.000,0.000,0,0,2.000,2.000,0,0,4
3748995670.414000,0.000,Standby,1.902,3.813,0.000,0.000,0,0,2.000,2.000,0,0,4
3748995760.414000,0.000,Standby,2.045,3.771,0.000,0.000,0,0,2.000,2.000,0,0,4
3748995850.414000,0.000,Standby,2.010,3.670,0.000,0.000,0,0,2.000,2.000,0,0,4
3748995940.414000,0.000,Standby,2.006,3.697,0.000,0.000,0,0,2.000,2.000,0,0,4
3748996030.414000,0.000,Standby,2.004,3.767,0.000,0.000,0,0,2.000,2.000,0,0,4
3748996120.414000,0.000,Standby,1.956,2.021,0.000,0.000,0,0,2.000,2.000,0,0,4
3748996210.414000,0.000,Standby,1.988,2.018,0.000,0.000,0,0,2.000,2.000,0,0,4
3748996300.414000,0.000,Standby,1.997,2.016,0.000,0.000,0,0,2.000,2.000,0,0,4
3748996390.414000,0.000,Standby,1.733,1.778,0.000,0.000,0,0,2.000,2.000,0,0,4
3748996480.414000,0.000,Standby,2.055,3.742,0.000,0.000,0,0,2.000,2.000,0,1,4
3748996570.414000,0.000,Standby,1.978,2.081,0.000,0.000,0,0,2.000,2.000,0,0,4
3748996660.414000,0.000,Standby,3.840,3.755,0.000,0.000,1,1,5.000,5.000,0,2,2
3748996750.414000,0.000,Standby,5.009,4.995,0.000,0.000,0,0,5.000,5.000,0,3,1
3748996840.414000,0.000,Standby,6.086,5.504,0.000,0.000,1,1,10.000,10.000,0,0,3
3748996930.414000,0.000,Standby,10.236,10.004,0.000,0.000,0,0,10.000,10.000,0,0,1
3748997020.414000,0.000,Standby,16.345,16.725,0.000,0.000,1,1,20.000,20.000,1,1,2
3748997110.414000,0.000,Standby,21.138,21.613,0.000,0.000,1,1,50.000,50.000,2,2,2
3748997200.414000,0.000,Standby,33.790,36.584,0.000,0.000,1,1,50.000,50.000,7,7,2
3748997290.414000,0.000,Standby,46.772,50.765,0.000,0.000,0,0,50.000,50.000,12,6,4
3748997380.414000,0.000,Standby,52.129,50.059,0.000,0.000,0,0,50.000,50.000,7,2,4
3748997470.414000,0.000,Standby,57.457,69.924,0.000,0.000,0,0,100.000,100.000,58,99,4
3748997560.414000,0.000,Standby,90.566,100.229,0.000,0.000,0,0,100.000,100.000,59,15,4
3748997650.414000,0.000,Standby,107.406,100.039,0.000,0.000,0,0,100.000,100.000,42,9,4
3748997740.414000,0.000,Standby,115.374,112.069,0.000,0.000,1,1,300.000,300.000,37,35,2
3748997830.414000,0.000,Standby,123.946,127.190,0.000,0.000,1,1,300.000,300.000,45,41,2
3748997920.414000,0.000,Standby,135.413,142.121,0.000,0.000,1,1,300.000,300.000,56,46,2
3748998010.414000,0.000,Standby,149.825,157.038,0.000,0.000,1,1,300.000,300.000,67,50,2
3748998100.414000,0.000,Standby,166.051,171.945,0.000,0.000,1,1,300.000,300.000,76,54,2
3748998190.414000,0.000,Standby,182.838,186.880,0.000,0.000,1,1,300.000,300.000,82,58,2
3748998280.414000,0.000,Standby,199.366,201.804,0.000,0.000,1,1,300.000,300.000,85,60,2
3748998370.414000,0.000,Standby,215.250,216.714,0.000,0.000,1,1,300.000,300.000,87,64,2
3748998460.414000,0.000,Standby,230.314,231.637,0.000,0.000,1,1,300.000,300.000,86,67,2
3748998550.414000,0.000,Standby,244.493,246.555,0.000,0.000,1,1,300.000,300.000,88,70,2
3748998640.414000,0.000,Standby,257.885,261.523,0.000,0.000,1,1,300.000,300.000,88,75,2
3748998730.414000,0.000,Standby,270.350,276.543,0.000,0.000,1,1,300.000,300.000,90,77,2
3748998820.414000,0.000,Standby,282.133,291.452,0.000,0.000,1,1,300.000,300.000,85,81,2
3748998910.414000,0.000,Standby,293.319,300.361,0.000,0.000,0,0,300.000,300.000,89,52,4
3748999000.414000,0.000,Standby,304.096,300.064,0.000,0.000,0,0,300.000,300.000,85,42,4
3748999090.414000,0.000,Standby,311.943,300.039,0.000,0.000,0,0,300.000,300.000,68,38,4
3748999180.414000,0.000,Standby,313.115,300.027,0.000,0.000,0,0,300.000,300.000,48,35,4
3748999270.414000,0.000,Standby,309.633,300.014,0.000,0.000,0,0,300.000,300.000,34,33,1
3748999360.414000,0.000,Standby,304.434,300.003,0.000,0.000,0,0,300.000,300.000,29,32,1
3748999450.414000,0.000,Standby,299.893,300.002,0.000,0.000,0,0,300.000,300.000,31,32,1
3748999540.414000,0.000,Standby,297.288,300.002,0.000,0.000,0,0,300.000,300.000,36,32,1
3748999630.414000,0.000,Standby,296.786,300.002,0.000,0.000,0,0,300.000,300.000,41,32,1
3748999720.414000,0.000,Standby,297.774,300.005,0.000,0.000,0,0,300.000,300.000,44,31,1
3748999810.414000,0.000,Standby,299.357,300.011,0.000,0.000,0,0,300.000,300.000,44,30,1
3748999900.414000,0.000,Standby,300.751,300.009,0.000,0.000,0,0,300.000,300.000,43,30,1
3748999990.414000,0.000,Standby,301.549,300.008,0.000,0.000,0,0,300.000,300.000,40,29,1
3749000080.414000,0.000,Standby,301.683,300.007,0.000,0.000,0,0,300.000,300.000,38,28,1
3749000170.414000,0.000,Standby,301.002,299.448,0.000,0.000,0,0,300.000,300.000,37,34,4
3749000260.414000,0.000,Standby,300.742,300.002,0.000,0.000,0,0,300.000,300.000,35,27,1
3749000350.414000,0.000,Standby,300.470,300.001,0.000,0.000,0,0,300.000,300.000,35,27,1
3749000440.414000,0.000,Standby,300.282,299.999,0.000,0.000,0,0,300.000,300.000,34,25,1
3749000530.414000,0.000,Standby,300.197,300.002,0.000,0.000,0,0,300.000,300.000,34,26,1
3749000620.414000,0.000,Standby,300.221,299.960,0.000,0.000,0,0,300.000,300.000,34,45,4
3749000710.414000,0.000,Standby,298.519,278.666,0.000,0.000,0,0,300.000,300.000,37,0,4
3749000800.414000,0.000,Standby,297.385,300.006,0.000,0.000,0,0,300.000,300.000,41,10,4
3749000890.414000,0.000,Standby,297.562,300.008,0.000,0.000,0,0,300.000,300.000,45,2,1
3749000980.414000,0.000,Standby,298.970,299.103,0.000,0.000,0,0,300.000,300.000,46,20,4
3749001070.414000,0.000,Standby,301.823,300.021,0.000,0.000,0,0,300.000,300.000,42,13,4
3749001160.414000,0.000,Standby,303.745,299.976,0.000,0.000,0,0,300.000,300.000,36,20,4
3749001250.414000,0.000,Standby,302.263,292.008,0.000,0.000,1,1,2.000,2.000,13,0,3
3749001340.414000,0.000,Standby,294.012,285.494,0.000,0.000,1,1,2.000,2.000,0,0,3
3749001430.414000,0.000,Standby,285.897,279.670,0.000,0.000,1,1,2.000,2.000,0,0,3
3749001520.414000,0.000,Standby,278.723,274.293,0.000,0.000,1,1,2.000,2.000,0,0,3
3749001610.414000,0.000,Standby,272.156,269.199,0.000,0.000,1,1,2.000,2.000,0,0,3
3749001700.414000,0.000,Standby,266.247,264.466,0.000,0.000,1,1,2.000,2.000,0,0,3
3749001790.414000,0.000,Standby,260.864,260.029,0.000,0.000,1,1,2.000,2.000,0,0,3
3749001880.414000,0.000,Standby,255.896,255.861,0.000,0.000,1,1,2.000,2.000,0,0,3
3749001970.414000,0.000,Standby,251.332,251.955,0.000,0.000,1,1,2.000,2.000,0,0,3
3749002060.414000,0.000,Standby,247.112,248.287,0.000,0.000,1,1,2.000,2.000,0,0,3
3749002150.414000,0.000,Standby,243.206,244.826,0.000,0.000,1,1,2.000,2.000,0,0,3
3749002240.414000,0.000,Standby,239.550,241.534,0.000,0.000,1,1,2.000,2.000,0,0,3
3749002330.414000,0.000,Standby,236.191,238.450,0.000,0.000,1,1,2.000,2.000,0,0,3
3749002420.414000,0.000,Standby,233.056,235.548,0.000,0.000,1,1,2.000,2.000,0,0,3
3749002510.414000,0.000,Standby,230.123,232.802,0.000,0.000,1,1,2.000,2.000,0,0,3
3749002600.414000,0.000,Standby,227.378,230.195,0.000,0.000,1,1,2.000,2.000,0,0,3
3749002690.414000,0.000,Standby,224.783,227.699,0.000,0.000,1,1,2.000,2.000,0,0,3
3749002780.414000,0.000,Standby,222.355,225.335,0.000,0.000,1,1,2.000,2.000,0,0,3
3749002870.414000,0.000,Standby,220.059,223.088,0.000,0.000,1,1,2.000,2.000,0,0,3
3749002960.414000,0.000,Standby,217.886,220.927,0.000,0.000,1,1,2.000,2.000,0,0,3
3749003050.414000,0.000,Standby,215.821,218.863,0.000,0.000,0,0,2.000,2.000,0,0,4
3749003140.414000,0.000,Standby,213.837,216.864,0.000,0.000,0,0,2.000,2.000,0,0,4
3749003230.414000,0.000,Standby,211.966,214.972,0.000,0.000,0,0,2.000,2.000,0,0,4
3749003320.414000,0.000,Standby,210.180,213.158,0.000,0.000,0,0,2.000,2.000,0,0,4
3749003410.414000,0.000,Standby,208.470,211.411,0.000,0.000,0,0,2.000,2.000,0,0,4
3749003500.414000,0.000,Standby,206.828,209.732,0.000,0.000,0,0,2.000,2.000,0,0,4
3749003590.414000,0.000,Standby,205.250,208.112,0.000,0.000,0,0,2.000,2.000,0,0,4
3749003680.414000,0.000,Standby,203.729,206.548,0.000,0.000,0,0,2.000,2.000,0,0,4
3749003770.414000,0.000,Standby,202.242,205.015,0.000,0.000,0,0,2.000,2.000,0,0,4
3749003860.414000,0.000,Standby,200.821,203.548,0.000,0.000,0,0,2.000,2.000,0,0,4
3749003950.414000,0.000,Standby,199.449,202.127,0.000,0.000,0,0,2.000,2.000,0,0,4
3749004040.414000,0.000,Standby,198.115,200.746,0.000,0.000,0,0,2.000,2.000,0,0,4
3749004130.414000,0.000,Standby,196.816,199.403,0.000,0.000,0,0,2.000,2.000,0,0,4
3749004220.414000,0.000,Standby,195.552,198.096,0.000,0.000,0,0,2.000,2.000,0,0,4
3749004310.414000,0.000,Standby,194.321,196.823,0.000,0.000,0,0,2.000,2.000,0,0,4
3749004400.414000,0.000,Standby,193.119,195.582,0.000,0.000,0,0,2.000,2.000,0,0,4
3749004490.414000,0.000,Standby,191.930,194.356,0.000,0.000,0,0,2.000,2.000,0,0,4
3749004580.414000,0.000,Standby,190.783,193.171,0.000,0.000,0,0,2.000,2.000,0,0,4
3749004670.414000,0.000,Standby,189.660,192.013,0.000,0.000,0,0,2.000,2.000,0,0,4
3749004760.414000,0.000,Standby,188.558,190.879,0.000,0.000,0,0,2.000,2.000,0,0,4
3749004850.414000,0.000,Standby,187.477,189.768,0.000,0.000,0,0,2.000,2.000,0,0,4
3749004940.414000,0.000,Standby,186.415,188.679,0.000,0.000,0,0,2.000,2.000,0,0,4
3749005030.414000,0.000,Standby,185.372,187.609,0.000,0.000,0,0,2.000,2.000,0,0,4
3749005120.414000,0.000,Standby,184.347,186.559,0.000,0.000,0,0,2.000,2.000,0,0,4
3749005210.414000,0.000,Standby,183.327,185.517,0.000,0.000,0,0,2.000,2.000,0,0,4
3749005300.414000,0.000,Standby,182.334,184.501,0.000,0.000,0,0,2.000,2.000,0,0,4
3749005390.414000,0.000,Standby,181.357,183.504,0.000,0.000,0,0,2.000,2.000,0,0,4
3749005480.414000,0.000,Standby,180.395,182.522,0.000,0.000,0,0,2.000,2.000,0,0,4
3749005570.414000,0.000,Standby,179.444,181.554,0.000,0.000,0,0,2.000,2.000,0,0,4
3749005660.414000,0.000,Standby,178.507,180.598,0.000,0.000,0,0,2.000,2.000,0,0,4
3749005750.414000,0.000,Standby,177.582,179.656,0.000,0.000,0,0,2.000,2.000,0,0,4
3749005840.414000,0.000,Standby,176.668,178.727,0.000,0.000,0,0,2.000,2.000,0,0,4
3749005930.414000,0.000,Standby,175.755,177.798,0.000,0.000,0,0,2.000,2.000,0,0,4
3749006020.414000,0.000,Standby,174.864,176.890,0.000,0.000,0,0,2.000,2.000,0,0,4
3749006110.414000,0.000,Standby,173.980,175.993,0.000,0.000,0,0,2.000,2.000,0,0,4
3749006200.414000,0.000,Standby,173.106,175.105,0.000,0.000,0,0,2.000,2.000,0,0,4
3749006290.414000,0.000,Standby,172.242,174.228,0.000,0.000,0,0,2.000,2.000,0,0,4
3749006380.414000,0.000,Standby,171.385,173.361,0.000,0.000,0,0,2.000,2.000,0,0,4
3749006470.414000,0.000,Standby,170.537,172.501,0.000,0.000,0,0,2.000,2.000,0,0,4
3749006560.414000,0.000,Standby,169.683,171.640,0.000,0.000,0,0,2.000,2.000,0,0,4
3749006650.414000,0.000,Standby,168.849,170.796,0.000,0.000,0,0,2.000,2.000,0,0,4
3749006740.414000,0.000,Standby,168.022,169.961,0.000,0.000,0,0,2.000,2.000,0,0,4
3749006830.414000,0.000,Standby,167.200,169.130,0.000,0.000,0,0,2.000,2.000,0,0,4
3749006920.414000,0.000,Standby,166.385,168.307,0.000,0.000,0,0,2.000,2.000,0,0,4
3749007010.414000,0.000,Standby,165.575,167.491,0.000,0.000,0,0,2.000,2.000,0,0,4
3749007100.414000,0.000,Standby,164.769,166.679,0.000,0.000,0,0,2.000,2.000,0,0,4
3749007190.414000,0.000,Standby,163.968,165.874,0.000,0.000,0,0,2.000,2.000,0,0,4
3749007280.414000,0.000,Standby,163.164,165.065,0.000,0.000,0,0,2.000,2.000,0,0,4
3749007370.414000,0.000,Standby,162.372,164.271,0.000,0.000,0,0,2.000,2.000,0,0,4
3749007460.414000,0.000,Standby,161.586,163.481,0.000,0.000,0,0,2.000,2.000,0,0,4
3749007550.414000,0.000,Standby,160.806,162.697,0.000,0.000,0,0,2.000,2.000,0,0,4
3749007640.414000,0.000,Standby,160.029,161.918,0.000,0.000,0,0,2.000,2.000,0,0,4
3749007730.414000,0.000,Standby,159.258,161.144,0.000,0.000,0,0,2.000,2.000,0,0,4
3749007820.414000,0.000,Standby,158.490,160.375,0.000,0.000,0,0,2.000,2.000,0,0,4
3749007910.414000,0.000,Standby,157.719,159.602,0.000,0.000,0,0,2.000,2.000,0,0,4
3749008000.414000,0.000,Standby,156.960,158.842,0.000,0.000,0,0,2.000,2.000,0,0,4
3749008090.414000,0.000,Standby,156.205,158.085,0.000,0.000,0,0,2.000,2.000,0,0,4
3749008180.414000,0.000,Standby,155.454,157.334,0.000,0.000,0,0,2.000,2.000,0,0,4
3749008270.414000,0.000,Standby,154.708,156.587,0.000,0.000,0,0,2.000,2.000,0,0,4
3749008360.414000,0.000,Standby,153.967,155.844,0.000,0.000,0,0,2.000,2.000,0,0,4
3749008450.414000,0.000,Standby,153.228,155.104,0.000,0.000,0,0,2.000,2.000,0,0,4
3749008540.414000,0.000,Standby,152.494,154.368,0.000,0.000,0,0,2.000,2.000,0,0,4
3749008630.414000,0.000,Standby,151.755,153.627,0.000,0.000,0,0,2.000,2.000,0,0,4
3749008720.414000,0.000,Standby,151.029,152.899,0.000,0.000,0,0,2.000,2.000,0,0,4
3749008810.414000,0.000,Standby,150.305,152.174,0.000,0.000,0,0,2.000,2.000,0,0,4
3749008900.414000,0.000,Standby,149.584,151.451,0.000,0.000,0,0,2.000,2.000,0,0,4
3749008990.414000,0.000,Standby,148.868,150.733,0.000,0.000,0,0,2.000,2.000,0,0,4
3749009080.414000,0.000,Standby,148.154,150.020,0.000,0.000,0,0,2.000,2.000,0,0,4
3749009170.414000,0.000,Standby,147.444,149.308,0.000,0.000,0,0,2.000,2.000,0,0,4
3749009260.414000,0.000,Standby,146.736,148.599,0.000,0.000,0,0,2.000,2.000,0,0,4
3749009350.414000,0.000,Standby,146.025,147.886,0.000,0.000,0,0,2.000,2.000,0,0,4
3749009440.414000,0.000,Standby,145.324,147.184,0.000,0.000,0,0,2.000,2.000,0,0,4
3749009530.414000,0.000,Standby,144.626,146.485,0.000,0.000,0,0,2.000,2.000,0,0,4
3749009620.414000,0.000,Standby,143.931,145.790,0.000,0.000,0,0,2.000,2.000,0,0,4
3749009710.414000,0.000,Standby,143.240,145.097,0.000,0.000,0,0,2.000,2.000,0,0,4
3749009800.414000,0.000,Standby,142.550,144.408,0.000,0.000,0,0,2.000,2.000,0,0,4
3749009890.414000,0.000,Standby,141.864,143.721,0.000,0.000,0,0,2.000,2.000,0,0,4
3749009980.414000,0.000,Standby,141.173,143.028,0.000,0.000,0,0,2.000,2.000,0,0,4
3749010070.414000,0.000,Standby,140.493,142.347,0.000,0.000,0,0,2.000,2.000,0,0,4
3749010160.414000,0.000,Standby,139.811,141.658,0.000,0.000,0,0,2.000,2.000,0,0,4
3749010250.414000,0.000,Standby,139.017,140.879,0.000,0.000,0,0,2.000,2.000,0,0,4
3749010340.414000,0.000,Standby,138.049,139.977,0.000,0.000,0,0,2.000,2.000,0,0,4
3749010430.414000,0.000,Standby,136.923,138.951,0.000,0.000,0,0,2.000,2.000,0,0,4
3749010520.414000,0.000,Standby,135.662,137.815,0.000,0.000,0,0,2.000,2.000,0,0,4
3749010610.414000,0.000,Standby,134.268,136.563,0.000,0.000,0,0,2.000,2.000,0,0,4
3749010700.414000,0.000,Standby,132.730,135.148,0.000,0.000,0,0,2.000,2.000,0,0,4
3749010790.414000,0.000,Standby,130.734,133.328,0.000,0.000,0,0,2.000,2.000,0,0,4
3749010880.414000,0.000,Standby,128.223,131.079,0.000,0.000,0,0,2.000,2.000,0,0,4
3749010970.414000,0.000,Standby,125.288,128.462,0.000,0.000,0,0,2.000,2.000,0,0,4
3749011060.414000,0.000,Standby,122.022,125.436,0.000,0.000,0,0,2.000,2.000,0,0,4
3749011150.414000,0.000,Standby,118.512,122.243,0.000,0.000,0,0,2.000,2.000,0,0,4
3749011240.414000,0.000,Standby,114.818,118.860,0.000,0.000,0,0,2.000,2.000,0,0,4
3749011330.414000,0.000,Standby,110.929,115.268,0.000,0.000,0,0,2.000,2.000,0,0,4
3749011420.414000,0.000,Standby,106.960,111.578,0.000,0.000,0,0,2.000,2.000,0,0,4
3749011510.414000,0.000,Standby,102.904,107.786,0.000,0.000,0,0,2.000,2.000,0,0,4
3749011600.414000,0.000,Standby,98.769,103.885,0.000,0.000,0,0,2.000,2.000,0,0,4
3749011690.414000,0.000,Standby,94.566,99.938,0.000,0.000,0,0,2.000,2.000,0,0,4
3749011780.414000,0.000,Standby,90.295,95.905,0.000,0.000,0,0,2.000,2.000,0,0,4
3749011870.414000,0.000,Standby,85.982,91.805,0.000,0.000,0,0,2.000,2.000,0,0,4
3749011960.414000,0.000,Standby,81.585,87.618,0.000,0.000,0,0,2.000,2.000,0,0,4
3749012050.414000,0.000,Standby,77.202,83.447,0.000,0.000,0,0,2.000,2.000,0,0,4
3749012140.414000,0.000,Standby,72.776,79.172,0.000,0.000,0,0,2.000,2.000,0,0,4
3749012230.414000,0.000,Standby,68.315,74.838,0.000,0.000,0,0,2.000,2.000,0,0,4
3749012320.414000,0.000,Standby,63.785,70.415,0.000,0.000,0,0,2.000,2.000,0,0,4
3749012410.414000,0.000,Standby,59.210,65.910,0.000,0.000,0,0,2.000,2.000,0,0,4
3749012500.414000,0.000,Standby,54.577,61.307,0.000,0.000,0,0,2.000,2.000,0,0,4
3749012590.414000,0.000,Standby,49.828,56.506,0.000,0.000,0,0,2.000,2.000,0,0,4
3749012680.414000,0.000,Standby,44.918,51.372,0.000,0.000,0,0,2.000,2.000,0,0,4
3749012770.414000,0.000,Standby,39.952,45.983,0.000,0.000,0,0,2.000,2.000,0,0,4
3749012860.414000,0.000,Standby,34.842,40.093,0.000,0.000,0,0,2.000,2.000,0,0,4
3749012950.414000,0.000,Standby,29.668,33.645,0.000,0.000,0,0,2.000,2.000,0,0,4
3749013040.414000,0.000,Standby,24.707,26.774,0.000,0.000,0,0,2.000,2.000,0,0,4
3749013130.414000,0.000,Standby,21.633,22.005,0.000,0.000,0,0,2.000,2.000,0,0,4
3749013220.414000,0.000,Standby,20.466,20.278,0.000,0.000,0,0,2.000,2.000,0,0,4
3749013310.414000,0.000,Standby,20.261,19.893,0.000,0.000,0,0,2.000,2.000,0,0,4
3749013400.414000,0.000,Standby,20.349,19.929,0.000,0.000,0,0,2.000,2.000,0,0,4
3749013490.414000,0.000,Standby,20.371,20.025,0.000,0.000,0,0,2.000,2.000,0,0,4
3749013580.414000,0.000,Standby,19.696,19.554,0.000,0.000,0,0,2.000,2.000,0,0,4
3749013670.414000,0.000,Standby,17.000,16.949,0.000,0.000,0,0,2.000,2.000,0,0,4
3749013760.414000,0.000,Standby,12.335,11.980,0.000,0.000,0,0,2.000,2.000,0,0,4
3749013850.414000,0.000,Standby,7.846,7.298,0.000,0.000,0,0,2.000,2.000,0,0,4
3749013940.414000,0.000,Standby,5.467,4.898,0.000,0.000,0,0,2.000,2.000,0,0,4
3749014030.414000,0.000,Standby,4.222,3.548,0.000,0.000,0,0,2.000,2.000,0,0,4
3749014120.414000,0.000,Standby,2.625,1.965,0.000,0.000,0,0,2.000,2.000,0,0,4
3749014210.414000,0.000,Standby,2.682,2.253,0.000,0.000,0,0,2.000,2.000,0,0,4
3749014300.414000,0.000,Standby,1.765,1.726,0.000,0.000,0,0,2.000,2.000,0,0,4
3749014390.414000,0.000,Standby,2.811,3.690,0.000,0.000,0,0,2.000,2.000,0,0,4
3749014480.414000,0.000,Standby,2.739,4.071,0.000,0.000,0,0,2.000,2.000,4,11,4
3749014570.414000,0.000,Standby,2.946,3.102,0.000,0.000,0,0,2.000,2.000,0,0,4
3749014660.414000,0.000,Standby,3.879,2.240,0.000,0.000,0,0,2.000,2.000,1,0,4
3749014750.414000,0.000,Standby,1.895,2.198,0.000,0.000,0,0,2.000,2.000,91,12,4
3749014840.414000,0.000,Standby,1.708,1.683,0.000,0.000,0,0,2.000,2.000,0,0,4
3749014930.414000,0.000,Standby,3.876,2.360,0.000,0.000,0,0,2.000,2.000,0,0,4
3749015020.414000,0.000,Standby,3.945,2.303,0.000,0.000,0,0,2.000,2.000,20,0,4
3749015110.414000,0.000,Standby,3.968,2.307,0.000,0.000,0,0,2.000,2.000,21,0,4
3749015200.414000,0.000,Standby,3.969,2.299,0.000,0.000,0,0,2.000,2.000,35,0,4
3749015290.414000,0.000,Standby,3.971,2.302,0.000,0.000,0,0,2.000,2.000,0,0,4
3749015380.414000,0.000,Standby,1.984,3.265,0.000,0.000,0,0,2.000,2.000,3,12,4
3749015470.414000,0.000,Standby,1.749,1.743,0.000,0.000,0,0,2.000,2.000,0,0,4
3749015560.414000,0.000,Standby,1.893,2.055,0.000,0.000,0,0,2.000,2.000,9,0,4
3749015650.414000,0.000,Standby,1.888,2.050,0.000,0.000,0,0,2.000,2.000,9,0,4
3749015740.414000,0.000,Standby,1.885,2.055,0.000,0.000,0,0,2.000,2.000,10,2,4
3749015830.414000,0.000,Standby,1.883,2.051,0.000,0.000,0,0,2.000,2.000,10,0,4
3749015920.414000,0.000,Standby,1.882,2.057,0.000,0.000,0,0,2.000,2.000,11,0,4
3749016010.414000,0.000,Standby,1.880,2.051,0.000,0.000,0,0,2.000,2.000,10,0,4
3749016100.414000,0.000,Standby,1.875,2.055,0.000,0.000,0,0,2.000,2.000,11,0,4
3749016190.414000,0.000,Standby,1.872,2.056,0.000,0.000,0,0,2.000,2.000,12,1,4
3749016280.414000,0.000,Standby,1.871,2.052,0.000,0.000,0,0,2.000,2.000,11,0,4
3749016370.414000,0.000,Standby,1.870,2.059,0.000,0.000,0,0,2.000,2.000,11,0,4
3749016460.414000,3.253,Sweeping up,1.868,2.054,0.000,0.000,0,0,2.000,2.000,12,2,4
3749016550.414000,0.526,Sweeping to zero,1.871,2.051,0.000,0.000,0,0,2.000,2.000,11,0,4
3749016640.414000,0.000,Standby,1.864,2.057,0.000,0.000,0,0,2.000,2.000,12,0,4
3749016730.414000,0.000,Standby,1.664,1.655,0.000,0.000,0,0,2.000,2.000,0,0,4
3749016820.414000,0.000,Standby,1.614,1.615,0.000,0.000,0,0,2.000,2.000,0,0,4
3749016910.414000,0.274,Sweeping up,1.589,1.594,0.000,0.000,0,0,2.000,2.000,0,0,4
3749017000.414000,3.636,Sweeping to zero,1.575,1.586,0.000,0.000,0,0,2.000,2.000,0,0,4
3749017090.414000,0.000,Standby,1.568,1.575,0.000,0.000,0,0,2.000,2.000,0,0,4
3749017180.414000,0.000,Standby,1.560,1.568,0.000,0.000,0,0,2.000,2.000,0,0,4
3749017270.414000,0.000,Standby,1.553,1.562,0.000,0.000,0,0,2.000,2.000,0,0,4
3749017360.414000,0.000,Standby,1.547,1.557,0.000,0.000,0,0,2.000,2.000,0,0,4
3749017450.414000,0.000,Standby,1.542,1.553,0.000,0.000,0,0,2.000,2.000,0,0,4
3749017540.414000,0.000,Standby,1.538,1.549,0.000,0.000,0,0,2.000,2.000,0,0,4
3749017630.414000,0.000,Standby,1.534,1.546,0.000,0.000,0,0,2.000,2.000,0,0,4
3749017720.414000,0.000,Standby,1.530,1.543,0.000,0.000,0,0,2.000,2.000,0,0,4
3749017810.414000,0.000,Standby,1.526,1.540,0.000,0.000,0,0,2.000,2.000,0,0,4
3749017900.414000,0.000,Standby,1.522,1.537,0.000,0.000,0,0,2.000,2.000,0,0,4
3749017990.414000,0.000,Standby,1.519,1.534,0.000,0.000,0,0,2.000,2.000,0,0,4
3749018080.414000,0.000,Standby,1.515,1.531,0.000,0.000,0,0,2.000,2.000,0,0,4
3749018170.414000,0.000,Standby,1.512,1.528,0.000,0.000,0,0,2.000,2.000,0,0,4
3749018260.414000,0.000,Standby,1.509,1.525,0.000,0.000,0,0,2.000,2.000,0,0,4
3749018350.414000,0.000,Standby,1.506,1.522,0.000,0.000,0,0,2.000,2.000,0,0,4
3749018440.414000,0.000,Standby,1.503,1.519,0.000,0.000,0,0,2.000,2.000,0,0,4
3749018530.414000,0.000,Standby,1.500,1.516,0.000,0.000,0,0,2.000,2.000,0,0,4
3749018620.414000,0.000,Standby,1.498,1.513,0.000,0.000,0,0,2.000,2.000,0,0,4
3749018710.414000,0.000,Standby,1.495,1.510,0.000,0.000,0,0,2.000,2.000,0,0,4
3749018800.414000,0.000,Standby,1.493,1.508,0.000,0.000,0,0,2.000,2.000,0,0,4
3749018890.414000,0.000,Standby,1.491,1.505,0.000,0.000,0,0,2.000,2.000,0,0,4
3749018980.414000,0.000,Standby,1.489,1.503,0.000,0.000,0,0,2.000,2.000,0,0,4
3749019070.414000,0.000,Standby,1.487,1.501,0.000,0.000,0,0,2.000,2.000,0,0,4
3749019160.414000,0.000,Standby,1.485,1.499,0.000,0.000,0,0,2.000,2.000,0,0,4
3749019250.414000,0.000,Standby,1.483,1.497,0.000,0.000,0,0,2.000,2.000,0,0,4
3749019340.414000,0.000,Standby,1.489,1.504,0.000,0.000,0,0,2.000,2.000,0,0,4
3749019430.414000,0.000,Standby,1.489,1.507,0.000,0.000,0,0,2.000,2.000,0,0,4
3749019520.414000,0.000,Standby,1.500,1.519,0.000,0.000,0,0,2.000,2.000,0,0,4
3749019610.414000,0.000,Standby,1.510,1.529,0.000,0.000,0,0,2.000,2.000,0,0,4
3749019700.414000,0.000,Standby,1.515,1.535,0.000,0.000,0,0,2.000,2.000,0,0,4
3749019790.414000,0.000,Standby,1.518,1.539,0.000,0.000,0,0,2.000,2.000,0,0,4
3749019880.414000,0.000,Standby,1.520,1.541,0.000,0.000,0,0,2.000,2.000,0,0,4
3749019970.414000,0.000,Standby,1.521,1.542,0.000,0.000,0,0,2.000,2.000,0,0,4
3749020060.414000,0.000,Standby,1.521,1.542,0.000,0.000,0,0,2.000,2.000,0,0,4
3749020150.414000,0.000,Standby,1.520,1.542,0.000,0.000,0,0,2.000,2.000,0,0,4
3749020240.414000,0.000,Standby,1.520,1.541,0.000,0.000,0,0,2.000,2.000,0,0,4
3749020330.414000,0.000,Standby,1.519,1.541,0.000,0.000,0,0,2.000,2.000,0,0,4
3749020420.414000,0.000,Standby,1.519,1.540,0.000,0.000,0,0,2.000,2.000,0,0,4
3749020510.414000,0.000,Standby,1.518,1.540,0.000,0.000,0,0,2.000,2.000,0,0,4
3749020600.414000,0.000,Standby,1.517,1.539,0.000,0.000,0,0,2.000,2.000,0,0,4
3749020690.414000,0.000,Standby,1.516,1.538,0.000,0.000,0,0,2.000,2.000,0,0,4
3749020780.414000,0.000,Standby,1.516,1.538,0.000,0.000,0,0,2.000,2.000,0,0,4
3749020870.414000,0.000,Standby,1.516,1.537,0.000,0.000,0,0,2.000,2.000,0,0,4
3749020960.414000,0.000,Standby,1.515,1.537,0.000,0.000,0,0,2.000,2.000,0,0,4
3749021050.414000,0.000,Standby,1.515,1.537,0.000,0.000,0,0,2.000,2.000,0,0,4
3749021140.414000,0.000,Standby,1.514,1.537,0.000,0.000,0,0,2.000,2.000,0,0,4
3749021230.414000,0.000,Standby,1.514,1.536,0.000,0.000,0,0,2.000,2.000,0,0,4
3749021320.414000,0.000,Standby,1.514,1.536,0.000,0.000,0,0,2.000,2.000,0,0,4
3749021410.414000,0.000,Standby,1.514,1.536,0.000,0.000,0,0,2.000,2.000,0,0,4
3749021500.414000,0.000,Standby,1.513,1.536,0.000,0.000,0,0,2.000,2.000,0,0,4
3749021590.414000,0.000,Standby,1.513,1.536,0.000,0.000,0,0,2.000,2.000,0,0,4
3749021680.414000,0.000,Standby,1.513,1.536,0.000,0.000,0,0,2.000,2.000,0,0,4
3749021770.414000,0.000,Standby,1.512,1.535,0.000,0.000,0,0,2.000,2.000,0,0,4
3749021860.414000,0.000,Standby,1.512,1.535,0.000,0.000,0,0,2.000,2.000,0,0,4
3749021950.414000,0.000,Standby,1.512,1.535,0.000,0.000,0,0,2.000,2.000,0,0,4
3749022040.414000,0.000,Standby,1.512,1.534,0.000,0.000,0,0,2.000,2.000,0,0,4
3749022130.414000,0.000,Standby,1.511,1.534,0.000,0.000,0,0,2.000,2.000,0,0,4
3749022220.414000,0.000,Standby,1.511,1.534,0.000,0.000,0,0,2.000,2.000,0,0,4
3749022310.414000,0.000,Standby,1.511,1.534,0.000,0.000,0,0,2.000,2.000,0,0,4
3749022400.414000,0.000,Standby,1.511,1.534,0.000,0.000,0,0,2.000,2.000,0,0,4
3749022490.414000,0.000,Standby,1.510,1.534,0.000,0.000,0,0,2.000,2.000,0,0,4
3749022580.414000,0.000,Standby,1.511,1.534,0.000,0.000,0,0,2.000,2.000,0,0,4
3749022670.414000,0.000,Standby,1.510,1.534,0.000,0.000,0,0,2.000,2.000,0,0,4
3749022760.414000,0.000,Standby,1.510,1.533,0.000,0.000,0,0,2.000,2.000,0,0,4
3749022850.414000,0.000,Standby,1.510,1.534,0.000,0.000,0,0,2.000,2.000,0,0,4
3749022940.414000,0.000,Standby,1.510,1.533,0.000,0.000,0,0,2.000,2.000,0,0,4
3749023030.414000,0.000,Standby,1.510,1.533,0.000,0.000,0,0,2.000,2.000,0,0,4
3749023120.414000,0.000,Standby,1.510,1.533,0.000,0.000,0,0,2.000,2.000,0,0,4
3749023210.414000,0.000,Standby,1.510,1.533,0.000,0.000,0,0,2.000,2.000,0,0,4
3749023300.414000,0.000,Standby,1.510,1.533,0.000,0.000,0,0,2.000,2.000,0,0,4
3749023390.414000,0.000,Standby,1.509,1.533,0.000,0.000,0,0,2.000,2.000,0,0,4
3749023480.414000,0.000,Standby,1.509,1.533,0.000,0.000,0,0,2.000,2.000,0,0,4
3749023570.414000,0.000,Standby,1.509,1.533,0.000,0.000,0,0,2.000,2.000,0,0,4
3749023660.414000,0.000,Standby,1.509,1.533,0.000,0.000,0,0,2.000,2.000,0,0,4
3749023750.414000,0.000,Standby,1.509,1.533,0.000,0.000,0,0,2.000,2.000,0,0,4
3749023840.414000,0.000,Standby,1.509,1.533,0.000,0.000,0,0,2.000,2.000,0,0,4
3749023930.414000,0.000,Standby,1.509,1.533,0.000,0.000,0,0,2.000,2.000,0,0,4
3749024020.414000,0.000,Standby,1.509,1.532,0.000,0.000,0,0,2.000,2.000,0,0,4
3749024110.414000,0.000,Standby,1.509,1.532,0.000,0.000,0,0,2.000,2.000,0,0,4
3749024200.414000,0.000,Standby,1.509,1.532,0.000,0.000,0,0,2.000,2.000,0,0,4
3749024290.414000,0.000,Standby,1.509,1.533,0.000,0.000,0,0,2.000,2.000,0,0,4
3749024380.414000,0.000,Standby,1.508,1.532,0.000,0.000,0,0,2.000,2.000,0,0,4
3749024470.414000,0.000,Standby,1.508,1.532,0.000,0.000,0,0,2.000,2.000,0,0,4
3749024560.414000,0.000,Standby,1.508,1.532,0.000,0.000,0,0,2.000,2.000,0,0,4
3749024650.414000,0.000,Standby,1.508,1.532,0.000,0.000,0,0,2.000,2.000,0,0,4
3749024740.414000,0.000,Standby,1.508,1.532,0.000,0.000,0,0,2.000,2.000,0,0,4
3749024830.414000,0.000,Standby,1.508,1.532,0.000,0.000,0,0,2.000,2.000,0,0,4
3749024920.414000,0.000,Standby,1.508,1.532,0.000,0.000,0,0,2.000,2.000,0,0,4
3749025010.414000,0.000,Standby,1.508,1.532,0.000,0.000,0,0,2.000,2.000,0,0,4
3749025100.414000,0.000,Standby,1.508,1.532,0.000,0.000,0,0,2.000,2.000,0,0,4
3749025190.414000,0.000,Standby,1.508,1.532,0.000,0.000,0,0,2.000,2.000,0,0,4
3749025280.414000,0.000,Standby,1.508,1.532,0.000,0.000,0,0,2.000,2.000,0,0,4
3749025370.414000,0.000,Standby,1.508,1.532,0.000,0.000,0,0,2.000,2.000,0,0,4
3749025460.414000,0.000,Standby,1.508,1.532,0.000,0.000,0,0,2.000,2.000,0,0,4
3749025550.414000,0.000,Standby,1.508,1.532,0.000,0.000,0,0,2.000,2.000,0,0,4
3749025640.414000,0.000,Standby,1.508,1.532,0.000,0.000,0,0,2.000,2.000,0,0,4
3749025730.414000,0.000,Standby,1.508,1.532,0.000,0.000,0,0,2.000,2.000,0,0,4
3749025820.414000,0.000,Standby,1.508,1.532,0.000,0.000,0,0,2.000,2.000,0,0,4
3749025910.414000,0.000,Standby,1.508,1.532,0.000,0.000,0,0,2.000,2.000,0,0,4
3749026000.414000,0.000,Standby,1.508,1.532,0.000,0.000,0,0,2.000,2.000,0,0,4
3749026090.414000,0.000,Standby,1.508,1.532,0.000,0.000,0,0,2.000,2.000,0,0,4
3749026180.414000,0.000,Standby,1.508,1.532,0.000,0.000,0,0,2.000,2.000,0,0,4
3749026270.414000,0.000,Standby,1.508,1.532,0.000,0.000,0,0,2.000,2.000,0,0,4
3749026360.414000,0.000,Standby,1.508,1.532,0.000,0.000,0,0,2.000,2.000,0,0,4
3749026450.414000,0.000,Standby,1.508,1.532,0.000,0.000,0,0,2.000,2.000,0,0,4
3749026540.414000,0.000,Standby,1.508,1.532,0.000,0.000,0,0,2.000,2.000,0,0,4
3749026630.414000,0.000,Standby,1.508,1.532,0.000,0.000,0,0,2.000,2.000,0,0,4
3749026720.414000,0.000,Standby,1.508,1.532,0.000,0.000,0,0,2.000,2.000,0,0,4
3749026810.414000,0.000,Standby,1.508,1.532,0.000,0.000,0,0,2.000,2.000,0,0,4
3749026900.414000,0.000,Standby,1.508,1.532,0.000,0.000,0,0,2.000,2.000,0,0,4
3749026990.414000,0.000,Standby,1.508,1.532,0.000,0.000,0,0,2.000,2.000,0,0,4
3749027080.414000,0.000,Standby,1.508,1.532,0.000,0.000,0,0,2.000,2.000,0,0,4
3749027170.414000,0.000,Standby,1.508,1.532,0.000,0.000,0,0,2.000,2.000,0,0,4
3749027260.414000,0.000,Standby,1.508,1.532,0.000,0.000,0,0,2.000,2.000,0,0,4
3749027350.414000,0.000,Standby,1.508,1.532,0.000,0.000,0,0,2.000,2.000,0,0,4
3749027440.414000,0.000,Standby,1.508,1.532,0.000,0.000,0,0,2.000,2.000,0,0,4
3749027530.414000,0.000,Standby,1.508,1.532,0.000,0.000,0,0,2.000,2.000,0,0,4
3749027620.414000,0.000,Standby,1.508,1.532,0.000,0.000,0,0,2.000,2.000,0,0,4
3749027710.414000,0.000,Standby,1.508,1.532,0.000,0.000,0,0,2.000,2.000,0,0,4
3749027800.414000,0.000,Standby,1.508,1.532,0.000,0.000,0,0,2.000,2.000,0,0,4
3749027890.414000,0.000,Standby,1.508,1.532,0.000,0.000,0,0,2.000,2.000,0,0,4
3749027980.414000,0.000,Standby,1.508,1.532,0.000,0.000,0,0,2.000,2.000,0,0,4
3749028070.414000,0.000,Standby,1.508,1.532,0.000,0.000,0,0,2.000,2.000,0,0,4
3749028160.414000,0.000,Standby,1.508,1.532,0.000,0.000,0,0,2.000,2.000,0,0,4
3749028250.414000,0.000,Standby,1.508,1.532,0.000,0.000,0,0,2.000,2.000,0,0,4
3749028340.414000,0.000,Standby,1.508,1.532,0.000,0.000,0,0,2.000,2.000,0,0,4
3749028430.414000,0.000,Standby,1.508,1.532,0.000,0.000,0,0,2.000,2.000,0,0,4
3749028520.414000,3.259,Sweeping up,1.508,1.537,0.000,0.000,0,0,2.000,2.000,0,0,4
3749028610.414000,10.403,Sweeping up,1.509,1.556,0.000,0.000,0,0,2.000,2.000,0,0,4
3749028700.414000,17.746,Sweeping up,1.513,1.583,0.000,0.000,0,0,2.000,2.000,0,0,4
3749028790.414000,25.049,Sweeping up,1.517,1.606,0.000,0.000,0,0,2.000,2.000,0,0,4
3749028880.414000,32.314,Sweeping up,1.520,1.622,0.000,0.000,0,0,2.000,2.000,0,0,4
3749028970.414000,39.624,Sweeping up,1.522,1.634,0.000,0.000,0,0,2.000,2.000,0,0,4
3749029060.414000,46.980,Sweeping up,1.525,1.643,0.000,0.000,0,0,2.000,2.000,0,0,4
3749029150.414000,54.178,Sweeping up,1.529,1.651,0.000,0.000,0,0,2.000,2.000,0,0,4
3749029240.414000,57.894,Sweeping up,1.530,1.654,0.000,0.000,0,0,2.000,2.000,0,0,4
3749029330.414000,60.714,Sweeping up,1.531,1.654,0.000,0.000,0,0,2.000,2.000,0,0,4
3749029420.414000,62.793,Sweeping up,1.532,1.655,0.000,0.000,0,0,2.000,2.000,0,0,4
3749029510.414000,64.787,Sweeping up,1.533,1.656,0.000,0.000,0,0,2.000,2.000,0,0,4
3749029600.414000,66.661,Sweeping up,1.534,1.657,0.000,0.000,0,0,2.000,2.000,0,0,4
3749029690.414000,68.422,Sweeping up,1.535,1.659,0.000,0.000,0,0,2.000,2.000,0,0,4
3749029780.414000,70.095,Sweeping up,1.537,1.660,0.000,0.000,0,0,2.000,2.000,0,0,4
3749029870.414000,71.684,Sweeping up,1.538,1.662,0.000,0.000,0,0,2.000,2.000,0,0,4
3749029960.414000,73.162,Sweeping up,1.539,1.663,0.000,0.000,0,0,2.000,2.000,0,0,4
3749030050.414000,74.586,Sweeping up,1.540,1.665,0.000,0.000,0,0,2.000,2.000,0,0,4
3749030140.414000,75.926,Sweeping up,1.541,1.665,0.000,0.000,0,0,2.000,2.000,0,0,4
3749030230.414000,77.186,Sweeping up,1.542,1.667,0.000,0.000,0,0,2.000,2.000,0,0,4
3749030320.414000,78.386,Sweeping up,1.543,1.667,0.000,0.000,0,0,2.000,2.000,0,0,4
3749030410.414000,76.784,Sweeping up,1.543,1.669,0.000,0.000,0,0,2.000,2.000,0,0,4
3749030500.414000,71.516,Sweeping up,1.540,1.664,0.000,0.000,0,0,2.000,2.000,0,0,4
3749030590.414000,73.049,Sweeping up,1.541,1.666,0.000,0.000,0,0,2.000,2.000,0,0,4
3749030680.414000,74.442,Sweeping up,1.541,1.666,0.000,0.000,0,0,2.000,2.000,0,0,4
3749030770.414000,75.677,Pause,1.542,1.666,0.000,0.000,0,0,2.000,2.000,0,0,4
3749030860.414000,77.012,Sweeping up,1.542,1.667,0.000,0.000,0,0,2.000,2.000,0,0,4
3749030950.414000,78.210,Sweeping up,1.543,1.667,0.000,0.000,0,0,2.000,2.000,0,0,4
3749031040.414000,77.513,Sweeping up,1.543,1.670,0.000,0.000,0,0,2.000,2.000,0,0,4
3749031130.414000,68.513,Sweeping to zero,1.539,1.664,0.000,0.000,0,0,2.000,2.000,0,0,4
3749031220.414000,69.010,Sweeping to zero,1.540,1.664,0.000,0.000,0,0,2.000,2.000,0,0,4
3749031310.414000,70.603,Sweeping to zero,1.541,1.665,0.000,0.000,0,0,2.000,2.000,0,0,4
3749031400.414000,72.112,Sweeping to zero,1.541,1.665,0.000,0.000,0,0,2.000,2.000,0,0,4
3749031490.414000,73.550,Sweeping to zero,1.541,1.665,0.000,0.000,0,0,2.000,2.000,0,0,4
3749031580.414000,74.894,Sweeping to zero,1.542,1.666,0.000,0.000,0,0,2.000,2.000,0,0,4
3749031670.414000,76.193,Sweeping down,1.543,1.667,0.000,0.000,0,0,2.000,2.000,0,0,4
3749031756.692000,75.528,Sweeping to zero,1.543,1.669,0.000,0.000,0,0,2.000,2.000,0,0,4
3749031786.692000,72.475,Sweeping to zero,1.541,1.667,0.000,0.000,0,0,2.000,2.000,0,0,4