File: log/20221231.dat
[Header]
; Displex Transport Data File (default extension .dat)
; Copyright 2016, Hechang LEI, hlei@ruc.edu.cn. All rights reserved.
BYAPP, Displex, 2.0
INFO, 9T mag, Release 2.0.
INFO, Channel 1, Temperature Sensor
INFO, Sample 1 Length (cm): 0.000000; Width (cm): 0.000000; Thickness (cm): 0.000000.

[Data]
Timestamp(s),Field(Oe),Field Status,TempA(K),TempB(K),TempC(K),TempD(K),Ramp1,Ramp2,Setpoint1,Setpoint2,Output1(%),Output2(%),Temp Status
3755332316.059400,0,1,299.986,300.075,42.587,3.229,0,0,300.000,300.000,13.640,11.090,4
3755332586.059400,0,1,300.074,299.998,42.904,3.228,0,0,300.000,300.000,14.160,10.290,1
3755332820.751400,0,1,299.678,299.436,42.976,3.229,1,1,2.000,2.000,0.000,3.500,3
3755333090.751400,0,1,288.282,288.689,42.928,3.228,1,1,300.000,300.000,0.000,0.000,3
3755333353.464400,0,1,300.909,300.008,42.827,3.230,0,0,300.000,300.000,7.250,10.760,4
3755333623.464400,0,1,299.841,300.000,42.713,3.229,0,0,300.000,300.000,26.680,10.310,1
3755333893.464400,0,1,299.474,300.001,42.606,3.229,0,0,300.000,300.000,11.660,10.210,1
3755334163.464400,0,1,300.452,300.002,42.510,3.230,0,0,300.000,300.000,7.170,10.190,1
3755334433.464400,0,1,300.084,299.998,42.426,3.232,0,0,300.000,300.000,20.580,10.170,1
3755334703.464400,0,1,299.617,300.001,42.356,3.230,0,0,300.000,300.000,15.570,10.120,1
3755334973.464400,0,1,300.155,300.000,42.299,3.233,0,0,300.000,300.000,9.120,10.140,1
3755335243.464400,0,1,300.170,299.999,42.256,3.232,0,0,300.000,300.000,16.410,10.120,1
3755335513.464400,0,1,299.787,299.999,42.217,3.232,0,0,300.000,300.000,16.510,10.090,1
3755335783.464400,0,1,300.000,300.001,42.182,3.233,0,0,300.000,300.000,11.360,10.060,1
3755336053.464400,0,1,300.149,300.000,42.153,3.231,0,0,300.000,300.000,14.210,10.070,1
3755336323.464400,0,1,299.909,299.999,42.127,3.234,0,0,300.000,300.000,16.230,10.030,1
3755336593.464400,0,1,299.952,0.000,42.108,3.233,0,0,300.000,300.000,12.900,0.000,4
3755336863.464400,0,1,299.942,0.000,42.153,3.234,0,0,300.000,300.000,16.050,0.000,4
3755337133.464400,0,1,300.059,0.000,42.145,3.234,0,0,300.000,300.000,16.010,0.000,4
3755337403.464400,0,1,300.005,0.000,42.095,3.233,0,0,300.000,300.000,17.700,0.000,4
3755337673.464400,0,1,299.952,0.000,42.043,3.233,0,0,300.000,300.000,17.060,0.000,4
3755337943.464400,0,1,300.029,286.557,42.235,3.232,0,0,300.000,300.000,12.990,94.710,4
3755338213.464400,0,1,300.126,300.000,42.813,3.232,0,0,300.000,300.000,14.230,9.960,1
3755338483.464400,0,1,299.919,299.999,43.096,3.233,0,0,300.000,300.000,15.850,9.890,1
3755338753.464400,0,1,299.957,300.000,43.127,3.232,0,0,300.000,300.000,13.020,9.910,1
3755339023.464400,0,1,300.247,0.000,43.056,3.233,0,0,300.000,300.000,14.800,0.000,4
3755339293.464400,0,1,299.926,0.000,42.978,3.233,0,0,300.000,300.000,19.960,0.000,4
3755339563.464400,0,1,299.865,0.000,42.820,3.232,0,0,300.000,300.000,15.750,0.000,4
3755339833.464400,0,1,300.123,0.000,42.661,3.232,0,0,300.000,300.000,14.890,0.000,4
3755340103.464400,0,1,300.008,0.000,42.756,3.233,0,0,300.000,300.000,14.270,0.000,4
3755340373.464400,0,1,300.063,0.000,43.135,3.233,0,0,300.000,300.000,17.870,0.000,4
3755340643.464400,0,1,299.895,0.000,43.137,3.233,0,0,300.000,300.000,17.780,0.000,4
3755340913.464400,0,1,300.003,0.000,42.982,3.233,0,0,300.000,300.000,15.480,0.000,4
3755341183.464400,0,1,300.070,0.000,42.811,3.233,0,0,300.000,300.000,16.950,0.000,4
3755341453.464400,0,1,299.958,0.000,42.660,3.232,0,0,300.000,300.000,17.990,0.000,4
3755341723.464400,0,1,299.969,0.000,42.537,3.232,0,0,300.000,300.000,16.570,0.000,4
3755341993.464400,0,1,300.045,0.000,42.438,3.232,0,0,300.000,300.000,16.650,0.000,4
3755342263.464400,0,1,300.000,0.000,42.353,3.232,0,0,300.000,300.000,17.740,0.000,4
3755342533.464400,0,1,299.966,0.000,42.285,3.230,0,0,300.000,300.000,17.340,0.000,4
3755342803.464400,0,1,300.019,0.000,42.227,3.232,0,0,300.000,300.000,16.790,0.000,4
3755343073.464400,0,1,300.015,0.000,42.181,3.231,0,0,300.000,300.000,17.570,0.000,4
3755343343.464400,0,1,299.979,0.000,42.140,3.231,0,0,300.000,300.000,17.610,0.000,4
3755343613.464400,0,1,299.999,0.000,42.110,3.231,0,0,300.000,300.000,17.080,0.000,4
3755343883.464400,0,1,300.017,0.000,42.086,3.230,0,0,300.000,300.000,17.370,0.000,4
3755344153.464400,0,1,299.993,0.000,42.061,3.232,0,0,300.000,300.000,17.720,0.000,4
3755344423.464400,0,1,299.991,0.000,42.035,3.231,0,0,300.000,300.000,17.410,0.000,4
3755344693.464400,0,1,300.009,0.000,42.016,3.231,0,0,300.000,300.000,17.470,0.000,4
3755344963.464400,0,1,299.999,0.000,41.996,3.231,0,0,300.000,300.000,17.720,0.000,4
3755345233.464400,0,1,299.990,0.000,41.977,3.232,0,0,300.000,300.000,17.590,0.000,4
3755345503.464400,0,1,300.001,0.000,41.960,3.231,0,0,300.000,300.000,17.390,0.000,4
3755345773.464400,0,1,300.001,0.000,41.944,3.231,0,0,300.000,300.000,17.700,0.000,4
3755346043.464400,0,1,299.995,0.000,41.930,3.232,0,0,300.000,300.000,17.660,0.000,4
3755346313.464400,0,1,299.998,0.000,41.917,3.231,0,0,300.000,300.000,17.660,0.000,4
3755346583.464400,0,1,300.002,0.000,41.906,3.230,0,0,300.000,300.000,17.610,0.000,4
3755346853.464400,0,1,300.002,0.000,41.899,3.231,0,0,300.000,300.000,17.700,0.000,4
3755347123.464400,0,1,300.000,0.000,41.891,3.230,0,0,300.000,300.000,17.700,0.000,4
3755347393.464400,0,1,300.001,0.000,41.877,3.230,0,0,300.000,300.000,17.700,0.000,4
3755347663.464400,0,1,300.000,0.000,41.865,3.228,0,0,300.000,300.000,17.820,0.000,4
3755347933.464400,0,1,299.998,0.000,41.855,3.229,0,0,300.000,300.000,17.720,0.000,4
3755348203.464400,0,1,300.001,0.000,41.846,3.229,0,0,300.000,300.000,17.700,0.000,4
3755348473.464400,0,1,300.003,0.000,41.836,3.228,0,0,300.000,300.000,17.720,0.000,4
3755348743.464400,0,1,299.997,0.000,41.828,3.227,0,0,300.000,300.000,17.840,0.000,4
3755349013.464400,0,1,299.997,0.000,41.824,3.226,0,0,300.000,300.000,17.680,0.000,4
3755349283.464400,0,1,300.005,0.000,41.817,3.227,0,0,300.000,300.000,17.780,0.000,4
3755349553.464400,0,1,299.996,0.000,41.809,3.227,0,0,300.000,300.000,17.910,0.000,4
3755349823.464400,0,1,299.998,0.000,41.800,3.225,0,0,300.000,300.000,17.720,0.000,4
3755350093.464400,0,1,300.005,0.000,41.792,3.226,0,0,300.000,300.000,17.780,0.000,4
3755350363.464400,0,1,300.002,0.000,41.790,3.225,0,0,300.000,300.000,17.840,0.000,4
3755350633.464400,0,1,299.994,0.000,41.786,3.226,0,0,300.000,300.000,17.760,0.000,4
3755350903.464400,0,1,300.000,0.000,41.781,3.225,0,0,300.000,300.000,17.780,0.000,4
3755351173.464400,0,1,300.000,0.000,41.777,3.225,0,0,300.000,300.000,17.820,0.000,4
3755351443.464400,0,1,300.000,0.000,41.772,3.226,0,0,300.000,300.000,17.820,0.000,4
3755351713.464400,0,1,299.998,0.000,41.766,3.227,0,0,300.000,300.000,17.870,0.000,4
3755351983.464400,0,1,299.998,0.000,41.758,3.227,0,0,300.000,300.000,17.780,0.000,4
3755352253.464400,0,1,300.005,0.000,41.754,3.229,0,0,300.000,300.000,17.800,0.000,4
3755352523.464400,0,1,299.998,0.000,41.752,3.228,0,0,300.000,300.000,17.910,0.000,4
3755352793.464400,0,1,299.999,0.000,41.747,3.228,0,0,300.000,300.000,17.820,0.000,4
3755353063.464400,0,1,300.003,0.000,41.744,3.227,0,0,300.000,300.000,17.840,0.000,4
3755353333.464400,0,1,299.998,0.000,41.746,3.226,0,0,300.000,300.000,17.840,0.000,4
3755353603.464400,0,1,299.999,0.000,41.744,3.225,0,0,300.000,300.000,17.840,0.000,4
3755353873.464400,0,1,299.999,0.000,41.738,3.228,0,0,300.000,300.000,17.930,0.000,4
3755354143.464400,0,1,300.000,0.000,41.737,3.225,0,0,300.000,300.000,17.840,0.000,4
3755354413.464400,0,1,300.002,0.000,41.734,3.225,0,0,300.000,300.000,17.950,0.000,4
3755354683.464400,0,1,299.998,0.000,41.733,3.226,0,0,300.000,300.000,17.910,0.000,4
3755354953.464400,0,1,300.003,0.000,41.729,3.226,0,0,300.000,300.000,17.840,0.000,4
3755355223.464400,0,1,299.998,0.000,41.726,3.227,0,0,300.000,300.000,17.930,0.000,4
3755355493.464400,0,1,299.998,0.000,41.726,3.227,0,0,300.000,300.000,17.780,0.000,4
3755355763.464400,0,1,300.003,0.000,41.726,3.227,0,0,300.000,300.000,17.840,0.000,4
3755356033.464400,0,1,300.000,0.000,41.726,3.228,0,0,300.000,300.000,17.910,0.000,4
3755356303.464400,0,1,299.998,0.000,41.727,3.227,0,0,300.000,300.000,17.930,0.000,4
3755356573.464400,0,1,300.004,0.000,41.724,3.226,0,0,300.000,300.000,17.800,0.000,4
3755356843.464400,0,1,300.002,0.000,41.721,3.227,0,0,300.000,300.000,17.890,0.000,4
3755357113.464400,0,1,299.997,0.000,41.718,3.226,0,0,300.000,300.000,17.890,0.000,4
3755357383.464400,0,1,300.000,0.000,41.716,3.227,0,0,300.000,300.000,17.840,0.000,4
3755357653.464400,0,1,300.000,0.000,41.712,3.227,0,0,300.000,300.000,17.870,0.000,4
3755357923.464400,0,1,300.000,0.000,41.714,3.226,0,0,300.000,300.000,17.950,0.000,4
3755358193.464400,0,1,299.999,0.000,41.714,3.225,0,0,300.000,300.000,17.870,0.000,4
3755358463.464400,0,1,300.002,0.000,41.713,3.226,0,0,300.000,300.000,17.870,0.000,4
3755358733.464400,0,1,299.999,0.000,41.709,3.227,0,0,300.000,300.000,17.930,0.000,4
3755359003.464400,0,1,299.994,0.000,41.705,3.226,0,0,300.000,300.000,17.930,0.000,4
3755359273.464400,0,1,300.002,0.000,41.706,3.227,0,0,300.000,300.000,17.800,0.000,4
3755359543.464400,0,1,300.002,0.000,41.703,3.226,0,0,300.000,300.000,17.970,0.000,4
3755359813.464400,0,1,299.993,0.000,41.697,3.227,0,0,300.000,300.000,17.970,0.000,4
3755360083.464400,0,1,300.005,0.000,41.699,3.227,0,0,300.000,300.000,17.780,0.000,4
3755360353.464400,0,1,300.006,0.000,41.697,3.226,0,0,300.000,300.000,17.930,0.000,4
3755360623.464400,0,1,299.997,0.000,41.699,3.226,0,0,300.000,300.000,17.950,0.000,4
3755360893.464400,0,1,299.997,0.000,41.697,3.226,0,0,300.000,300.000,17.820,0.000,4
3755361163.464400,0,1,300.006,0.000,41.698,3.225,0,0,300.000,300.000,17.870,0.000,4
3755361433.464400,0,1,299.998,0.000,41.698,3.225,0,0,300.000,300.000,17.990,0.000,4
3755361703.464400,0,1,299.998,0.000,41.696,3.225,0,0,300.000,300.000,17.870,0.000,4
3755361973.464400,0,1,300.004,0.000,41.695,3.225,0,0,300.000,300.000,17.870,0.000,4
3755362243.464400,0,1,300.000,0.000,41.694,3.225,0,0,300.000,300.000,17.950,0.000,4
3755362513.464400,0,1,299.999,0.000,41.694,3.226,0,0,300.000,300.000,17.890,0.000,4
3755362783.464400,0,1,300.001,0.000,41.693,3.225,0,0,300.000,300.000,17.910,0.000,4
3755363053.464400,0,1,299.998,0.000,41.689,3.226,0,0,300.000,300.000,17.890,0.000,4
3755363323.464400,0,1,300.002,0.000,41.689,3.225,0,0,300.000,300.000,17.950,0.000,4
3755363593.464400,0,1,299.995,0.000,41.688,3.225,0,0,300.000,300.000,17.970,0.000,4
3755363863.464400,0,1,300.001,0.000,41.688,3.226,0,0,300.000,300.000,17.870,0.000,4
3755364133.464400,0,1,300.002,0.000,41.685,3.226,0,0,300.000,300.000,17.950,0.000,4
3755364403.464400,0,1,299.994,0.000,41.681,3.226,0,0,300.000,300.000,17.930,0.000,4
3755364673.464400,0,1,300.000,0.000,41.680,3.226,0,0,300.000,300.000,17.840,0.000,4
3755364943.464400,0,1,300.001,0.000,41.679,3.226,0,0,300.000,300.000,17.930,0.000,4
3755365213.464400,0,1,300.000,0.000,41.681,3.226,0,0,300.000,300.000,17.910,0.000,4
3755365483.464400,0,1,299.995,0.000,41.682,3.226,0,0,300.000,300.000,17.970,0.000,4
3755365753.464400,0,1,300.001,0.000,41.679,3.226,0,0,300.000,300.000,17.840,0.000,4
3755366023.464400,0,1,300.002,0.000,41.676,3.226,0,0,300.000,300.000,17.910,0.000,4
3755366293.464400,0,1,299.997,0.000,41.676,3.225,0,0,300.000,300.000,17.970,0.000,4
3755366563.464400,0,1,299.998,0.000,41.679,3.226,0,0,300.000,300.000,17.870,0.000,4
3755366833.464400,0,1,299.999,0.000,41.678,3.226,0,0,300.000,300.000,17.890,0.000,4
3755367103.464400,0,1,300.002,0.000,41.675,3.225,0,0,300.000,300.000,17.840,0.000,4
3755367373.464400,0,1,300.003,0.000,41.675,3.224,0,0,300.000,300.000,18.010,0.000,4
3755367643.464400,0,1,299.995,0.000,41.674,3.225,0,0,300.000,300.000,17.950,0.000,4
3755367913.464400,0,1,299.999,0.000,41.674,3.225,0,0,300.000,300.000,17.930,0.000,4
3755368183.464400,0,1,300.000,0.000,41.673,3.225,0,0,300.000,300.000,17.910,0.000,4
3755368453.464400,0,1,299.999,0.000,41.672,3.224,0,0,300.000,300.000,17.950,0.000,4
3755368723.464400,0,1,300.001,0.000,41.673,3.224,0,0,300.000,300.000,17.950,0.000,4
3755368993.464400,0,1,300.002,0.000,41.673,3.225,0,0,300.000,300.000,17.870,0.000,4
3755369263.464400,0,1,300.000,0.000,41.672,3.224,0,0,300.000,300.000,17.970,0.000,4
3755369533.464400,0,1,300.000,0.000,41.671,3.224,0,0,300.000,300.000,17.890,0.000,4
3755369803.464400,0,1,300.002,0.000,41.671,3.225,0,0,300.000,300.000,17.890,0.000,4
3755370073.464400,0,1,300.002,0.000,41.669,3.224,0,0,300.000,300.000,17.950,0.000,4
3755370343.464400,0,1,300.002,0.000,41.669,3.224,0,0,300.000,300.000,17.930,0.000,4
3755370613.464400,0,1,300.000,0.000,41.668,3.225,0,0,300.000,300.000,17.890,0.000,4
3755370883.464400,0,1,299.999,0.000,41.668,3.225,0,0,300.000,300.000,17.930,0.000,4
3755371153.464400,0,1,300.002,0.000,41.667,3.225,0,0,300.000,300.000,17.870,0.000,4
3755371423.464400,0,1,299.995,0.000,41.666,3.227,0,0,300.000,300.000,17.950,0.000,4
3755371693.464400,0,1,300.003,0.000,41.665,3.224,0,0,300.000,300.000,17.890,0.000,4
3755371963.464400,0,1,300.003,0.000,41.664,3.226,0,0,300.000,300.000,17.930,0.000,4
3755372233.464400,0,1,299.999,0.000,41.663,3.226,0,0,300.000,300.000,18.010,0.000,4
3755372503.464400,0,1,299.997,0.000,41.665,3.228,0,0,300.000,300.000,17.890,0.000,4
3755372773.464400,0,1,300.005,0.000,41.665,3.226,0,0,300.000,300.000,17.820,0.000,4
3755373043.464400,0,1,300.002,0.000,41.667,3.226,0,0,300.000,300.000,17.990,0.000,4
3755373313.464400,0,1,299.995,0.000,41.665,3.226,0,0,300.000,300.000,17.930,0.000,4
3755373583.464400,0,1,300.002,0.000,41.664,3.227,0,0,300.000,300.000,17.820,0.000,4
3755373853.464400,0,1,300.001,0.000,41.665,3.227,0,0,300.000,300.000,17.950,0.000,4
3755374123.464400,0,1,299.996,0.000,41.667,3.226,0,0,300.000,300.000,17.970,0.000,4
3755374393.464400,0,1,299.999,0.000,41.668,3.226,0,0,300.000,300.000,17.840,0.000,4
3755374663.464400,0,1,300.004,0.000,41.668,3.227,0,0,300.000,300.000,17.910,0.000,4
3755374933.464400,0,1,299.997,0.000,41.668,3.227,0,0,300.000,300.000,17.950,0.000,4
3755375203.464400,0,1,299.999,0.000,41.667,3.226,0,0,300.000,300.000,17.930,0.000,4
3755375473.464400,0,1,300.004,0.000,41.668,3.227,0,0,300.000,300.000,17.840,0.000,4
3755375743.464400,0,1,300.001,0.000,41.663,3.227,0,0,300.000,300.000,17.950,0.000,4
3755376013.464400,0,1,299.996,0.000,41.666,3.225,0,0,300.000,300.000,17.930,0.000,4
3755376283.464400,0,1,300.000,0.000,41.668,3.225,0,0,300.000,300.000,17.870,0.000,4
3755376553.464400,0,1,300.000,0.000,41.670,3.224,0,0,300.000,300.000,17.970,0.000,4
3755376823.464400,0,1,299.996,0.000,41.671,3.226,0,0,300.000,300.000,17.930,0.000,4
3755377093.464400,0,1,299.998,0.000,41.671,3.225,0,0,300.000,300.000,17.870,0.000,4
3755377363.464400,0,1,300.003,0.000,41.668,3.226,0,0,300.000,300.000,17.910,0.000,4
3755377633.464400,0,1,300.001,0.000,41.668,3.226,0,0,300.000,300.000,17.910,0.000,4
3755377903.464400,0,1,299.996,0.000,41.667,3.226,0,0,300.000,300.000,17.840,0.000,4
3755378173.464400,0,1,300.000,0.000,41.667,3.225,0,0,300.000,300.000,17.950,0.000,4
3755378443.464400,0,1,300.001,0.000,41.664,3.227,0,0,300.000,300.000,17.910,0.000,4
3755378713.464400,0,1,300.000,0.000,41.665,3.227,0,0,300.000,300.000,17.950,0.000,4
3755378983.464400,0,1,299.999,0.000,41.667,3.226,0,0,300.000,300.000,17.970,0.000,4
3755379253.464400,0,1,299.998,0.000,41.668,3.226,0,0,300.000,300.000,17.890,0.000,4
3755379523.464400,0,1,300.000,0.000,41.668,3.225,0,0,300.000,300.000,17.840,0.000,4
3755379793.464400,0,1,300.002,0.000,41.666,3.227,0,0,300.000,300.000,17.930,0.000,4
3755380063.464400,0,1,299.995,0.000,41.665,3.228,0,0,300.000,300.000,17.970,0.000,4
3755380333.464400,0,1,299.998,0.000,41.667,3.226,0,0,300.000,300.000,17.840,0.000,4
3755380603.464400,0,1,300.004,0.000,41.666,3.226,0,0,300.000,300.000,17.930,0.000,4
3755380873.464400,0,1,300.000,0.000,41.664,3.226,0,0,300.000,300.000,17.930,0.000,4
3755381143.464400,0,1,299.995,0.000,41.665,3.226,0,0,300.000,300.000,17.890,0.000,4
3755381413.464400,0,1,299.999,0.000,41.667,3.227,0,0,300.000,300.000,17.840,0.000,4
3755381683.464400,0,1,299.999,0.000,41.667,3.227,0,0,300.000,300.000,17.910,0.000,4
3755381953.464400,0,1,299.998,0.000,41.667,3.225,0,0,300.000,300.000,17.930,0.000,4
3755382223.464400,0,1,300.001,0.000,41.668,3.226,0,0,300.000,300.000,17.890,0.000,4
3755382493.464400,0,1,300.001,0.000,41.667,3.226,0,0,300.000,300.000,17.930,0.000,4
3755382763.464400,0,1,299.997,0.000,41.668,3.226,0,0,300.000,300.000,17.950,0.000,4
3755383033.464400,0,1,300.000,0.000,41.667,3.226,0,0,300.000,300.000,17.800,0.000,4
3755383303.464400,0,1,300.007,0.000,41.668,3.225,0,0,300.000,300.000,17.930,0.000,4
3755383573.464400,0,1,299.996,0.000,41.668,3.225,0,0,300.000,300.000,17.970,0.000,4
3755383843.464400,0,1,300.000,0.000,41.669,3.227,0,0,300.000,300.000,17.800,0.000,4
3755384113.464400,0,1,300.005,0.000,41.668,3.227,0,0,300.000,300.000,17.930,0.000,4
3755384383.464400,0,1,299.994,0.000,41.670,3.227,0,0,300.000,300.000,17.990,0.000,4
3755384653.464400,0,1,299.999,0.000,41.669,3.227,0,0,300.000,300.000,17.820,0.000,4
3755384923.464400,0,1,300.005,0.000,41.670,3.227,0,0,300.000,300.000,17.930,0.000,4
3755385193.464400,0,1,299.999,0.000,41.668,3.228,0,0,300.000,300.000,17.950,0.000,4
3755385463.464400,0,1,299.998,0.000,41.668,3.228,0,0,300.000,300.000,17.930,0.000,4
3755385733.464400,0,1,300.002,0.000,41.661,3.230,0,0,300.000,300.000,17.890,0.000,4
3755386003.464400,0,1,299.999,0.000,41.650,3.228,0,0,300.000,300.000,17.990,0.000,4
3755386273.464400,0,1,299.996,0.000,41.651,3.229,0,0,300.000,300.000,17.970,0.000,4
3755386543.464400,0,1,300.003,0.000,41.651,3.228,0,0,300.000,300.000,17.870,0.000,4
3755386813.464400,0,1,299.998,0.000,41.653,3.226,0,0,300.000,300.000,18.030,0.000,4
3755387083.464400,0,1,299.996,0.000,41.654,3.228,0,0,300.000,300.000,17.890,0.000,4
3755387353.464400,0,1,300.004,0.000,41.661,3.225,0,0,300.000,300.000,17.870,0.000,4
3755387623.464400,0,1,300.000,0.000,41.663,3.228,0,0,300.000,300.000,17.930,0.000,4
3755387893.464400,0,1,299.999,0.000,41.666,3.226,0,0,300.000,300.000,17.890,0.000,4
3755388163.464400,0,1,300.001,0.000,41.668,3.227,0,0,300.000,300.000,17.840,0.000,4
3755388433.464400,0,1,300.004,0.000,41.668,3.227,0,0,300.000,300.000,17.950,0.000,4
3755388703.464400,0,1,299.998,0.000,41.662,3.228,0,0,300.000,300.000,17.970,0.000,4
3755388973.464400,0,1,299.998,0.000,41.663,3.226,0,0,300.000,300.000,17.870,0.000,4
3755389243.464400,0,1,300.002,0.000,41.664,3.226,0,0,300.000,300.000,17.950,0.000,4
3755389513.464400,0,1,300.001,0.000,41.659,3.227,0,0,300.000,300.000,17.890,0.000,4
3755389783.464400,0,1,300.000,0.000,41.657,3.228,0,0,300.000,300.000,17.910,0.000,4
3755390053.464400,0,1,299.999,0.000,41.658,3.226,0,0,300.000,300.000,17.890,0.000,4
3755390323.464400,0,1,299.998,0.000,41.655,3.228,0,0,300.000,300.000,17.910,0.000,4
3755390593.464400,0,1,299.999,0.000,41.657,3.229,0,0,300.000,300.000,17.890,0.000,4
3755390863.464400,0,1,300.004,0.000,41.658,3.227,0,0,300.000,300.000,17.950,0.000,4
3755391133.464400,0,1,299.998,0.000,41.663,3.227,0,0,300.000,300.000,17.910,0.000,4
3755391403.464400,0,1,300.002,0.000,41.665,3.225,0,0,300.000,300.000,17.890,0.000,4
3755391673.464400,0,1,300.000,0.000,41.663,3.226,0,0,300.000,300.000,17.930,0.000,4
3755391943.464400,0,1,300.000,0.000,41.668,3.226,0,0,300.000,300.000,17.950,0.000,4
3755392213.464400,0,1,299.998,0.000,41.666,3.227,0,0,300.000,300.000,17.870,0.000,4
3755392483.464400,0,1,299.998,0.000,41.664,3.226,0,0,300.000,300.000,17.930,0.000,4
3755392753.464400,0,1,299.998,0.000,41.662,3.225,0,0,300.000,300.000,17.910,0.000,4
3755393023.464400,0,1,300.000,0.000,41.662,3.226,0,0,300.000,300.000,17.910,0.000,4
3755393293.464400,0,1,299.999,0.000,41.663,3.225,0,0,300.000,300.000,17.950,0.000,4
3755393563.464400,0,1,300.002,0.000,41.663,3.225,0,0,300.000,300.000,17.950,0.000,4
3755393833.464400,0,1,300.002,0.000,41.662,3.225,0,0,300.000,300.000,17.970,0.000,4
3755394103.464400,0,1,300.002,0.000,41.662,3.225,0,0,300.000,300.000,17.890,0.000,4
3755394373.464400,0,1,300.005,0.000,41.665,3.225,0,0,300.000,300.000,17.910,0.000,4
3755394643.464400,0,1,299.996,0.000,41.668,3.226,0,0,300.000,300.000,17.970,0.000,4
3755394913.464400,0,1,299.999,0.000,41.669,3.226,0,0,300.000,300.000,17.910,0.000,4
3755395183.464400,0,1,300.000,0.000,41.669,3.226,0,0,300.000,300.000,17.890,0.000,4
3755395453.464400,0,1,300.000,0.000,41.669,3.226,0,0,300.000,300.000,17.910,0.000,4
3755395723.464400,0,1,299.998,0.000,41.664,3.227,0,0,300.000,300.000,17.930,0.000,4
3755395993.464400,0,1,299.998,0.000,41.666,3.226,0,0,300.000,300.000,17.910,0.000,4
3755396263.464400,0,1,300.001,0.000,41.664,3.226,0,0,300.000,300.000,17.870,0.000,4
3755396533.464400,0,1,300.003,0.000,41.669,3.226,0,0,300.000,300.000,17.950,0.000,4
3755396803.464400,0,1,299.998,0.000,41.674,3.227,0,0,300.000,300.000,17.910,0.000,4
3755397073.464400,0,1,300.002,0.000,41.675,3.228,0,0,300.000,300.000,17.890,0.000,4
3755397343.464400,0,1,299.999,0.000,41.669,3.228,0,0,300.000,300.000,17.970,0.000,4
3755397613.464400,0,1,299.996,0.000,41.669,3.227,0,0,300.000,300.000,17.890,0.000,4
3755397883.464400,0,1,300.001,0.000,41.672,3.226,0,0,300.000,300.000,17.840,0.000,4
3755398153.464400,0,1,300.001,0.000,41.675,3.225,0,0,300.000,300.000,17.970,0.000,4
3755398423.464400,0,1,299.996,0.000,41.675,3.225,0,0,300.000,300.000,17.930,0.000,4
3755398693.464400,0,1,300.001,0.000,41.678,3.226,0,0,300.000,300.000,17.870,0.000,4
3755398963.464400,0,1,300.000,0.000,41.679,3.225,0,0,300.000,300.000,17.950,0.000,4
3755399233.464400,0,1,300.000,0.000,41.679,3.225,0,0,300.000,300.000,17.910,0.000,4
3755399503.464400,0,1,300.002,0.000,41.681,3.227,0,0,300.000,300.000,17.930,0.000,4
3755399773.464400,0,1,299.999,0.000,41.680,3.224,0,0,300.000,300.000,17.970,0.000,4
3755400043.464400,0,1,300.001,0.000,41.678,3.227,0,0,300.000,300.000,17.930,0.000,4
3755400313.464400,0,1,300.001,0.000,41.676,3.226,0,0,300.000,300.000,17.820,0.000,4
3755400583.464400,0,1,300.002,0.000,41.675,3.225,0,0,300.000,300.000,17.910,0.000,4
3755400853.464400,0,1,299.994,0.000,41.677,3.226,0,0,300.000,300.000,17.870,0.000,4
3755401123.464400,0,1,300.001,0.000,41.679,3.227,0,0,300.000,300.000,17.870,0.000,4
3755401393.464400,0,1,300.001,0.000,41.679,3.227,0,0,300.000,300.000,17.990,0.000,4
3755401663.464400,0,1,300.001,0.000,41.678,3.228,0,0,300.000,300.000,17.910,0.000,4
3755401933.464400,0,1,300.000,0.000,41.678,3.226,0,0,300.000,300.000,17.890,0.000,4
3755402203.464400,0,1,299.999,0.000,41.683,3.227,0,0,300.000,300.000,17.890,0.000,4
3755402473.464400,0,1,299.998,0.000,41.679,3.227,0,0,300.000,300.000,17.870,0.000,4
3755402743.464400,0,1,300.002,0.000,41.682,3.226,0,0,300.000,300.000,17.890,0.000,4
3755403013.464400,0,1,299.996,0.000,41.682,3.226,0,0,300.000,300.000,17.990,0.000,4
3755403283.464400,0,1,300.001,0.000,41.685,3.225,0,0,300.000,300.000,17.840,0.000,4
3755403553.464400,0,1,300.002,0.000,41.684,3.227,0,0,300.000,300.000,17.930,0.000,4
3755403823.464400,0,1,299.996,0.000,41.685,3.228,0,0,300.000,300.000,17.930,0.000,4
3755404093.464400,0,1,300.003,0.000,41.683,3.227,0,0,300.000,300.000,17.840,0.000,4
3755404363.464400,0,1,299.998,0.000,41.680,3.228,0,0,300.000,300.000,17.970,0.000,4
3755404633.464400,0,1,299.999,0.000,41.682,3.227,0,0,300.000,300.000,17.910,0.000,4
3755404903.464400,0,1,299.998,0.000,41.683,3.227,0,0,300.000,300.000,17.890,0.000,4
3755405173.464400,0,1,300.003,0.000,41.684,3.226,0,0,300.000,300.000,17.870,0.000,4
3755405443.464400,0,1,300.000,0.000,41.683,3.227,0,0,300.000,300.000,17.990,0.000,4
3755405713.464400,0,1,299.995,0.000,41.683,3.226,0,0,300.000,300.000,17.910,0.000,4
3755405983.464400,0,1,300.002,0.000,41.682,3.225,0,0,300.000,300.000,17.840,0.000,4
3755406253.464400,0,1,300.003,0.000,41.678,3.227,0,0,300.000,300.000,17.910,0.000,4
3755406523.464400,0,1,300.000,0.000,41.678,3.226,0,0,300.000,300.000,17.950,0.000,4
3755406793.464400,0,1,300.000,0.000,41.676,3.226,0,0,300.000,300.000,17.910,0.000,4
3755407063.464400,0,1,300.001,0.000,41.677,3.226,0,0,300.000,300.000,17.950,0.000,4
3755407333.464400,0,1,299.999,0.000,41.676,3.228,0,0,300.000,300.000,17.820,0.000,4
3755407603.464400,0,1,299.999,0.000,41.678,3.226,0,0,300.000,300.000,17.890,0.000,4
3755407873.464400,0,1,300.002,0.000,41.678,3.226,0,0,300.000,300.000,17.910,0.000,4
3755408143.464400,0,1,299.997,0.000,41.678,3.226,0,0,300.000,300.000,17.890,0.000,4
3755408413.464400,0,1,300.002,0.000,41.678,3.227,0,0,300.000,300.000,17.870,0.000,4
3755408683.464400,0,1,299.997,0.000,41.678,3.226,0,0,300.000,300.000,17.990,0.000,4
3755408953.464400,0,1,299.999,0.000,41.679,3.227,0,0,300.000,300.000,17.890,0.000,4
3755409223.464400,0,1,300.002,0.000,41.679,3.228,0,0,300.000,300.000,17.910,0.000,4
3755409493.464400,0,1,300.000,0.000,41.680,3.226,0,0,300.000,300.000,17.950,0.000,4
3755409763.464400,0,1,299.998,0.000,41.682,3.225,0,0,300.000,300.000,17.970,0.000,4
3755410033.464400,0,1,299.998,0.000,41.684,3.226,0,0,300.000,300.000,17.930,0.000,4
3755410303.464400,0,1,300.003,0.000,41.683,3.226,0,0,300.000,300.000,17.890,0.000,4
3755410573.464400,0,1,299.998,0.000,41.684,3.226,0,0,300.000,300.000,17.950,0.000,4
3755410843.464400,0,1,299.998,0.000,41.685,3.226,0,0,300.000,300.000,17.930,0.000,4
3755411113.464400,0,1,300.001,0.000,41.683,3.226,0,0,300.000,300.000,17.910,0.000,4
3755411383.464400,0,1,300.000,0.000,41.683,3.227,0,0,300.000,300.000,17.990,0.000,4
3755411653.464400,0,1,299.999,0.000,41.685,3.227,0,0,300.000,300.000,17.930,0.000,4
3755411923.464400,0,1,300.002,0.000,41.689,3.227,0,0,300.000,300.000,17.870,0.000,4
3755412193.464400,0,1,300.005,0.000,41.691,3.226,0,0,300.000,300.000,17.930,0.000,4
3755412463.464400,0,1,299.997,0.000,41.693,3.227,0,0,300.000,300.000,17.970,0.000,4
3755412733.464400,0,1,300.000,0.000,41.691,3.227,0,0,300.000,300.000,17.950,0.000,4
3755413003.464400,0,1,300.001,0.000,41.691,3.228,0,0,300.000,300.000,17.870,0.000,4
3755413273.464400,0,1,300.000,0.000,41.691,3.227,0,0,300.000,300.000,17.930,0.000,4
3755413543.464400,0,1,300.000,0.000,41.693,3.225,0,0,300.000,300.000,17.910,0.000,4
3755413813.464400,0,1,300.000,0.000,41.694,3.226,0,0,300.000,300.000,17.870,0.000,4
3755414083.464400,0,1,299.999,0.000,41.694,3.226,0,0,300.000,300.000,17.910,0.000,4
3755414353.464400,0,1,299.997,0.000,41.695,3.227,0,0,300.000,300.000,17.930,0.000,4
3755414623.464400,0,1,299.999,0.000,41.696,3.227,0,0,300.000,300.000,17.990,0.000,4
3755414893.464400,0,1,300.002,0.000,41.696,3.226,0,0,300.000,300.000,17.840,0.000,4
3755415163.464400,0,1,300.002,0.000,41.696,3.226,0,0,300.000,300.000,17.910,0.000,4
3755415433.464400,0,1,299.997,0.000,41.694,3.227,0,0,300.000,300.000,18.010,0.000,4
3755415703.464400,0,1,299.998,0.000,41.692,3.227,0,0,300.000,300.000,17.890,0.000,4
3755415973.464400,0,1,300.003,0.000,41.694,3.226,0,0,300.000,300.000,17.930,0.000,4
3755416243.464400,0,1,299.998,0.000,41.696,3.226,0,0,300.000,300.000,17.950,0.000,4
3755416513.464400,0,1,299.997,0.000,41.697,3.224,0,0,300.000,300.000,17.910,0.000,4
3755416783.464400,0,1,300.004,0.000,41.696,3.225,0,0,300.000,300.000,17.910,0.000,4
3755417053.464400,0,1,300.000,0.000,41.695,3.227,0,0,300.000,300.000,17.950,0.000,4
3755417323.464400,0,1,300.001,0.000,41.692,3.227,0,0,300.000,300.000,17.870,0.000,4
3755417593.464400,0,1,299.998,0.000,41.694,3.226,0,0,300.000,300.000,17.950,0.000,4
3755417863.464400,0,1,299.999,0.000,41.694,3.227,0,0,300.000,300.000,17.910,0.000,4
3755418133.464400,0,1,300.000,0.000,41.691,3.228,0,0,300.000,300.000,17.870,0.000,4
3755418403.464400,0,1,300.002,0.000,41.684,3.226,0,0,300.000,300.000,17.890,0.000,4
3755418673.464400,0,1,299.998,0.000,41.680,3.228,0,0,300.000,300.000,17.930,0.000,4
3755418943.464400,0,1,300.001,0.000,41.680,3.225,0,0,300.000,300.000,17.970,0.000,4
3755419213.464400,0,1,300.001,0.000,41.678,3.226,0,0,300.000,300.000,17.890,0.000,4
3755419483.464400,0,1,300.002,0.000,41.677,3.228,0,0,300.000,300.000,17.870,0.000,4
3755419753.464400,0,1,300.002,0.000,41.680,3.226,0,0,300.000,300.000,17.950,0.000,4
3755420023.464400,0,1,299.996,0.000,41.678,3.227,0,0,300.000,300.000,17.910,0.000,4
3755420293.464400,0,1,300.000,0.000,41.678,3.227,0,0,300.000,300.000,17.840,0.000,4
3755420563.464400,0,1,300.001,0.000,41.678,3.226,0,0,300.000,300.000,17.890,0.000,4
3755420833.464400,0,1,299.999,0.000,41.680,3.225,0,0,300.000,300.000,17.910,0.000,4
3755421103.464400,0,1,299.999,0.000,41.682,3.227,0,0,300.000,300.000,17.990,0.000,4
3755421373.464400,0,1,300.001,0.000,41.682,3.226,0,0,300.000,300.000,17.890,0.000,4
3755421643.464400,0,1,300.001,0.000,41.681,3.225,0,0,300.000,300.000,17.930,0.000,4
3755421913.464400,0,1,299.998,0.000,41.680,3.227,0,0,300.000,300.000,17.930,0.000,4
3755422183.464400,0,1,299.997,0.000,41.683,3.225,0,0,300.000,300.000,17.950,0.000,4
3755422453.464400,0,1,300.000,0.000,41.685,3.225,0,0,300.000,300.000,17.890,0.000,4
3755422723.464400,0,1,300.003,0.000,41.685,3.225,0,0,300.000,300.000,17.910,0.000,4
3755422993.464400,0,1,300.002,0.000,41.685,3.225,0,0,300.000,300.000,17.950,0.000,4
3755423263.464400,0,1,299.997,0.000,41.685,3.224,0,0,300.000,300.000,17.840,0.000,4
3755423533.464400,0,1,300.002,0.000,41.687,3.225,0,0,300.000,300.000,17.910,0.000,4
3755423803.464400,0,1,300.000,0.000,41.685,3.225,0,0,300.000,300.000,17.950,0.000,4
3755424073.464400,0,1,299.999,0.000,41.685,3.227,0,0,300.000,300.000,17.930,0.000,4
3755424343.464400,0,1,300.001,0.000,41.684,3.225,0,0,300.000,300.000,17.930,0.000,4
3755424613.464400,0,1,300.000,0.000,41.684,3.226,0,0,300.000,300.000,17.910,0.000,4
3755424883.464400,0,1,300.000,0.000,41.687,3.225,0,0,300.000,300.000,17.910,0.000,4
3755425153.464400,0,1,299.996,0.000,41.686,3.227,0,0,300.000,300.000,17.910,0.000,4
3755425423.464400,0,1,299.999,0.000,41.683,3.226,0,0,300.000,300.000,17.870,0.000,4
3755425693.464400,0,1,300.004,0.000,41.686,3.225,0,0,300.000,300.000,17.870,0.000,4
3755425963.464400,0,1,300.002,0.000,41.686,3.226,0,0,300.000,300.000,17.890,0.000,4
3755426233.464400,0,1,299.996,0.000,41.686,3.226,0,0,300.000,300.000,17.950,0.000,4
3755426503.464400,0,1,299.997,0.000,41.683,3.226,0,0,300.000,300.000,17.910,0.000,4
3755426773.464400,0,1,300.000,0.000,41.682,3.226,0,0,300.000,300.000,17.870,0.000,4
3755427043.464400,0,1,299.996,0.000,41.687,3.224,0,0,300.000,300.000,17.990,0.000,4
3755427313.464400,0,1,299.995,0.000,41.687,3.226,0,0,300.000,300.000,17.890,0.000,4
3755427583.464400,0,1,300.001,0.000,41.688,3.225,0,0,300.000,300.000,17.870,0.000,4
3755427853.464400,0,1,300.000,0.000,41.685,3.225,0,0,300.000,300.000,17.910,0.000,4
3755428123.464400,0,1,299.999,0.000,41.684,3.226,0,0,300.000,300.000,17.910,0.000,4
3755428393.464400,0,1,300.000,0.000,41.684,3.225,0,0,300.000,300.000,17.970,0.000,4
3755428663.464400,0,1,299.998,0.000,41.683,3.226,0,0,300.000,300.000,17.870,0.000,4
3755428933.464400,0,1,300.002,0.000,41.686,3.224,0,0,300.000,300.000,17.910,0.000,4
3755429203.464400,0,1,299.998,0.000,41.684,3.225,0,0,300.000,300.000,17.840,0.000,4
3755429473.464400,0,1,299.997,0.000,41.686,3.227,0,0,300.000,300.000,17.890,0.000,4
3755429743.464400,0,1,300.000,0.000,41.687,3.226,0,0,300.000,300.000,17.950,0.000,4
3755430013.464400,0,1,300.001,0.000,41.689,3.227,0,0,300.000,300.000,17.930,0.000,4
3755430283.464400,0,1,299.999,0.000,41.691,3.226,0,0,300.000,300.000,17.910,0.000,4
3755430553.464400,0,1,300.002,0.000,41.691,3.226,0,0,300.000,300.000,17.950,0.000,4
3755430823.464400,0,1,299.999,0.000,41.692,3.226,0,0,300.000,300.000,17.930,0.000,4
3755431093.464400,0,1,300.003,0.000,41.696,3.227,0,0,300.000,300.000,17.870,0.000,4
3755431363.464400,0,1,300.002,0.000,41.700,3.225,0,0,300.000,300.000,17.930,0.000,4
3755431633.464400,0,1,300.000,0.000,41.701,3.226,0,0,300.000,300.000,17.930,0.000,4
3755431903.464400,0,1,300.001,0.000,41.702,3.226,0,0,300.000,300.000,17.930,0.000,4
3755432173.464400,0,1,300.001,0.000,41.702,3.224,0,0,300.000,300.000,17.930,0.000,4
3755432443.464400,0,1,300.002,0.000,41.701,3.225,0,0,300.000,300.000,17.890,0.000,4
3755432713.464400,0,1,299.999,0.000,41.702,3.227,0,0,300.000,300.000,17.950,0.000,4
3755432983.464400,0,1,299.999,0.000,41.702,3.227,0,0,300.000,300.000,17.930,0.000,4
3755433253.464400,0,1,299.996,0.000,41.701,3.227,0,0,300.000,300.000,17.990,0.000,4
3755433523.464400,0,1,299.999,0.000,41.698,3.227,0,0,300.000,300.000,17.930,0.000,4
3755433793.464400,0,1,299.999,0.000,41.695,3.228,0,0,300.000,300.000,17.950,0.000,4
3755434063.464400,0,1,299.998,0.000,41.697,3.227,0,0,300.000,300.000,17.890,0.000,4
3755434333.464400,0,1,300.001,0.000,41.698,3.226,0,0,300.000,300.000,17.890,0.000,4
3755434603.464400,0,1,300.000,0.000,41.695,3.228,0,0,300.000,300.000,17.930,0.000,4
3755434873.464400,0,1,299.998,0.000,41.699,3.227,0,0,300.000,300.000,17.990,0.000,4
3755435143.464400,0,1,300.001,0.000,41.700,3.226,0,0,300.000,300.000,17.910,0.000,4
3755435413.464400,0,1,299.996,0.000,41.698,3.228,0,0,300.000,300.000,17.930,0.000,4
3755435683.464400,0,1,300.002,0.000,41.701,3.227,0,0,300.000,300.000,17.840,0.000,4
3755435953.464400,0,1,300.001,0.000,41.700,3.227,0,0,300.000,300.000,17.910,0.000,4
3755436223.464400,0,1,299.999,0.000,41.699,3.228,0,0,300.000,300.000,17.890,0.000,4
3755436493.464400,0,1,300.000,0.000,41.698,3.228,0,0,300.000,300.000,17.870,0.000,4
3755436763.464400,0,1,300.001,0.000,41.697,3.226,0,0,300.000,300.000,17.930,0.000,4
3755437033.464400,0,1,300.000,0.000,41.699,3.226,0,0,300.000,300.000,17.910,0.000,4
3755437303.464400,0,1,300.001,0.000,41.694,3.228,0,0,300.000,300.000,17.910,0.000,4
3755437573.464400,0,1,299.998,0.000,41.693,3.227,0,0,300.000,300.000,18.010,0.000,4
3755437843.464400,0,1,299.995,0.000,41.693,3.228,0,0,300.000,300.000,17.930,0.000,4
3755438113.464400,0,1,300.002,0.000,41.693,3.226,0,0,300.000,300.000,17.800,0.000,4
3755438383.464400,0,1,300.000,0.000,41.692,3.228,0,0,300.000,300.000,17.970,0.000,4
3755438653.464400,0,1,299.995,0.000,41.692,3.228,0,0,300.000,300.000,17.910,0.000,4
3755438923.464400,0,1,300.002,0.000,41.691,3.227,0,0,300.000,300.000,17.820,0.000,4
3755439193.464400,0,1,300.003,0.000,41.688,3.227,0,0,300.000,300.000,17.890,0.000,4
3755439463.464400,0,1,300.000,0.000,41.691,3.227,0,0,300.000,300.000,18.010,0.000,4
3755439733.464400,0,1,299.997,0.000,41.689,3.227,0,0,300.000,300.000,17.930,0.000,4
3755440003.464400,0,1,300.000,0.000,41.690,3.227,0,0,300.000,300.000,17.870,0.000,4
3755440273.464400,0,1,300.003,0.000,41.691,3.227,0,0,300.000,300.000,17.840,0.000,4
3755440543.464400,0,1,299.999,0.000,41.690,3.227,0,0,300.000,300.000,17.970,0.000,4
3755440813.464400,0,1,299.999,0.000,41.690,3.227,0,0,300.000,300.000,17.910,0.000,4
3755441083.464400,0,1,299.998,0.000,41.691,3.227,0,0,300.000,300.000,17.930,0.000,4
3755441353.464400,0,1,299.999,0.000,41.688,3.226,0,0,300.000,300.000,17.910,0.000,4
3755441623.464400,0,1,299.999,0.000,41.685,3.228,0,0,300.000,300.000,17.930,0.000,4
3755441893.464400,0,1,299.998,0.000,41.683,3.228,0,0,300.000,300.000,17.910,0.000,4
3755442163.464400,0,1,300.002,0.000,41.677,3.227,0,0,300.000,300.000,17.910,0.000,4
3755442433.464400,0,1,300.001,0.000,41.676,3.228,0,0,300.000,300.000,17.950,0.000,4
3755442703.464400,0,1,299.998,0.000,41.677,3.228,0,0,300.000,300.000,17.890,0.000,4
3755442973.464400,0,1,299.999,0.000,41.673,3.227,0,0,300.000,300.000,17.870,0.000,4
3755443243.464400,0,1,299.999,0.000,41.673,3.227,0,0,300.000,300.000,17.930,0.000,4
3755443513.464400,0,1,299.998,0.000,41.669,3.228,0,0,300.000,300.000,17.870,0.000,4
3755443783.464400,0,1,300.000,0.000,41.668,3.227,0,0,300.000,300.000,17.970,0.000,4
3755444053.464400,0,1,299.995,0.000,41.664,3.228,0,0,300.000,300.000,17.950,0.000,4
3755444323.464400,0,1,300.003,0.000,41.668,3.226,0,0,300.000,300.000,17.930,0.000,4
3755444593.464400,0,1,300.000,0.000,41.671,3.228,0,0,300.000,300.000,17.930,0.000,4
3755444863.464400,0,1,299.997,0.000,41.672,3.226,0,0,300.000,300.000,17.950,0.000,4
3755445133.464400,0,1,300.002,0.000,41.672,3.227,0,0,300.000,300.000,17.840,0.000,4
3755445403.464400,0,1,300.001,0.000,41.671,3.228,0,0,300.000,300.000,17.970,0.000,4
3755445673.464400,0,1,299.996,0.000,41.671,3.227,0,0,300.000,300.000,17.890,0.000,4
3755445943.464400,0,1,299.995,0.000,41.667,3.226,0,0,300.000,300.000,17.910,0.000,4
3755446213.464400,0,1,300.003,0.000,41.668,3.226,0,0,300.000,300.000,17.870,0.000,4
3755446483.464400,0,1,299.997,0.000,41.668,3.227,0,0,300.000,300.000,17.970,0.000,4
3755446753.464400,0,1,299.998,0.000,41.667,3.226,0,0,300.000,300.000,17.910,0.000,4
3755447023.464400,0,1,300.000,0.000,41.668,3.226,0,0,300.000,300.000,17.890,0.000,4
3755447293.464400,0,1,300.000,0.000,41.669,3.226,0,0,300.000,300.000,17.890,0.000,4
3755447563.464400,0,1,299.997,0.000,41.666,3.226,0,0,300.000,300.000,17.870,0.000,4
3755447833.464400,0,1,300.002,0.000,41.664,3.225,0,0,300.000,300.000,17.840,0.000,4
3755448103.464400,0,1,300.000,0.000,41.662,3.227,0,0,300.000,300.000,17.950,0.000,4
3755448373.464400,0,1,299.997,0.000,41.664,3.226,0,0,300.000,300.000,17.930,0.000,4
3755448643.464400,0,1,300.001,0.000,41.663,3.225,0,0,300.000,300.000,17.800,0.000,4
3755448913.464400,0,1,300.006,0.000,41.661,3.226,0,0,300.000,300.000,17.910,0.000,4
3755449183.464400,0,1,299.995,0.000,41.660,3.226,0,0,300.000,300.000,18.080,0.000,4
3755449453.464400,0,1,299.995,0.000,41.659,3.227,0,0,300.000,300.000,17.870,0.000,4
3755449723.464400,0,1,300.002,0.000,41.656,3.225,0,0,300.000,300.000,17.890,0.000,4
3755449993.464400,0,1,300.000,0.000,41.655,3.224,0,0,300.000,300.000,17.970,0.000,4
3755450263.464400,0,1,299.998,0.000,41.656,3.224,0,0,300.000,300.000,17.930,0.000,4
3755450533.464400,0,1,300.001,0.000,41.658,3.224,0,0,300.000,300.000,17.930,0.000,4
3755450803.464400,0,1,300.001,0.000,41.658,3.224,0,0,300.000,300.000,17.950,0.000,4
3755451073.464400,0,1,299.998,0.000,41.661,3.225,0,0,300.000,300.000,17.930,0.000,4
3755451343.464400,0,1,299.999,0.000,41.659,3.225,0,0,300.000,300.000,17.840,0.000,4
3755451613.464400,0,1,300.004,0.000,41.655,3.225,0,0,300.000,300.000,17.890,0.000,4
3755451883.464400,0,1,300.000,0.000,41.657,3.226,0,0,300.000,300.000,17.930,0.000,4
3755452153.464400,0,1,299.996,0.000,41.656,3.225,0,0,300.000,300.000,17.890,0.000,4
3755452423.464400,0,1,300.001,0.000,41.654,3.226,0,0,300.000,300.000,17.890,0.000,4
3755452693.464400,0,1,300.001,0.000,41.656,3.227,0,0,300.000,300.000,17.890,0.000,4
3755452963.464400,0,1,299.998,0.000,41.654,3.227,0,0,300.000,300.000,17.970,0.000,4
3755453233.464400,0,1,299.996,0.000,41.653,3.227,0,0,300.000,300.000,17.840,0.000,4
3755453503.464400,0,1,300.006,0.000,41.654,3.226,0,0,300.000,300.000,17.870,0.000,4
3755453773.464400,0,1,299.996,0.000,41.651,3.226,0,0,300.000,300.000,17.990,0.000,4
3755454043.464400,0,1,299.995,0.000,41.653,3.226,0,0,300.000,300.000,17.910,0.000,4
3755454313.464400,0,1,300.001,0.000,41.652,3.226,0,0,300.000,300.000,17.870,0.000,4
3755454583.464400,0,1,299.998,0.000,41.653,3.226,0,0,300.000,300.000,18.010,0.000,4
3755454853.464400,0,1,299.996,0.000,41.650,3.227,0,0,300.000,300.000,17.890,0.000,4
3755455123.464400,0,1,300.003,0.000,41.647,3.225,0,0,300.000,300.000,17.910,0.000,4
3755455393.464400,0,1,300.000,0.000,41.647,3.227,0,0,300.000,300.000,17.970,0.000,4
3755455663.464400,0,1,299.995,0.000,41.646,3.226,0,0,300.000,300.000,17.930,0.000,4
3755455933.464400,0,1,300.001,0.000,41.646,3.225,0,0,300.000,300.000,17.840,0.000,4
3755456203.464400,0,1,300.002,0.000,41.646,3.225,0,0,300.000,300.000,17.930,0.000,4
3755456473.464400,0,1,299.997,0.000,41.642,3.226,0,0,300.000,300.000,17.930,0.000,4
3755456743.464400,0,1,300.001,0.000,41.640,3.225,0,0,300.000,300.000,17.840,0.000,4
3755457013.464400,0,1,300.001,0.000,41.637,3.226,0,0,300.000,300.000,17.890,0.000,4
3755457283.464400,0,1,299.995,0.000,41.637,3.225,0,0,300.000,300.000,17.910,0.000,4
3755457553.464400,0,1,300.001,0.000,41.639,3.225,0,0,300.000,300.000,17.870,0.000,4
3755457823.464400,0,1,300.003,0.000,41.635,3.225,0,0,300.000,300.000,17.930,0.000,4
3755458093.464400,0,1,299.996,0.000,41.632,3.225,0,0,300.000,300.000,17.910,0.000,4
3755458363.464400,0,1,300.002,0.000,41.630,3.226,0,0,300.000,300.000,17.890,0.000,4
3755458633.464400,0,1,300.002,0.000,41.629,3.224,0,0,300.000,300.000,17.950,0.000,4
3755458903.464400,0,1,299.997,0.000,41.626,3.225,0,0,300.000,300.000,17.950,0.000,4
3755459173.464400,0,1,300.000,0.000,41.625,3.226,0,0,300.000,300.000,17.930,0.000,4
3755459443.464400,0,1,299.998,0.000,41.625,3.225,0,0,300.000,300.000,17.910,0.000,4
3755459713.464400,0,1,300.002,0.000,41.626,3.224,0,0,300.000,300.000,17.910,0.000,4
3755459983.464400,0,1,300.000,0.000,41.624,3.225,0,0,300.000,300.000,17.910,0.000,4
3755460253.464400,0,1,299.999,0.000,41.622,3.226,0,0,300.000,300.000,17.950,0.000,4
3755460523.464400,0,1,299.999,0.000,41.622,3.224,0,0,300.000,300.000,17.840,0.000,4
3755460793.464400,0,1,300.004,0.000,41.623,3.225,0,0,300.000,300.000,17.890,0.000,4
3755461063.464400,0,1,299.999,0.000,41.624,3.225,0,0,300.000,300.000,17.930,0.000,4
3755461333.464400,0,1,299.995,0.000,41.622,3.226,0,0,300.000,300.000,17.950,0.000,4
3755461603.464400,0,1,300.000,0.000,41.620,3.226,0,0,300.000,300.000,17.800,0.000,4
3755461873.464400,0,1,300.004,0.000,41.623,3.226,0,0,300.000,300.000,17.870,0.000,4
3755462143.464400,0,1,299.996,0.000,41.623,3.225,0,0,300.000,300.000,17.990,0.000,4
3755462413.464400,0,1,299.995,0.000,41.623,3.226,0,0,300.000,300.000,17.870,0.000,4
3755462683.464400,0,1,300.003,0.000,41.621,3.225,0,0,300.000,300.000,17.820,0.000,4
3755462953.464400,0,1,299.998,0.000,41.622,3.226,0,0,300.000,300.000,17.970,0.000,4
3755463223.464400,0,1,300.000,0.000,41.623,3.225,0,0,300.000,300.000,17.910,0.000,4
3755463493.464400,0,1,299.997,0.000,41.620,3.225,0,0,300.000,300.000,17.990,0.000,4
3755463763.464400,0,1,300.001,0.000,41.618,3.224,0,0,300.000,300.000,17.840,0.000,4
3755464033.464400,0,1,300.003,0.000,41.614,3.225,0,0,300.000,300.000,17.870,0.000,4
3755464303.464400,0,1,300.000,0.000,41.614,3.225,0,0,300.000,300.000,17.970,0.000,4
3755464573.464400,0,1,299.996,0.000,41.612,3.225,0,0,300.000,300.000,17.800,0.000,4
3755464843.464400,0,1,300.002,0.000,41.612,3.224,0,0,300.000,300.000,17.910,0.000,4
3755465113.464400,0,1,300.000,0.000,41.609,3.226,0,0,300.000,300.000,17.930,0.000,4
3755465383.464400,0,1,299.999,0.000,41.610,3.224,0,0,300.000,300.000,17.910,0.000,4
3755465653.464400,0,1,299.998,0.000,41.612,3.224,0,0,300.000,300.000,17.870,0.000,4
3755465923.464400,0,1,299.998,0.000,41.612,3.225,0,0,300.000,300.000,17.890,0.000,4
3755466193.464400,0,1,299.999,0.000,41.611,3.225,0,0,300.000,300.000,17.950,0.000,4
3755466463.464400,0,1,300.002,0.000,41.611,3.224,0,0,300.000,300.000,17.870,0.000,4
3755466733.464400,0,1,300.003,0.000,41.608,3.225,0,0,300.000,300.000,17.950,0.000,4
3755467003.464400,0,1,299.999,0.000,41.609,3.224,0,0,300.000,300.000,17.910,0.000,4
3755467273.464400,0,1,300.001,0.000,41.608,3.225,0,0,300.000,300.000,17.910,0.000,4
3755467543.464400,0,1,300.004,0.000,41.607,3.226,0,0,300.000,300.000,17.930,0.000,4
3755467813.464400,0,1,300.000,0.000,41.609,3.224,0,0,300.000,300.000,17.910,0.000,4
3755468083.464400,0,1,300.001,0.000,41.607,3.225,0,0,300.000,300.000,17.840,0.000,4
3755468353.464400,0,1,300.002,0.000,41.603,3.225,0,0,300.000,300.000,17.890,0.000,4
3755468623.464400,0,1,299.998,0.000,41.602,3.225,0,0,300.000,300.000,17.950,0.000,4
3755468893.464400,0,1,300.001,0.000,41.602,3.226,0,0,300.000,300.000,17.820,0.000,4
3755469163.464400,0,1,300.003,0.000,41.599,3.225,0,0,300.000,300.000,17.840,0.000,4
3755469433.464400,0,1,300.000,0.000,41.600,3.226,0,0,300.000,300.000,17.950,0.000,4
3755469703.464400,0,1,299.997,0.000,41.597,3.225,0,0,300.000,300.000,17.910,0.000,4
3755469973.464400,0,1,299.999,0.000,41.598,3.225,0,0,300.000,300.000,17.820,0.000,4
3755470243.464400,0,1,300.005,0.000,41.595,3.225,0,0,300.000,300.000,17.930,0.000,4
3755470513.464400,0,1,299.995,0.000,41.599,3.225,0,0,300.000,300.000,18.010,0.000,4
3755470783.464400,0,1,299.997,0.000,41.600,3.227,0,0,300.000,300.000,17.820,0.000,4
3755471053.464400,0,1,300.002,0.000,41.598,3.226,0,0,300.000,300.000,17.890,0.000,4
3755471323.464400,0,1,299.998,0.000,41.597,3.226,0,0,300.000,300.000,17.930,0.000,4
3755471593.464400,0,1,299.999,0.000,41.599,3.226,0,0,300.000,300.000,17.890,0.000,4
3755471863.464400,0,1,300.004,0.000,41.602,3.225,0,0,300.000,300.000,17.890,0.000,4
3755472133.464400,0,1,299.999,0.000,41.599,3.225,0,0,300.000,300.000,17.990,0.000,4
3755472403.464400,0,1,299.996,0.000,41.600,3.226,0,0,300.000,300.000,17.820,0.000,4
3755472673.464400,0,1,300.005,0.000,41.599,3.225,0,0,300.000,300.000,17.820,0.000,4
3755472943.464400,0,1,299.996,0.000,41.596,3.225,0,0,300.000,300.000,18.010,0.000,4
3755473213.464400,0,1,299.997,0.000,41.589,3.225,0,0,300.000,300.000,17.890,0.000,4
3755473483.464400,0,1,300.001,0.000,41.583,3.224,0,0,300.000,300.000,17.910,0.000,4
3755473753.464400,0,1,299.997,0.000,41.573,3.224,0,0,300.000,300.000,17.910,0.000,4
3755474023.464400,0,1,300.000,0.000,41.568,3.223,0,0,300.000,300.000,17.820,0.000,4
3755474293.464400,0,1,300.005,0.000,41.560,3.223,0,0,300.000,300.000,17.870,0.000,4
3755474563.464400,0,1,299.997,0.000,41.560,3.224,0,0,300.000,300.000,17.950,0.000,4
3755474833.464400,0,1,299.999,0.000,41.559,3.224,0,0,300.000,300.000,17.840,0.000,4
3755475103.464400,0,1,300.001,0.000,41.557,3.224,0,0,300.000,300.000,17.910,0.000,4
3755475373.464400,0,1,299.995,0.000,41.559,3.224,0,0,300.000,300.000,17.870,0.000,4
3755475643.464400,0,1,300.002,0.000,41.564,3.223,0,0,300.000,300.000,17.890,0.000,4
3755475913.464400,0,1,300.001,0.000,41.568,3.223,0,0,300.000,300.000,17.950,0.000,4
3755476183.464400,0,1,299.994,0.000,41.573,3.224,0,0,300.000,300.000,17.870,0.000,4
3755476453.464400,0,1,300.002,0.000,41.572,3.222,0,0,300.000,300.000,17.840,0.000,4
3755476723.464400,0,1,300.003,0.000,41.570,3.225,0,0,300.000,300.000,17.910,0.000,4
3755476993.464400,0,1,299.996,0.000,41.569,3.223,0,0,300.000,300.000,17.990,0.000,4
3755477263.464400,0,1,299.997,0.000,41.573,3.223,0,0,300.000,300.000,17.840,0.000,4
3755477533.464400,0,1,300.002,0.000,41.575,3.224,0,0,300.000,300.000,17.840,0.000,4
3755477803.464400,0,1,300.000,0.000,41.576,3.223,0,0,300.000,300.000,17.930,0.000,4
3755478073.464400,0,1,299.998,0.000,41.580,3.224,0,0,300.000,300.000,17.840,0.000,4
3755478343.464400,0,1,300.007,0.000,41.583,3.223,0,0,300.000,300.000,17.840,0.000,4
3755478613.464400,0,1,300.000,0.000,41.583,3.223,0,0,300.000,300.000,17.990,0.000,4
3755478883.464400,0,1,299.996,0.000,41.584,3.223,0,0,300.000,300.000,17.890,0.000,4
3755479153.464400,0,1,300.001,0.000,41.585,3.224,0,0,300.000,300.000,17.870,0.000,4
3755479423.464400,0,1,300.004,0.000,41.589,3.224,0,0,300.000,300.000,17.970,0.000,4
3755479693.464400,0,1,299.995,0.000,41.589,3.224,0,0,300.000,300.000,17.990,0.000,4
3755479963.464400,0,1,300.001,0.000,41.589,3.225,0,0,300.000,300.000,17.780,0.000,4
3755480233.464400,0,1,300.003,0.000,41.594,3.225,0,0,300.000,300.000,17.890,0.000,4
3755480503.464400,0,1,300.001,0.000,41.596,3.224,0,0,300.000,300.000,17.930,0.000,4
3755480773.464400,0,1,299.999,0.000,41.601,3.225,0,0,300.000,300.000,17.870,0.000,4
3755481043.464400,0,1,299.928,306.298,41.729,3.225,0,0,300.000,300.000,18.290,16.460,4
3755481253.464400,0,1,299.980,300.003,42.258,3.225,0,0,300.000,300.000,16.670,10.590,1