File: log/20221202.dat
[Header]
; Displex Transport Data File (default extension .dat)
; Copyright 2016, Hechang LEI, hlei@ruc.edu.cn. All rights reserved.
BYAPP, Displex, 2.0
INFO, 9T mag, Release 2.0.
INFO, Channel 1, Temperature Sensor
INFO, Sample 1 Length (cm): 0.000000; Width (cm): 0.000000; Thickness (cm): 0.000000.

[Data]
Timestamp(s),Field(Oe),Field Status,TempA(K),TempB(K),TempC(K),TempD(K),Ramp1,Ramp2,Setpoint1,Setpoint2,Output1(%),Output2(%),Temp Status
3752792248.113800,0.000,Standby,299.997,300.000,41.196,3.171,0,0,300.000,300.000,13.310,9.430,1
3752792458.113800,2.176,Sweeping down,299.996,299.999,41.184,3.905,0,0,300.000,300.000,13.330,9.430,1
3752792668.113800,,,300.000,299.999,41.198,3.942,0,0,300.000,300.000,13.350,9.380,1
3752792878.113800,2.746,Sweeping up,300.002,299.999,41.217,4.222,0,0,300.000,300.000,13.270,9.410,1
3752793088.113800,0.197,Sweeping down,300.001,300.002,41.227,3.300,0,0,300.000,300.000,13.290,9.400,1
3752793298.113800,0.000,Standby,300.003,300.002,41.221,3.169,0,0,300.000,300.000,13.200,9.350,1
3752793508.113800,8.230,Sweeping down,300.002,300.000,41.203,3.826,0,0,300.000,300.000,13.170,9.400,1
3752793718.113800,-7.053,Sweeping up,299.998,300.002,41.209,3.827,0,0,300.000,300.000,13.200,9.400,1
3752793928.113800,5.807,Sweeping to zero,299.997,299.998,41.217,3.827,0,0,300.000,300.000,13.240,9.410,1
3752794138.113800,0.000,Standby,299.996,299.999,41.233,3.178,0,0,300.000,300.000,13.270,9.360,1
3752794563.885800,0.363k,Pause,299.999,300.001,41.209,3.173,0,0,300.000,300.000,13.290,9.380,1
3752794956.332800,0.000000,Standby,299.998,300.000,41.198,3.168,0,0,300.000,300.000,13.260,9.400,1
3752795165.154800,0.000000,Standby,299.997,299.999,41.195,3.170,0,0,300.000,300.000,13.290,9.400,1
3752795375.154800,0.000000,Standby,299.998,299.999,41.192,3.169,0,0,300.000,300.000,13.330,9.380,1
3752795585.154800,0.000000,Standby,300.000,300.000,41.189,3.169,0,0,300.000,300.000,13.290,9.380,1
3752795795.154800,0.000000,Standby,300.000,299.999,41.189,3.169,0,0,300.000,300.000,13.270,9.380,1
3752796005.154800,0.000000,Standby,300.003,300.000,41.190,3.168,0,0,300.000,300.000,13.240,9.380,1
3752796215.154800,0.000000,Standby,300.001,299.997,41.191,3.169,0,0,300.000,300.000,13.240,9.400,1
3752796425.154800,0.000000,Standby,300.000,299.998,41.190,3.169,0,0,300.000,300.000,13.240,9.400,1
3752796635.154800,0.000000,Standby,299.999,299.998,41.190,3.169,0,0,300.000,300.000,13.260,9.400,1
3752796845.154800,0.000000,Standby,299.997,300.001,41.194,3.170,0,0,300.000,300.000,13.270,9.400,1
3752797055.154800,0.000000,Standby,299.995,299.999,41.195,3.170,0,0,300.000,300.000,13.290,9.400,1
3752797265.154800,0.000000,Standby,299.997,299.999,41.196,3.169,0,0,300.000,300.000,13.330,9.400,1
3752797475.154800,0.000000,Standby,299.998,299.999,41.197,3.170,0,0,300.000,300.000,13.200,9.400,1
3752797685.154800,0.000000,Standby,300.000,300.000,41.200,3.170,0,0,300.000,300.000,13.260,9.380,1
3752797895.154800,0.000000,Standby,300.000,300.000,41.204,3.168,0,0,300.000,300.000,13.290,9.380,1
3752798105.154800,0.000000,Standby,300.002,300.001,41.205,3.163,0,0,300.000,300.000,13.260,9.400,1
3752798315.154800,0.000000,Standby,300.018,300.001,41.204,3.166,0,0,300.000,300.000,13.040,9.400,1
3752798525.154800,0.000000,Standby,300.010,299.998,41.205,3.165,0,0,300.000,300.000,12.950,9.410,1
3752798735.154800,0.000000,Standby,299.999,300.000,41.209,3.168,0,0,300.000,300.000,13.040,9.400,1
3752798945.154800,0.000000,Standby,299.994,300.000,41.210,3.167,0,0,300.000,300.000,13.130,9.400,1
3752799155.154800,0.000000,Standby,299.987,299.999,41.209,3.168,0,0,300.000,300.000,13.260,9.400,1
3752799365.154800,0.000000,Standby,299.988,300.001,41.208,3.169,0,0,300.000,300.000,13.370,9.400,1
3752799575.154800,0.000000,Standby,299.994,300.003,41.211,3.169,0,0,300.000,300.000,13.420,9.380,1
3752799785.154800,0.000000,Standby,299.994,299.999,41.215,3.169,0,0,300.000,300.000,13.380,9.410,1
3752799995.154800,0.000000,Standby,299.998,299.999,41.215,3.168,0,0,300.000,300.000,13.370,9.380,1
3752800205.161800,0.000000,Standby,299.999,299.998,41.217,3.167,0,0,300.000,300.000,13.370,9.400,1
3752800415.161800,0.000000,Standby,300.005,300.000,41.218,3.169,0,0,300.000,300.000,13.290,9.410,1
3752800625.161800,0.000000,Standby,300.000,300.000,41.221,3.169,0,0,300.000,300.000,13.200,9.410,1
3752800835.161800,0.000000,Standby,300.001,299.999,41.223,3.170,0,0,300.000,300.000,13.220,9.410,1
3752801045.161800,0.000000,Standby,299.999,300.000,41.223,3.170,0,0,300.000,300.000,13.260,9.410,1
3752801255.161800,0.000000,Standby,299.999,300.000,41.225,3.169,0,0,300.000,300.000,13.310,9.410,1
3752801465.161800,0.000000,Standby,300.001,299.998,41.223,3.169,0,0,300.000,300.000,13.290,9.360,1
3752801675.161800,0.000000,Standby,300.005,300.000,41.222,3.169,0,0,300.000,300.000,13.260,9.430,1
3752801885.161800,0.000000,Standby,300.001,300.001,41.223,3.168,0,0,300.000,300.000,13.240,9.430,1
3752802095.161800,0.000000,Standby,300.002,299.998,41.231,3.169,0,0,300.000,300.000,13.220,9.400,1
3752802305.161800,0.000000,Standby,299.999,300.001,41.241,3.170,0,0,300.000,300.000,13.220,9.410,1
3752802515.161800,0.000000,Standby,299.995,299.998,41.250,3.170,0,0,300.000,300.000,13.220,9.400,1
3752802725.161800,0.000000,Standby,299.994,300.003,41.253,3.169,0,0,300.000,300.000,13.270,9.400,1
3752802935.161800,0.000000,Standby,299.993,300.001,41.257,3.168,0,0,300.000,300.000,13.330,9.400,1
3752803145.161800,0.000000,Standby,299.998,299.999,41.260,3.170,0,0,300.000,300.000,13.350,9.400,1
3752803355.161800,0.000000,Standby,299.999,300.000,41.261,3.168,0,0,300.000,300.000,13.350,9.410,1
3752803565.161800,0.000000,Standby,300.000,299.999,41.263,3.168,0,0,300.000,300.000,13.310,9.380,1
3752803775.161800,0.000000,Standby,300.000,300.002,41.263,3.169,0,0,300.000,300.000,13.270,9.400,1
3752803985.161800,0.000000,Standby,300.001,300.001,41.265,3.168,0,0,300.000,300.000,13.330,9.380,1
3752804195.161800,0.000000,Standby,300.002,300.000,41.268,3.170,0,0,300.000,300.000,13.260,9.380,1
3752804405.161800,0.000000,Standby,300.003,300.002,41.271,3.171,0,0,300.000,300.000,13.270,9.400,1
3752804615.161800,0.000000,Standby,300.002,299.999,41.268,3.166,0,0,300.000,300.000,13.270,9.400,1
3752804825.161800,0.000000,Standby,300.002,300.000,41.268,3.167,0,0,300.000,300.000,13.200,9.400,1
3752805035.161800,0.000000,Standby,300.001,299.999,41.269,3.169,0,0,300.000,300.000,13.220,9.400,1
3752805245.161800,0.000000,Standby,299.997,300.002,41.266,3.168,0,0,300.000,300.000,13.240,9.400,1
3752805455.161800,0.000000,Standby,299.997,300.000,41.266,3.166,0,0,300.000,300.000,13.260,9.400,1
3752805665.161800,0.000000,Standby,299.996,300.000,41.267,3.166,0,0,300.000,300.000,13.270,9.360,1
3752805875.161800,0.000000,Standby,299.996,299.998,41.266,3.167,0,0,300.000,300.000,13.270,9.410,1
3752806085.161800,0.000000,Standby,300.000,299.998,41.265,3.168,0,0,300.000,300.000,13.270,9.400,1
3752806295.161800,0.000000,Standby,300.001,299.999,41.266,3.169,0,0,300.000,300.000,13.290,9.400,1
3752806505.161800,0.000000,Standby,300.003,299.999,41.264,3.167,0,0,300.000,300.000,13.220,9.400,1
3752806715.161800,0.000000,Standby,299.999,299.999,41.262,3.166,0,0,300.000,300.000,13.260,9.400,1
3752806925.161800,0.000000,Standby,300.000,300.000,41.261,3.165,0,0,300.000,300.000,13.310,9.400,1
3752807135.161800,0.000000,Standby,299.999,299.998,41.256,3.168,0,0,300.000,300.000,13.270,9.400,1
3752807345.161800,0.000000,Standby,300.002,300.000,41.255,3.165,0,0,300.000,300.000,13.220,9.430,1
3752807555.161800,0.000000,Standby,300.002,300.000,41.254,3.165,0,0,300.000,300.000,13.240,9.400,1
3752807765.161800,0.000000,Standby,299.999,299.999,41.255,3.163,0,0,300.000,300.000,13.270,9.400,1
3752807975.161800,0.000000,Standby,299.999,300.000,41.254,3.164,0,0,300.000,300.000,13.260,9.410,1
3752808185.161800,18416.000000,Sweeping up,299.998,300.000,41.243,3.923,0,0,300.000,300.000,13.240,9.400,1
3752808395.161800,41232.000000,Sweeping up,299.995,300.000,41.277,3.734,0,0,300.000,300.000,13.310,9.400,1
3752808605.161800,59241.000000,Sweeping up,299.996,300.001,41.353,3.446,0,0,300.000,300.000,13.370,9.400,1
3752808815.161800,70629.000000,Sweeping up,299.998,300.001,41.458,3.397,0,0,300.000,300.000,13.350,9.360,1
3752809025.161800,81994.000000,Sweeping up,299.998,300.001,41.585,3.374,0,0,300.000,300.000,13.310,9.380,1
3752809235.161800,90000.000000,Sweeping up,299.997,299.998,41.755,3.211,0,0,300.000,300.000,13.310,9.400,1
3752809445.161800,90000.000000,Sweeping up,300.002,299.997,41.924,3.183,0,0,300.000,300.000,13.330,9.410,1
3752809655.161800,87725.000000,Sweeping down,300.002,300.000,42.045,3.256,0,0,300.000,300.000,13.330,9.400,1
3752809865.161800,76355.000000,Sweeping down,300.004,299.999,42.097,3.376,0,0,300.000,300.000,13.270,9.400,1
3752810075.161800,64983.000000,Sweeping down,300.007,300.001,42.057,3.404,0,0,300.000,300.000,13.240,9.400,1
3752810285.161800,53424.000000,Sweeping down,300.002,300.001,41.962,3.442,0,0,300.000,300.000,13.180,9.400,1
3752810495.161800,30771.000000,Sweeping down,299.998,299.999,41.828,3.747,0,0,300.000,300.000,13.200,9.400,1
3752810705.161800,8071.000000,Sweeping down,299.994,299.998,41.692,3.941,0,0,300.000,300.000,13.200,9.400,1
3752810915.161800,-14439.000000,Sweeping down,299.996,300.001,41.590,4.066,0,0,300.000,300.000,13.290,9.380,1
3752811125.161800,-37078.000000,Sweeping down,299.997,300.001,41.543,3.763,0,0,300.000,300.000,13.270,9.360,1
3752811335.161800,-57211.000000,Sweeping down,299.996,300.000,41.552,3.502,0,0,300.000,300.000,13.330,9.360,1
3752811545.161800,-68580.000000,Sweeping down,299.994,299.999,41.616,3.408,0,0,300.000,300.000,13.310,9.360,1
3752811755.161800,-79910.000000,Sweeping down,299.998,300.000,41.711,3.381,0,0,300.000,300.000,13.270,9.330,1
3752811965.161800,-90000.000000,Sweeping down,300.000,300.000,41.853,3.287,0,0,300.000,300.000,13.290,9.360,1
3752812175.161800,-85137.000000,Sweeping up,300.004,300.001,42.011,3.327,0,0,300.000,300.000,13.260,9.380,1
3752812385.161800,-73768.000000,Sweeping up,300.002,299.999,42.062,3.381,0,0,300.000,300.000,13.290,9.380,1
3752812595.161800,-62408.000000,Sweeping up,300.003,300.000,42.024,3.409,0,0,300.000,300.000,13.270,9.380,1
3752812805.161800,-48294.000000,Sweeping up,300.004,299.999,41.938,3.626,0,0,300.000,300.000,13.260,9.380,1
3752813015.161800,-25645.000000,Sweeping up,300.008,299.999,41.810,3.777,0,0,300.000,300.000,13.170,9.380,1
3752813225.161800,-2959.000000,Sweeping up,300.005,300.000,41.681,4.039,0,0,300.000,300.000,13.130,9.380,1
3752813435.161800,19555.000000,Sweeping up,300.002,299.999,41.593,3.943,0,0,300.000,300.000,13.130,9.360,1
3752813645.161800,42259.000000,Sweeping up,299.997,299.999,41.558,3.734,0,0,300.000,300.000,13.170,9.360,1
3752813855.161800,59787.000000,Sweeping up,299.995,300.000,41.585,3.442,0,0,300.000,300.000,13.170,9.320,1
3752814065.161800,71161.000000,Sweeping up,299.998,300.000,41.650,3.398,0,0,300.000,300.000,13.220,9.330,1
3752814275.161800,82522.000000,Sweeping up,300.000,299.999,41.749,3.374,0,0,300.000,300.000,13.200,9.350,1
3752814485.161800,90000.000000,Sweeping up,299.999,299.997,41.900,3.205,0,0,300.000,300.000,13.200,9.360,1
3752814695.161800,90000.000000,Sweeping up,299.999,300.000,42.049,3.186,0,0,300.000,300.000,13.220,9.400,1
3752814905.161800,90000.000000,Sweeping up,300.000,300.000,42.154,3.186,0,0,300.000,300.000,13.220,9.360,1
3752815115.161800,90000.000000,Sweeping up,300.002,299.999,42.234,3.185,0,0,300.000,300.000,13.240,9.380,1
3752815325.161800,85217.000000,Sweeping to zero,300.000,300.000,42.296,3.324,0,0,300.000,300.000,13.260,9.360,1
3752815535.161800,73847.000000,Sweeping to zero,300.004,300.002,42.285,3.379,0,0,300.000,300.000,13.260,9.380,1
3752815745.161800,62500.000000,Sweeping to zero,300.005,299.997,42.201,3.408,0,0,300.000,300.000,13.090,9.330,1
3752815955.161800,48467.000000,Sweeping to zero,299.999,299.997,42.082,3.621,0,0,300.000,300.000,13.150,9.400,1
3752816165.161800,25754.000000,Sweeping to zero,299.995,300.002,41.930,3.777,0,0,300.000,300.000,13.220,9.380,1
3752816375.161800,3118.000000,Sweeping to zero,299.999,300.000,41.788,4.036,0,0,300.000,300.000,13.200,9.360,1
3752816585.161800,0.000000,Standby,299.998,300.002,41.694,3.172,0,0,300.000,300.000,13.220,9.380,1
3752816795.161800,0.000000,Standby,300.001,300.000,41.611,3.168,0,0,300.000,300.000,13.220,9.360,1
3752817005.161800,0.000000,Standby,300.000,300.001,41.549,3.166,0,0,300.000,300.000,13.270,9.360,1
3752817215.161800,0.000000,Standby,299.997,300.001,41.504,3.163,0,0,300.000,300.000,13.310,9.380,1
3752817425.161800,0.000000,Standby,300.002,299.999,41.470,3.162,0,0,300.000,300.000,13.270,9.360,1
3752817635.161800,0.000000,Standby,300.002,300.000,41.444,3.165,0,0,300.000,300.000,13.240,9.400,1
3752817845.161800,0.000000,Standby,300.005,299.999,41.424,3.163,0,0,300.000,300.000,13.260,9.410,1
3752818055.161800,0.000000,Standby,300.006,300.000,41.405,3.163,0,0,300.000,300.000,13.170,9.360,1
3752818265.161800,0.000000,Standby,300.002,300.000,41.389,3.163,0,0,300.000,300.000,13.170,9.400,1
3752818475.161800,0.000000,Standby,299.998,300.000,41.372,3.167,0,0,300.000,300.000,13.240,9.400,1
3752818685.161800,0.000000,Standby,300.000,300.000,41.358,3.168,0,0,300.000,300.000,13.220,9.400,1
3752818895.161800,0.000000,Standby,299.994,300.000,41.349,3.166,0,0,300.000,300.000,13.310,9.400,1
3752819105.161800,0.000000,Standby,299.999,300.001,41.342,3.164,0,0,300.000,300.000,13.350,9.400,1
3752819315.161800,0.000000,Standby,299.999,300.000,41.336,3.166,0,0,300.000,300.000,13.350,9.410,1
3752819525.161800,0.000000,Standby,299.999,299.997,41.332,3.168,0,0,300.000,300.000,13.290,9.410,1
3752819735.161800,0.000000,Standby,300.000,300.000,41.328,3.170,0,0,300.000,300.000,13.350,9.430,1
3752819945.161800,0.000000,Standby,300.003,300.000,41.319,3.169,0,0,300.000,300.000,13.270,9.410,1
3752820155.161800,0.000000,Standby,300.002,299.998,41.308,3.167,0,0,300.000,300.000,13.240,9.400,1
3752820365.161800,0.000000,Standby,300.000,300.001,41.300,3.168,0,0,300.000,300.000,13.200,9.400,1
3752820575.161800,0.000000,Standby,299.995,300.000,41.292,3.170,0,0,300.000,300.000,13.260,9.400,1
3752820785.161800,0.000000,Standby,299.995,300.000,41.288,3.168,0,0,300.000,300.000,13.310,9.430,1
3752820995.161800,0.000000,Standby,299.995,300.001,41.284,3.167,0,0,300.000,300.000,13.290,9.410,1
3752821205.161800,0.000000,Standby,299.997,300.000,41.279,3.167,0,0,300.000,300.000,13.290,9.410,1
3752821415.161800,0.000000,Standby,299.998,300.002,41.272,3.166,0,0,300.000,300.000,13.330,9.400,1
3752821625.161800,0.000000,Standby,300.003,300.001,41.268,3.166,0,0,300.000,300.000,13.240,9.410,1
3752821835.161800,0.000000,Standby,300.001,300.000,41.264,3.166,0,0,300.000,300.000,13.220,9.400,1
3752822045.161800,0.000000,Standby,299.997,300.002,41.260,3.167,0,0,300.000,300.000,13.330,9.400,1
3752822255.161800,0.000000,Standby,299.999,299.998,41.259,3.168,0,0,300.000,300.000,13.310,9.410,1
3752822465.161800,0.000000,Standby,299.996,299.999,41.255,3.167,0,0,300.000,300.000,13.310,9.430,1
3752822675.161800,0.000000,Standby,299.998,300.000,41.254,3.167,0,0,300.000,300.000,13.310,9.400,1
3752822885.161800,0.000000,Standby,299.999,300.001,41.253,3.167,0,0,300.000,300.000,13.330,9.410,1
3752823095.161800,0.000000,Standby,300.000,299.999,41.250,3.167,0,0,300.000,300.000,13.290,9.410,1
3752823305.161800,0.000000,Standby,300.002,300.000,41.248,3.165,0,0,300.000,300.000,13.350,9.410,1
3752823515.161800,0.000000,Standby,300.002,299.999,41.247,3.166,0,0,300.000,300.000,13.290,9.410,1
3752823725.161800,0.000000,Standby,299.999,299.999,41.249,3.163,0,0,300.000,300.000,13.330,9.400,1
3752823935.161800,0.000000,Standby,299.999,299.998,41.249,3.166,0,0,300.000,300.000,13.270,9.410,1
3752824145.161800,0.000000,Standby,300.000,300.000,41.249,3.167,0,0,300.000,300.000,13.310,9.430,1
3752824355.161800,0.000000,Standby,300.001,299.998,41.252,3.168,0,0,300.000,300.000,13.290,9.430,1
3752824565.161800,0.000000,Standby,300.001,299.997,41.256,3.169,0,0,300.000,300.000,13.270,9.410,1
3752824775.161800,0.000000,Standby,300.002,299.997,41.257,3.170,0,0,300.000,300.000,13.270,9.430,1
3752824985.161800,0.000000,Standby,299.999,299.999,41.254,3.168,0,0,300.000,300.000,13.310,9.430,1
3752825195.161800,0.000000,Standby,299.999,299.997,41.251,3.169,0,0,300.000,300.000,13.270,9.430,1
3752825405.161800,0.000000,Standby,299.997,299.999,41.249,3.166,0,0,300.000,300.000,13.330,9.400,1
3752825615.161800,0.000000,Standby,299.996,299.998,41.246,3.167,0,0,300.000,300.000,13.330,9.410,1
3752825825.161800,0.000000,Standby,300.000,299.999,41.245,3.168,0,0,300.000,300.000,13.330,9.410,1
3752826035.161800,0.000000,Standby,300.002,300.002,41.245,3.168,0,0,300.000,300.000,13.290,9.430,1
3752826245.161800,0.000000,Standby,300.001,299.998,41.245,3.169,0,0,300.000,300.000,13.310,9.430,1
3752826455.161800,0.000000,Standby,299.999,299.999,41.244,3.169,0,0,300.000,300.000,13.270,9.430,1
3752826665.161800,0.000000,Standby,299.998,300.000,41.245,3.169,0,0,300.000,300.000,13.270,9.440,1
3752826875.161800,0.000000,Standby,299.998,300.000,41.243,3.168,0,0,300.000,300.000,13.270,9.410,1
3752827085.161800,0.000000,Standby,300.001,299.998,41.243,3.168,0,0,300.000,300.000,13.290,9.460,1
3752827295.161800,0.000000,Standby,300.001,300.000,41.242,3.169,0,0,300.000,300.000,13.260,9.410,1
3752827505.161800,0.000000,Standby,300.000,299.997,41.241,3.168,0,0,300.000,300.000,13.260,9.410,1
3752827715.161800,0.000000,Standby,299.998,299.998,41.242,3.168,0,0,300.000,300.000,13.270,9.380,1
3752827925.161800,0.000000,Standby,299.997,300.000,41.241,3.167,0,0,300.000,300.000,13.290,9.410,1
3752828135.161800,0.000000,Standby,299.997,299.999,41.238,3.167,0,0,300.000,300.000,13.330,9.400,1
3752828345.161800,0.000000,Standby,299.997,300.000,41.237,3.167,0,0,300.000,300.000,13.310,9.440,1
3752828555.161800,0.000000,Standby,300.001,300.001,41.237,3.167,0,0,300.000,300.000,13.310,9.410,1
3752828765.161800,0.000000,Standby,299.999,299.998,41.240,3.167,0,0,300.000,300.000,13.270,9.410,1
3752828975.161800,0.000000,Standby,299.997,299.998,41.240,3.169,0,0,300.000,300.000,13.330,9.410,1
3752829185.161800,0.000000,Standby,300.001,300.002,41.237,3.168,0,0,300.000,300.000,13.310,9.410,1
3752829395.161800,0.000000,Standby,300.003,299.998,41.234,3.168,0,0,300.000,300.000,13.290,9.430,1
3752829605.161800,0.000000,Standby,300.000,300.000,41.229,3.167,0,0,300.000,300.000,13.290,9.410,1
3752829815.161800,0.000000,Standby,300.001,299.996,41.230,3.170,0,0,300.000,300.000,13.330,9.430,1
3752830025.161800,0.000000,Standby,300.003,300.000,41.231,3.167,0,0,300.000,300.000,13.330,9.430,1
3752830235.161800,0.000000,Standby,300.003,300.001,41.232,3.170,0,0,300.000,300.000,13.240,9.430,1
3752830445.161800,0.000000,Standby,300.004,300.000,41.232,3.169,0,0,300.000,300.000,13.240,9.430,1
3752830655.161800,17322.000000,Sweeping up,300.004,300.001,41.224,3.930,0,0,300.000,300.000,13.240,9.440,1
3752830865.161800,39965.000000,Sweeping up,300.000,299.999,41.258,3.737,0,0,300.000,300.000,13.310,9.430,1
3752831075.161800,58663.000000,Sweeping up,300.002,300.000,41.335,3.458,0,0,300.000,300.000,13.310,9.400,1
3752831285.161800,70052.000000,Sweeping up,299.999,300.001,41.440,3.401,0,0,300.000,300.000,13.310,9.430,1
3752831495.161800,81418.000000,Sweeping up,299.998,300.001,41.568,3.375,0,0,300.000,300.000,13.330,9.410,1
3752831705.161800,90000.000000,Sweeping up,300.001,300.000,41.739,3.226,0,0,300.000,300.000,13.310,9.400,1
3752831915.161800,90000.000000,Sweeping up,300.003,300.001,41.912,3.187,0,0,300.000,300.000,13.310,9.400,1
3752832125.161800,90000.000000,Sweeping up,292.800,292.811,42.038,3.185,1,1,2.000,2.000,0.000,0.000,3
3752832335.161800,90000.000000,Sweeping up,285.903,286.601,42.121,3.183,1,1,2.000,2.000,0.000,0.000,3
3752832545.161800,90000.000000,Sweeping up,280.120,281.176,42.181,3.181,1,1,2.000,2.000,0.000,0.000,3
3752832755.161800,90000.000000,Sweeping up,275.153,276.404,42.221,3.181,1,1,2.000,2.000,0.000,0.000,3
3752832965.161800,90000.000000,Sweeping up,270.809,272.174,42.250,3.180,1,1,2.000,2.000,0.000,0.000,3
3752833175.161800,90000.000000,Sweeping up,266.959,268.360,42.271,3.180,1,1,2.000,2.000,0.000,0.000,3
3752833385.161800,90000.000000,Sweeping up,263.502,264.911,42.288,3.178,1,1,2.000,2.000,0.000,0.000,3
3752833595.161800,90000.000000,Sweeping up,260.366,261.777,42.292,3.177,1,1,2.000,2.000,0.000,0.000,3
3752833805.161800,90000.000000,Sweeping up,257.457,258.846,42.293,3.174,1,1,2.000,2.000,0.000,0.000,3
3752834015.161800,90000.000000,Sweeping up,254.747,256.115,42.293,3.168,1,1,2.000,2.000,0.000,0.000,3
3752834225.161800,90000.000000,Sweeping up,252.201,253.550,42.285,3.168,1,1,2.000,2.000,0.000,0.000,3
3752834435.161800,90000.000000,Sweeping up,249.775,251.108,42.277,3.175,1,1,2.000,2.000,0.000,0.000,3
3752834645.161800,90000.000000,Sweeping up,247.470,248.781,42.267,3.175,1,1,2.000,2.000,0.000,0.000,3
3752834855.161800,0.000000,,245.267,246.560,42.256,3.169,1,1,2.000,2.000,0.000,0.000,3
3752835065.161800,90000.000000,Sweeping up,243.130,244.408,42.244,3.175,1,1,2.000,2.000,0.000,0.000,3
3752835275.161800,90000.000000,Sweeping up,241.062,242.318,42.232,3.173,1,1,2.000,2.000,0.000,0.000,3
3752835485.161800,90000.000000,Sweeping up,239.048,240.292,42.214,3.165,1,1,2.000,2.000,0.000,0.000,3
3752835695.161800,90000.000000,Sweeping up,237.085,238.311,42.192,3.165,1,1,2.000,2.000,0.000,0.000,3
3752835905.161800,90000.000000,Sweeping up,235.168,236.389,42.169,3.165,1,1,2.000,2.000,0.000,0.000,3
3752836115.161800,90000.000000,Sweeping up,233.286,234.493,42.147,3.166,1,1,2.000,2.000,0.000,0.000,3
3752836325.161800,90000.000000,Sweeping up,231.441,232.647,42.125,3.163,1,1,2.000,2.000,0.000,0.000,3
3752836535.161800,90000.000000,Sweeping up,229.625,230.819,42.098,3.165,1,1,2.000,2.000,0.000,0.000,3
3752836745.161800,90000.000000,Sweeping up,227.841,229.034,42.072,3.164,1,1,2.000,2.000,0.000,0.000,3
3752836955.161800,90000.000000,Sweeping up,226.080,227.261,42.044,3.159,1,1,2.000,2.000,0.000,0.000,3
3752837165.161800,90000.000000,Sweeping up,224.347,225.526,42.016,3.158,1,1,2.000,2.000,0.000,0.000,3
3752837375.161800,90001.000000,Sweeping up,222.642,223.816,41.985,3.158,1,1,2.000,2.000,0.000,0.000,3
3752837585.161800,90000.000000,Sweeping up,220.959,222.135,41.957,3.159,1,1,2.000,2.000,0.000,0.000,3
3752837795.161800,90000.000000,Sweeping up,219.294,220.459,41.925,3.158,1,1,2.000,2.000,0.000,0.000,3
3752838005.161800,90000.000000,Sweeping up,217.655,218.812,41.892,3.159,0,0,2.000,2.000,0.000,0.000,4
3752838215.161800,90000.000000,Sweeping up,216.030,217.184,41.859,3.157,0,0,2.000,2.000,0.000,0.000,4
3752838425.161800,90001.000000,Sweeping up,214.423,215.570,41.826,3.155,0,0,2.000,2.000,0.000,0.000,4
3752838635.161800,90001.000000,Sweeping up,212.820,213.968,41.791,3.154,0,0,2.000,2.000,0.000,0.000,4
3752838845.161800,90001.000000,Sweeping up,211.247,212.399,41.752,3.153,0,0,2.000,2.000,0.000,0.000,4
3752839055.164800,90001.000000,Sweeping up,209.688,210.839,41.713,3.153,0,0,2.000,2.000,0.000,0.000,4
3752839265.164800,90001.000000,Sweeping up,208.146,209.297,41.677,3.151,0,0,2.000,2.000,0.000,0.000,4
3752839475.164800,90001.000000,Sweeping up,206.619,207.769,41.639,3.151,0,0,2.000,2.000,0.000,0.000,4
3752839685.164800,90001.000000,Sweeping up,205.106,206.252,41.599,3.151,0,0,2.000,2.000,0.000,0.000,4
3752839895.164800,90000.000000,Sweeping up,203.607,204.753,41.561,3.149,0,0,2.000,2.000,0.000,0.000,4
3752840105.164800,90001.000000,Sweeping up,202.122,203.270,41.521,3.150,0,0,2.000,2.000,0.000,0.000,4
3752840315.164800,90001.000000,Sweeping up,200.650,201.795,41.485,3.149,0,0,2.000,2.000,0.000,0.000,4
3752840525.164800,90001.000000,Sweeping up,199.192,200.336,41.449,3.148,0,0,2.000,2.000,0.000,0.000,4
3752840735.164800,90001.000000,Sweeping up,197.747,198.888,41.409,3.150,0,0,2.000,2.000,0.000,0.000,4
3752840945.164800,90001.000000,Sweeping up,196.312,197.452,41.368,3.148,0,0,2.000,2.000,0.000,0.000,4
3752841155.164800,90001.000000,Sweeping up,194.890,196.030,41.331,3.148,0,0,2.000,2.000,0.000,0.000,4
3752841365.164800,90001.000000,Sweeping up,193.477,194.618,41.294,3.146,0,0,2.000,2.000,0.000,0.000,4
3752841575.164800,90001.000000,Sweeping up,192.078,193.218,41.252,3.147,0,0,2.000,2.000,0.000,0.000,4
3752841785.164800,90001.000000,Sweeping up,190.681,191.821,41.212,3.146,0,0,2.000,2.000,0.000,0.000,4
3752841995.164800,90001.000000,Sweeping up,189.303,190.441,41.172,3.147,0,0,2.000,2.000,0.000,0.000,4
3752842205.164800,90001.000000,Sweeping up,187.937,189.077,41.132,3.146,0,0,2.000,2.000,0.000,0.000,4
3752842415.164800,90001.000000,Sweeping up,186.580,187.724,41.094,3.145,0,0,2.000,2.000,0.000,0.000,4
3752842625.164800,90001.000000,Sweeping up,185.234,186.375,41.054,3.145,0,0,2.000,2.000,0.000,0.000,4
3752842835.164800,90001.000000,Sweeping up,183.896,185.040,41.013,3.143,0,0,2.000,2.000,0.000,0.000,4
3752843045.164800,90001.000000,Sweeping up,182.567,183.715,40.973,3.143,0,0,2.000,2.000,0.000,0.000,4
3752843255.164800,90001.000000,Sweeping up,181.249,182.397,40.930,3.141,0,0,2.000,2.000,0.000,0.000,4
3752843465.164800,90001.000000,Sweeping up,179.941,181.091,40.887,3.139,0,0,2.000,2.000,0.000,0.000,4
3752843675.164800,90001.000000,Sweeping up,178.642,179.793,40.848,3.141,0,0,2.000,2.000,0.000,0.000,4
3752843885.164800,90001.000000,Sweeping up,177.352,178.504,40.808,3.140,0,0,2.000,2.000,0.000,0.000,4
3752844095.164800,90001.000000,Sweeping up,176.070,177.222,40.769,3.140,0,0,2.000,2.000,0.000,0.000,4
3752844305.164800,90000.000000,Sweeping up,174.798,175.948,40.729,3.140,0,0,2.000,2.000,0.000,0.000,4
3752844515.164800,90000.000000,Sweeping up,173.528,174.677,40.689,3.139,0,0,2.000,2.000,0.000,0.000,4
3752844725.164800,90000.000000,Sweeping up,172.273,173.423,40.650,3.140,0,0,2.000,2.000,0.000,0.000,4
3752844935.164800,90000.000000,Sweeping up,171.027,172.176,40.613,3.138,0,0,2.000,2.000,0.000,0.000,4
3752845145.164800,90000.000000,Sweeping up,169.788,170.940,40.576,3.138,0,0,2.000,2.000,0.000,0.000,4
3752845355.164800,90001.000000,Sweeping up,168.558,169.709,40.535,3.138,0,0,2.000,2.000,0.000,0.000,4
3752845565.164800,90001.000000,Sweeping up,167.335,168.489,40.496,3.138,0,0,2.000,2.000,0.000,0.000,4
3752845775.164800,90001.000000,Sweeping up,166.119,167.276,40.457,3.138,0,0,2.000,2.000,0.000,0.000,4
3752845985.164800,90001.000000,Sweeping up,164.910,166.066,40.421,3.135,0,0,2.000,2.000,0.000,0.000,4
3752846195.164800,90001.000000,Sweeping up,163.708,164.869,40.382,3.136,0,0,2.000,2.000,0.000,0.000,4
3752846405.164800,90001.000000,Sweeping up,162.513,163.672,40.345,3.134,0,0,2.000,2.000,0.000,0.000,4
3752846615.164800,90001.000000,Sweeping up,161.326,162.489,40.306,3.136,0,0,2.000,2.000,0.000,0.000,4
3752846825.164800,90001.000000,Sweeping up,160.139,161.304,40.270,3.134,0,0,2.000,2.000,0.000,0.000,4
3752847035.164800,90001.000000,Sweeping up,158.969,160.131,40.231,3.134,0,0,2.000,2.000,0.000,0.000,4
3752847245.164800,90001.000000,Sweeping up,157.803,158.970,40.191,3.136,0,0,2.000,2.000,0.000,0.000,4
3752847455.164800,90001.000000,Sweeping up,156.643,157.812,40.152,3.134,0,0,2.000,2.000,0.000,0.000,4
3752847665.164800,90001.000000,Sweeping up,155.492,156.664,40.117,3.133,0,0,2.000,2.000,0.000,0.000,4
3752847875.164800,90001.000000,Sweeping up,154.347,155.518,40.081,3.134,0,0,2.000,2.000,0.000,0.000,4
3752848085.164800,90001.000000,Sweeping up,153.209,154.383,40.048,3.133,0,0,2.000,2.000,0.000,0.000,4
3752848295.164800,90001.000000,Sweeping up,152.077,153.252,40.013,3.133,0,0,2.000,2.000,0.000,0.000,4
3752848505.164800,90001.000000,Sweeping up,150.954,152.129,39.975,3.132,0,0,2.000,2.000,0.000,0.000,4
3752848715.164800,90001.000000,Sweeping up,149.834,151.010,39.939,3.133,0,0,2.000,2.000,0.000,0.000,4
3752848925.164800,90001.000000,Sweeping up,148.721,149.897,39.904,3.133,0,0,2.000,2.000,0.000,0.000,4
3752849135.164800,90001.000000,Sweeping up,147.614,148.791,39.871,3.132,0,0,2.000,2.000,0.000,0.000,4
3752849345.164800,90001.000000,Sweeping up,146.513,147.691,39.837,3.130,0,0,2.000,2.000,0.000,0.000,4
3752849555.164800,90001.000000,Sweeping up,145.418,146.597,39.803,3.131,0,0,2.000,2.000,0.000,0.000,4
3752849765.164800,90001.000000,Sweeping up,144.322,145.505,39.770,3.129,0,0,2.000,2.000,0.000,0.000,4
3752849975.164800,90001.000000,Sweeping up,143.238,144.424,39.736,3.129,0,0,2.000,2.000,0.000,0.000,4
3752850185.164800,90001.000000,Sweeping up,142.161,143.350,39.700,3.128,0,0,2.000,2.000,0.000,0.000,4
3752850395.164800,90001.000000,Sweeping up,141.088,142.278,39.665,3.126,0,0,2.000,2.000,0.000,0.000,4
3752850605.164800,90001.000000,Sweeping up,140.022,141.212,39.631,3.129,0,0,2.000,2.000,0.000,0.000,4
3752850815.164800,90000.000000,Sweeping up,138.959,140.150,39.599,3.128,0,0,2.000,2.000,0.000,0.000,4
3752851025.164800,90000.000000,Sweeping up,137.903,139.095,39.564,3.129,0,0,2.000,2.000,0.000,0.000,4
3752851235.164800,90001.000000,Sweeping up,136.853,138.047,39.531,3.127,0,0,2.000,2.000,0.000,0.000,4
3752851445.164800,90001.000000,Sweeping up,135.808,137.003,39.501,3.127,0,0,2.000,2.000,0.000,0.000,4
3752851655.164800,90001.000000,Sweeping up,134.766,135.966,39.469,3.127,0,0,2.000,2.000,0.000,0.000,4
3752851865.164800,90001.000000,Sweeping up,133.731,134.933,39.436,3.126,0,0,2.000,2.000,0.000,0.000,4
3752852075.164800,90000.000000,Sweeping up,132.699,133.904,39.405,3.124,0,0,2.000,2.000,0.000,0.000,4
3752852285.164800,90000.000000,Sweeping up,131.673,132.879,39.371,3.128,0,0,2.000,2.000,0.000,0.000,4
3752852495.164800,90000.000000,Sweeping up,130.653,131.860,39.340,3.128,0,0,2.000,2.000,0.000,0.000,4
3752852705.164800,90000.000000,Sweeping up,129.637,130.846,39.310,3.126,0,0,2.000,2.000,0.000,0.000,4
3752852915.164800,90001.000000,Sweeping up,128.625,129.836,39.281,3.123,0,0,2.000,2.000,0.000,0.000,4
3752853125.164800,90001.000000,Sweeping up,127.618,128.832,39.250,3.123,0,0,2.000,2.000,0.000,0.000,4
3752853335.164800,90001.000000,Sweeping up,126.615,127.832,39.218,3.124,0,0,2.000,2.000,0.000,0.000,4
3752853545.164800,90001.000000,Sweeping up,125.611,126.827,39.189,3.125,0,0,2.000,2.000,0.000,0.000,4
3752853755.164800,90000.000000,Sweeping up,124.617,125.835,39.160,3.124,0,0,2.000,2.000,0.000,0.000,4
3752853965.164800,90001.000000,Sweeping up,123.628,124.848,39.130,3.126,0,0,2.000,2.000,0.000,0.000,4
3752854175.164800,90000.000000,Sweeping up,122.643,123.864,39.101,3.126,0,0,2.000,2.000,0.000,0.000,4
3752854385.164800,90000.000000,Sweeping up,121.663,122.886,39.072,3.125,0,0,2.000,2.000,0.000,0.000,4
3752854595.164800,90001.000000,Sweeping up,120.686,121.909,39.042,3.124,0,0,2.000,2.000,0.000,0.000,4
3752854805.164800,90001.000000,Sweeping up,119.703,120.927,39.014,3.123,0,0,2.000,2.000,0.000,0.000,4
3752855015.164800,90001.000000,Sweeping up,118.745,119.969,38.985,3.124,0,0,2.000,2.000,0.000,0.000,4
3752855225.164800,90000.000000,Sweeping up,117.779,119.005,38.958,3.123,0,0,2.000,2.000,0.000,0.000,4
3752855435.164800,90000.000000,Sweeping up,116.811,118.040,38.930,3.122,0,0,2.000,2.000,0.000,0.000,4
3752855645.164800,90000.000000,Sweeping up,115.852,117.083,38.901,3.124,0,0,2.000,2.000,0.000,0.000,4
3752855855.164800,90000.000000,Sweeping up,114.896,116.133,38.872,3.123,0,0,2.000,2.000,0.000,0.000,4
3752856065.164800,90000.000000,Sweeping up,113.945,115.181,38.842,3.122,0,0,2.000,2.000,0.000,0.000,4
3752856275.164800,90000.000000,Sweeping up,112.997,114.237,38.812,3.121,0,0,2.000,2.000,0.000,0.000,4
3752856485.164800,90001.000000,Sweeping up,112.053,113.295,38.786,3.122,0,0,2.000,2.000,0.000,0.000,4
3752856695.164800,90001.000000,Sweeping up,111.113,112.357,38.759,3.122,0,0,2.000,2.000,0.000,0.000,4
3752856905.164800,90001.000000,Sweeping up,110.169,111.415,38.731,3.122,0,0,2.000,2.000,0.000,0.000,4
3752857115.164800,90001.000000,Sweeping up,109.234,110.482,38.703,3.122,0,0,2.000,2.000,0.000,0.000,4
3752857325.164800,90001.000000,Sweeping up,108.303,109.553,38.678,3.121,0,0,2.000,2.000,0.000,0.000,4
3752857535.164800,90001.000000,Sweeping up,107.375,108.628,38.650,3.123,0,0,2.000,2.000,0.000,0.000,4
3752857745.164800,90001.000000,Sweeping up,106.450,107.704,38.624,3.124,0,0,2.000,2.000,0.000,0.000,4
3752857955.164800,90001.000000,Sweeping up,105.526,106.783,38.597,3.120,0,0,2.000,2.000,0.000,0.000,4
3752858165.164800,90001.000000,Sweeping up,104.607,105.866,38.570,3.119,0,0,2.000,2.000,0.000,0.000,4
3752858375.164800,90001.000000,Sweeping up,103.684,104.947,38.541,3.119,0,0,2.000,2.000,0.000,0.000,4
3752858585.164800,90000.000000,Sweeping up,102.770,104.034,38.514,3.120,0,0,2.000,2.000,0.000,0.000,4
3752858795.164800,90000.000000,Sweeping up,101.860,103.127,38.488,3.121,0,0,2.000,2.000,0.000,0.000,4
3752859005.164800,90001.000000,Sweeping up,100.952,102.220,38.463,3.117,0,0,2.000,2.000,0.000,0.000,4
3752859215.164800,90001.000000,Sweeping up,100.046,101.314,38.435,3.120,0,0,2.000,2.000,0.000,0.000,4
3752859425.164800,90001.000000,Sweeping up,99.142,100.413,38.408,3.118,0,0,2.000,2.000,0.000,0.000,4
3752859635.164800,90001.000000,Sweeping up,98.241,99.512,38.382,3.120,0,0,2.000,2.000,0.000,0.000,4
3752859845.164800,90000.000000,Sweeping up,97.333,98.608,38.357,3.119,0,0,2.000,2.000,0.000,0.000,4
3752860055.164800,90001.000000,Sweeping up,96.434,97.710,38.332,3.120,0,0,2.000,2.000,0.000,0.000,4
3752860265.164800,90001.000000,Sweeping up,95.537,96.812,38.309,3.120,0,0,2.000,2.000,0.000,0.000,4
3752860475.164800,90001.000000,Sweeping up,94.643,95.916,38.284,3.119,0,0,2.000,2.000,0.000,0.000,4
3752860685.164800,90001.000000,Sweeping up,93.749,95.023,38.262,3.117,0,0,2.000,2.000,0.000,0.000,4
3752860895.164800,90001.000000,Sweeping up,92.857,94.131,38.236,3.117,0,0,2.000,2.000,0.000,0.000,4
3752861105.164800,90001.000000,Sweeping up,91.968,93.240,38.214,3.118,0,0,2.000,2.000,0.000,0.000,4
3752861315.164800,90001.000000,Sweeping up,91.073,92.345,38.191,3.117,0,0,2.000,2.000,0.000,0.000,4
3752861525.164800,90001.000000,Sweeping up,90.185,91.454,38.168,3.116,0,0,2.000,2.000,0.000,0.000,4
3752861735.164800,90000.000000,Sweeping up,89.299,90.564,38.146,3.115,0,0,2.000,2.000,0.000,0.000,4
3752861945.164800,90001.000000,Sweeping up,88.414,89.673,38.121,3.118,0,0,2.000,2.000,0.000,0.000,4
3752862155.164800,90001.000000,Sweeping up,87.527,88.781,38.099,3.117,0,0,2.000,2.000,0.000,0.000,4
3752862365.164800,90001.000000,Sweeping up,86.643,87.892,38.077,3.117,0,0,2.000,2.000,0.000,0.000,4
3752862575.164800,90000.000000,Sweeping up,85.753,86.999,38.053,3.116,0,0,2.000,2.000,0.000,0.000,4
3752862785.164800,90000.000000,Sweeping up,84.869,86.115,38.028,3.118,0,0,2.000,2.000,0.000,0.000,4
3752862995.164800,90000.000000,Sweeping up,83.986,85.228,38.008,3.117,0,0,2.000,2.000,0.000,0.000,4
3752863205.164800,90000.000000,Sweeping up,83.104,84.342,37.987,3.115,0,0,2.000,2.000,0.000,0.000,4
3752863415.164800,90000.000000,Sweeping up,82.222,83.457,37.965,3.117,0,0,2.000,2.000,0.000,0.000,4
3752863625.164800,90000.000000,Sweeping up,81.335,82.565,37.944,3.118,0,0,2.000,2.000,0.000,0.000,4
3752863835.164800,90000.000000,Sweeping up,80.452,81.678,37.926,3.116,0,0,2.000,2.000,0.000,0.000,4
3752864045.164800,90001.000000,Sweeping up,79.568,80.787,37.904,3.117,0,0,2.000,2.000,0.000,0.000,4
3752864255.164800,90000.000000,Sweeping up,78.680,79.882,37.884,3.115,0,0,2.000,2.000,0.000,0.000,4
3752864465.164800,90000.000000,Sweeping up,77.792,78.981,37.862,3.115,0,0,2.000,2.000,0.000,0.000,4
3752864675.164800,90000.000000,Sweeping up,76.902,78.081,37.840,3.115,0,0,2.000,2.000,0.000,0.000,4
3752864885.164800,90001.000000,Sweeping up,76.005,77.175,37.818,3.118,0,0,2.000,2.000,0.000,0.000,4
3752865095.164800,90000.000000,Sweeping up,75.115,76.280,37.799,3.114,0,0,2.000,2.000,0.000,0.000,4
3752865305.164800,90000.000000,Sweeping up,74.222,75.381,37.776,3.114,0,0,2.000,2.000,0.000,0.000,4
3752865515.164800,90000.000000,Sweeping up,73.327,74.476,37.757,3.114,0,0,2.000,2.000,0.000,0.000,4
3752865725.164800,90000.000000,Sweeping up,72.428,73.570,37.738,3.115,0,0,2.000,2.000,0.000,0.000,4
3752865935.164800,90001.000000,Sweeping up,71.526,72.664,37.718,3.113,0,0,2.000,2.000,0.000,0.000,4
3752866145.164800,90000.000000,Sweeping up,70.619,71.750,37.697,3.114,0,0,2.000,2.000,0.000,0.000,4
3752866355.164800,90001.000000,Sweeping up,69.712,70.832,37.675,3.116,0,0,2.000,2.000,0.000,0.000,4
3752866565.164800,90001.000000,Sweeping up,68.802,69.911,37.658,3.113,0,0,2.000,2.000,0.000,0.000,4
3752866775.164800,90001.000000,Sweeping up,67.887,69.001,37.640,3.113,0,0,2.000,2.000,0.000,0.000,4
3752866985.164800,90001.000000,Sweeping up,66.963,68.084,37.619,3.115,0,0,2.000,2.000,0.000,0.000,4
3752867195.164800,90000.000000,Sweeping up,66.038,67.150,37.597,3.116,0,0,2.000,2.000,0.000,0.000,4
3752867405.164800,90000.000000,Sweeping up,65.107,66.188,37.579,3.116,0,0,2.000,2.000,0.000,0.000,4
3752867615.164800,90001.000000,Sweeping up,64.172,65.229,37.559,3.115,0,0,2.000,2.000,0.000,0.000,4
3752867825.164800,90001.000000,Sweeping up,63.230,64.278,37.538,3.114,0,0,2.000,2.000,0.000,0.000,4
3752868035.164800,90001.000000,Sweeping up,62.282,63.326,37.518,3.112,0,0,2.000,2.000,0.000,0.000,4
3752868245.164800,90001.000000,Sweeping up,61.322,62.359,37.497,3.113,0,0,2.000,2.000,0.000,0.000,4
3752868455.164800,90001.000000,Sweeping up,60.358,61.386,37.474,3.115,0,0,2.000,2.000,0.000,0.000,4
3752868665.164800,90001.000000,Sweeping up,59.383,60.406,37.453,3.115,0,0,2.000,2.000,0.000,0.000,4
3752868875.164800,90000.000000,Sweeping up,58.399,59.413,37.433,3.115,0,0,2.000,2.000,0.000,0.000,4
3752869085.164800,90000.000000,Sweeping up,57.405,58.412,37.415,3.111,0,0,2.000,2.000,0.000,0.000,4
3752869295.164800,90000.000000,Sweeping up,56.394,57.392,37.394,3.114,0,0,2.000,2.000,0.000,0.000,4
3752869505.164800,90000.000000,Sweeping up,55.375,56.365,37.375,3.112,0,0,2.000,2.000,0.000,0.000,4
3752869715.164800,90000.000000,Sweeping up,54.343,55.323,37.354,3.114,0,0,2.000,2.000,0.000,0.000,4
3752869925.164800,90000.000000,Sweeping up,53.295,54.263,37.335,3.112,0,0,2.000,2.000,0.000,0.000,4
3752870135.164800,90000.000000,Sweeping up,52.231,53.191,37.315,3.112,0,0,2.000,2.000,0.000,0.000,4
3752870345.164800,90000.000000,Sweeping up,51.142,52.090,37.293,3.109,0,0,2.000,2.000,0.000,0.000,4
3752870555.164800,90000.000000,Sweeping up,50.037,50.974,37.273,3.115,0,0,2.000,2.000,0.000,0.000,4
3752870765.164800,90000.000000,Sweeping up,48.912,49.862,37.255,3.118,0,0,2.000,2.000,0.000,0.000,4
3752870975.164800,90000.000000,Sweeping up,47.763,48.739,37.236,3.115,0,0,2.000,2.000,0.000,0.000,4
3752871185.164800,90000.000000,Sweeping up,46.581,47.555,37.216,3.114,0,0,2.000,2.000,0.000,0.000,4
3752871395.164800,90000.000000,Sweeping up,45.361,46.332,37.194,3.114,0,0,2.000,2.000,0.000,0.000,4
3752871605.164800,90000.000000,Sweeping up,44.109,45.071,37.174,3.112,0,0,2.000,2.000,0.000,0.000,4
3752871815.164800,90000.000000,Sweeping up,42.813,43.758,37.152,3.114,0,0,2.000,2.000,0.000,0.000,4
3752872025.164800,90000.000000,Sweeping up,41.472,42.393,37.131,3.112,0,0,2.000,2.000,0.000,0.000,4
3752872235.164800,90000.000000,Sweeping up,40.070,40.965,37.109,3.115,0,0,2.000,2.000,0.000,0.000,4
3752872445.164800,90000.000000,Sweeping up,38.600,39.465,37.086,3.114,0,0,2.000,2.000,0.000,0.000,4
3752872655.164800,90000.000000,Sweeping up,37.043,37.871,37.062,3.115,0,0,2.000,2.000,0.000,0.000,4
3752872865.164800,90000.000000,Sweeping up,35.398,36.174,37.042,3.115,0,0,2.000,2.000,0.000,0.000,4
3752873075.164800,90000.000000,Sweeping up,33.623,34.351,37.017,3.114,0,0,2.000,2.000,0.000,0.000,4
3752873285.164800,90000.000000,Sweeping up,31.688,32.352,36.992,3.112,0,0,2.000,2.000,0.000,0.000,4
3752873495.164800,90000.000000,Sweeping up,29.535,30.136,36.966,3.116,0,0,2.000,2.000,0.000,0.000,4
3752873705.164800,90000.000000,Sweeping up,27.077,27.579,36.938,3.116,0,0,2.000,2.000,0.000,0.000,4
3752873915.164800,90000.000000,Sweeping up,24.158,24.547,36.912,3.117,0,0,2.000,2.000,0.000,0.000,4
3752874125.164800,90000.000000,Sweeping up,20.484,20.715,36.885,3.115,0,0,2.000,2.000,0.000,0.000,4
3752874335.164800,90000.000000,Sweeping up,15.504,15.527,36.854,3.113,0,0,2.000,2.000,0.000,0.000,4
3752874545.164800,90000.000000,Sweeping up,9.456,9.301,36.819,3.112,0,0,2.000,2.000,0.000,0.000,4
3752874755.164800,90000.000000,Sweeping up,5.859,5.710,36.782,3.114,0,0,2.000,2.000,0.000,0.000,4
3752874965.164800,90000.000000,Sweeping up,4.180,4.071,36.743,3.113,0,0,2.000,2.000,0.000,0.000,4
3752875175.164800,90000.000000,Sweeping up,2.924,2.873,36.701,3.113,0,0,2.000,2.000,0.000,0.000,4
3752875385.164800,90000.000000,Sweeping up,2.026,2.000,36.657,3.112,0,0,2.000,2.000,0.110,0.000,1
3752875595.164800,90000.000000,Sweeping up,2.015,2.000,36.611,3.112,0,0,2.000,2.000,0.230,0.000,1
3752875805.164800,90000.000000,Sweeping up,2.068,2.000,36.562,3.113,0,0,2.000,2.000,0.000,0.010,1
3752876015.164800,90000.000000,Sweeping up,2.065,2.000,36.500,3.112,0,0,2.000,2.000,0.000,0.010,1
3752876225.164800,90001.000000,Sweeping up,2.082,2.000,36.437,3.112,0,0,2.000,2.000,0.130,0.010,1
3752876435.164800,90001.000000,Sweeping up,2.087,2.000,36.382,3.111,0,0,2.000,2.000,0.000,0.010,1
3752876645.164800,90001.000000,Sweeping up,2.066,2.000,36.334,3.110,0,0,2.000,2.000,0.030,0.010,1
3752876855.164800,90000.000000,Sweeping up,2.056,2.001,36.296,3.111,0,0,2.000,2.000,0.070,0.010,1
3752877065.164800,90000.000000,Sweeping up,2.075,2.000,36.266,3.112,0,0,2.000,2.000,0.020,0.010,1
3752877275.164800,90001.000000,Sweeping up,2.072,2.000,36.238,3.111,0,0,2.000,2.000,0.000,0.010,1
3752877485.164800,90000.000000,Sweeping up,2.086,2.000,36.218,3.112,0,0,2.000,2.000,0.000,0.010,1
3752877695.164800,90000.000000,Sweeping up,2.090,2.000,36.201,3.111,0,0,2.000,2.000,0.000,0.010,1
3752877905.164800,90001.000000,Sweeping up,2.086,2.000,36.185,3.111,0,0,2.000,2.000,0.050,0.010,1
3752878115.164800,90000.000000,Sweeping up,2.082,2.000,36.171,3.111,0,0,2.000,2.000,0.230,0.010,1
3752878325.164800,90000.000000,Sweeping up,2.079,2.000,36.160,3.111,0,0,2.000,2.000,0.260,0.010,1
3752878535.164800,90000.000000,Sweeping up,2.074,2.000,36.151,3.111,0,0,2.000,2.000,0.220,0.010,1
3752878745.164800,90000.000000,Sweeping up,2.071,2.000,36.142,3.111,0,0,2.000,2.000,0.060,0.010,1
3752878955.164800,90000.000000,Sweeping up,2.080,2.000,36.133,3.112,0,0,2.000,2.000,0.000,0.010,1
3752879165.164800,90000.000000,Sweeping up,2.089,2.000,36.128,3.110,0,0,2.000,2.000,0.000,0.010,1
3752879375.164800,90000.000000,Sweeping up,2.091,2.000,36.119,3.113,0,0,2.000,2.000,0.000,0.010,1
3752879585.164800,90000.000000,Sweeping up,2.088,1.999,36.115,3.112,0,0,2.000,2.000,0.070,0.010,1
3752879795.164800,90000.000000,Sweeping up,2.089,2.000,36.111,3.111,0,0,2.000,2.000,0.190,0.010,1
3752880005.164800,90000.000000,Sweeping up,2.077,2.000,36.106,3.111,0,0,2.000,2.000,0.260,0.010,1
3752880215.164800,90000.000000,Sweeping up,2.075,2.000,36.102,3.111,0,0,2.000,2.000,0.280,0.010,1
3752880425.164800,90000.000000,Sweeping up,2.069,2.000,36.096,3.110,0,0,2.000,2.000,0.150,0.010,1
3752880635.164800,90000.000000,Sweeping up,2.074,2.000,36.091,3.110,0,0,2.000,2.000,0.000,0.010,1
3752880845.164800,90000.000000,Sweeping up,2.088,2.000,36.088,3.112,0,0,2.000,2.000,0.000,0.010,1
3752881055.164800,90000.000000,Sweeping up,2.093,2.000,36.086,3.111,0,0,2.000,2.000,0.010,0.010,1
3752881265.164800,90000.000000,Sweeping up,2.084,2.000,36.083,3.113,0,0,2.000,2.000,0.220,0.010,1
3752881475.164800,90000.000000,Sweeping up,2.075,2.000,36.081,3.109,0,0,2.000,2.000,0.220,0.010,1
3752881685.164800,90000.000000,Sweeping up,2.072,2.000,36.077,3.111,0,0,2.000,2.000,0.040,0.010,1
3752881895.164800,90000.000000,Sweeping up,2.082,2.000,36.077,3.111,0,0,2.000,2.000,0.000,0.010,1
3752882105.164800,90000.000000,Sweeping up,2.088,2.000,36.072,3.107,0,0,2.000,2.000,0.000,0.010,1
3752882315.164800,90000.000000,Sweeping up,2.091,2.000,36.071,3.110,0,0,2.000,2.000,0.010,0.010,1
3752882525.164800,90000.000000,Sweeping up,2.085,2.000,36.063,3.110,0,0,2.000,2.000,0.210,0.010,1
3752882735.164800,90000.000000,Sweeping up,2.071,2.000,36.058,3.111,0,0,2.000,2.000,0.250,0.010,1
3752882945.164800,90000.000000,Sweeping up,2.073,2.000,36.058,3.109,0,0,2.000,2.000,0.080,0.010,1
3752883155.164800,90000.000000,Sweeping up,2.073,2.000,36.058,3.110,0,0,2.000,2.000,0.000,0.010,1
3752883365.164800,90000.000000,Sweeping up,2.087,2.000,36.057,3.109,0,0,2.000,2.000,0.000,0.010,1
3752883575.164800,90000.000000,Sweeping up,2.088,2.000,36.057,3.109,0,0,2.000,2.000,0.000,0.010,1
3752883785.164800,90000.000000,Sweeping up,2.091,2.000,36.056,3.111,0,0,2.000,2.000,0.000,0.010,1
3752883995.164800,90000.000000,Sweeping up,2.092,2.000,36.054,3.110,0,0,2.000,2.000,0.090,0.010,1
3752884205.164800,90000.000000,Sweeping up,2.075,2.000,36.053,3.111,0,0,2.000,2.000,0.260,0.010,1
3752884415.164800,90000.000000,Sweeping up,2.073,2.000,36.054,3.112,0,0,2.000,2.000,0.200,0.010,1
3752884625.164800,90001.000000,Sweeping up,2.070,2.000,36.057,3.111,0,0,2.000,2.000,0.020,0.010,1
3752884835.164800,90001.000000,Sweeping up,2.076,2.000,36.057,3.111,0,0,2.000,2.000,0.000,0.010,1
3752885045.164800,90001.000000,Sweeping up,2.088,2.000,36.053,3.115,0,0,2.000,2.000,0.000,0.010,1
3752885255.164800,90000.000000,Sweeping up,2.092,2.000,36.053,3.113,0,0,2.000,2.000,0.000,0.010,1
3752885465.164800,90000.000000,Sweeping up,2.084,2.000,36.059,3.110,0,0,2.000,2.000,0.120,0.010,1
3752885675.164800,90000.000000,Sweeping up,2.076,2.000,36.060,3.110,0,0,2.000,2.000,0.250,0.010,1
3752885885.164800,90000.000000,Sweeping up,2.076,2.000,36.062,3.110,0,0,2.000,2.000,0.240,0.010,1
3752886095.164800,90000.000000,Sweeping up,2.071,2.000,36.064,3.111,0,0,2.000,2.000,0.030,0.010,1
3752886305.164800,90000.000000,Sweeping up,2.075,2.000,36.066,3.113,0,0,2.000,2.000,0.000,0.010,1
3752886515.164800,90000.000000,Sweeping up,2.083,2.000,36.067,3.112,0,0,2.000,2.000,0.000,0.010,1
3752886725.164800,90000.000000,Sweeping up,2.085,2.000,36.066,3.113,0,0,2.000,2.000,0.000,0.010,1
3752886935.164800,90000.000000,Sweeping up,2.090,2.000,36.065,3.112,0,0,2.000,2.000,0.020,0.010,1
3752887145.164800,90000.000000,Sweeping up,2.085,2.000,36.068,3.113,0,0,2.000,2.000,0.180,0.010,1
3752887355.164800,78982.000000,Sweeping to zero,2.078,2.000,36.040,3.299,0,0,2.000,2.000,0.180,0.010,1
3752887565.164800,67674.000000,Sweeping to zero,2.093,1.999,35.948,3.327,0,0,2.000,2.000,0.000,0.010,1
3752887775.164800,56300.000000,Sweeping to zero,2.103,2.000,35.822,3.353,0,0,2.000,2.000,0.100,0.010,1
3752887985.164800,36088.000000,Sweeping to zero,2.094,2.000,35.677,3.670,0,0,2.000,2.000,0.250,0.010,1
3752888195.164800,13380.000000,Sweeping to zero,2.100,2.000,35.544,3.828,0,0,2.000,2.000,0.000,0.010,1
3752888405.164800,0.000000,Standby,2.116,2.000,35.449,3.205,0,0,2.000,2.000,0.000,0.020,1
3752888615.164800,0.000000,Standby,2.086,2.001,35.373,3.095,0,0,2.000,2.000,0.120,0.020,1
3752888825.164800,0.000000,Standby,2.097,2.000,35.308,3.092,0,0,2.000,2.000,0.000,0.020,1
3752889035.164800,0.000000,Standby,33.072,32.998,35.235,3.093,1,1,300.000,300.000,7.740,5.470,2
3752889245.164800,0.000000,Standby,67.803,67.752,35.223,3.094,1,1,300.000,300.000,30.220,19.360,2
3752889455.164800,0.000000,Standby,102.556,102.467,35.261,3.095,1,1,300.000,300.000,49.160,32.640,2
3752889665.164800,0.000000,Standby,137.284,137.187,35.339,3.098,1,1,300.000,300.000,63.040,43.110,2
3752889875.164800,0.000000,Standby,172.017,171.939,35.444,3.102,1,1,300.000,300.000,74.130,52.030,2
3752890085.164800,0.000000,Standby,206.758,206.670,35.562,3.102,1,1,300.000,300.000,83.100,59.780,2
3752890295.164800,0.000000,Standby,241.386,241.399,35.692,3.104,1,1,300.000,300.000,90.780,67.290,2
3752890505.164800,0.000000,Standby,272.742,276.083,35.834,3.106,1,1,300.000,300.000,91.020,74.180,2
3752890715.164800,0.000000,Standby,300.175,300.002,35.981,3.108,0,0,300.000,300.000,90.410,46.510,4
3752890925.164800,0.000000,Standby,301.325,300.011,36.108,3.105,0,0,300.000,300.000,67.000,36.200,1
3752891135.164800,0.000000,Standby,301.946,300.014,36.221,3.106,0,0,300.000,300.000,38.990,33.210,4
3752891345.164800,0.000000,Standby,301.536,300.008,36.332,3.104,0,0,300.000,300.000,19.780,31.030,1
3752891555.164800,0.000000,Standby,300.523,300.017,36.449,3.103,0,0,300.000,300.000,14.500,29.100,1
3752891765.164800,0.000000,Standby,299.505,300.015,36.570,3.104,0,0,300.000,300.000,21.330,27.770,1
3752891975.164800,0.000000,Standby,298.928,300.007,36.692,3.107,0,0,300.000,300.000,33.590,26.560,1
3752892185.164800,0.000000,Standby,298.943,300.006,36.814,3.105,0,0,300.000,300.000,44.280,25.870,1
3752892395.164800,0.000000,Standby,299.410,300.006,36.935,3.108,0,0,300.000,300.000,48.050,24.590,1
3752892605.164800,0.000000,Standby,299.969,300.006,37.052,3.108,0,0,300.000,300.000,44.970,23.630,1
3752892815.164800,0.000000,Standby,300.458,300.007,37.170,3.112,0,0,300.000,300.000,37.220,22.680,1
3752893025.164800,0.000000,Standby,300.651,300.007,37.286,3.111,0,0,300.000,300.000,28.370,21.750,1
3752893235.164800,0.000000,Standby,300.536,300.005,37.396,3.113,0,0,300.000,300.000,21.960,20.960,1
3752893445.164800,0.000000,Standby,300.235,300.008,37.503,3.115,0,0,300.000,300.000,19.580,20.160,1
3752893655.164800,0.000000,Standby,299.913,300.007,37.607,3.116,0,0,300.000,300.000,20.830,19.450,1
3752893865.164800,0.000000,Standby,299.701,300.004,37.708,3.118,0,0,300.000,300.000,24.000,18.810,1
3752894075.164800,0.000000,Standby,299.657,300.003,37.807,3.119,0,0,300.000,300.000,27.190,18.280,1
3752894285.164800,0.000000,Standby,299.751,300.003,37.902,3.119,0,0,300.000,300.000,28.900,17.750,1
3752894495.164800,0.000000,Standby,299.925,300.002,37.993,3.121,0,0,300.000,300.000,28.390,17.360,1
3752894705.164800,0.000000,Standby,300.089,300.002,38.081,3.123,0,0,300.000,300.000,26.340,16.910,1
3752894915.164800,0.000000,Standby,300.179,300.001,38.172,3.122,0,0,300.000,300.000,23.520,16.530,1
3752894955.164800,0.000000,Standby,299.928,300.001,38.187,3.122,0,0,300.000,300.000,20.540,16.480,1