File: log/20221121.dat
[Header]
; Displex Transport Data File (default extension .dat)
; Copyright 2016, Hechang LEI, hlei@ruc.edu.cn. All rights reserved.
BYAPP, Displex, 2.0
INFO, 9T mag, Release 2.0.
INFO, Channel 1, Temperature Sensor
INFO, Sample 1 Length (cm): 0.000000; Width (cm): 0.000000; Thickness (cm): 0.000000.

[Data]
Timestamp(s),Field(Oe),Field Status,TempA(K),TempB(K),TempC(K),TempD(K),Ramp1,Ramp2,Setpoint1,Setpoint2,Output1(%),Output2(%),Temp Status
3751869669.331000,,,300.027,300.001,44.468,3.754,0,0,300.000,300.000,27.270,19.860,4
3751870004.669000,,,299.985,300.002,44.645,3.754,0,0,300.000,300.000,26.910,19.610,4
3751870154.669000,,,300.016,300.001,44.724,3.754,0,0,300.000,300.000,27.010,19.520,4
3751870304.669000,,,299.987,300.000,44.802,3.754,0,0,300.000,300.000,26.620,19.420,1
3751870454.669000,,,299.153,298.920,44.880,3.757,1,1,2.000,2.000,9.430,12.530,3
3751870604.669000,,,293.429,293.798,44.953,3.757,1,1,2.000,2.000,21.200,10.090,3
3751870754.669000,,,289.141,288.837,45.018,3.757,1,1,2.000,2.000,7.370,8.850,3
3751870904.669000,,,283.572,283.863,45.077,3.761,1,1,2.000,2.000,16.730,7.770,3
3751871054.669000,,,279.145,278.910,45.135,3.761,1,1,2.000,2.000,6.200,6.810,3
3751871204.669000,,,273.716,273.944,45.190,3.761,1,1,2.000,2.000,12.880,5.840,3
3751871354.669000,,,269.158,268.986,45.244,3.761,1,1,2.000,2.000,5.150,4.970,3
3751871504.669000,,,263.857,264.026,45.296,3.763,1,1,2.000,2.000,9.500,4.090,3
3751871654.669000,,,259.236,259.054,45.348,3.761,1,1,2.000,2.000,9.530,3.270,3
3751871804.669000,,,253.951,254.098,45.395,3.762,1,1,2.000,2.000,1.840,2.510,3
3751871954.669000,,,249.220,249.142,45.439,3.759,1,1,2.000,2.000,6.830,1.790,3
3751872104.669000,,,244.116,244.181,45.476,3.759,1,1,2.000,2.000,0.840,1.110,3
3751872254.669000,,,239.226,239.183,45.507,3.760,1,1,2.000,2.000,4.270,0.830,0
3751872404.669000,,,234.256,234.283,45.534,3.760,1,1,2.000,2.000,0.010,0.000,3
3751872554.669000,,,229.257,229.675,45.561,3.760,1,1,2.000,2.000,1.440,0.000,3
3751872704.669000,,,224.347,225.340,45.587,3.759,1,1,2.000,2.000,0.000,0.000,3
3751872854.669000,,,219.708,221.228,45.609,3.762,1,1,2.000,2.000,0.000,0.000,3
3751873004.669000,,,215.401,217.275,45.632,3.757,1,1,2.000,2.000,0.000,0.000,3
3751873154.669000,,,211.375,213.509,45.647,3.755,1,1,2.000,2.000,0.000,0.000,3
3751873304.669000,,,207.574,209.893,45.657,3.755,1,1,2.000,2.000,0.000,0.000,3
3751873454.669000,,,203.984,206.431,45.663,3.754,1,1,2.000,2.000,0.000,0.000,3
3751873604.669000,,,200.560,203.087,45.665,3.753,1,1,2.000,2.000,0.000,0.000,3
3751873754.669000,,,197.286,199.872,45.665,3.753,1,1,2.000,2.000,0.000,0.000,3
3751873904.669000,,,194.143,196.763,45.663,3.755,1,1,2.000,2.000,0.000,0.000,3
3751874054.669000,,,191.106,193.752,45.660,3.756,1,1,2.000,2.000,0.000,0.000,3
3751874204.669000,,,188.175,190.840,45.656,3.755,1,1,2.000,2.000,0.000,0.000,3
3751874354.669000,,,185.327,188.000,45.649,3.754,1,1,2.000,2.000,0.000,0.000,3
3751874504.669000,,,182.546,185.240,45.637,3.753,1,1,2.000,2.000,0.000,0.000,3
3751874654.669000,,,179.847,182.548,45.621,3.752,1,1,2.000,2.000,0.000,0.000,3
3751874804.669000,,,177.203,179.916,45.599,3.752,1,1,2.000,2.000,0.000,0.000,3
3751874954.669000,,,174.617,177.336,45.577,3.751,1,1,2.000,2.000,0.000,0.000,3
3751875104.673000,,,172.086,174.807,45.552,3.752,1,1,2.000,2.000,0.000,0.000,3
3751875254.673000,,,169.599,172.329,45.525,3.753,1,1,2.000,2.000,0.000,0.000,3
3751875404.673000,,,167.159,169.892,45.499,3.751,1,1,2.000,2.000,0.000,0.000,3
3751875554.673000,,,164.751,167.499,45.471,3.754,1,1,2.000,2.000,0.000,0.000,3
3751875704.673000,,,162.386,165.146,45.441,3.752,1,1,2.000,2.000,0.000,0.000,3
3751875854.673000,,,160.053,162.832,45.406,3.752,1,1,2.000,2.000,0.000,0.000,3
3751876004.673000,,,157.755,160.546,45.364,3.755,1,1,2.000,2.000,0.000,0.000,3
3751876154.673000,,,155.487,158.293,45.317,3.755,1,1,2.000,2.000,0.000,0.000,3
3751876304.673000,,,153.252,156.069,45.270,3.754,1,1,2.000,2.000,0.000,0.000,3
3751876454.673000,,,151.041,153.876,45.226,3.753,1,1,2.000,2.000,0.000,0.000,3
3751876604.673000,,,148.861,151.707,45.182,3.753,1,1,2.000,2.000,0.000,0.000,3
3751876754.673000,,,146.698,149.560,45.136,3.752,1,1,2.000,2.000,0.000,0.000,3
3751876904.673000,,,144.565,147.441,45.092,3.750,1,1,2.000,2.000,0.000,0.000,3
3751877054.673000,,,142.450,145.348,45.045,3.749,1,1,2.000,2.000,0.000,0.000,3
3751877204.673000,,,140.359,143.276,44.994,3.749,1,1,2.000,2.000,0.000,0.000,3
3751877354.673000,,,138.287,141.223,44.938,3.752,1,1,2.000,2.000,0.000,0.000,3
3751877504.673000,,,136.236,139.186,44.878,3.750,1,1,2.000,2.000,0.000,0.000,3
3751877654.673000,,,134.201,137.174,44.818,3.750,1,1,2.000,2.000,0.000,0.000,3
3751877804.673000,,,132.189,135.183,44.758,3.750,1,1,2.000,2.000,0.000,0.000,3
3751877954.673000,,,130.193,133.206,44.701,3.750,1,1,2.000,2.000,0.000,0.000,3
3751878104.673000,,,128.209,131.242,44.644,3.750,1,1,2.000,2.000,0.000,0.000,3
3751878254.673000,,,126.246,129.297,44.589,3.749,1,1,2.000,2.000,0.000,0.000,3
3751878404.673000,,,124.295,127.368,44.529,3.748,1,1,2.000,2.000,0.000,0.000,3
3751878554.673000,,,122.359,125.451,44.464,3.746,1,1,2.000,2.000,0.000,0.000,3
3751878704.673000,,,120.436,123.545,44.394,3.746,1,1,2.000,2.000,0.000,0.000,3
3751878854.673000,,,118.524,121.652,44.320,3.744,1,1,2.000,2.000,0.000,0.000,3
3751879004.673000,,,116.565,119.715,44.770,4.152,1,1,2.000,2.000,0.000,0.000,3
3751879154.673000,,,114.333,117.587,45.668,4.154,1,1,2.000,2.000,0.000,0.000,3
3751879304.673000,,,111.891,115.307,46.347,4.154,1,1,2.000,2.000,0.000,0.000,3
3751879454.673000,,,109.296,112.863,46.756,4.122,0,0,2.000,2.000,0.000,0.000,4
3751879604.673000,,,106.677,110.361,46.759,3.989,0,0,2.000,2.000,0.000,0.000,4
3751879754.673000,,,104.156,107.901,46.518,3.956,0,0,2.000,2.000,0.000,0.000,4
3751879904.673000,,,101.704,105.472,46.267,3.955,0,0,2.000,2.000,0.000,0.000,4
3751880054.673000,,,99.303,103.071,46.050,3.954,0,0,2.000,2.000,0.000,0.000,4
3751880204.673000,,,96.929,100.699,45.865,3.957,0,0,2.000,2.000,0.000,0.000,4
3751880354.673000,,,94.579,98.339,45.702,3.957,0,0,2.000,2.000,0.000,0.000,4
3751880504.673000,,,92.253,95.993,45.557,3.954,0,0,2.000,2.000,0.000,0.000,4
3751880654.673000,,,89.933,93.657,45.424,3.955,0,0,2.000,2.000,0.000,0.000,4
3751880804.673000,,,87.622,91.325,45.301,3.954,0,0,2.000,2.000,0.000,0.000,4
3751880954.673000,,,85.305,88.994,45.185,3.954,0,0,2.000,2.000,0.000,0.000,4
3751881104.673000,,,82.993,86.662,45.074,3.955,0,0,2.000,2.000,0.000,0.000,4
3751881254.673000,,,80.679,84.331,44.966,3.958,0,0,2.000,2.000,0.000,0.000,4
3751881404.673000,,,78.345,81.984,44.855,3.959,0,0,2.000,2.000,0.000,0.000,4
3751881554.673000,,,75.986,79.616,44.748,3.959,0,0,2.000,2.000,0.000,0.000,4
3751881704.673000,,,73.614,77.229,44.642,3.958,0,0,2.000,2.000,0.000,0.000,4
3751881854.673000,,,71.217,74.833,44.535,3.955,0,0,2.000,2.000,0.000,0.000,4
3751882004.673000,,,68.789,72.463,44.429,3.957,0,0,2.000,2.000,0.000,0.000,4
3751882154.673000,,,66.316,70.083,44.322,3.957,0,0,2.000,2.000,0.000,0.000,4
3751882304.673000,,,63.789,67.638,44.215,3.959,0,0,2.000,2.000,0.000,0.000,4
3751882454.673000,,,61.198,65.039,44.105,3.960,0,0,2.000,2.000,0.000,0.000,4
3751882604.673000,,,58.525,62.404,43.994,3.961,0,0,2.000,2.000,0.000,0.000,4
3751882754.673000,,,55.755,59.630,43.882,3.961,0,0,2.000,2.000,0.000,0.000,4
3751882904.673000,,,52.852,56.725,43.770,3.960,0,0,2.000,2.000,0.000,0.000,4
3751883054.673000,,,49.793,53.614,43.656,3.959,0,0,2.000,2.000,0.000,0.000,4
3751883204.673000,,,46.519,50.262,43.537,3.961,0,0,2.000,2.000,0.000,0.000,4
3751883354.673000,,,42.937,46.571,43.410,3.962,0,0,2.000,2.000,0.000,0.000,4
3751883504.673000,,,38.896,42.335,43.278,3.962,0,0,2.000,2.000,0.000,0.000,4
3751883654.673000,,,34.106,37.227,43.140,3.960,0,0,2.000,2.000,0.000,0.000,4
3751883804.673000,,,27.729,30.226,42.993,3.960,0,0,2.000,2.000,0.000,0.000,4
3751883954.673000,,,16.509,16.947,42.827,3.958,0,0,2.000,2.000,0.000,0.000,4
3751884085.639000,,,5.432,4.865,42.657,3.957,0,0,2.000,2.000,0.000,0.000,4
3751884235.639000,,,3.797,3.330,42.407,3.955,0,0,2.000,2.000,0.000,0.000,4
3751884385.639000,,,2.852,2.424,42.145,3.951,0,0,2.000,2.000,0.000,0.000,4
3751884535.639000,,,2.663,2.270,41.915,3.912,0,0,2.000,2.000,0.000,0.000,4
3751884685.639000,,,2.525,2.136,41.658,3.832,0,0,2.000,2.000,0.000,0.000,4
3751884835.639000,,,2.360,2.000,41.322,3.721,0,0,2.000,2.000,0.000,0.000,4
3751884985.639000,,,2.322,2.000,40.879,3.583,0,0,2.000,2.000,0.000,0.010,4
3751885135.639000,,,2.255,2.000,40.323,3.424,0,0,2.000,2.000,0.000,0.010,1
3751885285.639000,,,2.122,1.999,39.704,3.291,0,0,2.000,2.000,0.000,0.010,1
3751885435.639000,,,2.031,2.000,39.077,3.195,0,0,2.000,2.000,0.000,0.020,1
3751885585.639000,,,2.081,2.000,38.500,3.133,0,0,2.000,2.000,0.000,0.020,1
3751885735.639000,,,2.107,2.001,38.003,3.095,0,0,2.000,2.000,0.000,0.020,1
3751885885.639000,,,2.104,2.000,37.596,3.074,0,0,2.000,2.000,0.000,0.020,1
3751886035.639000,,,2.125,2.000,37.275,3.062,0,0,2.000,2.000,0.000,0.020,1
3751886185.639000,,,2.132,2.000,37.020,3.057,0,0,2.000,2.000,0.000,0.020,1
3751886335.639000,,,2.116,2.000,36.818,3.055,0,0,2.000,2.000,0.000,0.020,1
3751886485.639000,,,2.122,1.999,36.655,3.055,0,0,2.000,2.000,0.000,0.020,1
3751886635.639000,,,2.136,2.001,36.522,3.054,0,0,2.000,2.000,0.000,0.020,1
3751886785.639000,,,2.140,1.999,36.412,3.054,0,0,2.000,2.000,0.000,0.020,1
3751886935.639000,,,7.815,7.803,36.302,3.103,1,1,300.000,300.000,0.290,0.450,2
3751887085.639000,,,15.252,15.244,36.065,3.365,1,1,300.000,300.000,1.100,0.930,2
3751887235.639000,,,22.701,22.685,35.829,3.845,1,1,300.000,300.000,2.360,1.630,2
3751887385.639000,,,30.134,30.106,36.356,4.051,1,1,300.000,300.000,3.700,2.240,2
3751887535.639000,,,37.585,37.570,37.144,4.008,1,1,300.000,300.000,5.630,3.220,2
3751887685.639000,,,45.001,44.993,37.655,3.998,1,1,300.000,300.000,7.940,4.500,2
3751887835.639000,,,52.448,52.433,38.049,3.992,1,1,300.000,300.000,10.230,5.820,2
3751887985.639000,,,59.898,59.879,38.379,3.986,1,1,300.000,300.000,12.490,7.180,2
3751888135.639000,,,67.323,67.308,38.662,3.984,1,1,300.000,300.000,14.760,8.410,2
3751888285.639000,,,74.755,74.744,38.909,3.984,1,1,300.000,300.000,16.930,9.750,2
3751888435.639000,,,82.187,82.169,39.128,3.984,1,1,300.000,300.000,18.950,11.170,2
3751888585.639000,,,89.615,89.602,39.324,3.985,1,1,300.000,300.000,20.880,12.310,2
3751888735.639000,,,97.035,97.018,39.506,3.983,1,1,300.000,300.000,22.710,13.650,2
3751888885.639000,,,104.475,104.454,39.674,3.983,1,1,300.000,300.000,24.440,14.750,2
3751889035.639000,,,111.902,111.883,39.831,3.988,1,1,300.000,300.000,26.140,15.900,2
3751889185.639000,,,119.332,119.315,39.982,3.988,1,1,300.000,300.000,27.690,16.990,2
3751889335.639000,,,126.761,126.740,40.129,3.988,1,1,300.000,300.000,29.270,18.100,2
3751889485.639000,,,134.187,134.165,40.273,3.989,1,1,300.000,300.000,30.830,19.170,2
3751889635.639000,,,141.624,141.603,40.413,3.989,1,1,300.000,300.000,32.330,20.210,2
3751889785.639000,,,149.043,149.023,40.551,3.990,1,1,300.000,300.000,33.700,21.200,2
3751889935.639000,,,156.484,156.462,40.686,3.990,1,1,300.000,300.000,35.070,22.240,2
3751890085.639000,,,163.916,163.891,40.822,3.990,1,1,300.000,300.000,36.430,23.150,2
3751890235.639000,,,171.341,171.317,40.959,3.992,1,1,300.000,300.000,37.790,24.110,2
3751890385.639000,,,178.767,178.747,41.097,3.992,1,1,300.000,300.000,39.120,25.060,2
3751890535.639000,,,186.186,186.169,41.235,3.992,1,1,300.000,300.000,40.340,26.050,2
3751890685.639000,,,193.626,193.610,41.374,3.992,1,1,300.000,300.000,41.740,26.880,2
3751890835.639000,,,201.048,201.027,41.515,3.992,1,1,300.000,300.000,42.930,27.860,2
3751890985.639000,,,208.475,208.458,41.656,3.993,1,1,300.000,300.000,44.050,28.880,2
3751891135.639000,,,215.917,215.891,41.800,3.994,1,1,300.000,300.000,45.310,29.830,2
3751891285.639000,,,223.332,223.307,41.942,3.993,1,1,300.000,300.000,46.480,30.750,2
3751891435.639000,,,230.773,230.743,42.085,3.993,1,1,300.000,300.000,47.850,32.350,2
3751891585.639000,,,238.190,238.175,42.227,3.995,1,1,300.000,300.000,48.950,33.570,2
3751891735.639000,,,245.637,245.613,42.373,3.995,1,1,300.000,300.000,50.030,34.560,2
3751891885.639000,,,253.061,253.038,42.516,3.995,1,1,300.000,300.000,51.200,35.610,2
3751892035.639000,,,260.477,260.459,42.661,3.996,1,1,300.000,300.000,52.230,36.730,2
3751892185.639000,,,267.885,267.861,42.810,3.996,1,1,300.000,300.000,53.280,37.550,2
3751892335.639000,,,275.260,275.252,42.958,3.997,1,1,300.000,300.000,54.340,38.570,2
3751892485.639000,,,282.709,282.641,43.107,3.999,1,1,300.000,300.000,63.870,39.610,2
3751892635.639000,,,289.965,290.033,43.256,4.001,1,1,300.000,300.000,49.370,40.560,2
3751892785.639000,,,297.591,297.439,43.406,4.002,1,1,300.000,300.000,63.120,41.590,2
3751892935.639000,,,299.775,300.066,43.555,4.002,0,0,300.000,300.000,48.360,30.860,4
3751893085.639000,,,300.210,300.010,43.700,4.001,0,0,300.000,300.000,34.800,29.160,4
3751893235.639000,,,299.839,300.003,43.842,4.002,0,0,300.000,300.000,44.870,28.460,4
3751893385.639000,,,297.062,297.444,43.982,4.001,1,1,2.000,2.000,28.080,20.420,3
3751893535.639000,,,292.773,292.466,44.119,4.000,1,1,2.000,2.000,25.760,17.730,3
3751893685.639000,,,287.189,287.498,44.252,4.002,1,1,2.000,2.000,23.740,16.130,3
3751893835.639000,,,282.788,282.531,44.381,4.002,1,1,2.000,2.000,21.660,14.690,3
3751893985.639000,,,277.334,277.582,44.509,3.998,1,1,2.000,2.000,20.470,13.330,3
3751894135.639000,,,272.805,272.616,44.636,3.993,1,1,2.000,2.000,18.030,12.090,3
3751894285.639000,,,267.463,267.650,44.758,3.997,1,1,2.000,2.000,17.660,10.910,3
3751894435.639000,,,263.380,262.688,44.875,3.994,1,1,2.000,2.000,19.800,9.810,3
3751894585.639000,,,257.070,257.733,44.990,3.996,1,1,2.000,2.000,10.960,8.760,3
3751894735.649000,,,253.311,252.762,45.101,3.996,1,1,2.000,2.000,14.880,7.770,3
3751894885.649000,,,247.315,247.800,45.208,3.997,1,1,2.000,2.000,10.980,6.820,3
3751895035.649000,,,243.223,242.838,45.309,3.999,1,1,2.000,2.000,10.880,5.980,3
3751895185.649000,,,237.545,237.907,45.406,3.998,1,1,2.000,2.000,9.870,4.850,3
3751895335.649000,,,233.176,232.927,45.498,3.998,1,1,2.000,2.000,7.700,4.350,3
3751895485.649000,,,227.764,227.977,45.588,3.998,1,1,2.000,2.000,8.370,3.590,3
3751895635.649000,,,223.158,223.016,45.671,3.999,1,1,2.000,2.000,5.560,2.850,3
3751895785.649000,,,217.943,218.069,45.749,3.997,1,1,2.000,2.000,6.480,2.200,3
3751895935.649000,,,213.181,213.115,45.823,3.998,1,1,2.000,2.000,3.890,1.550,3
3751896085.649000,,,208.094,208.167,45.889,3.998,1,1,2.000,2.000,4.910,0.940,3
3751896235.649000,,,203.255,203.208,45.953,3.999,1,1,2.000,2.000,1.990,0.380,3
3751896385.649000,,,198.170,198.282,46.010,3.997,1,1,2.000,2.000,3.380,0.000,3
3751896535.649000,,,193.357,193.658,46.064,3.997,1,1,2.000,2.000,0.410,0.000,3
3751896685.649000,,,188.267,189.294,46.112,3.995,1,1,2.000,2.000,1.290,0.000,3
3751896835.649000,,,183.385,185.121,46.154,3.996,1,1,2.000,2.000,0.250,0.000,3
3751896985.649000,,,178.644,181.098,46.193,3.998,1,1,2.000,2.000,0.000,0.000,3
3751897135.649000,,,174.226,177.194,46.224,3.996,1,1,2.000,2.000,0.000,0.000,3
3751897285.649000,,,170.078,173.407,46.252,3.997,1,1,2.000,2.000,0.000,0.000,3
3751897435.649000,,,166.172,169.754,46.274,3.999,1,1,2.000,2.000,0.000,0.000,3
3751897585.649000,,,162.457,166.212,46.292,3.998,1,1,2.000,2.000,0.000,0.000,3
3751897735.649000,,,158.905,162.794,46.305,3.998,1,1,2.000,2.000,0.000,0.000,3
3751897885.649000,,,155.497,159.468,46.314,4.001,1,1,2.000,2.000,0.000,0.000,3
3751898035.649000,,,152.210,156.240,46.319,4.001,1,1,2.000,2.000,0.000,0.000,3
3751898185.649000,,,149.037,153.107,46.319,4.001,1,1,2.000,2.000,0.000,0.000,3
3751898335.649000,,,145.957,150.051,46.315,4.002,1,1,2.000,2.000,0.000,0.000,3
3751898485.649000,,,142.950,147.064,46.307,3.999,1,1,2.000,2.000,0.000,0.000,3
3751898635.649000,,,140.013,144.146,46.294,3.999,1,1,2.000,2.000,0.000,0.000,3
3751898785.649000,,,137.152,141.296,46.278,3.999,1,1,2.000,2.000,0.000,0.000,3
3751898935.649000,,,134.337,138.483,46.259,4.000,1,1,2.000,2.000,0.000,0.000,3
3751899085.649000,,,131.584,135.731,46.236,3.999,1,1,2.000,2.000,0.000,0.000,3
3751899235.649000,,,128.869,133.013,46.209,3.998,1,1,2.000,2.000,0.000,0.000,3
3751899385.649000,,,126.187,130.328,46.178,3.999,1,1,2.000,2.000,0.000,0.000,3
3751899535.649000,,,123.546,127.681,46.143,3.999,1,1,2.000,2.000,0.000,0.000,3
3751899685.649000,,,120.944,125.068,46.104,4.000,1,1,2.000,2.000,0.000,0.000,3
3751899835.649000,,,118.367,122.482,46.060,4.001,1,1,2.000,2.000,0.000,0.000,3
3751899985.649000,,,115.822,119.928,46.011,3.999,1,1,2.000,2.000,0.000,0.000,3
3751900135.649000,,,113.295,117.404,45.961,3.999,1,1,2.000,2.000,0.000,0.000,3
3751900285.649000,,,110.791,114.868,45.905,4.000,1,1,2.000,2.000,0.000,0.000,3
3751900435.649000,,,108.313,112.356,45.845,4.000,1,1,2.000,2.000,0.000,0.000,3
3751900585.649000,,,105.847,109.862,45.782,4.002,1,1,2.000,2.000,0.000,0.000,3
3751900735.649000,,,103.392,107.381,45.714,3.998,1,1,2.000,2.000,0.000,0.000,3
3751900885.649000,,,100.960,104.923,45.645,3.996,1,1,2.000,2.000,0.000,0.000,3
3751901035.649000,,,98.536,102.478,45.576,3.995,1,1,2.000,2.000,0.000,0.000,3
3751901185.649000,,,96.114,100.038,45.503,3.998,1,1,2.000,2.000,0.000,0.000,3
3751901335.649000,,,93.705,97.602,45.428,3.999,1,1,2.000,2.000,0.000,0.000,3
3751901485.649000,,,91.298,95.179,45.353,4.002,1,1,2.000,2.000,0.000,0.000,3
3751901635.649000,,,88.891,92.755,45.273,4.000,1,1,2.000,2.000,0.000,0.000,3
3751901785.649000,,,86.480,90.326,45.195,3.997,1,1,2.000,2.000,0.000,0.000,3
3751901935.649000,,,84.058,87.887,45.115,3.996,1,1,2.000,2.000,0.000,0.000,3
3751902085.649000,,,81.629,85.450,45.032,3.993,1,1,2.000,2.000,0.000,0.000,3
3751902235.649000,,,79.183,82.994,44.946,3.994,1,1,2.000,2.000,0.000,0.000,3
3751902385.649000,,,76.714,80.516,44.859,3.994,0,0,2.000,2.000,0.000,0.000,4
3751902535.649000,,,74.226,78.013,44.770,3.994,0,0,2.000,2.000,0.000,0.000,4
3751902685.649000,,,71.708,75.523,44.678,3.993,0,0,2.000,2.000,0.000,0.000,4
3751902835.649000,,,69.164,73.084,44.583,3.994,0,0,2.000,2.000,0.000,0.000,4
3751902985.649000,,,66.575,70.564,44.488,3.998,0,0,2.000,2.000,0.000,0.000,4
3751903135.649000,,,63.917,67.995,44.389,3.996,0,0,2.000,2.000,0.000,0.000,4
3751903285.649000,,,61.202,65.267,44.289,3.994,0,0,2.000,2.000,0.000,0.000,4
3751903435.649000,,,58.383,62.465,44.182,3.992,0,0,2.000,2.000,0.000,0.000,4
3751903585.649000,,,55.455,59.539,44.072,3.993,0,0,2.000,2.000,0.000,0.000,4
3751903735.649000,,,52.378,56.452,43.958,3.993,0,0,2.000,2.000,0.000,0.000,4
3751903885.649000,,,49.114,53.128,43.839,3.992,0,0,2.000,2.000,0.000,0.000,4
3751904035.649000,,,45.588,49.515,43.714,3.993,0,0,2.000,2.000,0.000,0.000,4
3751904185.649000,,,41.695,45.450,43.585,3.993,0,0,2.000,2.000,0.000,0.000,4
3751904335.649000,,,37.193,40.740,43.448,3.992,0,0,2.000,2.000,0.000,0.000,4
3751904485.649000,,,31.615,34.746,43.302,3.992,0,0,2.000,2.000,0.000,0.000,4
3751904635.649000,,,23.302,25.335,43.138,3.993,0,0,2.000,2.000,0.000,0.000,4
3751904785.649000,,,7.040,6.339,42.950,3.992,0,0,2.000,2.000,0.000,0.000,4
3751904935.649000,,,3.857,3.306,42.707,3.987,0,0,2.000,2.000,0.000,0.000,4
3751905085.652000,,,2.941,2.464,42.443,3.976,0,0,2.000,2.000,0.000,0.000,4
3751905235.652000,,,2.720,2.273,42.201,3.924,0,0,2.000,2.000,0.000,0.000,4
3751905385.652000,,,2.553,2.136,41.909,3.832,0,0,2.000,2.000,0.000,0.000,4
3751905535.652000,,,2.437,2.005,41.523,3.709,0,0,2.000,2.000,0.000,0.000,4
3751905685.652000,,,2.391,1.998,41.016,3.550,0,0,2.000,2.000,0.000,0.000,4
3751905835.652000,,,2.347,1.998,40.405,3.392,0,0,2.000,2.000,0.000,0.000,1
3751905985.652000,,,2.164,2.001,39.745,3.267,0,0,2.000,2.000,0.000,0.020,1
3751906135.652000,,,2.030,2.000,39.095,3.182,0,0,2.000,2.000,0.010,0.020,1
3751906285.652000,,,2.065,2.000,38.509,3.125,0,0,2.000,2.000,0.000,0.020,1
3751906435.652000,,,2.089,2.000,38.013,3.091,0,0,2.000,2.000,0.090,0.020,1
3751906585.652000,,,2.112,2.000,37.610,3.071,0,0,2.000,2.000,0.000,0.020,1
3751906735.652000,,,2.114,2.000,37.293,3.060,0,0,2.000,2.000,0.090,0.020,1
3751906885.652000,,,2.124,2.000,37.042,3.056,0,0,2.000,2.000,0.000,0.020,1
3751907035.652000,,,2.132,2.000,36.843,3.053,0,0,2.000,2.000,0.000,0.020,1
3751907185.652000,,,2.115,2.000,36.682,3.051,0,0,2.000,2.000,0.140,0.020,1
3751907335.652000,,,2.122,2.000,36.549,3.051,0,0,2.000,2.000,0.140,0.020,1
3751907485.652000,,,2.134,1.999,36.441,3.051,0,0,2.000,2.000,0.130,0.020,1
3751907635.652000,,,2.134,2.000,36.346,3.051,0,0,2.000,2.000,0.030,0.020,1
3751907785.652000,,,2.145,1.999,36.264,3.051,0,0,2.000,2.000,0.000,0.020,1
3751907935.652000,,,2.127,2.000,36.192,3.050,0,0,2.000,2.000,0.000,0.020,1
3751908085.652000,,,2.144,2.000,36.128,3.051,0,0,2.000,2.000,0.150,0.020,1
3751908235.652000,,,2.133,2.000,36.068,3.051,0,0,2.000,2.000,0.160,0.020,1
3751908385.652000,,,2.148,2.000,36.013,3.051,0,0,2.000,2.000,0.000,0.020,1
3751908535.652000,,,2.136,2.000,35.963,3.050,0,0,2.000,2.000,0.080,0.020,1
3751908685.652000,,,2.148,2.000,35.918,3.051,0,0,2.000,2.000,0.000,0.020,1
3751908835.652000,,,2.155,2.000,35.873,3.049,0,0,2.000,2.000,0.000,0.020,1
3751908985.652000,,,2.137,2.000,35.833,3.049,0,0,2.000,2.000,0.150,0.020,1
3751909135.652000,,,2.160,2.000,35.794,3.049,0,0,2.000,2.000,0.000,0.020,1
3751909285.652000,,,2.138,2.000,35.757,3.049,0,0,2.000,2.000,0.160,0.020,1
3751909435.652000,,,2.141,2.001,35.724,3.047,0,0,2.000,2.000,0.170,0.020,1
3751909585.652000,,,2.158,2.000,35.692,3.046,0,0,2.000,2.000,0.160,0.020,1
3751909735.652000,,,2.159,2.001,35.662,3.046,0,0,2.000,2.000,0.000,0.020,1
3751909885.652000,,,2.158,2.000,35.633,3.045,0,0,2.000,2.000,0.000,0.020,1
3751910035.652000,,,2.145,1.999,35.605,3.045,0,0,2.000,2.000,0.000,0.020,1
3751910185.652000,,,2.146,2.000,35.578,3.045,0,0,2.000,2.000,0.060,0.020,1
3751910335.652000,,,2.167,2.000,35.551,3.044,0,0,2.000,2.000,0.000,0.020,1
3751910485.652000,,,2.145,2.000,35.529,3.044,0,0,2.000,2.000,0.180,0.020,1
3751910635.652000,,,2.154,2.000,35.508,3.043,0,0,2.000,2.000,0.180,0.020,1
3751910785.652000,,,2.167,2.001,35.486,3.044,0,0,2.000,2.000,0.000,0.020,1
3751910935.652000,,,2.146,2.000,35.465,3.043,0,0,2.000,2.000,0.120,0.020,1
3751911085.652000,,,2.171,1.999,35.446,3.043,0,0,2.000,2.000,0.000,0.020,1
3751911235.652000,,,2.168,2.000,35.429,3.042,0,0,2.000,2.000,0.000,0.020,1
3751911385.652000,,,2.146,2.000,35.413,3.041,0,0,2.000,2.000,0.180,0.020,1
3751911535.652000,,,2.173,1.999,35.399,3.041,0,0,2.000,2.000,0.000,0.020,1
3751911685.652000,,,2.160,2.000,35.385,3.040,0,0,2.000,2.000,0.000,0.020,1
3751911835.652000,,,2.149,2.000,35.374,3.039,0,0,2.000,2.000,0.000,0.020,1
3751911985.652000,,,2.152,2.000,35.361,3.039,0,0,2.000,2.000,0.000,0.020,1
3751912135.652000,,,2.171,1.999,35.349,3.039,0,0,2.000,2.000,0.000,0.020,1
3751912285.652000,,,2.174,2.001,35.338,3.039,0,0,2.000,2.000,0.000,0.020,1
3751912435.652000,,,2.169,2.000,35.327,3.039,0,0,2.000,2.000,0.000,0.020,1
3751912585.652000,,,2.153,2.000,35.316,3.039,0,0,2.000,2.000,0.030,0.020,1
3751912735.652000,,,2.150,2.000,35.306,3.040,0,0,2.000,2.000,0.010,0.020,1
3751912885.652000,,,2.161,2.001,35.299,3.040,0,0,2.000,2.000,0.000,0.020,1
3751913035.652000,,,2.168,2.001,35.291,3.041,0,0,2.000,2.000,0.090,0.020,1
3751913185.652000,,,2.163,2.000,35.283,3.041,0,0,2.000,2.000,0.000,0.020,1
3751913335.652000,,,2.174,1.999,35.277,3.040,0,0,2.000,2.000,0.000,0.020,1
3751913485.652000,,,2.176,2.000,35.272,3.039,0,0,2.000,2.000,0.000,0.020,1
3751913635.652000,,,2.176,1.999,35.264,3.039,0,0,2.000,2.000,0.000,0.020,1
3751913785.652000,,,2.174,1.999,35.258,3.038,0,0,2.000,2.000,0.000,0.020,1
3751913935.652000,,,2.177,2.000,35.251,3.039,0,0,2.000,2.000,0.060,0.020,1
3751914085.652000,,,2.178,2.000,35.245,3.039,0,0,2.000,2.000,0.000,0.020,1
3751914235.652000,,,2.169,2.000,35.239,3.040,0,0,2.000,2.000,0.150,0.020,1
3751914385.652000,,,2.175,2.001,35.237,3.041,0,0,2.000,2.000,0.000,0.020,1
3751914535.652000,,,2.179,1.999,35.231,3.042,0,0,2.000,2.000,0.000,0.020,1
3751914685.652000,,,2.177,2.000,35.231,3.039,0,0,2.000,2.000,0.000,0.020,1
3751914835.652000,,,2.178,2.000,35.229,3.040,0,0,2.000,2.000,0.000,0.020,1
3751914985.652000,,,2.173,2.000,35.226,3.040,0,0,2.000,2.000,0.100,0.020,1
3751915135.652000,,,2.157,2.000,35.223,3.039,0,0,2.000,2.000,0.120,0.020,1
3751915285.652000,,,2.163,2.000,35.220,3.039,0,0,2.000,2.000,0.000,0.020,1
3751915435.652000,,,2.171,2.000,35.219,3.038,0,0,2.000,2.000,0.060,0.020,1
3751915585.652000,,,2.153,1.999,35.216,3.038,0,0,2.000,2.000,0.090,0.020,1
3751915735.652000,,,2.154,2.000,35.214,3.039,0,0,2.000,2.000,0.110,0.020,1
3751915885.652000,,,2.163,2.000,35.210,3.038,0,0,2.000,2.000,0.000,0.020,1
3751916035.652000,,,2.151,2.000,35.210,3.038,0,0,2.000,2.000,0.170,0.020,1
3751916185.652000,,,2.158,2.000,35.208,3.038,0,0,2.000,2.000,0.000,0.020,1
3751916335.652000,,,2.170,2.000,35.205,3.037,0,0,2.000,2.000,0.000,0.020,1
3751916485.652000,,,2.176,2.001,35.204,3.037,0,0,2.000,2.000,0.000,0.020,1
3751916635.652000,,,2.169,2.000,35.204,3.038,0,0,2.000,2.000,0.000,0.020,1
3751916785.652000,,,2.174,2.000,35.202,3.037,0,0,2.000,2.000,0.000,0.020,1
3751916935.652000,,,2.178,2.000,35.202,3.035,0,0,2.000,2.000,0.010,0.020,1
3751917085.652000,,,2.180,2.000,35.200,3.035,0,0,2.000,2.000,0.000,0.020,1
3751917235.652000,,,2.171,2.001,35.198,3.035,0,0,2.000,2.000,0.000,0.020,1
3751917385.652000,,,2.151,2.000,35.195,3.035,0,0,2.000,2.000,0.180,0.020,1
3751917535.652000,,,2.159,2.000,35.195,3.035,0,0,2.000,2.000,0.000,0.020,1
3751917685.652000,,,2.156,2.001,35.196,3.035,0,0,2.000,2.000,0.000,0.020,1
3751917835.652000,,,2.154,2.000,35.193,3.037,0,0,2.000,2.000,0.050,0.020,1
3751917985.652000,,,2.155,2.000,35.192,3.036,0,0,2.000,2.000,0.170,0.020,1
3751918135.652000,,,2.156,2.000,35.193,3.037,0,0,2.000,2.000,0.000,0.020,1
3751918285.652000,,,2.164,2.000,35.193,3.036,0,0,2.000,2.000,0.000,0.020,1
3751918435.652000,,,2.159,2.000,35.194,3.037,0,0,2.000,2.000,0.180,0.020,1
3751918585.652000,,,2.155,2.000,35.193,3.036,0,0,2.000,2.000,0.120,0.020,1
3751918735.652000,,,2.152,2.001,35.193,3.038,0,0,2.000,2.000,0.000,0.020,1
3751918885.652000,,,2.166,2.000,35.194,3.036,0,0,2.000,2.000,0.000,0.020,1
3751919035.652000,,,2.169,2.000,35.192,3.037,0,0,2.000,2.000,0.000,0.020,1
3751919185.652000,,,2.169,2.000,35.192,3.037,0,0,2.000,2.000,0.150,0.020,1
3751919335.652000,,,2.159,2.000,35.191,3.037,0,0,2.000,2.000,0.140,0.020,1
3751919485.652000,,,2.171,2.000,35.190,3.037,0,0,2.000,2.000,0.000,0.020,1
3751919635.652000,,,2.170,2.001,35.189,3.037,0,0,2.000,2.000,0.000,0.020,1
3751919785.652000,,,2.174,2.000,35.189,3.037,0,0,2.000,2.000,0.000,0.020,1
3751919935.652000,,,2.169,2.000,35.189,3.037,0,0,2.000,2.000,0.180,0.020,1
3751920085.652000,,,2.159,2.000,35.190,3.037,0,0,2.000,2.000,0.110,0.020,1
3751920235.652000,,,2.164,2.000,35.192,3.036,0,0,2.000,2.000,0.050,0.020,1
3751920385.652000,,,2.177,2.000,35.192,3.034,0,0,2.000,2.000,0.000,0.020,1
3751920535.652000,,,2.178,1.999,35.191,3.035,0,0,2.000,2.000,0.000,0.020,1
3751920685.652000,,,2.174,2.000,35.191,3.035,0,0,2.000,2.000,0.000,0.020,1
3751920835.652000,,,2.153,2.001,35.190,3.036,0,0,2.000,2.000,0.190,0.020,1
3751920985.652000,,,2.160,2.000,35.191,3.035,0,0,2.000,2.000,0.000,0.020,1
3751921135.652000,,,2.161,2.000,35.190,3.036,0,0,2.000,2.000,0.000,0.020,1
3751921285.652000,,,2.167,2.000,35.189,3.036,0,0,2.000,2.000,0.010,0.020,1
3751921435.652000,,,2.155,2.000,35.187,3.037,0,0,2.000,2.000,0.180,0.020,1
3751921585.652000,,,2.155,2.000,35.186,3.037,0,0,2.000,2.000,0.000,0.020,1
3751921735.652000,,,2.171,2.001,35.184,3.038,0,0,2.000,2.000,0.000,0.020,1
3751921885.652000,,,2.169,2.000,35.184,3.038,0,0,2.000,2.000,0.150,0.020,1
3751922035.652000,,,2.164,2.000,35.184,3.038,0,0,2.000,2.000,0.000,0.020,1
3751922185.652000,,,2.175,2.000,35.185,3.038,0,0,2.000,2.000,0.000,0.020,1
3751922335.652000,,,2.177,2.000,35.186,3.037,0,0,2.000,2.000,0.000,0.020,1
3751922485.652000,,,2.170,2.000,35.185,3.037,0,0,2.000,2.000,0.000,0.020,1
3751922635.652000,,,2.176,2.000,35.186,3.037,0,0,2.000,2.000,0.130,0.020,1
3751922785.652000,,,2.164,2.000,35.187,3.037,0,0,2.000,2.000,0.000,0.020,1
3751922935.652000,,,2.179,1.999,35.186,3.037,0,0,2.000,2.000,0.000,0.020,1
3751923085.652000,,,2.168,1.999,35.185,3.038,0,0,2.000,2.000,0.180,0.020,1
3751923235.652000,,,2.170,2.000,35.186,3.038,0,0,2.000,2.000,0.000,0.020,1
3751923385.652000,,,2.176,2.000,35.185,3.039,0,0,2.000,2.000,0.000,0.020,1
3751923535.652000,,,2.176,2.000,35.186,3.038,0,0,2.000,2.000,0.000,0.020,1
3751923685.652000,,,2.156,1.999,35.188,3.038,0,0,2.000,2.000,0.130,0.020,1
3751923835.652000,,,2.156,2.000,35.188,3.038,0,0,2.000,2.000,0.190,0.020,1
3751923985.652000,,,2.152,2.000,35.186,3.037,0,0,2.000,2.000,0.000,0.020,1
3751924135.652000,,,2.160,2.001,35.187,3.037,0,0,2.000,2.000,0.000,0.020,1
3751924285.652000,,,2.151,2.000,35.186,3.037,0,0,2.000,2.000,0.000,0.020,1
3751924435.652000,,,2.169,1.999,35.186,3.038,0,0,2.000,2.000,0.000,0.020,1
3751924585.652000,,,2.177,2.001,35.185,3.038,0,0,2.000,2.000,0.030,0.020,1
3751924735.652000,,,2.170,1.999,35.186,3.038,0,0,2.000,2.000,0.000,0.020,1
3751924885.652000,,,2.177,1.999,35.188,3.038,0,0,2.000,2.000,0.120,0.020,1
3751925035.652000,,,2.175,2.000,35.187,3.039,0,0,2.000,2.000,0.000,0.020,1
3751925185.652000,,,2.178,2.000,35.187,3.039,0,0,2.000,2.000,0.000,0.020,1
3751925335.652000,,,2.169,2.000,35.186,3.038,0,0,2.000,2.000,0.140,0.020,1
3751925485.652000,,,2.154,1.999,35.185,3.040,0,0,2.000,2.000,0.000,0.020,1
3751925635.652000,,,2.171,2.000,35.185,3.040,0,0,2.000,2.000,0.120,0.020,1
3751925785.652000,,,2.173,2.000,35.186,3.040,0,0,2.000,2.000,0.000,0.020,1
3751925935.652000,,,2.162,2.000,35.187,3.039,0,0,2.000,2.000,0.180,0.020,1
3751926085.652000,,,2.153,2.000,35.189,3.037,0,0,2.000,2.000,0.140,0.020,1
3751926235.652000,,,2.150,2.000,35.188,3.037,0,0,2.000,2.000,0.000,0.020,1
3751926385.652000,,,2.154,2.001,35.186,3.038,0,0,2.000,2.000,0.160,0.020,1
3751926535.652000,,,2.160,2.001,35.186,3.037,0,0,2.000,2.000,0.000,0.020,1
3751926685.652000,,,2.168,2.000,35.186,3.036,0,0,2.000,2.000,0.000,0.020,1
3751926835.652000,,,2.176,2.000,35.185,3.037,0,0,2.000,2.000,0.040,0.020,1
3751926985.652000,,,2.168,2.000,35.183,3.038,0,0,2.000,2.000,0.000,0.020,1
3751927135.652000,,,2.177,2.000,35.180,3.038,0,0,2.000,2.000,0.000,0.020,1
3751927285.652000,,,2.164,2.000,35.178,3.038,0,0,2.000,2.000,0.170,0.020,1
3751927435.652000,,,2.153,2.000,35.177,3.039,0,0,2.000,2.000,0.090,0.020,1
3751927585.652000,,,2.153,1.999,35.176,3.039,0,0,2.000,2.000,0.100,0.020,1
3751927735.652000,,,2.156,2.000,35.176,3.039,0,0,2.000,2.000,0.000,0.020,1
3751927885.652000,,,2.176,2.000,35.176,3.039,0,0,2.000,2.000,0.000,0.020,1
3751928035.652000,,,2.178,2.000,35.177,3.038,0,0,2.000,2.000,0.000,0.020,1
3751928185.652000,,,2.179,2.000,35.179,3.039,0,0,2.000,2.000,0.000,0.020,1
3751928335.652000,,,2.162,1.999,35.181,3.038,0,0,2.000,2.000,0.180,0.020,1
3751928485.652000,,,2.151,2.000,35.182,3.039,0,0,2.000,2.000,0.000,0.020,1
3751928635.652000,,,2.161,1.999,35.181,3.039,0,0,2.000,2.000,0.000,0.020,1
3751928785.652000,,,2.178,2.000,35.181,3.039,0,0,2.000,2.000,0.000,0.020,1
3751928935.652000,,,2.172,1.999,35.182,3.038,0,0,2.000,2.000,0.130,0.020,1
3751929085.652000,,,2.163,1.999,35.182,3.039,0,0,2.000,2.000,0.010,0.020,1
3751929235.652000,,,2.171,2.000,35.181,3.039,0,0,2.000,2.000,0.000,0.020,1
3751929385.652000,,,2.155,2.000,35.182,3.037,0,0,2.000,2.000,0.190,0.020,1
3751929535.652000,,,2.153,2.000,35.183,3.037,0,0,2.000,2.000,0.000,0.020,1
3751929685.652000,,,2.160,2.000,35.184,3.037,0,0,2.000,2.000,0.090,0.020,1
3751929835.652000,,,2.166,2.000,35.185,3.037,0,0,2.000,2.000,0.170,0.020,1
3751929985.652000,,,2.161,2.000,35.185,3.037,0,0,2.000,2.000,0.170,0.020,1
3751930135.652000,,,2.158,2.000,35.185,3.038,0,0,2.000,2.000,0.000,0.020,1
3751930285.652000,,,2.178,2.000,35.187,3.038,0,0,2.000,2.000,0.000,0.020,1
3751930435.652000,,,2.179,2.000,35.187,3.038,0,0,2.000,2.000,0.000,0.020,1
3751930585.652000,,,2.163,2.000,35.187,3.039,0,0,2.000,2.000,0.000,0.020,1
3751930735.652000,,,2.160,2.000,35.187,3.039,0,0,2.000,2.000,0.000,0.020,1
3751930885.652000,,,2.157,2.000,35.186,3.039,0,0,2.000,2.000,0.010,0.020,1
3751931035.652000,,,2.179,2.001,35.187,3.039,0,0,2.000,2.000,0.040,0.020,1
3751931185.652000,,,2.156,2.000,35.188,3.039,0,0,2.000,2.000,0.170,0.020,1
3751931335.652000,,,2.157,2.000,35.188,3.038,0,0,2.000,2.000,0.050,0.020,1
3751931485.652000,,,2.173,2.000,35.190,3.037,0,0,2.000,2.000,0.090,0.020,1
3751931635.652000,,,2.174,2.000,35.190,3.037,0,0,2.000,2.000,0.000,0.020,1
3751931785.652000,,,2.171,2.000,35.190,3.038,0,0,2.000,2.000,0.160,0.020,1
3751931935.652000,,,2.152,2.000,35.190,3.039,0,0,2.000,2.000,0.000,0.020,1
3751932085.652000,,,2.155,2.000,35.189,3.039,0,0,2.000,2.000,0.000,0.020,1
3751932235.652000,,,2.169,2.001,35.191,3.038,0,0,2.000,2.000,0.000,0.020,1
3751932385.652000,,,2.167,2.000,35.191,3.038,0,0,2.000,2.000,0.020,0.020,1
3751932535.652000,,,2.175,2.000,35.191,3.039,0,0,2.000,2.000,0.150,0.020,1
3751932685.652000,,,2.154,2.000,35.192,3.039,0,0,2.000,2.000,0.180,0.020,1
3751932835.652000,,,2.155,2.000,35.191,3.039,0,0,2.000,2.000,0.000,0.020,1
3751932985.652000,,,2.175,2.000,35.191,3.039,0,0,2.000,2.000,0.000,0.020,1
3751933135.652000,,,2.177,2.000,35.192,3.039,0,0,2.000,2.000,0.020,0.020,1
3751933285.652000,,,2.173,2.000,35.192,3.039,0,0,2.000,2.000,0.000,0.020,1
3751933435.652000,,,2.173,2.000,35.190,3.039,0,0,2.000,2.000,0.000,0.020,1
3751933585.652000,,,2.154,2.000,35.189,3.040,0,0,2.000,2.000,0.150,0.020,1
3751933735.652000,,,2.162,2.000,35.187,3.039,0,0,2.000,2.000,0.000,0.020,1
3751933885.652000,,,2.168,2.000,35.186,3.040,0,0,2.000,2.000,0.000,0.020,1
3751934035.652000,,,2.165,2.000,35.186,3.041,0,0,2.000,2.000,0.100,0.020,1
3751934185.652000,,,2.178,1.999,35.186,3.042,0,0,2.000,2.000,0.000,0.020,1
3751934335.652000,,,2.156,2.000,35.188,3.042,0,0,2.000,2.000,0.130,0.020,1
3751934485.652000,,,2.165,2.001,35.188,3.045,0,0,2.000,2.000,0.000,0.020,1
3751934635.652000,,,2.158,2.001,35.190,3.042,0,0,2.000,2.000,0.110,0.020,1
3751934785.652000,,,2.160,2.000,35.190,3.042,0,0,2.000,2.000,0.130,0.020,1
3751934935.652000,,,2.173,1.999,35.192,3.041,0,0,2.000,2.000,0.000,0.020,1
3751935085.652000,,,2.171,2.000,35.196,3.040,0,0,2.000,2.000,0.000,0.020,1
3751935235.652000,,,2.151,2.000,35.194,3.040,0,0,2.000,2.000,0.000,0.020,1
3751935385.652000,,,2.154,2.000,35.198,3.039,0,0,2.000,2.000,0.100,0.020,1
3751935535.652000,,,2.178,2.000,35.200,3.040,0,0,2.000,2.000,0.000,0.020,1
3751935685.652000,,,2.170,1.999,35.199,3.040,0,0,2.000,2.000,0.090,0.020,1
3751935835.652000,,,2.152,1.999,35.199,3.039,0,0,2.000,2.000,0.000,0.020,1
3751935985.652000,,,2.152,2.000,35.199,3.039,0,0,2.000,2.000,0.190,0.020,1
3751936135.652000,,,2.168,2.000,35.196,3.040,0,0,2.000,2.000,0.000,0.020,1
3751936285.652000,,,2.171,1.999,35.195,3.040,0,0,2.000,2.000,0.030,0.020,1
3751936435.652000,,,2.152,2.001,35.194,3.039,0,0,2.000,2.000,0.090,0.020,1
3751936585.652000,,,2.158,2.000,35.193,3.039,0,0,2.000,2.000,0.020,0.020,1
3751936735.652000,,,2.176,2.000,35.189,3.039,0,0,2.000,2.000,0.000,0.020,1
3751936885.652000,,,2.175,2.000,35.186,3.040,0,0,2.000,2.000,0.000,0.020,1
3751937035.652000,,,2.171,1.999,35.184,3.040,0,0,2.000,2.000,0.000,0.020,1
3751937185.652000,,,2.154,1.999,35.184,3.038,0,0,2.000,2.000,0.020,0.020,1
3751937335.652000,,,2.161,2.001,35.184,3.038,0,0,2.000,2.000,0.000,0.020,1
3751937485.652000,,,2.174,1.999,35.185,3.037,0,0,2.000,2.000,0.000,0.020,1
3751937635.652000,,,2.177,2.000,35.184,3.038,0,0,2.000,2.000,0.000,0.020,1
3751937785.652000,,,2.173,2.000,35.185,3.037,0,0,2.000,2.000,0.120,0.020,1
3751937935.652000,,,2.175,1.999,35.185,3.037,0,0,2.000,2.000,0.000,0.020,1
3751938085.652000,,,2.172,2.000,35.186,3.037,0,0,2.000,2.000,0.090,0.020,1
3751938235.652000,,,2.151,2.001,35.189,3.037,0,0,2.000,2.000,0.000,0.020,1
3751938385.652000,,,2.155,2.001,35.190,3.036,0,0,2.000,2.000,0.000,0.020,1
3751938535.652000,,,2.165,2.000,35.189,3.037,0,0,2.000,2.000,0.000,0.020,1
3751938685.652000,,,2.169,2.001,35.190,3.038,0,0,2.000,2.000,0.150,0.020,1
3751938835.652000,,,2.153,2.000,35.189,3.038,0,0,2.000,2.000,0.050,0.020,1
3751938985.652000,,,2.178,2.000,35.193,3.038,0,0,2.000,2.000,0.000,0.020,1
3751939135.652000,,,2.173,2.000,35.194,3.037,0,0,2.000,2.000,0.000,0.020,1
3751939285.652000,,,2.171,2.000,35.195,3.038,0,0,2.000,2.000,0.000,0.020,1
3751939435.652000,,,2.168,2.000,35.195,3.037,0,0,2.000,2.000,0.180,0.020,1
3751939585.652000,,,2.151,2.001,35.198,3.037,0,0,2.000,2.000,0.000,0.020,1
3751939735.652000,,,2.169,2.001,35.199,3.036,0,0,2.000,2.000,0.000,0.020,1
3751939885.652000,,,2.178,2.000,35.198,3.036,0,0,2.000,2.000,0.000,0.020,1
3751940035.652000,,,2.179,2.000,35.196,3.035,0,0,2.000,2.000,0.000,0.020,1
3751940185.652000,,,2.155,1.999,35.197,3.036,0,0,2.000,2.000,0.000,0.020,1
3751940335.652000,,,2.168,2.000,35.196,3.036,0,0,2.000,2.000,0.000,0.020,1
3751940485.652000,,,2.177,2.000,35.194,3.037,0,0,2.000,2.000,0.110,0.020,1
3751940635.652000,,,2.171,1.999,35.194,3.037,0,0,2.000,2.000,0.000,0.020,1
3751940785.652000,,,2.151,2.000,35.194,3.039,0,0,2.000,2.000,0.000,0.020,1
3751940935.652000,,,2.165,2.001,35.196,3.038,0,0,2.000,2.000,0.010,0.020,1
3751941085.652000,,,2.169,2.000,35.197,3.037,0,0,2.000,2.000,0.030,0.020,1
3751941235.652000,,,2.172,2.000,35.196,3.039,0,0,2.000,2.000,0.000,0.020,1
3751941385.652000,,,2.176,2.001,35.196,3.039,0,0,2.000,2.000,0.000,0.020,1
3751941535.652000,,,2.172,2.000,35.197,3.040,0,0,2.000,2.000,0.010,0.020,1
3751941685.652000,,,2.156,2.000,35.196,3.041,0,0,2.000,2.000,0.090,0.020,1
3751941835.652000,,,2.166,2.000,35.194,3.042,0,0,2.000,2.000,0.000,0.020,1
3751941985.652000,,,2.176,2.000,35.195,3.041,0,0,2.000,2.000,0.000,0.020,1
3751942135.652000,,,2.163,2.001,35.194,3.042,0,0,2.000,2.000,0.000,0.020,1
3751942285.652000,,,2.154,2.001,35.190,3.042,0,0,2.000,2.000,0.150,0.020,1
3751942435.652000,,,2.178,2.000,35.188,3.041,0,0,2.000,2.000,0.000,0.020,1
3751942585.652000,,,2.154,2.000,35.188,3.038,0,0,2.000,2.000,0.030,0.020,1
3751942735.652000,,,2.154,1.999,35.188,3.039,0,0,2.000,2.000,0.140,0.020,1
3751942885.652000,,,2.165,2.000,35.185,3.040,0,0,2.000,2.000,0.000,0.020,1
3751943035.652000,,,2.177,2.000,35.184,3.039,0,0,2.000,2.000,0.000,0.020,1
3751943185.652000,,,2.158,2.000,35.182,3.040,0,0,2.000,2.000,0.000,0.020,1
3751943335.652000,,,2.154,2.001,35.181,3.041,0,0,2.000,2.000,0.170,0.020,1
3751943485.652000,,,2.165,2.000,35.182,3.040,0,0,2.000,2.000,0.000,0.020,1
3751943635.652000,,,2.178,2.000,35.182,3.040,0,0,2.000,2.000,0.000,0.020,1
3751943785.652000,,,2.179,2.000,35.183,3.041,0,0,2.000,2.000,0.000,0.020,1
3751943935.652000,,,2.153,2.001,35.181,3.039,0,0,2.000,2.000,0.000,0.020,1
3751944085.652000,,,2.177,2.000,35.181,3.038,0,0,2.000,2.000,0.000,0.020,1
3751944235.652000,,,2.170,2.000,35.178,3.039,0,0,2.000,2.000,0.000,0.020,1
3751944385.652000,,,2.158,1.999,35.177,3.038,0,0,2.000,2.000,0.040,0.020,1
3751944535.652000,,,2.168,2.000,35.175,3.039,0,0,2.000,2.000,0.000,0.020,1
3751944685.652000,,,2.163,2.000,35.176,3.038,0,0,2.000,2.000,0.170,0.020,1
3751944835.652000,,,2.157,2.000,35.178,3.039,0,0,2.000,2.000,0.170,0.020,1
3751944985.652000,,,2.168,2.000,35.179,3.039,0,0,2.000,2.000,0.000,0.020,1
3751945135.652000,,,2.176,2.000,35.179,3.039,0,0,2.000,2.000,0.080,0.020,1
3751945285.652000,,,2.153,2.000,35.180,3.039,0,0,2.000,2.000,0.000,0.020,1
3751945435.652000,,,2.168,2.000,35.181,3.038,0,0,2.000,2.000,0.140,0.020,1
3751945585.652000,,,2.164,2.000,35.178,3.040,0,0,2.000,2.000,0.000,0.020,1
3751945735.652000,,,2.174,2.000,35.175,3.041,0,0,2.000,2.000,0.000,0.020,1
3751945885.652000,,,2.175,2.000,35.173,3.042,0,0,2.000,2.000,0.000,0.020,1
3751946035.652000,,,2.178,2.000,35.175,3.039,0,0,2.000,2.000,0.090,0.020,1
3751946185.652000,,,2.178,2.000,35.174,3.042,0,0,2.000,2.000,0.000,0.020,1
3751946335.652000,,,2.180,2.000,35.172,3.039,0,0,2.000,2.000,0.000,0.020,1
3751946485.652000,,,2.179,2.000,35.173,3.040,0,0,2.000,2.000,0.040,0.020,1
3751946635.652000,,,2.179,2.001,35.171,3.039,0,0,2.000,2.000,0.000,0.020,1
3751946785.652000,,,2.172,2.000,35.167,3.041,0,0,2.000,2.000,0.180,0.020,1
3751946935.652000,,,2.159,2.000,35.164,3.039,0,0,2.000,2.000,0.130,0.020,1
3751947085.652000,,,2.152,2.000,35.161,3.039,0,0,2.000,2.000,0.150,0.020,1
3751947235.652000,,,2.155,2.000,35.161,3.040,0,0,2.000,2.000,0.000,0.020,1
3751947385.652000,,,2.157,2.000,35.161,3.040,0,0,2.000,2.000,0.000,0.020,1
3751947535.652000,,,2.178,2.000,35.162,3.040,0,0,2.000,2.000,0.000,0.020,1
3751947685.652000,,,2.180,2.001,35.162,3.042,0,0,2.000,2.000,0.000,0.020,1
3751947835.652000,,,2.178,2.000,35.163,3.041,0,0,2.000,2.000,0.010,0.020,1
3751947985.652000,,,2.163,2.000,35.163,3.040,0,0,2.000,2.000,0.000,0.020,1
3751948015.652000,,,2.179,1.999,35.162,3.039,0,0,2.000,2.000,0.070,0.020,1