File: log/20221122.dat
[Header]
; Displex Transport Data File (default extension .dat)
; Copyright 2016, Hechang LEI, hlei@ruc.edu.cn. All rights reserved.
BYAPP, Displex, 2.0
INFO, 9T mag, Release 2.0.
INFO, Channel 1, Temperature Sensor
INFO, Sample 1 Length (cm): 0.000000; Width (cm): 0.000000; Thickness (cm): 0.000000.

[Data]
Timestamp(s),Field(Oe),Field Status,TempA(K),TempB(K),TempC(K),TempD(K),Ramp1,Ramp2,Setpoint1,Setpoint2,Output1(%),Output2(%),Temp Status
3751948075.451000,,,2.166,2.001,35.160,3.039,0,0,2.000,2.000,0.000,0.020,1
3751948135.451000,,,2.153,2.000,35.159,3.039,0,0,2.000,2.000,0.000,0.020,1
3751948195.451000,,,2.175,2.000,35.157,3.039,0,0,2.000,2.000,0.160,0.020,1
3751948287.891000,,,2.179,2.000,35.157,3.038,0,0,2.000,2.000,0.180,0.020,1
3751948323.637000,,,2.155,2.000,35.157,3.038,0,0,2.000,2.000,0.000,0.020,1
3751948383.637000,,,2.170,2.001,35.156,3.038,0,0,2.000,2.000,0.180,0.020,1
3751948443.637000,,,2.180,2.000,35.156,3.037,0,0,2.000,2.000,0.000,0.020,1
3751948503.637000,,,2.155,2.000,35.157,3.037,0,0,2.000,2.000,0.000,0.020,1
3751948614.583000,,,2.180,2.001,35.159,3.036,0,0,2.000,2.000,0.000,0.020,1
3751948741.228000,,,2.156,2.000,35.161,3.035,0,0,2.000,2.000,0.000,0.020,1
3751948783.425000,,,2.177,2.001,35.162,3.035,0,0,2.000,2.000,0.180,0.020,1
3751948920.211000,,,2.180,1.999,35.163,3.035,0,0,2.000,2.000,0.030,0.020,1
3751948980.211000,,,2.159,2.000,35.162,3.035,0,0,2.000,2.000,0.000,0.020,1
3751949032.091000,,,2.165,2.000,35.162,3.036,0,0,2.000,2.000,0.080,0.020,1
3751949092.091000,,,2.177,2.000,35.161,3.036,0,0,2.000,2.000,0.150,0.020,1
3751949152.091000,,,2.153,2.000,35.161,3.035,0,0,2.000,2.000,0.000,0.020,1
3751949212.091000,,,2.170,2.000,35.160,3.036,0,0,2.000,2.000,0.160,0.020,1
3751949291.387000,,,2.154,2.000,35.159,3.036,0,0,2.000,2.000,0.000,0.020,1
3751949351.387000,,,2.166,2.000,35.159,3.035,0,0,2.000,2.000,0.000,0.020,1
3751949448.842000,,,2.162,2.000,35.157,3.036,0,0,2.000,2.000,0.000,0.020,1
3751949498.817000,,,2.179,2.000,35.157,3.035,0,0,2.000,2.000,0.110,0.020,1
3751949544.766000,,,2.178,2.000,35.156,3.037,0,0,2.000,2.000,0.070,0.020,1
3751949595.961000,,,2.156,2.000,35.156,3.037,0,0,2.000,2.000,0.000,0.020,1
3751949655.961000,,,2.170,2.000,35.156,3.037,0,0,2.000,2.000,0.000,0.020,1
3751949715.961000,,,2.171,2.000,35.155,3.037,0,0,2.000,2.000,0.020,0.020,1
3751949775.961000,,,2.153,1.999,35.156,3.037,0,0,2.000,2.000,0.000,0.020,1
3751949835.961000,,,2.176,2.000,35.158,3.037,0,0,2.000,2.000,0.000,0.020,1
3751949895.961000,,,2.176,2.000,35.159,3.036,0,0,2.000,2.000,0.000,0.020,1
3751949955.961000,,,2.158,2.001,35.161,3.036,0,0,2.000,2.000,0.000,0.020,1
3751950015.961000,,,2.157,2.001,35.162,3.036,0,0,2.000,2.000,0.030,0.020,1
3751950075.961000,,,2.178,2.000,35.162,3.036,0,0,2.000,2.000,0.090,0.020,1
3751950135.961000,,,2.163,1.999,35.163,3.037,0,0,2.000,2.000,0.160,0.020,1
3751950195.961000,,,2.155,2.000,35.164,3.037,0,0,2.000,2.000,0.000,0.020,1
3751950255.961000,,,2.171,2.000,35.165,3.037,0,0,2.000,2.000,0.000,0.020,1
3751950315.961000,,,2.180,1.999,35.166,3.037,0,0,2.000,2.000,0.160,0.020,1
3751950375.961000,,,2.166,2.001,35.166,3.035,0,0,2.000,2.000,0.000,0.020,1
3751950435.961000,,,2.161,2.000,35.166,3.035,0,0,2.000,2.000,0.000,0.020,1
3751950495.961000,,,2.179,2.000,35.166,3.034,0,0,2.000,2.000,0.150,0.020,1
3751950555.961000,,,2.164,1.999,35.165,3.033,0,0,2.000,2.000,0.000,0.020,1
3751950646.472000,,,2.170,2.000,35.164,3.033,0,0,2.000,2.000,0.160,0.020,1
3751950706.472000,,,2.177,2.000,35.162,3.034,0,0,2.000,2.000,0.000,0.020,1
3751950766.472000,,,2.177,2.000,35.162,3.034,0,0,2.000,2.000,0.000,0.020,1
3751950826.472000,,,2.156,2.000,35.162,3.035,0,0,2.000,2.000,0.090,0.030,1
3751950886.472000,,,2.176,2.001,35.161,3.036,0,0,2.000,2.000,0.150,0.020,1
3751950946.472000,,,2.175,1.999,35.162,3.036,0,0,2.000,2.000,0.000,0.020,1
3751951006.472000,,,2.164,2.000,35.163,3.036,0,0,2.000,2.000,0.000,0.020,1
3751951066.472000,,,2.153,2.000,35.163,3.037,0,0,2.000,2.000,0.080,0.020,1
3751951126.472000,,,2.169,2.000,35.162,3.038,0,0,2.000,2.000,0.190,0.020,1
3751951186.472000,,,2.179,2.000,35.163,3.039,0,0,2.000,2.000,0.160,0.020,1
3751951246.472000,,,2.167,2.000,35.164,3.038,0,0,2.000,2.000,0.000,0.020,1
3751951306.472000,,,2.154,2.000,35.165,3.039,0,0,2.000,2.000,0.030,0.020,1
3751951366.472000,,,2.172,2.000,35.165,3.039,0,0,2.000,2.000,0.170,0.020,1
3751951426.472000,,,2.180,2.000,35.167,3.039,0,0,2.000,2.000,0.190,0.020,1
3751951486.472000,,,2.156,2.000,35.168,3.039,0,0,2.000,2.000,0.000,0.020,1
3751951546.472000,,,2.161,2.000,35.169,3.039,0,0,2.000,2.000,0.000,0.020,1
3751951606.472000,,,2.180,2.001,35.171,3.040,0,0,2.000,2.000,0.120,0.020,1
3751951666.472000,,,2.164,2.000,35.172,3.040,0,0,2.000,2.000,0.160,0.020,1
3751951726.472000,,,2.161,2.000,35.172,3.041,0,0,2.000,2.000,0.130,0.020,1
3751951786.472000,,,2.176,2.000,35.171,3.040,0,0,2.000,2.000,0.180,0.020,1
3751951846.472000,,,2.160,2.000,35.170,3.040,0,0,2.000,2.000,0.000,0.020,1
3751951906.472000,,,2.153,2.000,35.169,3.040,0,0,2.000,2.000,0.000,0.020,1
3751951966.472000,,,2.176,2.001,35.169,3.040,0,0,2.000,2.000,0.190,0.020,1
3751952026.472000,,,2.178,2.000,35.170,3.039,0,0,2.000,2.000,0.170,0.020,1
3751952086.472000,,,2.157,2.001,35.171,3.039,0,0,2.000,2.000,0.000,0.020,1
3751952146.472000,,,2.180,1.999,35.171,3.038,0,0,2.000,2.000,0.140,0.020,1
3751952226.111000,,,2.154,2.000,35.172,3.038,0,0,2.000,2.000,0.000,0.020,1
3751952286.111000,,,2.169,1.999,35.173,3.038,0,0,2.000,2.000,0.000,0.020,1
3751952346.111000,,,2.177,1.999,35.173,3.038,0,0,2.000,2.000,0.130,0.020,1
3751952406.111000,,,2.158,2.000,35.174,3.037,0,0,2.000,2.000,0.000,0.020,1
3751952466.111000,,,2.157,2.001,35.175,3.037,0,0,2.000,2.000,0.000,0.020,1
3751952526.111000,,,2.181,2.001,35.176,3.036,0,0,2.000,2.000,0.000,0.020,1
3751952586.111000,,,2.163,2.000,35.178,3.036,0,0,2.000,2.000,0.130,0.020,1
3751952646.111000,,,2.156,2.000,35.179,3.037,0,0,2.000,2.000,0.000,0.020,1
3751952706.111000,,,2.170,2.000,35.180,3.036,0,0,2.000,2.000,0.000,0.020,1
3751952766.111000,,,2.171,2.000,35.181,3.036,0,0,2.000,2.000,0.000,0.020,1
3751952826.111000,,,2.153,2.000,35.181,3.036,0,0,2.000,2.000,0.000,0.020,1
3751952886.111000,,,2.170,2.000,35.180,3.036,0,0,2.000,2.000,0.000,0.020,1
3751952946.111000,,,2.177,2.001,35.179,3.037,0,0,2.000,2.000,0.190,0.020,1
3751953006.111000,,,2.154,2.000,35.178,3.037,0,0,2.000,2.000,0.060,0.020,1
3751953066.111000,,,2.170,2.000,35.177,3.037,0,0,2.000,2.000,0.000,0.020,1
3751953126.111000,,,2.177,2.000,35.176,3.037,0,0,2.000,2.000,0.140,0.020,1
3751953186.111000,,,2.166,1.999,35.176,3.038,0,0,2.000,2.000,0.020,0.020,1
3751953246.111000,,,2.153,2.000,35.175,3.037,0,0,2.000,2.000,0.000,0.020,1
3751953306.111000,,,2.163,2.001,35.177,3.040,0,0,2.000,2.000,0.000,0.020,1
3751953366.111000,,,2.176,2.000,35.178,3.040,0,0,2.000,2.000,0.170,0.020,1
3751953426.111000,,,2.158,2.001,35.179,3.040,0,0,2.000,2.000,0.090,0.020,1
3751953486.111000,,,2.152,2.001,35.178,3.037,0,0,2.000,2.000,0.000,0.020,1
3751953546.111000,,,2.176,2.000,35.180,3.038,0,0,2.000,2.000,0.000,0.020,1
3751953606.111000,,,2.179,2.000,35.182,3.039,0,0,2.000,2.000,0.000,0.020,1
3751953666.111000,,,2.155,2.000,35.182,3.037,0,0,2.000,2.000,0.000,0.020,1
3751953726.111000,,,2.159,2.000,35.182,3.037,0,0,2.000,2.000,0.000,0.020,1
3751953786.111000,,,2.179,2.001,35.182,3.038,0,0,2.000,2.000,0.000,0.020,1
3751953846.111000,,,2.163,2.000,35.182,3.038,0,0,2.000,2.000,0.000,0.020,1
3751953906.111000,,,2.152,2.000,35.180,3.038,0,0,2.000,2.000,0.000,0.020,1
3751953966.111000,,,2.160,2.001,35.181,3.040,0,0,2.000,2.000,0.000,0.020,1
3751954026.111000,,,2.178,2.000,35.182,3.040,0,0,2.000,2.000,0.090,0.020,1
3751954086.111000,,,2.177,2.000,35.182,3.039,0,0,2.000,2.000,0.000,0.020,1
3751954146.111000,,,2.162,2.000,35.184,3.036,0,0,2.000,2.000,0.000,0.020,1
3751954206.111000,,,2.154,2.000,35.179,3.037,0,0,2.000,2.000,0.000,0.020,1
3751954266.111000,,,2.161,2.001,35.179,3.036,0,0,2.000,2.000,0.170,0.020,1
3751954326.111000,,,2.172,2.000,35.178,3.035,0,0,2.000,2.000,0.190,0.020,1
3751954386.111000,,,2.175,2.000,35.177,3.036,0,0,2.000,2.000,0.060,0.020,1
3751954446.111000,,,2.154,2.000,35.174,3.036,0,0,2.000,2.000,0.000,0.020,1
3751954506.111000,,,2.156,2.000,35.172,3.037,0,0,2.000,2.000,0.000,0.020,1
3751954566.111000,,,2.173,1.999,35.172,3.038,0,0,2.000,2.000,0.180,0.020,1
3751954626.111000,,,2.174,2.000,35.172,3.038,0,0,2.000,2.000,0.000,0.020,1
3751954686.111000,,,2.162,2.000,35.172,3.038,0,0,2.000,2.000,0.000,0.020,1
3751954746.111000,,,2.154,1.999,35.171,3.039,0,0,2.000,2.000,0.000,0.020,1
3751954806.111000,,,2.172,2.000,35.172,3.039,0,0,2.000,2.000,0.110,0.020,1
3751954866.111000,,,2.167,2.000,35.173,3.039,0,0,2.000,2.000,0.000,0.020,1
3751954926.111000,,,2.154,2.000,35.173,3.038,0,0,2.000,2.000,0.000,0.020,1
3751954986.111000,,,2.163,2.001,35.173,3.039,0,0,2.000,2.000,0.190,0.020,1
3751955046.111000,,,2.176,2.001,35.172,3.038,0,0,2.000,2.000,0.020,0.020,1
3751955106.111000,,,2.176,2.000,35.173,3.039,0,0,2.000,2.000,0.000,0.020,1
3751955166.111000,,,2.154,2.000,35.173,3.038,0,0,2.000,2.000,0.000,0.020,1
3751955226.111000,,,2.169,1.999,35.173,3.038,0,0,2.000,2.000,0.180,0.020,1
3751955286.111000,,,2.179,2.000,35.173,3.039,0,0,2.000,2.000,0.010,0.020,1
3751955346.111000,,,2.172,2.000,35.173,3.038,0,0,2.000,2.000,0.000,0.020,1
3751955406.111000,,,2.153,2.000,35.172,3.038,0,0,2.000,2.000,0.000,0.020,1
3751955466.111000,,,2.168,2.000,35.171,3.037,0,0,2.000,2.000,0.180,0.020,1
3751955526.111000,,,2.178,2.000,35.170,3.037,0,0,2.000,2.000,0.000,0.020,1
3751955586.111000,,,2.153,1.999,35.169,3.038,0,0,2.000,2.000,0.000,0.020,1
3751955646.111000,,,2.160,2.000,35.168,3.038,0,0,2.000,2.000,0.160,0.020,1
3751955706.111000,,,2.174,2.000,35.167,3.038,0,0,2.000,2.000,0.150,0.020,1
3751955766.111000,,,2.163,2.000,35.167,3.037,0,0,2.000,2.000,0.000,0.020,1
3751955826.111000,,,2.154,2.000,35.166,3.037,0,0,2.000,2.000,0.000,0.020,1
3751955886.111000,,,2.175,2.000,35.166,3.037,0,0,2.000,2.000,0.160,0.020,1
3751955946.111000,,,2.175,2.000,35.166,3.037,0,0,2.000,2.000,0.000,0.020,1
3751956006.111000,,,2.154,2.000,35.167,3.037,0,0,2.000,2.000,0.000,0.020,1
3751956066.111000,,,2.157,2.001,35.166,3.038,0,0,2.000,2.000,0.120,0.020,1
3751956126.111000,,,2.179,2.000,35.167,3.038,0,0,2.000,2.000,0.070,0.020,1
3751956186.111000,,,2.158,2.000,35.168,3.038,0,0,2.000,2.000,0.000,0.020,1
3751956246.111000,,,2.154,2.000,35.169,3.038,0,0,2.000,2.000,0.060,0.020,1
3751956306.111000,,,2.165,2.000,35.170,3.038,0,0,2.000,2.000,0.180,0.020,1
3751956366.111000,,,2.177,1.999,35.171,3.038,0,0,2.000,2.000,0.090,0.020,1
3751956426.111000,,,2.160,2.000,35.171,3.037,0,0,2.000,2.000,0.000,0.020,1
3751956486.111000,,,2.160,2.000,35.172,3.037,0,0,2.000,2.000,0.060,0.020,1
3751956546.111000,,,2.176,2.000,35.172,3.037,0,0,2.000,2.000,0.160,0.020,1
3751956606.111000,,,2.169,2.001,35.172,3.037,0,0,2.000,2.000,0.000,0.020,1
3751956666.111000,,,2.152,2.001,35.171,3.037,0,0,2.000,2.000,0.000,0.020,1
3751956726.111000,,,2.176,2.000,35.170,3.037,0,0,2.000,2.000,0.190,0.020,1
3751956786.111000,,,2.175,2.000,35.170,3.037,0,0,2.000,2.000,0.000,0.020,1
3751956846.111000,,,2.158,2.000,35.170,3.037,0,0,2.000,2.000,0.000,0.020,1
3751956906.111000,,,2.163,2.000,35.170,3.036,0,0,2.000,2.000,0.050,0.020,1
3751956966.111000,,,2.176,2.000,35.170,3.037,0,0,2.000,2.000,0.000,0.020,1
3751957026.111000,,,2.176,2.000,35.170,3.037,0,0,2.000,2.000,0.000,0.020,1
3751957086.111000,,,2.160,2.000,35.170,3.037,0,0,2.000,2.000,0.000,0.020,1
3751957146.111000,,,2.160,2.000,35.170,3.038,0,0,2.000,2.000,0.000,0.020,1
3751957206.111000,,,2.180,2.000,35.170,3.039,0,0,2.000,2.000,0.060,0.020,1
3751957266.111000,,,2.169,1.999,35.170,3.039,0,0,2.000,2.000,0.000,0.020,1
3751957326.111000,,,2.151,1.999,35.171,3.039,0,0,2.000,2.000,0.000,0.020,1
3751957386.111000,,,2.170,1.999,35.172,3.038,0,0,2.000,2.000,0.160,0.020,1
3751957446.111000,,,2.177,2.001,35.172,3.039,0,0,2.000,2.000,0.000,0.020,1
3751957506.111000,,,2.155,1.999,35.172,3.039,0,0,2.000,2.000,0.000,0.020,1
3751957566.111000,,,2.169,2.000,35.172,3.038,0,0,2.000,2.000,0.180,0.020,1
3751957626.111000,,,2.178,2.000,35.172,3.038,0,0,2.000,2.000,0.000,0.020,1
3751957686.111000,,,2.170,2.000,35.173,3.038,0,0,2.000,2.000,0.000,0.020,1
3751957746.111000,,,2.155,2.000,35.173,3.037,0,0,2.000,2.000,0.000,0.020,1
3751957806.111000,,,2.173,2.000,35.172,3.037,0,0,2.000,2.000,0.170,0.020,1
3751957866.111000,,,2.174,1.999,35.172,3.038,0,0,2.000,2.000,0.000,0.020,1
3751957926.111000,,,2.154,2.001,35.171,3.038,0,0,2.000,2.000,0.000,0.020,1
3751957986.111000,,,2.170,2.001,35.168,3.039,0,0,2.000,2.000,0.190,0.020,1
3751958046.111000,,,2.176,2.000,35.166,3.038,0,0,2.000,2.000,0.000,0.020,1
3751958106.111000,,,2.152,2.000,35.164,3.037,0,0,2.000,2.000,0.000,0.020,1
3751958166.111000,,,2.158,2.000,35.164,3.038,0,0,2.000,2.000,0.160,0.020,1
3751958226.111000,,,2.179,2.001,35.163,3.038,0,0,2.000,2.000,0.090,0.020,1
3751958286.111000,,,2.155,2.000,35.162,3.038,0,0,2.000,2.000,0.000,0.020,1
3751958346.111000,,,2.159,2.000,35.160,3.037,0,0,2.000,2.000,0.150,0.020,1
3751958406.111000,,,2.172,2.001,35.159,3.037,0,0,2.000,2.000,0.130,0.020,1
3751958466.111000,,,2.182,2.000,35.159,3.037,0,0,2.000,2.000,0.000,0.020,1
3751958526.111000,,,2.153,2.000,35.158,3.038,0,0,2.000,2.000,0.000,0.020,1
3751958586.111000,,,2.164,2.000,35.159,3.038,0,0,2.000,2.000,0.180,0.020,1
3751958646.111000,,,2.177,2.000,35.157,3.039,0,0,2.000,2.000,0.000,0.020,1
3751958706.111000,,,2.161,2.000,35.156,3.038,0,0,2.000,2.000,0.000,0.020,1
3751958766.111000,,,2.159,2.000,35.156,3.039,0,0,2.000,2.000,0.160,0.020,1
3751958826.111000,,,2.177,2.000,35.155,3.039,0,0,2.000,2.000,0.120,0.020,1
3751958886.111000,,,2.166,2.000,35.154,3.038,0,0,2.000,2.000,0.000,0.020,1
3751958946.111000,,,2.152,2.001,35.154,3.038,0,0,2.000,2.000,0.000,0.020,1
3751959006.111000,,,4.781,4.668,35.152,3.047,1,1,150.000,150.000,0.000,0.260,0
3751959066.111000,,,7.638,7.615,35.139,3.087,1,1,150.000,150.000,0.370,0.450,2
3751959126.111000,,,10.629,10.591,35.105,3.159,1,1,150.000,150.000,0.620,0.630,2
3751959186.111000,,,13.596,13.580,35.032,3.272,1,1,150.000,150.000,0.850,0.740,2
3751959246.111000,,,16.569,16.561,34.939,3.428,1,1,150.000,150.000,1.380,1.160,2
3751959306.111000,,,19.558,19.559,34.868,3.626,1,1,150.000,150.000,1.780,1.220,2
3751959366.111000,,,22.543,22.512,34.821,3.823,1,1,150.000,150.000,2.350,1.610,2
3751959426.111000,,,25.518,25.499,34.829,4.001,1,1,150.000,150.000,2.630,1.630,2
3751959486.111000,,,28.483,28.477,35.154,3.861,1,1,150.000,150.000,3.150,1.890,2
3751959546.111000,,,31.452,31.427,35.439,3.729,1,1,150.000,150.000,3.840,2.280,2
3751959606.111000,,,34.441,34.417,35.607,3.723,1,1,150.000,150.000,4.580,2.660,2
3751959666.111000,,,37.414,37.384,35.733,3.722,1,1,150.000,150.000,5.410,3.210,2
3751959726.111000,,,40.379,40.363,35.840,3.723,1,1,150.000,150.000,6.280,3.640,2
3751959786.111000,,,41.170,41.650,35.938,3.721,1,1,2.000,2.000,0.000,0.000,0
3751959846.111000,,,36.709,38.981,36.031,3.719,1,1,2.000,2.000,0.000,0.000,0
3751959906.111000,,,32.805,36.157,36.119,3.717,1,1,2.000,2.000,0.000,0.000,3
3751959966.111000,,,29.094,32.895,36.199,3.718,1,1,2.000,2.000,0.000,0.000,3
3751960026.111000,,,25.191,28.874,36.271,3.719,1,1,2.000,2.000,0.000,0.000,3
3751960093.402000,,,19.300,22.172,36.340,3.719,1,1,2.000,2.000,0.000,0.000,3
3751960153.402000,,,10.327,10.205,36.388,3.719,1,1,2.000,2.000,0.120,0.220,3
3751960213.402000,,,5.135,5.162,36.426,3.717,1,1,2.000,2.000,0.000,0.170,3
3751960273.402000,,,2.866,2.262,36.472,3.702,0,0,2.000,2.000,0.000,0.000,4
3751960333.402000,,,2.707,2.193,36.534,3.680,0,0,2.000,2.000,0.000,0.000,4
3751960393.402000,,,2.609,2.139,36.586,3.651,0,0,2.000,2.000,0.000,0.000,4
3751960453.402000,,,2.494,2.072,36.623,3.621,0,0,2.000,2.000,0.000,0.000,4
3751960513.402000,,,2.416,2.005,36.646,3.589,0,0,2.000,2.000,0.000,0.000,4
3751960573.402000,,,2.378,2.000,36.656,3.557,0,0,2.000,2.000,0.000,0.000,4
3751960633.402000,,,2.346,2.000,36.655,3.524,0,0,2.000,2.000,0.000,0.000,4
3751960693.402000,,,2.278,2.000,36.642,3.485,0,0,2.000,2.000,0.000,0.000,4
3751960753.402000,,,2.229,2.075,36.619,3.449,1,1,150.000,150.000,0.020,0.040,0
3751960813.402000,,,5.081,5.037,36.583,3.415,1,1,150.000,150.000,0.020,0.220,0
3751960873.402000,,,8.012,7.999,36.518,3.402,1,1,150.000,150.000,0.300,0.480,2
3751960933.402000,,,10.986,10.946,36.405,3.424,1,1,150.000,150.000,0.540,0.520,2
3751960993.402000,,,13.949,13.888,36.254,3.481,1,1,150.000,150.000,0.900,0.840,2
3751961053.402000,,,16.941,16.907,36.087,3.553,1,1,150.000,150.000,1.370,1.130,2
3751961113.402000,,,19.918,19.855,35.905,3.615,1,1,150.000,150.000,1.870,1.400,2
3751961173.402000,,,22.908,22.868,35.721,3.689,1,1,150.000,150.000,2.160,1.460,2
3751961233.402000,,,25.865,25.854,35.789,3.716,1,1,150.000,150.000,2.620,1.680,2
3751961293.402000,,,28.848,28.842,35.942,3.723,1,1,150.000,150.000,3.250,1.910,2
3751961353.402000,,,31.817,31.800,36.074,3.726,1,1,150.000,150.000,3.990,2.320,2
3751961413.402000,,,34.788,34.779,36.185,3.727,1,1,150.000,150.000,4.740,2.680,2
3751961473.402000,,,37.768,37.754,36.283,3.725,1,1,150.000,150.000,5.520,3.230,2
3751961533.402000,,,40.734,40.696,36.373,3.725,1,1,150.000,150.000,6.380,3.720,2
3751961593.402000,,,43.720,43.709,36.457,3.725,1,1,150.000,150.000,7.220,4.110,2
3751961653.402000,,,46.691,46.683,36.534,3.725,1,1,150.000,150.000,8.220,4.650,2
3751961713.402000,,,49.670,49.655,36.607,3.725,1,1,150.000,150.000,9.120,5.200,2
3751961773.402000,,,52.632,52.622,36.678,3.722,1,1,150.000,150.000,10.000,5.720,2
3751961833.402000,,,55.627,55.602,36.744,3.724,1,1,150.000,150.000,10.830,6.230,2
3751961893.402000,,,58.596,58.568,36.808,3.724,1,1,150.000,150.000,11.730,6.830,2
3751961953.402000,,,61.565,61.551,36.869,3.724,1,1,150.000,150.000,12.610,7.350,2
3751962013.402000,,,64.551,64.526,36.930,3.721,1,1,150.000,150.000,13.530,7.800,2
3751962073.402000,,,67.510,67.496,36.987,3.720,1,1,150.000,150.000,14.400,8.200,2
3751962133.402000,,,70.495,70.495,37.045,3.719,1,1,150.000,150.000,15.300,8.890,2
3751962193.402000,,,73.467,73.454,37.100,3.719,1,1,150.000,150.000,16.130,9.400,2
3751962253.402000,,,76.447,76.423,37.155,3.722,1,1,150.000,150.000,16.950,9.890,2
3751962313.402000,,,79.415,79.395,37.207,3.727,1,1,150.000,150.000,17.800,10.390,2
3751962373.402000,,,82.372,82.359,37.259,3.726,1,1,150.000,150.000,18.590,10.980,2
3751962433.402000,,,85.350,85.336,37.311,3.725,1,1,150.000,150.000,19.390,11.380,2
3751962493.402000,,,88.316,88.291,37.362,3.725,1,1,150.000,150.000,20.090,11.950,2
3751962553.402000,,,91.298,91.281,37.412,3.725,1,1,150.000,150.000,20.790,12.400,2
3751962613.402000,,,94.272,94.253,37.462,3.723,1,1,150.000,150.000,21.540,12.860,2
3751962673.402000,,,97.234,97.222,37.512,3.722,1,1,150.000,150.000,22.260,13.350,2
3751962733.402000,,,100.211,100.193,37.562,3.722,1,1,150.000,150.000,23.020,13.810,2
3751962793.402000,,,103.181,103.156,37.610,3.722,1,1,150.000,150.000,23.620,14.270,2
3751962853.402000,,,106.161,106.140,37.658,3.723,1,1,150.000,150.000,24.320,14.710,2
3751962913.402000,,,109.121,109.120,37.706,3.721,1,1,150.000,150.000,24.990,15.230,2
3751962973.402000,,,112.108,112.083,37.754,3.719,1,1,150.000,150.000,25.580,15.550,2
3751963033.402000,,,115.061,115.052,37.801,3.719,1,1,150.000,150.000,26.290,16.030,2
3751963093.402000,,,118.040,118.025,37.849,3.719,1,1,150.000,150.000,26.880,16.480,2
3751963153.402000,,,121.016,120.996,37.897,3.719,1,1,150.000,150.000,27.480,16.890,2
3751963213.402000,,,123.975,123.955,37.944,3.721,1,1,150.000,150.000,28.100,17.340,2
3751963273.402000,,,126.957,126.937,37.991,3.722,1,1,150.000,150.000,28.790,17.730,2
3751963333.402000,,,129.923,129.902,38.039,3.722,1,1,150.000,150.000,29.330,18.170,2
3751963393.402000,,,132.890,132.888,38.086,3.722,1,1,150.000,150.000,29.900,18.570,2
3751963453.402000,,,135.885,135.859,38.134,3.723,1,1,150.000,150.000,30.440,19.020,2
3751963513.402000,,,138.841,138.827,38.182,3.723,1,1,150.000,150.000,31.070,19.400,2
3751963573.402000,,,141.814,141.799,38.231,3.721,1,1,150.000,150.000,31.630,19.770,2
3751963633.402000,,,144.787,144.771,38.278,3.725,1,1,150.000,150.000,32.190,20.190,2
3751963693.402000,,,147.753,147.738,38.326,3.719,1,1,150.000,150.000,32.700,20.470,2
3751963753.402000,,,150.601,150.448,38.373,3.721,0,0,150.000,150.000,23.450,16.320,4
3751963813.402000,,,149.468,150.032,38.419,3.720,0,0,150.000,150.000,26.320,12.070,4
3751963873.402000,,,150.133,150.013,38.464,3.719,0,0,150.000,150.000,12.790,11.090,4
3751963933.402000,,,150.284,150.007,38.508,3.719,0,0,150.000,150.000,21.700,10.660,4
3751963993.402000,,,149.661,150.006,38.553,3.719,0,0,150.000,150.000,21.770,10.420,4
3751964053.402000,,,150.132,150.006,38.595,3.719,0,0,150.000,150.000,14.330,10.190,4
3751964113.402000,,,150.131,150.005,38.638,3.719,0,0,150.000,150.000,20.310,10.010,4
3751964173.402000,,,149.793,150.005,38.679,3.719,0,0,150.000,150.000,19.280,9.800,4
3751964233.402000,,,150.115,150.006,38.719,3.719,0,0,150.000,150.000,15.260,9.680,1
3751964269.710000,,,149.845,150.005,38.743,3.720,0,0,150.000,150.000,19.170,9.590,1
3751964329.710000,,,150.052,150.004,38.783,3.721,0,0,150.000,150.000,15.460,9.460,1
3751964389.710000,,,150.073,150.004,38.824,3.719,0,0,150.000,150.000,18.050,9.330,1
3751964449.710000,,,149.901,150.003,38.863,3.721,0,0,150.000,150.000,17.700,9.170,1
3751964509.710000,,,150.052,150.004,38.902,3.720,0,0,150.000,150.000,15.550,9.100,1
3751964569.710000,,,150.031,150.002,38.939,3.720,0,0,150.000,150.000,17.410,8.970,1
3751964629.710000,,,149.939,150.003,38.977,3.720,0,0,150.000,150.000,16.690,8.850,1
3751964689.710000,,,150.045,150.003,39.013,3.720,0,0,150.000,150.000,15.570,8.770,1
3751964749.710000,,,150.007,150.002,39.050,3.720,0,0,150.000,150.000,16.810,8.680,1
3751964809.710000,,,149.964,150.002,39.087,3.721,0,0,150.000,150.000,16.050,8.590,1
3751964869.710000,,,150.036,150.003,39.123,3.720,0,0,150.000,150.000,15.480,8.510,1
3751964929.710000,,,149.996,150.001,39.160,3.720,0,0,150.000,150.000,16.230,8.420,1
3751964989.710000,,,149.982,150.002,39.195,3.720,0,0,150.000,150.000,15.490,8.380,1
3751965049.710000,,,150.026,150.001,39.228,3.721,0,0,150.000,150.000,15.320,8.290,1
3751965109.710000,,,149.991,150.001,39.261,3.718,0,0,150.000,150.000,15.730,8.210,1
3751965169.710000,,,149.994,150.003,39.295,3.718,0,0,150.000,150.000,15.130,8.150,1
3751965229.710000,,,150.019,150.002,39.327,3.720,0,0,150.000,150.000,15.110,8.110,1
3751965289.710000,,,149.989,150.001,39.360,3.719,0,0,150.000,150.000,15.300,8.020,1
3751965349.710000,,,149.998,150.001,39.393,3.720,0,0,150.000,150.000,14.840,7.960,1
3751965409.710000,,,150.013,150.002,39.427,3.720,0,0,150.000,150.000,14.880,7.900,1
3751965469.710000,,,149.993,150.001,39.459,3.719,0,0,150.000,150.000,14.930,7.860,1
3751965529.710000,,,150.001,150.000,39.490,3.718,0,0,150.000,150.000,14.610,7.820,1
3751965589.710000,,,150.007,150.002,39.523,3.718,0,0,150.000,150.000,14.650,7.790,1
3751965649.710000,,,149.995,150.001,39.553,3.720,0,0,150.000,150.000,14.630,7.720,1
3751965709.710000,,,150.002,150.001,39.582,3.721,0,0,150.000,150.000,14.380,7.670,1
3751965769.710000,,,150.006,150.001,39.612,3.720,0,0,150.000,150.000,14.420,7.630,1
3751965829.710000,,,149.995,150.000,39.641,3.721,0,0,150.000,150.000,14.400,7.590,1
3751965889.710000,,,150.003,150.000,39.670,3.721,0,0,150.000,150.000,14.250,7.540,1
3751965949.710000,,,150.004,150.001,39.699,3.721,0,0,150.000,150.000,14.250,7.530,1
3751966009.710000,,,149.997,150.001,39.726,3.720,0,0,150.000,150.000,14.140,7.470,1
3751966069.710000,,,150.004,150.001,39.754,3.720,0,0,150.000,150.000,13.950,7.440,1
3751966129.710000,,,150.002,150.000,39.781,3.721,0,0,150.000,150.000,14.060,7.420,1
3751966189.710000,,,149.997,150.001,39.809,3.722,0,0,150.000,150.000,13.990,7.370,1
3751966249.710000,,,150.003,150.002,39.835,3.721,0,0,150.000,150.000,13.900,7.350,1
3751966309.710000,,,150.000,150.001,39.861,3.722,0,0,150.000,150.000,13.900,7.330,1
3751966369.710000,,,149.998,150.001,39.887,3.723,0,0,150.000,150.000,13.800,7.290,1
3751966429.710000,,,150.003,150.000,39.913,3.722,0,0,150.000,150.000,13.750,7.280,1
3751966489.710000,,,150.001,150.000,39.940,3.721,0,0,150.000,150.000,13.750,7.250,1
3751966526.600000,,,150.001,150.001,39.956,3.723,0,0,150.000,150.000,13.660,7.220,1
3751966586.600000,,,150.004,150.000,39.980,3.723,0,0,150.000,150.000,13.660,7.190,1
3751966646.600000,,,150.000,150.001,40.003,3.723,0,0,150.000,150.000,13.640,7.160,1
3751966706.600000,,,150.000,150.001,40.027,3.722,0,0,150.000,150.000,13.530,7.160,1
3751966766.600000,,,150.001,150.000,40.051,3.724,0,0,150.000,150.000,13.510,7.120,1
3751966826.600000,,,149.999,150.000,40.075,3.720,0,0,150.000,150.000,13.550,7.140,1
3751966886.600000,,,150.000,150.000,40.099,3.721,0,0,150.000,150.000,13.420,7.080,1
3751966947.840000,,,150.002,150.001,40.121,3.722,0,0,150.000,150.000,13.400,7.050,1
3751967007.840000,,,150.000,150.001,40.144,3.724,0,0,150.000,150.000,13.380,7.030,1
3751967061.072000,,,150.001,150.000,40.163,3.725,0,0,150.000,150.000,13.330,7.030,1
3751967123.591000,,,150.001,149.994,40.187,3.724,0,0,150.000,150.000,13.310,7.080,1
3751967183.591000,,,149.999,150.000,40.209,3.724,0,0,150.000,150.000,13.330,7.280,1
3751967221.157000,,,150.002,150.000,40.224,3.723,0,0,150.000,150.000,13.270,7.280,1
3751967281.157000,,,150.000,150.000,40.245,3.724,0,0,150.000,150.000,13.290,7.250,1
3751967341.157000,,,150.000,150.001,40.267,3.723,0,0,150.000,150.000,13.200,7.180,1
3751967401.157000,,,150.000,150.001,40.288,3.723,0,0,150.000,150.000,13.180,7.140,1
3751967461.157000,,,149.999,150.000,40.309,3.721,0,0,150.000,150.000,13.130,7.070,1
3751967521.157000,,,150.003,150.000,40.329,3.721,0,0,150.000,150.000,13.110,6.980,1
3751967581.157000,,,149.999,149.997,40.348,3.721,0,0,150.000,150.000,13.110,7.140,1
3751967641.157000,,,149.999,149.999,40.367,3.723,0,0,150.000,150.000,13.090,7.330,1
3751967701.157000,,,150.002,150.000,40.386,3.723,0,0,150.000,150.000,13.040,7.370,1
3751967761.157000,,,150.000,150.000,40.405,3.724,0,0,150.000,150.000,13.040,7.370,1
3751967821.157000,,,149.998,150.000,40.423,3.724,0,0,150.000,150.000,13.060,7.350,1
3751967881.157000,,,150.002,150.000,40.442,3.725,0,0,150.000,150.000,12.990,7.330,1
3751967941.157000,,,150.000,150.000,40.461,3.723,0,0,150.000,150.000,13.000,7.320,1
3751968001.157000,,,150.000,150.000,40.479,3.725,0,0,150.000,150.000,12.950,7.300,1
3751968061.157000,,,150.002,150.000,40.498,3.726,0,0,150.000,150.000,12.930,7.290,1
3751968121.157000,,,150.000,150.001,40.516,3.726,0,0,150.000,150.000,12.930,7.280,1
3751968181.157000,,,150.000,150.001,40.535,3.727,0,0,150.000,150.000,12.880,7.280,1
3751968241.157000,,,150.001,150.000,40.551,3.726,0,0,150.000,150.000,12.860,7.250,1
3751968301.157000,,,150.000,150.000,40.568,3.725,0,0,150.000,150.000,12.840,7.230,1
3751968361.157000,,,150.000,150.000,40.585,3.726,0,0,150.000,150.000,12.830,7.220,1
3751968421.157000,,,150.001,150.000,40.601,3.726,0,0,150.000,150.000,12.770,7.220,1
3751968481.157000,,,150.000,150.001,40.615,3.727,0,0,150.000,150.000,12.790,7.190,1
3751968541.157000,,,150.000,150.003,40.631,3.727,0,0,150.000,150.000,12.770,7.180,1
3751968601.157000,,,150.000,150.000,40.648,3.727,0,0,150.000,150.000,12.720,7.160,1
3751968661.157000,,,150.001,150.001,40.663,3.727,0,0,150.000,150.000,12.720,7.140,1
3751968721.157000,,,150.000,150.000,40.679,3.727,0,0,150.000,150.000,12.720,7.120,1
3751968781.157000,,,150.001,150.002,40.694,3.728,0,0,150.000,150.000,12.700,7.120,1
3751968841.157000,,,150.001,150.001,40.710,3.725,0,0,150.000,150.000,12.610,7.110,1
3751968901.157000,,,150.000,150.000,40.725,3.724,0,0,150.000,150.000,12.650,7.110,1
3751968961.157000,,,150.001,150.000,40.740,3.724,0,0,150.000,150.000,12.630,7.110,1
3751969021.157000,,,150.001,150.000,40.753,3.723,0,0,150.000,150.000,12.630,7.080,1
3751969081.157000,,,149.999,150.000,40.768,3.723,0,0,150.000,150.000,12.610,7.090,1
3751969141.157000,,,150.000,150.001,40.781,3.724,0,0,150.000,150.000,12.580,7.070,1
3751969201.157000,,,150.000,150.000,40.794,3.725,0,0,150.000,150.000,12.600,7.050,1
3751969243.688000,,,150.000,150.001,40.805,3.725,0,0,150.000,150.000,12.600,7.070,1
3751969303.688000,,,150.000,150.000,40.817,3.728,0,0,150.000,150.000,12.540,7.050,1
3751969363.688000,,,150.000,150.000,40.829,3.731,0,0,150.000,150.000,12.560,7.030,1
3751969423.688000,,,150.000,149.999,40.842,3.730,0,0,150.000,150.000,12.530,7.030,1
3751969483.688000,,,150.000,150.001,40.854,3.729,0,0,150.000,150.000,12.530,7.030,1
3751969543.688000,,,149.997,150.000,40.867,3.732,0,0,150.000,150.000,12.560,7.030,1
3751969603.688000,,,150.001,150.001,40.880,3.731,0,0,150.000,150.000,12.470,7.030,1
3751969663.688000,,,150.001,150.000,40.892,3.731,0,0,150.000,150.000,12.540,7.000,1
3751969723.688000,,,149.998,150.001,40.904,3.730,0,0,150.000,150.000,12.490,7.000,1
3751969783.688000,,,150.002,150.000,40.917,3.728,0,0,150.000,150.000,12.440,7.000,1
3751969843.688000,,,150.001,150.000,40.930,3.727,0,0,150.000,150.000,12.400,6.980,1
3751969903.688000,,,149.999,150.000,40.942,3.728,0,0,150.000,150.000,12.440,6.980,1
3751969963.688000,,,150.001,150.000,40.953,3.731,0,0,150.000,150.000,12.420,6.980,1
3751970023.688000,,,150.000,149.999,40.965,3.732,0,0,150.000,150.000,12.470,6.970,1
3751970083.688000,,,149.999,150.002,40.976,3.732,0,0,150.000,150.000,12.440,6.960,1
3751970121.739000,,,150.001,149.999,40.984,3.731,0,0,150.000,150.000,12.440,6.960,1
3751970174.631000,,,149.999,150.001,40.995,3.731,0,0,150.000,150.000,12.400,6.940,1
3751970234.631000,,,154.693,154.287,41.006,3.729,1,1,300.000,300.000,43.950,21.820,0
3751970294.631000,,,158.437,159.235,41.019,3.725,1,1,300.000,300.000,39.800,24.360,2
3751970354.631000,,,164.777,164.207,41.032,3.727,1,1,300.000,300.000,28.550,25.760,2
3751970414.631000,,,169.253,169.167,41.047,3.728,1,1,300.000,300.000,47.920,27.020,2
3751970474.631000,,,173.737,174.141,41.064,3.729,1,1,300.000,300.000,40.310,28.190,2
3751970534.631000,,,179.572,179.108,41.081,3.729,1,1,300.000,300.000,38.470,29.160,2
3751970594.631000,,,183.947,184.065,41.099,3.728,1,1,300.000,300.000,50.210,29.920,2
3751970642.627000,,,188.095,187.815,41.115,3.729,0,0,187.000,187.000,26.600,23.880,4
3751970688.693000,,,186.164,186.968,41.130,3.731,0,0,187.000,187.000,19.560,15.170,4
3751970748.693000,,,187.901,187.028,41.148,3.729,0,0,187.000,187.000,13.770,13.030,4
3751970808.693000,,,188.645,189.497,41.165,3.729,1,1,300.000,300.000,71.210,27.530,0
3751970868.693000,,,194.689,194.777,41.182,3.729,1,1,300.000,300.000,25.210,29.970,2
3751970928.693000,,,200.941,199.791,41.199,3.731,1,1,300.000,300.000,51.980,31.700,2
3751970988.693000,,,203.636,204.756,41.217,3.731,1,1,300.000,300.000,59.310,32.910,2
3751971048.693000,,,210.341,209.736,41.236,3.730,1,1,300.000,300.000,34.660,33.990,2
3751971108.693000,,,214.917,214.690,41.257,3.732,1,1,300.000,300.000,63.120,34.900,2
3751971168.693000,,,219.014,219.653,41.279,3.732,1,1,300.000,300.000,50.810,35.700,2
3751971228.693000,,,225.382,224.613,41.301,3.733,1,1,300.000,300.000,47.330,36.700,2
3751971288.693000,,,229.198,229.562,41.323,3.733,1,1,300.000,300.000,65.470,37.580,2
3751971348.693000,,,234.500,234.530,41.347,3.733,1,1,300.000,300.000,48.120,38.640,2
3751971408.693000,,,239.938,239.478,41.370,3.732,1,1,300.000,300.000,59.920,39.870,2
3751971468.693000,,,243.970,244.435,41.394,3.732,1,1,300.000,300.000,61.860,40.730,2
3751971528.693000,,,249.795,249.401,41.419,3.732,1,1,300.000,300.000,52.920,41.830,2
3751971588.693000,,,254.331,254.355,41.445,3.733,1,1,300.000,300.000,67.330,42.770,2
3751971648.693000,,,259.140,259.398,41.473,3.733,1,1,300.000,300.000,58.210,41.790,2
3751971708.693000,,,264.677,264.301,41.500,3.733,1,1,300.000,300.000,62.060,44.510,2
3751971768.693000,,,268.930,269.231,41.529,3.734,1,1,300.000,300.000,67.940,45.350,2
3751971828.693000,,,274.395,274.188,41.559,3.734,1,1,300.000,300.000,58.930,46.260,2
3751971888.693000,,,279.257,279.148,41.589,3.735,1,1,300.000,300.000,69.750,47.040,2
3751971948.693000,,,283.936,284.110,41.620,3.735,1,1,300.000,300.000,79.040,47.970,2
3751972008.693000,,,288.814,289.080,41.653,3.734,1,1,300.000,300.000,59.270,48.870,2
3751972068.693000,,,294.712,294.035,41.685,3.735,1,1,300.000,300.000,68.880,49.630,2
3751972128.693000,,,298.330,299.004,41.720,3.735,1,1,300.000,300.000,75.460,50.510,2
3751972188.693000,,,300.703,300.107,41.756,3.735,0,0,300.000,300.000,15.130,33.720,4
3751972248.693000,,,300.561,300.075,41.789,3.736,0,0,300.000,300.000,63.950,31.610,4
3751972308.693000,,,298.600,300.031,41.821,3.735,0,0,300.000,300.000,37.430,30.400,4
3751972371.176000,,,301.653,300.017,41.854,3.734,0,0,300.000,300.000,25.790,29.720,4
3751972431.176000,,,298.935,300.008,41.884,3.737,0,0,300.000,300.000,65.300,29.190,4
3751972491.176000,,,300.129,300.016,41.916,3.736,0,0,300.000,300.000,17.100,28.770,4
3751972551.176000,,,300.822,300.002,41.948,3.734,0,0,300.000,300.000,53.100,28.570,4
3751972611.176000,,,298.653,300.010,41.979,3.739,0,0,300.000,300.000,40.720,28.050,4
3751972671.176000,,,301.329,300.011,42.013,3.737,0,0,300.000,300.000,23.450,27.860,1
3751972731.176000,,,299.221,300.005,42.048,3.737,0,0,300.000,300.000,59.580,27.530,1
3751972791.176000,,,299.972,300.012,42.080,3.738,0,0,300.000,300.000,19.560,27.200,1
3751972849.691000,,,300.701,300.003,42.114,3.737,0,0,300.000,300.000,48.360,27.020,1
3751972904.703000,,,299.044,300.009,42.146,3.737,0,0,300.000,300.000,32.980,26.770,1
3751972964.703000,,,301.168,300.005,42.181,3.740,0,0,300.000,300.000,29.460,26.590,1
3751973024.703000,,,299.114,300.003,42.216,3.739,0,0,300.000,300.000,52.380,26.270,1
3751973084.703000,,,300.300,300.007,42.253,3.738,0,0,300.000,300.000,19.080,26.080,1
3751973144.703000,,,300.377,300.000,42.288,3.737,0,0,300.000,300.000,47.810,25.870,1
3751973204.703000,,,299.154,300.005,42.325,3.739,0,0,300.000,300.000,33.560,25.610,1
3751973264.703000,,,300.962,300.005,42.362,3.742,0,0,300.000,300.000,27.740,25.450,1
3751973324.703000,,,299.315,300.002,42.400,3.741,0,0,300.000,300.000,48.990,25.290,1
3751973384.703000,,,300.168,300.007,42.439,3.740,0,0,300.000,300.000,20.920,25.060,1
3751973444.703000,,,300.390,300.002,42.478,3.742,0,0,300.000,300.000,43.390,24.930,1
3751973504.703000,,,299.264,300.006,42.516,3.742,0,0,300.000,300.000,33.790,24.750,1
3751973564.703000,,,300.791,300.004,42.556,3.740,0,0,300.000,300.000,26.910,24.620,1
3751973624.703000,,,299.272,0.000,42.597,3.741,0,0,300.000,300.000,48.050,0.000,4
3751973684.703000,,,300.236,0.000,42.645,3.744,0,0,300.000,300.000,35.930,0.000,4
3751973744.703000,,,300.082,0.000,42.707,3.740,0,0,300.000,300.000,52.950,0.000,4
3751973804.703000,,,299.611,0.000,42.776,3.740,0,0,300.000,300.000,44.240,0.000,4
3751973864.703000,,,300.474,0.000,42.847,3.742,0,0,300.000,300.000,42.900,0.000,4
3751973924.703000,,,299.641,0.000,42.919,3.741,0,0,300.000,300.000,53.720,0.000,4
3751973984.703000,,,300.074,0.000,42.993,3.742,0,0,300.000,300.000,38.250,0.000,4
3751974044.703000,,,300.188,0.000,43.064,3.748,0,0,300.000,300.000,50.070,0.000,4
3751974104.703000,,,299.615,0.000,43.136,3.748,0,0,300.000,300.000,45.370,0.000,4
3751974164.703000,,,300.434,0.000,43.207,3.748,0,0,300.000,300.000,41.260,0.000,4
3751974224.703000,,,299.761,0.000,43.277,3.747,0,0,300.000,300.000,50.630,0.000,4
3751974284.703000,,,300.009,0.000,43.347,3.748,0,0,300.000,300.000,38.560,0.000,4
3751974344.703000,,,300.459,0.000,43.415,3.748,0,0,300.000,300.000,40.970,0.000,4
3751974404.703000,,,299.494,0.000,43.479,3.746,0,0,300.000,300.000,41.390,0.000,4
3751974464.703000,,,300.358,0.000,43.540,3.745,0,0,300.000,300.000,36.340,0.000,4
3751974524.703000,,,299.812,0.000,43.603,3.746,0,0,300.000,300.000,47.850,0.000,4
3751974584.703000,,,299.999,0.000,43.664,3.746,0,0,300.000,300.000,36.460,0.000,4
3751974644.703000,,,300.192,0.000,43.723,3.749,0,0,300.000,300.000,43.820,0.000,4
3751974704.703000,,,299.704,0.000,43.781,3.747,0,0,300.000,300.000,41.870,0.000,4
3751974764.703000,,,300.271,0.000,43.838,3.750,0,0,300.000,300.000,37.070,0.000,4
3751974824.703000,,,299.900,0.000,43.894,3.745,0,0,300.000,300.000,45.470,0.000,4
3751974884.703000,,,299.946,0.000,43.947,3.746,0,0,300.000,300.000,37.370,0.000,4
3751976860.240000,,,300.107,300.012,45.603,3.756,0,0,300.000,300.000,24.660,11.700,4
3751976920.240000,,,300.142,299.537,45.729,3.756,0,0,300.000,300.000,33.240,15.550,4
3751976980.240000,,,299.762,300.056,45.844,3.756,0,0,300.000,300.000,27.920,18.260,4
3751977040.240000,,,300.290,300.023,45.949,3.755,0,0,300.000,300.000,25.460,18.320,4