File: log/20221018.dat
[Header]
; Displex Transport Data File (default extension .dat)
; Copyright 2016, Hechang LEI, hlei@ruc.edu.cn. All rights reserved.
BYAPP, Displex, 2.0
INFO, 9T mag, Release 2.0.
INFO, Channel 1, Temperature Sensor
INFO, Sample 1 Length (cm): 0.000000; Width (cm): 0.000000; Thickness (cm): 0.000000.

[Data]
Timestamp(s),Field(Oe),Field Status,TempA(K),TempB(K),TempC(K),TempD(K),Ramp1,Ramp2,Setpoint1,Setpoint2,Output1(%),Output2(%),Temp Status
3748905208.777000,0.000,Standby,296.974,297.340,0.000,0.000,0,0,2.000,2.000,0,0,4
3748905358.777000,0.000,Standby,296.813,297.187,0.000,0.000,0,0,2.000,2.000,0,0,4
3748905508.777000,0.000,Standby,296.642,297.024,0.000,0.000,0,0,2.000,2.000,0,0,4
3748905658.777000,0.000,Standby,296.464,296.854,0.000,0.000,0,0,2.000,2.000,0,0,4
3748905918.142000,0.000,Standby,296.126,296.537,0.000,0.000,0,0,2.000,2.000,0,0,4
3748906068.142000,0.000,Standby,295.918,296.344,0.000,0.000,0,0,2.000,2.000,0,0,4
3748906218.142000,0.000,Standby,295.698,296.136,0.000,0.000,0,0,2.000,2.000,0,0,4
3748906368.142000,0.000,Standby,295.464,295.919,0.000,0.000,0,0,2.000,2.000,0,0,4
3748906518.142000,0.000,Standby,295.220,295.690,0.000,0.000,0,0,2.000,2.000,0,0,4
3748906668.142000,0.000,Standby,294.960,295.446,0.000,0.000,0,0,2.000,2.000,0,0,4
3748906818.142000,0.000,Standby,294.691,295.195,0.000,0.000,0,0,2.000,2.000,0,0,4
3748906968.142000,0.000,Standby,294.410,294.928,0.000,0.000,0,0,2.000,2.000,0,0,4
3748907118.142000,0.000,Standby,294.113,294.654,0.000,0.000,0,0,2.000,2.000,0,0,4
3748907268.142000,0.000,Standby,293.811,294.366,0.000,0.000,0,0,2.000,2.000,0,0,4
3748907418.142000,0.000,Standby,293.492,294.066,0.000,0.000,0,0,2.000,2.000,0,0,4
3748907568.142000,0.000,Standby,293.167,293.760,0.000,0.000,0,0,2.000,2.000,0,0,4
3748907718.142000,0.000,Standby,292.827,293.442,0.000,0.000,0,0,2.000,2.000,0,0,4
3748907868.142000,0.000,Standby,292.481,293.111,0.000,0.000,0,0,2.000,2.000,0,0,4
3748908018.142000,0.000,Standby,292.122,292.769,0.000,0.000,0,0,2.000,2.000,0,0,4
3748908168.142000,0.000,Standby,291.751,292.416,0.000,0.000,0,0,2.000,2.000,0,0,4
3748908318.142000,0.000,Standby,291.373,292.057,0.000,0.000,0,0,2.000,2.000,0,0,4
3748908468.142000,0.000,Standby,290.987,291.686,0.000,0.000,0,0,2.000,2.000,0,0,4
3748908618.142000,0.000,Standby,290.591,291.312,0.000,0.000,0,0,2.000,2.000,0,0,4
3748908768.142000,0.000,Standby,290.185,290.919,0.000,0.000,0,0,2.000,2.000,0,0,4
3748908918.142000,0.000,Standby,289.773,290.523,0.000,0.000,0,0,2.000,2.000,0,0,4
3748909068.142000,0.000,Standby,289.350,290.119,0.000,0.000,0,0,2.000,2.000,0,0,4
3748909218.142000,0.000,Standby,288.922,289.707,0.000,0.000,0,0,2.000,2.000,0,0,4
3748909368.142000,0.000,Standby,288.485,289.285,0.000,0.000,0,0,2.000,2.000,0,0,4
3748909518.142000,0.000,Standby,288.044,288.859,0.000,0.000,0,0,2.000,2.000,0,0,4
3748909668.142000,0.000,Standby,287.590,288.419,0.000,0.000,0,0,2.000,2.000,0,0,4
3748909818.142000,0.000,Standby,287.130,287.979,0.000,0.000,0,0,2.000,2.000,0,0,4
3748909968.142000,0.000,Standby,286.671,287.531,0.000,0.000,0,0,2.000,2.000,0,0,4
3748910118.142000,0.000,Standby,286.200,287.075,0.000,0.000,0,0,2.000,2.000,0,0,4
3748910268.142000,0.000,Standby,285.727,286.614,0.000,0.000,0,0,2.000,2.000,0,0,4
3748910418.142000,0.000,Standby,285.246,286.147,0.000,0.000,0,0,2.000,2.000,0,0,4
3748910568.142000,0.000,Standby,284.761,285.675,0.000,0.000,0,0,2.000,2.000,0,0,4
3748910718.142000,0.000,Standby,284.269,285.194,0.000,0.000,0,0,2.000,2.000,0,0,4
3748910868.142000,0.000,Standby,283.776,284.712,0.000,0.000,0,0,2.000,2.000,0,0,4
3748911018.142000,0.000,Standby,283.275,284.221,0.000,0.000,0,0,2.000,2.000,0,0,4
3748911168.142000,0.000,Standby,282.768,283.723,0.000,0.000,0,0,2.000,2.000,0,0,4
3748911318.142000,0.000,Standby,282.262,283.229,0.000,0.000,0,0,2.000,2.000,0,0,4
3748911468.142000,0.000,Standby,281.748,282.722,0.000,0.000,0,0,2.000,2.000,0,0,4
3748911618.142000,0.000,Standby,281.236,282.216,0.000,0.000,0,0,2.000,2.000,0,0,4
3748911768.142000,0.000,Standby,280.714,281.705,0.000,0.000,0,0,2.000,2.000,0,0,4
3748911918.142000,0.000,Standby,280.194,281.192,0.000,0.000,0,0,2.000,2.000,0,0,4
3748912068.142000,0.000,Standby,279.667,280.671,0.000,0.000,0,0,2.000,2.000,0,0,4
3748912218.142000,0.000,Standby,279.140,280.151,0.000,0.000,0,0,2.000,2.000,0,0,4
3748912368.142000,0.000,Standby,278.607,279.623,0.000,0.000,0,0,2.000,2.000,0,0,4
3748912518.142000,0.000,Standby,278.072,279.096,0.000,0.000,0,0,2.000,2.000,0,0,4
3748912668.142000,0.000,Standby,277.534,278.568,0.000,0.000,0,0,2.000,2.000,0,0,4
3748912818.142000,0.000,Standby,276.996,278.035,0.000,0.000,0,0,2.000,2.000,0,0,4
3748912968.142000,0.000,Standby,276.458,277.502,0.000,0.000,0,0,2.000,2.000,0,0,4
3748913118.142000,0.000,Standby,275.911,276.962,0.000,0.000,0,0,2.000,2.000,0,0,4
3748913268.142000,0.000,Standby,275.369,276.427,0.000,0.000,0,0,2.000,2.000,0,0,4
3748913418.142000,0.000,Standby,274.820,275.884,0.000,0.000,0,0,2.000,2.000,0,0,4
3748913568.142000,0.000,Standby,274.272,275.345,0.000,0.000,0,0,2.000,2.000,0,0,4
3748913718.142000,0.000,Standby,273.721,274.799,0.000,0.000,0,0,2.000,2.000,0,0,4
3748913868.142000,0.000,Standby,273.168,274.250,0.000,0.000,0,0,2.000,2.000,0,0,4
3748914018.142000,0.000,Standby,272.618,273.705,0.000,0.000,0,0,2.000,2.000,0,0,4
3748914168.142000,0.000,Standby,272.062,273.155,0.000,0.000,0,0,2.000,2.000,0,0,4
3748914318.142000,0.000,Standby,271.509,272.607,0.000,0.000,0,0,2.000,2.000,0,0,4
3748914468.142000,0.000,Standby,270.954,272.056,0.000,0.000,0,0,2.000,2.000,0,0,4
3748914618.142000,0.000,Standby,270.396,271.502,0.000,0.000,0,0,2.000,2.000,0,0,4
3748914768.142000,0.000,Standby,269.838,270.948,0.000,0.000,0,0,2.000,2.000,0,0,4
3748914918.142000,0.000,Standby,269.283,270.396,0.000,0.000,0,0,2.000,2.000,0,0,4
3748915068.142000,0.000,Standby,268.726,269.839,0.000,0.000,0,0,2.000,2.000,0,0,4
3748915218.142000,0.000,Standby,268.163,269.281,0.000,0.000,0,0,2.000,2.000,0,0,4
3748915368.142000,0.000,Standby,267.609,268.727,0.000,0.000,0,0,2.000,2.000,0,0,4
3748915518.142000,0.000,Standby,267.048,268.166,0.000,0.000,0,0,2.000,2.000,0,0,4
3748915668.142000,0.000,Standby,266.491,267.610,0.000,0.000,0,0,2.000,2.000,0,0,4
3748915818.142000,0.000,Standby,265.931,267.049,0.000,0.000,0,0,2.000,2.000,0,0,4
3748915968.142000,0.000,Standby,265.375,266.492,0.000,0.000,0,0,2.000,2.000,0,0,4
3748916118.142000,0.000,Standby,264.813,265.934,0.000,0.000,0,0,2.000,2.000,0,0,4
3748916268.142000,0.000,Standby,264.257,265.376,0.000,0.000,0,0,2.000,2.000,0,0,4
3748916418.142000,0.000,Standby,263.697,264.815,0.000,0.000,0,0,2.000,2.000,0,0,4
3748916568.142000,0.000,Standby,263.147,264.253,0.000,0.000,0,0,2.000,2.000,0,0,4
3748916718.142000,0.000,Standby,262.587,263.700,0.000,0.000,0,0,2.000,2.000,0,0,4
3748916868.142000,0.000,Standby,262.020,263.144,0.000,0.000,0,0,2.000,2.000,0,0,4
3748917018.142000,0.000,Standby,261.460,262.589,0.000,0.000,0,0,2.000,2.000,0,0,4
3748917168.142000,0.000,Standby,260.897,262.032,0.000,0.000,0,0,2.000,2.000,0,0,4
3748917318.142000,0.000,Standby,260.339,261.476,0.000,0.000,0,0,2.000,2.000,0,0,4
3748917468.142000,0.000,Standby,259.778,260.916,0.000,0.000,0,0,2.000,2.000,0,0,4
3748917618.142000,0.000,Standby,259.217,260.357,0.000,0.000,0,0,2.000,2.000,0,0,4
3748917768.142000,0.000,Standby,258.663,259.801,0.000,0.000,0,0,2.000,2.000,0,0,4
3748917918.142000,0.000,Standby,258.104,259.243,0.000,0.000,0,0,2.000,2.000,0,0,4
3748918068.142000,0.000,Standby,257.551,258.687,0.000,0.000,0,0,2.000,2.000,0,0,4
3748918218.142000,0.000,Standby,256.994,258.127,0.000,0.000,0,0,2.000,2.000,0,0,4
3748918368.142000,0.000,Standby,256.443,257.572,0.000,0.000,0,0,2.000,2.000,0,0,4
3748918518.142000,0.000,Standby,255.888,257.017,0.000,0.000,0,0,2.000,2.000,0,0,4
3748918668.142000,0.000,Standby,255.339,256.463,0.000,0.000,0,0,2.000,2.000,0,0,4
3748918818.142000,0.000,Standby,254.786,255.908,0.000,0.000,0,0,2.000,2.000,0,0,4
3748918968.142000,0.000,Standby,254.234,255.354,0.000,0.000,0,0,2.000,2.000,0,0,4
3748919118.142000,0.000,Standby,253.687,254.803,0.000,0.000,0,0,2.000,2.000,0,0,4
3748919268.142000,0.000,Standby,253.137,254.252,0.000,0.000,0,0,2.000,2.000,0,0,4
3748919418.142000,0.000,Standby,252.591,253.705,0.000,0.000,0,0,2.000,2.000,0,0,4
3748919568.142000,0.000,Standby,252.042,253.156,0.000,0.000,0,0,2.000,2.000,0,0,4
3748919718.142000,0.000,Standby,251.498,252.610,0.000,0.000,0,0,2.000,2.000,0,0,4
3748919868.142000,0.000,Standby,250.950,252.064,0.000,0.000,0,0,2.000,2.000,0,0,4
3748920018.142000,0.000,Standby,250.409,251.519,0.000,0.000,0,0,2.000,2.000,0,0,4
3748920168.142000,0.000,Standby,249.863,250.974,0.000,0.000,0,0,2.000,2.000,0,0,4
3748920318.142000,0.000,Standby,249.322,250.430,0.000,0.000,0,0,2.000,2.000,0,0,4
3748920468.142000,0.000,Standby,248.780,249.888,0.000,0.000,0,0,2.000,2.000,0,0,4
3748920618.142000,0.000,Standby,248.239,249.344,0.000,0.000,0,0,2.000,2.000,0,0,4
3748920768.142000,0.000,Standby,247.702,248.808,0.000,0.000,0,0,2.000,2.000,0,0,4
3748920918.142000,0.000,Standby,247.162,248.266,0.000,0.000,0,0,2.000,2.000,0,0,4
3748921068.142000,0.000,Standby,246.627,247.729,0.000,0.000,0,0,2.000,2.000,0,0,4
3748921218.142000,0.000,Standby,246.089,247.188,0.000,0.000,0,0,2.000,2.000,0,0,4
3748921368.142000,0.000,Standby,245.555,246.652,0.000,0.000,0,0,2.000,2.000,0,0,4
3748921518.142000,0.000,Standby,245.018,246.113,0.000,0.000,0,0,2.000,2.000,0,0,4
3748921668.142000,0.000,Standby,244.487,245.580,0.000,0.000,0,0,2.000,2.000,0,0,4
3748921818.142000,0.000,Standby,243.951,245.041,0.000,0.000,0,0,2.000,2.000,0,0,4
3748921968.142000,0.000,Standby,243.417,244.507,0.000,0.000,0,0,2.000,2.000,0,0,4
3748922118.142000,0.000,Standby,242.887,243.976,0.000,0.000,0,0,2.000,2.000,0,0,4
3748922268.142000,0.000,Standby,242.353,243.440,0.000,0.000,0,0,2.000,2.000,0,0,4
3748922418.142000,0.000,Standby,241.826,242.910,0.000,0.000,0,0,2.000,2.000,0,0,4
3748922568.142000,0.000,Standby,241.295,242.378,0.000,0.000,0,0,2.000,2.000,0,0,4
3748922718.142000,0.000,Standby,240.769,241.850,0.000,0.000,0,0,2.000,2.000,0,0,4
3748922868.142000,0.000,Standby,240.238,241.318,0.000,0.000,0,0,2.000,2.000,0,0,4
3748923018.142000,0.000,Standby,239.713,240.790,0.000,0.000,0,0,2.000,2.000,0,0,4
3748923168.142000,0.000,Standby,239.186,240.260,0.000,0.000,0,0,2.000,2.000,0,0,4
3748923318.142000,0.000,Standby,238.661,239.719,0.000,0.000,0,0,2.000,2.000,0,0,4
3748923468.142000,0.000,Standby,238.145,239.199,0.000,0.000,0,0,2.000,2.000,0,0,4
3748923618.142000,0.000,Standby,237.626,238.675,0.000,0.000,0,0,2.000,2.000,0,0,4
3748923768.142000,0.000,Standby,237.112,238.159,0.000,0.000,0,0,2.000,2.000,0,0,4
3748923918.142000,0.000,Standby,236.593,237.638,0.000,0.000,0,0,2.000,2.000,0,0,4
3748924068.142000,0.000,Standby,236.075,237.118,0.000,0.000,0,0,2.000,2.000,0,0,4
3748924218.142000,0.000,Standby,235.563,236.602,0.000,0.000,0,0,2.000,2.000,0,0,4
3748924368.142000,0.000,Standby,235.045,236.086,0.000,0.000,0,0,2.000,2.000,0,0,4
3748924518.142000,0.000,Standby,234.535,235.572,0.000,0.000,0,0,2.000,2.000,0,0,4
3748924668.142000,0.000,Standby,234.022,235.056,0.000,0.000,0,0,2.000,2.000,0,0,4
3748924818.142000,0.000,Standby,233.515,234.547,0.000,0.000,0,0,2.000,2.000,0,0,4
3748924968.142000,0.000,Standby,233.002,234.034,0.000,0.000,0,0,2.000,2.000,0,0,4
3748925118.142000,0.000,Standby,232.496,233.524,0.000,0.000,0,0,2.000,2.000,0,0,4
3748925268.142000,0.000,Standby,231.987,233.014,0.000,0.000,0,0,2.000,2.000,0,0,4
3748925418.142000,0.000,Standby,231.479,232.505,0.000,0.000,0,0,2.000,2.000,0,0,4
3748925568.142000,0.000,Standby,230.977,232.000,0.000,0.000,0,0,2.000,2.000,0,0,4
3748925718.142000,0.000,Standby,230.471,231.494,0.000,0.000,0,0,2.000,2.000,0,0,4
3748925868.142000,0.000,Standby,229.971,230.990,0.000,0.000,0,0,2.000,2.000,0,0,4
3748926018.142000,0.000,Standby,229.470,230.486,0.000,0.000,0,0,2.000,2.000,0,0,4
3748926168.142000,0.000,Standby,228.974,229.987,0.000,0.000,0,0,2.000,2.000,0,0,4
3748926318.142000,0.000,Standby,228.474,229.485,0.000,0.000,0,0,2.000,2.000,0,0,4
3748926468.142000,0.000,Standby,227.978,228.986,0.000,0.000,0,0,2.000,2.000,0,0,4
3748926618.142000,0.000,Standby,227.480,228.485,0.000,0.000,0,0,2.000,2.000,0,0,4
3748926768.142000,0.000,Standby,226.989,227.990,0.000,0.000,0,0,2.000,2.000,0,0,4
3748926918.142000,0.000,Standby,226.492,227.492,0.000,0.000,0,0,2.000,2.000,0,0,4
3748927068.142000,0.000,Standby,225.998,226.995,0.000,0.000,0,0,2.000,2.000,0,0,4
3748927218.142000,0.000,Standby,225.509,226.504,0.000,0.000,0,0,2.000,2.000,0,0,4
3748927368.142000,0.000,Standby,225.019,226.011,0.000,0.000,0,0,2.000,2.000,0,0,4
3748927518.142000,0.000,Standby,224.533,225.523,0.000,0.000,0,0,2.000,2.000,0,0,4
3748927668.142000,0.000,Standby,224.044,225.032,0.000,0.000,0,0,2.000,2.000,0,0,4
3748927818.142000,0.000,Standby,223.559,224.548,0.000,0.000,0,0,2.000,2.000,0,0,4
3748927968.142000,0.000,Standby,223.072,224.061,0.000,0.000,0,0,2.000,2.000,0,0,4
3748928118.142000,0.000,Standby,222.589,223.578,0.000,0.000,0,0,2.000,2.000,0,0,4
3748928268.142000,0.000,Standby,222.105,223.094,0.000,0.000,0,0,2.000,2.000,0,0,4
3748928418.142000,0.000,Standby,221.621,222.609,0.000,0.000,0,0,2.000,2.000,0,0,4
3748928568.142000,0.000,Standby,221.142,222.127,0.000,0.000,0,0,2.000,2.000,0,0,4
3748928718.142000,0.000,Standby,220.662,221.642,0.000,0.000,0,0,2.000,2.000,0,0,4
3748928868.142000,0.000,Standby,220.188,221.162,0.000,0.000,0,0,2.000,2.000,0,0,4
3748929018.142000,0.000,Standby,219.710,220.680,0.000,0.000,0,0,2.000,2.000,0,0,4
3748929168.142000,0.000,Standby,219.238,220.204,0.000,0.000,0,0,2.000,2.000,0,0,4
3748929318.142000,0.000,Standby,218.761,219.725,0.000,0.000,0,0,2.000,2.000,0,0,4
3748929468.142000,0.000,Standby,218.288,219.248,0.000,0.000,0,0,2.000,2.000,0,0,4
3748929618.142000,0.000,Standby,217.812,218.770,0.000,0.000,0,0,2.000,2.000,0,0,4
3748929768.142000,0.000,Standby,217.337,218.293,0.000,0.000,0,0,2.000,2.000,0,0,4
3748929918.142000,0.000,Standby,216.869,217.823,0.000,0.000,0,0,2.000,2.000,0,0,4
3748930068.142000,0.000,Standby,216.397,217.350,0.000,0.000,0,0,2.000,2.000,0,0,4
3748930218.142000,0.000,Standby,215.932,216.883,0.000,0.000,0,0,2.000,2.000,0,0,4
3748930368.142000,0.000,Standby,215.462,216.413,0.000,0.000,0,0,2.000,2.000,0,0,4
3748930518.142000,0.000,Standby,214.998,215.947,0.000,0.000,0,0,2.000,2.000,0,0,4
3748930668.142000,0.000,Standby,214.532,215.480,0.000,0.000,0,0,2.000,2.000,0,0,4
3748930818.142000,0.000,Standby,214.069,215.018,0.000,0.000,0,0,2.000,2.000,0,0,4
3748930968.142000,0.000,Standby,213.606,214.553,0.000,0.000,0,0,2.000,2.000,0,0,4
3748931118.142000,0.000,Standby,213.143,214.090,0.000,0.000,0,0,2.000,2.000,0,0,4
3748931268.142000,0.000,Standby,212.684,213.631,0.000,0.000,0,0,2.000,2.000,0,0,4
3748931418.142000,0.000,Standby,212.222,213.170,0.000,0.000,0,0,2.000,2.000,0,0,4
3748931568.142000,0.000,Standby,211.765,212.712,0.000,0.000,0,0,2.000,2.000,0,0,4
3748931718.142000,0.000,Standby,211.304,212.252,0.000,0.000,0,0,2.000,2.000,0,0,4
3748931868.142000,0.000,Standby,210.850,211.798,0.000,0.000,0,0,2.000,2.000,0,0,4
3748932018.142000,0.000,Standby,210.394,211.341,0.000,0.000,0,0,2.000,2.000,0,0,4
3748932168.142000,0.000,Standby,209.940,210.889,0.000,0.000,0,0,2.000,2.000,0,0,4
3748932318.142000,0.000,Standby,209.486,210.433,0.000,0.000,0,0,2.000,2.000,0,0,4
3748932468.142000,0.000,Standby,209.031,209.980,0.000,0.000,0,0,2.000,2.000,0,0,4
3748932618.142000,0.000,Standby,208.582,209.531,0.000,0.000,0,0,2.000,2.000,0,0,4
3748932768.142000,0.000,Standby,208.129,209.078,0.000,0.000,0,0,2.000,2.000,0,0,4
3748932918.142000,0.000,Standby,207.679,208.629,0.000,0.000,0,0,2.000,2.000,0,0,4
3748933068.142000,0.000,Standby,207.228,208.179,0.000,0.000,0,0,2.000,2.000,0,0,4
3748933218.142000,0.000,Standby,206.779,207.733,0.000,0.000,0,0,2.000,2.000,0,0,4
3748933368.142000,0.000,Standby,206.328,207.284,0.000,0.000,0,0,2.000,2.000,0,0,4
3748933518.142000,0.000,Standby,205.878,206.838,0.000,0.000,0,0,2.000,2.000,0,0,4
3748933668.142000,0.000,Standby,205.426,206.389,0.000,0.000,0,0,2.000,2.000,0,0,4
3748933818.142000,0.000,Standby,204.977,205.942,0.000,0.000,0,0,2.000,2.000,0,0,4
3748933968.142000,0.000,Standby,204.528,205.498,0.000,0.000,0,0,2.000,2.000,0,0,4
3748934118.142000,0.000,Standby,204.076,205.052,0.000,0.000,0,0,2.000,2.000,0,0,4
3748934268.142000,0.000,Standby,203.629,204.608,0.000,0.000,0,0,2.000,2.000,0,0,4
3748934418.142000,0.000,Standby,203.178,204.162,0.000,0.000,0,0,2.000,2.000,0,0,4
3748934568.142000,0.000,Standby,202.730,203.718,0.000,0.000,0,0,2.000,2.000,0,0,4
3748934718.142000,0.000,Standby,202.282,203.274,0.000,0.000,0,0,2.000,2.000,0,0,4
3748934868.142000,0.000,Standby,201.835,202.831,0.000,0.000,0,0,2.000,2.000,0,0,4
3748935018.142000,0.000,Standby,201.388,202.387,0.000,0.000,0,0,2.000,2.000,0,0,4
3748935168.142000,0.000,Standby,200.939,201.944,0.000,0.000,0,0,2.000,2.000,0,0,4
3748935318.142000,0.000,Standby,200.495,201.503,0.000,0.000,0,0,2.000,2.000,0,0,4
3748935468.142000,0.000,Standby,200.051,201.061,0.000,0.000,0,0,2.000,2.000,0,0,4
3748935618.142000,0.000,Standby,199.609,200.621,0.000,0.000,0,0,2.000,2.000,0,0,4
3748935768.142000,0.000,Standby,199.164,200.179,0.000,0.000,0,0,2.000,2.000,0,0,4
3748935918.142000,0.000,Standby,198.725,199.742,0.000,0.000,0,0,2.000,2.000,0,0,4
3748936068.142000,0.000,Standby,198.283,199.302,0.000,0.000,0,0,2.000,2.000,0,0,4
3748936218.142000,0.000,Standby,197.847,198.867,0.000,0.000,0,0,2.000,2.000,0,0,4
3748936368.142000,0.000,Standby,197.407,198.428,0.000,0.000,0,0,2.000,2.000,0,0,4
3748936518.142000,0.000,Standby,196.970,197.991,0.000,0.000,0,0,2.000,2.000,0,0,4
3748936668.142000,0.000,Standby,196.537,197.558,0.000,0.000,0,0,2.000,2.000,0,0,4
3748936818.142000,0.000,Standby,196.100,197.123,0.000,0.000,0,0,2.000,2.000,0,0,4
3748936968.142000,0.000,Standby,195.668,196.691,0.000,0.000,0,0,2.000,2.000,0,0,4
3748937118.142000,0.000,Standby,195.235,196.257,0.000,0.000,0,0,2.000,2.000,0,0,4
3748937268.142000,0.000,Standby,194.806,195.828,0.000,0.000,0,0,2.000,2.000,0,0,4
3748937418.142000,0.000,Standby,194.374,195.398,0.000,0.000,0,0,2.000,2.000,0,0,4
3748937568.142000,0.000,Standby,193.946,194.970,0.000,0.000,0,0,2.000,2.000,0,0,4
3748937718.142000,0.000,Standby,193.518,194.542,0.000,0.000,0,0,2.000,2.000,0,0,4
3748937868.142000,0.000,Standby,193.092,194.116,0.000,0.000,0,0,2.000,2.000,0,0,4
3748938018.142000,0.000,Standby,192.665,193.690,0.000,0.000,0,0,2.000,2.000,0,0,4
3748938168.142000,0.000,Standby,192.239,193.263,0.000,0.000,0,0,2.000,2.000,0,0,4
3748938318.142000,0.000,Standby,191.815,192.841,0.000,0.000,0,0,2.000,2.000,0,0,4
3748938468.142000,0.000,Standby,191.390,192.417,0.000,0.000,0,0,2.000,2.000,0,0,4
3748938618.142000,0.000,Standby,190.969,191.997,0.000,0.000,0,0,2.000,2.000,0,0,4
3748938768.142000,0.000,Standby,190.545,191.574,0.000,0.000,0,0,2.000,2.000,0,0,4
3748938918.142000,0.000,Standby,190.125,191.155,0.000,0.000,0,0,2.000,2.000,0,0,4
3748939068.142000,0.000,Standby,189.704,190.735,0.000,0.000,0,0,2.000,2.000,0,0,4
3748939218.142000,0.000,Standby,189.285,190.318,0.000,0.000,0,0,2.000,2.000,0,0,4
3748939368.142000,0.000,Standby,188.865,189.899,0.000,0.000,0,0,2.000,2.000,0,0,4
3748939518.142000,0.000,Standby,188.444,189.481,0.000,0.000,0,0,2.000,2.000,0,0,4
3748939668.142000,0.000,Standby,188.028,189.066,0.000,0.000,0,0,2.000,2.000,0,0,4
3748939818.142000,0.000,Standby,187.610,188.648,0.000,0.000,0,0,2.000,2.000,0,0,4
3748939968.142000,0.000,Standby,187.194,188.237,0.000,0.000,0,0,2.000,2.000,0,0,4
3748940118.142000,0.000,Standby,186.774,187.820,0.000,0.000,0,0,2.000,2.000,0,0,4
3748940268.142000,0.000,Standby,186.359,187.409,0.000,0.000,0,0,2.000,2.000,0,0,4
3748940418.142000,0.000,Standby,185.939,186.993,0.000,0.000,0,0,2.000,2.000,0,0,4
3748940568.142000,0.000,Standby,185.522,186.582,0.000,0.000,0,0,2.000,2.000,0,0,4
3748940718.142000,0.000,Standby,185.100,186.168,0.000,0.000,0,0,2.000,2.000,0,0,4
3748940868.142000,0.000,Standby,184.676,185.752,0.000,0.000,0,0,2.000,2.000,0,0,4
3748941018.142000,0.000,Standby,184.250,185.341,0.000,0.000,0,0,2.000,2.000,0,0,4
3748941168.142000,0.000,Standby,183.818,184.923,0.000,0.000,0,0,2.000,2.000,0,0,4
3748941318.142000,0.000,Standby,183.386,184.508,0.000,0.000,0,0,2.000,2.000,0,0,4
3748941468.142000,0.000,Standby,182.953,184.088,0.000,0.000,0,0,2.000,2.000,0,0,4
3748941618.142000,0.000,Standby,182.524,183.671,0.000,0.000,0,0,2.000,2.000,0,0,4
3748941768.142000,0.000,Standby,182.095,183.251,0.000,0.000,0,0,2.000,2.000,0,0,4
3748941918.142000,0.000,Standby,181.672,182.836,0.000,0.000,0,0,2.000,2.000,0,0,4
3748942068.142000,0.000,Standby,181.247,182.417,0.000,0.000,0,0,2.000,2.000,0,0,4
3748942218.142000,0.000,Standby,180.824,181.998,0.000,0.000,0,0,2.000,2.000,0,0,4
3748942368.142000,0.000,Standby,180.407,181.584,0.000,0.000,0,0,2.000,2.000,0,0,4
3748942518.142000,0.000,Standby,179.989,181.167,0.000,0.000,0,0,2.000,2.000,0,0,4
3748942668.142000,0.000,Standby,179.577,180.755,0.000,0.000,0,0,2.000,2.000,0,0,4
3748942818.142000,0.000,Standby,179.163,180.342,0.000,0.000,0,0,2.000,2.000,0,0,4
3748942968.142000,0.000,Standby,178.754,179.932,0.000,0.000,0,0,2.000,2.000,0,0,4
3748943118.142000,0.000,Standby,178.344,179.521,0.000,0.000,0,0,2.000,2.000,0,0,4
3748943268.142000,0.000,Standby,177.939,179.114,0.000,0.000,0,0,2.000,2.000,0,0,4
3748943418.142000,0.000,Standby,177.531,178.706,0.000,0.000,0,0,2.000,2.000,0,0,4
3748943568.142000,0.000,Standby,177.126,178.299,0.000,0.000,0,0,2.000,2.000,0,0,4
3748943718.142000,0.000,Standby,176.723,177.895,0.000,0.000,0,0,2.000,2.000,0,0,4
3748943868.142000,0.000,Standby,176.320,177.491,0.000,0.000,0,0,2.000,2.000,0,0,4
3748944018.142000,0.000,Standby,175.918,177.091,0.000,0.000,0,0,2.000,2.000,0,0,4
3748944168.142000,0.000,Standby,175.516,176.687,0.000,0.000,0,0,2.000,2.000,0,0,4
3748944318.142000,0.000,Standby,175.116,176.289,0.000,0.000,0,0,2.000,2.000,0,0,4
3748944468.142000,0.000,Standby,174.715,175.887,0.000,0.000,0,0,2.000,2.000,0,0,4
3748944618.142000,0.000,Standby,174.318,175.489,0.000,0.000,0,0,2.000,2.000,0,0,4
3748944768.142000,0.000,Standby,173.918,175.091,0.000,0.000,0,0,2.000,2.000,0,0,4
3748944918.142000,0.000,Standby,173.521,174.693,0.000,0.000,0,0,2.000,2.000,0,0,4
3748945068.142000,0.000,Standby,173.127,174.299,0.000,0.000,0,0,2.000,2.000,0,0,4
3748945218.142000,0.000,Standby,172.731,173.903,0.000,0.000,0,0,2.000,2.000,0,0,4
3748945368.142000,0.000,Standby,172.339,173.510,0.000,0.000,0,0,2.000,2.000,0,0,4
3748945518.142000,0.000,Standby,171.944,173.117,0.000,0.000,0,0,2.000,2.000,0,0,4
3748945668.142000,0.000,Standby,171.552,172.726,0.000,0.000,0,0,2.000,2.000,0,0,4
3748945818.142000,0.000,Standby,171.160,172.334,0.000,0.000,0,0,2.000,2.000,0,0,4
3748945968.142000,0.000,Standby,170.771,171.947,0.000,0.000,0,0,2.000,2.000,0,0,4
3748946118.142000,0.000,Standby,170.379,171.556,0.000,0.000,0,0,2.000,2.000,0,0,4
3748946268.142000,0.000,Standby,169.988,171.168,0.000,0.000,0,0,2.000,2.000,0,0,4
3748946418.142000,0.000,Standby,169.599,170.781,0.000,0.000,0,0,2.000,2.000,0,0,4
3748946568.142000,0.000,Standby,169.209,170.393,0.000,0.000,0,0,2.000,2.000,0,0,4
3748946718.142000,0.000,Standby,168.823,170.009,0.000,0.000,0,0,2.000,2.000,0,0,4
3748946868.142000,0.000,Standby,168.434,169.622,0.000,0.000,0,0,2.000,2.000,0,0,4
3748947018.142000,0.000,Standby,168.048,169.238,0.000,0.000,0,0,2.000,2.000,0,0,4
3748947168.142000,0.000,Standby,167.661,168.853,0.000,0.000,0,0,2.000,2.000,0,0,4
3748947318.142000,0.000,Standby,167.276,168.471,0.000,0.000,0,0,2.000,2.000,0,0,4
3748947468.142000,0.000,Standby,166.889,168.087,0.000,0.000,0,0,2.000,2.000,0,0,4
3748947618.142000,0.000,Standby,166.505,167.704,0.000,0.000,0,0,2.000,2.000,0,0,4
3748947768.142000,0.000,Standby,166.124,167.324,0.000,0.000,0,0,2.000,2.000,0,0,4
3748947918.142000,0.000,Standby,165.740,166.942,0.000,0.000,0,0,2.000,2.000,0,0,4
3748948068.142000,0.000,Standby,165.360,166.564,0.000,0.000,0,0,2.000,2.000,0,0,4
3748948218.142000,0.000,Standby,164.978,166.184,0.000,0.000,0,0,2.000,2.000,0,0,4
3748948368.142000,0.000,Standby,164.599,165.808,0.000,0.000,0,0,2.000,2.000,0,0,4
3748948518.142000,0.000,Standby,164.220,165.429,0.000,0.000,0,0,2.000,2.000,0,0,4
3748948668.142000,0.000,Standby,163.844,165.054,0.000,0.000,0,0,2.000,2.000,0,0,4
3748948818.142000,0.000,Standby,163.466,164.678,0.000,0.000,0,0,2.000,2.000,0,0,4
3748948968.142000,0.000,Standby,163.092,164.305,0.000,0.000,0,0,2.000,2.000,0,0,4
3748949118.142000,0.000,Standby,162.716,163.930,0.000,0.000,0,0,2.000,2.000,0,0,4
3748949268.142000,0.000,Standby,162.342,163.556,0.000,0.000,0,0,2.000,2.000,0,0,4
3748949418.142000,0.000,Standby,161.972,163.187,0.000,0.000,0,0,2.000,2.000,0,0,4
3748949568.142000,0.000,Standby,161.600,162.816,0.000,0.000,0,0,2.000,2.000,0,0,4
3748949718.142000,0.000,Standby,161.232,162.449,0.000,0.000,0,0,2.000,2.000,0,0,4
3748949868.142000,0.000,Standby,160.863,162.079,0.000,0.000,0,0,2.000,2.000,0,0,4
3748950018.142000,0.000,Standby,160.498,161.714,0.000,0.000,0,0,2.000,2.000,0,0,4
3748950168.142000,0.000,Standby,160.131,161.347,0.000,0.000,0,0,2.000,2.000,0,0,4
3748950318.142000,0.000,Standby,159.770,160.985,0.000,0.000,0,0,2.000,2.000,0,0,4
3748950468.142000,0.000,Standby,159.407,160.621,0.000,0.000,0,0,2.000,2.000,0,0,4
3748950618.142000,0.000,Standby,159.045,160.259,0.000,0.000,0,0,2.000,2.000,0,0,4
3748950768.142000,0.000,Standby,158.688,159.901,0.000,0.000,0,0,2.000,2.000,0,0,4
3748950918.142000,0.000,Standby,158.331,159.541,0.000,0.000,0,0,2.000,2.000,0,0,4
3748951068.142000,0.000,Standby,157.979,159.187,0.000,0.000,0,0,2.000,2.000,0,0,4
3748951218.142000,0.000,Standby,157.625,158.832,0.000,0.000,0,0,2.000,2.000,0,0,4
3748951368.142000,0.000,Standby,157.276,158.480,0.000,0.000,0,0,2.000,2.000,0,0,4
3748951518.142000,0.000,Standby,156.928,158.129,0.000,0.000,0,0,2.000,2.000,0,0,4
3748951668.142000,0.000,Standby,156.585,157.781,0.000,0.000,0,0,2.000,2.000,0,0,4
3748951818.142000,0.000,Standby,156.242,157.434,0.000,0.000,0,0,2.000,2.000,0,0,4
3748951968.142000,0.000,Standby,155.902,157.088,0.000,0.000,0,0,2.000,2.000,0,0,4
3748952118.142000,0.000,Standby,155.568,156.749,0.000,0.000,0,0,2.000,2.000,0,0,4
3748952268.142000,0.000,Standby,155.234,156.409,0.000,0.000,0,0,2.000,2.000,0,0,4
3748952418.142000,0.000,Standby,154.907,156.074,0.000,0.000,0,0,2.000,2.000,0,0,4
3748952568.142000,0.000,Standby,154.581,155.740,0.000,0.000,0,0,2.000,2.000,0,0,4
3748952718.142000,0.000,Standby,154.262,155.412,0.000,0.000,0,0,2.000,2.000,0,0,4
3748952868.142000,0.000,Standby,153.946,155.084,0.000,0.000,0,0,2.000,2.000,0,0,4
3748953018.142000,0.000,Standby,153.636,154.764,0.000,0.000,0,0,2.000,2.000,0,0,4
3748953168.142000,0.000,Standby,153.329,154.443,0.000,0.000,0,0,2.000,2.000,0,0,4
3748953318.142000,0.000,Standby,153.028,154.127,0.000,0.000,0,0,2.000,2.000,0,0,4
3748953468.142000,0.000,Standby,152.734,153.819,0.000,0.000,0,0,2.000,2.000,0,0,4
3748953618.142000,0.000,Standby,152.444,153.512,0.000,0.000,0,0,2.000,2.000,0,0,4
3748953768.142000,0.000,Standby,152.161,153.212,0.000,0.000,0,0,2.000,2.000,0,0,4
3748953918.142000,0.000,Standby,151.884,152.916,0.000,0.000,0,0,2.000,2.000,0,0,4
3748954068.142000,0.000,Standby,151.615,152.626,0.000,0.000,0,0,2.000,2.000,0,0,4
3748954218.142000,0.000,Standby,151.351,152.340,0.000,0.000,0,0,2.000,2.000,0,0,4
3748954368.142000,0.000,Standby,151.096,152.063,0.000,0.000,0,0,2.000,2.000,0,0,4
3748954518.142000,0.000,Standby,150.845,151.788,0.000,0.000,0,0,2.000,2.000,0,0,4
3748954668.142000,0.000,Standby,150.603,151.520,0.000,0.000,0,0,2.000,2.000,0,0,4
3748954818.142000,0.000,Standby,150.370,151.261,0.000,0.000,0,0,2.000,2.000,0,0,4
3748954968.142000,0.000,Standby,150.142,151.007,0.000,0.000,0,0,2.000,2.000,0,0,4
3748955118.142000,0.000,Standby,149.925,150.761,0.000,0.000,0,0,2.000,2.000,0,0,4
3748955268.142000,0.000,Standby,149.713,150.520,0.000,0.000,0,0,2.000,2.000,0,0,4
3748955418.142000,0.000,Standby,149.511,150.288,0.000,0.000,0,0,2.000,2.000,0,0,4
3748955568.142000,0.000,Standby,149.314,150.062,0.000,0.000,0,0,2.000,2.000,0,0,4
3748955718.142000,0.000,Standby,149.127,149.843,0.000,0.000,0,0,2.000,2.000,0,0,4
3748955868.142000,0.000,Standby,148.945,149.632,0.000,0.000,0,0,2.000,2.000,0,0,4
3748956018.142000,0.000,Standby,148.773,149.429,0.000,0.000,0,0,2.000,2.000,0,0,4
3748956168.142000,0.000,Standby,148.608,149.233,0.000,0.000,0,0,2.000,2.000,0,0,4
3748956318.142000,0.000,Standby,148.449,149.042,0.000,0.000,0,0,2.000,2.000,0,0,4
3748956468.142000,0.000,Standby,148.299,148.862,0.000,0.000,0,0,2.000,2.000,0,0,4
3748956618.142000,0.000,Standby,148.155,148.688,0.000,0.000,0,0,2.000,2.000,0,0,4
3748956768.142000,0.000,Standby,148.018,148.521,0.000,0.000,0,0,2.000,2.000,0,0,4
3748956918.142000,0.000,Standby,147.886,148.361,0.000,0.000,0,0,2.000,2.000,0,0,4
3748957068.142000,0.000,Standby,147.763,148.208,0.000,0.000,0,0,2.000,2.000,0,0,4
3748957218.142000,0.000,Standby,147.644,148.062,0.000,0.000,0,0,2.000,2.000,0,0,4
3748957368.142000,0.000,Standby,147.531,147.923,0.000,0.000,0,0,2.000,2.000,0,0,4
3748957518.142000,0.000,Standby,147.423,147.790,0.000,0.000,0,0,2.000,2.000,0,0,4
3748957668.142000,0.000,Standby,147.320,147.662,0.000,0.000,0,0,2.000,2.000,0,0,4
3748957818.142000,0.000,Standby,147.222,147.542,0.000,0.000,0,0,2.000,2.000,0,0,4
3748957968.142000,0.000,Standby,147.128,147.426,0.000,0.000,0,0,2.000,2.000,0,0,4
3748958118.142000,0.000,Standby,147.040,147.317,0.000,0.000,0,0,2.000,2.000,0,0,4
3748958268.142000,0.000,Standby,146.954,147.212,0.000,0.000,0,0,2.000,2.000,0,0,4
3748958418.142000,0.000,Standby,146.873,147.113,0.000,0.000,0,0,2.000,2.000,0,0,4
3748958568.142000,0.000,Standby,146.795,147.016,0.000,0.000,0,0,2.000,2.000,0,0,4
3748958718.142000,0.000,Standby,146.720,146.927,0.000,0.000,0,0,2.000,2.000,0,0,4
3748958868.142000,0.000,Standby,146.647,146.838,0.000,0.000,0,0,2.000,2.000,0,0,4
3748959018.142000,0.000,Standby,146.577,146.754,0.000,0.000,0,0,2.000,2.000,0,0,4
3748959168.142000,0.000,Standby,146.509,146.674,0.000,0.000,0,0,2.000,2.000,0,0,4
3748959318.142000,0.000,Standby,146.442,146.596,0.000,0.000,0,0,2.000,2.000,0,0,4
3748959468.142000,0.000,Standby,146.376,146.522,0.000,0.000,0,0,2.000,2.000,0,0,4
3748959618.142000,0.000,Standby,146.314,146.450,0.000,0.000,0,0,2.000,2.000,0,0,4
3748959768.142000,0.000,Standby,146.250,146.378,0.000,0.000,0,0,2.000,2.000,0,0,4
3748959918.142000,0.000,Standby,146.188,146.310,0.000,0.000,0,0,2.000,2.000,0,0,4
3748960068.142000,0.000,Standby,146.125,146.241,0.000,0.000,0,0,2.000,2.000,0,0,4
3748960218.142000,0.000,Standby,146.061,146.173,0.000,0.000,0,0,2.000,2.000,0,0,4
3748960368.142000,0.000,Standby,145.996,146.105,0.000,0.000,0,0,2.000,2.000,0,0,4
3748960518.142000,0.000,Standby,145.933,146.040,0.000,0.000,0,0,2.000,2.000,0,0,4
3748960668.142000,0.000,Standby,145.868,145.972,0.000,0.000,0,0,2.000,2.000,0,0,4
3748960818.142000,0.000,Standby,145.802,145.905,0.000,0.000,0,0,2.000,2.000,0,0,4
3748960968.142000,0.000,Standby,145.735,145.838,0.000,0.000,0,0,2.000,2.000,0,0,4
3748961118.142000,0.000,Standby,145.669,145.771,0.000,0.000,0,0,2.000,2.000,0,0,4
3748961268.142000,0.000,Standby,145.599,145.703,0.000,0.000,0,0,2.000,2.000,0,0,4
3748961418.142000,0.000,Standby,145.530,145.635,0.000,0.000,0,0,2.000,2.000,0,0,4
3748961568.142000,0.000,Standby,145.458,145.565,0.000,0.000,0,0,2.000,2.000,0,0,4
3748961718.142000,0.000,Standby,145.386,145.494,0.000,0.000,0,0,2.000,2.000,0,0,4
3748961868.142000,0.000,Standby,145.312,145.422,0.000,0.000,0,0,2.000,2.000,0,0,4
3748962018.142000,0.000,Standby,145.236,145.347,0.000,0.000,0,0,2.000,2.000,0,0,4
3748962168.142000,0.000,Standby,145.156,145.272,0.000,0.000,0,0,2.000,2.000,0,0,4
3748962318.142000,0.000,Standby,145.076,145.195,0.000,0.000,0,0,2.000,2.000,0,0,4
3748962468.142000,0.000,Standby,144.994,145.116,0.000,0.000,0,0,2.000,2.000,0,0,4
3748962618.142000,0.000,Standby,144.908,145.034,0.000,0.000,0,0,2.000,2.000,0,0,4
3748962768.142000,0.000,Standby,144.821,144.951,0.000,0.000,0,0,2.000,2.000,0,0,4
3748962918.142000,0.000,Standby,144.730,144.864,0.000,0.000,0,0,2.000,2.000,0,0,4
3748963068.142000,0.000,Standby,144.636,144.775,0.000,0.000,0,0,2.000,2.000,0,0,4
3748963218.142000,0.000,Standby,144.540,144.683,0.000,0.000,0,0,2.000,2.000,0,0,4
3748963368.142000,0.000,Standby,144.440,144.589,0.000,0.000,0,0,2.000,2.000,0,0,4
3748963518.142000,0.000,Standby,144.339,144.491,0.000,0.000,0,0,2.000,2.000,0,0,4
3748963668.142000,0.000,Standby,144.231,144.391,0.000,0.000,0,0,2.000,2.000,0,0,4
3748963818.142000,0.000,Standby,144.124,144.287,0.000,0.000,0,0,2.000,2.000,0,0,4
3748963968.142000,0.000,Standby,144.011,144.181,0.000,0.000,0,0,2.000,2.000,0,0,4
3748964118.142000,0.000,Standby,143.899,144.073,0.000,0.000,0,0,2.000,2.000,0,0,4
3748964268.142000,0.000,Standby,143.783,143.962,0.000,0.000,0,0,2.000,2.000,0,0,4
3748964418.142000,0.000,Standby,143.665,143.847,0.000,0.000,0,0,2.000,2.000,0,0,4
3748964568.142000,0.000,Standby,143.547,143.733,0.000,0.000,0,0,2.000,2.000,0,0,4
3748964718.142000,0.000,Standby,143.424,143.615,0.000,0.000,0,0,2.000,2.000,0,0,4
3748964868.142000,0.000,Standby,143.303,143.497,0.000,0.000,0,0,2.000,2.000,0,0,4
3748965018.142000,0.000,Standby,143.178,143.375,0.000,0.000,0,0,2.000,2.000,0,0,4
3748965168.142000,0.000,Standby,143.050,143.251,0.000,0.000,0,0,2.000,2.000,0,0,4
3748965318.142000,0.000,Standby,142.919,143.124,0.000,0.000,0,0,2.000,2.000,0,0,4
3748965468.142000,0.000,Standby,142.785,142.994,0.000,0.000,0,0,2.000,2.000,0,0,4
3748965618.142000,0.000,Standby,142.644,142.859,0.000,0.000,0,0,2.000,2.000,0,0,4
3748965768.142000,0.000,Standby,142.502,142.721,0.000,0.000,0,0,2.000,2.000,0,0,4
3748965918.142000,0.000,Standby,142.354,142.579,0.000,0.000,0,0,2.000,2.000,0,0,4
3748966068.142000,0.000,Standby,142.201,142.431,0.000,0.000,0,0,2.000,2.000,0,0,4
3748966218.142000,0.000,Standby,142.046,142.282,0.000,0.000,0,0,2.000,2.000,0,0,4
3748966368.142000,0.000,Standby,141.886,142.128,0.000,0.000,0,0,2.000,2.000,0,0,4
3748966518.142000,0.000,Standby,141.721,141.970,0.000,0.000,0,0,2.000,2.000,0,0,4
3748966668.142000,0.000,Standby,141.553,141.806,0.000,0.000,0,0,2.000,2.000,0,0,4
3748966818.142000,0.000,Standby,141.382,141.641,0.000,0.000,0,0,2.000,2.000,0,0,4
3748966968.142000,0.000,Standby,141.206,141.471,0.000,0.000,0,0,2.000,2.000,0,0,4
3748967118.142000,0.000,Standby,141.028,141.299,0.000,0.000,0,0,2.000,2.000,0,0,4
3748967268.142000,0.000,Standby,140.844,141.119,0.000,0.000,0,0,2.000,2.000,0,0,4
3748967418.142000,0.000,Standby,140.658,140.939,0.000,0.000,0,0,2.000,2.000,0,0,4
3748967568.142000,0.000,Standby,140.468,140.755,0.000,0.000,0,0,2.000,2.000,0,0,4
3748967718.142000,0.000,Standby,140.275,140.567,0.000,0.000,0,0,2.000,2.000,0,0,4
3748967868.142000,0.000,Standby,140.077,140.376,0.000,0.000,0,0,2.000,2.000,0,0,4
3748968018.142000,0.000,Standby,139.876,140.180,0.000,0.000,0,0,2.000,2.000,0,0,4
3748968168.142000,0.000,Standby,139.673,139.982,0.000,0.000,0,0,2.000,2.000,0,0,4
3748968318.142000,0.000,Standby,139.464,139.779,0.000,0.000,0,0,2.000,2.000,0,0,4
3748968468.142000,0.000,Standby,139.248,139.570,0.000,0.000,0,0,2.000,2.000,0,0,4
3748968618.142000,0.000,Standby,139.022,139.353,0.000,0.000,0,0,2.000,2.000,0,0,4
3748968768.142000,0.000,Standby,138.789,139.130,0.000,0.000,0,0,2.000,2.000,0,0,4
3748968918.142000,0.000,Standby,138.553,138.902,0.000,0.000,0,0,2.000,2.000,0,0,4
3748969068.142000,0.000,Standby,138.310,138.668,0.000,0.000,0,0,2.000,2.000,0,0,4
3748969218.142000,0.000,Standby,138.066,138.432,0.000,0.000,0,0,2.000,2.000,0,0,4
3748969368.142000,0.000,Standby,137.818,138.192,0.000,0.000,0,0,2.000,2.000,0,0,4
3748969518.142000,0.000,Standby,137.575,137.954,0.000,0.000,0,0,2.000,2.000,0,0,4
3748969668.142000,0.000,Standby,137.330,137.713,0.000,0.000,0,0,2.000,2.000,0,0,4
3748969818.142000,0.000,Standby,137.086,137.472,0.000,0.000,0,0,2.000,2.000,0,0,4
3748969968.142000,0.000,Standby,136.840,137.231,0.000,0.000,0,0,2.000,2.000,0,0,4
3748970118.142000,0.000,Standby,136.595,136.988,0.000,0.000,0,0,2.000,2.000,0,0,4
3748970268.142000,0.000,Standby,136.348,136.743,0.000,0.000,0,0,2.000,2.000,0,0,4
3748970418.142000,0.000,Standby,136.097,136.496,0.000,0.000,0,0,2.000,2.000,0,0,4
3748970568.142000,0.000,Standby,135.846,136.249,0.000,0.000,0,0,2.000,2.000,0,0,4
3748970718.142000,0.000,Standby,135.589,135.996,0.000,0.000,0,0,2.000,2.000,0,0,4
3748970868.142000,0.000,Standby,135.332,135.743,0.000,0.000,0,0,2.000,2.000,0,0,4
3748971018.142000,0.000,Standby,135.068,135.484,0.000,0.000,0,0,2.000,2.000,0,0,4
3748971168.142000,0.000,Standby,134.805,135.226,0.000,0.000,0,0,2.000,2.000,0,0,4
3748971318.142000,0.000,Standby,134.538,134.963,0.000,0.000,0,0,2.000,2.000,0,0,4
3748971468.142000,0.000,Standby,134.272,134.701,0.000,0.000,0,0,2.000,2.000,0,0,4
3748971618.142000,0.000,Standby,134.000,134.435,0.000,0.000,0,0,2.000,2.000,0,0,4
3748971768.142000,0.000,Standby,133.729,134.168,0.000,0.000,0,0,2.000,2.000,0,0,4
3748971918.142000,0.000,Standby,133.455,133.897,0.000,0.000,0,0,2.000,2.000,0,0,4
3748972068.142000,0.000,Standby,133.180,133.626,0.000,0.000,0,0,2.000,2.000,0,0,4
3748972218.142000,0.000,Standby,132.905,133.354,0.000,0.000,0,0,2.000,2.000,0,0,4
3748972368.142000,0.000,Standby,132.624,133.078,0.000,0.000,0,0,2.000,2.000,0,0,4
3748972518.142000,0.000,Standby,132.342,132.800,0.000,0.000,0,0,2.000,2.000,0,0,4
3748972668.142000,0.000,Standby,132.056,132.518,0.000,0.000,0,0,2.000,2.000,0,0,4
3748972818.142000,0.000,Standby,131.767,132.234,0.000,0.000,0,0,2.000,2.000,0,0,4
3748972968.142000,0.000,Standby,131.473,131.945,0.000,0.000,0,0,2.000,2.000,0,0,4
3748973118.142000,0.000,Standby,131.178,131.656,0.000,0.000,0,0,2.000,2.000,0,0,4
3748973268.142000,0.000,Standby,130.880,131.363,0.000,0.000,0,0,2.000,2.000,0,0,4
3748973418.142000,0.000,Standby,130.580,131.067,0.000,0.000,0,0,2.000,2.000,0,0,4
3748973568.142000,0.000,Standby,130.279,130.771,0.000,0.000,0,0,2.000,2.000,0,0,4
3748973718.142000,0.000,Standby,129.976,130.472,0.000,0.000,0,0,2.000,2.000,0,0,4
3748973868.142000,0.000,Standby,129.676,130.176,0.000,0.000,0,0,2.000,2.000,0,0,4
3748974018.142000,0.000,Standby,129.374,129.877,0.000,0.000,0,0,2.000,2.000,0,0,4
3748974168.142000,0.000,Standby,129.072,129.578,0.000,0.000,0,0,2.000,2.000,0,0,4
3748974318.142000,0.000,Standby,128.769,129.277,0.000,0.000,0,0,2.000,2.000,0,0,4
3748974468.142000,0.000,Standby,128.468,128.978,0.000,0.000,0,0,2.000,2.000,0,0,4
3748974618.142000,0.000,Standby,128.162,128.674,0.000,0.000,0,0,2.000,2.000,0,0,4
3748974768.142000,0.000,Standby,127.857,128.371,0.000,0.000,0,0,2.000,2.000,0,0,4
3748974918.142000,0.000,Standby,127.550,128.068,0.000,0.000,0,0,2.000,2.000,0,0,4
3748975068.142000,0.000,Standby,127.240,127.761,0.000,0.000,0,0,2.000,2.000,0,0,4
3748975218.142000,0.000,Standby,126.933,127.457,0.000,0.000,0,0,2.000,2.000,0,0,4
3748975368.142000,0.000,Standby,126.625,127.149,0.000,0.000,0,0,2.000,2.000,0,0,4
3748975518.142000,0.000,Standby,126.318,126.845,0.000,0.000,0,0,2.000,2.000,0,0,4
3748975668.142000,0.000,Standby,126.008,126.537,0.000,0.000,0,0,2.000,2.000,0,0,4
3748975818.142000,0.000,Standby,125.697,126.230,0.000,0.000,0,0,2.000,2.000,0,0,4
3748975968.142000,0.000,Standby,125.383,125.918,0.000,0.000,0,0,2.000,2.000,0,0,4
3748976118.142000,0.000,Standby,125.069,125.608,0.000,0.000,0,0,2.000,2.000,0,0,4
3748976268.142000,0.000,Standby,124.750,125.292,0.000,0.000,0,0,2.000,2.000,0,0,4
3748976418.142000,0.000,Standby,124.431,124.976,0.000,0.000,0,0,2.000,2.000,0,0,4
3748976568.142000,0.000,Standby,124.113,124.661,0.000,0.000,0,0,2.000,2.000,0,0,4
3748976718.142000,0.000,Standby,123.792,124.344,0.000,0.000,0,0,2.000,2.000,0,0,4
3748976868.142000,0.000,Standby,123.471,124.026,0.000,0.000,0,0,2.000,2.000,0,0,4
3748977018.142000,0.000,Standby,123.147,123.704,0.000,0.000,0,0,2.000,2.000,0,0,4
3748977168.142000,0.000,Standby,122.823,123.384,0.000,0.000,0,0,2.000,2.000,0,0,4
3748977318.142000,0.000,Standby,122.495,123.059,0.000,0.000,0,0,2.000,2.000,0,0,4
3748977468.142000,0.000,Standby,122.166,122.734,0.000,0.000,0,0,2.000,2.000,0,0,4
3748977618.142000,0.000,Standby,121.834,122.405,0.000,0.000,0,0,2.000,2.000,0,0,4
3748977768.142000,0.000,Standby,121.502,122.077,0.000,0.000,0,0,2.000,2.000,0,0,4
3748977918.142000,0.000,Standby,121.173,121.750,0.000,0.000,0,0,2.000,2.000,0,0,4
3748978068.142000,0.000,Standby,120.841,121.420,0.000,0.000,0,0,2.000,2.000,0,0,4
3748978218.142000,0.000,Standby,120.510,121.091,0.000,0.000,0,0,2.000,2.000,0,0,4
3748978368.142000,0.000,Standby,120.175,120.759,0.000,0.000,0,0,2.000,2.000,0,0,4
3748978518.142000,0.000,Standby,119.844,120.430,0.000,0.000,0,0,2.000,2.000,0,0,4
3748978668.142000,0.000,Standby,119.510,120.097,0.000,0.000,0,0,2.000,2.000,0,0,4
3748978818.142000,0.000,Standby,119.174,119.765,0.000,0.000,0,0,2.000,2.000,0,0,4
3748978968.142000,0.000,Standby,118.835,119.428,0.000,0.000,0,0,2.000,2.000,0,0,4
3748979118.142000,0.000,Standby,118.496,119.091,0.000,0.000,0,0,2.000,2.000,0,0,4
3748979268.142000,0.000,Standby,118.157,118.756,0.000,0.000,0,0,2.000,2.000,0,0,4
3748979418.142000,0.000,Standby,117.818,118.418,0.000,0.000,0,0,2.000,2.000,0,0,4
3748979568.142000,0.000,Standby,117.479,118.082,0.000,0.000,0,0,2.000,2.000,0,0,4
3748979718.142000,0.000,Standby,117.139,117.745,0.000,0.000,0,0,2.000,2.000,0,0,4
3748979868.142000,0.000,Standby,116.805,117.409,0.000,0.000,0,0,2.000,2.000,0,0,4
3748980018.142000,0.000,Standby,116.465,117.071,0.000,0.000,0,0,2.000,2.000,0,0,4
3748980168.142000,0.000,Standby,116.127,116.735,0.000,0.000,0,0,2.000,2.000,0,0,4
3748980318.142000,0.000,Standby,115.787,116.397,0.000,0.000,0,0,2.000,2.000,0,0,4
3748980468.142000,0.000,Standby,115.448,116.059,0.000,0.000,0,0,2.000,2.000,0,0,4
3748980618.142000,0.000,Standby,115.110,115.722,0.000,0.000,0,0,2.000,2.000,0,0,4
3748980768.142000,0.000,Standby,114.769,115.383,0.000,0.000,0,0,2.000,2.000,0,0,4
3748980918.142000,0.000,Standby,114.428,115.045,0.000,0.000,0,0,2.000,2.000,0,0,4
3748981068.142000,0.000,Standby,114.086,114.704,0.000,0.000,0,0,2.000,2.000,0,0,4
3748981218.142000,0.000,Standby,113.748,114.367,0.000,0.000,0,0,2.000,2.000,0,0,4
3748981368.142000,0.000,Standby,113.408,114.028,0.000,0.000,0,0,2.000,2.000,0,0,4
3748981518.142000,0.000,Standby,113.072,113.692,0.000,0.000,0,0,2.000,2.000,0,0,4
3748981668.142000,0.000,Standby,112.736,113.355,0.000,0.000,0,0,2.000,2.000,0,0,4
3748981818.142000,0.000,Standby,112.397,113.017,0.000,0.000,0,0,2.000,2.000,0,0,4
3748981968.142000,0.000,Standby,112.064,112.685,0.000,0.000,0,0,2.000,2.000,0,0,4
3748982118.142000,0.000,Standby,111.728,112.349,0.000,0.000,0,0,2.000,2.000,0,0,4
3748982268.142000,0.000,Standby,111.394,112.015,0.000,0.000,0,0,2.000,2.000,0,0,4
3748982418.142000,0.000,Standby,111.058,111.680,0.000,0.000,0,0,2.000,2.000,0,0,4
3748982568.142000,0.000,Standby,110.727,111.348,0.000,0.000,0,0,2.000,2.000,0,0,4
3748982718.142000,0.000,Standby,110.396,111.015,0.000,0.000,0,0,2.000,2.000,0,0,4
3748982868.142000,0.000,Standby,110.069,110.686,0.000,0.000,0,0,2.000,2.000,0,0,4
3748983018.142000,0.000,Standby,109.737,110.356,0.000,0.000,0,0,2.000,2.000,0,0,4
3748983168.142000,0.000,Standby,109.412,110.028,0.000,0.000,0,0,2.000,2.000,0,0,4
3748983318.142000,0.000,Standby,109.085,109.700,0.000,0.000,0,0,2.000,2.000,0,0,4
3748983468.142000,0.000,Standby,108.759,109.373,0.000,0.000,0,0,2.000,2.000,0,0,4
3748983618.142000,0.000,Standby,108.436,109.048,0.000,0.000,0,0,2.000,2.000,0,0,4
3748983768.142000,0.000,Standby,108.109,108.722,0.000,0.000,0,0,2.000,2.000,0,0,4
3748983918.142000,0.000,Standby,107.786,108.397,0.000,0.000,0,0,2.000,2.000,0,0,4
3748984068.142000,0.000,Standby,107.461,108.072,0.000,0.000,0,0,2.000,2.000,0,0,4
3748984218.142000,0.000,Standby,107.141,107.751,0.000,0.000,0,0,2.000,2.000,0,0,4
3748984368.142000,0.000,Standby,106.823,107.430,0.000,0.000,0,0,2.000,2.000,0,0,4
3748984518.142000,0.000,Standby,106.508,107.114,0.000,0.000,0,0,2.000,2.000,0,0,4
3748984668.142000,0.000,Standby,106.192,106.795,0.000,0.000,0,0,2.000,2.000,0,0,4
3748984818.142000,0.000,Standby,105.877,106.479,0.000,0.000,0,0,2.000,2.000,0,0,4
3748984968.142000,0.000,Standby,105.564,106.165,0.000,0.000,0,0,2.000,2.000,0,0,4
3748985118.142000,0.000,Standby,104.973,105.648,0.000,0.000,0,0,2.000,2.000,0,0,4
3748985268.142000,0.000,Standby,103.212,104.427,0.000,0.000,0,0,2.000,2.000,0,0,4
3748985418.142000,0.000,Standby,100.971,102.773,0.000,0.000,0,0,2.000,2.000,0,0,4
3748985568.142000,0.000,Standby,98.415,100.779,0.000,0.000,0,0,2.000,2.000,0,0,4
3748985718.142000,0.000,Standby,95.570,98.439,0.000,0.000,0,0,2.000,2.000,0,0,4
3748985868.142000,0.000,Standby,92.538,95.875,0.000,0.000,0,0,2.000,2.000,0,0,4
3748986018.142000,0.000,Standby,89.311,93.008,0.000,0.000,0,0,2.000,2.000,0,0,4
3748986168.142000,0.000,Standby,85.931,89.884,0.000,0.000,0,0,2.000,2.000,0,0,4
3748986318.142000,0.000,Standby,82.449,86.615,0.000,0.000,0,0,2.000,2.000,0,0,4
3748986468.142000,0.000,Standby,78.825,83.200,0.000,0.000,0,0,2.000,2.000,0,0,4
3748986618.142000,0.000,Standby,75.127,79.774,0.000,0.000,0,0,2.000,2.000,0,0,4
3748986768.142000,0.000,Standby,71.288,76.162,0.000,0.000,0,0,2.000,2.000,0,0,4
3748986918.142000,0.000,Standby,67.345,72.363,0.000,0.000,0,0,2.000,2.000,0,0,4
3748987068.142000,0.000,Standby,63.215,68.351,0.000,0.000,0,0,2.000,2.000,0,0,4
3748987218.142000,0.000,Standby,58.910,64.036,0.000,0.000,0,0,2.000,2.000,0,0,4
3748987368.142000,0.000,Standby,54.304,59.441,0.000,0.000,0,0,2.000,2.000,0,0,4
3748987518.142000,0.000,Standby,49.317,54.378,0.000,0.000,0,0,2.000,2.000,0,0,4
3748987668.142000,0.000,Standby,43.765,48.653,0.000,0.000,0,0,2.000,2.000,0,0,4
3748987818.142000,0.000,Standby,37.082,41.564,0.000,0.000,0,0,2.000,2.000,0,0,4
3748987968.142000,0.000,Standby,28.051,31.467,0.000,0.000,0,0,2.000,2.000,0,0,4
3748988118.142000,0.000,Standby,10.347,9.462,0.000,0.000,0,0,2.000,2.000,0,0,4
3748988268.142000,0.000,Standby,4.998,4.303,0.000,0.000,0,0,2.000,2.000,0,0,4
3748988418.142000,0.000,Standby,2.611,2.544,0.000,0.000,0,0,2.000,2.000,0,0,4
3748988568.142000,0.000,Standby,2.767,3.240,0.000,0.000,0,0,2.000,2.000,0,0,4
3748988718.142000,0.000,Standby,2.602,2.929,0.000,0.000,0,0,2.000,2.000,0,0,4
3748988868.142000,0.000,Standby,2.590,3.110,0.000,0.000,0,0,2.000,2.000,0,0,4
3748989018.142000,0.000,Standby,2.618,3.205,0.000,0.000,0,0,2.000,2.000,0,0,4
3748989168.142000,0.000,Standby,2.635,3.280,0.000,0.000,0,0,2.000,2.000,0,0,4
3748989318.142000,0.000,Standby,2.607,3.315,0.000,0.000,0,0,2.000,2.000,0,0,4
3748989468.142000,0.000,Standby,2.676,3.378,0.000,0.000,0,0,2.000,2.000,0,0,4
3748989618.142000,0.000,Standby,2.638,3.385,0.000,0.000,0,0,2.000,2.000,0,0,4
3748989768.142000,0.000,Standby,2.647,3.460,0.000,0.000,0,0,2.000,2.000,0,0,4
3748989918.142000,0.000,Standby,2.655,3.467,0.000,0.000,0,0,2.000,2.000,0,0,4
3748990068.142000,0.000,Standby,2.676,3.455,0.000,0.000,0,0,2.000,2.000,0,0,4
3748990218.142000,0.000,Standby,2.610,3.337,0.000,0.000,0,0,2.000,2.000,0,0,4
3748990368.142000,0.000,Standby,2.606,2.324,0.000,0.000,0,0,2.000,2.000,0,0,4
3748990518.142000,0.000,Standby,2.638,3.448,0.000,0.000,0,0,2.000,2.000,0,0,4
3748990668.142000,0.000,Standby,2.614,2.295,0.000,0.000,0,0,2.000,2.000,0,0,4
3748990818.142000,0.000,Standby,2.621,2.146,0.000,0.000,0,0,2.000,2.000,0,0,4
3748990968.142000,0.000,Standby,2.624,2.199,0.000,0.000,0,0,2.000,2.000,0,0,4
3748991118.142000,0.000,Standby,2.607,2.369,0.000,0.000,0,0,2.000,2.000,0,0,4
3748991268.142000,0.000,Standby,2.631,3.426,0.000,0.000,0,0,2.000,2.000,0,0,4
3748991418.142000,0.000,Standby,2.664,3.431,0.000,0.000,0,0,2.000,2.000,0,0,4
3748991568.142000,0.000,Standby,2.681,3.415,0.000,0.000,0,0,2.000,2.000,0,0,4
3748991718.142000,0.000,Standby,2.607,3.464,0.000,0.000,0,0,2.000,2.000,0,0,4
3748991868.142000,0.000,Standby,2.685,3.445,0.000,0.000,0,0,2.000,2.000,0,0,4
3748992018.142000,0.000,Standby,2.597,3.448,0.000,0.000,0,0,2.000,2.000,0,0,4
3748992168.142000,0.000,Standby,2.621,3.420,0.000,0.000,0,0,2.000,2.000,0,0,4
3748992318.142000,0.000,Standby,2.604,3.426,0.000,0.000,0,0,2.000,2.000,0,0,4
3748992468.142000,0.000,Standby,2.607,2.190,0.000,0.000,0,0,2.000,2.000,0,0,4
3748992618.142000,0.000,Standby,2.673,2.088,0.000,0.000,0,0,2.000,2.000,0,0,4
3748992768.142000,0.000,Standby,1.908,2.367,0.000,0.000,0,0,2.000,2.000,0,0,4
3748992918.142000,0.000,Standby,1.953,5.278,0.000,0.000,0,0,2.000,2.000,0,0,4
3748993068.142000,0.000,Standby,1.555,1.985,0.000,0.000,0,0,1.500,1.500,0,0,4
3748993218.142000,0.000,Standby,1.500,1.500,0.000,0.000,0,0,1.500,1.500,3,0,1
3748993368.142000,0.000,Standby,1.404,0.000,0.000,0.000,0,0,1.500,1.500,0,0,4
3748993428.142000,0.000,Standby,1.386,0.000,0.000,0.000,0,0,1.500,1.500,0,0,4