File: log/20221201.dat
[Header]
; Displex Transport Data File (default extension .dat)
; Copyright 2016, Hechang LEI, hlei@ruc.edu.cn. All rights reserved.
BYAPP, Displex, 2.0
INFO, 9T mag, Release 2.0.
INFO, Channel 1, Temperature Sensor
INFO, Sample 1 Length (cm): 0.000000; Width (cm): 0.000000; Thickness (cm): 0.000000.

[Data]
Timestamp(s),Field(Oe),Field Status,TempA(K),TempB(K),TempC(K),TempD(K),Ramp1,Ramp2,Setpoint1,Setpoint2,Output1(%),Output2(%),Temp Status
3752702928.968800,0.000,Standby,2.116,2.000,34.961,3.089,0,0,2.000,2.000,0.230,0.020,1
3752702998.968800,0.000,Standby,2.094,2.000,34.961,3.090,0,0,2.000,2.000,0.000,0.020,1
3752703068.968800,0.000,Standby,2.107,2.000,34.961,3.090,0,0,2.000,2.000,0.000,0.020,1
3752703138.968800,0.000,Standby,2.113,2.000,34.961,3.089,0,0,2.000,2.000,0.250,0.020,1
3752703208.968800,0.000,Standby,2.098,2.000,34.962,3.090,0,0,2.000,2.000,0.050,0.020,1
3752703278.968800,0.000,Standby,2.117,1.999,34.962,3.089,0,0,2.000,2.000,0.230,0.020,1
3752703348.968800,1.277,Sweeping up,2.096,1.999,34.963,3.112,0,0,2.000,2.000,0.000,0.020,1
3752703418.968800,8.676,Sweeping up,2.119,2.000,34.960,3.828,0,0,2.000,2.000,0.100,0.020,1
3752703488.968800,16.278,Sweeping up,2.096,1.999,34.955,3.896,0,0,2.000,2.000,0.000,0.010,1
3752703558.968800,23.822,Sweeping to zero,2.114,1.998,34.966,3.808,0,0,2.000,2.000,0.230,0.000,1
3752703628.968800,17.283,Sweeping to zero,2.119,2.003,34.982,3.702,0,0,2.000,2.000,0.000,0.010,1
3752703698.968800,9.741,Sweeping to zero,2.113,2.004,34.988,3.850,0,0,2.000,2.000,0.180,0.020,1
3752703768.968800,2.149,Sweeping to zero,2.106,2.000,34.989,4.002,0,0,2.000,2.000,0.050,0.020,1
3752703838.968800,0.000,Standby,2.119,1.999,34.991,3.450,0,0,2.000,2.000,0.210,0.010,1
3752703908.968800,0.000,Standby,2.120,2.000,35.005,3.122,0,0,2.000,2.000,0.000,0.020,1
3752703978.968800,0.000,Standby,2.094,1.999,35.005,3.094,0,0,2.000,2.000,0.000,0.020,1
3752704048.968800,0.000,Standby,2.105,2.000,35.000,3.090,0,0,2.000,2.000,0.000,0.010,1
3752704118.968800,0.000,Standby,2.112,2.002,34.995,3.093,0,0,2.000,2.000,0.000,0.020,1
3752704188.968800,0.000,Standby,2.099,2.000,34.990,3.091,0,0,2.000,2.000,0.000,0.020,1
3752704258.968800,0.000,Standby,2.114,1.999,34.986,3.092,0,0,2.000,2.000,0.030,0.020,1
3752704328.968800,0.000,Standby,2.104,1.998,34.983,3.091,0,0,2.000,2.000,0.100,0.010,1
3752704398.968800,0.000,Standby,2.115,1.999,34.982,3.090,0,0,2.000,2.000,0.220,0.020,1
3752704468.968800,0.000,Standby,2.110,2.000,34.980,3.090,0,0,2.000,2.000,0.000,0.020,1
3752704538.968800,0.000,Standby,2.096,1.998,34.978,3.090,0,0,2.000,2.000,0.000,0.010,1
3752704608.968800,0.000,Standby,2.115,2.004,34.976,3.090,0,0,2.000,2.000,0.090,0.020,1
3752704678.968800,0.000,Standby,2.100,2.000,34.975,3.090,0,0,2.000,2.000,0.000,0.020,1
3752704748.968800,0.000,Standby,2.114,1.999,34.973,3.090,0,0,2.000,2.000,0.000,0.020,1
3752704818.968800,0.000,Standby,2.115,2.001,34.974,3.090,0,0,2.000,2.000,0.260,0.010,1
3752704888.968800,0.000,Standby,2.089,2.000,34.974,3.091,0,0,2.000,2.000,0.000,0.020,1
3752704958.968800,0.000,Standby,2.114,1.998,34.974,3.091,0,0,2.000,2.000,0.260,0.020,1
3752705028.968800,0.000,Standby,2.103,2.000,34.973,3.090,0,0,2.000,2.000,0.100,0.020,1
3752705098.968800,0.000,Standby,2.105,2.000,34.972,3.089,0,0,2.000,2.000,0.000,0.020,1
3752705168.968800,0.000,Standby,2.112,2.000,34.971,3.089,0,0,2.000,2.000,0.250,0.020,1
3752705238.968800,0.000,Standby,2.096,2.000,34.970,3.089,0,0,2.000,2.000,0.000,0.020,1
3752705308.968800,0.000,Standby,2.116,2.000,34.970,3.089,0,0,2.000,2.000,0.160,0.020,1
3752705378.968800,0.000,Standby,2.096,1.999,34.970,3.090,0,0,2.000,2.000,0.000,0.020,1
3752705448.968800,0.000,Standby,2.111,2.000,34.968,3.089,0,0,2.000,2.000,0.140,0.020,1
3752705518.968800,0.000,Standby,2.108,1.999,34.966,3.089,0,0,2.000,2.000,0.220,0.020,1
3752705588.968800,0.000,Standby,2.094,2.000,34.965,3.090,0,0,2.000,2.000,0.000,0.020,1
3752705658.968800,0.000,Standby,2.116,2.000,34.964,3.091,0,0,2.000,2.000,0.210,0.020,1
3752705728.968800,0.000,Standby,2.095,2.000,34.965,3.091,0,0,2.000,2.000,0.000,0.020,1
3752705798.968800,0.000,Standby,2.113,1.999,34.965,3.090,0,0,2.000,2.000,0.000,0.020,1
3752705868.968800,0.000,Standby,2.111,2.000,34.965,3.091,0,0,2.000,2.000,0.260,0.020,1
3752705938.968800,0.000,Standby,2.096,2.000,34.966,3.090,0,0,2.000,2.000,0.000,0.020,1
3752706008.968800,0.000,Standby,2.109,2.000,34.966,3.088,0,0,2.000,2.000,0.250,0.020,1
3752706078.968800,0.000,Standby,2.094,2.000,34.967,3.088,0,0,2.000,2.000,0.000,0.020,1
3752706148.968800,0.000,Standby,2.117,2.000,34.968,3.090,0,0,2.000,2.000,0.250,0.020,1
3752706218.968800,0.000,Standby,2.097,2.000,34.969,3.089,0,0,2.000,2.000,0.000,0.020,1
3752706288.968800,0.000,Standby,2.107,2.000,34.969,3.089,0,0,2.000,2.000,0.000,0.020,1
3752706358.968800,0.000,Standby,2.109,2.000,34.970,3.089,0,0,2.000,2.000,0.190,0.020,1
3752706428.968800,0.000,Standby,2.096,2.000,34.971,3.089,0,0,2.000,2.000,0.000,0.020,1
3752706498.968800,0.000,Standby,2.116,2.000,34.972,3.090,0,0,2.000,2.000,0.160,0.020,1
3752706568.968800,0.000,Standby,2.095,2.000,34.973,3.091,0,0,2.000,2.000,0.000,0.020,1
3752706638.968800,0.000,Standby,2.111,2.000,34.975,3.091,0,0,2.000,2.000,0.000,0.020,1
3752706708.968800,0.000,Standby,2.108,2.000,34.974,3.089,0,0,2.000,2.000,0.190,0.020,1
3752706778.968800,0.000,Standby,2.098,2.001,34.973,3.089,0,0,2.000,2.000,0.000,0.020,1
3752706848.968800,0.000,Standby,2.114,2.001,34.971,3.088,0,0,2.000,2.000,0.240,0.020,1
3752706918.968800,0.000,Standby,2.097,2.001,34.970,3.090,0,0,2.000,2.000,0.000,0.020,1
3752706988.968800,0.000,Standby,2.115,1.999,34.970,3.090,0,0,2.000,2.000,0.260,0.020,1
3752707058.968800,0.000,Standby,2.095,2.000,34.969,3.090,0,0,2.000,2.000,0.000,0.020,1
3752707128.968800,0.000,Standby,2.101,2.000,34.968,3.090,0,0,2.000,2.000,0.000,0.020,1
3752707198.968800,0.000,Standby,2.117,2.000,34.968,3.091,0,0,2.000,2.000,0.090,0.020,1
3752707268.968800,0.000,Standby,2.097,2.000,34.967,3.091,0,0,2.000,2.000,0.000,0.020,1
3752707338.968800,0.000,Standby,2.114,2.000,34.965,3.090,0,0,2.000,2.000,0.040,0.020,1
3752707408.968800,0.000,Standby,2.105,2.000,34.963,3.091,0,0,2.000,2.000,0.240,0.020,1
3752707478.968800,0.000,Standby,2.097,2.000,34.961,3.091,0,0,2.000,2.000,0.000,0.020,1
3752707548.968800,0.000,Standby,2.111,1.999,34.960,3.091,0,0,2.000,2.000,0.260,0.020,1
3752707618.968800,0.000,Standby,2.093,2.000,34.958,3.089,0,0,2.000,2.000,0.000,0.020,1
3752707688.968800,0.000,Standby,2.115,2.000,34.957,3.089,0,0,2.000,2.000,0.170,0.020,1
3752707758.968800,0.000,Standby,2.105,1.999,34.956,3.090,0,0,2.000,2.000,0.180,0.020,1
3752707828.968800,0.000,Standby,2.100,2.000,34.956,3.091,0,0,2.000,2.000,0.000,0.020,1
3752707898.968800,0.000,Standby,2.115,2.000,34.956,3.090,0,0,2.000,2.000,0.180,0.020,1
3752707968.968800,0.000,Standby,2.092,2.000,34.956,3.089,0,0,2.000,2.000,0.000,0.020,1
3752708038.968800,0.000,Standby,2.116,1.999,34.955,3.088,0,0,2.000,2.000,0.220,0.020,1
3752708108.968800,0.000,Standby,2.095,1.999,34.955,3.088,0,0,2.000,2.000,0.000,0.020,1
3752708178.968800,0.000,Standby,2.115,2.000,34.955,3.085,0,0,2.000,2.000,0.040,0.020,1
3752708248.968800,0.000,Standby,2.107,2.000,34.954,3.087,0,0,2.000,2.000,0.260,0.020,1
3752708318.968800,0.000,Standby,2.093,2.000,34.954,3.086,0,0,2.000,2.000,0.000,0.020,1
3752708403.424800,0.000,Standby,2.114,2.001,34.954,3.087,0,0,2.000,2.000,0.000,0.010,1
3752708473.424800,0.000,Standby,2.101,1.999,34.954,3.085,0,0,2.000,2.000,0.000,0.020,1
3752708543.424800,0.000,Standby,2.107,1.999,34.953,3.086,0,0,2.000,2.000,0.020,0.020,1
3752708613.424800,0.000,Standby,2.115,2.006,34.951,3.088,0,0,2.000,2.000,0.000,0.020,1
3752708683.424800,0.000,Standby,2.094,1.999,34.951,3.088,0,0,2.000,2.000,0.000,0.020,1
3752708753.424800,0.000,Standby,2.105,1.999,34.950,3.088,0,0,2.000,2.000,0.220,0.020,1
3752708823.424800,0.000,Standby,2.105,1.999,34.949,3.089,0,0,2.000,2.000,0.000,0.020,1
3752708893.424800,0.000,Standby,2.094,2.000,34.949,3.087,0,0,2.000,2.000,0.110,0.020,1
3752708963.424800,0.000,Standby,2.117,2.001,34.948,3.082,0,0,2.000,2.000,0.000,0.020,1
3752709046.333800,0.000,Standby,2.095,1.998,34.947,3.082,0,0,2.000,2.000,0.000,0.020,1
3752709116.333800,0.000,Standby,2.096,2.001,34.946,3.085,0,0,2.000,2.000,0.000,0.010,1
3752709284.307800,0.000,Standby,2.104,2.001,34.946,3.087,0,0,2.000,2.000,0.000,0.020,4
3752709354.307800,0.000,Standby,2.116,1.999,34.945,3.086,0,0,2.000,2.000,0.210,0.010,1
3752709424.307800,0.000,Standby,2.103,2.004,34.945,3.089,0,0,2.000,2.000,0.000,0.020,1
3752709494.307800,2.399,Sweeping up,2.096,2.000,34.945,3.160,0,0,2.000,2.000,0.200,0.020,1
3752709564.307800,9.893,Sweeping up,2.116,1.998,34.940,3.882,0,0,2.000,2.000,0.020,0.020,1
3752709634.307800,17.436,Sweeping up,2.118,2.000,34.938,3.880,0,0,2.000,2.000,0.000,0.010,1
3752709704.307800,24.981,Sweeping up,2.115,2.000,34.949,3.795,0,0,2.000,2.000,0.000,0.010,1
3752709774.307800,32.529,Sweeping up,2.119,2.000,34.965,3.731,0,0,2.000,2.000,0.000,0.010,1
3752709844.307800,40.135,Sweeping up,2.114,2.000,34.981,3.682,0,0,2.000,2.000,0.000,0.010,1
3752709914.307800,47.686,Sweeping up,2.111,2.000,35.000,3.644,0,0,2.000,2.000,0.000,0.010,1
3752709984.307800,54.897,Sweeping up,2.113,2.000,35.024,3.587,0,0,2.000,2.000,0.000,0.010,1
3752710054.307800,58.718,Sweeping up,2.107,2.000,35.053,3.380,0,0,2.000,2.000,0.030,0.010,1
3752710124.307800,62.505,Sweeping up,2.109,2.000,35.082,3.345,0,0,2.000,2.000,0.000,0.010,1
3752710194.307800,66.321,Sweeping up,2.105,2.000,35.108,3.334,0,0,2.000,2.000,0.000,0.010,1
3752710264.307800,70.107,Sweeping up,2.098,2.000,35.136,3.326,0,0,2.000,2.000,0.000,0.010,1
3752710334.307800,73.891,Sweeping up,2.097,1.999,35.168,3.319,0,0,2.000,2.000,0.000,0.010,1
3752710404.307800,77.704,Sweeping up,2.082,2.004,35.202,3.311,0,0,2.000,2.000,0.000,0.010,1
3752710474.307800,81.477,Sweeping up,2.099,2.000,35.239,3.304,0,0,2.000,2.000,0.000,0.010,1
3752710544.307800,85.254,Sweeping up,2.102,2.000,35.280,3.295,0,0,2.000,2.000,0.000,0.010,1
3752710614.307800,89.035,Sweeping up,2.099,2.000,35.325,3.289,0,0,2.000,2.000,0.010,0.010,1
3752710684.307800,90.000,Sweeping up,2.096,2.000,35.378,3.150,0,0,2.000,2.000,0.000,0.010,1
3752710754.307800,90.000,Sweeping up,2.093,2.000,35.429,3.109,0,0,2.000,2.000,0.000,0.010,1
3752710824.307800,90.000,Sweeping up,2.090,2.000,35.474,3.106,0,0,2.000,2.000,0.000,0.010,1
3752710894.307800,90.000,Sweeping up,2.080,2.000,35.511,3.105,0,0,2.000,2.000,0.000,0.010,1
3752710964.307800,90.000,Sweeping up,2.071,2.000,35.546,3.103,0,0,2.000,2.000,0.030,0.010,1
3752711034.307800,90.000,Sweeping up,2.074,2.000,35.577,3.105,0,0,2.000,2.000,0.250,0.010,1
3752711104.307800,90.000,Sweeping up,2.092,2.000,35.603,3.105,0,0,2.000,2.000,0.200,0.010,1
3752711174.307800,90.000,Sweeping up,2.091,2.000,35.627,3.106,0,0,2.000,2.000,0.000,0.010,1
3752711244.307800,90.000,Sweeping up,2.083,2.000,35.648,3.105,0,0,2.000,2.000,0.000,0.010,1
3752711314.307800,90.000,Sweeping up,2.068,2.000,35.667,3.105,0,0,2.000,2.000,0.000,0.010,1
3752711384.307800,90.000,Sweeping up,2.073,1.999,35.684,3.106,0,0,2.000,2.000,0.270,0.010,1
3752711606.692800,90.000,Sweeping up,2.079,2.000,35.729,3.109,0,0,2.000,2.000,0.120,0.010,1
3752711676.692800,90.000,Sweeping up,2.088,1.999,35.742,3.105,0,0,2.000,2.000,0.000,0.010,1
3752711746.692800,90.000,Sweeping up,2.095,2.000,35.754,3.108,0,0,2.000,2.000,0.150,0.010,1
3752711816.692800,89.266,Sweeping down,2.086,1.998,35.764,3.114,0,0,2.000,2.000,0.220,0.010,1
3752711886.692800,85.513,Sweeping down,2.089,2.002,35.773,3.252,0,0,2.000,2.000,0.230,0.000,1
3752711956.692800,81.727,Sweeping down,2.085,1.999,35.773,3.284,0,0,2.000,2.000,0.000,0.010,1
3752712026.692800,77.945,Sweeping down,2.075,1.999,35.763,3.299,0,0,2.000,2.000,0.000,0.000,1
3752712096.692800,74.139,Sweeping down,2.079,2.000,35.746,3.307,0,0,2.000,2.000,0.000,0.000,1
3752712166.692800,70.358,Sweeping down,2.080,1.999,35.722,3.316,0,0,2.000,2.000,0.000,0.010,1
3752712236.692800,66.579,Sweeping down,2.086,1.999,35.693,3.322,0,0,2.000,2.000,0.200,0.000,1
3752712306.692800,62.766,Sweeping down,2.103,2.005,35.660,3.328,0,0,2.000,2.000,0.180,0.010,1
3752712376.692800,58.986,Sweeping down,2.108,1.999,35.624,3.338,0,0,2.000,2.000,0.250,0.010,1
3752712446.692800,55.205,Sweeping down,2.110,1.999,35.589,3.349,0,0,2.000,2.000,0.060,0.010,1
3752712516.692800,49.058,Sweeping down,2.094,1.999,35.549,3.548,0,0,2.000,2.000,0.000,0.010,1
3752712586.692800,41.392,Sweeping down,2.107,1.999,35.504,3.631,0,0,2.000,2.000,0.000,0.010,1
3752712656.692800,33.895,Sweeping down,2.096,1.999,35.460,3.675,0,0,2.000,2.000,0.000,0.010,1
3752712726.692800,26.344,Sweeping down,2.099,2.001,35.419,3.719,0,0,2.000,2.000,0.000,0.010,1
3752712796.692800,18.795,Sweeping down,2.112,2.000,35.381,3.776,0,0,2.000,2.000,0.220,0.010,1
3752712866.692800,11.248,Sweeping down,2.114,1.999,35.345,3.852,0,0,2.000,2.000,0.200,0.020,1
3752712936.692800,3.650,Sweeping down,2.112,2.001,35.313,3.978,0,0,2.000,2.000,0.240,0.020,1
3752713006.692800,-3.704,Sweeping down,2.117,1.999,35.283,4.360,0,0,2.000,2.000,0.000,0.020,1
3752713076.692800,-11.263,Sweeping down,2.119,1.999,35.258,4.132,0,0,2.000,2.000,0.230,0.010,1
3752713146.692800,-18.865,Sweeping down,2.113,2.000,35.250,3.911,0,0,2.000,2.000,0.210,0.010,1
3752713216.692800,-26.411,Sweeping down,2.107,1.998,35.243,3.801,0,0,2.000,2.000,0.200,0.010,1
3752713286.692800,-33.959,Sweeping down,2.103,1.999,35.237,3.733,0,0,2.000,2.000,0.250,0.010,1
3752713356.692800,-41.507,Sweeping down,2.103,1.999,35.233,3.685,0,0,2.000,2.000,0.250,0.010,1
3752713426.692800,-49.056,Sweeping down,2.113,1.999,35.238,3.645,0,0,2.000,2.000,0.250,0.010,1
3752713496.692800,-55.646,Sweeping down,2.101,2.000,35.248,3.528,0,0,2.000,2.000,0.160,0.010,1
3752713566.692800,-59.428,Sweeping down,2.108,1.999,35.266,3.374,0,0,2.000,2.000,0.260,0.010,1
3752713949.100800,-80.104,Sweeping down,2.081,1.999,35.388,3.308,0,0,2.000,2.000,0.000,0.010,1
3752714019.100800,-83.881,Sweeping down,2.085,1.999,35.421,3.301,0,0,2.000,2.000,0.250,0.000,1
3752714089.100800,-87.657,Sweeping down,2.080,2.002,35.458,3.292,0,0,2.000,2.000,0.240,0.010,1
3752714159.100800,-89.999,Sweeping down,2.091,1.999,35.502,3.202,0,0,2.000,2.000,0.250,0.010,1
3752714229.100800,-90.000,Sweeping down,2.093,1.999,35.552,3.118,0,0,2.000,2.000,0.180,0.010,1
3752714299.100800,-90.000,Sweeping down,1.627,1.746,35.596,3.108,0,0,5.000,5.000,0.000,0.000,4
3752714369.100800,-90.000,Sweeping down,5.058,5.002,35.630,3.106,1,1,2.000,2.000,0.240,0.160,0
3752714439.100800,-90.000,Sweeping down,2.108,2.051,35.653,3.106,0,0,2.000,2.000,0.000,0.000,4
3752714509.100800,-90.000,Sweeping down,2.281,2.128,35.683,3.105,1,1,5.000,5.000,0.160,0.020,0
3752714579.100800,-90.000,Sweeping down,2.925,2.706,35.710,3.105,1,1,5.000,5.000,0.200,0.070,2
3752714649.100800,-90.000,Sweeping down,3.430,3.286,35.731,3.106,1,1,5.000,5.000,0.000,0.110,2
3752714719.100800,-90.000,Sweeping down,4.071,3.959,35.748,3.106,1,1,5.000,5.000,0.000,0.150,2
3752714789.100800,-90.000,Sweeping down,5.055,4.999,35.762,3.105,0,0,5.000,5.000,0.240,0.150,4
3752714859.100800,-90.000,Sweeping down,5.032,5.015,35.771,3.108,0,0,5.000,5.000,0.000,0.160,4
3752714929.100800,-90.000,Sweeping down,5.032,4.990,35.783,3.106,0,0,5.000,5.000,0.130,0.130,1
3752714999.100800,-90.000,Sweeping down,5.034,4.994,35.796,3.108,0,0,5.000,5.000,0.170,0.150,1
3752715069.100800,-90.000,Sweeping down,5.041,5.002,35.809,3.107,0,0,5.000,5.000,0.040,0.160,1
3752715139.100800,-88.595,Sweeping up,5.028,5.004,35.820,3.141,0,0,5.000,5.000,0.000,0.160,1
3752715209.100800,-84.822,Sweeping up,5.023,4.994,35.830,3.262,0,0,5.000,5.000,0.000,0.150,1
3752715279.100800,-81.014,Sweeping up,5.028,5.008,35.828,3.289,0,0,5.000,5.000,0.040,0.160,1
3752715349.100800,-77.237,Sweeping up,5.030,4.993,35.818,3.301,0,0,5.000,5.000,0.220,0.160,1
3752715419.100800,-73.457,Sweeping up,5.039,4.987,35.801,3.310,0,0,5.000,5.000,0.000,0.150,1
3752715489.100800,-69.678,Sweeping up,5.049,5.001,35.776,3.320,0,0,5.000,5.000,0.170,0.160,1
3752715559.100800,-65.872,Sweeping up,5.036,5.000,35.747,3.328,0,0,5.000,5.000,0.270,0.170,1
3752715629.100800,-62.091,Sweeping up,5.018,4.997,35.715,3.336,0,0,5.000,5.000,0.000,0.150,1
3752715699.100800,-58.316,Sweeping up,5.021,5.002,35.680,3.345,0,0,5.000,5.000,0.150,0.180,1
3752715945.160800,-36.254,Sweeping up,5.022,4.993,35.535,3.667,0,0,5.000,5.000,0.230,0.160,4
3752716015.160800,-28.647,Sweeping up,5.028,5.013,35.494,3.707,0,0,5.000,5.000,0.000,0.150,4
3752716085.160800,-21.101,Sweeping up,5.040,5.006,35.454,3.757,0,0,5.000,5.000,0.000,0.120,1
3752716155.160800,-13.555,Sweeping up,5.037,4.993,35.417,3.824,0,0,5.000,5.000,0.000,0.150,1
3752716225.160800,-6.013,Sweeping up,5.029,4.996,35.382,3.931,0,0,5.000,5.000,0.220,0.190,1
3752716295.160800,1.442,Sweeping up,5.015,4.986,35.351,4.116,0,0,5.000,5.000,0.220,0.140,1
3752716365.160800,8.954,Sweeping up,5.023,5.011,35.321,4.231,0,0,5.000,5.000,0.000,0.150,1
3752716435.160800,16.497,Sweeping up,5.022,4.994,35.308,3.964,0,0,5.000,5.000,0.000,0.140,1
3752716505.160800,24.044,Sweeping up,5.033,4.993,35.302,3.827,0,0,5.000,5.000,0.200,0.160,1
3752716575.160800,31.650,Sweeping up,5.031,5.018,35.295,3.751,0,0,5.000,5.000,0.220,0.150,1
3752716645.160800,39.200,Sweeping up,5.047,5.014,35.291,3.697,0,0,5.000,5.000,0.300,0.170,1
3752716715.160800,46.753,Sweeping up,5.032,5.001,35.293,3.658,0,0,5.000,5.000,0.060,0.170,1
3752716785.160800,54.311,Sweeping up,5.020,4.990,35.301,3.619,0,0,5.000,5.000,0.040,0.170,1
3752716855.160800,58.284,Sweeping up,5.025,4.993,35.316,3.397,0,0,5.000,5.000,0.180,0.110,1
3752716925.160800,62.066,Sweeping up,5.040,5.003,35.334,3.354,0,0,5.000,5.000,0.210,0.130,1
3752716995.160800,65.846,Sweeping up,5.018,4.996,35.351,3.341,0,0,5.000,5.000,0.030,0.140,1
3752717065.160800,69.625,Sweeping up,5.020,4.993,35.369,3.332,0,0,5.000,5.000,0.000,0.180,1
3752717135.160800,73.459,Sweeping up,5.043,5.010,35.391,3.321,0,0,5.000,5.000,0.020,0.180,1
3752717205.160800,77.210,Sweeping up,5.030,5.004,35.416,3.313,0,0,5.000,5.000,0.000,0.120,1
3752717275.160800,80.993,Sweeping up,5.033,5.002,35.446,3.307,0,0,5.000,5.000,0.120,0.150,1
3752717345.160800,84.769,Sweeping up,5.036,4.993,35.481,3.300,0,0,5.000,5.000,0.060,0.160,1
3752717415.160800,88.573,Sweeping up,5.049,5.008,35.521,3.293,0,0,5.000,5.000,0.140,0.180,1
3752717485.160800,90.000,Sweeping up,5.039,5.004,35.567,3.166,0,0,5.000,5.000,0.000,0.150,1
3752717555.160800,90.000,Sweeping up,5.026,5.002,35.614,3.117,0,0,5.000,5.000,0.310,0.170,1
3752717625.160800,90.000,Sweeping up,5.047,5.003,35.654,3.110,0,0,5.000,5.000,0.220,0.150,1
3752717695.160800,90.000,Sweeping up,5.024,4.997,35.688,3.113,0,0,5.000,5.000,0.080,0.180,1
3752717765.160800,90.000,Sweeping up,5.025,4.986,35.717,3.113,0,0,5.000,5.000,0.170,0.170,1
3752717835.160800,90.000,Sweeping up,5.021,4.995,35.742,3.112,0,0,5.000,5.000,0.000,0.200,1
3752717905.160800,90.000,Sweeping up,5.028,5.001,35.765,3.111,0,0,5.000,5.000,0.000,0.140,1
3752717975.160800,90.000,Sweeping up,5.032,4.996,35.784,3.111,0,0,5.000,5.000,0.000,0.170,1
3752718045.160800,90.000,Sweeping up,5.032,5.001,35.802,3.112,0,0,5.000,5.000,0.000,0.120,1
3752718115.160800,90.000,Sweeping up,5.038,5.004,35.818,3.112,0,0,5.000,5.000,0.010,0.150,1
3752718185.160800,90.000,Sweeping up,5.037,4.997,35.832,3.111,0,0,5.000,5.000,0.220,0.160,1
3752718255.160800,90.000,Sweeping up,5.037,5.011,35.843,3.112,0,0,5.000,5.000,0.160,0.140,1
3752718325.160800,90.000,Sweeping up,5.049,5.008,35.855,3.110,0,0,5.000,5.000,0.010,0.160,1
3752718395.160800,90.000,Sweeping up,5.047,4.999,35.865,3.106,0,0,5.000,5.000,0.220,0.170,1
3752718465.160800,90.000,Sweeping up,5.046,4.996,35.875,3.108,0,0,5.000,5.000,0.190,0.140,1
3752718535.160800,90.000,Sweeping up,5.045,5.008,35.883,3.112,0,0,5.000,5.000,0.130,0.140,1
3752718605.160800,90.000,Sweeping up,5.043,5.006,35.892,3.110,0,0,5.000,5.000,0.080,0.160,1
3752718675.160800,90.000,Sweeping up,5.030,5.000,35.900,3.111,0,0,5.000,5.000,0.000,0.150,1
3752718745.160800,90.000,Sweeping up,5.043,4.990,35.908,3.110,0,0,5.000,5.000,0.000,0.170,1
3752718815.160800,90.000,Sweeping up,5.028,4.989,35.917,3.109,0,0,5.000,5.000,0.000,0.150,1
3752718885.160800,90.000,Sweeping up,5.034,4.993,35.922,3.108,0,0,5.000,5.000,0.000,0.160,1
3752718955.160800,90.000,Sweeping up,5.034,5.007,35.928,3.108,0,0,5.000,5.000,0.020,0.170,1
3752719025.160800,90.000,Sweeping up,5.034,5.005,35.931,3.111,0,0,5.000,5.000,0.000,0.170,1
3752719095.160800,90.000,Sweeping up,5.035,5.009,35.936,3.111,0,0,5.000,5.000,0.210,0.160,1
3752719165.160800,90.000,Sweeping up,5.042,5.000,35.943,3.111,0,0,5.000,5.000,0.210,0.150,1
3752719235.160800,90.000,Sweeping up,5.032,5.004,35.948,3.110,0,0,5.000,5.000,0.220,0.110,1
3752719305.160800,90.000,Sweeping up,5.041,5.012,35.953,3.110,0,0,5.000,5.000,0.240,0.130,1
3752719375.160800,90.000,Sweeping up,5.043,4.996,35.958,3.111,0,0,5.000,5.000,0.230,0.150,1
3752719445.160800,90.000,Sweeping up,5.042,4.997,35.961,3.110,0,0,5.000,5.000,0.080,0.120,1
3752719515.160800,90.000,Sweeping up,5.042,4.994,35.965,3.110,0,0,5.000,5.000,0.230,0.170,1
3752719585.160800,90.000,Sweeping up,5.047,5.000,35.969,3.111,0,0,5.000,5.000,0.020,0.120,1
3752719655.160800,90.000,Sweeping up,5.036,5.000,35.972,3.110,0,0,5.000,5.000,0.000,0.130,1
3752719725.160800,90.000,Sweeping up,5.041,4.988,35.975,3.112,0,0,5.000,5.000,0.000,0.160,1
3752719795.160800,90.000,Sweeping up,5.053,5.015,35.978,3.114,0,0,5.000,5.000,0.070,0.120,1
3752719865.160800,90.000,Sweeping up,5.044,5.000,35.982,3.112,0,0,5.000,5.000,0.130,0.160,1
3752719935.160800,90.000,Sweeping up,5.031,5.001,35.985,3.113,0,0,5.000,5.000,0.240,0.140,4
3752720005.160800,90.000,Sweeping up,5.029,5.014,35.987,3.113,0,0,5.000,5.000,0.220,0.210,1
3752720075.160800,90.000,Sweeping up,5.042,4.993,35.990,3.114,0,0,5.000,5.000,0.190,0.130,1
3752720145.160800,90.000,Sweeping up,5.032,4.995,35.991,3.114,0,0,5.000,5.000,0.240,0.170,1
3752720215.160800,90.000,Sweeping up,7.102,7.081,35.993,3.114,1,1,10.000,10.000,0.200,0.250,2
3752720285.160800,90.000,Sweeping up,9.422,9.405,35.993,3.112,1,1,10.000,10.000,0.320,0.370,2
3752720355.160800,90.000,Sweeping up,9.999,10.008,35.991,3.114,0,0,10.000,10.000,0.260,0.340,4
3752720425.160800,90.000,Sweeping up,10.003,10.015,35.990,3.113,0,0,10.000,10.000,0.220,0.270,1
3752720495.160800,90.000,Sweeping up,9.999,9.979,35.994,3.112,0,0,10.000,10.000,0.210,0.310,4
3752720565.160800,90.000,Sweeping up,9.998,9.981,35.998,3.112,0,0,10.000,10.000,0.220,0.270,4
3752720635.160800,90.000,Sweeping up,10.003,10.006,36.003,3.112,0,0,10.000,10.000,0.230,0.330,4
3752720705.160800,90.000,Sweeping up,9.997,9.986,36.007,3.113,0,0,10.000,10.000,0.220,0.260,1
3752720775.160800,90.000,Sweeping up,10.001,9.997,36.014,3.111,0,0,10.000,10.000,0.200,0.250,1
3752720845.160800,90.000,Sweeping up,9.998,9.996,36.018,3.110,0,0,10.000,10.000,0.210,0.240,4
3752720915.160800,90.000,Sweeping up,10.000,10.005,36.023,3.109,0,0,10.000,10.000,0.240,0.270,1
3752720985.160800,90.000,Sweeping up,9.997,10.004,36.029,3.110,0,0,10.000,10.000,0.220,0.260,4
3752721055.160800,90.000,Sweeping up,10.002,10.011,36.033,3.111,0,0,10.000,10.000,0.250,0.310,1
3752721125.160800,90.000,Sweeping up,10.002,10.008,36.038,3.110,0,0,10.000,10.000,0.230,0.310,1
3752721195.160800,90.000,Sweeping up,10.000,9.996,36.040,3.113,0,0,10.000,10.000,0.240,0.270,4
3752721265.160800,90.000,Sweeping up,10.002,10.009,36.044,3.111,0,0,10.000,10.000,0.220,0.300,1
3752721335.160800,90.000,Sweeping up,10.002,9.998,36.049,3.111,0,0,10.000,10.000,0.220,0.300,4
3752721405.160800,90.000,Sweeping up,9.999,10.004,36.052,3.112,0,0,10.000,10.000,0.190,0.240,4
3752721475.160800,90.000,Sweeping up,10.001,9.998,36.056,3.113,0,0,10.000,10.000,0.200,0.260,1
3752721545.160800,90.000,Sweeping up,10.000,9.985,36.060,3.110,0,0,10.000,10.000,0.210,0.260,4
3752721615.160800,90.000,Sweeping up,9.999,10.013,36.063,3.112,0,0,10.000,10.000,0.230,0.270,4
3752721685.160800,90.000,Sweeping up,9.997,9.980,36.065,3.110,0,0,10.000,10.000,0.200,0.270,4
3752721755.160800,90.000,Sweeping up,10.000,10.011,36.068,3.111,0,0,10.000,10.000,0.220,0.310,1
3752721825.160800,90.000,Sweeping up,10.000,9.993,36.071,3.111,0,0,10.000,10.000,0.230,0.250,1
3752721895.160800,87.553,Sweeping down,9.998,9.992,36.074,3.203,0,0,10.000,10.000,0.210,0.300,1
3752721965.160800,83.740,Sweeping down,9.998,10.001,36.069,3.279,0,0,10.000,10.000,0.230,0.320,1
3752722035.160800,79.956,Sweeping down,9.996,9.991,36.056,3.297,0,0,10.000,10.000,0.230,0.300,1
3752722105.160800,76.173,Sweeping down,10.000,10.002,36.036,3.308,0,0,10.000,10.000,0.200,0.290,1
3752722175.160800,72.394,Sweeping down,10.001,9.999,36.009,3.317,0,0,10.000,10.000,0.210,0.290,4
3752722245.160800,68.586,Sweeping down,10.001,9.984,35.975,3.327,0,0,10.000,10.000,0.220,0.300,4
3752722315.160800,64.808,Sweeping down,10.000,10.009,35.937,3.334,0,0,10.000,10.000,0.200,0.250,4
3752722385.160800,61.025,Sweeping down,9.996,9.979,35.897,3.342,0,0,10.000,10.000,0.220,0.270,4
3752722455.160800,57.244,Sweeping down,10.002,10.013,35.855,3.351,0,0,10.000,10.000,0.230,0.280,4
3752722525.160800,53.043,Sweeping down,10.003,10.004,35.813,3.396,0,0,10.000,10.000,0.200,0.230,4
3752722595.160800,45.521,Sweeping down,10.000,9.989,35.764,3.606,0,0,10.000,10.000,0.210,0.280,4
3752722665.160800,37.967,Sweeping down,10.001,9.994,35.715,3.658,0,0,10.000,10.000,0.220,0.290,4
3752722735.160800,30.414,Sweeping down,9.999,9.987,35.667,3.701,0,0,10.000,10.000,0.210,0.300,4
3752722805.160800,22.807,Sweeping down,9.999,10.003,35.623,3.747,0,0,10.000,10.000,0.190,0.260,1
3752722875.160800,15.259,Sweeping down,10.002,9.993,35.580,3.810,0,0,10.000,10.000,0.240,0.290,1
3752722945.160800,7.715,Sweeping down,9.999,10.011,35.540,3.905,0,0,10.000,10.000,0.220,0.270,1
3752723015.160800,0.225,Sweeping down,10.003,10.022,35.505,4.063,0,0,10.000,10.000,0.200,0.260,1
3752723085.160800,-7.253,Sweeping down,9.999,10.002,35.471,4.312,0,0,10.000,10.000,0.200,0.280,4
3752723155.160800,-14.797,Sweeping down,9.999,9.992,35.450,4.012,0,0,10.000,10.000,0.190,0.240,4
3752723225.160800,-22.342,Sweeping down,10.001,10.019,35.441,3.852,0,0,10.000,10.000,0.210,0.290,1
3752723295.160800,-29.888,Sweeping down,10.000,10.013,35.430,3.767,0,0,10.000,10.000,0.200,0.260,1
3752723365.160800,-37.494,Sweeping down,10.004,10.006,35.421,3.712,0,0,10.000,10.000,0.200,0.270,1
3752723435.160800,-45.043,Sweeping down,10.000,10.004,35.419,3.667,0,0,10.000,10.000,0.230,0.280,1
3752723505.160800,-52.592,Sweeping down,9.997,9.987,35.423,3.631,0,0,10.000,10.000,0.210,0.280,1
3752723575.160800,-57.389,Sweeping down,9.998,9.980,35.434,3.423,0,0,10.000,10.000,0.210,0.290,1
3752723645.160800,-61.199,Sweeping down,10.002,9.994,35.449,3.361,0,0,10.000,10.000,0.200,0.260,4
3752723715.160800,-64.980,Sweeping down,9.999,10.002,35.464,3.350,0,0,10.000,10.000,0.220,0.310,1
3752723785.160800,-68.759,Sweeping down,10.001,9.998,35.480,3.337,0,0,10.000,10.000,0.200,0.280,1
3752723855.160800,-72.536,Sweeping down,10.001,10.017,35.500,3.330,0,0,10.000,10.000,0.220,0.280,4
3752723925.160800,-76.339,Sweeping down,10.001,9.997,35.523,3.321,0,0,10.000,10.000,0.210,0.310,4
3752723995.160800,-80.114,Sweeping down,9.998,9.996,35.551,3.312,0,0,10.000,10.000,0.230,0.310,1
3752724065.160800,-83.891,Sweeping down,10.001,10.007,35.582,3.302,0,0,10.000,10.000,0.200,0.250,1
3752724135.160800,-87.668,Sweeping down,10.001,10.005,35.619,3.292,0,0,10.000,10.000,0.200,0.250,1
3752724205.160800,-89.999,Sweeping down,10.000,9.997,35.662,3.201,0,0,10.000,10.000,0.220,0.270,4
3752724275.160800,-90.000,Sweeping down,10.000,9.998,35.710,3.117,0,0,10.000,10.000,0.220,0.290,4
3752724345.160800,-90.000,Sweeping down,10.004,9.997,35.751,3.111,0,0,10.000,10.000,0.220,0.270,4
3752724415.160800,-90.000,Sweeping down,10.002,10.010,35.785,3.111,0,0,10.000,10.000,0.230,0.310,4
3752724485.160800,-90.000,Sweeping down,10.000,9.993,35.815,3.111,0,0,10.000,10.000,0.220,0.310,1
3752724555.160800,-90.000,Sweeping down,9.998,10.017,35.842,3.112,0,0,10.000,10.000,0.210,0.270,4
3752724625.160800,-90.000,Sweeping down,10.002,10.007,35.864,3.111,0,0,10.000,10.000,0.230,0.270,4
3752724695.160800,-90.000,Sweeping down,9.997,9.991,35.884,3.112,0,0,10.000,10.000,0.260,0.320,1
3752724765.160800,-90.000,Sweeping down,16.701,16.641,35.902,3.113,1,1,20.000,20.000,1.550,1.280,0
3752724835.160800,-90.000,Sweeping down,20.002,19.991,35.916,3.112,0,0,20.000,20.000,0.750,0.530,4
3752724905.160800,-90.000,Sweeping down,20.001,20.000,35.930,3.112,0,0,20.000,20.000,0.690,0.460,4
3752724975.160800,-90.000,Sweeping down,20.001,20.009,35.943,3.113,0,0,20.000,20.000,0.630,0.410,1
3752725045.160800,-90.000,Sweeping down,20.002,20.005,35.955,3.111,0,0,20.000,20.000,0.610,0.410,4
3752725115.160800,-90.000,Sweeping down,19.999,19.994,35.968,3.109,0,0,20.000,20.000,0.630,0.430,4
3752725185.160800,-90.000,Sweeping down,20.002,20.010,35.981,3.111,0,0,20.000,20.000,0.600,0.410,1
3752725255.160800,-90.000,Sweeping down,20.000,19.994,35.995,3.110,0,0,20.000,20.000,0.610,0.420,1
3752725325.160800,-90.000,Sweeping down,20.002,19.998,36.008,3.112,0,0,20.000,20.000,0.600,0.410,1
3752725395.160800,-90.000,Sweeping down,20.003,20.000,36.020,3.113,0,0,20.000,20.000,0.590,0.420,1
3752725465.160800,-90.000,Sweeping down,20.003,20.008,36.033,3.112,0,0,20.000,20.000,0.590,0.400,1
3752725535.160800,-90.000,Sweeping down,20.003,19.997,36.045,3.112,0,0,20.000,20.000,0.610,0.420,1
3752725605.160800,-90.000,Sweeping down,20.001,20.006,36.055,3.111,0,0,20.000,20.000,0.610,0.410,4
3752725675.160800,-88.532,Sweeping up,19.997,19.998,36.066,3.148,0,0,20.000,20.000,0.620,0.410,4
3752725745.160800,-84.760,Sweeping up,19.999,19.994,36.073,3.269,0,0,20.000,20.000,0.600,0.420,1
3752725815.160800,-80.981,Sweeping up,20.002,20.000,36.071,3.293,0,0,20.000,20.000,0.580,0.390,1
3752725885.160800,-77.204,Sweeping up,20.001,20.005,36.059,3.305,0,0,20.000,20.000,0.570,0.380,1
3752725955.160800,-73.396,Sweeping up,19.999,19.993,36.039,3.316,0,0,20.000,20.000,0.600,0.420,1
3752726025.160800,-69.616,Sweeping up,20.004,20.009,36.011,3.323,0,0,20.000,20.000,0.570,0.390,1
3752726095.160800,-65.837,Sweeping up,19.999,20.010,35.979,3.329,0,0,20.000,20.000,0.580,0.380,1
3752726165.160800,-62.058,Sweeping up,20.002,19.998,35.945,3.343,0,0,20.000,20.000,0.570,0.410,1
3752726235.160800,-58.250,Sweeping up,20.001,20.006,35.906,3.351,0,0,20.000,20.000,0.580,0.380,1
3752726305.160800,-54.473,Sweeping up,19.999,20.003,35.867,3.359,0,0,20.000,20.000,0.570,0.390,1
3752726375.160800,-47.594,Sweeping up,20.000,19.989,35.822,3.579,0,0,20.000,20.000,0.580,0.410,1
3752726445.160800,-40.045,Sweeping up,20.002,19.993,35.773,3.647,0,0,20.000,20.000,0.580,0.420,1
3752726515.160800,-32.437,Sweeping up,19.999,19.993,35.727,3.689,0,0,20.000,20.000,0.580,0.410,1
3752726585.160800,-24.889,Sweeping up,20.002,20.004,35.685,3.734,0,0,20.000,20.000,0.560,0.410,1
3752726655.160800,-17.342,Sweeping up,19.999,20.009,35.645,3.790,0,0,20.000,20.000,0.590,0.370,1
3752726725.160800,-9.797,Sweeping up,20.000,20.003,35.607,3.872,0,0,20.000,20.000,0.600,0.400,1
3752726795.160800,-2.205,Sweeping up,20.000,19.996,35.573,4.014,0,0,20.000,20.000,0.580,0.420,4
3752726865.160800,5.164,Sweeping up,19.998,19.983,35.542,4.381,0,0,20.000,20.000,0.580,0.440,4
3752726935.160800,12.710,Sweeping up,19.998,19.986,35.517,4.078,0,0,20.000,20.000,0.560,0.430,1
3752727005.160800,20.255,Sweeping up,19.999,19.997,35.509,3.885,0,0,20.000,20.000,0.550,0.370,1
3752727075.160800,27.861,Sweeping up,20.003,19.996,35.500,3.785,0,0,20.000,20.000,0.570,0.400,4
3752727145.160800,35.410,Sweeping up,20.000,19.998,35.491,3.726,0,0,20.000,20.000,0.560,0.400,4
3752727215.160800,42.962,Sweeping up,19.996,19.998,35.488,3.678,0,0,20.000,20.000,0.580,0.390,4
3752727285.160800,50.516,Sweeping up,19.999,20.005,35.494,3.640,0,0,20.000,20.000,0.580,0.380,1
3752727355.160800,56.384,Sweeping up,19.999,20.011,35.505,3.475,0,0,20.000,20.000,0.560,0.340,1
3752727425.160800,60.169,Sweeping up,20.000,19.989,35.522,3.369,0,0,20.000,20.000,0.570,0.410,4
3752727495.160800,63.950,Sweeping up,19.999,20.011,35.540,3.349,0,0,20.000,20.000,0.590,0.370,1
3752727565.160800,67.728,Sweeping up,20.000,19.997,35.559,3.339,0,0,20.000,20.000,0.580,0.410,1
3752727635.160800,71.531,Sweeping up,20.000,20.011,35.581,3.330,0,0,20.000,20.000,0.580,0.360,1
3752727705.160800,75.314,Sweeping up,19.998,20.003,35.605,3.321,0,0,20.000,20.000,0.600,0.380,1
3752727775.160800,79.093,Sweeping up,19.996,19.993,35.633,3.312,0,0,20.000,20.000,0.590,0.410,1
3752727845.160800,82.876,Sweeping up,20.002,20.007,35.665,3.305,0,0,20.000,20.000,0.570,0.360,1
3752727915.160800,86.677,Sweeping up,20.003,20.007,35.702,3.296,0,0,20.000,20.000,0.560,0.360,1
3752727985.160800,89.960,Sweeping up,19.999,20.009,35.744,3.270,0,0,20.000,20.000,0.570,0.360,4
3752728055.160800,90.000,Sweeping up,19.996,19.992,35.796,3.130,0,0,20.000,20.000,0.590,0.420,4
3752728125.160800,90.000,Sweeping up,19.998,20.002,35.841,3.112,0,0,20.000,20.000,0.570,0.430,4
3752728195.160800,90.000,Sweeping up,20.000,19.997,35.879,3.111,0,0,20.000,20.000,0.590,0.430,1
3752728265.160800,90.000,Sweeping up,19.999,20.013,35.912,3.111,0,0,20.000,20.000,0.570,0.370,4
3752728335.160800,90.000,Sweeping up,20.002,20.008,35.940,3.111,0,0,20.000,20.000,0.560,0.390,1
3752728405.160800,90.000,Sweeping up,20.003,20.017,35.965,3.112,0,0,20.000,20.000,0.570,0.380,1
3752728475.160800,90.000,Sweeping up,20.001,19.999,35.987,3.112,0,0,20.000,20.000,0.580,0.390,1
3752728545.160800,90.000,Sweeping up,19.997,20.006,36.008,3.111,0,0,20.000,20.000,0.570,0.380,1
3752728615.160800,90.000,Sweeping up,19.999,19.990,36.025,3.111,0,0,20.000,20.000,0.600,0.420,1
3752728685.160800,90.000,Sweeping up,19.994,19.988,36.040,3.111,0,0,20.000,20.000,0.620,0.450,1
3752728755.160800,90.000,Sweeping up,29.878,29.840,36.054,3.113,1,1,50.000,50.000,5.920,4.090,2
3752728825.160800,90.000,Sweeping up,41.466,41.397,36.068,3.112,1,1,50.000,50.000,12.580,8.390,2
3752728895.160800,90.000,Sweeping up,50.827,50.782,36.080,3.111,0,0,50.000,50.000,0.000,1.170,4
3752728965.160800,90.000,Sweeping up,49.826,50.040,36.094,3.112,0,0,50.000,50.000,4.740,2.030,4
3752729035.160800,90.000,Sweeping up,49.998,50.005,36.107,3.112,0,0,50.000,50.000,4.640,1.890,4
3752729105.160800,90.000,Sweeping up,50.027,50.005,36.122,3.111,0,0,50.000,50.000,3.690,1.800,4
3752729175.160800,90.000,Sweeping up,50.003,50.006,36.137,3.112,0,0,50.000,50.000,3.500,1.630,1
3752729245.160800,90.000,Sweeping up,50.000,50.002,36.153,3.112,0,0,50.000,50.000,3.380,1.530,1
3752729315.160800,90.000,Sweeping up,50.007,50.008,36.168,3.112,0,0,50.000,50.000,3.120,1.390,1
3752729385.160800,90.000,Sweeping up,50.001,49.998,36.184,3.112,0,0,50.000,50.000,2.980,1.340,1
3752729455.160800,90.000,Sweeping up,50.002,50.006,36.200,3.112,0,0,50.000,50.000,2.870,1.260,1
3752729525.160800,90.000,Sweeping up,50.002,49.998,36.215,3.113,0,0,50.000,50.000,2.730,1.200,1
3752729595.160800,90.000,Sweeping up,50.002,49.998,36.230,3.111,0,0,50.000,50.000,2.630,1.160,1
3752729665.160800,90.000,Sweeping up,49.997,49.999,36.244,3.113,0,0,50.000,50.000,2.590,1.140,1
3752729735.160800,90.000,Sweeping up,50.002,50.003,36.259,3.113,0,0,50.000,50.000,2.500,1.060,1
3752729805.160800,90.000,Sweeping up,50.002,50.003,36.273,3.112,0,0,50.000,50.000,2.440,1.040,1
3752729875.160800,90.000,Sweeping up,50.000,50.000,36.286,3.113,0,0,50.000,50.000,2.380,1.030,1
3752729945.160800,90.000,Sweeping up,50.000,50.004,36.299,3.114,0,0,50.000,50.000,2.350,0.980,1
3752730015.160800,90.000,Sweeping up,50.003,50.002,36.312,3.113,0,0,50.000,50.000,2.280,0.970,1
3752730085.160800,90.000,Sweeping up,50.001,50.005,36.325,3.113,0,0,50.000,50.000,2.230,0.960,1
3752730155.160800,90.000,Sweeping up,50.000,50.001,36.337,3.113,0,0,50.000,50.000,2.210,0.920,1
3752730225.160800,90.000,Sweeping up,49.999,50.001,36.349,3.113,0,0,50.000,50.000,2.200,0.910,1
3752730295.160800,90.000,Sweeping up,50.001,50.001,36.362,3.111,0,0,50.000,50.000,2.140,0.880,1
3752730365.160800,88.129,Sweeping down,50.003,50.001,36.373,3.173,0,0,50.000,50.000,2.110,0.890,1
3752730435.160800,84.313,Sweeping down,49.997,49.999,36.379,3.274,0,0,50.000,50.000,2.110,0.910,1
3752730505.160800,80.529,Sweeping down,50.003,49.999,36.376,3.296,0,0,50.000,50.000,2.080,0.890,1
3752730575.160800,76.747,Sweeping down,50.000,50.003,36.365,3.307,0,0,50.000,50.000,2.060,0.870,1
3752730645.160800,72.970,Sweeping down,50.000,50.004,36.346,3.316,0,0,50.000,50.000,2.040,0.820,1
3752730715.160800,69.161,Sweeping down,50.001,49.996,36.320,3.326,0,0,50.000,50.000,2.000,0.850,1
3752730785.160800,65.380,Sweeping down,49.999,49.996,36.290,3.333,0,0,50.000,50.000,2.010,0.840,1
3752730855.160800,61.599,Sweeping down,50.001,50.003,36.256,3.343,0,0,50.000,50.000,2.010,0.850,1
3752730925.160800,57.819,Sweeping down,50.002,50.003,36.220,3.351,0,0,50.000,50.000,1.970,0.830,1
3752730995.160800,54.027,Sweeping down,50.001,50.004,36.183,3.360,0,0,50.000,50.000,1.950,0.800,1
3752731065.160800,46.665,Sweeping down,50.000,50.002,36.141,3.594,0,0,50.000,50.000,1.980,0.830,1
3752731135.160800,39.112,Sweeping down,49.998,49.999,36.094,3.654,0,0,50.000,50.000,1.970,0.840,1
3752731205.160800,31.560,Sweeping down,50.001,49.996,36.050,3.696,0,0,50.000,50.000,1.950,0.830,1
3752731275.160800,24.009,Sweeping down,49.999,50.000,36.008,3.742,0,0,50.000,50.000,1.950,0.840,1
3752731345.160800,16.402,Sweeping down,50.001,49.998,35.969,3.800,0,0,50.000,50.000,1.920,0.850,1
3752731415.160800,8.858,Sweeping down,49.998,49.995,35.932,3.887,0,0,50.000,50.000,1.940,0.840,1
3752731485.160800,1.325,Sweeping down,50.002,50.003,35.899,4.038,0,0,50.000,50.000,1.900,0.820,1
3752731555.160800,-6.052,Sweeping down,50.001,49.998,35.869,4.357,0,0,50.000,50.000,1.880,0.820,1
3752731625.160800,-13.654,Sweeping down,49.999,50.001,35.847,4.047,0,0,50.000,50.000,1.900,0.820,1
3752731695.160800,-21.198,Sweeping down,50.001,49.998,35.840,3.871,0,0,50.000,50.000,1.870,0.790,1
3752731765.160800,-28.745,Sweeping down,50.000,50.000,35.832,3.780,0,0,50.000,50.000,1.880,0.820,1
3752731835.160800,-36.293,Sweeping down,50.003,49.997,35.826,3.720,0,0,50.000,50.000,1.840,0.790,1
3752731905.160800,-43.900,Sweeping down,50.000,49.997,35.825,3.672,0,0,50.000,50.000,1.860,0.810,1
3752731975.160800,-51.449,Sweeping down,50.000,50.004,35.830,3.635,0,0,50.000,50.000,1.850,0.760,1
3752732045.160800,-56.816,Sweeping down,50.000,50.005,35.842,3.450,0,0,50.000,50.000,1.850,0.750,1
3752732115.160800,-60.595,Sweeping down,50.001,50.003,35.861,3.365,0,0,50.000,50.000,1.840,0.740,1
3752732185.160800,-64.405,Sweeping down,49.999,49.996,35.879,3.350,0,0,50.000,50.000,1.850,0.770,1
3752732255.160800,-68.184,Sweeping down,50.000,50.003,35.900,3.339,0,0,50.000,50.000,1.850,0.770,1
3752732325.160800,-71.960,Sweeping down,50.002,49.997,35.923,3.330,0,0,50.000,50.000,1.820,0.740,1
3752732395.160800,-75.735,Sweeping down,49.998,49.997,35.951,3.321,0,0,50.000,50.000,1.860,0.780,1
3752732465.160800,-79.539,Sweeping down,50.001,49.999,35.983,3.311,0,0,50.000,50.000,1.830,0.790,1
3752732535.160800,-83.316,Sweeping down,50.001,49.999,36.019,3.305,0,0,50.000,50.000,1.820,0.760,1
3752732605.160800,-87.093,Sweeping down,50.000,49.992,36.059,3.297,0,0,50.000,50.000,1.830,0.800,1
3752732675.160800,-90.000,Sweeping down,50.000,50.001,36.104,3.238,0,0,50.000,50.000,1.850,0.760,1
3752732745.160800,-90.000,Sweeping down,50.000,49.996,36.158,3.127,0,0,50.000,50.000,1.820,0.750,1
3752732815.160800,-90.000,Sweeping down,50.000,50.000,36.206,3.113,0,0,50.000,50.000,1.830,0.760,1
3752732885.160800,-90.000,Sweeping down,50.001,50.001,36.246,3.112,0,0,50.000,50.000,1.840,0.730,1
3752732955.160800,-90.000,Sweeping down,50.001,50.002,36.281,3.113,0,0,50.000,50.000,1.840,0.770,1
3752733025.160800,-90.000,Sweeping down,50.001,50.003,36.312,3.112,0,0,50.000,50.000,1.830,0.740,1
3752733095.160800,-90.000,Sweeping down,50.000,49.996,36.339,3.112,0,0,50.000,50.000,1.850,0.750,1
3752733165.160800,-90.000,Sweeping down,50.000,49.999,36.362,3.112,0,0,50.000,50.000,1.830,0.750,1
[...]
3752769485.160800,0.000,Standby,300.005,300.002,40.952,3.157,0,0,300.000,300.000,13.620,9.670,1
3752769595.160800,0.000,Standby,300.002,299.998,40.955,3.159,0,0,300.000,300.000,13.620,9.670,1
3752769705.160800,0.000,Standby,300.000,299.999,40.958,3.163,0,0,300.000,300.000,13.580,9.650,1
3752769815.160800,0.000,Standby,300.000,300.002,40.962,3.162,0,0,300.000,300.000,13.530,9.650,1
3752769925.160800,0.000,Standby,299.996,300.000,40.966,3.163,0,0,300.000,300.000,13.570,9.650,1
3752770035.160800,0.000,Standby,299.997,300.001,40.971,3.162,0,0,300.000,300.000,13.570,9.670,1
3752770145.160800,0.000,Standby,300.001,300.001,40.975,3.161,0,0,300.000,300.000,13.600,9.640,1
3752770255.160800,0.000,Standby,299.998,300.000,40.980,3.163,0,0,300.000,300.000,13.600,9.670,1
3752770365.160800,0.000,Standby,299.999,299.998,40.986,3.161,0,0,300.000,300.000,13.580,9.670,1
3752770475.160800,0.000,Standby,299.999,299.999,40.991,3.161,0,0,300.000,300.000,13.570,9.570,1
3752770585.160800,0.000,Standby,300.000,299.998,40.997,3.161,0,0,300.000,300.000,13.550,9.650,1
3752770695.160800,0.000,Standby,300.000,300.001,41.002,3.160,0,0,300.000,300.000,13.530,9.640,1
3752770805.160800,0.000,Standby,300.001,300.002,41.006,3.158,0,0,300.000,300.000,13.530,9.620,1
3752770915.160800,0.000,Standby,300.001,300.002,41.009,3.163,0,0,300.000,300.000,13.470,9.620,1
3752771025.160800,0.000,Standby,299.997,299.999,41.012,3.162,0,0,300.000,300.000,13.530,9.620,1
3752771135.160800,0.000,Standby,299.999,300.001,41.014,3.163,0,0,300.000,300.000,13.470,9.620,1
3752771245.160800,0.000,Standby,300.000,300.001,41.019,3.163,0,0,300.000,300.000,13.490,9.560,1
3752771355.160800,0.000,Standby,299.996,300.000,41.023,3.159,0,0,300.000,300.000,13.580,9.620,1
3752771465.160800,0.000,Standby,299.997,300.000,41.025,3.161,0,0,300.000,300.000,13.620,9.600,1
3752771575.160800,0.000,Standby,299.996,299.999,41.029,3.160,0,0,300.000,300.000,13.620,9.590,1
3752771685.160800,0.000,Standby,300.001,300.000,41.034,3.160,0,0,300.000,300.000,13.570,9.620,1
3752771795.160800,0.000,Standby,300.003,300.000,41.039,3.162,0,0,300.000,300.000,13.570,9.600,1
3752771905.160800,0.000,Standby,300.005,299.999,41.044,3.159,0,0,300.000,300.000,13.490,9.590,1
3752772015.160800,0.000,Standby,300.003,299.999,41.045,3.160,0,0,300.000,300.000,13.460,9.600,1
3752772125.160800,0.000,Standby,300.001,299.998,41.048,3.162,0,0,300.000,300.000,13.420,9.600,1
3752772235.160800,0.000,Standby,299.998,299.998,41.051,3.159,0,0,300.000,300.000,13.440,9.560,1
3752772345.160800,0.000,Standby,299.999,299.999,41.054,3.159,0,0,300.000,300.000,13.470,9.590,1
3752772455.160800,0.000,Standby,299.998,300.000,41.056,3.160,0,0,300.000,300.000,13.490,9.540,1
3752772565.160800,0.000,Standby,299.998,299.999,41.059,3.158,0,0,300.000,300.000,13.510,9.560,1
3752772675.160800,0.000,Standby,300.001,300.000,41.062,3.162,0,0,300.000,300.000,13.490,9.540,1
3752772785.160800,0.000,Standby,300.002,299.997,41.063,3.164,0,0,300.000,300.000,13.470,9.570,1
3752772895.160800,0.000,Standby,300.000,300.000,41.068,3.163,0,0,300.000,300.000,13.440,9.540,1
3752773005.160800,0.000,Standby,300.001,300.000,41.069,3.161,0,0,300.000,300.000,13.460,9.570,1
3752773115.160800,0.000,Standby,300.001,300.002,41.071,3.162,0,0,300.000,300.000,13.440,9.560,1
3752773225.160800,0.000,Standby,300.002,299.998,41.071,3.165,0,0,300.000,300.000,13.420,9.570,1
3752773335.160800,0.000,Standby,300.000,300.000,41.074,3.163,0,0,300.000,300.000,13.400,9.560,1
3752773445.160800,0.000,Standby,300.000,300.000,41.075,3.165,0,0,300.000,300.000,13.400,9.540,1
3752773555.160800,0.000,Standby,299.999,300.001,41.075,3.162,0,0,300.000,300.000,13.420,9.540,1
3752773665.160800,0.000,Standby,299.996,299.998,41.076,3.164,0,0,300.000,300.000,13.400,9.570,1
3752773775.160800,0.000,Standby,299.995,299.999,41.078,3.163,0,0,300.000,300.000,13.530,9.540,1
3752773885.160800,0.000,Standby,299.998,300.000,41.082,3.165,0,0,300.000,300.000,13.490,9.540,1
3752773995.160800,0.000,Standby,300.000,299.999,41.085,3.161,0,0,300.000,300.000,13.510,9.570,1
3752774105.160800,0.000,Standby,300.000,299.999,41.088,3.163,0,0,300.000,300.000,13.530,9.540,1
3752774215.160800,0.000,Standby,300.000,299.997,41.092,3.162,0,0,300.000,300.000,13.510,9.520,1
3752774325.160800,0.000,Standby,300.004,299.997,41.095,3.161,0,0,300.000,300.000,13.490,9.520,1
3752774435.160800,0.000,Standby,300.007,299.999,41.097,3.161,0,0,300.000,300.000,13.420,9.520,1
3752774545.160800,0.000,Standby,300.007,300.001,41.100,3.162,0,0,300.000,300.000,13.370,9.520,1
3752774655.160800,0.000,Standby,300.004,299.999,41.102,3.163,0,0,300.000,300.000,13.310,9.510,1
3752774765.160800,0.000,Standby,299.999,299.997,41.104,3.165,0,0,300.000,300.000,13.350,9.520,1
3752774875.160800,0.000,Standby,299.998,300.000,41.106,3.161,0,0,300.000,300.000,13.380,9.540,1
3752774985.160800,0.000,Standby,299.997,300.000,41.108,3.162,0,0,300.000,300.000,13.400,9.520,1
3752775095.160800,0.000,Standby,299.995,300.000,41.110,3.166,0,0,300.000,300.000,13.440,9.480,1
3752775205.160800,0.000,Standby,299.995,299.999,41.113,3.163,0,0,300.000,300.000,13.460,9.520,1
3752775315.160800,0.000,Standby,299.995,299.999,41.112,3.163,0,0,300.000,300.000,13.530,9.510,1
3752775425.160800,0.000,Standby,300.000,300.000,41.114,3.161,0,0,300.000,300.000,13.490,9.510,1
3752775535.160800,0.000,Standby,300.003,299.999,41.114,3.163,0,0,300.000,300.000,13.440,9.520,1
3752775645.160800,0.000,Standby,300.003,299.999,41.113,3.166,0,0,300.000,300.000,13.380,9.510,1
3752775755.160800,0.000,Standby,300.000,300.000,41.112,3.164,0,0,300.000,300.000,13.370,9.520,1
3752775865.160800,0.000,Standby,300.000,300.001,41.113,3.162,0,0,300.000,300.000,13.400,9.490,1
3752775975.160800,0.000,Standby,300.003,300.001,41.116,3.162,0,0,300.000,300.000,13.370,9.490,1
3752776085.160800,0.000,Standby,300.003,299.999,41.119,3.163,0,0,300.000,300.000,13.350,9.520,1
3752776195.160800,0.000,Standby,300.002,300.001,41.123,3.162,0,0,300.000,300.000,13.350,9.490,1
3752776305.160800,0.000,Standby,299.998,299.998,41.124,3.164,0,0,300.000,300.000,13.370,9.520,1
3752776415.160800,0.000,Standby,299.995,300.002,41.127,3.164,0,0,300.000,300.000,13.380,9.510,1
3752776525.160800,0.000,Standby,299.996,299.998,41.132,3.164,0,0,300.000,300.000,13.440,9.490,1
3752776635.160800,0.000,Standby,300.000,300.001,41.135,3.164,0,0,300.000,300.000,13.400,9.490,1
3752776745.160800,0.000,Standby,300.001,299.998,41.139,3.162,0,0,300.000,300.000,13.460,9.520,1
3752776855.160800,0.000,Standby,300.003,299.999,41.140,3.164,0,0,300.000,300.000,13.400,9.490,1
3752776965.160800,0.000,Standby,300.006,300.001,41.141,3.162,0,0,300.000,300.000,13.370,9.460,1
3752777075.160800,0.000,Standby,300.005,300.000,41.141,3.164,0,0,300.000,300.000,13.350,9.490,1
3752777185.160800,0.000,Standby,300.003,299.999,41.143,3.165,0,0,300.000,300.000,13.330,9.510,1
3752777295.160800,0.000,Standby,300.000,299.998,41.147,3.166,0,0,300.000,300.000,13.310,9.480,1
3752777405.160800,0.000,Standby,299.998,299.999,41.149,3.165,0,0,300.000,300.000,13.350,9.490,1
3752777515.160800,0.000,Standby,299.997,300.001,41.153,3.164,0,0,300.000,300.000,13.350,9.460,1
3752777625.160800,0.000,Standby,299.998,300.001,41.154,3.163,0,0,300.000,300.000,13.350,9.480,1
3752777735.160800,0.000,Standby,299.997,300.000,41.154,3.165,0,0,300.000,300.000,13.400,9.480,1
3752777845.160800,0.000,Standby,299.996,300.001,41.156,3.167,0,0,300.000,300.000,13.440,9.460,1
3752777955.160800,0.000,Standby,300.001,300.001,41.156,3.166,0,0,300.000,300.000,13.420,9.490,1
3752778065.160800,0.000,Standby,300.001,300.001,41.157,3.166,0,0,300.000,300.000,13.420,9.490,1
3752778175.160800,0.000,Standby,300.000,300.000,41.158,3.168,0,0,300.000,300.000,13.400,9.480,1
3752778285.160800,0.000,Standby,300.002,299.998,41.157,3.166,0,0,300.000,300.000,13.400,9.510,1
3752778395.160800,0.000,Standby,300.004,299.998,41.159,3.166,0,0,300.000,300.000,13.350,9.460,1
3752778505.160800,0.000,Standby,300.005,299.998,41.160,3.164,0,0,300.000,300.000,13.270,9.460,1
3752778615.160800,0.000,Standby,300.002,300.000,41.162,3.165,0,0,300.000,300.000,13.240,9.480,1
3752778725.160800,0.000,Standby,299.997,299.999,41.164,3.165,0,0,300.000,300.000,13.270,9.460,1
3752778835.160800,0.000,Standby,299.994,299.999,41.167,3.167,0,0,300.000,300.000,13.350,9.490,1
3752778945.160800,0.000,Standby,299.996,300.001,41.169,3.166,0,0,300.000,300.000,13.400,9.480,1
3752779055.160800,0.000,Standby,299.993,299.998,41.169,3.164,0,0,300.000,300.000,13.470,9.480,1
3752779165.160800,0.000,Standby,300.001,299.998,41.169,3.165,0,0,300.000,300.000,13.460,9.480,1
3752779275.160800,0.000,Standby,300.003,299.998,41.168,3.169,0,0,300.000,300.000,13.420,9.480,1
3752779385.160800,0.000,Standby,300.006,299.999,41.171,3.167,0,0,300.000,300.000,13.350,9.480,1
3752779495.160800,0.000,Standby,300.007,299.999,41.171,3.168,0,0,300.000,300.000,13.310,9.480,1
3752779605.160800,0.000,Standby,300.010,300.002,41.174,3.165,0,0,300.000,300.000,13.220,9.440,1
3752779715.160800,0.000,Standby,300.004,299.997,41.175,3.166,0,0,300.000,300.000,13.240,9.480,1
3752779825.160800,0.000,Standby,300.001,300.000,41.179,3.166,0,0,300.000,300.000,13.170,9.440,1
3752779935.160800,0.000,Standby,299.994,300.000,41.180,3.168,0,0,300.000,300.000,13.260,9.480,1
3752780045.160800,0.000,Standby,299.990,300.000,41.181,3.166,0,0,300.000,300.000,13.330,9.480,1
3752780155.160800,0.000,Standby,299.989,300.000,41.183,3.167,0,0,300.000,300.000,13.460,9.480,1
3752780265.160800,0.000,Standby,299.994,300.000,41.185,3.166,0,0,300.000,300.000,13.470,9.460,1
3752780375.160800,0.000,Standby,299.998,299.998,41.187,3.165,0,0,300.000,300.000,13.440,9.490,1
3752780485.160800,0.000,Standby,300.004,299.999,41.188,3.168,0,0,300.000,300.000,13.380,9.480,1
3752780595.160800,0.000,Standby,300.005,300.000,41.185,3.168,0,0,300.000,300.000,13.350,9.480,1
3752780705.160800,0.000,Standby,300.008,300.000,41.185,3.166,0,0,300.000,300.000,13.270,9.460,1
3752780815.160800,0.000,Standby,300.006,300.001,41.185,3.166,0,0,300.000,300.000,13.180,9.480,1
3752780925.160800,0.000,Standby,299.999,299.999,41.184,3.167,0,0,300.000,300.000,13.240,9.460,1
3752781035.160800,0.000,Standby,299.996,299.999,41.182,3.165,0,0,300.000,300.000,13.290,9.480,1
3752781145.160800,0.000,Standby,299.995,300.000,41.178,3.163,0,0,300.000,300.000,13.310,9.460,1
3752781255.160800,0.000,Standby,299.995,299.999,41.176,3.163,0,0,300.000,300.000,13.400,9.490,1
3752781365.160800,0.000,Standby,299.996,300.000,41.173,3.165,0,0,300.000,300.000,13.460,9.460,1
3752781475.160800,0.000,Standby,300.001,300.000,41.174,3.167,0,0,300.000,300.000,13.380,9.440,1
3752781585.160800,0.000,Standby,300.002,299.998,41.178,3.167,0,0,300.000,300.000,13.330,9.460,1
3752781695.160800,0.000,Standby,300.000,300.001,41.181,3.166,0,0,300.000,300.000,13.330,9.460,1
3752781805.160800,0.000,Standby,299.999,300.000,41.183,3.168,0,0,300.000,300.000,13.290,9.440,1
3752781915.160800,0.000,Standby,300.000,300.000,41.186,3.167,0,0,300.000,300.000,13.330,9.460,1
3752782025.160800,0.000,Standby,300.000,300.000,41.189,3.165,0,0,300.000,300.000,13.310,9.410,1
3752782135.160800,0.000,Standby,299.997,300.001,41.190,3.164,0,0,300.000,300.000,13.290,9.440,1
3752782245.160800,0.000,Standby,299.998,300.000,41.191,3.165,0,0,300.000,300.000,13.330,9.460,1
3752782355.160800,0.000,Standby,299.998,299.998,41.190,3.167,0,0,300.000,300.000,13.370,9.440,1
3752782465.160800,0.000,Standby,299.999,299.999,41.191,3.166,0,0,300.000,300.000,13.330,9.440,1
3752782575.160800,0.000,Standby,300.001,300.000,41.191,3.168,0,0,300.000,300.000,13.290,9.430,1
3752782685.160800,0.000,Standby,300.003,300.000,41.192,3.170,0,0,300.000,300.000,13.240,9.460,1
3752782795.160800,0.000,Standby,300.003,300.001,41.192,3.167,0,0,300.000,300.000,13.240,9.430,1
3752782905.160800,0.000,Standby,299.999,300.000,41.191,3.169,0,0,300.000,300.000,13.260,9.440,1
3752783015.160800,0.000,Standby,299.999,299.998,41.192,3.168,0,0,300.000,300.000,13.290,9.440,1
3752783125.160800,0.000,Standby,299.999,300.000,41.193,3.169,0,0,300.000,300.000,13.290,9.440,1
3752783235.160800,0.000,Standby,299.999,300.000,41.195,3.168,0,0,300.000,300.000,13.330,9.400,1
3752783345.160800,0.000,Standby,300.000,300.000,41.194,3.169,0,0,300.000,300.000,13.370,9.440,1
3752783455.160800,0.000,Standby,300.002,300.000,41.196,3.169,0,0,300.000,300.000,13.270,9.440,1
3752783565.160800,0.000,Standby,300.004,300.001,41.198,3.168,0,0,300.000,300.000,13.270,9.410,1
3752783675.160800,0.000,Standby,300.000,300.000,41.200,3.168,0,0,300.000,300.000,13.260,9.440,1
3752783785.160800,0.000,Standby,299.999,299.999,41.202,3.168,0,0,300.000,300.000,13.290,9.430,1
3752783895.160800,0.000,Standby,300.000,300.000,41.203,3.168,0,0,300.000,300.000,13.270,9.440,1
3752784005.160800,0.000,Standby,299.997,299.999,41.204,3.169,0,0,300.000,300.000,13.330,9.440,1
3752784115.160800,0.000,Standby,300.002,300.002,41.204,3.169,0,0,300.000,300.000,13.270,9.430,1
3752784225.160800,0.000,Standby,300.001,300.000,41.204,3.169,0,0,300.000,300.000,13.290,9.460,1
3752784335.160800,0.000,Standby,300.001,299.999,41.207,3.169,0,0,300.000,300.000,13.260,9.440,1
3752784445.160800,0.000,Standby,299.998,300.000,41.210,3.169,0,0,300.000,300.000,13.290,9.440,1
3752784555.160800,0.000,Standby,300.000,300.000,41.210,3.167,0,0,300.000,300.000,13.290,9.460,1
3752784665.160800,0.000,Standby,299.994,299.999,41.209,3.168,0,0,300.000,300.000,13.370,9.460,1
3752784775.160800,0.000,Standby,299.997,300.000,41.205,3.169,0,0,300.000,300.000,13.380,9.460,1
3752784885.160800,0.000,Standby,300.002,300.002,41.202,3.166,0,0,300.000,300.000,13.310,9.410,1
3752784995.160800,0.000,Standby,300.002,299.998,41.199,3.169,0,0,300.000,300.000,13.330,9.440,1
3752785105.160800,0.000,Standby,300.002,300.000,41.200,3.168,0,0,300.000,300.000,13.260,9.440,1
3752785215.160800,0.000,Standby,299.999,300.001,41.201,3.167,0,0,300.000,300.000,13.260,9.430,1
3752785325.160800,0.000,Standby,299.997,300.001,41.200,3.169,0,0,300.000,300.000,13.330,9.410,1
3752785435.160800,0.000,Standby,299.996,299.999,41.200,3.168,0,0,300.000,300.000,13.330,9.460,1
3752785545.160800,0.000,Standby,299.997,299.999,41.200,3.166,0,0,300.000,300.000,13.350,9.430,1
3752785655.160800,0.000,Standby,299.999,300.000,41.197,3.168,0,0,300.000,300.000,13.350,9.410,1
3752785765.160800,0.000,Standby,300.002,300.000,41.195,3.167,0,0,300.000,300.000,13.310,9.410,1
3752785875.160800,0.000,Standby,300.004,300.002,41.194,3.165,0,0,300.000,300.000,13.270,9.430,1
3752785985.160800,0.000,Standby,300.002,299.998,41.193,3.166,0,0,300.000,300.000,13.290,9.430,1
3752786095.160800,0.000,Standby,300.003,299.998,41.192,3.169,0,0,300.000,300.000,13.260,9.440,1
3752786205.160800,0.000,Standby,300.000,299.999,41.192,3.168,0,0,300.000,300.000,13.270,9.460,1
3752786315.160800,0.000,Standby,299.997,300.000,41.189,3.167,0,0,300.000,300.000,13.310,9.430,1
3752786425.160800,0.000,Standby,299.998,300.000,41.188,3.168,0,0,300.000,300.000,13.270,9.440,1
3752786535.160800,0.000,Standby,299.998,299.998,41.186,3.169,0,0,300.000,300.000,13.350,9.430,1
3752786645.160800,0.000,Standby,300.002,300.002,41.186,3.168,0,0,300.000,300.000,13.330,9.400,1
3752786755.160800,0.000,Standby,300.001,300.001,41.185,3.167,0,0,300.000,300.000,13.290,9.440,1
3752786865.160800,0.000,Standby,300.000,300.003,41.185,3.168,0,0,300.000,300.000,13.310,9.410,1
3752786975.160800,0.000,Standby,299.999,300.001,41.184,3.170,0,0,300.000,300.000,13.310,9.410,1
3752787085.160800,0.000,Standby,300.000,299.997,41.186,3.169,0,0,300.000,300.000,13.310,9.440,1
3752787195.160800,0.000,Standby,300.000,300.002,41.184,3.169,0,0,300.000,300.000,13.330,9.430,1
3752787305.160800,0.000,Standby,300.002,300.001,41.185,3.169,0,0,300.000,300.000,13.310,9.430,1
3752787415.160800,0.000,Standby,300.004,300.001,41.186,3.169,0,0,300.000,300.000,13.290,9.430,1
3752787525.160800,0.000,Standby,300.004,300.000,41.187,3.169,0,0,300.000,300.000,13.270,9.440,1
3752787635.160800,0.000,Standby,300.003,300.001,41.190,3.169,0,0,300.000,300.000,13.260,9.440,1
3752787745.160800,0.000,Standby,300.003,299.996,41.189,3.168,0,0,300.000,300.000,13.200,9.440,1
3752787855.160800,0.000,Standby,299.998,300.000,41.189,3.168,0,0,300.000,300.000,13.270,9.430,1
3752787965.160800,0.000,Standby,299.998,299.999,41.190,3.169,0,0,300.000,300.000,13.260,9.430,1
3752788075.160800,0.000,Standby,299.995,299.999,41.190,3.168,0,0,300.000,300.000,13.370,9.430,1
3752788185.160800,0.000,Standby,299.997,299.999,41.188,3.168,0,0,300.000,300.000,13.350,9.430,1
3752788295.160800,0.000,Standby,300.000,299.998,41.187,3.167,0,0,300.000,300.000,13.370,9.440,1
3752788405.160800,0.000,Standby,300.000,299.999,41.185,3.168,0,0,300.000,300.000,13.400,9.440,1
3752788515.160800,0.000,Standby,300.001,299.999,41.184,3.169,0,0,300.000,300.000,13.330,9.460,1
3752788625.160800,0.000,Standby,300.001,299.998,41.182,3.170,0,0,300.000,300.000,13.270,9.440,1
3752788735.160800,0.000,Standby,300.001,300.002,41.184,3.168,0,0,300.000,300.000,13.330,9.430,1
3752788845.160800,0.000,Standby,300.000,299.999,41.183,3.166,0,0,300.000,300.000,13.290,9.440,1
3752788955.160800,0.000,Standby,300.000,299.999,41.183,3.167,0,0,300.000,300.000,13.270,9.430,1
3752789065.160800,0.000,Standby,299.998,300.001,41.182,3.165,0,0,300.000,300.000,13.330,9.430,1
3752789175.160800,0.000,Standby,300.000,300.001,41.181,3.168,0,0,300.000,300.000,13.350,9.430,1
3752789285.160800,0.000,Standby,299.995,300.000,41.182,3.168,0,0,300.000,300.000,13.380,9.430,1
3752789395.160800,0.000,Standby,299.997,300.000,41.184,3.166,0,0,300.000,300.000,13.380,9.430,1
3752789505.160800,0.000,Standby,299.997,299.998,41.182,3.167,0,0,300.000,300.000,13.420,9.430,1
3752789615.160800,0.000,Standby,300.002,300.000,41.184,3.164,0,0,300.000,300.000,13.350,9.440,1
3752789725.160800,0.000,Standby,300.003,299.997,41.183,3.164,0,0,300.000,300.000,13.330,9.480,1
3752789835.160800,0.000,Standby,300.001,300.000,41.183,3.162,0,0,300.000,300.000,13.310,9.440,1
3752789945.160800,0.000,Standby,300.003,299.998,41.182,3.163,0,0,300.000,300.000,13.260,9.440,1
3752790055.160800,0.000,Standby,299.999,300.000,41.181,3.169,0,0,300.000,300.000,13.290,9.430,1
3752790165.160800,0.000,Standby,299.999,300.002,41.183,3.167,0,0,300.000,300.000,13.370,9.410,1
3752790275.160800,0.000,Standby,300.003,300.000,41.186,3.169,0,0,300.000,300.000,13.310,9.430,1
3752790385.160800,0.000,Standby,300.002,299.998,41.186,3.166,0,0,300.000,300.000,13.270,9.400,1
3752790495.160800,0.000,Standby,300.004,300.001,41.187,3.168,0,0,300.000,300.000,13.220,9.430,1
3752790605.160800,0.000,Standby,300.002,300.001,41.188,3.167,0,0,300.000,300.000,13.220,9.410,1
3752790715.160800,0.000,Standby,299.998,300.000,41.189,3.168,0,0,300.000,300.000,13.200,9.430,1
3752790825.160800,0.000,Standby,299.997,300.001,41.190,3.169,0,0,300.000,300.000,13.240,9.410,1
3752790935.160800,0.000,Standby,299.994,300.001,41.193,3.168,0,0,300.000,300.000,13.330,9.410,1
3752791045.160800,0.000,Standby,299.993,300.001,41.193,3.167,0,0,300.000,300.000,13.330,9.410,1
3752791155.160800,0.000,Standby,299.994,299.999,41.192,3.168,0,0,300.000,300.000,13.440,9.430,1
3752791265.160800,0.000,Standby,299.998,300.001,41.192,3.168,0,0,300.000,300.000,13.380,9.430,1
3752791375.160800,0.000,Standby,300.001,299.999,41.191,3.170,0,0,300.000,300.000,13.370,9.430,1
3752791485.160800,0.000,Standby,300.003,299.999,41.190,3.170,0,0,300.000,300.000,13.310,9.440,1
3752791595.160800,0.000,Standby,300.007,300.000,41.190,3.170,0,0,300.000,300.000,13.330,9.430,1
3752791705.160800,0.000,Standby,300.010,299.999,41.190,3.169,0,0,300.000,300.000,13.220,9.430,1
3752791815.160800,0.000,Standby,300.002,299.999,41.191,3.168,0,0,300.000,300.000,13.200,9.410,1
3752791925.160800,0.000,Standby,300.001,300.001,41.192,3.170,0,0,300.000,300.000,13.240,9.430,1
3752792035.160800,0.000,Standby,299.996,299.999,41.192,3.170,0,0,300.000,300.000,13.270,9.430,1
3752792145.160800,0.000,Standby,299.996,299.998,41.193,3.170,0,0,300.000,300.000,13.310,9.440,1
3752792235.160800,0.000,Standby,299.999,299.999,41.195,3.171,0,0,300.000,300.000,13.260,9.430,1