File: log/20221203.dat
[Header]
; Displex Transport Data File (default extension .dat)
; Copyright 2016, Hechang LEI, hlei@ruc.edu.cn. All rights reserved.
BYAPP, Displex, 2.0
INFO, 9T mag, Release 2.0.
INFO, Channel 1, Temperature Sensor
INFO, Sample 1 Length (cm): 0.000000; Width (cm): 0.000000; Thickness (cm): 0.000000.

[Data]
Timestamp(s),Field(Oe),Field Status,TempA(K),TempB(K),TempC(K),TempD(K),Ramp1,Ramp2,Setpoint1,Setpoint2,Output1(%),Output2(%),Temp Status
3752894965.164800,0.000000,Standby,299.829,300.004,38.192,3.122,0,0,300.000,300.000,22.310,16.400,1
3752895125.164800,0.000000,Standby,300.182,300.001,38.260,3.124,0,0,300.000,300.000,21.110,16.170,1
3752895285.164800,0.000000,Standby,299.886,300.002,38.323,3.127,0,0,300.000,300.000,24.570,15.900,1
3752895445.164800,0.000000,Standby,300.024,300.004,38.387,3.125,0,0,300.000,300.000,19.500,15.630,1
3752895605.164800,0.000000,Standby,300.058,300.003,38.447,3.125,0,0,300.000,300.000,22.990,15.410,1
3752895765.164800,0.000000,Standby,299.896,300.005,38.507,3.127,0,0,300.000,300.000,20.860,15.150,1
3752895925.164800,0.000000,Standby,300.111,300.003,38.565,3.127,0,0,300.000,300.000,20.000,14.920,1
3752896085.164800,0.000000,Standby,299.930,299.999,38.618,3.128,0,0,300.000,300.000,21.960,14.730,1
3752896245.164800,0.000000,Standby,300.017,300.003,38.674,3.129,0,0,300.000,300.000,18.860,14.530,1
3752896405.164800,0.000000,Standby,300.040,300.003,38.724,3.131,0,0,300.000,300.000,20.810,14.310,1
3752896565.164800,0.000000,Standby,299.936,299.999,38.776,3.132,0,0,300.000,300.000,19.600,14.150,1
3752896725.164800,0.000000,Standby,300.065,300.001,38.829,3.132,0,0,300.000,300.000,18.990,13.940,1
3752896885.164800,0.000000,Standby,299.959,300.000,38.880,3.132,0,0,300.000,300.000,20.000,13.790,1
3752897045.164800,0.000000,Standby,300.010,300.002,38.929,3.134,0,0,300.000,300.000,18.180,13.610,1
3752897205.164800,0.000000,Standby,300.023,300.000,38.982,3.133,0,0,300.000,300.000,19.250,13.440,1
3752897365.164800,0.000000,Standby,299.962,300.003,39.032,3.135,0,0,300.000,300.000,18.480,13.250,1
3752897525.164800,0.000000,Standby,300.039,300.000,39.080,3.138,0,0,300.000,300.000,18.050,13.160,1
3752897685.164800,0.000000,Standby,299.971,300.003,39.128,3.137,0,0,300.000,300.000,18.670,13.010,1
3752897845.164800,0.000000,Standby,300.009,300.001,39.173,3.137,0,0,300.000,300.000,17.530,12.900,1
3752898005.164800,0.000000,Standby,300.011,299.999,39.218,3.138,0,0,300.000,300.000,18.100,12.790,1
3752898165.164800,0.000000,Standby,299.979,299.999,39.263,3.139,0,0,300.000,300.000,17.550,12.640,1
3752898325.164800,0.000000,Standby,300.021,300.002,39.305,3.139,0,0,300.000,300.000,17.220,12.510,1
3752898485.164800,0.000000,Standby,299.985,300.002,39.347,3.137,0,0,300.000,300.000,17.680,12.400,1
3752898645.164800,0.000000,Standby,300.003,299.999,39.388,3.137,0,0,300.000,300.000,16.890,12.270,1
3752898805.164800,0.000000,Standby,300.005,299.999,39.427,3.139,0,0,300.000,300.000,17.200,12.220,1
3752898965.164800,0.000000,Standby,299.989,299.999,39.468,3.139,0,0,300.000,300.000,16.790,12.110,1
3752899125.164800,0.000000,Standby,300.014,300.003,39.507,3.140,0,0,300.000,300.000,16.710,11.980,1
3752899285.164800,0.000000,Standby,299.991,300.002,39.547,3.141,0,0,300.000,300.000,16.790,11.890,1
3752899445.164800,0.000000,Standby,300.084,0.000,39.599,3.139,0,0,300.000,300.000,18.270,0.000,4
3752899605.164800,0.000000,Standby,299.934,0.000,39.657,3.138,0,0,300.000,300.000,20.400,0.000,4
3752899765.164800,0.000000,Standby,300.020,0.000,39.666,3.139,0,0,300.000,300.000,17.990,0.000,4
3752899925.164800,0.000000,Standby,300.024,0.000,39.652,3.138,0,0,300.000,300.000,19.940,0.000,4
3752900085.164800,0.000000,Standby,299.954,0.000,39.632,3.136,0,0,300.000,300.000,18.820,0.000,4
3752900245.164800,0.000000,Standby,300.052,0.000,39.614,3.137,0,0,300.000,300.000,18.630,0.000,4
3752900405.164800,0.000000,Standby,299.962,0.000,39.601,3.138,0,0,300.000,300.000,19.390,0.000,4
3752900565.164800,0.000000,Standby,300.012,0.000,39.592,3.139,0,0,300.000,300.000,18.100,0.000,4
3752900725.164800,0.000000,Standby,300.014,0.000,39.589,3.138,0,0,300.000,300.000,19.100,0.000,4
3752900885.164800,0.000000,Standby,299.974,0.000,39.587,3.139,0,0,300.000,300.000,18.460,0.000,4
3752901045.164800,0.000000,Standby,300.030,0.000,39.591,3.140,0,0,300.000,300.000,18.350,0.000,4
3752901205.164800,0.000000,Standby,299.980,0.000,39.599,3.142,0,0,300.000,300.000,18.760,0.000,4
3752901365.164800,0.000000,Standby,300.009,0.000,39.610,3.143,0,0,300.000,300.000,17.990,0.000,4
3752901525.164800,0.000000,Standby,300.005,0.000,39.624,3.142,0,0,300.000,300.000,18.560,0.000,4
3752901685.164800,0.000000,Standby,299.986,0.000,39.638,3.145,0,0,300.000,300.000,18.120,0.000,4
3752901845.164800,0.000000,Standby,300.017,0.000,39.654,3.143,0,0,300.000,300.000,18.120,0.000,4
3752902005.164800,0.000000,Standby,299.986,0.000,39.668,3.143,0,0,300.000,300.000,18.270,0.000,4
3752902165.164800,0.000000,Standby,300.007,0.000,39.684,3.144,0,0,300.000,300.000,17.780,0.000,4
3752902325.164800,0.000000,Standby,300.001,0.000,39.700,3.145,0,0,300.000,300.000,18.220,0.000,4
3752902485.164800,0.000000,Standby,299.994,0.000,39.717,3.146,0,0,300.000,300.000,17.820,0.000,4
3752902645.164800,0.000000,Standby,300.012,0.000,39.739,3.145,0,0,300.000,300.000,17.910,0.000,4
3752902805.164800,0.000000,Standby,299.987,0.000,39.757,3.149,0,0,300.000,300.000,17.930,0.000,4
3752902965.164800,0.000000,Standby,300.007,0.000,39.776,3.148,0,0,300.000,300.000,17.640,0.000,4
3752903125.164800,0.000000,Standby,300.002,0.000,39.796,3.146,0,0,300.000,300.000,17.870,0.000,4
3752903285.164800,0.000000,Standby,299.994,0.000,39.814,3.149,0,0,300.000,300.000,17.660,0.000,4
3752903445.164800,0.000000,Standby,300.008,0.000,39.834,3.148,0,0,300.000,300.000,17.640,0.000,4
3752903605.164800,0.000000,Standby,299.993,0.000,39.854,3.150,0,0,300.000,300.000,17.680,0.000,4
3752903765.164800,0.000000,Standby,300.001,0.000,39.873,3.149,0,0,300.000,300.000,17.450,0.000,4
3752903925.164800,0.000000,Standby,300.001,0.000,39.893,3.150,0,0,300.000,300.000,17.640,0.000,4
3752904085.164800,0.000000,Standby,299.998,0.000,39.913,3.150,0,0,300.000,300.000,17.450,0.000,4
3752904245.164800,0.000000,Standby,300.004,0.000,39.929,3.149,0,0,300.000,300.000,17.430,0.000,4
3752904405.164800,0.000000,Standby,299.995,0.000,39.945,3.151,0,0,300.000,300.000,17.490,0.000,4
3752904565.164800,0.000000,Standby,300.002,0.000,39.962,3.150,0,0,300.000,300.000,17.320,0.000,4
3752904725.164800,0.000000,Standby,300.000,0.000,39.978,3.149,0,0,300.000,300.000,17.430,0.000,4
3752904885.164800,0.000000,Standby,299.997,0.000,39.995,3.152,0,0,300.000,300.000,17.300,0.000,4
3752905045.164800,0.000000,Standby,300.006,0.000,40.013,3.152,0,0,300.000,300.000,17.300,0.000,4
3752905205.164800,0.000000,Standby,299.998,0.000,40.030,3.151,0,0,300.000,300.000,17.370,0.000,4
3752905365.164800,0.000000,Standby,300.000,0.000,40.045,3.152,0,0,300.000,300.000,17.180,0.000,4
3752905525.164800,0.000000,Standby,300.000,0.000,40.064,3.150,0,0,300.000,300.000,17.260,0.000,4
3752905685.164800,0.000000,Standby,300.000,0.000,40.081,3.150,0,0,300.000,300.000,17.200,0.000,4
3752905845.164800,0.000000,Standby,300.003,0.000,40.098,3.150,0,0,300.000,300.000,17.160,0.000,4
3752906005.164800,0.000000,Standby,299.994,0.000,40.114,3.150,0,0,300.000,300.000,17.220,0.000,4
3752906165.164800,0.000000,Standby,300.006,0.000,40.128,3.149,0,0,300.000,300.000,16.990,0.000,4
3752906325.164800,0.000000,Standby,300.000,0.000,40.144,3.151,0,0,300.000,300.000,17.180,0.000,4
3752906485.164800,0.000000,Standby,299.997,0.000,40.158,3.151,0,0,300.000,300.000,17.040,0.000,4
3752906645.164800,0.000000,Standby,300.005,0.000,40.172,3.152,0,0,300.000,300.000,17.020,0.000,4
3752906805.164800,0.000000,Standby,299.994,0.000,40.188,3.152,0,0,300.000,300.000,17.080,0.000,4
3752906965.164800,0.000000,Standby,300.003,0.000,40.204,3.154,0,0,300.000,300.000,16.930,0.000,4
3752907125.164800,0.000000,Standby,299.998,0.000,40.218,3.153,0,0,300.000,300.000,17.060,0.000,4
3752907285.164800,0.000000,Standby,300.000,0.000,40.232,3.154,0,0,300.000,300.000,16.970,0.000,4
3752907445.164800,0.000000,Standby,300.004,0.000,40.248,3.152,0,0,300.000,300.000,16.950,0.000,4
3752907605.164800,0.000000,Standby,299.998,0.000,40.262,3.152,0,0,300.000,300.000,16.970,0.000,4
3752907765.164800,0.000000,Standby,300.004,0.000,40.274,3.153,0,0,300.000,300.000,16.850,0.000,4
3752907925.164800,0.000000,Standby,299.997,0.000,40.287,3.152,0,0,300.000,300.000,16.950,0.000,4
3752908085.164800,0.000000,Standby,299.998,0.000,40.298,3.154,0,0,300.000,300.000,16.790,0.000,4
3752908245.164800,0.000000,Standby,300.006,0.000,40.310,3.152,0,0,300.000,300.000,16.930,0.000,4
3752908405.164800,0.000000,Standby,299.992,0.000,40.322,3.155,0,0,300.000,300.000,16.890,0.000,4
3752908565.164800,0.000000,Standby,300.007,0.000,40.334,3.154,0,0,300.000,300.000,16.670,0.000,4
3752908725.164800,0.000000,Standby,299.997,0.000,40.346,3.153,0,0,300.000,300.000,16.910,0.000,4
3752908885.164800,0.000000,Standby,299.996,0.000,40.355,3.155,0,0,300.000,300.000,16.610,0.000,4
3752909045.164800,0.000000,Standby,300.005,0.000,40.368,3.153,0,0,300.000,300.000,16.770,0.000,4
3752909205.164800,0.000000,Standby,299.997,0.000,40.379,3.155,0,0,300.000,300.000,16.850,0.000,4
3752909365.164800,0.000000,Standby,300.005,0.000,40.389,3.155,0,0,300.000,300.000,16.730,0.000,4
3752909525.164800,0.000000,Standby,299.999,0.000,40.399,3.156,0,0,300.000,300.000,16.810,0.000,4
3752909685.164800,0.000000,Standby,299.999,0.000,40.408,3.156,0,0,300.000,300.000,16.670,0.000,4
3752909845.164800,0.000000,Standby,300.001,0.000,40.418,3.157,0,0,300.000,300.000,16.790,0.000,4
3752910005.164800,0.000000,Standby,299.998,0.000,40.430,3.155,0,0,300.000,300.000,16.730,0.000,4
3752910165.164800,0.000000,Standby,300.003,0.000,40.439,3.153,0,0,300.000,300.000,16.670,0.000,4
3752910325.164800,0.000000,Standby,299.997,0.000,40.447,3.154,0,0,300.000,300.000,16.710,0.000,4
3752910485.164800,0.000000,Standby,300.000,0.000,40.455,3.155,0,0,300.000,300.000,16.610,0.000,4
3752910645.164800,0.000000,Standby,300.001,0.000,40.464,3.155,0,0,300.000,300.000,16.730,0.000,4
3752910805.164800,0.000000,Standby,299.998,0.000,40.472,3.154,0,0,300.000,300.000,16.690,0.000,4
3752910965.164800,0.000000,Standby,300.002,0.000,40.480,3.154,0,0,300.000,300.000,16.590,0.000,4
3752911125.164800,0.000000,Standby,300.000,0.000,40.487,3.155,0,0,300.000,300.000,16.690,0.000,4
3752911285.164800,0.000000,Standby,299.998,0.000,40.494,3.155,0,0,300.000,300.000,16.670,0.000,4
3752911445.164800,0.000000,Standby,300.003,0.000,40.503,3.155,0,0,300.000,300.000,16.590,0.000,4
3752911605.164800,0.000000,Standby,299.997,0.000,40.510,3.154,0,0,300.000,300.000,16.610,0.000,4
3752911765.164800,0.000000,Standby,299.999,0.000,40.518,3.155,0,0,300.000,300.000,16.510,0.000,4
3752911925.164800,0.000000,Standby,300.004,0.000,40.524,3.154,0,0,300.000,300.000,16.650,0.000,4
3752912085.164800,0.000000,Standby,299.997,0.000,40.530,3.154,0,0,300.000,300.000,16.630,0.000,4
3752912245.164800,0.000000,Standby,300.005,0.000,40.538,3.156,0,0,300.000,300.000,16.550,0.000,4
3752912405.164800,0.000000,Standby,299.996,0.000,40.546,3.156,0,0,300.000,300.000,16.670,0.000,4
3752912565.164800,0.000000,Standby,299.998,0.000,40.552,3.155,0,0,300.000,300.000,16.450,0.000,4
3752912725.164800,0.000000,Standby,300.005,0.000,40.558,3.156,0,0,300.000,300.000,16.670,0.000,4
3752912885.164800,0.000000,Standby,299.994,0.000,40.565,3.159,0,0,300.000,300.000,16.550,0.000,4
3752913045.164800,0.000000,Standby,300.008,0.000,40.571,3.157,0,0,300.000,300.000,16.430,0.000,4
3752913205.164800,0.000000,Standby,299.992,0.000,40.576,3.162,0,0,300.000,300.000,16.710,0.000,4
3752913365.164800,0.000000,Standby,300.002,0.000,40.584,3.160,0,0,300.000,300.000,16.410,0.000,4
3752913525.164800,0.000000,Standby,300.004,0.000,40.592,3.158,0,0,300.000,300.000,16.650,0.000,4
3752913685.164800,0.000000,Standby,299.993,0.000,40.597,3.158,0,0,300.000,300.000,16.510,0.000,4
3752913845.164800,0.000000,Standby,300.008,0.000,40.603,3.159,0,0,300.000,300.000,16.410,0.000,4
3752914005.164800,0.000000,Standby,299.996,0.000,40.608,3.159,0,0,300.000,300.000,16.650,0.000,4
3752914165.164800,0.000000,Standby,299.997,0.000,40.614,3.161,0,0,300.000,300.000,16.450,0.000,4
3752914325.164800,0.000000,Standby,300.005,0.000,40.618,3.161,0,0,300.000,300.000,16.530,0.000,4
3752914485.164800,0.000000,Standby,299.996,0.000,40.623,3.164,0,0,300.000,300.000,16.490,0.000,4
3752914645.164800,0.000000,Standby,300.001,0.000,40.629,3.163,0,0,300.000,300.000,16.450,0.000,4
3752914805.164800,0.000000,Standby,300.002,0.000,40.635,3.162,0,0,300.000,300.000,16.550,0.000,4
3752914965.164800,0.000000,Standby,299.998,0.000,40.640,3.161,0,0,300.000,300.000,16.490,0.000,4
3752915125.164800,0.000000,Standby,300.001,0.000,40.644,3.161,0,0,300.000,300.000,16.490,0.000,4
3752915285.164800,0.000000,Standby,299.998,0.000,40.649,3.161,0,0,300.000,300.000,16.470,0.000,4
3752915445.164800,0.000000,Standby,300.003,0.000,40.655,3.161,0,0,300.000,300.000,16.450,0.000,4
3752915605.164800,0.000000,Standby,300.003,0.000,40.658,3.161,0,0,300.000,300.000,16.490,0.000,4
3752915765.164800,0.000000,Standby,299.994,0.000,40.662,3.160,0,0,300.000,300.000,16.530,0.000,4
3752915925.164800,0.000000,Standby,300.003,0.000,40.666,3.160,0,0,300.000,300.000,16.390,0.000,4
3752916085.164800,0.000000,Standby,299.997,0.000,40.668,3.160,0,0,300.000,300.000,16.510,0.000,4
3752916245.164800,0.000000,Standby,300.002,0.000,40.672,3.160,0,0,300.000,300.000,16.350,0.000,4
3752916405.164800,0.000000,Standby,300.001,0.000,40.675,3.160,0,0,300.000,300.000,16.470,0.000,4
3752916565.164800,0.000000,Standby,299.996,0.000,40.676,3.161,0,0,300.000,300.000,16.430,0.000,4
3752916725.164800,0.000000,Standby,300.001,0.000,40.681,3.160,0,0,300.000,300.000,16.390,0.000,4
3752916885.164800,0.000000,Standby,300.000,0.000,40.685,3.162,0,0,300.000,300.000,16.510,0.000,4
3752917045.164800,0.000000,Standby,299.997,0.000,40.691,3.161,0,0,300.000,300.000,16.470,0.000,4
3752917205.164800,0.000000,Standby,300.003,0.000,40.694,3.160,0,0,300.000,300.000,16.430,0.000,4
3752917365.164800,0.000000,Standby,299.997,0.000,40.698,3.161,0,0,300.000,300.000,16.450,0.000,4
3752917525.164800,0.000000,Standby,300.000,0.000,40.701,3.163,0,0,300.000,300.000,16.410,0.000,4
3752917685.164800,0.000000,Standby,299.998,0.000,40.707,3.162,0,0,300.000,300.000,16.410,0.000,4
3752917845.164800,0.000000,Standby,300.003,0.000,40.709,3.162,0,0,300.000,300.000,16.410,0.000,4
3752918005.164800,0.000000,Standby,299.999,0.000,40.711,3.161,0,0,300.000,300.000,16.470,0.000,4
3752918165.164800,0.000000,Standby,299.999,0.000,40.713,3.162,0,0,300.000,300.000,16.390,0.000,4
3752918325.164800,0.000000,Standby,300.002,0.000,40.715,3.161,0,0,300.000,300.000,16.410,0.000,4
3752918485.164800,0.000000,Standby,299.998,0.000,40.718,3.161,0,0,300.000,300.000,16.390,0.000,4
3752918645.164800,0.000000,Standby,299.999,0.000,40.720,3.163,0,0,300.000,300.000,16.350,0.000,4
3752918805.164800,0.000000,Standby,300.001,0.000,40.724,3.161,0,0,300.000,300.000,16.410,0.000,4
3752918965.164800,0.000000,Standby,300.000,0.000,40.724,3.160,0,0,300.000,300.000,16.390,0.000,4
3752919125.164800,0.000000,Standby,299.998,0.000,40.727,3.161,0,0,300.000,300.000,16.430,0.000,4
3752919285.164800,0.000000,Standby,300.002,0.000,40.728,3.162,0,0,300.000,300.000,16.370,0.000,4
3752919445.164800,0.000000,Standby,300.000,0.000,40.730,3.161,0,0,300.000,300.000,16.430,0.000,4
3752919605.164800,0.000000,Standby,299.998,0.000,40.733,3.162,0,0,300.000,300.000,16.390,0.000,4
3752919765.164800,0.000000,Standby,300.004,0.000,40.735,3.161,0,0,300.000,300.000,16.350,0.000,4
3752919925.164800,0.000000,Standby,299.996,0.000,40.737,3.163,0,0,300.000,300.000,16.430,0.000,4
3752920085.164800,0.000000,Standby,300.000,0.000,40.737,3.163,0,0,300.000,300.000,16.350,0.000,4
3752920245.164800,0.000000,Standby,300.000,0.000,40.739,3.162,0,0,300.000,300.000,16.430,0.000,4
3752920405.164800,0.000000,Standby,299.999,0.000,40.739,3.162,0,0,300.000,300.000,16.370,0.000,4
3752920565.164800,0.000000,Standby,300.003,0.000,40.741,3.162,0,0,300.000,300.000,16.350,0.000,4
3752920725.164800,0.000000,Standby,299.997,0.000,40.744,3.160,0,0,300.000,300.000,16.450,0.000,4
3752920885.164800,0.000000,Standby,300.000,0.000,40.746,3.161,0,0,300.000,300.000,16.330,0.000,4
3752921045.164800,0.000000,Standby,300.000,0.000,40.748,3.161,0,0,300.000,300.000,16.410,0.000,4
3752921205.164800,0.000000,Standby,299.999,0.000,40.749,3.162,0,0,300.000,300.000,16.370,0.000,4
3752921365.164800,0.000000,Standby,300.000,0.000,40.752,3.161,0,0,300.000,300.000,16.330,0.000,4
3752921525.164800,0.000000,Standby,300.000,0.000,40.754,3.160,0,0,300.000,300.000,16.370,0.000,4
3752921685.164800,0.000000,Standby,299.997,0.000,40.756,3.163,0,0,300.000,300.000,16.390,0.000,4
3752921845.164800,0.000000,Standby,300.001,0.000,40.757,3.162,0,0,300.000,300.000,16.270,0.000,4
3752922005.164800,0.000000,Standby,300.002,0.000,40.758,3.163,0,0,300.000,300.000,16.410,0.000,4
3752922165.164800,0.000000,Standby,299.998,0.000,40.760,3.164,0,0,300.000,300.000,16.370,0.000,4
3752922325.164800,0.000000,Standby,300.001,0.000,40.761,3.162,0,0,300.000,300.000,16.370,0.000,4
3752922485.164800,0.000000,Standby,300.000,0.000,40.759,3.164,0,0,300.000,300.000,16.410,0.000,4
3752922645.164800,0.000000,Standby,300.001,0.000,40.756,3.162,0,0,300.000,300.000,16.350,0.000,4
3752922805.164800,0.000000,Standby,299.999,0.000,40.755,3.163,0,0,300.000,300.000,16.390,0.000,4
3752922965.164800,0.000000,Standby,299.999,0.000,40.758,3.162,0,0,300.000,300.000,16.370,0.000,4
3752923125.164800,0.000000,Standby,300.003,0.000,40.756,3.162,0,0,300.000,300.000,16.410,0.000,4
3752923285.164800,0.000000,Standby,299.998,0.000,40.754,3.162,0,0,300.000,300.000,16.410,0.000,4
3752923445.164800,0.000000,Standby,300.002,0.000,40.756,3.162,0,0,300.000,300.000,16.330,0.000,4
3752923605.164800,0.000000,Standby,300.001,0.000,40.757,3.163,0,0,300.000,300.000,16.430,0.000,4
3752923765.164800,0.000000,Standby,299.994,0.000,40.759,3.162,0,0,300.000,300.000,16.330,0.000,4
3752923925.164800,0.000000,Standby,300.005,0.000,40.762,3.163,0,0,300.000,300.000,16.290,0.000,4
3752924085.164800,0.000000,Standby,299.998,0.000,40.764,3.163,0,0,300.000,300.000,16.450,0.000,4
3752924245.164800,0.000000,Standby,299.999,0.000,40.763,3.162,0,0,300.000,300.000,16.290,0.000,4
3752924405.164800,0.000000,Standby,300.003,0.000,40.760,3.163,0,0,300.000,300.000,16.330,0.000,4
3752924565.164800,0.000000,Standby,299.998,0.000,40.763,3.164,0,0,300.000,300.000,16.350,0.000,4
3752924725.164800,0.000000,Standby,300.000,0.000,40.768,3.163,0,0,300.000,300.000,16.390,0.000,4
3752924885.164800,0.000000,Standby,299.998,0.000,40.771,3.164,0,0,300.000,300.000,16.370,0.000,4
3752925045.164800,0.000000,Standby,299.998,0.000,40.775,3.164,0,0,300.000,300.000,16.330,0.000,4
3752925205.164800,0.000000,Standby,300.003,0.000,40.777,3.163,0,0,300.000,300.000,16.330,0.000,4
3752925365.164800,0.000000,Standby,299.995,0.000,40.777,3.163,0,0,300.000,300.000,16.350,0.000,4
3752925525.164800,0.000000,Standby,300.003,0.000,40.779,3.163,0,0,300.000,300.000,16.290,0.000,4
3752925685.164800,0.000000,Standby,300.001,0.000,40.778,3.163,0,0,300.000,300.000,16.390,0.000,4
3752925845.164800,0.000000,Standby,299.996,0.000,40.780,3.162,0,0,300.000,300.000,16.350,0.000,4
3752926005.164800,0.000000,Standby,300.002,0.000,40.780,3.163,0,0,300.000,300.000,16.310,0.000,4
3752926165.164800,0.000000,Standby,299.998,0.000,40.782,3.162,0,0,300.000,300.000,16.430,0.000,4
3752926325.164800,0.000000,Standby,299.998,0.000,40.780,3.162,0,0,300.000,300.000,16.290,0.000,4
3752926485.164800,0.000000,Standby,300.000,0.000,40.780,3.163,0,0,300.000,300.000,16.350,0.000,4
3752926645.164800,0.000000,Standby,299.995,0.000,40.780,3.165,0,0,300.000,300.000,16.330,0.000,4
3752926805.164800,0.000000,Standby,300.003,0.000,40.779,3.164,0,0,300.000,300.000,16.350,0.000,4
3752926965.164800,0.000000,Standby,300.000,0.000,40.777,3.162,0,0,300.000,300.000,16.330,0.000,4
3752927125.164800,0.000000,Standby,299.998,0.000,40.775,3.162,0,0,300.000,300.000,16.350,0.000,4
3752927285.164800,0.000000,Standby,300.000,0.000,40.777,3.164,0,0,300.000,300.000,16.370,0.000,4
3752927445.164800,0.000000,Standby,300.000,0.000,40.778,3.163,0,0,300.000,300.000,16.330,0.000,4
3752927605.164800,0.000000,Standby,300.000,0.000,40.778,3.162,0,0,300.000,300.000,16.310,0.000,4
3752927765.164800,0.000000,Standby,299.997,0.000,40.779,3.163,0,0,300.000,300.000,16.370,0.000,4
3752927925.164800,0.000000,Standby,300.001,0.000,40.780,3.164,0,0,300.000,300.000,16.350,0.000,4
3752928085.164800,0.000000,Standby,299.999,0.000,40.783,3.165,0,0,300.000,300.000,16.410,0.000,4
3752928245.164800,0.000000,Standby,299.999,0.000,40.786,3.165,0,0,300.000,300.000,16.310,0.000,4
3752928405.164800,0.000000,Standby,300.002,0.000,40.787,3.164,0,0,300.000,300.000,16.390,0.000,4
3752928565.164800,0.000000,Standby,299.989,0.000,40.788,3.163,0,0,300.000,300.000,16.410,0.000,4
3752928725.164800,0.000000,Standby,300.006,0.000,40.792,3.163,0,0,300.000,300.000,16.210,0.000,4
3752928885.164800,0.000000,Standby,299.996,0.000,40.795,3.162,0,0,300.000,300.000,16.490,0.000,4
3752929045.164800,0.000000,Standby,300.001,0.000,40.795,3.164,0,0,300.000,300.000,16.230,0.000,4
3752929205.164800,0.000000,Standby,300.000,0.000,40.796,3.163,0,0,300.000,300.000,16.430,0.000,4
3752929365.164800,0.000000,Standby,299.995,0.000,40.797,3.164,0,0,300.000,300.000,16.270,0.000,4
3752929525.164800,0.000000,Standby,300.007,0.000,40.797,3.163,0,0,300.000,300.000,16.330,0.000,4
3752929685.164800,0.000000,Standby,299.995,0.000,40.801,3.165,0,0,300.000,300.000,16.410,0.000,4
3752929845.164800,0.000000,Standby,300.001,0.000,40.804,3.163,0,0,300.000,300.000,16.230,0.000,4
3752930005.164800,0.000000,Standby,300.001,0.000,40.805,3.163,0,0,300.000,300.000,16.410,0.000,4
3752930165.164800,0.000000,Standby,299.995,0.000,40.806,3.163,0,0,300.000,300.000,16.290,0.000,4
3752930325.164800,0.000000,Standby,300.005,0.000,40.807,3.164,0,0,300.000,300.000,16.350,0.000,4
3752930485.164800,0.000000,Standby,299.993,0.000,40.808,3.164,0,0,300.000,300.000,16.370,0.000,4
3752930645.164800,0.000000,Standby,300.003,0.000,40.808,3.164,0,0,300.000,300.000,16.270,0.000,4
3752930805.164800,0.000000,Standby,299.996,0.000,40.810,3.163,0,0,300.000,300.000,16.410,0.000,4
3752930965.164800,0.000000,Standby,300.001,0.000,40.810,3.165,0,0,300.000,300.000,16.230,0.000,4
3752931125.164800,0.000000,Standby,300.003,0.000,40.810,3.162,0,0,300.000,300.000,16.390,0.000,4
3752931285.164800,0.000000,Standby,299.996,0.000,40.811,3.164,0,0,300.000,300.000,16.350,0.000,4
3752931445.164800,0.000000,Standby,300.005,0.000,40.810,3.163,0,0,300.000,300.000,16.330,0.000,4
3752931605.164800,0.000000,Standby,300.001,0.000,40.809,3.163,0,0,300.000,300.000,16.430,0.000,4
3752931765.165000,0.000000,Standby,299.992,0.000,40.809,3.162,0,0,300.000,300.000,16.330,0.000,4
3752931925.165000,0.000000,Standby,300.007,0.000,40.807,3.163,0,0,300.000,300.000,16.290,0.000,4
3752932085.165000,0.000000,Standby,299.993,0.000,40.809,3.162,0,0,300.000,300.000,16.410,0.000,4
3752932245.165000,0.000000,Standby,300.003,0.000,40.808,3.163,0,0,300.000,300.000,16.230,0.000,4
3752932405.165000,0.000000,Standby,299.999,0.000,40.809,3.165,0,0,300.000,300.000,16.410,0.000,4
3752932565.165000,0.000000,Standby,299.998,0.000,40.809,3.163,0,0,300.000,300.000,16.330,0.000,4
3752932725.165000,0.000000,Standby,300.002,0.000,40.809,3.164,0,0,300.000,300.000,16.370,0.000,4
3752932885.165000,0.000000,Standby,299.998,0.000,40.810,3.162,0,0,300.000,300.000,16.350,0.000,4
3752933045.165000,0.000000,Standby,300.004,0.000,40.809,3.162,0,0,300.000,300.000,16.310,0.000,4
3752933205.165000,0.000000,Standby,300.000,0.000,40.808,3.164,0,0,300.000,300.000,16.390,0.000,4
3752933365.165000,0.000000,Standby,299.997,0.000,40.809,3.164,0,0,300.000,300.000,16.370,0.000,4
3752933525.165000,0.000000,Standby,300.002,0.000,40.808,3.164,0,0,300.000,300.000,16.370,0.000,4
3752933685.165000,0.000000,Standby,299.995,0.000,40.810,3.162,0,0,300.000,300.000,16.330,0.000,4
3752933845.165000,0.000000,Standby,300.003,0.000,40.809,3.163,0,0,300.000,300.000,16.350,0.000,4
3752934005.165000,0.000000,Standby,299.996,0.000,40.808,3.162,0,0,300.000,300.000,16.370,0.000,4
3752934165.165000,0.000000,Standby,300.000,0.000,40.807,3.163,0,0,300.000,300.000,16.270,0.000,4
3752934325.165000,0.000000,Standby,300.000,0.000,40.806,3.161,0,0,300.000,300.000,16.390,0.000,4
3752934485.165000,0.000000,Standby,300.001,0.000,40.807,3.160,0,0,300.000,300.000,16.310,0.000,4
3752934645.165000,0.000000,Standby,300.001,0.000,40.804,3.161,0,0,300.000,300.000,16.350,0.000,4
3752934805.165000,0.000000,Standby,300.000,0.000,40.802,3.162,0,0,300.000,300.000,16.310,0.000,4
3752934965.165000,0.000000,Standby,299.999,0.000,40.803,3.162,0,0,300.000,300.000,16.330,0.000,4
3752935125.165000,0.000000,Standby,300.000,0.000,40.804,3.163,0,0,300.000,300.000,16.330,0.000,4
3752935285.165000,0.000000,Standby,299.999,0.000,40.803,3.163,0,0,300.000,300.000,16.350,0.000,4
3752935445.165000,0.000000,Standby,300.000,0.000,40.802,3.162,0,0,300.000,300.000,16.310,0.000,4
3752935605.165000,0.000000,Standby,300.002,0.000,40.803,3.164,0,0,300.000,300.000,16.310,0.000,4
3752935765.165000,0.000000,Standby,299.997,0.000,40.803,3.164,0,0,300.000,300.000,16.410,0.000,4
3752935925.165000,0.000000,Standby,300.000,0.000,40.804,3.164,0,0,300.000,300.000,16.330,0.000,4
3752936085.165000,0.000000,Standby,300.002,0.000,40.804,3.164,0,0,300.000,300.000,16.290,0.000,4
3752936245.165000,0.000000,Standby,299.998,0.000,40.802,3.165,0,0,300.000,300.000,16.370,0.000,4
3752936405.165000,0.000000,Standby,300.000,0.000,40.804,3.164,0,0,300.000,300.000,16.330,0.000,4
3752936565.165000,0.000000,Standby,300.002,0.000,40.804,3.164,0,0,300.000,300.000,16.350,0.000,4
3752936725.165000,0.000000,Standby,299.999,0.000,40.805,3.162,0,0,300.000,300.000,16.330,0.000,4
3752936885.165000,0.000000,Standby,300.003,0.000,40.806,3.162,0,0,300.000,300.000,16.350,0.000,4
3752937045.165000,0.000000,Standby,299.999,0.000,40.808,3.164,0,0,300.000,300.000,16.310,0.000,4
3752937205.165000,0.000000,Standby,300.003,0.000,40.807,3.164,0,0,300.000,300.000,16.310,0.000,4
3752937365.165000,0.000000,Standby,299.997,0.000,40.807,3.165,0,0,300.000,300.000,16.350,0.000,4
3752937525.165000,0.000000,Standby,299.999,0.000,40.806,3.164,0,0,300.000,300.000,16.310,0.000,4
3752937685.165000,0.000000,Standby,299.998,0.000,40.807,3.165,0,0,300.000,300.000,16.350,0.000,4
3752937845.165000,0.000000,Standby,300.000,0.000,40.806,3.164,0,0,300.000,300.000,16.330,0.000,4
3752938005.165000,0.000000,Standby,300.000,0.000,40.806,3.165,0,0,300.000,300.000,16.290,0.000,4
3752938165.165000,0.000000,Standby,300.000,0.000,40.807,3.164,0,0,300.000,300.000,16.350,0.000,4
3752938325.165000,0.000000,Standby,299.997,0.000,40.805,3.164,0,0,300.000,300.000,16.370,0.000,4
3752938485.165000,0.000000,Standby,300.002,0.000,40.803,3.163,0,0,300.000,300.000,16.290,0.000,4
3752938645.165000,0.000000,Standby,299.997,0.000,40.802,3.161,0,0,300.000,300.000,16.390,0.000,4
3752938805.165000,0.000000,Standby,300.000,0.000,40.801,3.162,0,0,300.000,300.000,16.270,0.000,4
3752938965.165000,0.000000,Standby,300.002,0.000,40.801,3.163,0,0,300.000,300.000,16.350,0.000,4
3752939125.165000,0.000000,Standby,299.994,0.000,40.799,3.161,0,0,300.000,300.000,16.390,0.000,4
3752939285.165000,0.000000,Standby,300.005,0.000,40.799,3.162,0,0,300.000,300.000,16.330,0.000,4
3752939445.165000,0.000000,Standby,299.997,0.000,40.799,3.163,0,0,300.000,300.000,16.330,0.000,4
3752939605.165000,0.000000,Standby,300.000,0.000,40.798,3.163,0,0,300.000,300.000,16.290,0.000,4
3752939765.165000,0.000000,Standby,299.998,0.000,40.796,3.163,0,0,300.000,300.000,16.330,0.000,4
3752939925.165000,0.000000,Standby,300.000,0.000,40.796,3.162,0,0,300.000,300.000,16.290,0.000,4
3752940085.165000,0.000000,Standby,300.002,0.000,40.798,3.164,0,0,300.000,300.000,16.390,0.000,4
3752940245.165000,0.000000,Standby,299.998,0.000,40.796,3.163,0,0,300.000,300.000,16.270,0.000,4
3752940405.165000,0.000000,Standby,300.004,0.000,40.796,3.163,0,0,300.000,300.000,16.330,0.000,4
3752940565.165000,0.000000,Standby,300.000,0.000,40.796,3.162,0,0,300.000,300.000,16.390,0.000,4
3752940725.165000,0.000000,Standby,300.001,0.000,40.796,3.163,0,0,300.000,300.000,16.270,0.000,4
3752940885.165000,0.000000,Standby,299.999,0.000,40.797,3.162,0,0,300.000,300.000,16.410,0.000,4
3752941045.165000,0.000000,Standby,299.998,0.000,40.794,3.164,0,0,300.000,300.000,16.330,0.000,4
3752941205.165000,0.000000,Standby,300.002,0.000,40.796,3.163,0,0,300.000,300.000,16.350,0.000,4
3752941365.165000,0.000000,Standby,299.997,0.000,40.794,3.163,0,0,300.000,300.000,16.430,0.000,4
3752941525.165000,0.000000,Standby,299.999,0.000,40.792,3.163,0,0,300.000,300.000,16.310,0.000,4
3752941685.165000,0.000000,Standby,300.003,0.000,40.793,3.162,0,0,300.000,300.000,16.310,0.000,4
3752941845.165000,0.000000,Standby,299.996,0.000,40.792,3.163,0,0,300.000,300.000,16.370,0.000,4
3752942005.165000,0.000000,Standby,299.998,0.000,40.792,3.162,0,0,300.000,300.000,16.330,0.000,4
3752942165.165000,0.000000,Standby,300.003,0.000,40.791,3.163,0,0,300.000,300.000,16.350,0.000,4
3752942325.165000,0.000000,Standby,300.000,0.000,40.791,3.163,0,0,300.000,300.000,16.350,0.000,4
3752942485.165000,0.000000,Standby,299.999,0.000,40.792,3.164,0,0,300.000,300.000,16.330,0.000,4
3752942645.165000,0.000000,Standby,300.001,0.000,40.793,3.164,0,0,300.000,300.000,16.310,0.000,4
3752942805.165000,0.000000,Standby,300.002,0.000,40.792,3.162,0,0,300.000,300.000,16.350,0.000,4
3752942965.165000,0.000000,Standby,300.000,0.000,40.791,3.163,0,0,300.000,300.000,16.330,0.000,4
3752943125.165000,0.000000,Standby,300.000,0.000,40.790,3.164,0,0,300.000,300.000,16.330,0.000,4
3752943285.165000,0.000000,Standby,299.998,0.000,40.788,3.163,0,0,300.000,300.000,16.350,0.000,4
3752943445.165000,0.000000,Standby,299.999,0.000,40.790,3.162,0,0,300.000,300.000,16.350,0.000,4
3752943605.165000,0.000000,Standby,300.002,0.000,40.792,3.161,0,0,300.000,300.000,16.310,0.000,4
3752943765.165000,0.000000,Standby,299.996,0.000,40.792,3.162,0,0,300.000,300.000,16.390,0.000,4
3752943925.165000,0.000000,Standby,299.999,0.000,40.791,3.162,0,0,300.000,300.000,16.310,0.000,4
3752944085.165000,0.000000,Standby,300.000,0.000,40.790,3.162,0,0,300.000,300.000,16.330,0.000,4
3752944245.165000,0.000000,Standby,299.999,0.000,40.791,3.162,0,0,300.000,300.000,16.310,0.000,4
3752944405.165000,0.000000,Standby,299.999,0.000,40.791,3.161,0,0,300.000,300.000,16.330,0.000,4
3752944565.165000,0.000000,Standby,300.001,0.000,40.791,3.162,0,0,300.000,300.000,16.290,0.000,4
3752944725.165000,0.000000,Standby,300.001,0.000,40.792,3.163,0,0,300.000,300.000,16.350,0.000,4
3752944885.165000,0.000000,Standby,300.001,0.000,40.791,3.160,0,0,300.000,300.000,16.350,0.000,4
3752945045.165000,0.000000,Standby,300.000,0.000,40.792,3.161,0,0,300.000,300.000,16.330,0.000,4
3752945205.165000,0.000000,Standby,300.001,0.000,40.793,3.164,0,0,300.000,300.000,16.270,0.000,4
3752945365.165000,0.000000,Standby,299.998,0.000,40.794,3.164,0,0,300.000,300.000,16.350,0.000,4
3752945525.165000,0.000000,Standby,300.000,0.000,40.796,3.164,0,0,300.000,300.000,16.310,0.000,4
3752945685.165000,0.000000,Standby,300.002,0.000,40.795,3.162,0,0,300.000,300.000,16.370,0.000,4
3752945845.165000,0.000000,Standby,300.000,0.000,40.795,3.163,0,0,300.000,300.000,16.390,0.000,4
3752946005.165000,0.000000,Standby,300.001,0.000,40.793,3.162,0,0,300.000,300.000,16.290,0.000,4
3752946165.165000,0.000000,Standby,299.999,0.000,40.794,3.163,0,0,300.000,300.000,16.350,0.000,4
3752946325.165000,0.000000,Standby,299.995,0.000,40.795,3.162,0,0,300.000,300.000,16.370,0.000,4
3752946485.165000,0.000000,Standby,300.004,0.000,40.796,3.161,0,0,300.000,300.000,16.250,0.000,4
3752946645.165000,0.000000,Standby,299.996,0.000,40.795,3.160,0,0,300.000,300.000,16.450,0.000,4
3752946805.165000,0.000000,Standby,299.999,0.000,40.793,3.161,0,0,300.000,300.000,16.230,0.000,4
3752946965.165000,0.000000,Standby,300.002,0.000,40.792,3.163,0,0,300.000,300.000,16.370,0.000,4
3752947125.165000,0.000000,Standby,299.994,0.000,40.793,3.161,0,0,300.000,300.000,16.350,0.000,4
3752947285.165000,0.000000,Standby,300.006,0.000,40.794,3.162,0,0,300.000,300.000,16.250,0.000,4
3752947445.165000,0.000000,Standby,299.997,0.000,40.793,3.163,0,0,300.000,300.000,16.410,0.000,4
3752947605.165000,0.000000,Standby,299.999,0.000,40.792,3.163,0,0,300.000,300.000,16.230,0.000,4
3752947765.165000,0.000000,Standby,300.005,0.000,40.792,3.161,0,0,300.000,300.000,16.370,0.000,4
3752947925.165000,0.000000,Standby,299.993,0.000,40.792,3.163,0,0,300.000,300.000,16.350,0.000,4
3752948085.165000,0.000000,Standby,300.006,0.000,40.792,3.162,0,0,300.000,300.000,16.250,0.000,4
3752948245.165000,0.000000,Standby,299.993,0.000,40.792,3.163,0,0,300.000,300.000,16.490,0.000,4
3752948405.165000,0.000000,Standby,300.001,0.000,40.790,3.163,0,0,300.000,300.000,16.190,0.000,4
3752948565.165000,0.000000,Standby,300.003,0.000,40.790,3.163,0,0,300.000,300.000,16.490,0.000,4
3752948725.165000,0.000000,Standby,299.991,0.000,40.792,3.164,0,0,300.000,300.000,16.310,0.000,4
3752948885.165000,0.000000,Standby,300.005,0.000,40.791,3.163,0,0,300.000,300.000,16.270,0.000,4
3752949045.165000,0.000000,Standby,299.997,0.000,40.791,3.162,0,0,300.000,300.000,16.390,0.000,4
3752949205.165000,0.000000,Standby,299.999,0.000,40.792,3.163,0,0,300.000,300.000,16.270,0.000,4
3752949365.165000,0.000000,Standby,300.002,0.000,40.793,3.164,0,0,300.000,300.000,16.330,0.000,4
3752949525.165000,0.000000,Standby,299.998,0.000,40.794,3.165,0,0,300.000,300.000,16.350,0.000,4
3752949685.165000,0.000000,Standby,300.003,0.000,40.795,3.163,0,0,300.000,300.000,16.290,0.000,4
3752949845.165000,0.000000,Standby,300.000,0.000,40.795,3.164,0,0,300.000,300.000,16.390,0.000,4
3752950005.165000,0.000000,Standby,299.997,0.000,40.794,3.163,0,0,300.000,300.000,16.310,0.000,4
3752950165.165000,0.000000,Standby,300.003,0.000,40.793,3.163,0,0,300.000,300.000,16.330,0.000,4
3752950325.165000,0.000000,Standby,299.997,0.000,40.793,3.164,0,0,300.000,300.000,16.350,0.000,4
3752950485.165000,0.000000,Standby,300.001,0.000,40.792,3.163,0,0,300.000,300.000,16.310,0.000,4
3752950645.165000,0.000000,Standby,300.002,0.000,40.791,3.162,0,0,300.000,300.000,16.290,0.000,4
3752950805.165000,0.000000,Standby,299.999,0.000,40.789,3.162,0,0,300.000,300.000,16.290,0.000,4
3752950965.165000,0.000000,Standby,300.002,0.000,40.790,3.160,0,0,300.000,300.000,16.290,0.000,4
3752951125.165000,0.000000,Standby,299.997,0.000,40.791,3.161,0,0,300.000,300.000,16.330,0.000,4
3752951285.165000,0.000000,Standby,300.000,0.000,40.789,3.161,0,0,300.000,300.000,16.330,0.000,4
3752951445.165000,0.000000,Standby,299.999,0.000,40.788,3.160,0,0,300.000,300.000,16.370,0.000,4
3752951605.165000,0.000000,Standby,299.998,0.000,40.788,3.161,0,0,300.000,300.000,16.310,0.000,4
3752951765.165000,0.000000,Standby,300.002,0.000,40.788,3.161,0,0,300.000,300.000,16.310,0.000,4
3752951925.165000,0.000000,Standby,299.998,0.000,40.787,3.162,0,0,300.000,300.000,16.350,0.000,4
3752952085.165000,0.000000,Standby,300.001,0.000,40.787,3.162,0,0,300.000,300.000,16.290,0.000,4
3752952245.165000,0.000000,Standby,300.001,0.000,40.788,3.162,0,0,300.000,300.000,16.390,0.000,4
3752952405.165000,0.000000,Standby,299.998,0.000,40.790,3.162,0,0,300.000,300.000,16.290,0.000,4
3752952565.165000,0.000000,Standby,300.000,0.000,40.791,3.164,0,0,300.000,300.000,16.330,0.000,4
3752952725.165000,0.000000,Standby,300.000,0.000,40.791,3.161,0,0,300.000,300.000,16.310,0.000,4
3752952885.165000,0.000000,Standby,300.001,0.000,40.791,3.159,0,0,300.000,300.000,16.370,0.000,4
3752953045.165000,0.000000,Standby,299.999,0.000,40.792,3.160,0,0,300.000,300.000,16.350,0.000,4
3752953205.165000,0.000000,Standby,299.998,0.000,40.789,3.163,0,0,300.000,300.000,16.230,0.000,4
3752953365.165000,0.000000,Standby,300.001,0.000,40.790,3.161,0,0,300.000,300.000,16.370,0.000,4
3752953525.165000,0.000000,Standby,299.999,0.000,40.792,3.163,0,0,300.000,300.000,16.390,0.000,4
3752953685.165000,0.000000,Standby,300.000,0.000,40.794,3.161,0,0,300.000,300.000,16.330,0.000,4
3752953845.165000,0.000000,Standby,300.000,0.000,40.793,3.161,0,0,300.000,300.000,16.330,0.000,4
3752954005.165000,0.000000,Standby,300.000,0.000,40.794,3.159,0,0,300.000,300.000,16.330,0.000,4
3752954165.165000,0.000000,Standby,299.999,0.000,40.793,3.160,0,0,300.000,300.000,16.390,0.000,4
3752954325.165000,0.000000,Standby,299.998,0.000,40.793,3.161,0,0,300.000,300.000,16.330,0.000,4
3752954485.165000,0.000000,Standby,300.000,0.000,40.794,3.161,0,0,300.000,300.000,16.350,0.000,4
3752954645.165000,0.000000,Standby,300.000,0.000,40.794,3.161,0,0,300.000,300.000,16.310,0.000,4
3752954805.165000,0.000000,Standby,299.998,0.000,40.792,3.163,0,0,300.000,300.000,16.390,0.000,4
3752954965.165000,0.000000,Standby,300.001,0.000,40.789,3.162,0,0,300.000,300.000,16.270,0.000,4
3752955125.165000,0.000000,Standby,300.000,0.000,40.789,3.162,0,0,300.000,300.000,16.350,0.000,4
3752955285.165000,0.000000,Standby,299.999,0.000,40.790,3.164,0,0,300.000,300.000,16.290,0.000,4
3752955445.165000,0.000000,Standby,300.001,0.000,40.791,3.163,0,0,300.000,300.000,16.350,0.000,4
3752955605.165000,0.000000,Standby,300.000,0.000,40.791,3.164,0,0,300.000,300.000,16.310,0.000,4
3752955765.165000,0.000000,Standby,300.000,0.000,40.790,3.163,0,0,300.000,300.000,16.310,0.000,4
3752955925.165000,0.000000,Standby,299.998,0.000,40.790,3.162,0,0,300.000,300.000,16.270,0.000,4
3752956085.165000,0.000000,Standby,300.000,0.000,40.789,3.162,0,0,300.000,300.000,16.370,0.000,4
3752956245.165000,0.000000,Standby,300.000,0.000,40.789,3.165,0,0,300.000,300.000,16.310,0.000,4
3752956405.165000,0.000000,Standby,300.000,0.000,40.787,3.163,0,0,300.000,300.000,16.390,0.000,4
3752956565.165000,0.000000,Standby,299.997,0.000,40.788,3.164,0,0,300.000,300.000,16.310,0.000,4
3752956725.165000,0.000000,Standby,300.003,0.000,40.788,3.166,0,0,300.000,300.000,16.350,0.000,4
3752956885.165000,0.000000,Standby,299.997,0.000,40.790,3.165,0,0,300.000,300.000,16.370,0.000,4
3752957045.165000,0.000000,Standby,299.998,0.000,40.791,3.166,0,0,300.000,300.000,16.250,0.000,4
3752957205.165000,0.000000,Standby,300.001,0.000,40.791,3.164,0,0,300.000,300.000,16.330,0.000,4
3752957365.165000,0.000000,Standby,299.997,0.000,40.791,3.165,0,0,300.000,300.000,16.250,0.000,4
3752957525.165000,0.000000,Standby,300.000,0.000,40.790,3.165,0,0,300.000,300.000,16.290,0.000,4
3752957685.165000,0.000000,Standby,300.000,0.000,40.788,3.166,0,0,300.000,300.000,16.390,0.000,4
3752957845.165000,0.000000,Standby,299.999,0.000,40.787,3.162,0,0,300.000,300.000,16.330,0.000,4
3752958005.165000,0.000000,Standby,300.000,0.000,40.784,3.162,0,0,300.000,300.000,16.290,0.000,4
3752958165.165000,0.000000,Standby,299.999,0.000,40.783,3.163,0,0,300.000,300.000,16.350,0.000,4
3752958325.165000,0.000000,Standby,300.001,0.000,40.784,3.163,0,0,300.000,300.000,16.350,0.000,4
3752958485.165000,0.000000,Standby,299.999,0.000,40.785,3.162,0,0,300.000,300.000,16.350,0.000,4
3752958645.165000,0.000000,Standby,299.998,0.000,40.784,3.161,0,0,300.000,300.000,16.330,0.000,4
3752958805.165000,0.000000,Standby,300.002,0.000,40.784,3.162,0,0,300.000,300.000,16.330,0.000,4
3752958965.165000,0.000000,Standby,299.998,0.000,40.782,3.162,0,0,300.000,300.000,16.350,0.000,4
3752959125.165000,0.000000,Standby,300.000,0.000,40.780,3.162,0,0,300.000,300.000,16.330,0.000,4
3752959285.165000,0.000000,Standby,300.002,0.000,40.779,3.163,0,0,300.000,300.000,16.310,0.000,4
3752959445.165000,0.000000,Standby,299.997,0.000,40.780,3.162,0,0,300.000,300.000,16.310,0.000,4
3752959605.165000,0.000000,Standby,300.001,0.000,40.779,3.163,0,0,300.000,300.000,16.290,0.000,4
3752959765.165000,0.000000,Standby,299.999,0.000,40.779,3.165,0,0,300.000,300.000,16.350,0.000,4
3752959925.165000,0.000000,Standby,300.001,0.000,40.781,3.164,0,0,300.000,300.000,16.330,0.000,4
3752960085.165000,0.000000,Standby,300.001,0.000,40.780,3.163,0,0,300.000,300.000,16.330,0.000,4
3752960245.165000,0.000000,Standby,299.998,0.000,40.781,3.163,0,0,300.000,300.000,16.290,0.000,4
3752960405.165000,0.000000,Standby,300.000,0.000,40.782,3.164,0,0,300.000,300.000,16.290,0.000,4
3752960565.165000,0.000000,Standby,299.998,0.000,40.784,3.165,0,0,300.000,300.000,16.410,0.000,4
3752960725.165000,0.000000,Standby,300.000,0.000,40.784,3.164,0,0,300.000,300.000,16.290,0.000,4
3752960885.165000,0.000000,Standby,300.003,0.000,40.783,3.164,0,0,300.000,300.000,16.330,0.000,4
3752961045.165000,0.000000,Standby,300.000,0.000,40.784,3.164,0,0,300.000,300.000,16.350,0.000,4
3752961205.165000,0.000000,Standby,299.997,0.000,40.781,3.163,0,0,300.000,300.000,16.310,0.000,4
3752961365.165000,0.000000,Standby,300.003,0.000,40.780,3.164,0,0,300.000,300.000,16.330,0.000,4
3752961525.165000,0.000000,Standby,299.996,0.000,40.780,3.164,0,0,300.000,300.000,16.350,0.000,4
3752961685.165000,0.000000,Standby,300.004,0.000,40.780,3.164,0,0,300.000,300.000,16.290,0.000,4
3752961845.165000,0.000000,Standby,299.999,0.000,40.781,3.164,0,0,300.000,300.000,16.370,0.000,4
3752962005.165000,0.000000,Standby,299.999,0.000,40.781,3.163,0,0,300.000,300.000,16.330,0.000,4
3752962165.165000,0.000000,Standby,300.006,0.000,40.782,3.162,0,0,300.000,300.000,16.290,0.000,4
3752962325.165000,0.000000,Standby,299.995,0.000,40.783,3.164,0,0,300.000,300.000,16.410,0.000,4
3752962485.165000,0.000000,Standby,300.004,0.000,40.784,3.164,0,0,300.000,300.000,16.210,0.000,4
3752962645.165000,0.000000,Standby,299.999,0.000,40.783,3.163,0,0,300.000,300.000,16.430,0.000,4
3752962805.165000,0.000000,Standby,299.995,0.000,40.783,3.163,0,0,300.000,300.000,16.270,0.000,4
3752962965.165000,0.000000,Standby,300.009,0.000,40.783,3.164,0,0,300.000,300.000,16.330,0.000,4
3752963125.165000,0.000000,Standby,299.993,0.000,40.783,3.162,0,0,300.000,300.000,16.330,0.000,4
3752963285.165000,0.000000,Standby,300.004,0.000,40.783,3.163,0,0,300.000,300.000,16.270,0.000,4
3752963445.165000,0.000000,Standby,300.000,0.000,40.784,3.163,0,0,300.000,300.000,16.430,0.000,4
3752963605.165000,0.000000,Standby,299.999,0.000,40.784,3.162,0,0,300.000,300.000,16.270,0.000,4
3752963765.165000,0.000000,Standby,300.003,0.000,40.783,3.162,0,0,300.000,300.000,16.390,0.000,4
3752963925.165000,0.000000,Standby,299.995,0.000,40.783,3.159,0,0,300.000,300.000,16.330,0.000,4
3752964085.165000,0.000000,Standby,300.002,0.000,40.781,3.163,0,0,300.000,300.000,16.330,0.000,4
3752964245.165000,0.000000,Standby,299.998,0.000,40.781,3.163,0,0,300.000,300.000,16.350,0.000,4
3752964405.165000,0.000000,Standby,299.997,0.000,40.780,3.164,0,0,300.000,300.000,16.290,0.000,4
3752964565.165000,0.000000,Standby,300.002,0.000,40.782,3.165,0,0,300.000,300.000,16.310,0.000,4
3752964725.165000,0.000000,Standby,299.998,0.000,40.785,3.163,0,0,300.000,300.000,16.370,0.000,4
3752964885.165000,0.000000,Standby,299.998,0.000,40.788,3.162,0,0,300.000,300.000,16.310,0.000,4
3752965045.165000,0.000000,Standby,300.002,0.000,40.788,3.165,0,0,300.000,300.000,16.290,0.000,4
3752965205.165000,0.000000,Standby,299.996,0.000,40.788,3.164,0,0,300.000,300.000,16.290,0.000,4
3752965365.165000,0.000000,Standby,300.003,0.000,40.788,3.165,0,0,300.000,300.000,16.330,0.000,4
3752965525.165000,0.000000,Standby,299.995,0.000,40.788,3.165,0,0,300.000,300.000,16.350,0.000,4
3752965685.165000,0.000000,Standby,300.001,0.000,40.791,3.165,0,0,300.000,300.000,16.310,0.000,4
3752965845.165000,0.000000,Standby,300.000,0.000,40.791,3.163,0,0,300.000,300.000,16.390,0.000,4
3752966005.165000,0.000000,Standby,299.996,0.000,40.789,3.164,0,0,300.000,300.000,16.290,0.000,4
3752966165.165000,0.000000,Standby,300.000,0.000,40.788,3.164,0,0,300.000,300.000,16.290,0.000,4
3752966325.165000,0.000000,Standby,299.998,0.000,40.789,3.165,0,0,300.000,300.000,16.350,0.000,4
3752966485.165000,0.000000,Standby,300.000,0.000,40.789,3.165,0,0,300.000,300.000,16.270,0.000,4
3752966645.165000,0.000000,Standby,300.001,0.000,40.788,3.164,0,0,300.000,300.000,16.410,0.000,4
3752966805.165000,0.000000,Standby,299.996,0.000,40.787,3.164,0,0,300.000,300.000,16.330,0.000,4
3752966965.165000,0.000000,Standby,300.004,0.000,40.788,3.164,0,0,300.000,300.000,16.310,0.000,4
3752967125.165000,0.000000,Standby,299.999,0.000,40.788,3.163,0,0,300.000,300.000,16.370,0.000,4
3752967285.165000,0.000000,Standby,299.999,0.000,40.787,3.164,0,0,300.000,300.000,16.310,0.000,4
3752967445.165000,0.000000,Standby,300.001,0.000,40.787,3.165,0,0,300.000,300.000,16.330,0.000,4
3752967605.165000,0.000000,Standby,299.996,0.000,40.788,3.165,0,0,300.000,300.000,16.330,0.000,4
3752967765.165000,0.000000,Standby,300.002,0.000,40.790,3.164,0,0,300.000,300.000,16.210,0.000,4
3752967925.165000,0.000000,Standby,300.001,0.000,40.791,3.164,0,0,300.000,300.000,16.430,0.000,4
3752968085.165000,0.000000,Standby,299.997,0.000,40.792,3.163,0,0,300.000,300.000,16.250,0.000,4
3752968245.165000,0.000000,Standby,300.006,0.000,40.794,3.163,0,0,300.000,300.000,16.390,0.000,4
3752968405.165000,0.000000,Standby,299.994,0.000,40.794,3.162,0,0,300.000,300.000,16.370,0.000,4
3752968565.165000,0.000000,Standby,300.005,0.000,40.793,3.164,0,0,300.000,300.000,16.290,0.000,4
3752968725.165000,0.000000,Standby,299.998,0.000,40.794,3.162,0,0,300.000,300.000,16.390,0.000,4
3752968885.165000,0.000000,Standby,299.998,0.000,40.794,3.164,0,0,300.000,300.000,16.230,0.000,4
3752969045.165000,0.000000,Standby,300.003,0.000,40.795,3.166,0,0,300.000,300.000,16.310,0.000,4
3752969205.165000,0.000000,Standby,299.995,0.000,40.794,3.164,0,0,300.000,300.000,16.310,0.000,4
3752969365.165000,0.000000,Standby,300.003,0.000,40.792,3.163,0,0,300.000,300.000,16.230,0.000,4
3752969525.165000,0.000000,Standby,299.999,0.000,40.790,3.163,0,0,300.000,300.000,16.370,0.000,4
3752969685.165000,0.000000,Standby,300.000,0.000,40.788,3.165,0,0,300.000,300.000,16.270,0.000,4
3752969845.165000,0.000000,Standby,300.001,0.000,40.790,3.163,0,0,300.000,300.000,16.350,0.000,4
3752970005.165000,0.000000,Standby,299.995,0.000,40.792,3.164,0,0,300.000,300.000,16.350,0.000,4
3752970165.165000,0.000000,Standby,300.004,0.000,40.794,3.164,0,0,300.000,300.000,16.290,0.000,4
3752970325.165000,0.000000,Standby,299.997,0.000,40.796,3.163,0,0,300.000,300.000,16.390,0.000,4
3752970485.165000,0.000000,Standby,300.002,0.000,40.796,3.165,0,0,300.000,300.000,16.230,0.000,4
3752970645.165000,0.000000,Standby,299.996,0.000,40.796,3.163,0,0,300.000,300.000,16.430,0.000,4
3752970805.165000,0.000000,Standby,299.998,0.000,40.796,3.163,0,0,300.000,300.000,16.290,0.000,4
3752970965.165000,0.000000,Standby,300.000,0.000,40.796,3.164,0,0,300.000,300.000,16.310,0.000,4
3752971125.165000,0.000000,Standby,300.001,0.000,40.798,3.164,0,0,300.000,300.000,16.290,0.000,4
3752971285.165000,0.000000,Standby,299.999,0.000,40.797,3.163,0,0,300.000,300.000,16.310,0.000,4
3752971445.165000,0.000000,Standby,299.998,0.000,40.798,3.164,0,0,300.000,300.000,16.370,0.000,4
3752971605.165000,0.000000,Standby,300.000,0.000,40.800,3.162,0,0,300.000,300.000,16.330,0.000,4
3752971765.165000,0.000000,Standby,300.001,0.000,40.802,3.163,0,0,300.000,300.000,16.350,0.000,4
3752971925.165000,0.000000,Standby,300.000,0.000,40.805,3.164,0,0,300.000,300.000,16.330,0.000,4
3752972085.165000,0.000000,Standby,299.996,0.000,40.809,3.165,0,0,300.000,300.000,16.330,0.000,4
3752972245.165000,0.000000,Standby,300.000,0.000,40.809,3.164,0,0,300.000,300.000,16.250,0.000,4
3752972405.165000,0.000000,Standby,299.998,0.000,40.810,3.166,0,0,300.000,300.000,16.410,0.000,4
3752972565.165000,0.000000,Standby,299.997,0.000,40.811,3.165,0,0,300.000,300.000,16.290,0.000,4
3752972725.165000,0.000000,Standby,300.005,0.000,40.813,3.165,0,0,300.000,300.000,16.290,0.000,4
3752972885.165000,0.000000,Standby,299.996,0.000,40.813,3.164,0,0,300.000,300.000,16.410,0.000,4
3752973045.165000,0.000000,Standby,299.999,0.000,40.812,3.165,0,0,300.000,300.000,16.310,0.000,4
3752973205.165000,0.000000,Standby,300.001,0.000,40.811,3.165,0,0,300.000,300.000,16.350,0.000,4
3752973365.165000,0.000000,Standby,299.998,0.000,40.812,3.165,0,0,300.000,300.000,16.370,0.000,4
3752973525.165000,0.000000,Standby,299.999,0.000,40.811,3.164,0,0,300.000,300.000,16.370,0.000,4
3752973685.165000,0.000000,Standby,300.002,0.000,40.810,3.164,0,0,300.000,300.000,16.310,0.000,4
3752973845.165000,0.000000,Standby,300.000,0.000,40.809,3.163,0,0,300.000,300.000,16.390,0.000,4
3752974005.165000,0.000000,Standby,299.998,0.000,40.807,3.162,0,0,300.000,300.000,16.310,0.000,4
3752974165.165000,0.000000,Standby,300.002,0.000,40.807,3.163,0,0,300.000,300.000,16.350,0.000,4
3752974325.165000,0.000000,Standby,299.998,0.000,40.806,3.164,0,0,300.000,300.000,16.310,0.000,4
3752974485.165000,0.000000,Standby,299.997,0.000,40.806,3.164,0,0,300.000,300.000,16.330,0.000,4
3752974645.165000,0.000000,Standby,300.002,0.000,40.804,3.163,0,0,300.000,300.000,16.290,0.000,4
3752974805.165000,0.000000,Standby,299.995,0.000,40.803,3.163,0,0,300.000,300.000,16.350,0.000,4
3752974965.165000,0.000000,Standby,300.004,0.000,40.802,3.163,0,0,300.000,300.000,16.250,0.000,4
3752975125.165000,0.000000,Standby,300.000,0.000,40.801,3.163,0,0,300.000,300.000,16.390,0.000,4
3752975285.165000,0.000000,Standby,300.000,0.000,40.800,3.162,0,0,300.000,300.000,16.250,0.000,4
3752975445.165000,0.000000,Standby,300.000,0.000,40.799,3.163,0,0,300.000,300.000,16.390,0.000,4
3752975605.165000,0.000000,Standby,300.000,0.000,40.796,3.164,0,0,300.000,300.000,16.310,0.000,4
3752975705.165000,0.000000,Standby,300.001,0.000,40.794,3.163,0,0,300.000,300.000,16.270,0.000,4