File: log/20221022.dat
[Header]
; Displex Transport Data File (default extension .dat)
; Copyright 2016, Hechang LEI, hlei@ruc.edu.cn. All rights reserved.
BYAPP, Displex, 2.0
INFO, 9T mag, Release 2.0.
INFO, Channel 1, Temperature Sensor
INFO, Sample 1 Length (cm): 0.000000; Width (cm): 0.000000; Thickness (cm): 0.000000.

[Data]
Timestamp(s),Field(Oe),Field Status,TempA(K),TempB(K),TempC(K),TempD(K),Ramp1,Ramp2,Setpoint1,Setpoint2,Output1(%),Output2(%),Temp Status
3749227617.723400,,,121.157,122.737,0.000,0.000,0,0,100.000,100.000,0,0,4
3749227697.305400,,,120.686,122.265,0.000,0.000,0,0,100.000,100.000,0,0,4
3749227776.928400,,,120.215,121.791,0.000,0.000,0,0,100.000,100.000,0,0,4
3749227856.510400,,,119.743,121.317,0.000,0.000,0,0,100.000,100.000,0,0,4
3749227936.132400,,,119.272,120.847,0.000,0.000,0,0,100.000,100.000,0,0,4
3749228015.716400,,,118.802,120.376,0.000,0.000,0,0,100.000,100.000,0,0,4
3749228095.293400,,,118.335,119.906,0.000,0.000,0,0,100.000,100.000,0,0,4
3749228174.900400,,,117.866,119.437,0.000,0.000,0,0,100.000,100.000,0,0,4
3749228254.452400,,,117.400,118.970,0.000,0.000,0,0,100.000,100.000,0,0,4
3749228334.060400,,,116.933,118.502,0.000,0.000,0,0,100.000,100.000,0,0,4
3749228413.657400,,,116.468,118.036,0.000,0.000,0,0,100.000,100.000,0,0,4
3749228493.265400,,,116.003,117.570,0.000,0.000,0,0,100.000,100.000,0,0,4
3749228572.863400,,,115.538,117.103,0.000,0.000,0,0,100.000,100.000,0,0,4
3749228652.470400,,,115.075,116.640,0.000,0.000,0,0,100.000,100.000,0,0,4
3749228732.068400,,,114.611,116.176,0.000,0.000,0,0,100.000,100.000,0,0,4
3749228811.675400,,,114.150,115.712,0.000,0.000,0,0,100.000,100.000,0,0,4
3749228891.273400,,,113.689,115.250,0.000,0.000,0,0,100.000,100.000,0,0,4
3749228970.856400,,,113.230,114.790,0.000,0.000,0,0,100.000,100.000,0,0,4
3749229050.443400,,,112.772,114.329,0.000,0.000,0,0,100.000,100.000,0,0,4
3749229130.040400,,,112.311,113.869,0.000,0.000,0,0,100.000,100.000,0,0,4
3749229209.622400,,,111.855,113.409,0.000,0.000,0,0,100.000,100.000,0,0,4
3749229289.245400,,,111.397,112.950,0.000,0.000,0,0,100.000,100.000,0,0,4
3749229368.827400,,,110.942,112.493,0.000,0.000,0,0,100.000,100.000,0,0,4
3749229448.440400,,,110.487,112.036,0.000,0.000,0,0,100.000,100.000,0,0,4
3749229528.032400,,,110.032,111.579,0.000,0.000,0,0,100.000,100.000,0,0,4
3749229607.655400,,,109.578,111.123,0.000,0.000,0,0,100.000,100.000,0,0,4
3749229687.238400,,,109.124,110.669,0.000,0.000,0,0,100.000,100.000,0,0,4
3749229766.860400,,,108.673,110.214,0.000,0.000,0,0,100.000,100.000,0,0,4
3749229846.422400,,,108.219,109.760,0.000,0.000,0,0,100.000,100.000,0,0,4
3749229926.004400,,,107.769,109.307,0.000,0.000,0,0,100.000,100.000,0,0,4
3749230005.627400,,,107.318,108.854,0.000,0.000,0,0,100.000,100.000,0,0,4
3749230085.179400,,,106.868,108.403,0.000,0.000,0,0,100.000,100.000,0,0,4
3749230164.773400,,,106.420,107.951,0.000,0.000,0,0,100.000,100.000,0,0,4
3749230244.344400,,,105.972,107.501,0.000,0.000,0,0,100.000,100.000,0,0,4
3749230323.967400,,,105.522,107.052,0.000,0.000,0,0,100.000,100.000,0,0,4
3749230403.550400,,,105.074,106.601,0.000,0.000,0,0,100.000,100.000,0,0,4
3749230483.137400,,,104.627,106.154,0.000,0.000,0,0,100.000,100.000,0,0,4
3749230562.735400,,,104.179,105.706,0.000,0.000,0,0,100.000,100.000,0,0,4
3749230642.341400,,,103.732,105.258,0.000,0.000,0,0,100.000,100.000,0,0,4
3749230721.940400,,,103.287,104.811,0.000,0.000,0,0,100.000,100.000,0,0,4
3749230801.547400,,,102.840,104.365,0.000,0.000,0,0,100.000,100.000,0,0,4
3749230881.145400,,,102.398,103.920,0.000,0.000,0,0,100.000,100.000,0,0,4
3749230960.752400,,,101.954,103.475,0.000,0.000,0,0,100.000,100.000,0,0,4
3749231040.350400,,,101.512,103.031,0.000,0.000,0,0,100.000,100.000,0,0,4
3749231119.992400,,,101.070,102.587,0.000,0.000,0,0,100.000,100.000,0,0,4
3749231199.545400,,,100.627,102.144,0.000,0.000,0,0,100.000,100.000,0,0,4
3749231279.152400,,,100.188,101.701,0.000,0.000,0,0,100.000,100.000,0,0,4
3749231358.743400,,,100.004,101.258,0.000,0.000,0,0,100.000,100.000,1,0,4
3749231438.452400,,,99.975,100.827,0.000,0.000,0,0,100.000,100.000,2,0,4
3749231517.895400,,,99.958,100.416,0.000,0.000,0,0,100.000,100.000,2,0,4
3749231597.417400,,,99.954,100.025,0.000,0.000,0,0,100.000,100.000,1,0,4
3749231677.019400,,,99.958,100.003,0.000,0.000,0,0,100.000,100.000,1,0,1
3749231756.502400,,,99.965,99.999,0.000,0.000,0,0,100.000,100.000,1,0,1
3749231836.094400,,,99.974,99.998,0.000,0.000,0,0,100.000,100.000,1,0,1
3749231915.617400,,,99.985,99.999,0.000,0.000,0,0,100.000,100.000,1,0,1
3749231995.189400,,,99.993,99.998,0.000,0.000,0,0,100.000,100.000,1,0,1
3749232074.775400,,,100.000,99.999,0.000,0.000,0,0,100.000,100.000,1,1,1
3749232154.274400,,,100.005,99.999,0.000,0.000,0,0,100.000,100.000,2,1,1
3749232233.902400,,,100.007,99.999,0.000,0.000,0,0,100.000,100.000,2,1,1
3749232313.489400,,,100.009,99.999,0.000,0.000,0,0,100.000,100.000,2,1,1
3749232393.051400,,,100.010,99.998,0.000,0.000,0,0,100.000,100.000,2,1,1
3749232472.734400,,,100.007,99.999,0.000,0.000,0,0,100.000,100.000,2,1,1
3749232552.347400,,,100.005,100.000,0.000,0.000,0,0,100.000,100.000,2,1,1
3749232631.945400,,,100.002,99.999,0.000,0.000,0,0,100.000,100.000,2,1,1
3749232711.582400,,,100.000,99.999,0.000,0.000,0,0,100.000,100.000,2,1,1
3749232791.104400,,,99.999,100.000,0.000,0.000,0,0,100.000,100.000,2,1,1
3749232870.786400,,,99.997,99.999,0.000,0.000,0,0,100.000,100.000,2,1,1
3749232950.329400,,,99.996,100.000,0.000,0.000,0,0,100.000,100.000,2,1,1
3749233029.963400,,,99.996,99.999,0.000,0.000,0,0,100.000,100.000,2,1,1
3749233109.573400,,,99.996,99.999,0.000,0.000,0,0,100.000,100.000,3,1,1
3749233189.267400,,,99.997,99.999,0.000,0.000,0,0,100.000,100.000,3,1,1
3749233268.838400,,,99.997,100.000,0.000,0.000,0,0,100.000,100.000,3,1,1
3749233348.472400,,,99.998,99.999,0.000,0.000,0,0,100.000,100.000,3,1,1
3749233428.054400,,,99.999,100.000,0.000,0.000,0,0,100.000,100.000,3,1,1
3749233507.686400,,,99.999,100.000,0.000,0.000,0,0,100.000,100.000,3,1,1
3749233587.323400,,,99.999,99.999,0.000,0.000,0,0,100.000,100.000,3,1,1
3749233666.901400,,,99.998,99.999,0.000,0.000,0,0,100.000,100.000,3,1,1
3749233746.473400,,,99.999,99.999,0.000,0.000,0,0,100.000,100.000,3,1,1
3749233826.077400,,,99.998,100.000,0.000,0.000,0,0,100.000,100.000,3,1,1
3749233905.642400,,,99.999,99.999,0.000,0.000,0,0,100.000,100.000,3,1,1
3749233985.301400,,,100.000,99.999,0.000,0.000,0,0,100.000,100.000,3,1,1
3749234064.874400,,,100.000,99.999,0.000,0.000,0,0,100.000,100.000,3,1,1
3749234144.377400,,,100.001,100.000,0.000,0.000,0,0,100.000,100.000,3,1,1
3749234223.985400,,,100.000,99.999,0.000,0.000,0,0,100.000,100.000,3,1,1
3749234303.572400,,,100.000,99.999,0.000,0.000,0,0,100.000,100.000,3,1,1
3749234383.300400,,,100.001,100.000,0.000,0.000,0,0,100.000,100.000,3,1,1
3749234462.878400,,,100.000,99.999,0.000,0.000,0,0,100.000,100.000,3,1,1
3749234542.499400,,,100.000,99.999,0.000,0.000,0,0,100.000,100.000,3,1,1
3749234622.171400,,,100.001,100.000,0.000,0.000,0,0,100.000,100.000,3,1,1
3749234701.763400,,,100.000,100.000,0.000,0.000,0,0,100.000,100.000,3,1,1
3749234781.330400,,,100.000,100.000,0.000,0.000,0,0,100.000,100.000,3,1,1
3749234860.979400,,,100.000,99.999,0.000,0.000,0,0,100.000,100.000,3,1,1
3749234940.661400,,,99.999,99.999,0.000,0.000,0,0,100.000,100.000,3,1,1
3749235020.415400,,,99.999,100.000,0.000,0.000,0,0,100.000,100.000,3,1,1
3749235099.982400,,,99.999,99.999,0.000,0.000,0,0,100.000,100.000,3,2,1
3749235179.629400,,,99.999,100.000,0.000,0.000,0,0,100.000,100.000,3,2,1
3749235259.181400,,,99.998,99.998,0.000,0.000,0,0,100.000,100.000,3,2,1
3749235338.864400,,,98.810,99.014,0.000,0.000,1,1,80.000,80.000,0,0,3
3749235418.087400,,,97.442,98.100,0.000,0.000,1,1,80.000,80.000,0,0,3
3749235497.310400,,,96.227,97.228,0.000,0.000,1,1,80.000,80.000,0,0,3
3749235576.532400,,,95.121,96.389,0.000,0.000,1,1,80.000,80.000,0,0,3
3749235655.754400,,,94.110,95.578,0.000,0.000,1,1,80.000,80.000,0,0,3
3749235735.317400,,,93.171,94.793,0.000,0.000,0,0,80.000,80.000,0,0,4
3749235814.970400,,,92.298,94.033,0.000,0.000,0,0,80.000,80.000,0,0,4
3749235894.572400,,,91.482,93.298,0.000,0.000,0,0,80.000,80.000,0,0,4
3749235974.205400,,,90.718,92.587,0.000,0.000,0,0,80.000,80.000,0,0,4
3749236053.857400,,,89.996,91.897,0.000,0.000,0,0,80.000,80.000,0,0,4
3749236133.470400,,,89.311,91.227,0.000,0.000,0,0,80.000,80.000,0,0,4
3749236213.062400,,,88.660,90.579,0.000,0.000,0,0,80.000,80.000,0,0,4
3749236292.674400,,,88.035,89.946,0.000,0.000,0,0,80.000,80.000,0,0,4
3749236372.318400,,,87.434,89.330,0.000,0.000,0,0,80.000,80.000,0,0,4
3749236451.959400,,,86.853,88.729,0.000,0.000,0,0,80.000,80.000,0,0,4
3749236531.612400,,,86.290,88.142,0.000,0.000,0,0,80.000,80.000,0,0,4
3749236611.264400,,,85.739,87.569,0.000,0.000,0,0,80.000,80.000,0,0,4
3749236690.897400,,,85.205,87.009,0.000,0.000,0,0,80.000,80.000,0,0,4
3749236770.549400,,,84.680,86.460,0.000,0.000,0,0,80.000,80.000,0,0,4
3749236850.162400,,,84.165,85.922,0.000,0.000,0,0,80.000,80.000,0,0,4
3749236929.754400,,,83.660,85.391,0.000,0.000,0,0,80.000,80.000,0,0,4
3749237009.367400,,,83.162,84.868,0.000,0.000,0,0,80.000,80.000,0,0,4
3749237089.019400,,,82.670,84.352,0.000,0.000,0,0,80.000,80.000,0,0,4
3749237168.652400,,,82.182,83.842,0.000,0.000,0,0,80.000,80.000,0,0,4
3749237248.324400,,,81.700,83.339,0.000,0.000,0,0,80.000,80.000,0,0,4
3749237327.956400,,,81.220,82.839,0.000,0.000,0,0,80.000,80.000,0,0,4
3749237407.609400,,,80.745,82.345,0.000,0.000,0,0,80.000,80.000,0,0,4
3749237487.241400,,,80.273,81.855,0.000,0.000,0,0,80.000,80.000,0,0,4
3749237566.894400,,,79.957,81.369,0.000,0.000,0,0,80.000,80.000,1,0,4
3749237646.547400,,,79.977,80.897,0.000,0.000,0,0,80.000,80.000,1,0,4
3749237726.090400,,,79.991,80.453,0.000,0.000,0,0,80.000,80.000,1,0,4
3749237805.771400,,,80.001,80.033,0.000,0.000,0,0,80.000,80.000,1,0,4
3749237885.344400,,,80.006,80.005,0.000,0.000,0,0,80.000,80.000,1,0,1
3749237964.876400,,,80.010,79.999,0.000,0.000,0,0,80.000,80.000,1,0,1
3749238044.518400,,,80.009,79.999,0.000,0.000,0,0,80.000,80.000,1,0,1
3749238124.116400,,,80.007,79.999,0.000,0.000,0,0,80.000,80.000,1,0,1
3749238203.683400,,,80.005,80.000,0.000,0.000,0,0,80.000,80.000,1,0,1
3749238283.267400,,,80.002,79.999,0.000,0.000,0,0,80.000,80.000,1,0,1
3749238362.838400,,,80.001,80.000,0.000,0.000,0,0,80.000,80.000,1,0,1
3749238442.561400,,,79.999,79.999,0.000,0.000,0,0,80.000,80.000,2,0,1
3749238522.323400,,,79.999,79.999,0.000,0.000,0,0,80.000,80.000,2,1,1
3749238602.048400,,,79.999,80.000,0.000,0.000,0,0,80.000,80.000,2,1,1
3749238681.848400,,,79.998,79.998,0.000,0.000,0,0,80.000,80.000,2,1,1
3749238761.622400,,,79.998,79.999,0.000,0.000,0,0,80.000,80.000,2,1,1
3749238841.333400,,,79.997,79.999,0.000,0.000,0,0,80.000,80.000,2,1,1
3749238921.226400,,,79.345,79.498,0.000,0.000,1,1,60.000,60.000,0,0,3
3749239000.478400,,,78.246,78.818,0.000,0.000,1,1,60.000,60.000,0,0,3
3749239079.742400,,,77.278,78.154,0.000,0.000,1,1,60.000,60.000,0,0,3
3749239159.024400,,,76.399,77.501,0.000,0.000,1,1,60.000,60.000,0,0,3
3749239238.303400,,,75.590,76.862,0.000,0.000,1,1,60.000,60.000,0,0,3
3749239317.630400,,,74.841,76.236,0.000,0.000,0,0,60.000,60.000,0,0,4
3749239397.202400,,,74.139,75.620,0.000,0.000,0,0,60.000,60.000,0,0,4
3749239476.704400,,,73.478,75.015,0.000,0.000,0,0,60.000,60.000,0,0,4
3749239556.206400,,,72.849,74.422,0.000,0.000,0,0,60.000,60.000,0,0,4
3749239635.779400,,,72.248,73.839,0.000,0.000,0,0,60.000,60.000,0,0,4
3749239715.352400,,,71.670,73.269,0.000,0.000,0,0,60.000,60.000,0,0,4
3749239794.903400,,,71.110,72.710,0.000,0.000,0,0,60.000,60.000,0,0,4
3749239874.427400,,,70.567,72.159,0.000,0.000,0,0,60.000,60.000,0,0,4
3749239954.008400,,,70.038,71.616,0.000,0.000,0,0,60.000,60.000,0,0,4
3749240033.531400,,,69.518,71.077,0.000,0.000,0,0,60.000,60.000,0,0,4
3749240113.064400,,,69.007,70.546,0.000,0.000,0,0,60.000,60.000,0,0,4
3749240192.606400,,,68.500,70.022,0.000,0.000,0,0,60.000,60.000,0,0,4
3749240272.179400,,,68.000,69.508,0.000,0.000,0,0,60.000,60.000,0,0,4
3749240351.741400,,,67.503,69.002,0.000,0.000,0,0,60.000,60.000,0,0,4
3749240431.304400,,,67.009,68.501,0.000,0.000,0,0,60.000,60.000,0,0,4
3749240510.767400,,,66.518,68.000,0.000,0.000,0,0,60.000,60.000,0,0,4
3749240590.319400,,,66.029,67.496,0.000,0.000,0,0,60.000,60.000,0,0,4
3749240669.881400,,,65.541,66.985,0.000,0.000,0,0,60.000,60.000,0,0,4
3749240749.394400,,,65.054,66.471,0.000,0.000,0,0,60.000,60.000,0,0,4
3749240828.956400,,,64.567,65.958,0.000,0.000,0,0,60.000,60.000,0,0,4
3749240908.478400,,,64.081,65.450,0.000,0.000,0,0,60.000,60.000,0,0,4
3749240988.031400,,,63.594,64.947,0.000,0.000,0,0,60.000,60.000,0,0,4
3749241067.594400,,,63.106,64.448,0.000,0.000,0,0,60.000,60.000,0,0,4
3749241147.126400,,,62.617,63.951,0.000,0.000,0,0,60.000,60.000,0,0,4
3749241226.758400,,,62.127,63.453,0.000,0.000,0,0,60.000,60.000,0,0,4
3749241306.371400,,,61.635,62.954,0.000,0.000,0,0,60.000,60.000,0,0,4
3749241385.954400,,,61.141,62.452,0.000,0.000,0,0,60.000,60.000,0,0,4
3749241465.477400,,,60.646,61.949,0.000,0.000,0,0,60.000,60.000,0,0,4
3749241545.029400,,,60.149,61.445,0.000,0.000,0,0,60.000,60.000,0,0,4
3749241624.591400,,,60.040,60.941,0.000,0.000,0,0,60.000,60.000,0,0,4
3749241704.104400,,,59.984,60.463,0.000,0.000,0,0,60.000,60.000,0,0,4
3749241783.676400,,,59.982,60.019,0.000,0.000,0,0,60.000,60.000,1,0,4
3749241863.228400,,,60.004,60.001,0.000,0.000,0,0,60.000,60.000,1,0,1
3749241942.740400,,,60.004,59.999,0.000,0.000,0,0,60.000,60.000,1,0,1
3749242022.333400,,,59.995,60.000,0.000,0.000,0,0,60.000,60.000,1,0,1
3749242101.835400,,,59.998,60.000,0.000,0.000,0,0,60.000,60.000,1,0,1
3749242181.538400,,,60.000,60.000,0.000,0.000,0,0,60.000,60.000,1,0,1
3749242261.120400,,,60.001,60.003,0.000,0.000,0,0,60.000,60.000,1,0,1
3749242340.693400,,,59.998,59.998,0.000,0.000,0,0,60.000,60.000,1,0,1
3749242420.336400,,,59.998,59.997,0.000,0.000,0,0,60.000,60.000,1,0,1
3749242499.979400,,,60.001,60.001,0.000,0.000,0,0,60.000,60.000,1,0,1
3749242579.641400,,,59.997,59.997,0.000,0.000,0,0,60.000,60.000,1,0,1
3749242659.302400,,,59.999,59.999,0.000,0.000,0,0,60.000,60.000,1,0,1
3749242738.855400,,,60.000,60.000,0.000,0.000,0,0,60.000,60.000,1,0,1
3749242818.418400,,,59.998,59.999,0.000,0.000,0,0,60.000,60.000,2,0,1
3749242898.030400,,,60.000,59.999,0.000,0.000,0,0,60.000,60.000,2,0,1
3749242977.683400,,,60.000,59.997,0.000,0.000,0,0,60.000,60.000,2,0,1
3749243057.265400,,,59.999,59.998,0.000,0.000,0,0,60.000,60.000,2,0,1
3749243136.878400,,,59.998,59.999,0.000,0.000,0,0,60.000,60.000,2,0,1
3749243216.421400,,,60.002,60.000,0.000,0.000,0,0,60.000,60.000,2,1,1
3749243296.003400,,,59.998,59.998,0.000,0.000,0,0,60.000,60.000,2,1,1
3749243375.656400,,,60.000,60.002,0.000,0.000,0,0,60.000,60.000,2,1,1
3749243455.217400,,,59.998,60.002,0.000,0.000,0,0,60.000,60.000,2,1,1
3749243534.780400,,,60.000,60.007,0.000,0.000,0,0,60.000,60.000,2,1,1
3749243614.372400,,,60.001,60.002,0.000,0.000,0,0,60.000,60.000,2,1,1
3749243694.005400,,,59.998,60.000,0.000,0.000,0,0,60.000,60.000,2,1,1
3749243773.577400,,,60.000,59.999,0.000,0.000,0,0,60.000,60.000,2,1,1
3749243853.191400,,,59.997,60.000,0.000,0.000,0,0,60.000,60.000,2,1,1
3749243932.803400,,,59.999,60.003,0.000,0.000,0,0,60.000,60.000,2,1,1
3749244012.346400,,,60.000,60.003,0.000,0.000,0,0,60.000,60.000,2,1,1
3749244091.957400,,,59.999,60.005,0.000,0.000,0,0,60.000,60.000,2,1,1
3749244171.590400,,,60.000,60.001,0.000,0.000,0,0,60.000,60.000,2,1,1
3749244251.183400,,,60.000,59.997,0.000,0.000,0,0,60.000,60.000,2,1,1
3749244330.816400,,,59.996,60.002,0.000,0.000,0,0,60.000,60.000,2,1,1
3749244410.427400,,,60.002,59.999,0.000,0.000,0,0,60.000,60.000,2,1,1
3749244490.010400,,,60.001,60.000,0.000,0.000,0,0,60.000,60.000,2,1,1
3749244569.613400,,,60.001,60.001,0.000,0.000,0,0,60.000,60.000,2,1,1
3749244649.265400,,,59.999,60.000,0.000,0.000,0,0,60.000,60.000,2,1,1
3749244728.878400,,,60.003,60.003,0.000,0.000,0,0,60.000,60.000,2,1,1
3749244808.511400,,,59.998,60.001,0.000,0.000,0,0,60.000,60.000,2,1,1
3749244888.122400,,,60.001,60.002,0.000,0.000,0,0,60.000,60.000,2,1,1
3749244967.725400,,,59.999,60.001,0.000,0.000,0,0,60.000,60.000,2,1,1
3749245047.307400,,,60.001,59.996,0.000,0.000,0,0,60.000,60.000,2,1,1
3749245126.740400,,,60.000,60.000,0.000,0.000,0,0,60.000,60.000,2,1,1
3749245206.293400,,,59.999,59.997,0.000,0.000,0,0,60.000,60.000,2,1,1
3749245285.865400,,,60.003,60.000,0.000,0.000,0,0,60.000,60.000,2,1,1
3749245365.488400,,,59.998,59.999,0.000,0.000,0,0,60.000,60.000,2,1,1
3749245445.030400,,,60.003,60.004,0.000,0.000,0,0,60.000,60.000,2,1,1
3749245524.770400,,,58.427,59.022,0.000,0.000,1,1,40.000,40.000,0,0,3
3749245604.116400,,,56.900,58.039,0.000,0.000,1,1,40.000,40.000,0,0,3
3749245683.458400,,,55.602,57.081,0.000,0.000,1,1,40.000,40.000,0,0,3
3749245762.817400,,,54.477,56.154,0.000,0.000,1,1,40.000,40.000,0,0,3
3749245842.173400,,,53.482,55.254,0.000,0.000,1,1,40.000,40.000,0,0,3
3749245921.436400,,,52.589,54.393,0.000,0.000,0,0,40.000,40.000,0,0,4
3749246000.469400,,,51.769,53.562,0.000,0.000,0,0,40.000,40.000,0,0,4
3749246079.551400,,,51.003,52.753,0.000,0.000,0,0,40.000,40.000,0,0,4
3749246158.583400,,,50.276,51.971,0.000,0.000,0,0,40.000,40.000,0,0,4
3749246237.616400,,,49.572,51.211,0.000,0.000,0,0,40.000,40.000,0,0,4
3749246316.648400,,,48.886,50.465,0.000,0.000,0,0,40.000,40.000,0,0,4
3749246395.681400,,,48.211,49.725,0.000,0.000,0,0,40.000,40.000,0,0,4
3749246474.873400,,,47.541,48.996,0.000,0.000,0,0,40.000,40.000,0,0,4
3749246553.906400,,,46.873,48.280,0.000,0.000,0,0,40.000,40.000,0,0,4
3749246632.938400,,,46.202,47.562,0.000,0.000,0,0,40.000,40.000,0,0,4
3749246711.971400,,,45.526,46.844,0.000,0.000,0,0,40.000,40.000,0,0,4
3749246791.004400,,,44.845,46.126,0.000,0.000,0,0,40.000,40.000,0,0,4
3749246870.036400,,,44.152,45.401,0.000,0.000,0,0,40.000,40.000,0,0,4
3749246949.069400,,,43.450,44.672,0.000,0.000,0,0,40.000,40.000,0,0,4
3749247028.102400,,,42.738,43.928,0.000,0.000,0,0,40.000,40.000,0,0,4
3749247107.134400,,,42.012,43.174,0.000,0.000,0,0,40.000,40.000,0,0,4
3749247186.166400,,,41.270,42.400,0.000,0.000,0,0,40.000,40.000,0,0,4
3749247265.430400,,,40.512,41.615,0.000,0.000,0,0,40.000,40.000,0,0,4
3749247344.513400,,,40.023,40.813,0.000,0.000,0,0,40.000,40.000,0,0,4
3749247423.744400,,,39.986,40.075,0.000,0.000,0,0,40.000,40.000,0,0,4
3749247503.236400,,,39.991,39.983,0.000,0.000,0,0,40.000,40.000,0,0,1
3749247582.618400,,,39.997,40.000,0.000,0.000,0,0,40.000,40.000,1,0,1
3749247662.181400,,,39.998,39.996,0.000,0.000,0,0,40.000,40.000,1,0,1
3749247741.707400,,,39.998,39.999,0.000,0.000,0,0,40.000,40.000,1,0,1
3749247821.261400,,,39.998,39.996,0.000,0.000,0,0,40.000,40.000,1,0,1
3749247900.799400,,,39.998,39.998,0.000,0.000,0,0,40.000,40.000,1,0,1
3749247980.343400,,,40.002,40.001,0.000,0.000,0,0,40.000,40.000,1,0,1
3749248059.863400,,,40.000,40.000,0.000,0.000,0,0,40.000,40.000,1,0,1
3749248139.396400,,,39.997,39.992,0.000,0.000,0,0,40.000,40.000,1,0,1
3749248218.913400,,,39.995,39.996,0.000,0.000,0,0,40.000,40.000,1,0,1
3749248298.452400,,,39.996,39.999,0.000,0.000,0,0,40.000,40.000,1,0,1
3749248377.977400,,,40.001,39.999,0.000,0.000,0,0,40.000,40.000,1,0,1
3749248457.531400,,,40.000,40.005,0.000,0.000,0,0,40.000,40.000,1,0,1
3749248537.069400,,,39.999,40.003,0.000,0.000,0,0,40.000,40.000,1,0,1
3749248616.544400,,,40.001,40.006,0.000,0.000,0,0,40.000,40.000,1,0,1
3749248696.099400,,,40.004,40.005,0.000,0.000,0,0,40.000,40.000,1,0,1
3749248775.636400,,,39.998,40.002,0.000,0.000,0,0,40.000,40.000,1,0,1
3749248855.160400,,,39.998,40.005,0.000,0.000,0,0,40.000,40.000,1,0,1
3749248941.760400,,,39.998,40.002,0.000,0.000,0,0,40.000,40.000,1,0,1
3749249158.830400,,,37.804,38.591,0.000,0.000,1,1,20.000,20.000,0,0,3
3749249348.830400,,,33.809,34.988,0.000,0.000,1,1,20.000,20.000,0,0,3
3749249538.830400,,,30.732,31.634,0.000,0.000,0,0,20.000,20.000,0,0,4
3749249728.830400,,,27.376,28.038,0.000,0.000,0,0,20.000,20.000,0,0,4
3749249918.830400,,,23.093,23.533,0.000,0.000,0,0,20.000,20.000,0,0,4
3749250108.830400,,,20.006,20.001,0.000,0.000,0,0,20.000,20.000,0,0,4
3749250298.830400,,,20.002,19.994,0.000,0.000,0,0,20.000,20.000,0,0,1
3749250488.830400,,,20.003,20.013,0.000,0.000,0,0,20.000,20.000,0,0,1
3749251340.154400,,,19.996,20.015,0.000,0.000,0,0,20.000,20.000,0,0,4
3749251530.154400,,,14.996,15.007,0.000,0.000,0,0,15.000,15.000,0,0,4
3749251720.154400,,,15.004,15.010,0.000,0.000,0,0,15.000,15.000,0,0,4
3749251910.154400,,,14.996,14.979,0.000,0.000,0,0,15.000,15.000,0,0,4
3749252100.154400,,,15.003,15.007,0.000,0.000,0,0,15.000,15.000,0,0,4
3749252290.154400,,,15.002,14.978,0.000,0.000,0,0,15.000,15.000,0,0,4
3749252480.154400,,,15.000,14.992,0.000,0.000,0,0,15.000,15.000,0,0,4
3749252670.154400,,,15.003,14.994,0.000,0.000,0,0,15.000,15.000,0,0,1
3749252860.154400,,,15.002,15.003,0.000,0.000,0,0,15.000,15.000,0,0,4
3749253050.154400,,,14.999,14.993,0.000,0.000,0,0,15.000,15.000,0,0,4
3749253240.154400,,,14.997,15.006,0.000,0.000,0,0,15.000,15.000,0,0,1
3749253430.154400,,,15.001,14.993,0.000,0.000,0,0,15.000,15.000,0,0,4
3749253620.154400,,,14.988,14.998,0.000,0.000,0,0,15.000,15.000,0,0,4
3749253810.154400,,,15.001,14.989,0.000,0.000,0,0,15.000,15.000,0,0,4
3749254000.154400,,,14.995,14.987,0.000,0.000,0,0,15.000,15.000,0,0,4
3749254190.154400,,,15.004,14.998,0.000,0.000,0,0,15.000,15.000,0,0,4
3749254380.154400,,,14.992,14.998,0.000,0.000,0,0,15.000,15.000,0,0,4
3749254570.154400,,,14.995,14.984,0.000,0.000,0,0,15.000,15.000,0,0,4
3749254760.154400,,,15.003,14.993,0.000,0.000,0,0,15.000,15.000,0,0,4
3749254950.154400,,,15.006,15.007,0.000,0.000,0,0,15.000,15.000,0,0,4
3749255140.154400,,,11.852,11.875,0.000,0.000,1,1,10.000,10.000,0,0,3
3749255330.154400,,,10.000,10.015,0.000,0.000,0,0,10.000,10.000,0,0,4
3749255520.154400,,,10.002,10.013,0.000,0.000,0,0,10.000,10.000,0,0,4
3749255710.154400,,,9.994,9.985,0.000,0.000,0,0,10.000,10.000,0,0,4
3749255900.154400,,,10.001,9.991,0.000,0.000,0,0,10.000,10.000,0,0,4
3749256090.154400,,,10.007,10.015,0.000,0.000,0,0,10.000,10.000,0,0,1
3749256280.154400,,,9.988,9.970,0.000,0.000,0,0,10.000,10.000,0,0,4
3749256470.154400,,,10.002,10.005,0.000,0.000,0,0,10.000,10.000,0,0,4
3749256660.154400,,,10.000,10.002,0.000,0.000,0,0,10.000,10.000,0,0,4
3749256850.154400,,,10.001,10.003,0.000,0.000,0,0,10.000,10.000,0,0,4
3749257040.154400,,,9.993,9.996,0.000,0.000,0,0,10.000,10.000,0,0,4
3749257230.154400,,,10.001,10.000,0.000,0.000,0,0,10.000,10.000,0,0,1
3749257420.154400,,,9.999,9.999,0.000,0.000,0,0,10.000,10.000,0,0,4
3749257610.154400,,,9.995,9.992,0.000,0.000,0,0,10.000,10.000,0,0,4
3749257800.154400,,,10.004,10.011,0.000,0.000,0,0,10.000,10.000,0,0,4
3749257990.154400,,,10.003,10.016,0.000,0.000,0,0,10.000,10.000,0,0,4
3749258180.154400,,,10.000,10.017,0.000,0.000,0,0,10.000,10.000,0,0,4
3749258370.154400,,,10.001,9.999,0.000,0.000,0,0,10.000,10.000,0,0,4
3749258560.154400,,,10.003,10.008,0.000,0.000,0,0,10.000,10.000,0,0,4
3749258750.154400,,,10.000,9.992,0.000,0.000,0,0,10.000,10.000,0,0,1
3749258940.154400,,,4.996,5.004,0.000,0.000,0,0,5.000,5.000,0,0,4
3749259130.154400,,,4.999,4.991,0.000,0.000,0,0,5.000,5.000,0,0,4
3749259320.154400,,,5.000,5.007,0.000,0.000,0,0,5.000,5.000,0,0,1
3749259510.154400,,,5.007,5.013,0.000,0.000,0,0,5.000,5.000,0,0,4
3749259700.154400,,,4.994,4.997,0.000,0.000,0,0,5.000,5.000,0,0,1
3749259890.154400,,,5.006,5.006,0.000,0.000,0,0,5.000,5.000,0,0,1
3749260080.154400,,,5.004,5.009,0.000,0.000,0,0,5.000,5.000,0,0,1
3749260270.154400,,,5.000,5.016,0.000,0.000,0,0,5.000,5.000,0,0,1
3749260460.154400,,,4.999,5.008,0.000,0.000,0,0,5.000,5.000,0,0,4
3749260650.154400,,,5.001,5.010,0.000,0.000,0,0,5.000,5.000,0,0,1
3749260840.154400,,,4.990,4.977,0.000,0.000,0,0,5.000,5.000,0,0,1
3749261030.154400,,,4.998,5.006,0.000,0.000,0,0,5.000,5.000,0,0,1
3749261220.154400,,,5.001,5.020,0.000,0.000,0,0,5.000,5.000,0,0,4
3749261410.154400,,,4.998,4.998,0.000,0.000,0,0,5.000,5.000,0,0,1
3749261600.154400,,,4.997,4.999,0.000,0.000,0,0,5.000,5.000,0,0,1
3749261790.154400,,,5.002,5.002,0.000,0.000,0,0,5.000,5.000,0,0,1
3749261980.154400,,,5.001,4.998,0.000,0.000,0,0,5.000,5.000,0,0,4
3749262170.154400,,,5.002,4.996,0.000,0.000,0,0,5.000,5.000,0,0,4
3749262360.154400,,,5.001,5.006,0.000,0.000,0,0,5.000,5.000,0,0,1
3749262550.154400,,,4.810,4.821,0.000,0.000,1,1,2.000,2.000,0,0,0
3749262740.154400,,,1.994,2.000,0.000,0.000,0,0,2.000,2.000,0,0,1
3749262930.154400,,,2.003,1.999,0.000,0.000,0,0,2.000,2.000,0,0,1
3749263120.154400,,,1.997,2.000,0.000,0.000,0,0,2.000,2.000,0,0,1
3749263310.154400,,,1.999,2.000,0.000,0.000,0,0,2.000,2.000,0,0,1
3749263500.154400,,,2.001,2.000,0.000,0.000,0,0,2.000,2.000,0,0,1
3749263690.154400,,,2.002,2.000,0.000,0.000,0,0,2.000,2.000,0,0,1
3749263880.154400,,,1.995,2.000,0.000,0.000,0,0,2.000,2.000,0,0,1
3749264070.154400,,,1.994,2.000,0.000,0.000,0,0,2.000,2.000,0,0,1
3749264260.154400,,,2.001,2.000,0.000,0.000,0,0,2.000,2.000,0,0,1
3749264450.154400,,,1.996,2.000,0.000,0.000,0,0,2.000,2.000,0,0,1
3749264640.154400,,,1.993,2.000,0.000,0.000,0,0,2.000,2.000,0,0,1
3749264830.154400,,,2.000,2.001,0.000,0.000,0,0,2.000,2.000,0,0,1
3749265020.154400,,,1.998,2.001,0.000,0.000,0,0,2.000,2.000,0,0,1
3749265210.154400,,,1.995,2.000,0.000,0.000,0,0,2.000,2.000,0,0,1
3749265400.154400,,,1.995,2.001,0.000,0.000,0,0,2.000,2.000,0,0,1
3749265590.154400,,,2.003,2.000,0.000,0.000,0,0,2.000,2.000,0,0,1
3749265780.154400,,,1.998,2.001,0.000,0.000,0,0,2.000,2.000,0,0,1
3749265970.154400,,,2.005,2.000,0.000,0.000,0,0,2.000,2.000,0,0,1
3749266160.154400,,,1.994,2.000,0.000,0.000,0,0,2.000,2.000,0,0,1
3749266350.154400,,,2.003,2.000,0.000,0.000,0,0,2.000,2.000,0,0,1
3749266540.154400,,,1.997,1.999,0.000,0.000,0,0,2.000,2.000,0,0,1
3749266730.154400,,,2.002,2.000,0.000,0.000,0,0,2.000,2.000,0,0,1
3749266920.154400,,,1.999,1.999,0.000,0.000,0,0,2.000,2.000,0,0,1
3749267110.154400,,,1.994,2.000,0.000,0.000,0,0,2.000,2.000,0,0,1
3749267300.154400,,,2.002,2.000,0.000,0.000,0,0,2.000,2.000,0,0,1
3749267490.154400,,,1.999,2.000,0.000,0.000,0,0,2.000,2.000,0,0,1
3749267680.154400,,,1.990,2.000,0.000,0.000,0,0,2.000,2.000,0,0,1
3749267870.154400,,,2.000,2.000,0.000,0.000,0,0,2.000,2.000,0,0,1
3749268060.154400,,,2.001,2.000,0.000,0.000,0,0,2.000,2.000,0,0,1
3749268250.154400,,,2.001,2.000,0.000,0.000,0,0,2.000,2.000,0,0,1
3749268440.154400,,,2.006,2.000,0.000,0.000,0,0,2.000,2.000,0,0,1
3749268630.154400,,,1.997,2.000,0.000,0.000,0,0,2.000,2.000,0,0,1
3749268820.154400,,,1.999,2.000,0.000,0.000,0,0,2.000,2.000,0,0,1
3749269010.154400,,,2.008,1.999,0.000,0.000,0,0,2.000,2.000,0,0,1
3749269200.154400,,,1.997,2.000,0.000,0.000,0,0,2.000,2.000,0,0,1
3749269390.154400,,,1.998,1.999,0.000,0.000,0,0,2.000,2.000,0,0,1
3749269580.154400,,,1.994,2.001,0.000,0.000,0,0,2.000,2.000,0,0,1
3749269770.154400,,,2.002,2.000,0.000,0.000,0,0,2.000,2.000,0,0,1
3749269960.154400,,,1.993,2.000,0.000,0.000,0,0,2.000,2.000,0,0,1
3749270150.154400,,,2.000,2.000,0.000,0.000,0,0,2.000,2.000,0,0,1
3749270340.154400,,,1.997,2.000,0.000,0.000,0,0,2.000,2.000,0,0,1
3749270530.154400,,,1.997,2.000,0.000,0.000,0,0,2.000,2.000,0,0,1
3749270720.154400,,,2.004,2.000,0.000,0.000,0,0,2.000,2.000,0,0,1
3749270910.154400,,,2.004,2.000,0.000,0.000,0,0,2.000,2.000,0,0,1
3749271100.154400,,,2.006,2.000,0.000,0.000,0,0,2.000,2.000,0,0,1
3749271290.154400,,,1.999,2.000,0.000,0.000,0,0,2.000,2.000,0,0,1
3749271480.154400,,,2.006,2.000,0.000,0.000,0,0,2.000,2.000,0,0,1
3749271670.154400,,,2.007,2.000,0.000,0.000,0,0,2.000,2.000,0,0,1
3749271860.154400,,,1.992,2.000,0.000,0.000,0,0,2.000,2.000,0,0,1
3749272050.154400,,,2.001,2.000,0.000,0.000,0,0,2.000,2.000,0,0,1
3749272240.154400,,,2.000,2.000,0.000,0.000,0,0,2.000,2.000,0,0,1
3749272430.154400,,,2.005,2.000,0.000,0.000,0,0,2.000,2.000,0,0,1
3749272620.154400,,,4.986,4.979,0.000,0.000,0,0,5.000,5.000,0,0,4
3749272810.154400,,,4.997,5.006,0.000,0.000,0,0,5.000,5.000,0,0,1
3749273000.154400,,,5.004,5.012,0.000,0.000,0,0,5.000,5.000,0,0,4
3749273190.154400,,,5.002,5.020,0.000,0.000,0,0,5.000,5.000,0,0,1
3749273380.154400,,,5.007,5.004,0.000,0.000,0,0,5.000,5.000,0,0,1
3749273570.154400,,,5.004,4.994,0.000,0.000,0,0,5.000,5.000,0,0,1
3749273760.154400,,,4.999,4.986,0.000,0.000,0,0,5.000,5.000,0,0,1
3749273950.154400,,,9.996,10.012,0.000,0.000,0,0,10.000,10.000,0,0,4
3749274140.154400,,,10.000,10.000,0.000,0.000,0,0,10.000,10.000,0,0,4
3749274330.154400,,,10.001,10.008,0.000,0.000,0,0,10.000,10.000,0,0,4
3749274520.154400,,,9.998,9.978,0.000,0.000,0,0,10.000,10.000,0,0,4
3749274710.154400,,,10.002,10.012,0.000,0.000,0,0,10.000,10.000,0,0,4
3749274900.154400,,,10.002,9.999,0.000,0.000,0,0,10.000,10.000,0,0,1
3749275090.154400,,,10.000,10.022,0.000,0.000,0,0,10.000,10.000,0,0,4
3749275280.154400,,,13.539,13.534,0.000,0.000,1,1,20.000,20.000,0,0,2
3749275470.154400,,,19.989,19.991,0.000,0.000,0,0,20.000,20.000,0,0,4
3749275660.154400,,,20.001,20.003,0.000,0.000,0,0,20.000,20.000,0,0,4
3749275850.154400,,,19.998,19.990,0.000,0.000,0,0,20.000,20.000,0,0,4
3749276040.154400,,,20.009,20.011,0.000,0.000,0,0,20.000,20.000,0,0,1
3749276230.154400,,,20.002,19.995,0.000,0.000,0,0,20.000,20.000,0,0,1
3749276420.154400,,,19.999,20.006,0.000,0.000,0,0,20.000,20.000,0,0,4
3749276610.154400,,,20.000,20.001,0.000,0.000,0,0,20.000,20.000,0,0,4
3749276800.154400,,,21.665,21.542,0.000,0.000,1,1,40.000,40.000,0,1,2
3749276990.154400,,,30.979,30.948,0.000,0.000,1,1,40.000,40.000,3,2,2
3749277180.154400,,,40.268,40.256,0.000,0.000,0,0,40.000,40.000,2,1,4
3749277370.154400,,,39.978,40.006,0.000,0.000,0,0,40.000,40.000,2,1,1
3749277560.154400,,,40.004,40.005,0.000,0.000,0,0,40.000,40.000,2,1,1
3749277750.154400,,,39.997,39.991,0.000,0.000,0,0,40.000,40.000,2,0,1
3749277940.154400,,,40.003,39.997,0.000,0.000,0,0,40.000,40.000,1,0,1
3749278130.154400,,,40.006,39.998,0.000,0.000,0,0,40.000,40.000,1,0,1
3749278320.154400,,,40.001,39.996,0.000,0.000,0,0,40.000,40.000,1,0,1
3749278510.154400,,,41.577,41.422,0.000,0.000,1,1,60.000,60.000,4,3,2
3749278700.154400,,,50.873,50.833,0.000,0.000,1,1,60.000,60.000,8,5,2
3749278890.154400,,,60.263,60.227,0.000,0.000,0,0,60.000,60.000,8,5,4
3749279080.154400,,,60.137,59.997,0.000,0.000,0,0,60.000,60.000,4,2,1
3749279270.154400,,,60.049,60.006,0.000,0.000,0,0,60.000,60.000,4,2,1
3749279460.154400,,,60.015,60.002,0.000,0.000,0,0,60.000,60.000,3,1,1
3749279650.154400,,,60.003,60.003,0.000,0.000,0,0,60.000,60.000,3,1,1
3749279840.154400,,,60.005,60.005,0.000,0.000,0,0,60.000,60.000,3,1,1
3749280030.154400,,,60.002,60.002,0.000,0.000,0,0,60.000,60.000,3,1,1
3749280220.154400,,,60.481,60.542,0.000,0.000,1,1,80.000,80.000,11,5,2
3749280410.154400,,,70.187,70.323,0.000,0.000,1,1,80.000,80.000,13,8,2
3749280600.154400,,,79.808,79.762,0.000,0.000,1,1,80.000,80.000,14,10,2
3749280790.154400,,,79.990,80.004,0.000,0.000,0,0,80.000,80.000,4,3,1
3749280980.154400,,,80.067,79.994,0.000,0.000,0,0,80.000,80.000,7,3,1
3749281170.154400,,,79.952,80.006,0.000,0.000,0,0,80.000,80.000,5,3,1
3749281360.154400,,,80.039,80.002,0.000,0.000,0,0,80.000,80.000,5,2,1
3749281550.154400,,,79.981,80.009,0.000,0.000,0,0,80.000,80.000,5,2,1
3749281740.154400,,,80.015,80.008,0.000,0.000,0,0,80.000,80.000,5,2,1
3749281930.154400,,,81.284,81.326,0.000,0.000,1,1,100.000,100.000,19,9,2
3749282120.154400,,,91.171,90.985,0.000,0.000,1,1,100.000,100.000,13,11,2
3749282310.154400,,,100.242,100.340,0.000,0.000,0,0,100.000,100.000,16,10,4
3749282500.154400,,,100.275,100.008,0.000,0.000,0,0,100.000,100.000,4,4,1
3749282690.154400,,,99.754,100.007,0.000,0.000,0,0,100.000,100.000,8,4,1
3749282880.154400,,,100.027,100.008,0.000,0.000,0,0,100.000,100.000,9,4,1
3749283070.154400,,,100.104,99.999,0.000,0.000,0,0,100.000,100.000,6,4,1
3749283260.154400,,,99.939,100.008,0.000,0.000,0,0,100.000,100.000,7,3,1
3749283450.154400,,,99.997,100.004,0.000,0.000,0,0,100.000,100.000,7,3,1
3749283640.154400,,,103.915,103.393,0.000,0.000,1,1,150.000,150.000,11,11,2
3749283830.154400,,,112.602,112.825,0.000,0.000,1,1,150.000,150.000,17,14,2
3749284020.154400,,,121.969,122.254,0.000,0.000,1,1,150.000,150.000,26,16,2
3749284210.154400,,,131.653,131.695,0.000,0.000,1,1,150.000,150.000,29,17,2
3749284400.154400,,,141.262,141.129,0.000,0.000,1,1,150.000,150.000,30,19,2
3749284595.505400,,,150.878,150.481,0.000,0.000,0,0,150.000,150.000,18,15,4
3749284785.505400,,,150.852,150.002,0.000,0.000,0,0,150.000,150.000,11,10,1
3749284975.505400,,,150.709,150.010,0.000,0.000,0,0,150.000,150.000,6,9,1
3749285165.505400,,,150.481,150.011,0.000,0.000,0,0,150.000,150.000,4,9,1
3749285355.505400,,,150.225,150.016,0.000,0.000,0,0,150.000,150.000,3,8,4
3749285545.505400,,,149.962,150.005,0.000,0.000,0,0,150.000,150.000,5,8,1
3749285735.505400,,,149.748,150.003,0.000,0.000,0,0,150.000,150.000,6,7,1
3749285925.505400,,,153.811,153.510,0.000,0.000,1,1,200.000,200.000,18,17,2
3749286115.505400,,,163.099,162.947,0.000,0.000,1,1,200.000,200.000,21,20,2
3749286305.505400,,,172.447,172.392,0.000,0.000,1,1,200.000,200.000,24,22,2
3749286495.505400,,,181.849,181.828,0.000,0.000,1,1,200.000,200.000,26,23,2
3749286685.505400,,,191.291,191.268,0.000,0.000,1,1,200.000,200.000,28,25,2
3749286875.505400,,,200.681,200.473,0.000,0.000,0,0,200.000,200.000,19,22,4
3749287065.505400,,,200.622,200.008,0.000,0.000,0,0,200.000,200.000,18,15,1
3749287255.505400,,,200.586,200.003,0.000,0.000,0,0,200.000,200.000,18,14,1
3749287445.505400,,,200.546,200.001,0.000,0.000,0,0,200.000,200.000,18,13,1
3749287635.505400,,,200.503,200.004,0.000,0.000,0,0,200.000,200.000,18,13,1
3749287825.505400,,,200.456,200.006,0.000,0.000,0,0,200.000,200.000,19,12,1
3749288015.505400,,,200.404,200.003,0.000,0.000,0,0,200.000,200.000,19,12,1
3749288205.505400,,,204.585,203.490,0.000,0.000,1,1,250.000,250.000,31,22,2
3749288395.505400,,,213.943,212.919,0.000,0.000,1,1,250.000,250.000,38,25,2
3749288585.505400,,,223.267,222.358,0.000,0.000,1,1,250.000,250.000,45,27,2
3749288775.505400,,,232.439,231.805,0.000,0.000,1,1,250.000,250.000,54,29,2
3749288965.505400,,,241.324,241.232,0.000,0.000,1,1,250.000,250.000,65,30,2
3749289155.505400,,,249.828,250.464,0.000,0.000,0,0,250.000,250.000,65,27,4
3749289345.505400,,,248.711,250.007,0.000,0.000,0,0,250.000,250.000,51,19,4
3749289535.505400,,,248.355,250.004,0.000,0.000,0,0,250.000,250.000,38,18,1
3749289725.505400,,,248.540,250.006,0.000,0.000,0,0,250.000,250.000,23,17,1
3749289915.505400,,,249.174,250.010,0.000,0.000,0,0,250.000,250.000,8,17,1
3749290105.505400,,,250.009,250.010,0.000,0.000,0,0,250.000,250.000,1,16,1
3749290295.505400,,,250.849,250.008,0.000,0.000,0,0,250.000,250.000,0,15,1
3749290485.505400,,,255.445,253.331,0.000,0.000,1,1,300.000,300.000,21,26,2
3749290675.505400,,,265.195,262.748,0.000,0.000,1,1,300.000,300.000,41,30,2
3749290865.505400,,,273.722,272.183,0.000,0.000,1,1,300.000,300.000,68,31,2
3749291055.505400,,,282.698,281.623,0.000,0.000,1,1,300.000,300.000,79,33,2
3749291245.505400,,,290.067,291.055,0.000,0.000,1,1,300.000,300.000,92,35,2
3749291435.505400,,,297.632,300.398,0.000,0.000,0,0,300.000,300.000,75,33,4
3749291625.505400,,,298.168,300.015,0.000,0.000,0,0,300.000,300.000,29,23,4
3749291815.505400,,,299.291,300.012,0.000,0.000,0,0,300.000,300.000,7,22,1
3749292005.505400,,,300.706,300.012,0.000,0.000,0,0,300.000,300.000,0,21,1
3749292195.505400,,,301.805,300.008,0.000,0.000,0,0,300.000,300.000,3,21,1
3749292385.505400,,,301.824,300.000,0.000,0.000,0,0,300.000,300.000,25,20,1
3749292575.505400,,,300.814,299.998,0.000,0.000,0,0,300.000,300.000,46,19,1
3749292765.505400,,,296.180,296.918,0.000,0.000,1,1,2.000,2.000,16,7,3
3749292955.505400,,,287.278,287.491,0.000,0.000,1,1,2.000,2.000,1,3,3
3749293145.505400,,,278.231,278.041,0.000,0.000,1,1,2.000,2.000,0,0,3
3749293335.505400,,,268.608,268.981,0.000,0.000,1,1,2.000,2.000,1,0,3
3749293525.505400,,,260.279,261.218,0.000,0.000,1,1,2.000,2.000,0,0,3
3749293715.505400,,,252.624,254.417,0.000,0.000,1,1,2.000,2.000,0,0,3
3749293905.505400,,,246.095,248.371,0.000,0.000,1,1,2.000,2.000,0,0,3
3749294095.505400,,,240.442,242.961,0.000,0.000,1,1,2.000,2.000,0,0,3
3749294285.505400,,,235.490,238.094,0.000,0.000,1,1,2.000,2.000,0,0,3
3749294475.505400,,,231.088,233.708,0.000,0.000,1,1,2.000,2.000,0,0,3
3749294665.505400,,,227.131,229.718,0.000,0.000,1,1,2.000,2.000,0,0,3
3749294855.505400,,,223.551,226.070,0.000,0.000,1,1,2.000,2.000,0,0,3
3749295045.505400,,,220.270,222.715,0.000,0.000,1,1,2.000,2.000,0,0,3
3749295235.505400,,,217.246,219.594,0.000,0.000,1,1,2.000,2.000,0,0,3
3749295425.505400,,,214.416,216.685,0.000,0.000,1,1,2.000,2.000,0,0,3
3749295615.505400,,,211.765,213.955,0.000,0.000,1,1,2.000,2.000,0,0,3
3749295805.505400,,,209.257,211.384,0.000,0.000,1,1,2.000,2.000,0,0,3
3749295995.505400,,,206.872,208.940,0.000,0.000,1,1,2.000,2.000,0,0,3
3749296185.505400,,,204.592,206.605,0.000,0.000,1,1,2.000,2.000,0,0,3
3749296375.505400,,,202.405,204.366,0.000,0.000,1,1,2.000,2.000,0,0,3
3749296565.505400,,,200.296,202.214,0.000,0.000,1,1,2.000,2.000,0,0,3
3749296755.505400,,,198.263,200.139,0.000,0.000,1,1,2.000,2.000,0,0,3
3749296945.505400,,,196.291,198.126,0.000,0.000,1,1,2.000,2.000,0,0,3
3749297135.505400,,,194.373,196.178,0.000,0.000,1,1,2.000,2.000,0,0,3
3749297325.505400,,,192.507,194.286,0.000,0.000,1,1,2.000,2.000,0,0,3
3749297515.505400,,,190.688,192.439,0.000,0.000,1,1,2.000,2.000,0,0,3
3749297705.505400,,,188.911,190.640,0.000,0.000,1,1,2.000,2.000,0,0,3
3749297895.505400,,,187.171,188.882,0.000,0.000,1,1,2.000,2.000,0,0,3
3749298085.505400,,,185.466,187.160,0.000,0.000,1,1,2.000,2.000,0,0,3
3749298275.505400,,,183.792,185.473,0.000,0.000,1,1,2.000,2.000,0,0,3
3749298465.505400,,,182.144,183.817,0.000,0.000,1,1,2.000,2.000,0,0,3
3749298655.505400,,,180.524,182.187,0.000,0.000,1,1,2.000,2.000,0,0,3
3749298845.505400,,,178.930,180.584,0.000,0.000,0,0,2.000,2.000,0,0,4
3749299035.505400,,,177.357,179.004,0.000,0.000,0,0,2.000,2.000,0,0,4
3749299225.505400,,,175.803,177.442,0.000,0.000,0,0,2.000,2.000,0,0,4
3749299415.505400,,,174.270,175.898,0.000,0.000,0,0,2.000,2.000,0,0,4
3749299605.505400,,,172.756,174.376,0.000,0.000,0,0,2.000,2.000,0,0,4
3749299795.505400,,,171.260,172.875,0.000,0.000,0,0,2.000,2.000,0,0,4
3749299985.505400,,,169.780,171.391,0.000,0.000,0,0,2.000,2.000,0,0,4
3749300175.505400,,,168.316,169.923,0.000,0.000,0,0,2.000,2.000,0,0,4
3749300365.505400,,,166.865,168.470,0.000,0.000,0,0,2.000,2.000,0,0,4
3749300555.505400,,,165.430,167.033,0.000,0.000,0,0,2.000,2.000,0,0,4
3749300745.505400,,,164.009,165.611,0.000,0.000,0,0,2.000,2.000,0,0,4
3749300935.505400,,,162.602,164.203,0.000,0.000,0,0,2.000,2.000,0,0,4
3749301125.505400,,,161.210,162.808,0.000,0.000,0,0,2.000,2.000,0,0,4
3749301315.505400,,,159.826,161.422,0.000,0.000,0,0,2.000,2.000,0,0,4
3749301505.505400,,,158.457,160.054,0.000,0.000,0,0,2.000,2.000,0,0,4
3749301695.505400,,,157.099,158.694,0.000,0.000,0,0,2.000,2.000,0,0,4
3749301885.505400,,,155.752,157.348,0.000,0.000,0,0,2.000,2.000,0,0,4
3749302075.505400,,,154.417,156.013,0.000,0.000,0,0,2.000,2.000,0,0,4
3749302265.505400,,,153.092,154.688,0.000,0.000,0,0,2.000,2.000,0,0,4
3749302455.505400,,,151.777,153.373,0.000,0.000,0,0,2.000,2.000,0,0,4
3749302645.505400,,,150.474,152.068,0.000,0.000,0,0,2.000,2.000,0,0,4
3749302835.505400,,,149.179,150.774,0.000,0.000,0,0,2.000,2.000,0,0,4
3749303025.505400,,,147.893,149.486,0.000,0.000,0,0,2.000,2.000,0,0,4
3749303215.505400,,,146.615,148.209,0.000,0.000,0,0,2.000,2.000,0,0,4
3749303405.505400,,,145.349,146.943,0.000,0.000,0,0,2.000,2.000,0,0,4
3749303595.505400,,,144.091,145.687,0.000,0.000,0,0,2.000,2.000,0,0,4
3749303785.505400,,,142.840,144.440,0.000,0.000,0,0,2.000,2.000,0,0,4
3749303975.505400,,,141.599,143.200,0.000,0.000,0,0,2.000,2.000,0,0,4
3749304165.505400,,,140.365,141.967,0.000,0.000,0,0,2.000,2.000,0,0,4
3749304355.505400,,,139.139,140.740,0.000,0.000,0,0,2.000,2.000,0,0,4
3749304545.505400,,,137.922,139.522,0.000,0.000,0,0,2.000,2.000,0,0,4
3749304735.505400,,,136.712,138.313,0.000,0.000,0,0,2.000,2.000,0,0,4
3749304925.505400,,,135.508,137.109,0.000,0.000,0,0,2.000,2.000,0,0,4
3749305115.505400,,,134.310,135.914,0.000,0.000,0,0,2.000,2.000,0,0,4
3749305305.505400,,,133.121,134.726,0.000,0.000,0,0,2.000,2.000,0,0,4
3749305495.505400,,,131.938,133.545,0.000,0.000,0,0,2.000,2.000,0,0,4
3749305685.505400,,,130.761,132.367,0.000,0.000,0,0,2.000,2.000,0,0,4
3749305875.505400,,,129.590,131.195,0.000,0.000,0,0,2.000,2.000,0,0,4
3749306065.505400,,,128.427,130.030,0.000,0.000,0,0,2.000,2.000,0,0,4
3749306255.505400,,,127.267,128.868,0.000,0.000,0,0,2.000,2.000,0,0,4
3749306445.505400,,,126.115,127.715,0.000,0.000,0,0,2.000,2.000,0,0,4
3749306635.505400,,,124.967,126.565,0.000,0.000,0,0,2.000,2.000,0,0,4
3749306825.505400,,,123.827,125.422,0.000,0.000,0,0,2.000,2.000,0,0,4
3749307015.505400,,,122.693,124.283,0.000,0.000,0,0,2.000,2.000,0,0,4
3749307205.505400,,,121.561,123.149,0.000,0.000,0,0,2.000,2.000,0,0,4
3749307395.505400,,,120.437,122.020,0.000,0.000,0,0,2.000,2.000,0,0,4
3749307585.505400,,,119.318,120.897,0.000,0.000,0,0,2.000,2.000,0,0,4
3749307775.505400,,,118.203,119.779,0.000,0.000,0,0,2.000,2.000,0,0,4
3749307965.505400,,,117.092,118.666,0.000,0.000,0,0,2.000,2.000,0,0,4
3749308155.505400,,,115.986,117.557,0.000,0.000,0,0,2.000,2.000,0,0,4
3749308345.505400,,,114.886,116.454,0.000,0.000,0,0,2.000,2.000,0,0,4
3749308535.505400,,,113.788,115.352,0.000,0.000,0,0,2.000,2.000,0,0,4
3749308725.505400,,,112.696,114.256,0.000,0.000,0,0,2.000,2.000,0,0,4
3749308915.505400,,,111.609,113.165,0.000,0.000,0,0,2.000,2.000,0,0,4
3749309105.505400,,,110.526,112.078,0.000,0.000,0,0,2.000,2.000,0,0,4
3749309295.505400,,,109.446,110.994,0.000,0.000,0,0,2.000,2.000,0,0,4
3749309485.505400,,,108.372,109.914,0.000,0.000,0,0,2.000,2.000,0,0,4
3749309675.505400,,,107.299,108.838,0.000,0.000,0,0,2.000,2.000,0,0,4
3749309865.505400,,,106.230,107.766,0.000,0.000,0,0,2.000,2.000,0,0,4
3749310055.505400,,,105.165,106.697,0.000,0.000,0,0,2.000,2.000,0,0,4
3749310245.505400,,,104.103,105.631,0.000,0.000,0,0,2.000,2.000,0,0,4
3749310435.505400,,,103.048,104.571,0.000,0.000,0,0,2.000,2.000,0,0,4
3749310625.505400,,,101.993,103.513,0.000,0.000,0,0,2.000,2.000,0,0,4
3749310815.505400,,,100.943,102.459,0.000,0.000,0,0,2.000,2.000,0,0,4
3749311005.505400,,,99.897,101.408,0.000,0.000,0,0,2.000,2.000,0,0,4
3749311195.505400,,,98.850,100.359,0.000,0.000,0,0,2.000,2.000,0,0,4
3749311385.505400,,,97.806,99.311,0.000,0.000,0,0,2.000,2.000,0,0,4
3749311575.505400,,,96.763,98.265,0.000,0.000,0,0,2.000,2.000,0,0,4
3749311765.505400,,,95.725,97.221,0.000,0.000,0,0,2.000,2.000,0,0,4
3749311955.505400,,,94.687,96.179,0.000,0.000,0,0,2.000,2.000,0,0,4
3749312145.505400,,,93.654,95.139,0.000,0.000,0,0,2.000,2.000,0,0,4
3749312335.505400,,,92.622,94.102,0.000,0.000,0,0,2.000,2.000,0,0,4
3749312525.505400,,,91.590,93.066,0.000,0.000,0,0,2.000,2.000,0,0,4
3749312715.505400,,,90.561,92.031,0.000,0.000,0,0,2.000,2.000,0,0,4
3749312905.505400,,,89.532,90.996,0.000,0.000,0,0,2.000,2.000,0,0,4
3749313095.505400,,,88.507,89.959,0.000,0.000,0,0,2.000,2.000,0,0,4
3749313285.505400,,,87.480,88.926,0.000,0.000,0,0,2.000,2.000,0,0,4
3749313475.505400,,,86.452,87.891,0.000,0.000,0,0,2.000,2.000,0,0,4
3749313665.505400,,,85.425,86.860,0.000,0.000,0,0,2.000,2.000,0,0,4
3749313855.505400,,,84.400,85.829,0.000,0.000,0,0,2.000,2.000,0,0,4
3749314045.505400,,,83.373,84.797,0.000,0.000,0,0,2.000,2.000,0,0,4
3749314235.505400,,,82.347,83.764,0.000,0.000,0,0,2.000,2.000,0,0,4
3749314425.505400,,,81.319,82.728,0.000,0.000,0,0,2.000,2.000,0,0,4
3749314615.505400,,,80.290,81.694,0.000,0.000,0,0,2.000,2.000,0,0,4
3749314805.505400,,,79.257,80.656,0.000,0.000,0,0,2.000,2.000,0,0,4
3749314995.505400,,,78.224,79.616,0.000,0.000,0,0,2.000,2.000,0,0,4
3749315185.505400,,,77.187,78.573,0.000,0.000,0,0,2.000,2.000,0,0,4
3749315375.505400,,,76.149,77.528,0.000,0.000,0,0,2.000,2.000,0,0,4
3749315565.505400,,,75.108,76.485,0.000,0.000,0,0,2.000,2.000,0,0,4
3749315755.505400,,,74.067,75.439,0.000,0.000,0,0,2.000,2.000,0,0,4
3749315945.505400,,,73.018,74.383,0.000,0.000,0,0,2.000,2.000,0,0,4
3749316135.505400,,,71.967,73.326,0.000,0.000,0,0,2.000,2.000,0,0,4
3749316325.505400,,,70.912,72.264,0.000,0.000,0,0,2.000,2.000,0,0,4
3749316515.505400,,,69.854,71.195,0.000,0.000,0,0,2.000,2.000,0,0,4
3749316705.505400,,,68.787,70.117,0.000,0.000,0,0,2.000,2.000,0,0,4
3749316895.505400,,,67.715,69.048,0.000,0.000,0,0,2.000,2.000,0,0,4
3749317085.505400,,,66.637,67.979,0.000,0.000,0,0,2.000,2.000,0,0,4
3749317275.505400,,,65.548,66.872,0.000,0.000,0,0,2.000,2.000,0,0,4
3749317465.505400,,,64.452,65.741,0.000,0.000,0,0,2.000,2.000,0,0,4
3749317655.505400,,,63.347,64.618,0.000,0.000,0,0,2.000,2.000,0,0,4
3749317845.505400,,,62.234,63.499,0.000,0.000,0,0,2.000,2.000,0,0,4
3749318035.505400,,,61.109,62.365,0.000,0.000,0,0,2.000,2.000,0,0,4
3749318225.505400,,,59.968,61.214,0.000,0.000,0,0,2.000,2.000,0,0,4
3749318415.505400,,,58.815,60.052,0.000,0.000,0,0,2.000,2.000,0,0,4
3749318605.505400,,,57.647,58.874,0.000,0.000,0,0,2.000,2.000,0,0,4
3749318795.505400,,,56.463,57.679,0.000,0.000,0,0,2.000,2.000,0,0,4
3749318985.505400,,,55.260,56.463,0.000,0.000,0,0,2.000,2.000,0,0,4
3749319175.505400,,,54.037,55.227,0.000,0.000,0,0,2.000,2.000,0,0,4
3749319365.505400,,,52.788,53.967,0.000,0.000,0,0,2.000,2.000,0,0,4
3749319555.505400,,,51.517,52.679,0.000,0.000,0,0,2.000,2.000,0,0,4
3749319745.505400,,,50.216,51.363,0.000,0.000,0,0,2.000,2.000,0,0,4
3749319935.505400,,,48.881,50.010,0.000,0.000,0,0,2.000,2.000,0,0,4
3749320125.505400,,,47.506,48.618,0.000,0.000,0,0,2.000,2.000,0,0,4
3749320315.505400,,,46.096,47.204,0.000,0.000,0,0,2.000,2.000,0,0,4
3749320505.505400,,,44.630,45.726,0.000,0.000,0,0,2.000,2.000,0,0,4
3749320695.505400,,,43.104,44.179,0.000,0.000,0,0,2.000,2.000,0,0,4
3749320885.505400,,,41.510,42.550,0.000,0.000,0,0,2.000,2.000,0,0,4
3749321075.505400,,,39.831,40.835,0.000,0.000,0,0,2.000,2.000,0,0,4
3749321265.505400,,,38.051,39.004,0.000,0.000,0,0,2.000,2.000,0,0,4
3749321455.505400,,,36.141,37.041,0.000,0.000,0,0,2.000,2.000,0,0,4
3749321645.505400,,,34.062,34.893,0.000,0.000,0,0,2.000,2.000,0,0,4
3749321835.505400,,,31.756,32.506,0.000,0.000,0,0,2.000,2.000,0,0,4
3749322025.505400,,,29.126,29.779,0.000,0.000,0,0,2.000,2.000,0,0,4
3749322215.505400,,,26.000,26.530,0.000,0.000,0,0,2.000,2.000,0,0,4
3749322405.505400,,,22.019,22.371,0.000,0.000,0,0,2.000,2.000,0,0,4
3749322595.505400,,,16.399,16.497,0.000,0.000,0,0,2.000,2.000,0,0,4
3749322785.505400,,,8.968,8.824,0.000,0.000,0,0,2.000,2.000,0,0,4
3749322975.505400,,,5.066,4.888,0.000,0.000,0,0,2.000,2.000,0,0,4
3749323165.505400,,,3.389,3.196,0.000,0.000,0,0,2.000,2.000,0,0,4
3749323355.505400,,,1.997,1.999,0.000,0.000,0,0,2.000,2.000,0,0,4
3749323545.505400,,,1.999,2.000,0.000,0.000,0,0,2.000,2.000,0,0,1
3749323735.505400,,,1.996,2.000,0.000,0.000,0,0,2.000,2.000,0,0,1
3749323925.505400,,,2.001,2.000,0.000,0.000,0,0,2.000,2.000,0,0,1
3749324115.505400,,,1.999,2.000,0.000,0.000,0,0,2.000,2.000,0,0,1
3749324305.505400,,,1.997,2.000,0.000,0.000,0,0,2.000,2.000,0,0,1
3749324495.505400,,,2.005,2.000,0.000,0.000,0,0,2.000,2.000,0,0,1
3749324685.505400,,,1.996,2.000,0.000,0.000,0,0,2.000,2.000,0,0,1
3749324875.505400,,,2.006,1.999,0.000,0.000,0,0,2.000,2.000,0,0,1
3749325065.505400,,,2.007,1.999,0.000,0.000,0,0,2.000,2.000,0,0,1
3749325255.505400,,,2.003,1.999,0.000,0.000,0,0,2.000,2.000,0,0,1
3749325445.505400,,,1.997,2.000,0.000,0.000,0,0,2.000,2.000,0,0,1
3749325635.505400,,,2.002,2.000,0.000,0.000,0,0,2.000,2.000,0,0,1
3749325825.505400,,,1.999,2.001,0.000,0.000,0,0,2.000,2.000,0,0,1
3749326015.505400,,,2.000,2.000,0.000,0.000,0,0,2.000,2.000,0,0,1
3749326205.505400,,,1.997,2.000,0.000,0.000,0,0,2.000,2.000,0,0,1
3749326395.505400,,,2.004,2.000,0.000,0.000,0,0,2.000,2.000,0,0,1
3749326585.505400,,,1.994,2.000,0.000,0.000,0,0,2.000,2.000,0,0,1
3749326775.505400,,,1.993,2.000,0.000,0.000,0,0,2.000,2.000,0,0,1
3749326965.505400,,,2.006,2.000,0.000,0.000,0,0,2.000,2.000,0,0,1
3749327155.505400,,,2.001,2.001,0.000,0.000,0,0,2.000,2.000,0,0,1
3749327345.505400,,,2.002,2.000,0.000,0.000,0,0,2.000,2.000,0,0,1
3749327535.505400,,,2.006,2.000,0.000,0.000,0,0,2.000,2.000,0,0,1
3749327725.505400,,,2.004,2.001,0.000,0.000,0,0,2.000,2.000,0,0,1
3749327915.505400,,,1.995,2.000,0.000,0.000,0,0,2.000,2.000,0,0,1
3749328105.505400,,,2.000,2.001,0.000,0.000,0,0,2.000,2.000,0,0,1
3749328295.505400,,,2.002,2.000,0.000,0.000,0,0,2.000,2.000,0,0,1
3749328485.505400,,,2.005,2.000,0.000,0.000,0,0,2.000,2.000,0,0,1
3749328675.505400,,,2.002,2.000,0.000,0.000,0,0,2.000,2.000,0,0,1
3749328865.505400,,,2.000,1.999,0.000,0.000,0,0,2.000,2.000,0,0,1
3749329055.505400,,,1.995,2.000,0.000,0.000,0,0,2.000,2.000,0,0,1
3749329245.505400,,,2.002,1.999,0.000,0.000,0,0,2.000,2.000,0,0,1
3749329435.505400,,,2.003,2.000,0.000,0.000,0,0,2.000,2.000,0,0,1
3749329625.505400,,,1.999,2.000,0.000,0.000,0,0,2.000,2.000,0,0,1
3749329815.505400,,,2.008,2.000,0.000,0.000,0,0,2.000,2.000,0,0,1
3749330005.505400,,,2.004,2.000,0.000,0.000,0,0,2.000,2.000,0,0,1
3749330195.505400,,,1.995,2.000,0.000,0.000,0,0,2.000,2.000,0,0,1
3749330385.505400,,,2.004,2.000,0.000,0.000,0,0,2.000,2.000,0,0,1
3749330575.505400,,,1.996,2.000,0.000,0.000,0,0,2.000,2.000,0,0,1
3749330765.505400,,,1.996,2.000,0.000,0.000,0,0,2.000,2.000,0,0,1
3749330955.505400,,,1.999,2.000,0.000,0.000,0,0,2.000,2.000,0,0,1
3749331145.505400,,,2.003,2.000,0.000,0.000,0,0,2.000,2.000,0,0,1
3749331335.505400,,,2.003,2.000,0.000,0.000,0,0,2.000,2.000,0,0,1
3749331525.505400,,,1.995,2.001,0.000,0.000,0,0,2.000,2.000,0,0,1
3749331715.505400,,,2.000,2.001,0.000,0.000,0,0,2.000,2.000,0,0,1
3749331905.505400,,,1.994,2.000,0.000,0.000,0,0,2.000,2.000,0,0,1
3749332095.505400,,,1.993,2.001,0.000,0.000,0,0,2.000,2.000,0,0,1
3749332285.505400,,,1.996,2.000,0.000,0.000,0,0,2.000,2.000,0,0,1
3749332475.505400,,,2.000,2.000,0.000,0.000,0,0,2.000,2.000,0,0,1
3749332665.505400,,,1.994,2.000,0.000,0.000,0,0,2.000,2.000,0,0,1
3749332855.505400,,,1.994,2.000,0.000,0.000,0,0,2.000,2.000,0,0,1
3749333045.505400,,,1.998,2.000,0.000,0.000,0,0,2.000,2.000,0,0,1
3749333235.505400,,,1.999,2.000,0.000,0.000,0,0,2.000,2.000,0,0,1
3749333425.505400,,,1.994,2.000,0.000,0.000,0,0,2.000,2.000,0,0,1
3749333615.505400,,,2.006,1.999,0.000,0.000,0,0,2.000,2.000,0,0,1
3749333805.505400,,,2.005,2.000,0.000,0.000,0,0,2.000,2.000,0,0,1
3749333995.505400,,,2.007,2.000,0.000,0.000,0,0,2.000,2.000,0,0,1
3749334185.505400,,,1.991,1.999,0.000,0.000,0,0,2.000,2.000,0,0,1
3749334375.505400,,,2.005,2.000,0.000,0.000,0,0,2.000,2.000,0,0,1
3749334410.505400,,,1.994,2.000,0.000,0.000,0,0,2.000,2.000,0,0,1