File: log/20221024.dat
[Header]
; Displex Transport Data File (default extension .dat)
; Copyright 2016, Hechang LEI, hlei@ruc.edu.cn. All rights reserved.
BYAPP, Displex, 2.0
INFO, 9T mag, Release 2.0.
INFO, Channel 1, Temperature Sensor
INFO, Sample 1 Length (cm): 0.000000; Width (cm): 0.000000; Thickness (cm): 0.000000.

[Data]
Timestamp(s),Field(Oe),Field Status,TempA(K),TempB(K),TempC(K),TempD(K),Ramp1,Ramp2,Setpoint1,Setpoint2,Output1(%),Output2(%),Temp Status
3749434415.505400,,,154.224,153.235,0.000,0.000,1,1,200.000,200.000,22,13,2
3749434445.505400,,,154.791,154.674,0.000,0.000,1,1,200.000,200.000,5,14,2
3749434475.505400,,,155.208,156.186,0.000,0.000,1,1,200.000,200.000,33,15,2
3749434505.505400,,,158.568,157.688,0.000,0.000,1,1,200.000,200.000,27,15,2
3749434535.505400,,,159.435,159.181,0.000,0.000,1,1,200.000,200.000,7,16,2
3749434565.505400,,,159.672,160.672,0.000,0.000,1,1,200.000,200.000,32,16,2
3749434595.505400,,,162.856,162.158,0.000,0.000,1,1,200.000,200.000,31,16,2
3749434625.505400,,,164.091,163.654,0.000,0.000,1,1,200.000,200.000,8,17,2
3749434655.505400,,,164.157,165.140,0.000,0.000,1,1,200.000,200.000,30,17,2
3749434685.505400,,,167.126,166.631,0.000,0.000,1,1,200.000,200.000,34,17,2
3749434715.505400,,,168.740,168.122,0.000,0.000,1,1,200.000,200.000,11,18,2
3749434745.505400,,,168.673,169.607,0.000,0.000,1,1,200.000,200.000,28,18,2
3749434775.505400,,,171.348,171.097,0.000,0.000,1,1,200.000,200.000,38,18,2
3749434805.505400,,,173.374,172.599,0.000,0.000,1,1,200.000,200.000,13,19,2
3749434835.505400,,,173.252,174.084,0.000,0.000,1,1,200.000,200.000,25,19,2
3749434865.505400,,,175.569,175.566,0.000,0.000,1,1,200.000,200.000,41,19,2
3749434895.505400,,,177.960,177.064,0.000,0.000,1,1,200.000,200.000,17,19,2
3749434925.505400,,,177.887,178.551,0.000,0.000,1,1,200.000,200.000,22,20,2
3749434955.505400,,,179.779,180.040,0.000,0.000,1,1,200.000,200.000,43,20,2
3749434985.505400,,,182.499,181.538,0.000,0.000,1,1,200.000,200.000,22,20,2
3749435015.505400,,,182.590,183.028,0.000,0.000,1,1,200.000,200.000,20,21,2
3749435045.505400,,,183.978,184.507,0.000,0.000,1,1,200.000,200.000,43,21,2
3749435075.505400,,,186.934,185.997,0.000,0.000,1,1,200.000,200.000,28,21,2
3749435105.505400,,,187.343,187.489,0.000,0.000,1,1,200.000,200.000,18,21,2
3749435135.505400,,,188.236,188.977,0.000,0.000,1,1,200.000,200.000,42,22,2
3749435165.505400,,,191.281,190.464,0.000,0.000,1,1,200.000,200.000,34,22,2
3749435195.505400,,,192.133,191.956,0.000,0.000,1,1,200.000,200.000,17,22,2
3749435225.505400,,,192.582,193.448,0.000,0.000,1,1,200.000,200.000,40,23,2
3749435255.505400,,,195.529,194.939,0.000,0.000,1,1,200.000,200.000,39,23,2
3749435285.505400,,,196.918,196.428,0.000,0.000,1,1,200.000,200.000,18,23,2
3749435315.505400,,,197.011,197.909,0.000,0.000,1,1,200.000,200.000,36,23,2
3749435345.505400,,,199.687,199.405,0.000,0.000,1,1,200.000,200.000,44,24,2
3749435375.505400,,,201.463,200.503,0.000,0.000,0,0,200.000,200.000,8,18,4
3749435405.505400,,,199.376,200.080,0.000,0.000,0,0,200.000,200.000,6,14,4
3749435435.505400,,,199.187,200.017,0.000,0.000,0,0,200.000,200.000,39,14,4
3749435465.505400,,,201.337,200.039,0.000,0.000,0,0,200.000,200.000,16,13,4
3749435495.505400,,,199.915,200.015,0.000,0.000,0,0,200.000,200.000,1,12,4
3749435525.505400,,,198.848,200.008,0.000,0.000,0,0,200.000,200.000,33,12,4
3749435555.505400,,,200.982,200.006,0.000,0.000,0,0,200.000,200.000,24,12,1
3749435585.505400,,,200.426,200.011,0.000,0.000,0,0,200.000,200.000,0,12,1
3749435615.505400,,,198.750,200.005,0.000,0.000,0,0,200.000,200.000,25,12,1
3749435645.505400,,,200.511,200.003,0.000,0.000,0,0,200.000,200.000,31,12,1
3749435675.505400,,,200.849,200.008,0.000,0.000,0,0,200.000,200.000,0,12,1
3749435705.505400,,,198.916,200.005,0.000,0.000,0,0,200.000,200.000,16,11,1
3749435735.505400,,,199.972,200.000,0.000,0.000,0,0,200.000,200.000,35,11,1
3749435765.505400,,,201.119,200.005,0.000,0.000,0,0,200.000,200.000,5,11,1
3749435795.505400,,,199.273,200.007,0.000,0.000,0,0,200.000,200.000,8,11,1
3749435825.505400,,,199.457,200.000,0.000,0.000,0,0,200.000,200.000,35,11,1
3749435855.505400,,,201.185,200.003,0.000,0.000,0,0,200.000,200.000,12,11,1
3749435885.505400,,,199.732,200.008,0.000,0.000,0,0,200.000,200.000,2,11,1
3749435915.505400,,,199.052,200.000,0.000,0.000,0,0,200.000,200.000,32,11,1
3749435945.505400,,,201.010,200.003,0.000,0.000,0,0,200.000,200.000,20,11,1
3749435975.505400,,,200.224,200.007,0.000,0.000,0,0,200.000,200.000,0,11,1
3749436005.505400,,,198.854,200.004,0.000,0.000,0,0,200.000,200.000,25,11,1
3749436035.505400,,,200.643,199.999,0.000,0.000,0,0,200.000,200.000,26,11,1
3749436065.505400,,,200.655,200.006,0.000,0.000,0,0,200.000,200.000,0,11,1
3749436095.505400,,,198.917,200.004,0.000,0.000,0,0,200.000,200.000,17,11,1
3749436125.505400,,,200.148,200.000,0.000,0.000,0,0,200.000,200.000,31,10,1
3749436155.505400,,,200.972,200.005,0.000,0.000,0,0,200.000,200.000,2,10,1
3749436185.505400,,,199.198,200.005,0.000,0.000,0,0,200.000,200.000,9,10,1
3749436215.505400,,,199.636,199.999,0.000,0.000,0,0,200.000,200.000,33,10,1
3749436245.505400,,,201.108,200.005,0.000,0.000,0,0,200.000,200.000,9,10,1
3749436275.505400,,,199.624,200.006,0.000,0.000,0,0,200.000,200.000,3,10,1
3749436305.505400,,,199.209,200.001,0.000,0.000,0,0,200.000,200.000,31,10,1
3749436335.505400,,,201.019,200.002,0.000,0.000,0,0,200.000,200.000,16,10,1
3749436365.505400,,,200.082,200.007,0.000,0.000,0,0,200.000,200.000,0,10,1
3749436395.505400,,,198.951,200.002,0.000,0.000,0,0,200.000,200.000,26,10,1
3749436425.505400,,,200.706,200.002,0.000,0.000,0,0,200.000,200.000,23,10,1
3749436455.505400,,,200.508,200.004,0.000,0.000,0,0,200.000,200.000,0,10,1
3749436485.505400,,,198.947,200.003,0.000,0.000,0,0,200.000,200.000,18,10,1
3749436515.505400,,,200.264,199.999,0.000,0.000,0,0,200.000,200.000,29,10,1
3749436545.505400,,,200.853,200.004,0.000,0.000,0,0,200.000,200.000,1,10,1
3749436575.505400,,,199.167,200.006,0.000,0.000,0,0,200.000,200.000,11,10,1
3749436605.505400,,,199.773,199.998,0.000,0.000,0,0,200.000,200.000,31,10,1
3749436635.505400,,,201.032,200.002,0.000,0.000,0,0,200.000,200.000,6,10,1
3749436665.505400,,,199.539,200.004,0.000,0.000,0,0,200.000,200.000,4,9,1
3749436695.505400,,,199.329,199.999,0.000,0.000,0,0,200.000,200.000,30,9,1
3749436725.505400,,,201.001,200.001,0.000,0.000,0,0,200.000,200.000,13,9,1
3749436755.505400,,,199.987,200.006,0.000,0.000,0,0,200.000,200.000,0,9,1
3749436785.505400,,,199.035,200.000,0.000,0.000,0,0,200.000,200.000,25,9,1
3749436815.505400,,,200.743,200.000,0.000,0.000,0,0,200.000,200.000,21,9,1
3749436845.505400,,,200.411,200.004,0.000,0.000,0,0,200.000,200.000,0,9,1
3749436875.505400,,,198.982,200.002,0.000,0.000,0,0,200.000,200.000,19,9,1
3749436905.505400,,,200.342,199.999,0.000,0.000,0,0,200.000,200.000,26,9,1
3749436935.505400,,,200.762,200.004,0.000,0.000,0,0,200.000,200.000,1,9,1
3749436965.505400,,,199.162,200.004,0.000,0.000,0,0,200.000,200.000,11,9,1
3749436995.505400,,,199.863,199.997,0.000,0.000,0,0,200.000,200.000,29,9,1
3749437025.505400,,,200.966,200.004,0.000,0.000,0,0,200.000,200.000,5,9,1
3749437055.505400,,,199.504,200.004,0.000,0.000,0,0,200.000,200.000,5,9,1
3749437085.505400,,,199.412,199.999,0.000,0.000,0,0,200.000,200.000,29,9,1
3749437115.505400,,,200.972,200.001,0.000,0.000,0,0,200.000,200.000,12,9,1
3749437145.505400,,,199.920,200.006,0.000,0.000,0,0,200.000,200.000,1,9,1
3749437175.505400,,,199.104,199.999,0.000,0.000,0,0,200.000,200.000,25,9,1
3749437205.505400,,,200.759,199.999,0.000,0.000,0,0,200.000,200.000,19,9,1
3749437235.505400,,,200.351,200.005,0.000,0.000,0,0,200.000,200.000,0,9,1
3749437265.505400,,,199.018,200.000,0.000,0.000,0,0,200.000,200.000,19,9,1
3749437295.505400,,,200.379,199.999,0.000,0.000,0,0,200.000,200.000,24,9,1
3749437325.505400,,,200.707,200.003,0.000,0.000,0,0,200.000,200.000,0,9,1
3749437355.505400,,,199.172,200.002,0.000,0.000,0,0,200.000,200.000,11,9,1
3749437385.505400,,,199.906,199.999,0.000,0.000,0,0,200.000,200.000,28,9,1
3749437415.505400,,,200.917,200.002,0.000,0.000,0,0,200.000,200.000,4,9,1
3749437445.505400,,,199.483,200.003,0.000,0.000,0,0,200.000,200.000,5,9,1
3749437475.505400,,,199.471,199.999,0.000,0.000,0,0,200.000,200.000,28,9,1
3749437505.505400,,,200.947,200.001,0.000,0.000,0,0,200.000,200.000,11,9,1
3749437535.505400,,,199.885,200.005,0.000,0.000,0,0,200.000,200.000,1,8,1
3749437565.505400,,,199.147,199.999,0.000,0.000,0,0,200.000,200.000,24,8,1
3749437595.505400,,,200.757,200.000,0.000,0.000,0,0,200.000,200.000,18,8,1
3749437625.505400,,,200.306,200.003,0.000,0.000,0,0,200.000,200.000,0,8,1
3749437655.505400,,,199.052,200.001,0.000,0.000,0,0,200.000,200.000,18,8,1
3749437685.505400,,,200.395,199.999,0.000,0.000,0,0,200.000,200.000,23,8,1
3749437715.505400,,,200.667,200.002,0.000,0.000,0,0,200.000,200.000,0,8,1
3749437745.505400,,,199.189,200.003,0.000,0.000,0,0,200.000,200.000,11,8,1
3749437775.505400,,,199.927,199.998,0.000,0.000,0,0,200.000,200.000,27,8,1
3749437805.505400,,,200.880,200.001,0.000,0.000,0,0,200.000,200.000,4,8,1
3749437835.505400,,,199.491,200.003,0.000,0.000,0,0,200.000,200.000,5,8,1
3749437865.505400,,,199.501,199.999,0.000,0.000,0,0,200.000,200.000,27,8,1
3749437895.505400,,,200.918,200.001,0.000,0.000,0,0,200.000,200.000,10,8,1
3749437925.505400,,,199.894,200.005,0.000,0.000,0,0,200.000,200.000,1,8,1
3749437955.505400,,,199.181,200.000,0.000,0.000,0,0,200.000,200.000,24,8,1
3749437985.505400,,,200.740,200.000,0.000,0.000,0,0,200.000,200.000,17,8,1
3749438015.505400,,,200.293,200.004,0.000,0.000,0,0,200.000,200.000,0,8,1
3749438045.505400,,,199.082,200.000,0.000,0.000,0,0,200.000,200.000,18,8,1
3749438075.505400,,,200.372,199.998,0.000,0.000,0,0,200.000,200.000,23,8,1
3749438105.505400,,,200.643,200.002,0.000,0.000,0,0,200.000,200.000,0,8,1
3749438135.505400,,,199.218,200.002,0.000,0.000,0,0,200.000,200.000,11,8,1
3749438165.505400,,,199.933,199.999,0.000,0.000,0,0,200.000,200.000,26,8,1
3749438195.505400,,,200.859,200.002,0.000,0.000,0,0,200.000,200.000,4,8,1
3749438225.505400,,,199.522,200.002,0.000,0.000,0,0,200.000,200.000,5,8,1
3749438255.505400,,,199.503,199.997,0.000,0.000,0,0,200.000,200.000,26,8,1
3749438285.505400,,,200.890,200.001,0.000,0.000,0,0,200.000,200.000,10,8,1
3749438315.505400,,,199.907,200.004,0.000,0.000,0,0,200.000,200.000,1,8,1
3749438345.505400,,,199.195,200.000,0.000,0.000,0,0,200.000,200.000,23,8,1
3749438375.505400,,,200.705,199.999,0.000,0.000,0,0,200.000,200.000,16,8,1
3749438405.505400,,,200.304,200.002,0.000,0.000,0,0,200.000,200.000,0,8,1
3749438435.505400,,,199.109,200.001,0.000,0.000,0,0,200.000,200.000,17,8,1
3749438465.505400,,,200.346,199.998,0.000,0.000,0,0,200.000,200.000,22,8,1
3749438495.505400,,,200.645,200.001,0.000,0.000,0,0,200.000,200.000,0,8,1
3749438525.505400,,,199.250,200.003,0.000,0.000,0,0,200.000,200.000,10,8,1
3749438555.505400,,,199.899,199.999,0.000,0.000,0,0,200.000,200.000,25,8,1
3749438585.505400,,,200.847,200.000,0.000,0.000,0,0,200.000,200.000,4,8,1
3749438615.505400,,,199.559,200.003,0.000,0.000,0,0,200.000,200.000,4,8,1
3749438645.505400,,,199.489,199.999,0.000,0.000,0,0,200.000,200.000,25,8,1
3749438675.505400,,,200.862,199.999,0.000,0.000,0,0,200.000,200.000,10,8,1
3749438705.505400,,,199.945,200.003,0.000,0.000,0,0,200.000,200.000,0,8,1
3749438735.505400,,,199.195,199.999,0.000,0.000,0,0,200.000,200.000,22,8,1
3749438765.505400,,,200.668,200.000,0.000,0.000,0,0,200.000,200.000,16,8,1
3749438795.505400,,,200.331,200.002,0.000,0.000,0,0,200.000,200.000,0,7,1
3749438825.505400,,,199.136,200.001,0.000,0.000,0,0,200.000,200.000,16,7,1
3749438855.505400,,,200.302,199.998,0.000,0.000,0,0,200.000,200.000,22,7,1
3749438885.505400,,,200.655,200.001,0.000,0.000,0,0,200.000,200.000,0,7,1
3749438915.505400,,,199.786,200.040,0.000,0.000,0,0,200.000,200.000,11,8,4
3749438945.505400,,,199.895,200.016,0.000,0.000,0,0,200.000,200.000,12,7,4
3749438975.505400,,,199.944,199.986,0.000,0.000,0,0,200.000,200.000,12,7,4
3749439005.505400,,,199.970,200.006,0.000,0.000,0,0,200.000,200.000,11,7,1
3749439035.505400,,,199.987,200.000,0.000,0.000,0,0,200.000,200.000,12,7,1
3749439065.505400,,,199.991,200.000,0.000,0.000,0,0,200.000,200.000,12,7,1
3749439095.505400,,,199.996,200.000,0.000,0.000,0,0,200.000,200.000,11,7,1
3749439125.505400,,,199.997,200.001,0.000,0.000,0,0,200.000,200.000,12,7,1
3749439155.505400,,,199.998,199.999,0.000,0.000,0,0,200.000,200.000,12,7,1
3749439185.505400,,,200.001,200.000,0.000,0.000,0,0,200.000,200.000,12,7,1
3749439215.505400,,,199.999,200.000,0.000,0.000,0,0,200.000,200.000,11,7,1
3749439245.505400,,,200.002,200.001,0.000,0.000,0,0,200.000,200.000,11,7,1
3749439275.505400,,,199.999,199.999,0.000,0.000,0,0,200.000,200.000,11,7,1
3749439305.505400,,,200.000,200.001,0.000,0.000,0,0,200.000,200.000,11,7,1
3749439335.505400,,,200.001,200.000,0.000,0.000,0,0,200.000,200.000,12,7,1
3749439365.505400,,,200.000,200.000,0.000,0.000,0,0,200.000,200.000,12,7,1
3749439395.505400,,,200.002,200.000,0.000,0.000,0,0,200.000,200.000,11,7,1
3749439425.505400,,,200.001,200.001,0.000,0.000,0,0,200.000,200.000,11,7,1
3749439455.505400,,,200.001,200.001,0.000,0.000,0,0,200.000,200.000,11,7,1
3749439485.505400,,,200.001,200.001,0.000,0.000,0,0,200.000,200.000,11,7,1
3749439515.505400,,,200.001,200.000,0.000,0.000,0,0,200.000,200.000,11,7,1
3749439545.505400,,,200.008,200.039,0.000,0.000,0,0,200.000,200.000,11,8,4
3749439575.505400,,,200.004,200.015,0.000,0.000,0,0,200.000,200.000,11,7,4
3749439605.505400,,,200.003,199.988,0.000,0.000,0,0,200.000,200.000,11,7,4
3749439635.505400,,,200.000,200.005,0.000,0.000,0,0,200.000,200.000,11,7,1
3749439665.505400,,,200.001,199.999,0.000,0.000,0,0,200.000,200.000,11,7,1
3749439695.505400,,,200.000,200.000,0.000,0.000,0,0,200.000,200.000,11,7,1
3749439725.505400,,,200.000,200.001,0.000,0.000,0,0,200.000,200.000,11,7,1
3749439755.505400,,,200.002,200.001,0.000,0.000,0,0,200.000,200.000,11,7,1
3749439785.505400,,,200.000,200.000,0.000,0.000,0,0,200.000,200.000,11,7,1
3749439815.505400,,,200.001,200.000,0.000,0.000,0,0,200.000,200.000,11,7,1
3749439845.505400,,,200.000,200.000,0.000,0.000,0,0,200.000,200.000,11,7,1
3749439875.505400,,,200.001,200.000,0.000,0.000,0,0,200.000,200.000,11,7,1
3749439905.505400,,,200.001,200.000,0.000,0.000,0,0,200.000,200.000,11,7,1
3749439935.505400,,,200.000,200.000,0.000,0.000,0,0,200.000,200.000,11,7,1
3749439965.505400,,,199.999,200.000,0.000,0.000,0,0,200.000,200.000,11,7,1
3749439995.505400,,,200.001,200.000,0.000,0.000,0,0,200.000,200.000,11,7,1
3749440025.505400,,,200.000,200.001,0.000,0.000,0,0,200.000,200.000,11,7,1
3749440055.505400,,,200.000,199.999,0.000,0.000,0,0,200.000,200.000,11,7,1
3749440085.505400,,,201.371,200.718,0.000,0.000,1,1,300.000,300.000,32,17,2
3749440115.505400,,,203.924,203.939,0.000,0.000,1,1,300.000,300.000,35,24,2
3749440145.505400,,,206.477,206.507,0.000,0.000,1,1,300.000,300.000,36,25,2
3749440175.505400,,,208.985,208.959,0.000,0.000,1,1,300.000,300.000,37,27,2
3749440205.505400,,,211.498,211.483,0.000,0.000,1,1,300.000,300.000,38,28,2
3749440235.505400,,,213.998,213.966,0.000,0.000,1,1,300.000,300.000,39,28,2
3749440265.505400,,,216.489,216.463,0.000,0.000,1,1,300.000,300.000,40,29,2
3749440295.505400,,,218.980,218.939,0.000,0.000,1,1,300.000,300.000,40,30,2
3749440325.505400,,,221.471,221.429,0.000,0.000,1,1,300.000,300.000,41,31,2
3749440355.505400,,,223.962,223.909,0.000,0.000,1,1,300.000,300.000,42,31,2
3749440385.505400,,,226.446,226.411,0.000,0.000,1,1,300.000,300.000,43,32,2
3749440415.505400,,,228.929,228.882,0.000,0.000,1,1,300.000,300.000,44,32,2
3749440445.505400,,,231.412,231.359,0.000,0.000,1,1,300.000,300.000,45,33,2
3749440475.505400,,,233.907,233.855,0.000,0.000,1,1,300.000,300.000,45,33,2
3749440505.505400,,,236.381,236.335,0.000,0.000,1,1,300.000,300.000,45,34,2
3749440535.505400,,,238.863,238.812,0.000,0.000,1,1,300.000,300.000,46,34,2
3749440565.505400,,,241.342,241.292,0.000,0.000,1,1,300.000,300.000,47,35,2
3749440595.505400,,,243.820,243.780,0.000,0.000,1,1,300.000,300.000,48,35,2
3749440625.505400,,,246.301,246.261,0.000,0.000,1,1,300.000,300.000,48,36,2
3749440655.505400,,,248.794,248.740,0.000,0.000,1,1,300.000,300.000,49,37,2
3749440685.505400,,,251.287,251.226,0.000,0.000,1,1,300.000,300.000,49,37,2
3749440715.505400,,,253.755,253.714,0.000,0.000,1,1,300.000,300.000,50,38,2
3749440745.505400,,,256.248,256.199,0.000,0.000,1,1,300.000,300.000,50,38,2
3749440775.505400,,,258.731,258.945,0.000,0.000,1,1,300.000,300.000,51,37,2
3749440805.505400,,,261.199,261.036,0.000,0.000,1,1,300.000,300.000,52,39,2
3749440835.505400,,,263.687,263.652,0.000,0.000,1,1,300.000,300.000,52,40,2
3749440865.505400,,,266.179,266.130,0.000,0.000,1,1,300.000,300.000,52,40,2
3749440895.505400,,,268.666,268.606,0.000,0.000,1,1,300.000,300.000,54,41,2
3749440925.505400,,,271.136,271.094,0.000,0.000,1,1,300.000,300.000,54,41,2
3749440955.505400,,,273.629,273.574,0.000,0.000,1,1,300.000,300.000,55,42,2
3749440985.505400,,,276.110,276.056,0.000,0.000,1,1,300.000,300.000,55,42,2
3749441015.505400,,,278.580,278.537,0.000,0.000,1,1,300.000,300.000,56,43,2
3749441045.505400,,,281.940,281.014,0.000,0.000,1,1,300.000,300.000,46,43,2
3749441075.505400,,,284.103,283.506,0.000,0.000,1,1,300.000,300.000,55,44,2
3749441105.505400,,,286.371,285.985,0.000,0.000,1,1,300.000,300.000,55,44,2
3749441135.505400,,,288.708,288.473,0.000,0.000,1,1,300.000,300.000,57,45,2
3749441165.505400,,,291.107,290.947,0.000,0.000,1,1,300.000,300.000,58,45,2
3749441195.505400,,,293.557,293.437,0.000,0.000,1,1,300.000,300.000,58,46,2
3749441225.505400,,,296.002,295.913,0.000,0.000,1,1,300.000,300.000,60,46,2
3749441255.505400,,,298.471,298.396,0.000,0.000,1,1,300.000,300.000,60,47,2
3749441285.505400,,,300.329,300.687,0.000,0.000,0,0,300.000,300.000,37,41,4
3749441315.505400,,,300.210,300.373,0.000,0.000,0,0,300.000,300.000,36,29,4
3749441345.505400,,,300.144,299.988,0.000,0.000,0,0,300.000,300.000,34,29,4
3749441375.505400,,,300.097,300.094,0.000,0.000,0,0,300.000,300.000,33,27,4
3749441405.505400,,,300.066,300.037,0.000,0.000,0,0,300.000,300.000,33,26,4
3749441435.505400,,,300.043,300.022,0.000,0.000,0,0,300.000,300.000,33,26,4
3749441465.505400,,,300.032,300.021,0.000,0.000,0,0,300.000,300.000,33,26,4
3749441495.505400,,,300.022,300.013,0.000,0.000,0,0,300.000,300.000,32,25,4
3749441525.505400,,,300.019,300.012,0.000,0.000,0,0,300.000,300.000,33,25,4
3749441555.505400,,,300.013,300.012,0.000,0.000,0,0,300.000,300.000,32,25,1
3749441585.505400,,,300.012,300.011,0.000,0.000,0,0,300.000,300.000,33,24,1
3749441615.505400,,,300.011,300.011,0.000,0.000,0,0,300.000,300.000,32,24,1
3749441645.505400,,,300.006,300.007,0.000,0.000,0,0,300.000,300.000,31,24,1
3749441675.505400,,,300.007,300.009,0.000,0.000,0,0,300.000,300.000,32,24,1
3749441705.505400,,,300.008,300.008,0.000,0.000,0,0,300.000,300.000,31,24,1
3749441735.505400,,,300.004,300.010,0.000,0.000,0,0,300.000,300.000,31,24,1
3749441765.505400,,,300.008,300.009,0.000,0.000,0,0,300.000,300.000,31,23,1
3749441795.505400,,,300.008,300.009,0.000,0.000,0,0,300.000,300.000,31,23,1
3749441825.505400,,,300.005,300.008,0.000,0.000,0,0,300.000,300.000,31,23,1
3749441855.505400,,,300.008,300.010,0.000,0.000,0,0,300.000,300.000,30,23,1
3749441885.505400,,,300.005,300.008,0.000,0.000,0,0,300.000,300.000,29,23,1
3749441915.505400,,,300.007,300.007,0.000,0.000,0,0,300.000,300.000,30,23,1
3749441945.505400,,,300.007,300.007,0.000,0.000,0,0,300.000,300.000,29,23,1
3749441975.505400,,,300.005,300.009,0.000,0.000,0,0,300.000,300.000,29,22,1
3749442005.505400,,,300.007,300.006,0.000,0.000,0,0,300.000,300.000,29,22,1
3749442035.505400,,,300.005,300.007,0.000,0.000,0,0,300.000,300.000,30,22,1
3749442065.505400,,,300.005,300.008,0.000,0.000,0,0,300.000,300.000,29,22,1
3749442095.505400,,,300.004,300.005,0.000,0.000,0,0,300.000,300.000,29,22,1
3749442125.505400,,,300.007,300.007,0.000,0.000,0,0,300.000,300.000,28,22,1
3749442155.505400,,,300.007,300.009,0.000,0.000,0,0,300.000,300.000,28,22,1
3749442185.505400,,,300.002,300.007,0.000,0.000,0,0,300.000,300.000,29,22,1
3749442215.505400,,,300.004,300.006,0.000,0.000,0,0,300.000,300.000,29,21,1
3749442245.505400,,,300.005,300.007,0.000,0.000,0,0,300.000,300.000,29,21,1
3749442275.505400,,,300.003,300.007,0.000,0.000,0,0,300.000,300.000,28,21,1
3749442305.505400,,,300.004,300.007,0.000,0.000,0,0,300.000,300.000,27,21,1
3749442335.505400,,,300.004,300.006,0.000,0.000,0,0,300.000,300.000,28,21,1
3749442365.505400,,,300.003,300.007,0.000,0.000,0,0,300.000,300.000,28,21,1
3749442395.505400,,,300.004,300.005,0.000,0.000,0,0,300.000,300.000,27,21,1
3749442425.505400,,,300.003,300.003,0.000,0.000,0,0,300.000,300.000,28,21,1
3749442455.505400,,,300.002,0.000,0.000,0.000,0,0,300.000,300.000,28,0,4
3749442485.505400,,,300.006,0.000,0.000,0.000,0,0,300.000,300.000,27,0,4
3749442515.505400,,,299.948,0.000,0.000,0.000,0,0,300.000,300.000,31,0,4
3749442545.505400,,,299.938,0.000,0.000,0.000,0,0,300.000,300.000,34,0,4
3749442575.505400,,,299.956,0.000,0.000,0.000,0,0,300.000,300.000,34,0,4
3749442605.505400,,,299.970,0.000,0.000,0.000,0,0,300.000,300.000,35,0,4
3749442635.505400,,,299.976,0.000,0.000,0.000,0,0,300.000,300.000,35,0,4
3749442665.505400,,,299.982,0.000,0.000,0.000,0,0,300.000,300.000,34,0,4
3749442695.505400,,,299.997,0.000,0.000,0.000,0,0,300.000,300.000,33,0,4
3749442725.505400,,,299.992,0.000,0.000,0.000,0,0,300.000,300.000,35,0,4
3749442755.505400,,,300.000,0.000,0.000,0.000,0,0,300.000,300.000,35,0,4
3749442785.505400,,,299.992,0.000,0.000,0.000,0,0,300.000,300.000,34,0,4
3749442815.505400,,,300.000,0.000,0.000,0.000,0,0,300.000,300.000,34,0,4
3749442845.505400,,,300.005,0.000,0.000,0.000,0,0,300.000,300.000,34,0,4
3749442875.505400,,,300.003,0.000,0.000,0.000,0,0,300.000,300.000,33,0,4
3749442905.505400,,,300.001,0.000,0.000,0.000,0,0,300.000,300.000,33,0,4
3749442935.505400,,,299.997,0.000,0.000,0.000,0,0,300.000,300.000,36,0,4
3749442965.505400,,,299.998,0.000,0.000,0.000,0,0,300.000,300.000,34,0,4
3749442995.505400,,,300.001,0.000,0.000,0.000,0,0,300.000,300.000,34,0,4
3749443025.505400,,,300.008,0.000,0.000,0.000,0,0,300.000,300.000,33,0,4
3749443055.505400,,,300.005,0.000,0.000,0.000,0,0,300.000,300.000,33,0,4
3749443085.505400,,,299.999,0.000,0.000,0.000,0,0,300.000,300.000,32,0,4
3749443115.505400,,,300.025,0.000,0.000,0.000,0,0,300.000,300.000,31,0,4
3749443145.505400,,,300.040,300.463,0.000,0.000,0,0,300.000,300.000,30,59,4
3749443175.505400,,,300.043,302.310,0.000,0.000,0,0,300.000,300.000,28,0,4
3749443205.505400,,,300.031,299.141,0.000,0.000,0,0,300.000,300.000,28,6,4
3749443235.505400,,,300.036,299.989,0.000,0.000,0,0,300.000,300.000,27,15,4
3749443265.505400,,,300.033,300.273,0.000,0.000,0,0,300.000,300.000,25,9,4
3749443295.505400,,,300.028,300.012,0.000,0.000,0,0,300.000,300.000,25,8,4
3749443325.505400,,,300.016,299.969,0.000,0.000,0,0,300.000,300.000,26,13,4
3749443355.505400,,,300.013,300.386,0.000,0.000,0,0,300.000,300.000,26,6,4
3749443385.505400,,,300.003,300.002,0.000,0.000,0,0,300.000,300.000,26,4,4
3749443415.505400,,,299.997,300.050,0.000,0.000,0,0,300.000,300.000,25,4,4
3749443445.505400,,,300.004,299.383,0.000,0.000,0,0,300.000,300.000,26,15,4
3749443475.505400,,,300.012,300.067,0.000,0.000,1,1,2.000,2.000,11,16,2
3749443505.505400,,,297.962,298.404,0.000,0.000,1,1,2.000,2.000,0,2,3
3749443535.505400,,,295.458,295.236,0.000,0.000,1,1,2.000,2.000,0,0,3
3749443565.505400,,,293.126,292.918,0.000,0.000,1,1,2.000,2.000,0,0,3
3749443595.505400,,,290.899,290.807,0.000,0.000,1,1,2.000,2.000,0,0,3
3749443625.505400,,,288.745,288.757,0.000,0.000,1,1,2.000,2.000,0,0,3
3749443655.505400,,,286.635,286.728,0.000,0.000,1,1,2.000,2.000,0,0,3
3749443685.505400,,,284.560,284.711,0.000,0.000,1,1,2.000,2.000,0,0,3
3749443715.505400,,,282.505,282.714,0.000,0.000,1,1,2.000,2.000,0,0,3
3749443745.505400,,,280.452,280.709,0.000,0.000,1,1,2.000,2.000,0,0,3
3749443775.505400,,,278.413,278.715,0.000,0.000,1,1,2.000,2.000,0,0,3
3749443805.505400,,,276.382,276.714,0.000,0.000,1,1,2.000,2.000,0,0,3
3749443835.505400,,,274.373,274.734,0.000,0.000,1,1,2.000,2.000,0,0,3
3749443865.505400,,,272.370,272.765,0.000,0.000,1,1,2.000,2.000,0,0,3
3749443895.505400,,,270.365,270.790,0.000,0.000,1,1,2.000,2.000,0,0,3
3749443925.505400,,,268.379,268.829,0.000,0.000,1,1,2.000,2.000,0,0,3
3749443955.505400,,,266.398,266.858,0.000,0.000,1,1,2.000,2.000,0,0,3
3749443985.505400,,,264.440,264.903,0.000,0.000,1,1,2.000,2.000,0,0,3
3749444015.505400,,,262.545,262.971,0.000,0.000,1,1,2.000,2.000,0,0,3
3749444045.505400,,,260.647,261.042,0.000,0.000,1,1,2.000,2.000,0,0,3
3749444075.505400,,,258.697,259.111,0.000,0.000,1,1,2.000,2.000,0,0,3
3749444105.505400,,,256.762,257.190,0.000,0.000,1,1,2.000,2.000,0,0,3
3749444135.505400,,,254.851,255.280,0.000,0.000,1,1,2.000,2.000,0,0,3
3749444165.505400,,,252.949,253.399,0.000,0.000,1,1,2.000,2.000,0,0,3
3749444195.505400,,,251.042,251.513,0.000,0.000,1,1,2.000,2.000,0,0,3
3749444225.505400,,,249.158,249.649,0.000,0.000,1,1,2.000,2.000,0,0,3
3749444255.505400,,,247.282,247.785,0.000,0.000,1,1,2.000,2.000,0,0,3
3749444285.505400,,,245.430,245.936,0.000,0.000,1,1,2.000,2.000,0,0,3
3749444315.505400,,,243.571,244.096,0.000,0.000,1,1,2.000,2.000,0,0,3
3749444345.505400,,,241.736,242.274,0.000,0.000,1,1,2.000,2.000,0,0,3
3749444375.505400,,,239.915,240.467,0.000,0.000,1,1,2.000,2.000,0,0,3
3749444405.505400,,,238.099,238.652,0.000,0.000,1,1,2.000,2.000,0,0,3
3749444435.505400,,,236.309,236.866,0.000,0.000,1,1,2.000,2.000,0,0,3
3749444465.505400,,,234.511,235.090,0.000,0.000,1,1,2.000,2.000,0,0,3
3749444495.505400,,,232.735,233.334,0.000,0.000,1,1,2.000,2.000,0,0,3
3749444525.505400,,,230.970,231.586,0.000,0.000,1,1,2.000,2.000,0,0,3
3749444555.505400,,,229.212,229.847,0.000,0.000,1,1,2.000,2.000,0,0,3
3749444585.505400,,,227.477,228.121,0.000,0.000,1,1,2.000,2.000,0,0,3
3749444615.505400,,,225.739,226.404,0.000,0.000,1,1,2.000,2.000,0,0,3
3749444645.505400,,,224.020,224.710,0.000,0.000,1,1,2.000,2.000,0,0,3
3749444675.505400,,,222.315,223.012,0.000,0.000,1,1,2.000,2.000,0,0,3
3749444705.505400,,,220.617,221.298,0.000,0.000,1,1,2.000,2.000,0,0,3
3749444735.505400,,,218.941,219.607,0.000,0.000,1,1,2.000,2.000,0,0,3
3749444765.505400,,,217.263,217.931,0.000,0.000,1,1,2.000,2.000,0,0,3
3749444795.505400,,,215.598,216.277,0.000,0.000,1,1,2.000,2.000,0,0,3
3749444825.505400,,,213.945,214.643,0.000,0.000,1,1,2.000,2.000,0,0,3
3749444855.505400,,,212.303,213.015,0.000,0.000,1,1,2.000,2.000,0,0,3
3749444885.505400,,,210.684,211.429,0.000,0.000,1,1,2.000,2.000,0,0,3
3749444915.505400,,,209.064,209.895,0.000,0.000,1,1,2.000,2.000,0,0,3
3749444945.505400,,,207.463,208.332,0.000,0.000,1,1,2.000,2.000,0,0,3
3749444975.505400,,,205.870,206.831,0.000,0.000,1,1,2.000,2.000,0,0,3
3749445005.505400,,,204.288,205.341,0.000,0.000,1,1,2.000,2.000,0,0,3
3749445035.505400,,,202.729,203.907,0.000,0.000,1,1,2.000,2.000,0,0,3
3749445065.505400,,,201.174,202.464,0.000,0.000,1,1,2.000,2.000,0,0,3
3749445095.505400,,,199.626,200.969,0.000,0.000,1,1,2.000,2.000,0,0,3
3749445125.505400,,,198.101,199.511,0.000,0.000,1,1,2.000,2.000,0,0,3
3749445155.505400,,,196.572,198.057,0.000,0.000,1,1,2.000,2.000,0,0,3
3749445185.505400,,,195.055,196.614,0.000,0.000,1,1,2.000,2.000,0,0,3
3749445215.505400,,,193.559,195.199,0.000,0.000,1,1,2.000,2.000,0,0,3
3749445245.505400,,,192.064,193.774,0.000,0.000,1,1,2.000,2.000,0,0,3
3749445275.505400,,,190.585,192.368,0.000,0.000,1,1,2.000,2.000,0,0,3
3749445305.505400,,,189.114,190.965,0.000,0.000,1,1,2.000,2.000,0,0,3
3749445335.505400,,,187.658,189.578,0.000,0.000,1,1,2.000,2.000,0,0,3
3749445365.505400,,,186.208,188.174,0.000,0.000,1,1,2.000,2.000,0,0,3
3749445395.505400,,,184.757,186.780,0.000,0.000,1,1,2.000,2.000,0,0,3
3749445425.505400,,,183.330,185.428,0.000,0.000,1,1,2.000,2.000,0,0,3
3749445455.505400,,,181.899,184.048,0.000,0.000,1,1,2.000,2.000,0,0,3
3749445485.505400,,,180.497,182.686,0.000,0.000,1,1,2.000,2.000,0,0,3
3749445515.505400,,,179.089,181.335,0.000,0.000,1,1,2.000,2.000,0,0,3
3749445545.505400,,,177.693,179.969,0.000,0.000,1,1,2.000,2.000,0,0,3
3749445575.505400,,,176.303,178.621,0.000,0.000,1,1,2.000,2.000,0,0,3
3749445605.505400,,,174.927,177.262,0.000,0.000,1,1,2.000,2.000,0,0,3
3749445635.505400,,,173.553,175.919,0.000,0.000,1,1,2.000,2.000,0,0,3
3749445665.505400,,,172.193,174.597,0.000,0.000,1,1,2.000,2.000,0,0,3
3749445695.505400,,,170.842,173.266,0.000,0.000,1,1,2.000,2.000,0,0,3
3749445725.505400,,,169.493,171.969,0.000,0.000,1,1,2.000,2.000,0,0,3
3749445755.505400,,,168.160,170.663,0.000,0.000,1,1,2.000,2.000,0,0,3
3749445785.505400,,,166.835,169.352,0.000,0.000,1,1,2.000,2.000,0,0,3
3749445815.505400,,,165.512,168.059,0.000,0.000,1,1,2.000,2.000,0,0,3
3749445845.505400,,,164.195,166.764,0.000,0.000,1,1,2.000,2.000,0,0,3
3749445875.505400,,,162.890,165.477,0.000,0.000,1,1,2.000,2.000,0,0,3
3749445905.505400,,,161.586,164.188,0.000,0.000,1,1,2.000,2.000,0,0,3
3749445935.505400,,,160.296,162.903,0.000,0.000,1,1,2.000,2.000,0,0,3
3749445965.505400,,,159.013,161.628,0.000,0.000,1,1,2.000,2.000,0,0,3
3749445995.505400,,,157.729,160.340,0.000,0.000,1,1,2.000,2.000,0,0,3
3749446025.505400,,,156.457,159.095,0.000,0.000,1,1,2.000,2.000,0,0,3
3749446055.505400,,,155.198,157.839,0.000,0.000,1,1,2.000,2.000,0,0,3
3749446085.505400,,,153.937,156.605,0.000,0.000,1,1,2.000,2.000,0,0,3
3749446115.505400,,,152.691,155.393,0.000,0.000,1,1,2.000,2.000,0,0,3
3749446145.505400,,,151.454,154.182,0.000,0.000,1,1,2.000,2.000,0,0,3
3749446175.505400,,,150.213,152.971,0.000,0.000,1,1,2.000,2.000,0,0,3
3749446205.505400,,,148.980,151.733,0.000,0.000,1,1,2.000,2.000,0,0,3
3749446235.505400,,,147.754,150.519,0.000,0.000,1,1,2.000,2.000,0,0,3
3749446265.505400,,,146.533,149.311,0.000,0.000,1,1,2.000,2.000,0,0,3
3749446295.505400,,,145.323,148.103,0.000,0.000,1,1,2.000,2.000,0,0,3
3749446325.505400,,,144.119,146.916,0.000,0.000,1,1,2.000,2.000,0,0,3
3749446355.505400,,,142.913,145.724,0.000,0.000,1,1,2.000,2.000,0,0,3
3749446385.505400,,,141.718,144.532,0.000,0.000,1,1,2.000,2.000,0,0,3
3749446415.505400,,,140.521,143.352,0.000,0.000,1,1,2.000,2.000,0,0,3
3749446445.505400,,,139.338,142.182,0.000,0.000,1,1,2.000,2.000,0,0,3
3749446475.505400,,,138.162,141.025,0.000,0.000,1,1,2.000,2.000,0,0,3
3749446505.505400,,,136.988,139.867,0.000,0.000,1,1,2.000,2.000,0,0,3
3749446535.505400,,,135.822,138.700,0.000,0.000,1,1,2.000,2.000,0,0,3
3749446565.505400,,,134.658,137.536,0.000,0.000,1,1,2.000,2.000,0,0,3
3749446595.505400,,,133.491,136.380,0.000,0.000,1,1,2.000,2.000,0,0,3
3749446625.505400,,,132.338,135.241,0.000,0.000,1,1,2.000,2.000,0,0,3
3749446655.505400,,,131.190,134.111,0.000,0.000,1,1,2.000,2.000,0,0,3
3749446685.505400,,,130.043,132.972,0.000,0.000,1,1,2.000,2.000,0,0,3
3749446715.505400,,,128.901,131.846,0.000,0.000,1,1,2.000,2.000,0,0,3
3749446745.505400,,,127.768,130.708,0.000,0.000,1,1,2.000,2.000,0,0,3
3749446775.505400,,,126.635,129.602,0.000,0.000,1,1,2.000,2.000,0,0,3
3749446805.505400,,,125.505,128.478,0.000,0.000,1,1,2.000,2.000,0,0,3
3749446835.505400,,,124.380,127.356,0.000,0.000,1,1,2.000,2.000,0,0,3
3749446865.505400,,,123.264,126.251,0.000,0.000,1,1,2.000,2.000,0,0,3
3749446895.505400,,,122.142,125.136,0.000,0.000,1,1,2.000,2.000,0,0,3
3749446925.505400,,,121.029,124.008,0.000,0.000,1,1,2.000,2.000,0,0,3
3749446955.505400,,,119.913,122.910,0.000,0.000,1,1,2.000,2.000,0,0,3
3749446985.505400,,,118.809,121.823,0.000,0.000,1,1,2.000,2.000,0,0,3
3749447015.505400,,,117.700,120.724,0.000,0.000,1,1,2.000,2.000,0,0,3
3749447045.505400,,,116.593,119.669,0.000,0.000,1,1,2.000,2.000,0,0,3
3749447075.505400,,,115.500,118.594,0.000,0.000,1,1,2.000,2.000,0,0,3
3749447105.505400,,,114.409,117.506,0.000,0.000,0,0,2.000,2.000,0,0,4
3749447135.505400,,,113.315,116.420,0.000,0.000,0,0,2.000,2.000,0,0,4
3749447165.505400,,,112.224,115.351,0.000,0.000,0,0,2.000,2.000,0,0,4
3749447195.505400,,,111.140,114.275,0.000,0.000,0,0,2.000,2.000,0,0,4
3749447225.505400,,,110.055,113.187,0.000,0.000,0,0,2.000,2.000,0,0,4
3749447255.505400,,,108.969,112.115,0.000,0.000,0,0,2.000,2.000,0,0,4
3749447285.505400,,,107.896,111.043,0.000,0.000,0,0,2.000,2.000,0,0,4
3749447315.505400,,,106.810,109.959,0.000,0.000,0,0,2.000,2.000,0,0,4
3749447345.505400,,,105.737,108.884,0.000,0.000,0,0,2.000,2.000,0,0,4
3749447375.505400,,,104.660,107.801,0.000,0.000,0,0,2.000,2.000,0,0,4
3749447405.505400,,,103.581,106.740,0.000,0.000,0,0,2.000,2.000,0,0,4
3749447435.505400,,,102.509,105.669,0.000,0.000,0,0,2.000,2.000,0,0,4
3749447465.505400,,,101.436,104.600,0.000,0.000,0,0,2.000,2.000,0,0,4
3749447495.505400,,,100.366,103.523,0.000,0.000,0,0,2.000,2.000,0,0,4
3749447525.505400,,,99.301,102.452,0.000,0.000,0,0,2.000,2.000,0,0,4
3749447555.505400,,,98.228,101.396,0.000,0.000,0,0,2.000,2.000,0,0,4
3749447585.505400,,,97.158,100.329,0.000,0.000,0,0,2.000,2.000,0,0,4
3749447615.505400,,,96.080,99.257,0.000,0.000,0,0,2.000,2.000,0,0,4
3749447645.505400,,,95.013,98.205,0.000,0.000,0,0,2.000,2.000,0,0,4
3749447675.505400,,,93.941,97.173,0.000,0.000,0,0,2.000,2.000,0,0,4
3749447705.505400,,,92.865,96.112,0.000,0.000,0,0,2.000,2.000,0,0,4
3749447735.505400,,,91.795,95.044,0.000,0.000,0,0,2.000,2.000,0,0,4
3749447765.505400,,,90.720,93.983,0.000,0.000,0,0,2.000,2.000,0,0,4
3749447795.505400,,,89.646,92.907,0.000,0.000,0,0,2.000,2.000,0,0,4
3749447825.505400,,,88.566,91.834,0.000,0.000,0,0,2.000,2.000,0,0,4
3749447855.505400,,,87.486,90.789,0.000,0.000,0,0,2.000,2.000,0,0,4
3749447885.505400,,,86.402,89.703,0.000,0.000,0,0,2.000,2.000,0,0,4
3749447915.505400,,,85.323,88.637,0.000,0.000,0,0,2.000,2.000,0,0,4
3749447945.505400,,,84.233,87.558,0.000,0.000,0,0,2.000,2.000,0,0,4
3749447975.505400,,,83.150,86.486,0.000,0.000,0,0,2.000,2.000,0,0,4
3749448005.505400,,,82.057,85.420,0.000,0.000,0,0,2.000,2.000,0,0,4
3749448035.505400,,,80.959,84.330,0.000,0.000,0,0,2.000,2.000,0,0,4
3749448065.505400,,,79.868,83.246,0.000,0.000,0,0,2.000,2.000,0,0,4
3749448095.505400,,,78.766,82.141,0.000,0.000,0,0,2.000,2.000,0,0,4
3749448125.505400,,,77.647,81.028,0.000,0.000,0,0,2.000,2.000,0,0,4
3749448155.505400,,,76.537,79.962,0.000,0.000,0,0,2.000,2.000,0,0,4
3749448185.505400,,,75.421,78.856,0.000,0.000,0,0,2.000,2.000,0,0,4
3749448215.505400,,,74.302,77.727,0.000,0.000,0,0,2.000,2.000,0,0,4
3749448245.505400,,,73.172,76.617,0.000,0.000,0,0,2.000,2.000,0,0,4
3749448275.505400,,,72.030,75.502,0.000,0.000,0,0,2.000,2.000,0,0,4
3749448305.505400,,,70.888,74.394,0.000,0.000,0,0,2.000,2.000,0,0,4
3749448335.505400,,,69.743,73.267,0.000,0.000,0,0,2.000,2.000,0,0,4
3749448365.505400,,,68.589,72.129,0.000,0.000,0,0,2.000,2.000,0,0,4
3749448395.505400,,,67.415,70.940,0.000,0.000,0,0,2.000,2.000,0,0,4
3749448425.505400,,,66.238,69.776,0.000,0.000,0,0,2.000,2.000,0,0,4
3749448455.505400,,,65.046,68.589,0.000,0.000,0,0,2.000,2.000,0,0,4
3749448485.505400,,,63.835,67.411,0.000,0.000,0,0,2.000,2.000,0,0,4
3749448515.505400,,,62.623,66.176,0.000,0.000,0,0,2.000,2.000,0,0,4
3749448545.505400,,,61.391,64.921,0.000,0.000,0,0,2.000,2.000,0,0,4
3749448575.505400,,,60.139,63.685,0.000,0.000,0,0,2.000,2.000,0,0,4
3749448605.505400,,,58.873,62.417,0.000,0.000,0,0,2.000,2.000,0,0,4
3749448635.505400,,,57.589,61.130,0.000,0.000,0,0,2.000,2.000,0,0,4
3749448665.505400,,,56.285,59.830,0.000,0.000,0,0,2.000,2.000,0,0,4
3749448695.505400,,,54.964,58.518,0.000,0.000,0,0,2.000,2.000,0,0,4
3749448725.505400,,,53.600,57.146,0.000,0.000,0,0,2.000,2.000,0,0,4
3749448755.505400,,,52.222,55.759,0.000,0.000,0,0,2.000,2.000,0,0,4
3749448785.505400,,,50.806,54.301,0.000,0.000,0,0,2.000,2.000,0,0,4
3749448815.505400,,,49.359,52.827,0.000,0.000,0,0,2.000,2.000,0,0,4
3749448845.505400,,,47.869,51.304,0.000,0.000,0,0,2.000,2.000,0,0,4
3749448875.505400,,,46.339,49.729,0.000,0.000,0,0,2.000,2.000,0,0,4
3749448905.505400,,,44.760,48.086,0.000,0.000,0,0,2.000,2.000,0,0,4
3749448935.505400,,,43.125,46.360,0.000,0.000,0,0,2.000,2.000,0,0,4
3749448965.505400,,,41.418,44.560,0.000,0.000,0,0,2.000,2.000,0,0,4
3749448995.505400,,,39.619,42.641,0.000,0.000,0,0,2.000,2.000,0,0,4
3749449025.505400,,,37.731,40.607,0.000,0.000,0,0,2.000,2.000,0,0,4
3749449055.505400,,,35.731,38.396,0.000,0.000,0,0,2.000,2.000,0,0,4
3749449085.505400,,,33.591,36.010,0.000,0.000,0,0,2.000,2.000,0,0,4
3749449115.505400,,,31.291,33.360,0.000,0.000,0,0,2.000,2.000,0,0,4
3749449145.505400,,,28.782,30.370,0.000,0.000,0,0,2.000,2.000,0,0,4
3749449175.505400,,,26.005,26.925,0.000,0.000,0,0,2.000,2.000,0,0,4
3749449205.505400,,,22.880,23.071,0.000,0.000,0,0,2.000,2.000,0,0,4
3749449235.505400,,,22.195,18.650,0.000,0.000,0,0,2.000,2.000,0,0,4
3749449265.505400,,,22.915,16.776,0.000,0.000,0,0,2.000,2.000,0,0,4
3749449295.505400,,,22.437,16.676,0.000,0.000,0,0,2.000,2.000,0,0,4
3749449325.505400,,,21.549,16.707,0.000,0.000,0,0,2.000,2.000,0,0,4
3749449355.505400,,,20.520,16.514,0.000,0.000,0,0,2.000,2.000,0,0,4
3749449385.505400,,,22.066,16.267,0.000,0.000,0,0,2.000,2.000,0,0,4
3749449415.505400,,,22.814,16.249,0.000,0.000,0,0,2.000,2.000,0,0,4
3749449445.505400,,,21.914,16.338,0.000,0.000,0,0,2.000,2.000,0,0,4
3749449475.505400,,,20.713,16.406,0.000,0.000,0,0,2.000,2.000,0,0,4
3749449505.505400,,,21.402,16.151,0.000,0.000,0,0,2.000,2.000,0,0,4
3749449535.505400,,,18.431,15.771,0.000,0.000,1,1,10.000,10.000,0,0,0
3749449565.505400,,,15.165,12.790,0.000,0.000,1,1,10.000,10.000,0,0,3
3749449595.505400,,,15.116,11.815,0.000,0.000,1,1,10.000,10.000,0,0,3
3749449625.505400,,,16.207,12.268,0.000,0.000,0,0,10.000,10.000,0,0,4
3749449655.505400,,,14.971,11.977,0.000,0.000,0,0,10.000,10.000,2,0,4
3749449685.505400,,,14.497,11.509,0.000,0.000,0,0,10.000,10.000,2,0,4
3749449715.505400,,,14.336,11.356,0.000,0.000,0,0,10.000,10.000,2,0,4
3749449745.505400,,,13.857,11.231,0.000,0.000,1,1,2.000,2.000,0,0,0
3749449775.505400,,,13.406,10.800,0.000,0.000,1,1,2.000,2.000,0,0,3
3749449805.505400,,,13.009,10.446,0.000,0.000,1,1,2.000,2.000,0,0,3
3749449835.505400,,,12.590,10.274,0.000,0.000,1,1,2.000,2.000,1,0,0
3749449865.505400,,,12.168,9.953,0.000,0.000,1,1,2.000,2.000,0,0,0
3749449895.505400,,,11.651,9.776,0.000,0.000,1,1,2.000,2.000,0,0,3
3749449925.505400,,,11.150,9.441,0.000,0.000,1,1,2.000,2.000,0,0,3
3749449955.505400,,,10.443,8.991,0.000,0.000,1,1,2.000,2.000,0,0,3
3749449985.505400,,,8.984,8.335,0.000,0.000,1,1,2.000,2.000,0,0,3
3749450015.505400,,,8.245,7.658,0.000,0.000,1,1,2.000,2.000,0,0,3
3749450045.505400,,,8.014,7.448,0.000,0.000,1,1,2.000,2.000,0,0,3
3749450075.505400,,,7.652,7.071,0.000,0.000,1,1,2.000,2.000,0,0,3
3749450105.505400,,,6.964,6.339,0.000,0.000,1,1,2.000,2.000,0,0,3
3749450135.505400,,,6.172,5.547,0.000,0.000,1,1,2.000,2.000,0,0,3
3749450165.505400,,,5.461,4.780,0.000,0.000,1,1,2.000,2.000,0,0,3
3749450195.505400,,,4.858,4.042,0.000,0.000,1,1,2.000,2.000,0,0,3
3749450225.505400,,,11.857,7.731,0.000,0.000,0,0,2.000,2.000,0,0,4
3749450255.505400,,,11.913,8.399,0.000,0.000,0,0,2.000,2.000,0,0,4
3749450285.505400,,,11.539,8.369,0.000,0.000,0,0,2.000,2.000,0,0,4
3749450315.505400,,,11.657,8.434,0.000,0.000,0,0,2.000,2.000,1,0,4
3749450345.505400,,,35.482,16.440,0.000,0.000,0,0,2.000,2.000,0,0,4
3749450375.505400,,,30.993,21.521,0.000,0.000,0,0,2.000,2.000,0,0,4
3749450405.505400,,,26.994,22.008,0.000,0.000,0,0,2.000,2.000,0,0,4
3749450435.505400,,,23.253,21.076,0.000,0.000,0,0,2.000,2.000,0,0,4
3749450465.505400,,,19.341,18.962,0.000,0.000,0,0,2.000,2.000,0,0,4
3749450495.505400,,,15.853,15.445,0.000,0.000,0,0,2.000,2.000,0,0,4
3749450525.505400,,,10.994,10.159,0.000,0.000,0,0,2.000,2.000,0,0,4
3749450555.505400,,,6.055,5.244,0.000,0.000,0,0,2.000,2.000,0,0,4
3749450585.505400,,,3.405,2.640,0.000,0.000,0,0,2.000,2.000,0,0,4
3749450615.505400,,,2.106,2.000,0.000,0.000,0,0,2.000,2.000,0,0,4
3749450645.505400,,,2.009,1.999,0.000,0.000,0,0,2.000,2.000,0,0,4
3749450675.505400,,,1.921,2.000,0.000,0.000,0,0,2.000,2.000,0,0,1
3749450705.505400,,,1.939,1.994,0.000,0.000,0,0,2.000,2.000,0,0,1
3749450735.505400,,,2.646,2.024,0.000,0.000,0,0,2.000,2.000,0,0,1
3749450765.505400,,,3.370,2.781,0.000,0.000,0,0,2.000,2.000,0,0,4
3749450795.505400,,,4.071,3.529,0.000,0.000,0,0,2.000,2.000,0,0,4
3749450825.505400,,,4.705,4.241,0.000,0.000,0,0,2.000,2.000,0,0,4
3749450855.505400,,,5.330,4.880,0.000,0.000,0,0,2.000,2.000,0,0,4
3749450885.505400,,,6.102,5.679,0.000,0.000,0,0,2.000,2.000,0,0,4
3749450915.505400,,,6.288,5.809,0.000,0.000,0,0,2.000,2.000,0,0,4
3749450945.505400,,,3.054,2.510,0.000,0.000,0,0,2.000,2.000,0,0,4
3749450975.505400,,,2.841,2.290,0.000,0.000,0,0,2.000,2.000,0,0,4
3749451005.505400,,,2.844,2.289,0.000,0.000,0,0,2.000,2.000,0,0,4
3749451035.505400,,,2.817,2.241,0.000,0.000,0,0,2.000,2.000,0,0,4
3749451065.505400,,,2.742,2.220,0.000,0.000,0,0,2.000,2.000,0,0,4
3749451095.505400,,,2.760,2.206,0.000,0.000,0,0,2.000,2.000,0,0,4
3749451125.505400,,,2.712,2.174,0.000,0.000,0,0,2.000,2.000,0,0,4
3749451155.505400,,,2.704,2.146,0.000,0.000,0,0,2.000,2.000,0,0,4
3749451185.505400,,,2.591,2.039,0.000,0.000,0,0,2.000,2.000,0,0,4
3749451215.505400,,,2.397,1.995,0.000,0.000,0,0,2.000,2.000,0,0,4
3749451245.505400,,,1.957,2.000,0.000,0.000,0,0,2.000,2.000,0,0,1
3749451275.505400,,,2.533,2.027,0.000,0.000,0,0,2.000,2.000,0,0,1
3749451305.505400,,,2.623,2.120,0.000,0.000,0,0,2.000,2.000,0,0,4
3749451335.505400,,,2.543,2.050,0.000,0.000,0,0,2.000,2.000,0,0,4
3749451365.505400,,,2.320,1.997,0.000,0.000,0,0,2.000,2.000,0,0,4
3749451395.505400,,,2.216,2.003,0.000,0.000,0,0,2.000,2.000,0,0,4
3749451425.505400,,,2.015,2.000,0.000,0.000,0,0,2.000,2.000,0,0,1
3749451455.505400,,,1.854,1.996,0.000,0.000,0,0,2.000,2.000,0,0,1
3749451485.505400,,,2.537,2.066,0.000,0.000,0,0,2.000,2.000,0,0,1
3749451515.505400,,,2.559,2.104,0.000,0.000,0,0,2.000,2.000,0,0,4
3749451545.505400,,,2.420,2.000,0.000,0.000,0,0,2.000,2.000,0,0,4
3749451575.505400,,,2.338,2.000,0.000,0.000,0,0,2.000,2.000,0,0,4
3749451605.505400,,,2.126,1.999,0.000,0.000,0,0,2.000,2.000,0,0,1
3749451635.505400,,,1.977,2.000,0.000,0.000,0,0,2.000,2.000,0,0,1
3749451665.505400,,,1.993,2.001,0.000,0.000,0,0,2.000,2.000,0,0,1
3749451695.505400,,,1.992,2.001,0.000,0.000,0,0,2.000,2.000,0,0,1
3749451725.505400,,,1.940,1.999,0.000,0.000,0,0,2.000,2.000,0,0,4
3749451755.505400,,,1.971,2.001,0.000,0.000,0,0,2.000,2.000,0,0,4
3749451785.505400,,,1.993,2.000,0.000,0.000,0,0,2.000,2.000,0,0,1
3749451815.505400,,,2.013,2.000,0.000,0.000,0,0,2.000,2.000,0,0,1
3749451845.505400,,,2.014,2.000,0.000,0.000,0,0,2.000,2.000,0,0,1
3749451875.505400,,,2.002,2.000,0.000,0.000,0,0,2.000,2.000,0,0,1
3749451905.505400,,,1.998,1.999,0.000,0.000,0,0,2.000,2.000,0,0,1
3749451935.505400,,,1.999,2.000,0.000,0.000,0,0,2.000,2.000,0,0,1
3749451965.505400,,,2.003,2.000,0.000,0.000,0,0,2.000,2.000,0,0,1
3749451995.505400,,,1.999,2.000,0.000,0.000,0,0,2.000,2.000,0,0,1
3749452025.505400,,,2.003,1.999,0.000,0.000,0,0,2.000,2.000,0,0,1
3749452055.505400,,,2.003,2.000,0.000,0.000,0,0,2.000,2.000,0,0,1
3749452085.505400,,,2.000,2.000,0.000,0.000,0,0,2.000,2.000,0,0,1
3749452115.505400,,,2.000,2.000,0.000,0.000,0,0,2.000,2.000,0,0,1
3749452145.505400,,,1.999,2.001,0.000,0.000,0,0,2.000,2.000,0,0,1
3749452175.505400,,,1.989,2.000,0.000,0.000,0,0,2.000,2.000,0,0,1
3749452205.505400,,,2.002,2.000,0.000,0.000,0,0,2.000,2.000,0,0,1
3749452235.505400,,,1.998,2.000,0.000,0.000,0,0,2.000,2.000,0,0,1
3749452265.505400,,,2.000,2.000,0.000,0.000,0,0,2.000,2.000,0,0,1
3749452295.505400,,,2.002,2.000,0.000,0.000,0,0,2.000,2.000,0,0,1
3749452325.505400,,,1.994,2.001,0.000,0.000,0,0,2.000,2.000,0,0,1
3749452355.505400,,,2.003,2.000,0.000,0.000,0,0,2.000,2.000,0,0,1
3749452385.505400,,,1.998,2.000,0.000,0.000,0,0,2.000,2.000,0,0,1
3749452415.505400,,,2.002,2.000,0.000,0.000,0,0,2.000,2.000,0,0,1
3749452445.505400,,,1.998,2.000,0.000,0.000,0,0,2.000,2.000,0,0,1
3749452475.505400,,,2.010,2.000,0.000,0.000,0,0,2.000,2.000,0,0,1
3749452505.505400,,,1.996,2.000,0.000,0.000,0,0,2.000,2.000,0,0,1
3749452535.505400,,,1.998,2.000,0.000,0.000,0,0,2.000,2.000,0,0,1
3749452565.505400,,,1.995,2.000,0.000,0.000,0,0,2.000,2.000,0,0,1
3749452595.505400,,,1.997,2.000,0.000,0.000,0,0,2.000,2.000,0,0,1
3749452625.505400,,,2.001,2.000,0.000,0.000,0,0,2.000,2.000,0,0,1
3749452655.505400,,,2.001,2.000,0.000,0.000,0,0,2.000,2.000,0,0,1
3749452685.505400,,,2.000,2.000,0.000,0.000,0,0,2.000,2.000,0,0,1
3749452715.505400,,,2.000,2.000,0.000,0.000,0,0,2.000,2.000,0,0,1
3749452745.505400,,,2.003,2.000,0.000,0.000,0,0,2.000,2.000,0,0,1
3749452775.505400,,,1.999,2.000,0.000,0.000,0,0,2.000,2.000,0,0,1
3749452805.505400,,,2.000,2.000,0.000,0.000,0,0,2.000,2.000,0,0,1
3749452835.505400,,,2.001,2.000,0.000,0.000,0,0,2.000,2.000,0,0,1
3749452865.505400,,,2.001,2.000,0.000,0.000,0,0,2.000,2.000,0,0,1
3749452895.505400,,,2.007,2.000,0.000,0.000,0,0,2.000,2.000,0,0,1
3749452925.505400,,,1.994,2.001,0.000,0.000,0,0,2.000,2.000,0,0,1
3749452955.505400,,,1.757,1.994,0.000,0.000,0,0,2.000,2.000,0,0,4
3749452985.505400,,,2.080,1.999,0.000,0.000,0,0,2.000,2.000,0,0,4
3749453015.505400,,,1.703,2.000,0.000,0.000,0,0,300.000,2.000,0,0,4
3749453045.505400,,,1.734,1.990,0.000,0.000,0,0,2.000,2.000,0,0,4
3749453075.505400,,,2.261,2.000,0.000,0.000,0,0,2.000,2.000,0,0,4
3749453105.505400,,,2.007,1.999,0.000,0.000,0,0,2.000,2.000,0,0,1
3749453135.505400,,,1.998,2.000,0.000,0.000,0,0,2.000,2.000,0,0,1
3749453165.505400,,,2.004,1.999,0.000,0.000,0,0,2.000,2.000,0,0,1
3749453195.505400,,,1.998,2.001,0.000,0.000,0,0,2.000,2.000,0,0,1
3749453225.505400,,,2.001,2.000,0.000,0.000,0,0,2.000,2.000,0,0,1
3749453255.505400,,,1.998,2.000,0.000,0.000,0,0,2.000,2.000,0,0,1
3749453285.505400,,,2.002,2.000,0.000,0.000,0,0,2.000,2.000,0,0,1
3749453315.505400,,,2.001,2.000,0.000,0.000,0,0,2.000,2.000,0,0,1
3749453345.505400,,,1.998,2.000,0.000,0.000,0,0,2.000,2.000,0,0,1
3749453375.505400,,,2.001,2.000,0.000,0.000,0,0,2.000,2.000,0,0,1
3749453405.505400,,,1.999,2.000,0.000,0.000,0,0,2.000,2.000,0,0,1
3749453435.505400,,,2.000,2.000,0.000,0.000,0,0,2.000,2.000,0,0,1
3749453465.505400,,,2.001,2.000,0.000,0.000,0,0,2.000,2.000,0,0,1
3749453495.505400,,,1.996,2.000,0.000,0.000,0,0,2.000,2.000,0,0,1
3749453525.505400,,,2.007,2.000,0.000,0.000,0,0,2.000,2.000,0,0,1
3749453555.505400,,,1.999,2.000,0.000,0.000,0,0,2.000,2.000,0,0,1
3749453585.505400,,,1.999,2.000,0.000,0.000,0,0,2.000,2.000,0,0,1
3749453615.506000,,,2.001,2.000,0.000,0.000,0,0,2.000,2.000,0,0,1
3749453645.506000,,,1.996,2.000,0.000,0.000,0,0,2.000,2.000,0,0,1
3749454234.590000,,,1.997,1.999,0.000,0.000,0,0,2.000,2.000,0,0,4
3749454414.590000,,,2.003,2.000,0.000,0.000,0,0,2.000,2.000,0,0,1
3749454594.590000,,,1.999,2.000,0.000,0.000,0,0,2.000,2.000,0,0,1
3749455076.648000,,,1.981,2.000,0.000,0.000,0,0,2.000,2.000,0,0,4
3749455256.648000,,,2.000,0.000,2.000,0.140,0,0,2.005,0.000,0,0,4
3749455436.648000,,,0.000,0.000,2.000,2.000,0,0,2.000,2.000,0,0,4
3749455616.648000,,,2.000,2.006,0.000,0.000,0,0,0.140,0.030,2,2,4
3749455796.648000,,,0.030,0.140,1.998,1.996,0,0,0.000,0.000,0,2,4
3749456250.004000,,,1.996,2.001,0.000,0.000,0,0,2.000,2.000,0,0,4
3749456462.232000,,,1.998,2.000,0.000,0.000,0,0,2.000,2.000,0,0,4
3749456642.232000,,,1.662,1.654,0.000,0.000,0,0,2.000,2.000,0,0,4
3749456822.232000,,,2.001,2.000,0.000,0.000,0,0,2.000,2.000,0,0,4
3749457033.204000,,,2.002,1.999,0.000,0.000,0,0,2.000,2.000,0,0,4