File: log/20230107.dat
[Header]
; Displex Transport Data File (default extension .dat)
; Copyright 2016, Hechang LEI, hlei@ruc.edu.cn. All rights reserved.
BYAPP, Displex, 2.0
INFO, 9T mag, Release 2.0.
INFO, Channel 1, Temperature Sensor
INFO, Sample 1 Length (cm): 0.000000; Width (cm): 0.000000; Thickness (cm): 0.000000.

[Data]
Timestamp(s),Field(Oe),Field Status,TempA(K),TempB(K),TempC(K),TempD(K),Ramp1,Ramp2,Setpoint1,Setpoint2,Output1(%),Output2(%),Temp Status
3755900690.034400,0,1,3.393,0.000,35.096,3.205,0,0,2.000,2.000,0.000,0.000,4
3755900850.351400,0,1,3.185,0.000,35.184,2.999,0,0,2.000,2.000,0.000,0.000,4
3755901030.351400,0,1,3.235,0.000,34.977,2.944,0,0,2.000,2.000,0.000,0.000,4
3755901210.351400,0,1,3.230,0.000,34.870,2.937,0,0,2.000,2.000,0.000,0.000,4
3755901390.351400,0,1,3.224,0.000,34.825,2.933,0,0,2.000,2.000,0.000,0.000,4
3755901570.351400,0,1,3.222,0.000,34.821,2.938,0,0,2.000,2.000,0.000,0.000,4
3755901886.176400,0,0,3.301,0.000,34.859,3.148,0,0,2.000,2.000,0.000,0.000,4
3755902066.176400,0,0,3.555,0.000,38.333,3.889,0,0,2.000,2.000,0.000,0.000,4
3755902246.176400,0,0,3.812,0.000,41.998,4.759,0,0,2.000,2.000,0.000,0.000,4
3755902426.176400,0,0,4.009,0.000,44.979,5.644,0,0,2.000,2.000,0.000,0.000,4
3755902606.176400,0,0,4.189,0.000,47.366,6.635,0,0,2.000,2.000,0.000,0.000,4
3755902786.176400,0,0,4.367,0.000,49.346,7.681,0,0,2.000,2.000,0.000,0.000,4
3755902966.176400,0,0,4.533,0.000,51.059,8.732,0,0,2.000,2.000,0.000,0.000,4
3755903146.176400,0,0,4.678,0.000,52.622,9.735,0,0,2.000,2.000,0.000,0.000,4
3755903326.176400,0,0,4.742,0.000,54.072,10.816,0,0,2.000,2.000,0.000,0.000,4
3755903506.176400,0,0,4.791,0.000,55.454,12.026,0,0,2.000,2.000,0.000,0.000,4
3755903686.176400,0,0,4.839,0.000,56.775,13.200,0,0,2.000,2.000,0.000,0.000,4
3755903866.176400,0,0,4.887,0.000,58.038,14.385,0,0,2.000,2.000,0.000,0.000,4
3755904046.176400,0,0,5.074,0.000,59.261,15.641,0,0,2.000,2.000,0.000,0.000,4
3755904226.176400,0,0,5.723,0.000,60.433,16.864,0,0,2.000,2.000,0.000,0.000,4
3755904406.176400,0,0,6.658,0.000,61.573,17.978,0,0,2.000,2.000,0.000,0.000,4
3755904586.176400,0,0,8.001,0.000,62.679,18.940,0,0,2.000,2.000,0.000,0.000,4
3755904766.176400,0,0,9.774,0.000,63.751,19.789,0,0,2.000,2.000,0.000,0.000,4
3755904946.176400,0,0,11.867,0.000,64.802,20.581,0,0,2.000,2.000,0.000,0.000,4
3755905126.176400,0,0,13.990,0.000,65.823,21.403,0,0,2.000,2.000,0.000,0.000,4
3755905306.176400,0,0,15.965,0.000,66.824,22.219,0,0,2.000,2.000,0.000,0.000,4
3755905486.176400,0,0,17.717,0.000,67.802,23.046,0,0,2.000,2.000,0.000,0.000,4
3755905666.176400,0,0,19.256,0.000,68.750,23.918,0,0,2.000,2.000,0.000,0.000,4
3755905846.176400,0,0,20.635,0.000,69.678,24.818,0,0,2.000,2.000,0.000,0.000,4
3755906026.176400,0,0,21.878,0.000,70.576,25.721,0,0,2.000,2.000,0.000,0.000,4
3755906206.176400,0,0,23.024,0.000,71.454,26.618,0,0,2.000,2.000,0.000,0.000,4
3755906386.176400,0,0,24.082,0.000,72.302,27.536,0,0,2.000,2.000,0.000,0.000,4
3755906566.176400,0,0,25.080,0.000,73.132,28.391,0,0,2.000,2.000,0.000,0.000,4
3755906746.176400,0,0,26.023,0.000,73.934,29.228,0,0,2.000,2.000,0.000,0.000,4
3755906926.176400,0,0,26.931,0.000,74.719,30.028,0,0,2.000,2.000,0.000,0.000,4
3755907106.176400,0,0,27.811,0.000,75.485,30.798,0,0,2.000,2.000,0.000,0.000,4
3755907286.176400,0,0,28.668,0.000,76.228,31.516,0,0,2.000,2.000,0.000,0.000,4
3755907466.176400,0,0,29.509,0.000,76.961,32.222,0,0,2.000,2.000,0.000,0.000,4
3755907646.176400,0,0,30.330,0.000,77.675,32.862,0,0,2.000,2.000,0.000,0.000,4
3755907826.176400,0,0,31.138,0.000,78.382,33.488,0,0,2.000,2.000,0.000,0.000,4
3755908006.176400,0,0,31.943,0.000,79.073,34.080,0,0,2.000,2.000,0.000,0.000,4
3755908186.176400,0,0,32.770,0.000,79.761,34.636,0,0,2.000,2.000,0.000,0.000,4
3755908366.176400,0,0,33.621,0.000,80.439,35.177,0,0,2.000,2.000,0.000,0.000,4
3755908546.176400,0,0,34.496,0.000,81.114,35.697,0,0,2.000,2.000,0.000,0.000,4
3755908726.176400,0,0,35.365,0.000,81.779,36.190,0,0,2.000,2.000,0.000,0.000,4
3755908906.176400,0,0,36.225,0.000,82.437,36.646,1,0,300.000,2.000,0.000,0.000,4
3755909086.176400,0,0,37.098,0.000,83.092,37.041,1,0,300.000,2.000,0.000,0.000,4
3755909266.176400,0,0,44.386,0.000,83.748,37.408,1,0,300.000,2.000,6.050,0.000,4
3755909446.176400,0,0,59.234,0.000,84.405,37.728,1,0,300.000,2.000,13.260,0.000,4
3755909626.176400,0,0,74.112,0.000,85.069,38.047,1,0,300.000,2.000,19.650,0.000,4
3755909806.176400,0,0,89.075,0.000,85.746,38.334,1,0,300.000,2.000,25.330,0.000,4
3755909986.176400,0,0,103.951,0.000,86.432,38.645,1,0,300.000,2.000,30.360,0.000,4
3755910166.176400,0,0,118.824,0.000,87.136,38.940,1,0,300.000,2.000,35.100,0.000,4
3755910346.176400,0,0,133.696,0.000,87.865,39.275,1,0,300.000,2.000,39.430,0.000,4
3755910526.176400,0,0,148.512,0.000,88.610,39.615,1,0,300.000,2.000,43.420,0.000,4
3755910706.176400,0,0,163.396,0.000,89.370,39.964,1,0,300.000,2.000,47.570,0.000,4
3755910886.176400,0,0,178.192,0.000,90.121,40.337,1,0,300.000,2.000,51.310,0.000,4
3755911066.176400,0,0,193.098,0.000,90.785,40.679,1,0,300.000,2.000,54.190,0.000,4
3755911246.176400,0,0,207.982,0.000,91.418,41.026,1,0,300.000,2.000,57.420,0.000,4
3755911426.176400,0,0,222.800,0.000,92.048,41.386,1,0,300.000,2.000,60.660,0.000,4
3755911606.176400,0,0,237.693,0.000,92.685,41.794,1,0,300.000,2.000,63.950,0.000,4
3755911786.176400,0,0,252.503,0.000,93.328,42.193,1,0,300.000,2.000,67.240,0.000,4
3755911966.176400,0,0,267.381,0.000,93.986,42.625,1,0,300.000,2.000,70.460,0.000,4
3755912146.176400,0,0,281.094,0.000,94.639,43.087,1,0,300.000,2.000,77.940,0.000,4
3755912326.176400,0,0,296.681,0.000,95.261,43.566,1,0,300.000,2.000,64.780,0.000,4
3755912506.176400,0,0,301.123,0.000,95.866,44.000,0,0,300.000,2.000,18.500,0.000,4
3755912686.176400,0,0,301.800,0.000,96.465,44.466,0,0,300.000,2.000,41.260,0.000,4
3755912866.176400,0,0,300.389,0.000,97.061,44.939,0,0,300.000,2.000,67.040,0.000,4
3755913046.176400,0,0,298.868,0.000,97.656,45.428,0,0,300.000,2.000,64.540,0.000,4
3755913226.176400,0,0,298.802,0.000,98.245,45.941,0,0,300.000,2.000,39.650,0.000,4
3755913406.176400,0,0,300.104,0.000,98.832,46.459,0,0,300.000,2.000,21.520,0.000,4
3755913586.176400,0,0,301.065,0.000,99.417,46.988,0,0,300.000,2.000,27.710,0.000,4
3755913766.176400,0,0,300.657,0.000,100.001,47.544,0,0,300.000,2.000,45.540,0.000,4
3755913946.176400,0,0,299.585,0.000,100.586,48.096,0,0,300.000,2.000,51.060,0.000,4
3755914126.176400,0,0,299.193,0.000,101.170,48.633,0,0,300.000,2.000,38.900,0.000,4
3755914306.176400,0,0,299.810,0.000,101.754,49.275,0,0,300.000,2.000,25.040,0.000,4
3755914486.176400,0,0,300.538,0.000,102.339,49.833,0,0,300.000,2.000,24.590,0.000,4
3755914666.176400,0,0,300.516,0.000,102.925,50.454,0,0,300.000,2.000,34.600,0.000,4
3755914846.176400,0,0,299.904,0.000,103.513,51.159,0,0,300.000,2.000,40.590,0.000,4
3755915026.176400,0,0,299.532,0.000,104.107,51.794,0,0,300.000,2.000,35.900,0.000,4
3755915206.176400,0,0,299.752,0.000,104.699,52.471,0,0,300.000,2.000,26.880,0.000,4
3755915386.176400,0,0,300.222,0.000,105.295,53.086,0,0,300.000,2.000,24.050,0.000,4
3755915566.176400,0,0,300.345,0.000,105.894,53.747,0,0,300.000,2.000,28.980,0.000,4
3755915746.176400,0,0,300.035,0.000,106.496,54.519,0,0,300.000,2.000,33.760,0.000,4
3755915926.176400,0,0,299.748,0.000,107.102,55.311,0,0,300.000,2.000,32.280,0.000,4
3755916106.176400,0,0,299.817,0.000,107.712,55.933,0,0,300.000,2.000,26.980,0.000,4
3755916286.176400,0,0,300.092,0.000,108.327,56.763,0,0,300.000,2.000,24.620,0.000,4
3755916466.176400,0,0,300.204,0.000,108.946,57.580,0,0,300.000,2.000,27.060,0.000,4
3755916646.176400,0,0,300.053,0.000,109.571,58.309,0,0,300.000,2.000,30.220,0.000,4
3755916826.176400,0,0,299.875,0.000,110.205,59.116,0,0,300.000,2.000,30.030,0.000,4
3755917006.176400,0,0,299.871,0.000,110.841,59.932,0,0,300.000,2.000,27.400,0.000,4
3755917186.176400,0,0,300.019,0.000,111.485,60.784,0,0,300.000,2.000,25.640,0.000,4
3755917366.176400,0,0,300.114,0.000,112.135,61.640,0,0,300.000,2.000,26.680,0.000,4
3755917546.176400,0,0,300.049,0.000,112.793,62.485,0,0,300.000,2.000,28.770,0.000,4
3755917726.176400,0,0,299.940,0.000,113.459,63.349,0,0,300.000,2.000,29.250,0.000,4
3755917906.176400,0,0,299.924,0.000,114.134,64.311,0,0,300.000,2.000,28.160,0.000,4
3755918086.176400,0,0,300.000,0.000,114.817,65.199,0,0,300.000,2.000,27.140,0.000,4
3755918266.176400,0,0,300.060,0.000,115.511,66.220,0,0,300.000,2.000,27.870,0.000,4
3755918446.176400,0,0,300.034,0.000,116.214,67.219,0,0,300.000,2.000,29.330,0.000,4
3755918626.176400,0,0,299.970,0.000,116.929,68.130,0,0,300.000,2.000,29.980,0.000,4
3755918806.176400,0,0,299.950,0.000,117.659,69.033,0,0,300.000,2.000,29.680,0.000,4
3755918986.176400,0,0,299.988,0.000,118.399,70.107,0,0,300.000,2.000,29.360,0.000,4
3755919166.176400,0,0,300.028,0.000,119.152,70.987,0,0,300.000,2.000,30.030,0.000,4
3755919346.176400,0,0,300.023,0.000,119.919,72.007,0,0,300.000,2.000,31.160,0.000,4
3755919526.176400,0,0,299.989,0.000,120.701,73.054,0,0,300.000,2.000,31.990,0.000,4
3755919706.176400,0,0,299.970,0.000,121.500,74.157,0,0,300.000,2.000,32.250,0.000,4
3755919886.176400,0,0,299.986,0.000,122.316,75.109,0,0,300.000,2.000,32.470,0.000,4
3755920066.176400,0,0,300.012,0.000,123.152,75.990,0,0,300.000,2.000,33.070,0.000,4
3755920246.176400,0,0,300.015,0.000,124.006,77.102,0,0,300.000,2.000,33.990,0.000,4
3755920426.176400,0,0,299.997,0.000,124.882,78.070,0,0,300.000,2.000,35.010,0.000,4
3755920606.176400,0,0,299.983,0.000,125.780,79.024,0,0,300.000,2.000,35.540,0.000,4
3755920786.176400,0,0,299.986,0.000,126.706,80.100,0,0,300.000,2.000,36.020,0.000,4
3755920966.176400,0,0,300.004,0.000,127.652,81.113,0,0,300.000,2.000,36.700,0.000,4
3755921146.176400,0,0,300.008,0.000,128.624,82.180,0,0,300.000,2.000,37.580,0.000,4
3755921326.176400,0,0,299.998,0.000,129.622,83.099,0,0,300.000,2.000,38.470,0.000,4
3755921506.176400,0,0,299.988,0.000,130.646,84.222,0,0,300.000,2.000,39.210,0.000,4
3755921686.176400,0,0,299.991,0.000,131.700,85.203,0,0,300.000,2.000,39.740,0.000,4
3755921866.176400,0,0,299.995,0.000,132.780,86.339,0,0,300.000,2.000,40.340,0.000,4
3755922046.176400,0,0,300.001,0.000,133.888,87.269,0,0,300.000,2.000,41.000,0.000,4
3755922226.176400,0,0,299.996,0.000,135.022,88.407,0,0,300.000,2.000,41.610,0.000,4
3755922406.176400,0,0,299.995,0.000,136.180,89.388,0,0,300.000,2.000,42.120,0.000,4
3755922586.176400,0,0,299.997,0.000,137.368,90.359,0,0,300.000,2.000,42.710,0.000,4
3755922766.176400,0,0,300.000,0.000,138.568,91.418,0,0,300.000,2.000,43.160,0.000,4
3755922946.176400,0,0,299.999,0.000,139.786,92.496,0,0,300.000,2.000,43.550,0.000,4
3755923126.176400,0,0,300.002,0.000,141.019,93.368,0,0,300.000,2.000,43.980,0.000,4
3755923306.176400,0,0,299.999,0.000,142.261,94.738,0,0,300.000,2.000,44.280,0.000,4
3755923486.176400,0,0,299.995,0.000,143.512,95.348,0,0,300.000,2.000,44.640,0.000,4
3755923666.176400,0,0,299.997,0.000,144.768,96.339,0,0,300.000,2.000,44.740,0.000,4
3755923846.176400,0,0,299.998,0.000,146.025,97.254,0,0,300.000,2.000,45.040,0.000,4
3755924026.176400,0,0,299.998,0.000,147.284,98.266,0,0,300.000,2.000,45.140,0.000,4
3755924206.176400,0,0,299.999,0.000,148.540,99.093,0,0,300.000,2.000,45.270,0.000,4
3755924386.176400,0,0,299.998,0.000,149.794,100.081,0,0,300.000,2.000,45.410,0.000,4
3755924566.176400,0,0,299.999,0.000,151.050,100.966,0,0,300.000,2.000,45.510,0.000,4
3755924746.176400,0,0,299.999,0.000,152.294,101.912,0,0,300.000,2.000,45.510,0.000,4
3755924926.176400,0,0,299.997,0.000,153.532,102.800,0,0,300.000,2.000,45.510,0.000,4
3755925106.176400,0,0,300.001,0.000,154.764,103.563,0,0,300.000,2.000,45.470,0.000,4
3755925286.176400,0,0,300.000,0.000,155.987,104.515,0,0,300.000,2.000,45.540,0.000,4
3755925466.176400,0,0,300.001,0.000,157.201,105.419,0,0,300.000,2.000,45.570,0.000,4
3755925646.176400,0,0,299.998,0.000,158.407,106.043,0,0,300.000,2.000,45.570,0.000,4
3755925826.176400,0,0,299.999,0.000,159.600,106.937,0,0,300.000,2.000,45.370,0.000,4
3755926006.176400,0,0,299.999,0.000,160.784,107.737,0,0,300.000,2.000,45.240,0.000,4
3755926186.176400,0,0,300.003,0.000,161.957,108.424,0,0,300.000,2.000,45.270,0.000,4
3755926366.176400,0,0,300.002,0.000,163.118,109.198,0,0,300.000,2.000,45.140,0.000,4
3755926546.176400,0,0,299.999,0.000,164.274,109.914,0,0,300.000,2.000,44.970,0.000,4
3755926726.176400,0,0,299.999,0.000,165.411,110.618,0,0,300.000,2.000,44.870,0.000,4
3755926906.176400,0,0,300.001,0.000,166.538,111.352,0,0,300.000,2.000,44.770,0.000,4
3755927086.176400,0,0,300.003,0.000,167.652,111.905,0,0,300.000,2.000,44.710,0.000,4
3755927266.176400,0,0,300.000,0.000,168.755,112.599,0,0,300.000,2.000,44.610,0.000,4
3755927446.176400,0,0,299.997,0.000,169.847,113.206,0,0,300.000,2.000,44.440,0.000,4
3755927626.176400,0,0,300.000,0.000,170.928,113.866,0,0,300.000,2.000,44.240,0.000,4
3755927806.176400,0,0,299.993,0.000,171.998,114.355,0,0,300.000,2.000,44.110,0.000,4
3755927986.176400,0,0,300.006,0.000,173.057,114.885,0,0,300.000,2.000,43.880,0.000,4
3755928166.176400,0,0,300.010,0.000,174.106,115.430,0,0,300.000,2.000,43.720,0.000,4
3755928346.176400,0,0,300.005,0.000,175.145,115.959,0,0,300.000,2.000,43.820,0.000,4
3755928526.176400,0,0,299.999,0.000,176.178,116.482,0,0,300.000,2.000,43.680,0.000,4
3755928706.176400,0,0,299.997,0.000,177.195,116.923,0,0,300.000,2.000,43.450,0.000,4
3755928886.176400,0,0,299.995,0.000,178.202,117.324,0,0,300.000,2.000,43.290,0.000,4
3755929066.176400,0,0,287.193,0.000,179.198,117.775,0,0,2.000,2.000,0.000,0.000,4
3755929246.176400,0,0,267.620,0.000,180.179,118.118,0,0,2.000,2.000,0.000,0.000,4
3755929426.176400,0,0,252.940,0.000,181.145,118.449,0,0,2.000,2.000,0.000,0.000,4
3755929606.176400,0,0,241.540,0.000,182.097,118.772,0,0,2.000,2.000,0.000,0.000,4
3755929786.176400,0,0,232.530,0.000,183.036,119.071,0,0,2.000,2.000,0.000,0.000,4
3755929966.176400,0,0,225.285,0.000,183.960,119.358,0,0,2.000,2.000,0.000,0.000,4
3755930146.176400,0,0,219.379,0.000,184.870,119.638,0,0,2.000,2.000,0.000,0.000,4
3755930326.176400,0,0,214.472,0.000,185.766,119.829,0,0,2.000,2.000,0.000,0.000,4
3755930506.176400,0,0,210.309,0.000,186.646,120.021,0,0,2.000,2.000,0.000,0.000,4
3755930686.176400,0,0,206.699,0.000,187.518,120.216,0,0,2.000,2.000,0.000,0.000,4
3755930866.176400,0,0,203.566,0.000,188.370,120.386,0,0,2.000,2.000,0.000,0.000,4
3755931046.176400,0,0,200.812,0.000,189.209,120.566,0,0,2.000,2.000,0.000,0.000,4
3755931226.176400,0,0,198.370,0.000,190.035,120.684,0,0,2.000,2.000,0.000,0.000,4
3755931406.176400,0,0,196.182,0.000,190.849,120.785,0,0,2.000,2.000,0.000,0.000,4
3755931586.176400,0,0,194.207,0.000,191.651,120.865,0,0,2.000,2.000,0.000,0.000,4
3755931766.176400,0,0,192.409,0.000,192.442,120.935,0,0,2.000,2.000,0.000,0.000,4
3755931946.176400,0,0,190.762,0.000,193.222,120.984,0,0,2.000,2.000,0.000,0.000,4
3755932126.176400,0,0,189.249,0.000,193.992,121.014,0,0,2.000,2.000,0.000,0.000,4
3755932306.176400,0,0,187.845,0.000,194.755,121.034,0,0,2.000,2.000,0.000,0.000,4
3755932486.176400,0,0,186.547,0.000,195.503,121.035,0,0,2.000,2.000,0.000,0.000,4
3755932666.176400,0,0,185.353,0.000,196.245,121.014,0,0,2.000,2.000,0.000,0.000,4
3755932846.176400,0,0,184.241,0.000,196.975,120.988,0,0,2.000,2.000,0.000,0.000,4
3755933026.176400,0,0,183.201,0.000,197.695,120.934,0,0,2.000,2.000,0.000,0.000,4
3755933206.176400,0,0,182.232,0.000,198.407,120.878,0,0,2.000,2.000,0.000,0.000,4
3755933386.176400,0,0,181.326,0.000,199.109,120.801,0,0,2.000,2.000,0.000,0.000,4
3755933566.176400,0,0,180.481,0.000,199.802,120.680,0,0,2.000,2.000,0.000,0.000,4
3755933746.176400,0,0,179.688,0.000,200.490,120.577,0,0,2.000,2.000,0.000,0.000,4
3755933926.176400,0,0,178.950,0.000,201.166,120.462,0,0,2.000,2.000,0.000,0.000,4
3755934106.176400,0,0,178.262,0.000,201.833,120.335,0,0,2.000,2.000,0.000,0.000,4
3755934286.176400,0,0,177.620,0.000,202.492,120.175,0,0,2.000,2.000,0.000,0.000,4
3755934466.176400,0,0,177.025,0.000,203.142,119.990,0,0,2.000,2.000,0.000,0.000,4
3755934646.176400,0,0,176.474,0.000,203.784,119.833,0,0,2.000,2.000,0.000,0.000,4
3755934826.176400,0,0,175.964,0.000,204.417,119.642,0,0,2.000,2.000,0.000,0.000,4
3755935006.176400,0,0,175.496,0.000,205.042,119.463,0,0,2.000,2.000,0.000,0.000,4
3755935186.176400,0,0,175.065,0.000,205.659,119.242,0,0,2.000,2.000,0.000,0.000,4
3755935366.176400,0,0,174.670,0.000,206.272,119.021,0,0,2.000,2.000,0.000,0.000,4
3755935546.176400,0,0,174.313,0.000,206.874,118.851,0,0,2.000,2.000,0.000,0.000,4
3755935726.176400,0,0,173.988,0.000,207.469,118.557,0,0,2.000,2.000,0.000,0.000,4
3755935906.176400,0,0,173.696,0.000,208.057,118.334,0,0,2.000,2.000,0.000,0.000,4
3755936086.176400,0,0,173.433,0.000,208.638,118.125,0,0,2.000,2.000,0.000,0.000,4
3755936266.176400,0,0,173.202,0.000,209.211,117.948,0,0,2.000,2.000,0.000,0.000,4
3755936446.176400,0,0,172.998,0.000,209.778,117.650,0,0,2.000,2.000,0.000,0.000,4
3755936626.176400,0,0,172.822,0.000,210.339,117.466,0,0,2.000,2.000,0.000,0.000,4
3755936806.176400,0,0,172.671,0.000,210.895,117.206,0,0,2.000,2.000,0.000,0.000,4
3755936986.176400,0,0,172.545,0.000,211.442,116.943,0,0,2.000,2.000,0.000,0.000,4
3755937166.176400,0,0,172.443,0.000,211.984,116.739,0,0,2.000,2.000,0.000,0.000,4
3755937346.176400,0,0,172.364,0.000,212.519,116.431,0,0,2.000,2.000,0.000,0.000,4
3755937526.176400,0,0,172.307,0.000,213.048,116.311,0,0,2.000,2.000,0.000,0.000,4
3755937706.176400,0,0,172.271,0.000,213.571,115.993,0,0,2.000,2.000,0.000,0.000,4
3755937886.176400,0,0,172.257,0.000,214.088,115.779,0,0,2.000,2.000,0.000,0.000,4
3755938066.176400,0,0,172.260,0.000,214.599,115.510,0,0,2.000,2.000,0.000,0.000,4
3755938246.176400,0,0,172.282,0.000,215.105,115.325,0,0,2.000,2.000,0.000,0.000,4
3755938426.176400,0,0,172.324,0.000,215.608,115.147,0,0,2.000,2.000,0.000,0.000,4
3755938606.176400,0,0,172.382,0.000,216.103,114.862,0,0,2.000,2.000,0.000,0.000,4
3755938786.176400,0,0,172.455,0.000,216.593,114.619,0,0,2.000,2.000,0.000,0.000,4
3755938966.176400,0,0,172.544,0.000,217.078,114.424,0,0,2.000,2.000,0.000,0.000,4
3755939146.176400,0,0,172.649,0.000,217.557,114.242,0,0,2.000,2.000,0.000,0.000,4
3755939326.176400,0,0,172.770,0.000,218.031,114.005,0,0,2.000,2.000,0.000,0.000,4
3755939506.176400,0,0,172.902,0.000,218.500,113.789,0,0,2.000,2.000,0.000,0.000,4
3755939686.176400,0,0,173.048,0.000,218.965,113.640,0,0,2.000,2.000,0.000,0.000,4
3755939866.176400,0,0,173.208,0.000,219.424,113.468,0,0,2.000,2.000,0.000,0.000,4
3755940046.176400,0,0,173.382,0.000,219.881,113.297,0,0,2.000,2.000,0.000,0.000,4
3755940226.176400,0,0,173.566,0.000,220.331,113.145,0,0,2.000,2.000,0.000,0.000,4
3755940406.176400,0,0,173.760,0.000,220.776,112.959,0,0,2.000,2.000,0.000,0.000,4
3755940586.176400,0,0,173.965,0.000,221.217,112.842,0,0,2.000,2.000,0.000,0.000,4
3755940766.176400,0,0,174.181,0.000,221.652,112.654,0,0,2.000,2.000,0.000,0.000,4
3755940946.176400,0,0,174.407,0.000,222.083,112.529,0,0,2.000,2.000,0.000,0.000,4
3755941126.176400,0,0,174.640,0.000,222.509,112.423,0,0,2.000,2.000,0.000,0.000,4
3755941306.176400,0,0,174.883,0.000,222.931,112.303,0,0,2.000,2.000,0.000,0.000,4
3755941486.176400,0,0,175.137,0.000,223.347,112.198,0,0,2.000,2.000,0.000,0.000,4
3755941666.176400,0,0,175.397,0.000,223.762,112.084,0,0,2.000,2.000,0.000,0.000,4
3755941846.176400,0,0,175.664,0.000,224.169,111.989,0,0,2.000,2.000,0.000,0.000,4
3755942026.176400,0,0,175.935,0.000,224.574,111.930,0,0,2.000,2.000,0.000,0.000,4
3755942206.176400,0,0,176.212,0.000,224.974,111.800,0,0,2.000,2.000,0.000,0.000,4
3755942386.176400,0,0,176.497,0.000,225.367,111.772,0,0,2.000,2.000,0.000,0.000,4
3755942566.176400,0,0,176.786,0.000,225.758,111.721,0,0,2.000,2.000,0.000,0.000,4
3755942746.176400,0,0,177.082,0.000,226.145,111.690,0,0,2.000,2.000,0.000,0.000,4
3755942926.176400,0,0,177.386,0.000,226.526,111.664,0,0,2.000,2.000,0.000,0.000,4
3755943106.176400,0,0,177.694,0.000,226.907,111.637,0,0,2.000,2.000,0.000,0.000,4
3755943286.176400,0,0,178.008,0.000,227.281,111.632,0,0,2.000,2.000,0.000,0.000,4
3755943466.176400,0,0,178.324,0.000,227.653,111.628,0,0,2.000,2.000,0.000,0.000,4
3755943646.176400,0,0,178.648,0.000,228.019,111.637,0,0,2.000,2.000,0.000,0.000,4
3755943826.176400,0,0,178.976,0.000,228.383,111.663,0,0,2.000,2.000,0.000,0.000,4
3755944006.176400,0,0,179.306,0.000,228.743,111.698,0,0,2.000,2.000,0.000,0.000,4
3755944186.176400,0,0,179.643,0.000,229.099,111.730,0,0,2.000,2.000,0.000,0.000,4
3755944366.176400,0,0,179.982,0.000,229.452,111.807,0,0,2.000,2.000,0.000,0.000,4
3755944546.176400,0,0,180.327,0.000,229.802,111.853,0,0,2.000,2.000,0.000,0.000,4
3755944726.176400,0,0,180.674,0.000,230.151,111.966,0,0,2.000,2.000,0.000,0.000,4
3755944906.176400,0,0,181.026,0.000,230.495,112.044,0,0,2.000,2.000,0.000,0.000,4
3755945086.176400,0,0,181.380,0.000,230.836,112.163,0,0,2.000,2.000,0.000,0.000,4
3755945266.176400,0,0,181.736,0.000,231.173,112.284,0,0,2.000,2.000,0.000,0.000,4
3755945446.176400,0,0,182.096,0.000,231.509,112.415,0,0,2.000,2.000,0.000,0.000,4
3755945626.176400,0,0,182.458,0.000,231.841,112.531,0,0,2.000,2.000,0.000,0.000,4
3755945806.176400,0,0,182.822,0.000,232.169,112.706,0,0,2.000,2.000,0.000,0.000,4
3755945986.176400,0,0,183.189,0.000,232.496,112.825,0,0,2.000,2.000,0.000,0.000,4
3755946166.176400,0,0,183.560,0.000,232.821,113.027,0,0,2.000,2.000,0.000,0.000,4
3755946346.176400,0,0,183.932,0.000,233.143,113.175,0,0,2.000,2.000,0.000,0.000,4
3755946526.176400,0,0,184.305,0.000,233.461,113.389,0,0,2.000,2.000,0.000,0.000,4
3755946706.176400,0,0,184.680,0.000,233.776,113.580,0,0,2.000,2.000,0.000,0.000,4
3755946886.176400,0,0,185.056,0.000,234.089,113.859,0,0,2.000,2.000,0.000,0.000,4
3755947066.176400,0,0,185.434,0.000,234.399,114.118,0,0,2.000,2.000,0.000,0.000,4
3755947246.176400,0,0,185.815,0.000,234.707,114.303,0,0,2.000,2.000,0.000,0.000,4
3755947426.176400,0,0,186.194,0.000,235.011,114.597,0,0,2.000,2.000,0.000,0.000,4
3755947606.176400,0,0,186.577,0.000,235.314,114.839,0,0,2.000,2.000,0.000,0.000,4
3755947786.176400,0,0,186.962,0.000,235.615,115.186,0,0,2.000,2.000,0.000,0.000,4
3755947966.176400,0,0,187.346,0.000,235.912,115.491,0,0,2.000,2.000,0.000,0.000,4
3755948146.176400,0,0,187.732,0.000,236.207,115.697,0,0,2.000,2.000,0.000,0.000,4
3755948326.176400,0,0,188.118,0.000,236.499,116.063,0,0,2.000,2.000,0.000,0.000,4
3755948506.176400,0,0,188.504,0.000,236.788,116.238,0,0,2.000,2.000,0.000,0.000,4
3755948686.176400,0,0,188.891,0.000,237.075,116.692,0,0,2.000,2.000,0.000,0.000,4
3755948866.176400,0,0,189.278,0.000,237.360,116.963,0,0,2.000,2.000,0.000,0.000,4
3755949046.176400,0,0,189.666,0.000,237.642,117.412,0,0,2.000,2.000,0.000,0.000,4
3755949226.176400,0,0,190.056,0.000,237.924,117.754,0,0,2.000,2.000,0.000,0.000,4
3755949406.176400,0,0,190.445,0.000,238.202,118.153,0,0,2.000,2.000,0.000,0.000,4
3755949586.176400,0,0,190.835,0.000,238.477,118.449,0,0,2.000,2.000,0.000,0.000,4
3755949766.176400,0,0,191.224,0.000,238.750,118.955,0,0,2.000,2.000,0.000,0.000,4
3755949946.176400,0,0,191.615,0.000,239.020,119.273,0,0,2.000,2.000,0.000,0.000,4
3755950126.176400,0,0,192.004,0.000,239.288,119.888,0,0,2.000,2.000,0.000,0.000,4
3755950306.176400,0,0,192.395,0.000,239.555,120.245,0,0,2.000,2.000,0.000,0.000,4
3755950486.176400,0,0,192.785,0.000,239.820,120.649,0,0,2.000,2.000,0.000,0.000,4
3755950666.176400,0,0,193.178,0.000,240.083,121.113,0,0,2.000,2.000,0.000,0.000,4
3755950846.176400,0,0,193.568,0.000,240.343,121.623,0,0,2.000,2.000,0.000,0.000,4
3755951026.176400,0,0,193.958,0.000,240.601,122.100,0,0,2.000,2.000,0.000,0.000,4
3755951206.176400,0,0,194.349,0.000,240.857,122.386,0,0,2.000,2.000,0.000,0.000,4
3755951386.176400,0,0,194.738,0.000,241.111,123.046,0,0,2.000,2.000,0.000,0.000,4
3755951566.176400,0,0,195.129,0.000,241.363,123.417,0,0,2.000,2.000,0.000,0.000,4
3755951746.176400,0,0,195.518,0.000,241.613,123.928,0,0,2.000,2.000,0.000,0.000,4
3755951926.176400,0,0,195.907,0.000,241.861,124.579,0,0,2.000,2.000,0.000,0.000,4
3755952106.176400,0,0,196.295,0.000,242.107,125.114,0,0,2.000,2.000,0.000,0.000,4
3755952286.176400,0,0,196.687,0.000,242.352,125.599,0,0,2.000,2.000,0.000,0.000,4
3755952466.176400,0,0,197.075,0.000,242.595,126.203,0,0,2.000,2.000,0.000,0.000,4
3755952646.176400,0,0,197.460,0.000,242.836,126.926,0,0,2.000,2.000,0.000,0.000,4
3755952826.176400,0,0,197.849,0.000,243.075,127.365,0,0,2.000,2.000,0.000,0.000,4
3755953006.176400,0,0,198.234,0.000,243.311,128.039,0,0,2.000,2.000,0.000,0.000,4
3755953186.176400,0,0,198.619,0.000,243.548,128.626,0,0,2.000,2.000,0.000,0.000,4
3755953366.176400,0,0,199.005,0.000,243.781,129.162,0,0,2.000,2.000,0.000,0.000,4
3755953546.176400,0,0,199.391,0.000,244.013,129.658,0,0,2.000,2.000,0.000,0.000,4
3755953726.176400,0,0,199.778,0.000,244.244,130.259,0,0,2.000,2.000,0.000,0.000,4
3755953906.176400,0,0,200.161,0.000,244.473,130.860,0,0,2.000,2.000,0.000,0.000,4
3755954086.176400,0,0,200.544,0.000,244.699,131.653,0,0,2.000,2.000,0.000,0.000,4
3755954266.176400,0,0,200.925,0.000,244.924,132.262,0,0,2.000,2.000,0.000,0.000,4
3755954446.176400,0,0,201.306,0.000,245.147,133.101,0,0,2.000,2.000,0.000,0.000,4
3755954626.176400,0,0,201.687,0.000,245.370,133.549,0,0,2.000,2.000,0.000,0.000,4
3755954806.176400,0,0,202.066,0.000,245.590,134.016,0,0,2.000,2.000,0.000,0.000,4
3755954986.176400,0,0,202.445,0.000,245.809,134.786,0,0,2.000,2.000,0.000,0.000,4
3755955166.176400,0,0,202.824,0.000,246.028,135.573,0,0,2.000,2.000,0.000,0.000,4
3755955346.176400,0,0,203.199,0.000,246.244,136.069,0,0,2.000,2.000,0.000,0.000,4
3755955526.176400,0,0,203.574,0.000,246.458,137.266,0,0,2.000,2.000,0.000,0.000,4
3755955706.177000,0,0,203.949,0.000,246.671,137.634,0,0,2.000,2.000,0.000,0.000,4
3755955886.177000,0,0,204.324,0.000,246.882,138.552,0,0,2.000,2.000,0.000,0.000,4
3755956066.177000,0,0,204.698,0.000,247.092,138.854,0,0,2.000,2.000,0.000,0.000,4
3755956246.177000,0,0,205.069,0.000,247.300,139.510,0,0,2.000,2.000,0.000,0.000,4
3755956426.177000,0,0,205.439,0.000,247.508,140.130,0,0,2.000,2.000,0.000,0.000,4
3755956606.177000,0,0,205.808,0.000,247.714,141.229,0,0,2.000,2.000,0.000,0.000,4
3755956786.177000,0,0,206.175,0.000,247.918,141.728,0,0,2.000,2.000,0.000,0.000,4
3755956966.177000,0,0,206.543,0.000,248.123,142.404,0,0,2.000,2.000,0.000,0.000,4
3755957146.177000,0,0,206.908,0.000,248.325,143.404,0,0,2.000,2.000,0.000,0.000,4
3755957326.177000,0,0,207.273,0.000,248.525,144.180,0,0,2.000,2.000,0.000,0.000,4
3755957506.177000,0,0,207.636,0.000,248.725,144.808,0,0,2.000,2.000,0.000,0.000,4
3755957686.177000,0,0,207.998,0.000,248.923,145.647,0,0,2.000,2.000,0.000,0.000,4
3755957866.177000,0,0,208.358,0.000,249.119,146.495,0,0,2.000,2.000,0.000,0.000,4
3755958046.177000,0,0,208.716,0.000,249.314,147.133,0,0,2.000,2.000,0.000,0.000,4
3755958226.177000,0,0,209.073,0.000,249.508,147.919,0,0,2.000,2.000,0.000,0.000,4
3755958406.177000,0,0,209.430,0.000,249.701,148.772,0,0,2.000,2.000,0.000,0.000,4
3755958586.177000,0,0,209.787,0.000,249.894,149.460,0,0,2.000,2.000,0.000,0.000,4
3755958766.177000,0,0,210.141,0.000,250.084,150.476,0,0,2.000,2.000,0.000,0.000,4
3755958946.177000,0,0,210.493,0.000,250.274,151.214,0,0,2.000,2.000,0.000,0.000,4
3755959126.177000,0,0,210.846,0.000,250.462,151.667,0,0,2.000,2.000,0.000,0.000,4
3755959306.177000,0,0,211.195,0.000,250.649,152.430,0,0,2.000,2.000,0.000,0.000,4
3755959486.177000,0,0,211.545,0.000,250.835,152.985,0,0,2.000,2.000,0.000,0.000,4
3755959666.177000,0,0,211.891,0.000,251.020,154.251,0,0,2.000,2.000,0.000,0.000,4
3755959846.177000,0,0,212.237,0.000,251.204,155.129,0,0,2.000,2.000,0.000,0.000,4
3755960026.177000,0,0,212.583,0.000,251.387,155.853,0,0,2.000,2.000,0.000,0.000,4
3755960206.177000,0,0,212.930,0.000,251.570,156.648,0,0,2.000,2.000,0.000,0.000,4
3755960386.177000,0,0,213.272,0.000,251.751,158.740,0,0,2.000,2.000,0.000,0.000,4
3755960566.177000,0,0,213.613,0.000,251.930,158.322,0,0,2.000,2.000,0.000,0.000,4
3755960746.177000,0,0,213.954,0.000,252.109,158.542,0,0,2.000,2.000,0.000,0.000,4
3755960926.177000,0,0,214.292,0.000,252.286,160.006,0,0,2.000,2.000,0.000,0.000,4
3755961106.177000,0,0,214.633,0.000,252.463,160.454,0,0,2.000,2.000,0.000,0.000,4
3755961286.177000,0,0,214.970,0.000,252.638,161.432,0,0,2.000,2.000,0.000,0.000,4
3755961466.177000,0,0,215.307,0.000,252.812,162.139,0,0,2.000,2.000,0.000,0.000,4
3755961646.177000,0,0,215.645,0.000,252.987,162.814,0,0,2.000,2.000,0.000,0.000,4
3755961826.177000,0,0,215.980,0.000,253.159,163.392,0,0,2.000,2.000,0.000,0.000,4
3755962006.177000,0,0,216.314,0.000,253.330,164.266,0,0,2.000,2.000,0.000,0.000,4
3755962186.177000,0,0,216.647,0.000,253.501,165.029,0,0,2.000,2.000,0.000,0.000,4
3755962366.177000,0,0,216.978,0.000,253.670,166.277,0,0,2.000,2.000,0.000,0.000,4
3755962546.177000,0,0,217.308,0.000,253.838,167.400,0,0,2.000,2.000,0.000,0.000,4
3755962726.177000,0,0,217.639,0.000,254.006,167.721,0,0,2.000,2.000,0.000,0.000,4
3755962906.177000,0,0,217.968,0.000,254.172,168.743,0,0,2.000,2.000,0.000,0.000,4
3755963086.177000,0,0,218.296,0.000,254.338,169.211,0,0,2.000,2.000,0.000,0.000,4
3755963266.177000,0,0,218.624,0.000,254.504,170.195,0,0,2.000,2.000,0.000,0.000,4
3755963446.177000,0,0,218.950,0.000,254.667,170.838,0,0,2.000,2.000,0.000,0.000,4
3755963626.177000,0,0,219.275,0.000,254.830,171.505,0,0,2.000,2.000,0.000,0.000,4
3755963806.177000,0,0,219.598,0.000,254.992,172.959,0,0,2.000,2.000,0.000,0.000,4
3755963986.177000,0,0,219.922,0.000,255.153,173.928,0,0,2.000,2.000,0.000,0.000,4
3755964166.177000,0,0,220.244,0.000,255.313,174.812,0,0,2.000,2.000,0.000,0.000,4
3755964346.177000,0,0,220.565,0.000,255.473,175.942,0,0,2.000,2.000,0.000,0.000,4
3755964526.177000,0,0,220.885,0.000,255.632,176.444,0,0,2.000,2.000,0.000,0.000,4
3755964706.177000,0,0,221.204,0.000,255.790,177.058,0,0,2.000,2.000,0.000,0.000,4
3755964886.177000,0,0,221.525,0.000,255.948,178.573,0,0,2.000,2.000,0.000,0.000,4
3755965066.177000,0,0,221.843,0.000,256.104,178.261,0,0,2.000,2.000,0.000,0.000,4
3755965246.177000,0,0,222.159,0.000,256.259,179.629,0,0,2.000,2.000,0.000,0.000,4
3755965426.177000,0,0,222.475,0.000,256.415,179.979,0,0,2.000,2.000,0.000,0.000,4
3755965606.177000,0,0,222.790,0.000,256.569,180.675,0,0,2.000,2.000,0.000,0.000,4
3755965786.177000,0,0,223.102,0.000,256.722,181.750,0,0,2.000,2.000,0.000,0.000,4
3755965966.177000,0,0,223.412,0.000,256.875,182.960,0,0,2.000,2.000,0.000,0.000,4
3755966146.177000,0,0,223.703,0.000,257.027,183.452,0,0,2.000,2.000,0.000,0.000,4
3755966326.177000,0,0,223.977,0.000,257.177,185.034,0,0,2.000,2.000,0.000,0.000,4
3755966506.177000,0,0,224.257,0.000,257.328,185.208,0,0,2.000,2.000,0.000,0.000,4
3755966686.177000,0,0,224.543,0.000,257.479,186.185,0,0,2.000,2.000,0.000,0.000,4
3755966866.177000,0,0,224.831,0.000,257.628,186.656,0,0,2.000,2.000,0.000,0.000,4
3755967046.177000,0,0,225.120,0.000,257.776,188.152,0,0,2.000,2.000,0.000,0.000,4
3755967226.177000,0,0,225.411,0.000,257.925,188.050,0,0,2.000,2.000,0.000,0.000,4
3755967406.177000,0,0,225.702,0.000,258.072,189.243,0,0,2.000,2.000,0.000,0.000,4
3755967586.177000,0,0,225.995,0.000,258.219,189.478,0,0,2.000,2.000,0.000,0.000,4
3755967766.177000,0,0,226.286,0.000,258.364,190.796,0,0,2.000,2.000,0.000,0.000,4
3755967946.177000,0,0,226.578,0.000,258.510,191.444,0,0,2.000,2.000,0.000,0.000,4
3755968126.177000,0,0,226.871,0.000,258.654,192.246,0,0,2.000,2.000,0.000,0.000,4
3755968306.177000,0,0,227.161,0.000,258.798,192.764,0,0,2.000,2.000,0.000,0.000,4
3755968486.177000,0,0,227.452,0.000,258.942,193.718,0,0,2.000,2.000,0.000,0.000,4
3755968666.177000,0,0,227.740,0.000,259.085,194.551,0,0,2.000,2.000,0.000,0.000,4
3755968846.177000,0,0,228.028,0.000,259.228,195.461,0,0,2.000,2.000,0.000,0.000,4
3755969026.177000,0,0,228.314,0.000,259.369,196.016,0,0,2.000,2.000,0.000,0.000,4
3755969206.177000,0,0,228.601,0.000,259.509,197.310,0,0,2.000,2.000,0.000,0.000,4
3755969386.177000,0,0,228.887,0.000,259.650,197.576,0,0,2.000,2.000,0.000,0.000,4
3755969566.177000,0,0,229.173,0.000,259.789,198.219,0,0,2.000,2.000,0.000,0.000,4
3755969746.177000,0,0,229.457,0.000,259.929,198.543,0,0,2.000,2.000,0.000,0.000,4
3755969926.177000,0,0,229.740,0.000,260.068,200.302,0,0,2.000,2.000,0.000,0.000,4
3755970106.177000,0,0,230.023,0.000,260.206,200.587,0,0,2.000,2.000,0.000,0.000,4
3755970286.177000,0,0,230.305,0.000,260.345,201.467,0,0,2.000,2.000,0.000,0.000,4
3755970466.177000,0,0,230.587,0.000,260.481,202.439,0,0,2.000,2.000,0.000,0.000,4
3755970646.177000,0,0,230.867,0.000,260.618,202.627,0,0,2.000,2.000,0.000,0.000,4
3755970826.177000,0,0,231.146,0.000,260.754,203.723,0,0,2.000,2.000,0.000,0.000,4
3755971006.177000,0,0,231.425,0.000,260.890,204.287,0,0,2.000,2.000,0.000,0.000,4
3755971186.177000,0,0,231.699,0.000,261.025,205.185,0,0,2.000,2.000,0.000,0.000,4
3755971366.177000,0,0,231.976,0.000,261.160,206.020,0,0,2.000,2.000,0.000,0.000,4
3755971546.177000,0,0,232.250,0.000,261.294,207.201,0,0,2.000,2.000,0.000,0.000,4
3755971726.177000,0,0,232.526,0.000,261.428,207.423,0,0,2.000,2.000,0.000,0.000,4
3755971906.177000,0,0,232.800,0.000,261.560,207.945,0,0,2.000,2.000,0.000,0.000,4
3755972086.177000,0,0,233.074,0.000,261.694,209.544,0,0,2.000,2.000,0.000,0.000,4
3755972266.177000,0,0,233.345,0.000,261.827,209.340,0,0,2.000,2.000,0.000,0.000,4
3755972446.177000,0,0,233.614,0.000,261.958,210.790,0,0,2.000,2.000,0.000,0.000,4
3755972626.177000,0,0,233.883,0.000,262.091,210.526,0,0,2.000,2.000,0.000,0.000,4
3755972806.177000,0,0,234.151,0.000,262.221,211.658,0,0,2.000,2.000,0.000,0.000,4
3755972986.177000,0,0,234.417,0.000,262.352,212.741,0,0,2.000,2.000,0.000,0.000,4
3755973166.177000,0,0,234.682,0.000,262.482,213.372,0,0,2.000,2.000,0.000,0.000,4
3755973346.177000,0,0,234.948,0.000,262.611,213.927,0,0,2.000,2.000,0.000,0.000,4
3755973526.177000,0,0,235.212,0.000,262.740,214.204,0,0,2.000,2.000,0.000,0.000,4
3755973706.177000,0,0,235.472,0.000,262.870,215.554,0,0,2.000,2.000,0.000,0.000,4
3755973886.177000,0,0,235.735,0.000,262.998,215.436,0,0,2.000,2.000,0.000,0.000,4
3755974066.177000,0,0,235.995,0.000,263.127,216.542,0,0,2.000,2.000,0.000,0.000,4
3755974246.177000,0,0,236.254,0.000,263.254,217.358,0,0,2.000,2.000,0.000,0.000,4
3755974426.177000,0,0,236.511,0.000,263.380,218.495,0,0,2.000,2.000,0.000,0.000,4
3755974606.177000,0,0,236.768,0.000,263.507,219.320,0,0,2.000,2.000,0.000,0.000,4
3755974786.177000,0,0,237.024,0.000,263.633,219.772,0,0,2.000,2.000,0.000,0.000,4
3755974966.177000,0,0,237.281,0.000,263.759,219.808,0,0,2.000,2.000,0.000,0.000,4
3755975146.177000,0,0,237.532,0.000,263.885,221.041,0,0,2.000,2.000,0.000,0.000,4
3755975326.177000,0,0,237.786,0.000,264.009,221.384,0,0,2.000,2.000,0.000,0.000,4
3755975506.177000,0,0,238.038,0.000,264.135,221.657,0,0,2.000,2.000,0.000,0.000,4
3755975686.177000,0,0,238.290,0.000,264.260,223.094,0,0,2.000,2.000,0.000,0.000,4
3755975866.177000,0,0,238.540,0.000,264.384,223.252,0,0,2.000,2.000,0.000,0.000,4
3755976046.177000,0,0,238.788,0.000,264.509,223.665,0,0,2.000,2.000,0.000,0.000,4
3755976226.177000,0,0,239.035,0.000,264.632,224.462,0,0,2.000,2.000,0.000,0.000,4
3755976406.177000,0,0,239.282,0.000,264.756,224.863,0,0,2.000,2.000,0.000,0.000,4
3755976586.177000,0,0,239.528,0.000,264.879,225.480,0,0,2.000,2.000,0.000,0.000,4
3755976766.177000,0,0,239.772,0.000,265.001,226.758,0,0,2.000,2.000,0.000,0.000,4
3755976946.177000,0,0,240.017,0.000,265.123,226.564,0,0,2.000,2.000,0.000,0.000,4
3755977126.177000,0,0,240.258,0.000,265.245,228.007,0,0,2.000,2.000,0.000,0.000,4
3755977306.177000,0,0,240.500,0.000,265.366,228.358,0,0,2.000,2.000,0.000,0.000,4
3755977486.177000,0,0,240.741,0.000,265.488,228.633,0,0,2.000,2.000,0.000,0.000,4
3755977666.177000,0,0,240.981,0.000,265.609,229.761,0,0,2.000,2.000,0.000,0.000,4
3755977846.177000,0,0,241.220,0.000,265.728,230.695,0,0,2.000,2.000,0.000,0.000,4
3755978026.177000,0,0,241.457,0.000,265.847,230.333,0,0,2.000,2.000,0.000,0.000,4
3755978206.177000,0,0,241.694,0.000,265.966,231.096,0,0,2.000,2.000,0.000,0.000,4
3755978386.177000,0,0,241.929,0.000,266.084,232.114,0,0,2.000,2.000,0.000,0.000,4
3755978566.177000,0,0,242.163,0.000,266.202,234.208,0,0,2.000,2.000,0.000,0.000,4
3755978746.177000,0,0,242.394,0.000,266.320,232.819,0,0,2.000,2.000,0.000,0.000,4
3755978926.177000,0,0,242.626,0.000,266.436,233.524,0,0,2.000,2.000,0.000,0.000,4
3755979106.177000,0,0,242.859,0.000,266.552,233.925,0,0,2.000,2.000,0.000,0.000,4
3755979286.177000,0,0,243.090,0.000,266.668,234.003,0,0,2.000,2.000,0.000,0.000,4
3755979466.177000,0,0,243.320,0.000,266.784,235.913,0,0,2.000,2.000,0.000,0.000,4
3755979646.177000,0,0,243.551,0.000,266.899,235.031,0,0,2.000,2.000,0.000,0.000,4
3755979826.177000,0,0,243.781,0.000,267.013,236.183,0,0,2.000,2.000,0.000,0.000,4
3755980006.177000,0,0,244.010,0.000,267.127,236.922,0,0,2.000,2.000,0.000,0.000,4
3755980186.177000,0,0,244.238,0.000,267.241,237.284,0,0,2.000,2.000,0.000,0.000,4
3755980366.177000,0,0,244.466,0.000,267.353,238.536,0,0,2.000,2.000,0.000,0.000,4
3755980546.177000,0,0,244.693,0.000,267.466,239.101,0,0,2.000,2.000,0.000,0.000,4
3755980726.177000,0,0,244.919,0.000,267.578,239.018,0,0,2.000,2.000,0.000,0.000,4
3755980906.177000,0,0,245.144,0.000,267.690,239.859,0,0,2.000,2.000,0.000,0.000,4
3755981086.177000,0,0,245.370,0.000,267.801,240.617,0,0,2.000,2.000,0.000,0.000,4
3755981266.177000,0,0,245.596,0.000,267.912,241.435,0,0,2.000,2.000,0.000,0.000,4
3755981446.177000,0,0,245.819,0.000,268.023,240.885,0,0,2.000,2.000,0.000,0.000,4
3755981626.177000,0,0,246.043,0.000,268.134,242.578,0,0,2.000,2.000,0.000,0.000,4
3755981806.177000,0,0,246.265,0.000,268.243,242.544,0,0,2.000,2.000,0.000,0.000,4
3755981986.177000,0,0,246.487,0.000,268.352,243.419,0,0,2.000,2.000,0.000,0.000,4
3755982166.177000,0,0,246.709,0.000,268.461,244.066,0,0,2.000,2.000,0.000,0.000,4
3755982346.177000,0,0,246.930,0.000,268.570,244.113,0,0,2.000,2.000,0.000,0.000,4
3755982526.177000,0,0,247.149,0.000,268.678,245.280,0,0,2.000,2.000,0.000,0.000,4
3755982706.177000,0,0,247.368,0.000,268.786,246.072,0,0,2.000,2.000,0.000,0.000,4
3755982886.177000,0,0,247.587,0.000,268.894,246.194,0,0,2.000,2.000,0.000,0.000,4
3755983066.177000,0,0,247.805,0.000,269.002,246.629,0,0,2.000,2.000,0.000,0.000,4
3755983246.177000,0,0,248.024,0.000,269.109,246.840,0,0,2.000,2.000,0.000,0.000,4
3755983426.177000,0,0,248.240,0.000,269.216,248.517,0,0,2.000,2.000,0.000,0.000,4
3755983606.177000,0,0,248.455,0.000,269.322,247.957,0,0,2.000,2.000,0.000,0.000,4
3755983786.177000,0,0,248.670,0.000,269.428,249.665,0,0,2.000,2.000,0.000,0.000,4
3755983966.177000,0,0,248.885,0.000,269.533,248.842,0,0,2.000,2.000,0.000,0.000,4
3755984146.177000,0,0,249.098,0.000,269.639,249.306,0,0,2.000,2.000,0.000,0.000,4
3755984326.177000,0,0,249.308,0.000,269.743,250.274,0,0,2.000,2.000,0.000,0.000,4
3755984506.177000,0,0,249.519,0.000,269.848,251.362,0,0,2.000,2.000,0.000,0.000,4
3755984686.177000,0,0,249.728,0.000,269.953,250.561,0,0,2.000,2.000,0.000,0.000,4
3755984866.177000,0,0,249.939,0.000,270.057,252.318,0,0,2.000,2.000,0.000,0.000,4
3755985046.177000,0,0,250.147,0.000,270.160,252.964,0,0,2.000,2.000,0.000,0.000,4
3755985226.177000,0,0,250.353,0.000,270.263,253.503,0,0,2.000,2.000,0.000,0.000,4
3755985406.177000,0,0,250.559,0.000,270.365,253.612,0,0,2.000,2.000,0.000,0.000,4
3755985586.177000,0,0,250.764,0.000,270.467,253.615,0,0,2.000,2.000,0.000,0.000,4
3755985766.177000,0,0,250.966,0.000,270.567,254.074,0,0,2.000,2.000,0.000,0.000,4
3755985946.177000,0,0,251.167,0.000,270.667,255.214,0,0,2.000,2.000,0.000,0.000,4
3755986126.177000,0,0,251.368,0.000,270.767,254.766,0,0,2.000,2.000,0.000,0.000,4
3755986306.177000,0,0,251.567,0.000,270.865,256.308,0,0,2.000,2.000,0.000,0.000,4
3755986486.177000,0,0,251.765,0.000,270.964,256.786,0,0,2.000,2.000,0.000,0.000,4
3755986666.177000,0,0,251.965,0.000,271.063,256.192,0,0,2.000,2.000,0.000,0.000,4
3755986846.177000,0,0,252.161,0.000,271.160,257.111,0,0,2.000,2.000,0.000,0.000,4
3755987026.177000,0,0,252.355,0.000,271.257,257.785,0,0,2.000,2.000,0.000,0.000,4
3755987206.177000,0,0,252.549,0.000,271.354,258.480,0,0,2.000,2.000,0.000,0.000,4
3755987386.177000,0,0,252.741,0.000,271.451,258.723,0,0,2.000,2.000,0.000,0.000,4
3755987566.177000,0,0,252.930,0.000,271.546,259.824,0,0,2.000,2.000,0.000,0.000,4
3755987746.177000,0,0,253.121,0.000,271.642,258.954,0,0,2.000,2.000,0.000,0.000,4
3755987926.177000,0,0,253.310,0.000,271.736,259.949,0,0,2.000,2.000,0.000,0.000,4
3755988106.177000,0,0,253.496,0.000,271.831,261.247,0,0,2.000,2.000,0.000,0.000,4
3755988286.177000,0,0,253.682,0.000,271.926,261.437,0,0,2.000,2.000,0.000,0.000,4
3755988466.177000,0,0,253.867,0.000,272.019,261.243,0,0,2.000,2.000,0.000,0.000,4
3755988646.177000,0,0,254.050,0.000,272.113,262.159,0,0,2.000,2.000,0.000,0.000,4
3755988826.177000,0,0,254.232,0.000,272.206,262.870,0,0,2.000,2.000,0.000,0.000,4
3755989006.177000,0,0,254.413,0.000,272.299,262.969,0,0,2.000,2.000,0.000,0.000,4
3755989186.177000,0,0,254.591,0.000,272.392,263.399,0,0,2.000,2.000,0.000,0.000,4
3755989366.177000,0,0,254.770,0.000,272.484,263.451,0,0,2.000,2.000,0.000,0.000,4
3755989546.177000,0,0,254.946,0.000,272.575,263.750,0,0,2.000,2.000,0.000,0.000,4
3755989726.177000,0,0,255.121,0.000,272.666,264.356,0,0,2.000,2.000,0.000,0.000,4
3755989906.177000,0,0,255.296,0.000,272.756,265.767,0,0,2.000,2.000,0.000,0.000,4
3755990086.177000,0,0,255.469,0.000,272.846,266.379,0,0,2.000,2.000,0.000,0.000,4
3755990266.177000,0,0,255.640,0.000,272.936,266.339,0,0,2.000,2.000,0.000,0.000,4
3755990446.177000,0,0,255.810,0.000,273.026,267.209,0,0,2.000,2.000,0.000,0.000,4
3755990626.177000,0,0,255.994,0.000,273.115,266.869,0,0,2.000,2.000,0.000,0.000,4
3755990806.177000,0,0,256.204,0.000,273.204,267.819,0,0,2.000,2.000,0.000,0.000,4
3755990986.177000,0,0,256.469,0.000,273.293,267.527,0,0,2.000,2.000,0.000,0.000,4
3755991166.177000,0,0,256.726,0.000,273.380,269.048,0,0,2.000,2.000,0.000,0.000,4
3755991346.177000,0,0,256.968,0.000,273.468,268.709,0,0,2.000,2.000,0.000,0.000,4
3755991526.177000,0,0,257.195,0.000,273.555,269.457,0,0,2.000,2.000,0.000,0.000,4
3755991706.177000,0,0,257.414,0.000,273.642,268.973,0,0,2.000,2.000,0.000,0.000,4
3755991886.177000,0,0,257.623,0.000,273.728,270.215,0,0,2.000,2.000,0.000,0.000,4
3755992066.177000,0,0,257.824,0.000,273.815,270.960,0,0,2.000,2.000,0.000,0.000,4
3755992246.177000,0,0,258.023,0.000,273.901,270.689,0,0,2.000,2.000,0.000,0.000,4
3755992426.177000,0,0,258.218,0.000,273.986,271.398,0,0,2.000,2.000,0.000,0.000,4
3755992606.177000,0,0,258.408,0.000,274.071,271.626,0,0,2.000,2.000,0.000,0.000,4
3755992786.177000,0,0,258.598,0.000,274.156,271.519,0,0,2.000,2.000,0.000,0.000,4
3755992966.177000,0,0,258.783,0.000,274.239,272.382,0,0,2.000,2.000,0.000,0.000,4
3755993146.177000,0,0,258.966,0.000,274.324,273.347,0,0,2.000,2.000,0.000,0.000,4
3755993326.177000,0,0,259.149,0.000,274.407,273.382,0,0,2.000,2.000,0.000,0.000,4
3755993506.177000,0,0,259.331,0.000,274.491,272.528,0,0,2.000,2.000,0.000,0.000,4
3755993686.177000,0,0,259.510,0.000,274.574,273.632,0,0,2.000,2.000,0.000,0.000,4
3755993716.177000,0,0,259.539,0.000,274.588,274.686,0,0,2.000,2.000,0.000,0.000,4