File: log/20231212.dat
[Header]
; Displex Transport Data File (default extension .dat)
; Copyright 2016, Hechang LEI, hlei@ruc.edu.cn. All rights reserved.
BYAPP, Displex, 2.0
INFO, 9T mag, Release 2.0.
INFO, Channel 1, Temperature Sensor
INFO, Sample 1 Length (cm): 0.000000; Width (cm): 0.000000; Thickness (cm): 0.000000.

[Data]
Timestamp(s),Field(Oe),Field Status,TempA(K),TempB(K),TempC(K),TempD(K),Ramp1,Ramp2,Setpoint1,Setpoint2,Output1(%),Output2(%),Temp Status,in plane position,out plane position
3785189973.450000,0,1,2.127,1.999,36.051,3.091,0,0,2.000,2.000,0.000,0.110,1,145.151041,-21.979648
3785190093.450000,0,1,2.129,2.000,36.064,3.089,0,0,2.000,2.000,0.000,0.100,1,136.962461,-21.979648
3785190213.450000,0,1,2.134,2.000,36.074,3.086,0,0,2.000,2.000,0.000,0.100,1,124.645969,-21.979648
3785190333.450000,0,1,2.133,2.000,36.081,3.085,0,0,2.000,2.000,0.000,0.100,1,111.372967,-21.979648
3785190453.450000,0,1,2.134,2.000,36.090,3.085,0,0,2.000,2.000,0.000,0.100,1,99.365199,-21.979648
3785190573.450000,0,1,2.118,2.000,36.094,3.081,0,0,2.000,2.000,0.000,0.100,1,90.067494,-21.979648
3785190693.450000,0,1,2.134,2.000,36.099,3.080,0,0,2.000,2.000,0.140,0.100,1,80.951399,-21.979648
3785190813.450000,0,1,2.123,2.000,36.098,3.077,0,0,2.000,2.000,0.000,0.100,1,71.695573,-21.979648
3785190933.450000,0,1,2.137,2.000,36.098,3.077,0,0,2.000,2.000,0.000,0.100,1,63.213571,-21.979648
3785191053.450000,0,1,2.137,2.000,36.094,3.076,0,0,2.000,2.000,0.160,0.100,1,55.412643,-21.979648
3785191173.450000,0,1,2.136,2.000,36.095,3.074,0,0,2.000,2.000,0.150,0.100,1,47.778291,-21.979648
3785191293.450000,0,1,2.129,2.000,36.091,3.073,0,0,2.000,2.000,0.110,0.100,1,40.774542,-21.979648
3785191413.450000,0,1,2.142,2.000,36.090,3.073,0,0,2.000,2.000,0.130,0.110,1,33.296432,-21.979648
3785191533.450000,0,1,2.143,2.000,36.088,3.071,0,0,2.000,2.000,0.000,0.110,1,25.478188,-21.979648
3785191653.450000,0,1,2.138,2.000,36.086,3.069,0,0,2.000,2.000,0.000,0.110,1,17.394709,-21.979648
3785191773.450000,0,1,2.124,2.000,36.080,3.070,0,0,2.000,2.000,0.020,0.100,1,8.975258,-21.979648
3785191893.450000,0,1,2.137,2.000,36.078,3.066,0,0,2.000,2.000,0.160,0.110,1,0.236881,-21.979648
3785192013.450000,0,1,2.135,2.000,36.071,3.066,0,0,2.000,2.000,0.000,0.110,1,-8.562301,-21.979648
3785192133.450000,0,1,2.141,2.000,36.064,3.065,0,0,2.000,2.000,0.160,0.110,1,-17.168061,-21.979648
3785192253.450000,0,1,2.140,2.000,36.062,3.065,0,0,2.000,2.000,0.000,0.110,1,-25.714358,-21.979648
3785192373.450000,0,1,2.144,2.000,36.059,3.064,0,0,2.000,2.000,0.160,0.110,1,-34.988305,-21.979648
3785192493.450000,0,1,2.135,2.000,36.057,3.063,0,0,2.000,2.000,0.000,0.110,1,-44.241983,-21.979648
3785192613.450000,0,1,2.148,2.000,36.054,3.063,0,0,2.000,2.000,0.040,0.110,1,-54.318882,-21.979648
3785192733.450000,0,1,2.130,2.000,36.052,3.062,0,0,2.000,2.000,0.110,0.110,1,-64.825578,-21.979648
3785192853.450000,0,1,2.139,2.000,36.045,3.061,0,0,2.000,2.000,0.000,0.110,1,-74.002881,-21.979648
3785192973.450000,0,1,2.148,2.000,36.042,3.061,0,0,2.000,2.000,0.000,0.110,1,-82.486493,-21.979648
3785193093.450000,0,1,2.131,2.000,36.033,3.059,0,0,2.000,2.000,0.100,0.110,1,-90.971582,-21.979648
3785193213.450000,0,1,2.126,2.000,36.030,3.060,0,0,2.000,2.000,0.000,0.110,1,-99.214523,-21.979648
3785193356.785000,0,1,2.134,2.000,36.024,3.059,0,0,2.000,2.000,0.000,0.120,1,-99.934522,-21.979648
3785193476.785000,3084,2,2.131,2.000,36.026,3.173,0,0,2.000,2.000,0.000,0.120,1,-99.933583,-21.979648
3785193596.785000,9011,2,2.129,2.001,36.017,3.598,0,0,2.000,2.000,0.000,0.120,1,-99.933449,-21.979648
3785193716.785000,14975,2,2.148,2.000,36.025,3.526,0,0,2.000,2.000,0.000,0.120,1,-99.935193,-21.979648
3785193836.785000,20996,2,2.133,2.000,36.029,3.458,0,0,2.000,2.000,0.000,0.120,1,-99.933449,-21.979648
3785193956.785000,26967,2,2.150,2.000,36.037,3.417,0,0,2.000,2.000,0.040,0.120,1,-99.927140,-21.979648
3785194076.785000,33020,2,2.130,2.000,36.044,3.385,0,0,2.000,2.000,0.000,0.120,1,-99.912375,-21.979648
3785194196.785000,38996,2,2.146,2.000,36.061,3.360,0,0,2.000,2.000,0.000,0.120,1,-99.913985,-21.979648
3785194316.785000,44974,2,2.142,2.000,36.078,3.341,0,0,2.000,2.000,0.180,0.120,1,-99.907945,-21.979648
3785194436.785000,51010,2,2.140,2.000,36.106,3.324,0,0,2.000,2.000,0.000,0.120,1,-99.897341,-21.979648
3785194556.785000,56997,2,2.149,2.000,36.136,3.308,0,0,2.000,2.000,0.090,0.120,1,-99.895865,-21.979648
3785194676.785000,63060,2,2.130,2.000,36.174,3.295,0,0,2.000,2.000,0.000,0.120,1,-99.889690,-21.979648
3785194796.785000,69038,2,2.147,1.999,36.213,3.283,0,0,2.000,2.000,0.000,0.120,1,-99.879086,-21.979648
3785194916.785000,75016,2,2.124,2.000,36.266,3.270,0,0,2.000,2.000,0.010,0.120,1,-99.879757,-21.979648
3785195036.785000,81050,2,2.141,1.999,36.326,3.259,0,0,2.000,2.000,0.160,0.120,1,-99.875999,-21.979648
3785195156.785000,87026,2,2.131,2.000,36.403,3.248,0,0,2.000,2.000,0.000,0.110,1,-99.877341,-21.979648
3785195276.785000,90000,1,2.131,1.999,36.491,3.104,0,0,2.000,2.000,0.000,0.110,1,-100.005261,-21.979648
3785195396.785000,90000,1,2.144,2.000,36.631,3.076,0,0,2.000,2.000,0.050,0.120,1,-97.008755,-21.979648
3785195579.174000,90000,1,2.146,2.000,36.678,3.074,0,0,2.000,2.000,0.000,0.120,1,-96.011978,-21.979648
3785195690.296000,90000,1,2.128,2.000,36.727,3.074,0,0,2.000,2.000,0.000,0.120,1,-94.667684,-21.979648
3785195810.296000,86492,4,2.139,2.000,36.769,3.195,0,0,2.000,2.000,0.150,0.100,1,-93.628759,-21.979648
3785195905.212000,81766,4,2.138,2.000,36.786,3.242,0,0,2.000,2.000,0.000,0.100,1,-95.199495,-21.979648
3785196003.357000,76827,4,2.146,2.000,36.779,3.258,0,0,2.000,2.000,0.080,0.120,1,-95.742716,-21.979648
3785196123.357000,70843,4,2.125,2.000,36.753,3.272,0,0,2.000,2.000,0.050,0.120,1,-95.741911,-21.979648
3785196243.357000,64810,4,2.141,2.000,36.709,3.285,0,0,2.000,2.000,0.000,0.120,1,-95.742716,-21.979648
3785196363.357000,58811,4,2.149,2.000,36.658,3.298,0,0,2.000,2.000,0.020,0.120,1,-95.756139,-21.979648
3785196483.357000,52776,4,2.127,2.000,36.600,3.310,0,0,2.000,2.000,0.020,0.120,1,-95.760837,-21.979648
3785196603.357000,45380,4,2.133,2.000,36.547,3.441,0,0,2.000,2.000,0.000,0.120,1,-95.764864,-21.979648
3785196723.357000,35819,4,2.140,2.000,36.485,3.513,0,0,2.000,2.000,0.000,0.120,1,-95.772649,-21.979648
3785196843.357000,26176,4,2.151,2.000,36.425,3.568,0,0,2.000,2.000,0.120,0.120,1,-95.793320,-21.979648
3785196963.357000,16581,4,2.145,2.000,36.364,3.637,0,0,2.000,2.000,0.170,0.120,1,-95.799495,-21.979648
3785197083.357000,6947,4,2.128,2.000,36.313,3.752,0,0,2.000,2.000,0.000,0.120,1,-95.798287,-21.979648
3785197203.357000,0,4,2.146,2.000,36.269,3.504,0,0,2.000,2.000,0.000,0.120,1,-95.792783,-21.979648
3785197323.357000,0,1,4.927,4.884,36.243,3.063,1,1,12.000,12.000,0.160,0.680,2,-96.568889,-21.979648
3785197443.357000,0,1,8.848,8.838,36.154,3.067,1,1,12.000,12.000,0.200,1.340,2,-96.818285,-21.979648
3785197563.357000,0,1,12.001,12.005,35.929,3.091,0,0,12.000,12.000,0.290,1.980,1,-96.917211,-21.979648
3785197683.357000,5531,2,12.000,11.996,35.715,3.385,0,0,12.000,12.000,0.180,1.100,1,-96.920433,-21.979648
3785197803.357000,11508,2,12.000,11.998,35.717,3.615,0,0,12.000,12.000,0.170,1.020,1,-96.923386,-21.979648
3785197923.357000,17526,2,12.000,12.003,35.752,3.531,0,0,12.000,12.000,0.170,1.000,1,-96.927278,-21.979648
3785198043.357000,23495,2,12.000,12.003,35.789,3.478,0,0,12.000,12.000,0.170,0.980,1,-96.930097,-21.979648
3785198163.357000,29466,2,12.000,11.997,35.825,3.440,0,0,12.000,12.000,0.170,1.000,1,-96.932647,-21.979648
3785198283.357000,35492,2,11.999,11.998,35.862,3.414,0,0,12.000,12.000,0.170,0.980,1,-96.935198,-21.979648
3785198403.357000,41493,2,12.000,11.999,35.903,3.391,0,0,12.000,12.000,0.170,0.970,1,-96.934929,-21.979648
3785198523.357000,47526,2,12.000,11.996,35.946,3.375,0,0,12.000,12.000,0.160,0.980,1,-96.939359,-21.979648
3785198643.357000,53510,2,12.000,11.998,35.993,3.357,0,0,12.000,12.000,0.160,0.970,1,-96.943520,-21.979648
3785198763.357000,59493,2,12.000,12.000,36.041,3.345,0,0,12.000,12.000,0.160,0.950,1,-96.946070,-21.979648
3785198883.357000,65529,2,12.000,11.999,36.097,3.331,0,0,12.000,12.000,0.160,0.960,1,-96.950500,-21.979648
3785199003.357000,71530,2,12.000,11.998,36.154,3.319,0,0,12.000,12.000,0.160,0.960,1,-96.953453,-21.979648
3785199123.357000,77509,2,12.000,11.997,36.226,3.307,0,0,12.000,12.000,0.160,0.960,1,-96.953587,-21.979648
3785199243.357000,83544,2,12.000,11.996,36.304,3.297,0,0,12.000,12.000,0.160,0.960,1,-96.958553,-21.979648
3785199363.357000,89517,2,12.000,11.998,36.397,3.286,0,0,12.000,12.000,0.160,0.960,1,-96.963654,-21.979648
3785199483.357000,90000,1,12.000,11.999,36.499,3.127,0,0,12.000,12.000,0.160,0.950,1,-99.638952,-21.979648
3785199603.357000,90000,1,12.000,11.999,36.588,3.121,0,0,12.000,12.000,0.160,0.960,1,-97.041640,-21.979648
3785199723.357000,90000,1,11.999,12.003,36.658,3.122,0,0,12.000,12.000,0.160,0.930,1,-94.299899,-21.979648
3785199843.357000,90000,1,12.000,12.004,36.719,3.121,0,0,12.000,12.000,0.160,0.920,1,-92.058292,-21.979648
3785199963.357000,90000,1,12.000,12.007,36.764,3.121,0,0,12.000,12.000,0.160,0.910,1,-90.184066,-21.979648
3785200083.357000,90000,1,12.000,11.997,36.805,3.122,0,0,12.000,12.000,0.160,0.960,1,-89.003665,-21.979648
3785200203.357000,90000,1,12.000,11.999,36.840,3.121,0,0,12.000,12.000,0.160,0.940,1,-86.022998,-21.979648
3785200323.357000,90000,1,12.000,11.992,36.878,3.122,0,0,12.000,12.000,0.160,0.950,1,-84.033739,-21.979648
3785200443.357000,90000,1,12.000,11.995,36.908,3.121,0,0,12.000,12.000,0.160,0.970,1,-82.002064,-21.979648
3785200563.357000,90000,1,11.999,11.994,36.939,3.122,0,0,12.000,12.000,0.160,0.960,1,-79.008243,-21.979648
3785200683.357000,90000,1,12.000,12.005,36.962,3.122,0,0,12.000,12.000,0.160,0.950,1,-75.721805,-21.979648
3785200803.357000,90000,1,12.000,12.009,36.985,3.123,0,0,12.000,12.000,0.160,0.920,1,-72.023018,-21.979648
3785200923.357000,90000,1,12.000,11.995,37.000,3.122,0,0,12.000,12.000,0.160,0.970,1,-69.046646,-21.979648
3785201043.357000,90000,1,12.000,12.003,37.018,3.124,0,0,12.000,12.000,0.160,0.920,1,-65.967858,-21.979648
3785201163.357000,90000,1,12.000,12.004,37.034,3.123,0,0,12.000,12.000,0.160,0.940,1,-62.241823,-21.979648
3785201283.357000,90000,1,12.000,12.000,37.051,3.123,0,0,12.000,12.000,0.160,0.960,1,-60.070954,-21.979648
3785201403.357000,90000,1,12.000,11.994,37.066,3.123,0,0,12.000,12.000,0.160,0.950,1,-58.012433,-21.979648
3785201523.357000,90000,1,12.001,12.008,37.082,3.124,0,0,12.000,12.000,0.160,0.920,1,-54.108815,-21.979648
3785201643.357000,90000,1,12.000,12.002,37.096,3.124,0,0,12.000,12.000,0.160,0.950,1,-52.089623,-21.979648
3785201763.357000,90000,1,12.000,12.003,37.111,3.124,0,0,12.000,12.000,0.160,0.940,1,-50.413518,-21.979648
3785201883.357000,90000,1,12.000,11.999,37.121,3.124,0,0,12.000,12.000,0.160,0.950,1,-47.042650,-21.979648
3785202003.357000,90000,1,12.000,11.998,37.129,3.123,0,0,12.000,12.000,0.160,0.940,1,-44.030171,-21.979648
3785202123.357000,90000,1,12.000,12.001,37.138,3.124,0,0,12.000,12.000,0.160,0.950,1,-40.690578,-21.979648
3785202243.357000,90000,1,12.000,11.994,37.148,3.124,0,0,12.000,12.000,0.160,0.960,1,-37.034476,-21.979648
3785202363.357000,90000,1,12.001,12.007,37.158,3.124,0,0,12.000,12.000,0.160,0.930,1,-34.289379,-21.979648
3785202483.357000,90000,1,12.000,11.994,37.169,3.125,0,0,12.000,12.000,0.160,0.970,1,-32.030456,-21.979648
3785202603.357000,90000,1,12.000,11.995,37.179,3.125,0,0,12.000,12.000,0.160,0.960,1,-29.027776,-21.979648
3785202723.357000,90000,1,11.999,11.992,37.186,3.124,0,0,12.000,12.000,0.160,0.960,1,-27.019054,-21.979648
3785202843.357000,90000,1,12.000,11.991,37.192,3.124,0,0,12.000,12.000,0.160,0.960,1,-23.992078,-21.979648
3785202963.357000,90000,1,12.000,11.999,37.197,3.124,0,0,12.000,12.000,0.160,0.950,1,-20.744835,-21.979648
3785203083.357000,90000,1,12.000,12.004,37.203,3.123,0,0,12.000,12.000,0.160,0.940,1,-18.298798,-21.979648
3785203203.357000,90000,1,12.000,11.999,37.207,3.126,0,0,12.000,12.000,0.160,0.960,1,-16.002291,-21.979648
3785203323.357000,90000,1,12.000,12.007,37.215,3.124,0,0,12.000,12.000,0.160,0.920,1,-13.058939,-21.979648
3785203443.357000,90000,1,12.000,11.998,37.220,3.125,0,0,12.000,12.000,0.160,0.960,1,-9.995588,-21.979648
3785203563.357000,90000,1,12.000,12.006,37.230,3.126,0,0,12.000,12.000,0.160,0.920,1,-6.974518,-21.979648
3785203683.357000,90000,1,12.000,12.000,37.236,3.126,0,0,12.000,12.000,0.160,0.960,1,-4.004992,-21.979648
3785203803.357000,90000,1,12.000,12.001,37.245,3.125,0,0,12.000,12.000,0.160,0.950,1,-1.005802,-21.979648
3785203923.357000,90000,1,12.000,12.001,37.247,3.126,0,0,12.000,12.000,0.160,0.950,1,0.987887,-21.979648
3785204043.357000,90000,1,12.000,12.001,37.253,3.125,0,0,12.000,12.000,0.160,0.950,1,2.994998,-21.979648
3785204163.357000,90000,1,12.000,12.000,37.254,3.126,0,0,12.000,12.000,0.160,0.960,1,5.958886,-21.979648
3785204283.357000,90000,1,12.000,12.000,37.260,3.125,0,0,12.000,12.000,0.160,0.960,1,6.989892,-21.979648
3785204403.357000,90000,1,12.000,12.000,37.263,3.125,0,0,12.000,12.000,0.160,0.960,1,9.996465,-21.979648
3785204523.357000,90000,1,12.000,11.999,37.271,3.125,0,0,12.000,12.000,0.160,0.960,1,14.131627,-21.979648
3785204643.357000,90000,1,12.000,11.999,37.272,3.127,0,0,12.000,12.000,0.160,0.960,1,14.927062,-21.979648
3785204763.357000,90000,1,12.000,12.010,37.276,3.126,0,0,12.000,12.000,0.160,0.910,1,17.610145,-21.979648
3785204883.357000,90000,1,11.999,11.999,37.276,3.126,0,0,12.000,12.000,0.160,0.950,1,19.975108,-21.979648
3785205003.357000,90000,1,12.000,12.002,37.278,3.126,0,0,12.000,12.000,0.160,0.960,1,21.999401,-21.979648
3785205123.357000,90000,1,12.000,11.994,37.278,3.127,0,0,12.000,12.000,0.160,0.960,1,25.003558,-21.979648
3785205243.357000,90000,1,12.000,12.000,37.283,3.125,0,0,12.000,12.000,0.160,0.950,1,28.005030,-21.979648
3785205363.357000,90000,1,12.000,12.000,37.287,3.127,0,0,12.000,12.000,0.160,0.960,1,30.976435,-21.979648
3785205483.357000,90000,1,12.000,11.993,37.293,3.126,0,0,12.000,12.000,0.160,0.970,1,33.978310,-21.979648
3785205603.357000,90000,1,12.000,11.997,37.296,3.128,0,0,12.000,12.000,0.160,0.960,1,35.993609,-21.979648
3785205723.357000,90000,1,12.000,11.997,37.301,3.126,0,0,12.000,12.000,0.160,0.970,1,38.978169,-21.979648
3785205843.357000,90000,1,12.000,12.004,37.303,3.126,0,0,12.000,12.000,0.160,0.930,1,41.763400,-21.979648
3785205963.357000,90000,1,12.000,12.005,37.306,3.126,0,0,12.000,12.000,0.160,0.930,1,43.523263,-21.979648
3785206083.357000,90000,1,12.000,12.000,37.308,3.127,0,0,12.000,12.000,0.160,0.950,1,45.949300,-21.979648
3785206203.357000,90000,1,12.000,12.002,37.311,3.125,0,0,12.000,12.000,0.160,0.950,1,48.114532,-21.979648
3785206323.357000,90000,1,12.000,11.992,37.311,3.126,0,0,12.000,12.000,0.160,0.960,1,50.978689,-21.979648
3785206443.357000,90000,1,12.000,12.002,37.316,3.127,0,0,12.000,12.000,0.160,0.950,1,53.242310,-21.979648
3785206563.357000,90000,1,12.000,11.997,37.318,3.128,0,0,12.000,12.000,0.160,0.950,1,55.961367,-21.979648
3785206683.357000,90000,1,12.000,11.999,37.321,3.128,0,0,12.000,12.000,0.160,0.960,1,57.995995,-21.979648
3785206803.357000,90000,1,12.000,11.999,37.322,3.128,0,0,12.000,12.000,0.160,0.960,1,59.996126,-21.979648
3785206923.357000,90000,1,12.000,12.002,37.324,3.126,0,0,12.000,12.000,0.160,0.950,1,61.995184,-21.979648
3785207043.357000,90000,1,12.000,12.006,37.326,3.125,0,0,12.000,12.000,0.160,0.910,1,65.993567,-21.979648
3785207163.357000,90000,1,12.000,12.003,37.325,3.125,0,0,12.000,12.000,0.160,0.930,1,68.998664,-21.979648
3785207283.357000,90000,1,12.000,12.000,37.327,3.127,0,0,12.000,12.000,0.160,0.960,1,71.995438,-21.979648
3785207403.357000,90000,1,12.000,11.998,37.330,3.127,0,0,12.000,12.000,0.160,0.940,1,74.963488,-21.979648
3785207523.357000,90000,1,12.000,12.000,37.334,3.127,0,0,12.000,12.000,0.160,0.940,1,78.007376,-21.979648
3785207643.357000,90000,1,12.000,11.998,37.336,3.126,0,0,12.000,12.000,0.160,0.950,1,80.995157,-21.979648
3785207763.357000,90000,1,12.000,11.999,37.339,3.126,0,0,12.000,12.000,0.160,0.960,1,83.995824,-21.979648
3785207883.357000,90000,1,12.000,11.997,37.338,3.126,0,0,12.000,12.000,0.160,0.950,1,87.247632,-21.979648
3785208003.357000,90000,1,12.000,11.999,37.339,3.127,0,0,12.000,12.000,0.160,0.950,1,90.335413,-21.979648
3785208123.357000,90000,1,12.000,12.002,37.338,3.126,0,0,12.000,12.000,0.160,0.950,1,93.240509,-21.979648
3785208243.357000,90000,1,12.000,11.999,37.340,3.127,0,0,12.000,12.000,0.160,0.960,1,95.969230,-21.979648
3785208363.357000,90000,1,12.000,12.001,37.342,3.127,0,0,12.000,12.000,0.160,0.950,1,99.193387,-21.979648
3785208483.357000,90000,1,12.000,12.002,37.347,3.129,0,0,12.000,12.000,0.160,0.930,1,102.912442,-21.979648
3785208603.357000,90000,1,12.000,11.998,37.350,3.126,0,0,12.000,12.000,0.160,0.960,1,105.003714,-21.979648
3785208723.357000,90000,1,12.000,11.998,37.354,3.126,0,0,12.000,12.000,0.160,0.970,1,107.996193,-21.979648
3785208843.357000,90000,1,12.000,11.997,37.355,3.126,0,0,12.000,12.000,0.160,0.940,1,112.057530,-21.979648
3785208963.357000,90000,1,12.000,12.005,37.354,3.126,0,0,12.000,12.000,0.160,0.930,1,114.849606,-21.979648
3785209083.357000,90000,1,11.999,11.994,37.354,3.125,0,0,12.000,12.000,0.160,0.960,1,118.029468,-21.979648
3785209203.357000,90000,1,12.000,11.994,37.355,3.127,0,0,12.000,12.000,0.160,0.970,1,121.121947,-21.979648
3785209323.357000,90000,1,12.000,11.999,37.356,3.126,0,0,12.000,12.000,0.160,0.940,1,124.055231,-21.979648
3785209443.357000,90000,1,12.000,11.998,37.358,3.128,0,0,12.000,12.000,0.160,0.960,1,126.013886,-21.979648
3785209563.357000,90000,1,12.000,12.001,37.361,3.126,0,0,12.000,12.000,0.160,0.950,1,128.321802,-21.979648
3785209683.357000,90000,1,12.000,12.004,37.363,3.127,0,0,12.000,12.000,0.160,0.930,1,130.965154,-21.979648
3785209803.357000,90000,1,12.000,11.998,37.361,3.126,0,0,12.000,12.000,0.160,0.960,1,133.038977,-21.979648
3785209923.357000,90000,1,11.999,11.996,37.361,3.127,0,0,12.000,12.000,0.160,0.940,1,135.098840,-21.979648
3785210043.357000,90000,1,12.000,11.999,37.360,3.127,0,0,12.000,12.000,0.160,0.960,1,136.056422,-21.979648
3785210163.357000,90000,1,12.000,12.003,37.363,3.127,0,0,12.000,12.000,0.160,0.940,1,137.011992,-21.979648
3785210283.357000,90000,1,11.999,11.998,37.366,3.127,0,0,12.000,12.000,0.160,0.940,1,140.021786,-21.979648
3785210403.357000,90000,1,12.001,12.003,37.366,3.127,0,0,12.000,12.000,0.160,0.950,1,142.998560,-21.979648
3785210523.357000,90000,1,12.000,12.006,37.368,3.128,0,0,12.000,12.000,0.160,0.930,1,146.819360,-21.979648
3785210643.357000,90000,1,12.000,11.999,37.371,3.128,0,0,12.000,12.000,0.160,0.960,1,150.002980,-21.979648
3785210763.357000,90000,1,12.000,12.005,37.372,3.126,0,0,12.000,12.000,0.160,0.950,1,153.366868,-21.979648
3785210883.357000,90000,1,12.000,12.002,37.372,3.127,0,0,12.000,12.000,0.160,0.940,1,155.725791,-21.979648
3785211003.357000,90000,1,12.000,11.998,37.369,3.126,0,0,12.000,12.000,0.160,0.940,1,158.185787,-21.979648
3785211123.357000,90000,1,12.000,11.999,37.369,3.127,0,0,12.000,12.000,0.160,0.940,1,161.031824,-21.979648
3785211243.357000,90000,1,12.000,12.000,37.368,3.126,0,0,12.000,12.000,0.160,0.940,1,163.067928,-21.979648
3785211363.357000,90000,1,12.000,12.004,37.368,3.127,0,0,12.000,12.000,0.160,0.940,1,164.125779,-21.979648
3785211483.357000,90000,1,12.000,11.998,37.366,3.128,0,0,12.000,12.000,0.160,0.960,1,166.058125,-21.979648
3785211603.357000,90000,1,12.000,11.997,37.366,3.127,0,0,12.000,12.000,0.160,0.960,1,166.997587,-21.979648
3785211723.357000,90000,1,12.000,11.997,37.364,3.127,0,0,12.000,12.000,0.160,0.960,1,169.087114,-21.979648
3785211843.357000,90000,1,12.000,12.002,37.363,3.127,0,0,12.000,12.000,0.160,0.950,1,170.039328,-21.979648
3785211963.357000,90000,1,12.000,12.004,37.361,3.126,0,0,12.000,12.000,0.160,0.950,1,171.064696,-21.979648
3785212083.357000,90000,1,12.000,11.998,37.357,3.126,0,0,12.000,12.000,0.160,0.950,1,172.077446,-21.979648
3785212203.357000,90000,1,12.000,12.000,37.358,3.126,0,0,12.000,12.000,0.160,0.950,1,173.063619,-21.979648
3785212323.357000,90000,1,12.000,11.999,37.360,3.127,0,0,12.000,12.000,0.160,0.960,1,174.063752,-21.979648
3785212443.357000,90000,1,12.000,12.001,37.360,3.128,0,0,12.000,12.000,0.160,0.960,1,175.019052,-21.979648
3785212563.357000,90000,1,12.000,12.003,37.363,3.128,0,0,12.000,12.000,0.160,0.940,1,176.106702,-21.979648
3785212683.357000,90000,1,12.000,11.998,37.363,3.127,0,0,12.000,12.000,0.160,0.940,1,178.249518,-21.979648
3785212803.357000,90000,1,12.000,12.004,37.362,3.127,0,0,12.000,12.000,0.160,0.930,1,178.593276,-21.979648
3785212923.357000,90000,1,12.000,12.000,37.359,3.126,0,0,12.000,12.000,0.160,0.950,1,180.066025,-21.979648
3785213043.357000,90000,1,12.000,12.006,37.359,3.127,0,0,12.000,12.000,0.160,0.920,1,181.953137,-21.979648
3785213163.357000,90000,1,12.000,12.010,37.359,3.127,0,0,12.000,12.000,0.160,0.920,1,182.217029,-21.979648
3785213283.357000,90000,1,12.000,12.000,37.361,3.127,0,0,12.000,12.000,0.160,0.960,1,184.116758,-21.979648
3785213403.357000,90000,1,12.000,12.003,37.360,3.127,0,0,12.000,12.000,0.160,0.940,1,184.057563,-21.979648
3785213523.357000,90000,1,12.000,12.006,37.363,3.127,0,0,12.000,12.000,0.160,0.950,1,185.049106,-21.979648
3785213643.357000,90000,1,12.000,12.001,37.363,3.127,0,0,12.000,12.000,0.160,0.960,1,186.011386,-21.979648
3785213763.357000,90000,1,12.000,12.006,37.365,3.128,0,0,12.000,12.000,0.160,0.920,1,187.793263,-21.979648
3785213883.357000,90000,1,12.000,12.002,37.364,3.127,0,0,12.000,12.000,0.160,0.950,1,189.079570,-21.979648
3785214003.357000,90000,1,12.000,12.002,37.363,3.127,0,0,12.000,12.000,0.160,0.950,1,190.112588,-21.979648
3785214123.357000,90000,1,12.000,12.002,37.362,3.127,0,0,12.000,12.000,0.160,0.940,1,191.041043,-21.979648
3785214243.357000,90000,1,12.000,12.000,37.363,3.127,0,0,12.000,12.000,0.160,0.950,1,192.114599,-21.979648
3785214363.357000,90000,1,12.000,12.000,37.363,3.126,0,0,12.000,12.000,0.160,0.950,1,194.091912,-21.979648
3785214483.357000,90000,1,12.000,11.997,37.367,3.129,0,0,12.000,12.000,0.160,0.960,1,195.043857,-21.979648
3785214603.357000,90000,1,12.000,12.004,37.371,3.127,0,0,12.000,12.000,0.160,0.930,1,196.676472,-21.979648
3785214723.357000,90000,1,12.000,12.000,37.370,3.127,0,0,12.000,12.000,0.160,0.950,1,199.164254,-21.979648
3785214843.357000,90000,1,12.000,12.001,37.369,3.126,0,0,12.000,12.000,0.160,0.950,1,200.004387,-21.979648
3785215053.081000,90000,1,12.000,11.997,37.366,3.127,0,0,12.000,12.000,0.160,0.970,1,200.005997,-21.979648
3785215190.321000,90000,1,11.999,12.000,37.371,3.128,0,0,12.000,12.000,0.160,0.900,1,198.070295,-21.979648
3785215316.823000,90000,1,12.001,12.011,37.371,3.128,0,0,12.000,12.000,0.160,0.900,1,198.968549,-21.979648
3785215436.823000,90000,1,12.000,11.999,37.372,3.128,0,0,12.000,12.000,0.160,0.960,1,195.018085,-21.979648
3785215716.055000,90000,1,11.999,11.991,37.374,3.129,0,0,12.000,12.000,0.160,0.930,1,200.168279,-21.979648
3785215841.114000,90000,1,12.000,12.002,37.374,3.127,0,0,12.000,12.000,0.160,0.950,1,196.983317,-21.979648
3785215961.114000,90000,1,12.000,12.007,37.372,3.129,0,0,12.000,12.000,0.160,0.900,1,197.024122,-21.979648
3785216081.114000,90000,1,12.000,11.999,37.372,3.127,0,0,12.000,12.000,0.160,0.960,1,195.065736,-21.979648
3785216201.114000,90000,1,12.000,12.001,37.371,3.128,0,0,12.000,12.000,0.160,0.950,1,195.065736,-21.979648
3785216321.114000,90000,1,12.000,12.001,37.373,3.129,0,0,12.000,12.000,0.160,0.950,1,195.065736,-21.979648
3785216441.114000,90000,1,12.000,11.995,37.375,3.128,0,0,12.000,12.000,0.160,0.980,1,195.065736,-21.979648
3785216561.114000,90000,1,11.999,11.999,37.378,3.129,0,0,12.000,12.000,0.160,0.960,1,195.065870,-21.979648
3785216681.114000,90000,1,12.000,12.002,37.378,3.129,0,0,12.000,12.000,0.160,0.950,1,195.066004,-21.979648
3785216801.114000,90000,1,12.000,12.003,37.380,3.128,0,0,12.000,12.000,0.160,0.950,1,195.065870,-21.979648
3785216921.114000,90000,1,12.000,11.999,37.377,3.127,0,0,12.000,12.000,0.160,0.960,1,195.066004,-21.979648
3785217041.114000,90000,1,12.000,11.999,37.377,3.127,0,0,12.000,12.000,0.160,0.950,1,195.066138,-21.979648
3785217161.114000,90000,1,12.000,12.002,37.375,3.128,0,0,12.000,12.000,0.160,0.950,1,195.065467,-21.979648
3785217281.114000,90000,1,12.000,11.997,37.377,3.128,0,0,12.000,12.000,0.160,0.960,1,195.065602,-21.979648
3785217401.114000,90000,1,12.000,12.000,37.377,3.129,0,0,12.000,12.000,0.160,0.950,1,195.065736,-21.979648
3785217521.114000,90000,1,10.344,10.348,37.383,3.128,1,1,2.000,2.000,0.110,0.540,3,195.061575,-21.979648
3785217641.114000,90000,1,8.369,8.370,37.380,3.128,1,1,2.000,2.000,0.050,0.580,3,195.056071,-21.979648
3785217761.114000,90000,1,6.376,6.384,37.385,3.128,1,1,2.000,2.000,0.030,0.410,3,195.046810,-21.979648
3785217881.114000,90000,1,4.400,4.410,37.387,3.127,1,1,2.000,2.000,0.000,0.300,3,195.030031,-21.979648
3785218001.114000,90000,1,2.620,2.422,37.397,3.126,1,1,2.000,2.000,0.000,0.140,3,194.947347,-21.979648
3785218121.114000,90000,1,2.127,2.000,37.414,3.124,0,0,2.000,2.000,0.040,0.110,1,194.937145,-21.979648
3785218241.114000,90000,1,2.963,2.872,37.438,3.123,1,1,10.000,10.000,0.000,0.290,2,194.955803,-21.979648
3785218361.114000,90000,1,3.901,3.868,37.441,3.120,1,1,10.000,10.000,0.000,0.410,2,195.017816,-21.979648
3785218481.114000,90000,1,4.880,4.863,37.429,3.124,1,1,10.000,10.000,0.040,0.540,2,195.031239,-21.979648
3785218601.114000,90000,1,5.855,5.856,37.391,3.125,1,1,10.000,10.000,0.080,0.620,2,195.043722,-21.979648
3785218721.114000,90000,1,6.850,6.843,37.352,3.127,1,1,10.000,10.000,0.070,0.580,2,195.048286,-21.979648
3785218841.114000,90000,1,7.848,7.845,37.330,3.128,1,1,10.000,10.000,0.090,0.700,2,195.053521,-21.979648
3785218961.114000,90000,1,8.833,8.830,37.320,3.126,1,1,10.000,10.000,0.110,0.770,2,195.057011,-21.979648
3785219081.114000,90000,1,9.361,9.367,37.315,3.127,1,1,5.000,5.000,0.100,0.620,3,195.058622,-21.979648
3785219201.114000,90000,1,7.368,7.374,37.317,3.128,1,1,5.000,5.000,0.060,0.460,3,195.051508,-21.979648
3785219321.114000,90000,1,5.392,5.401,37.323,3.127,1,1,5.000,5.000,0.030,0.390,3,195.039696,-21.979648
3785219441.114000,90000,1,5.000,4.989,37.334,3.128,0,0,5.000,5.000,0.000,0.430,1,200.192037,-21.979648
3785219561.114000,90000,1,4.999,4.985,37.341,3.127,0,0,5.000,5.000,0.000,0.440,1,194.061173,-21.979648
3785219681.114000,90000,1,5.000,5.003,37.341,3.126,0,0,5.000,5.000,0.020,0.410,1,187.649370,-21.979648
3785219801.114000,90000,1,5.006,4.990,37.337,3.126,0,0,5.000,5.000,0.040,0.440,1,181.950049,-21.979648
3785219921.114000,90000,1,5.006,4.999,37.335,3.126,0,0,5.000,5.000,0.030,0.430,1,175.881065,-21.979648
3785220041.114000,90000,1,4.999,5.008,37.331,3.126,0,0,5.000,5.000,0.000,0.390,1,169.656375,-21.979648
3785220161.114000,90000,1,5.006,4.992,37.327,3.126,0,0,5.000,5.000,0.070,0.440,1,164.029806,-21.979648
3785220281.114000,90000,1,5.006,5.009,37.327,3.126,0,0,5.000,5.000,0.040,0.390,1,158.580149,-21.979648
3785220401.114000,90000,1,5.002,5.000,37.324,3.127,0,0,5.000,5.000,0.070,0.400,1,153.415056,-21.979648
3785220521.114000,90000,1,5.002,4.997,37.325,3.126,0,0,5.000,5.000,0.050,0.430,1,149.022445,-21.979648
3785220641.114000,90000,1,5.003,5.001,37.322,3.127,0,0,5.000,5.000,0.000,0.420,1,143.966613,-21.979648
3785220761.114000,90000,1,5.002,4.985,37.322,3.126,0,0,5.000,5.000,0.050,0.440,1,140.006887,-21.979648
3785220881.114000,90000,1,5.003,5.010,37.319,3.126,0,0,5.000,5.000,0.000,0.400,1,135.725013,-21.979648
3785221001.114000,90000,1,5.003,5.008,37.320,3.126,0,0,5.000,5.000,0.000,0.380,1,131.462872,-21.979648
3785221121.114000,90000,1,5.005,4.999,37.316,3.126,0,0,5.000,5.000,0.070,0.390,1,127.022878,-21.979648
3785221241.114000,90000,1,5.000,5.002,37.314,3.126,0,0,5.000,5.000,0.000,0.430,1,123.926104,-21.979648
3785221361.114000,90000,1,5.005,5.014,37.313,3.127,0,0,5.000,5.000,0.070,0.380,1,119.575640,-21.979648
3785221481.114000,90000,1,5.000,5.003,37.318,3.127,0,0,5.000,5.000,0.000,0.370,1,115.250814,-21.979648
3785221601.114000,90000,1,5.003,5.002,37.317,3.128,0,0,5.000,5.000,0.070,0.380,1,111.308403,-21.979648
3785221721.114000,90000,1,5.001,5.003,37.318,3.127,0,0,5.000,5.000,0.000,0.380,1,107.340758,-21.979648
3785221841.114000,90000,1,5.006,5.001,37.314,3.126,0,0,5.000,5.000,0.050,0.390,1,103.464790,-21.979648
3785221961.114000,90000,1,5.003,4.990,37.312,3.126,0,0,5.000,5.000,0.000,0.430,1,99.050166,-21.979648
3785222081.114000,90000,1,5.004,4.997,37.308,3.125,0,0,5.000,5.000,0.000,0.430,1,95.034332,-21.979648
3785222201.114000,90000,1,5.001,5.008,37.309,3.127,0,0,5.000,5.000,0.000,0.400,1,91.759035,-21.979648
3785222321.114000,90000,1,5.006,4.995,37.307,3.127,0,0,5.000,5.000,0.080,0.440,1,87.937698,-21.979648
3785222441.114000,90000,1,5.000,5.008,37.309,3.127,0,0,5.000,5.000,0.040,0.390,1,83.511127,-21.979648
3785222561.114000,90000,1,5.003,5.004,37.307,3.128,0,0,5.000,5.000,0.050,0.420,1,79.040395,-21.979648
3785222681.114000,90000,1,5.004,4.993,37.307,3.127,0,0,5.000,5.000,0.070,0.430,1,75.062145,-21.979648
3785222801.114000,90000,1,5.006,4.999,37.306,3.126,0,0,5.000,5.000,0.060,0.430,1,71.062285,-21.979648
3785222921.114000,90000,1,5.001,4.995,37.304,3.126,0,0,5.000,5.000,0.050,0.430,1,67.048331,-21.979648
3785223041.114000,90000,1,5.003,4.989,37.303,3.126,0,0,5.000,5.000,0.000,0.450,1,62.106325,-21.979648
3785223161.114000,90000,1,5.000,5.003,37.303,3.127,0,0,5.000,5.000,0.000,0.420,1,58.073444,-21.979648
3785223281.114000,90000,1,5.001,4.992,37.303,3.127,0,0,5.000,5.000,0.000,0.440,1,54.104994,-21.979648
3785223401.114000,90000,1,5.007,5.001,37.305,3.127,0,0,5.000,5.000,0.060,0.430,1,50.079496,-21.979648
3785223521.114000,90000,1,5.000,5.005,37.307,3.128,0,0,5.000,5.000,0.000,0.420,1,45.070241,-21.979648
3785223641.114000,90000,1,4.999,5.010,37.308,3.126,0,0,5.000,5.000,0.010,0.380,1,41.464474,-21.979648
3785223761.114000,90000,1,5.004,4.999,37.309,3.126,0,0,5.000,5.000,0.070,0.430,1,37.080454,-21.979648
3785223881.114000,90000,1,5.004,5.000,37.302,3.128,0,0,5.000,5.000,0.020,0.390,1,32.198850,-21.979648
3785224001.114000,90000,1,5.003,5.007,37.303,3.126,0,0,5.000,5.000,0.060,0.380,1,27.552547,-21.979648
3785224121.115000,90000,1,5.000,4.999,37.298,3.126,0,0,5.000,5.000,0.020,0.430,1,24.085036,-21.979648
3785224241.115000,90000,1,5.000,5.000,37.300,3.127,0,0,5.000,5.000,0.020,0.420,1,19.951350,-21.979648
3785224361.115000,90000,1,5.000,5.000,37.302,3.127,0,0,5.000,5.000,0.010,0.430,1,15.070820,-21.979648
3785224481.115000,90000,1,5.001,4.998,37.306,3.127,0,0,5.000,5.000,0.000,0.430,1,11.035792,-21.979648
3785224601.115000,90000,1,5.002,5.001,37.310,3.128,0,0,5.000,5.000,0.000,0.390,1,6.230027,-21.979648
3785224721.115000,90000,1,5.001,4.990,37.309,3.127,0,0,5.000,5.000,0.050,0.430,1,1.056209,-21.979648
3785224841.115000,90000,1,4.999,5.000,37.310,3.127,0,0,5.000,5.000,0.030,0.400,1,-3.847811,-21.979648
3785224961.115000,90000,1,5.000,5.006,37.306,3.127,0,0,5.000,5.000,0.000,0.380,1,-8.633979,-21.979648
3785225081.115000,90000,1,5.005,4.987,37.308,3.127,0,0,5.000,5.000,0.020,0.430,1,-12.995584,-21.979648
3785225201.115000,90000,1,5.004,5.010,37.306,3.126,0,0,5.000,5.000,0.070,0.390,1,-17.302692,-21.979648
3785225321.115000,90000,1,5.002,5.003,37.310,3.127,0,0,5.000,5.000,0.000,0.380,1,-21.612753,-21.979648
3785225441.115000,90000,1,5.005,5.005,37.310,3.127,0,0,5.000,5.000,0.070,0.390,1,-25.576774,-21.979648
3785225561.115000,90000,1,5.003,4.999,37.315,3.128,0,0,5.000,5.000,0.070,0.430,1,-28.963212,-21.979648
3785225681.115000,90000,1,5.007,4.995,37.313,3.127,0,0,5.000,5.000,0.030,0.430,1,-32.988173,-21.979648
3785225824.818000,90000,1,5.006,5.003,37.317,3.127,0,0,5.000,5.000,0.060,0.430,1,-33.997165,-21.979648
3785225937.517000,90000,1,5.004,5.001,37.311,3.127,0,0,5.000,5.000,0.000,0.430,1,-36.499443,-21.979648
3785226057.517000,90000,1,5.005,4.997,37.313,3.128,0,0,5.000,5.000,0.070,0.390,1,-38.867091,-21.979648
3785226177.517000,90000,1,5.006,5.002,37.310,3.127,0,0,5.000,5.000,0.020,0.430,1,-41.112189,-21.979648
3785226511.690000,90000,2,5.001,4.997,37.316,3.127,0,0,5.000,5.000,0.000,0.400,1,-34.920788,-21.979648
3785226664.066000,90000,1,4.999,5.001,37.314,3.128,0,0,5.000,5.000,0.000,0.430,1,-41.087088,-21.979648
3785226784.066000,90000,1,5.006,4.997,37.318,3.127,0,0,5.000,5.000,0.060,0.430,1,-43.411246,-21.979648
3785226904.066000,90000,1,5.004,4.993,37.316,3.126,0,0,5.000,5.000,0.080,0.400,1,-45.147619,-21.979648
3785227024.066000,90000,1,5.006,4.995,37.316,3.126,0,0,5.000,5.000,0.020,0.430,1,-48.212313,-21.979648
3785227144.066000,90000,1,4.999,4.998,37.314,3.127,0,0,5.000,5.000,0.020,0.430,1,-50.963718,-21.979648
3785227264.066000,90000,1,5.002,5.000,37.317,3.126,0,0,5.000,5.000,0.060,0.420,1,-51.420094,-21.979648
3785227384.066000,90000,1,4.999,4.997,37.319,3.127,0,0,5.000,5.000,0.020,0.430,1,-53.106132,-21.979648
3785227504.066000,90000,1,5.006,4.986,37.321,3.127,0,0,5.000,5.000,0.010,0.430,1,-56.421295,-21.979648
3785227624.066000,90000,1,5.000,5.004,37.322,3.128,0,0,5.000,5.000,0.000,0.360,1,-58.814446,-21.979648
3785227744.066000,90000,1,5.005,4.997,37.324,3.127,0,0,5.000,5.000,0.020,0.420,1,-60.327732,-21.979648
3785227864.066000,90000,1,5.000,5.001,37.323,3.126,0,0,5.000,5.000,0.000,0.430,1,-62.093904,-21.979648
3785228154.947000,90000,2,5.001,4.999,37.320,3.129,0,0,5.000,5.000,0.000,0.400,1,-74.693752,-21.979648
3785228274.947000,90000,1,5.002,5.004,37.323,3.129,0,0,5.000,5.000,0.040,0.370,1,-64.466921,-21.979648
3785228394.947000,90000,1,5.003,4.997,37.320,3.128,0,0,5.000,5.000,0.000,0.430,1,-61.815918,-21.979648
3785228514.947000,90000,1,5.004,4.999,37.326,3.126,0,0,5.000,5.000,0.000,0.430,1,-64.084908,-21.979648
3785228634.947000,90000,1,5.006,5.003,37.325,3.127,0,0,5.000,5.000,0.060,0.430,1,-66.232422,-21.979648
3785228754.947000,90000,1,4.999,4.999,37.329,3.127,0,0,5.000,5.000,0.020,0.430,1,-69.831209,-21.979648
3785228874.947000,90000,1,5.004,4.988,37.326,3.127,0,0,5.000,5.000,0.010,0.420,1,-72.788789,-21.979648
3785228994.947000,90000,1,4.999,5.000,37.325,3.126,0,0,5.000,5.000,0.000,0.420,1,-71.104227,-21.979648
3785229114.947000,90000,1,5.006,5.001,37.323,3.127,0,0,5.000,5.000,0.050,0.430,1,-72.504762,-21.979648
3785229234.947000,90000,1,5.004,5.001,37.322,3.127,0,0,5.000,5.000,0.000,0.420,1,-75.263819,-21.979648
3785229354.947000,90000,1,5.001,4.999,37.323,3.127,0,0,5.000,5.000,0.050,0.440,1,-77.151870,-21.979648
3785229474.947000,90000,1,4.999,5.003,37.323,3.128,0,0,5.000,5.000,0.000,0.410,1,-77.197373,-21.979648
3785229594.947000,90000,1,5.000,4.999,37.323,3.127,0,0,5.000,5.000,0.000,0.420,1,-80.419516,-21.979648
3785229714.947000,90000,1,4.998,4.989,37.324,3.127,0,0,5.000,5.000,0.000,0.420,1,-81.264884,-21.979648
3785229834.947000,90000,1,5.002,4.998,37.324,3.127,0,0,5.000,5.000,0.070,0.410,1,-86.223803,-21.979648
3785229954.947000,90000,1,5.005,5.000,37.322,3.126,0,0,5.000,5.000,0.080,0.430,1,-84.726624,-21.979648
3785230074.947000,90000,1,5.003,4.999,37.322,3.127,0,0,5.000,5.000,0.080,0.410,1,-86.998030,-21.979648
3785230194.947000,90000,1,5.004,5.008,37.322,3.127,0,0,5.000,5.000,0.010,0.370,1,-88.669437,-21.979648
3785230314.947000,90000,1,4.998,4.998,37.322,3.128,0,0,5.000,5.000,0.000,0.430,1,-89.259906,-21.979648
3785230434.947000,90000,1,5.004,4.993,37.323,3.127,0,0,5.000,5.000,0.080,0.420,1,-93.463927,-21.979648
3785230554.947000,90000,1,5.006,4.997,37.328,3.126,0,0,5.000,5.000,0.070,0.430,1,-96.171306,-21.979648
3785230674.947000,90000,1,5.004,4.993,37.328,3.128,0,0,5.000,5.000,0.000,0.410,1,-98.212243,-21.979648
3785231110.454000,90000,2,5.000,5.002,37.325,3.126,0,0,5.000,5.000,0.000,0.400,1,-118.400000,-21.979648
3785231230.454000,90000,1,4.998,4.997,37.324,3.128,0,0,5.000,5.000,0.010,0.390,1,-107.296257,-21.979648
3785231350.454000,90000,1,5.002,5.012,37.324,3.127,0,0,5.000,5.000,0.050,0.390,1,-99.844992,-21.979648
3785231470.454000,90000,1,5.000,5.000,37.323,3.127,0,0,5.000,5.000,0.020,0.380,1,-90.958025,-21.979648
3785231590.454000,90000,1,5.000,5.006,37.326,3.127,0,0,5.000,5.000,0.010,0.400,1,-84.525953,-21.979648
3785231710.454000,90000,1,4.999,4.997,37.324,3.126,0,0,5.000,5.000,0.000,0.430,1,-73.467580,-21.979648
3785231830.454000,90000,1,5.004,5.004,37.325,3.127,0,0,5.000,5.000,0.080,0.420,1,-74.784222,-21.979648
3785231950.454000,90000,1,4.999,5.000,37.321,3.128,0,0,5.000,5.000,0.000,0.380,1,-67.543024,-21.979648
3785232070.454000,90000,1,5.003,4.993,37.322,3.128,0,0,5.000,5.000,0.050,0.390,1,-56.154449,-21.979648
3785232191.574000,90000,1,5.006,4.998,37.318,3.128,0,0,5.000,5.000,0.040,0.430,1,-46.917952,-21.979648
3785232311.574000,90000,1,5.006,5.005,37.322,3.127,0,0,5.000,5.000,0.020,0.430,1,-48.221843,-21.979648
3785232431.574000,90000,1,5.004,5.001,37.321,3.127,0,0,5.000,5.000,0.000,0.420,1,-49.598754,-21.979648
3785232551.574000,90000,1,5.006,4.999,37.326,3.127,0,0,5.000,5.000,0.070,0.430,1,-43.825742,-21.979648
3785232671.574000,90000,1,5.000,5.008,37.326,3.128,0,0,5.000,5.000,0.000,0.380,1,-44.182386,-21.979648
3785232791.574000,90000,1,5.004,5.001,37.327,3.126,0,0,5.000,5.000,0.000,0.430,1,-38.091119,-21.979648
3785232911.574000,90000,1,5.000,5.000,37.326,3.127,0,0,5.000,5.000,0.000,0.430,1,-39.249372,0.000000
3785233031.574000,90000,1,5.003,5.004,37.326,3.127,0,0,5.000,5.000,0.070,0.380,1,-33.737165,-21.979648
3785233151.574000,90000,1,5.001,4.998,37.323,3.127,0,0,5.000,5.000,0.040,0.430,1,-23.835166,-21.979648
3785233271.574000,90000,1,4.999,5.001,37.323,3.128,0,0,5.000,5.000,0.000,0.380,1,-22.054229,-21.979648
3785233391.574000,90000,1,5.005,5.003,37.325,3.129,0,0,5.000,5.000,0.060,0.380,1,-18.949267,-21.979648
3785233511.574000,90000,1,5.006,5.001,37.325,3.127,0,0,5.000,5.000,0.060,0.380,1,-7.631027,-21.979648
3785233631.574000,90000,1,5.000,4.996,37.327,3.129,0,0,5.000,5.000,0.040,0.390,1,2.660368,-21.979648
3785233751.574000,90000,1,5.000,5.000,37.324,3.128,0,0,5.000,5.000,0.000,0.390,1,11.552436,-21.979648
3785233871.574000,90000,1,5.005,5.001,37.323,3.127,0,0,5.000,5.000,0.080,0.430,1,15.128941,-21.979648
3785233991.587000,90000,1,4.999,5.006,37.319,3.128,0,0,5.000,5.000,0.000,0.370,1,24.078727,-21.979648
3785234111.587000,90000,1,5.004,5.006,37.319,3.128,0,0,5.000,5.000,0.000,0.380,1,31.618582,-21.979648
3785234231.587000,90000,1,5.006,5.008,37.316,3.128,0,0,5.000,5.000,0.070,0.390,1,40.308637,-21.979648
3785234351.587000,90000,1,5.000,4.999,37.317,3.125,0,0,5.000,5.000,0.030,0.420,1,46.430776,-21.979648
3785234471.587000,90000,1,5.001,5.008,37.319,3.127,0,0,5.000,5.000,0.050,0.400,1,45.400845,-21.979648
3785234591.587000,90000,1,5.004,4.996,37.320,3.128,0,0,5.000,5.000,0.070,0.390,1,54.708214,-21.979648
3785234711.587000,90000,1,5.005,5.004,37.323,3.125,0,0,5.000,5.000,0.020,0.380,1,63.233034,-21.979648
3785234831.587000,90000,1,5.003,4.996,37.320,3.125,0,0,5.000,5.000,0.070,0.380,1,72.935840,-21.979648
3785234951.587000,90000,1,5.000,4.999,37.320,3.127,0,0,5.000,5.000,0.000,0.420,1,81.042540,-21.979648
3785235071.587000,90000,1,4.999,4.986,37.318,3.127,0,0,5.000,5.000,0.030,0.430,1,85.041192,-21.979648
3785235191.587000,90000,1,5.004,5.007,37.321,3.128,0,0,5.000,5.000,0.000,0.400,1,95.290842,-21.979648
3785235311.587000,90000,1,5.003,5.004,37.319,3.127,0,0,5.000,5.000,0.000,0.390,1,106.130156,-21.979648
3785235431.587000,90000,1,5.000,5.002,37.320,3.127,0,0,5.000,5.000,0.000,0.420,1,110.825048,-21.979648
3785235551.587000,90000,1,5.003,4.990,37.321,3.128,0,0,5.000,5.000,0.000,0.420,1,115.935108,-21.979648
3785235671.587000,90000,1,4.999,4.986,37.324,3.128,0,0,5.000,5.000,0.000,0.440,1,120.154029,-21.979648
3785235791.587000,90000,1,5.000,5.003,37.324,3.127,0,0,5.000,5.000,0.040,0.390,1,126.071067,-21.979648
3785235911.587000,90000,1,5.006,5.000,37.321,3.127,0,0,5.000,5.000,0.040,0.420,1,130.744886,-21.979648
3785236031.587000,90000,1,5.005,4.999,37.319,3.128,0,0,5.000,5.000,0.000,0.420,1,135.610920,-21.979648
3785236151.587000,90000,1,5.004,5.008,37.317,3.126,0,0,5.000,5.000,0.000,0.370,1,141.140039,-21.979648
3785236271.587000,90000,1,5.003,4.997,37.320,3.128,0,0,5.000,5.000,0.070,0.390,1,149.785128,-21.979648
3785236391.587000,90000,1,4.999,5.001,37.315,3.128,0,0,5.000,5.000,0.000,0.410,1,150.733717,-21.979648
3785236511.587000,90000,1,5.006,5.000,37.319,3.128,0,0,5.000,5.000,0.070,0.420,1,155.525254,-21.979648
3785236631.587000,90000,1,5.002,4.996,37.319,3.127,0,0,5.000,5.000,0.000,0.430,1,160.955180,-21.979648
3785236751.587000,90000,1,5.006,4.998,37.319,3.128,0,0,5.000,5.000,0.040,0.430,1,165.662019,-21.979648
3785236871.587000,90000,1,5.000,5.002,37.320,3.126,0,0,5.000,5.000,0.030,0.420,1,170.665099,-21.979648
3785236991.587000,90000,1,5.002,5.006,37.318,3.127,0,0,5.000,5.000,0.050,0.390,1,175.034220,-21.979648
3785237111.587000,90000,1,5.001,5.005,37.317,3.127,0,0,5.000,5.000,0.040,0.370,1,182.688438,-21.979648
3785237231.587000,90000,1,5.005,5.003,37.313,3.126,0,0,5.000,5.000,0.060,0.370,1,186.604271,-21.979648
3785237351.587000,90000,1,4.999,4.998,37.316,3.128,0,0,5.000,5.000,0.000,0.380,1,192.683591,-21.979648
3785237471.587000,90000,1,5.004,5.002,37.314,3.127,0,0,5.000,5.000,0.000,0.380,1,197.559960,-21.979648
3785237591.587000,90000,1,4.998,4.994,37.316,3.127,0,0,5.000,5.000,0.000,0.430,1,200.091903,-21.979648
3785237711.587000,90000,1,5.005,5.006,37.313,3.127,0,0,5.000,5.000,0.080,0.430,1,200.092574,-21.979648
3785237831.587000,90000,1,5.002,5.002,37.315,3.127,0,0,5.000,5.000,0.040,0.440,1,200.092440,-21.979648
3785237951.587000,90000,1,5.006,5.001,37.310,3.128,0,0,5.000,5.000,0.050,0.430,1,200.092977,-21.979648
3785238071.587000,90000,1,5.007,5.000,37.309,3.127,0,0,5.000,5.000,0.070,0.430,1,200.094185,-21.979648
3785238191.587000,90000,1,5.003,5.000,37.308,3.127,0,0,5.000,5.000,0.000,0.430,1,200.092709,-21.979648
3785238311.587000,90000,1,5.000,5.001,37.311,3.127,0,0,5.000,5.000,0.000,0.430,1,200.094454,-21.979648
3785238431.587000,90000,1,4.999,5.000,37.313,3.127,0,0,5.000,5.000,0.000,0.430,1,200.093514,-21.979648
3785238551.587000,90000,1,5.003,5.006,37.312,3.127,0,0,5.000,5.000,0.070,0.430,1,200.093648,-21.979648
3785238671.587000,90000,1,5.006,4.998,37.313,3.127,0,0,5.000,5.000,0.070,0.430,1,200.094185,-21.979648
3785238791.587000,90000,1,5.005,5.002,37.309,3.126,0,0,5.000,5.000,0.070,0.430,1,200.093917,-21.979648
3785238911.587000,90000,1,5.006,4.994,37.310,3.126,0,0,5.000,5.000,0.020,0.450,1,200.093380,-21.979648
3785239031.587000,90000,1,5.007,5.002,37.306,3.127,0,0,5.000,5.000,0.070,0.430,1,200.093917,-21.979648
3785239151.587000,90000,1,5.005,5.000,37.306,3.127,0,0,5.000,5.000,0.000,0.440,1,200.092977,-21.979648
3785239271.587000,90000,1,5.000,4.995,37.305,3.125,0,0,5.000,5.000,0.000,0.430,1,200.094051,-21.979648
3785239391.587000,90000,1,5.005,5.004,37.304,3.126,0,0,5.000,5.000,0.000,0.430,1,200.094319,-21.979648
3785239511.587000,90000,1,5.000,5.007,37.305,3.126,0,0,5.000,5.000,0.000,0.420,1,200.094454,-21.979648
3785239631.587000,90000,1,5.001,5.004,37.305,3.126,0,0,5.000,5.000,0.000,0.420,1,200.094856,-21.979648
3785239751.587000,90000,1,5.001,4.998,37.306,3.127,0,0,5.000,5.000,0.030,0.450,1,200.093246,-21.979648
3785239871.587000,84827,4,5.005,4.996,37.301,3.278,0,0,5.000,5.000,0.070,0.390,1,189.040912,-21.979648
3785239991.587000,78272,4,5.005,4.998,37.272,3.315,0,0,5.000,5.000,0.060,0.380,1,174.787643,-21.979648
3785240111.587000,71806,4,4.999,5.000,37.211,3.333,0,0,5.000,5.000,0.000,0.380,1,161.979339,0.000000
3785240231.587000,65341,4,5.003,4.998,37.139,3.351,0,0,5.000,5.000,0.000,0.380,1,150.367812,-21.979648
3785240351.587000,58816,4,4.999,4.999,37.058,3.365,0,0,5.000,5.000,0.020,0.370,1,139.644203,-21.979648
3785240471.587000,51132,4,4.999,4.998,36.974,3.498,0,0,5.000,5.000,0.010,0.370,1,127.718448,-21.979648
3785240591.587000,39076,4,5.005,5.001,36.884,3.636,0,0,5.000,5.000,0.020,0.360,1,114.809204,-21.979648
3785240711.587000,27079,4,4.999,4.996,36.794,3.700,0,0,5.000,5.000,0.000,0.380,1,101.822779,-21.979648
3785240831.587000,15085,4,5.003,4.998,36.706,3.789,0,0,5.000,5.000,0.000,0.410,1,89.943467,-21.979648
3785240951.587000,3101,4,5.000,5.001,36.628,3.965,0,0,5.000,5.000,0.030,0.420,1,89.951655,-21.979648
3785241071.587000,0,1,5.005,5.003,36.576,3.189,0,0,5.000,5.000,0.060,0.410,1,89.964675,-21.979648
3785241191.587000,0,1,5.007,5.003,36.526,3.110,0,0,5.000,5.000,0.060,0.440,1,89.965614,-21.979648
3785241311.587000,0,1,5.002,5.002,36.479,3.107,0,0,5.000,5.000,0.000,0.430,1,89.964943,-21.979648
3785241431.587000,0,1,5.003,5.002,36.433,3.107,0,0,5.000,5.000,0.000,0.430,1,89.966957,-21.979648
3785241551.587000,0,1,5.000,5.000,36.398,3.105,0,0,5.000,5.000,0.040,0.440,1,89.953937,-21.979648
3785241671.587000,0,1,5.005,4.998,36.364,3.105,0,0,5.000,5.000,0.080,0.440,1,89.956890,-21.979648
3785241791.587000,0,1,5.005,5.000,36.336,3.104,0,0,5.000,5.000,0.080,0.440,1,89.947494,-21.979648
3785241911.587000,0,1,5.005,4.997,36.308,3.103,0,0,5.000,5.000,0.010,0.450,1,89.958769,-21.979648
3785242031.587000,0,1,5.006,5.001,36.283,3.103,0,0,5.000,5.000,0.020,0.430,1,89.947762,-21.979648
3785242151.587000,0,1,4.999,5.001,36.259,3.103,0,0,5.000,5.000,0.000,0.430,1,89.964541,-21.979648
3785242271.587000,0,1,5.001,5.004,36.238,3.103,0,0,5.000,5.000,0.050,0.440,1,89.958635,-21.979648
3785242301.587000,0,1,4.999,5.001,36.233,3.103,0,0,5.000,5.000,0.000,0.440,1,89.961185,-21.979648