File: log/20231213.dat
[Header]
; Displex Transport Data File (default extension .dat)
; Copyright 2016, Hechang LEI, hlei@ruc.edu.cn. All rights reserved.
BYAPP, Displex, 2.0
INFO, 9T mag, Release 2.0.
INFO, Channel 1, Temperature Sensor
INFO, Sample 1 Length (cm): 0.000000; Width (cm): 0.000000; Thickness (cm): 0.000000.

[Data]
Timestamp(s),Field(Oe),Field Status,TempA(K),TempB(K),TempC(K),TempD(K),Ramp1,Ramp2,Setpoint1,Setpoint2,Output1(%),Output2(%),Temp Status,in plane position,out plane position
3785242350.240000,0,1,5.005,5.000,36.226,3.103,0,0,5.000,5.000,0.000,0.440,1,89.959037,-21.979648
3785242470.240000,0,1,13.934,13.836,36.198,3.106,1,1,300.000,300.000,0.510,2.780,2,89.969641,-21.979648
3785242590.240000,0,1,23.895,23.787,36.175,3.104,1,1,300.000,300.000,1.760,7.430,2,89.980916,-21.979648
3785242710.240000,0,1,33.776,33.648,36.159,3.105,1,1,300.000,300.000,4.110,15.570,2,89.988031,-21.979648
3785242830.240000,0,1,43.743,43.591,36.155,3.101,1,1,300.000,300.000,7.330,26.480,2,89.994205,-21.979648
3785242950.240000,0,1,53.626,53.464,36.157,3.103,1,1,300.000,300.000,10.800,38.280,2,89.998232,-21.979648
3785243070.240000,0,1,63.597,63.440,36.167,3.101,1,1,300.000,300.000,14.250,50.550,2,90.003735,-21.979648
3785243190.240000,0,1,73.483,73.318,36.183,3.102,1,1,300.000,300.000,17.410,62.700,2,90.007359,-21.979648
3785243310.240000,0,1,83.370,83.212,36.202,3.103,1,1,300.000,300.000,20.250,74.360,2,90.011789,-21.979648
3785243430.240000,0,1,93.343,93.178,36.229,3.102,1,1,300.000,300.000,22.850,85.900,2,90.015010,-21.979648
3785243550.240000,0,1,103.229,103.079,36.257,3.104,1,1,300.000,300.000,25.060,96.540,2,90.019440,-21.979648
3785243670.240000,0,1,113.195,112.608,36.292,3.104,1,1,300.000,300.000,27.270,100.000,2,90.022393,-21.979648
3785243790.240000,0,1,123.076,120.671,36.321,3.105,1,1,300.000,300.000,29.810,100.000,2,90.025749,-21.979648
3785243910.240000,0,1,133.046,128.259,36.358,3.104,1,1,300.000,300.000,32.470,100.000,2,90.032057,-21.979648
3785244030.240000,0,1,142.918,135.539,36.392,3.104,1,1,300.000,300.000,35.130,100.000,2,90.035547,-21.979648
3785244150.240000,0,1,152.782,142.761,36.430,3.105,1,1,300.000,300.000,38.010,100.000,2,90.040514,-21.979648
3785244270.240000,0,1,162.739,149.975,36.471,3.106,1,1,300.000,300.000,40.720,100.000,2,90.043467,-21.979648
3785244390.240000,0,1,172.617,157.122,36.514,3.106,1,1,300.000,300.000,43.360,100.000,2,90.047762,-21.979648
3785244510.240000,0,1,182.570,164.400,36.560,3.107,1,1,300.000,300.000,46.080,100.000,2,90.048567,-21.979648
3785244630.240000,0,1,192.441,171.662,36.607,3.108,1,1,300.000,300.000,48.670,100.000,2,90.051655,-21.979648
3785244750.240000,0,1,202.315,178.968,36.658,3.107,1,1,300.000,300.000,51.410,100.000,2,90.051520,-21.979648
3785244870.240000,0,1,212.272,186.145,36.704,3.109,1,1,300.000,300.000,53.970,100.000,2,90.052460,-21.979648
3785244990.240000,0,1,222.132,193.883,36.756,3.109,1,1,300.000,300.000,56.330,100.000,2,90.053131,-21.979648
3785245110.240000,0,1,232.094,201.457,36.807,3.110,1,1,300.000,300.000,58.820,100.000,2,90.051789,-21.979648
3785245230.240000,0,1,241.969,209.051,36.863,3.111,1,1,300.000,300.000,61.280,100.000,2,90.044138,-21.979648
3785245350.240000,0,1,251.843,216.680,36.921,3.111,1,1,300.000,300.000,63.390,100.000,2,90.044943,-21.979648
3785245470.240000,0,1,261.796,224.423,36.983,3.112,1,1,300.000,300.000,65.750,100.000,2,90.042393,-21.979648
3785245590.240000,0,1,271.637,232.157,37.046,3.114,1,1,300.000,300.000,67.980,100.000,2,90.039574,-21.979648
3785245710.240000,0,1,280.725,240.032,37.108,3.114,1,1,300.000,300.000,67.570,100.000,2,90.038500,-21.979648
3785245830.240000,0,1,290.757,247.792,37.175,3.115,1,1,300.000,300.000,84.600,100.000,2,90.035547,-21.979648
3785245950.240000,0,1,301.368,255.581,37.237,3.116,0,0,300.000,300.000,68.100,100.000,4,90.031789,-21.979648
3785246070.240000,0,1,301.675,262.215,37.300,3.114,0,0,300.000,300.000,23.690,100.000,4,90.028836,-21.979648
3785246190.240000,0,1,299.655,267.148,37.354,3.116,0,0,300.000,300.000,19.520,100.000,4,90.027359,-21.979648
3785246310.240000,0,1,298.439,271.007,37.408,3.115,0,0,300.000,300.000,48.500,100.000,4,90.027494,-21.979648
3785246430.240000,0,1,299.613,274.080,37.458,3.115,0,0,300.000,300.000,59.850,100.000,4,90.025480,-21.979648
3785246550.240000,0,1,301.160,276.732,37.506,3.115,0,0,300.000,300.000,38.350,100.000,4,90.022527,-21.979648
3785246670.240000,0,1,300.914,279.127,37.558,3.116,0,0,300.000,300.000,13.770,100.000,4,90.022124,-21.979648
3785246790.240000,0,1,299.496,281.217,37.603,3.115,0,0,300.000,300.000,17.550,100.000,4,90.024675,-21.979648
3785246910.240000,0,1,298.968,283.036,37.651,3.116,0,0,300.000,300.000,37.890,100.000,4,90.025212,-21.979648
3785247030.240000,0,1,299.930,284.637,37.692,3.117,0,0,300.000,300.000,42.280,100.000,4,90.025346,-21.979648
3785247150.240000,0,1,300.860,286.129,37.737,3.117,0,0,300.000,300.000,25.810,100.000,4,90.025883,-21.979648
3785247270.240000,0,1,300.521,287.559,37.785,3.118,0,0,300.000,300.000,11.110,100.000,4,90.025883,-21.979648
3785247390.240000,0,1,299.562,288.851,37.829,3.118,0,0,300.000,300.000,15.870,100.000,4,90.025883,-21.979648
3785247510.240000,0,1,299.323,290.004,37.880,3.119,0,0,300.000,300.000,29.440,100.000,4,90.025077,-21.979648
3785247630.240000,0,1,300.022,291.033,37.923,3.121,0,0,300.000,300.000,30.800,100.000,4,90.024675,-21.979648
3785247750.240000,0,1,300.607,292.012,37.971,3.121,0,0,300.000,300.000,19.100,100.000,4,90.024541,-21.979648
3785247870.240000,0,1,300.321,292.983,38.014,3.122,0,0,300.000,300.000,9.700,100.000,4,90.025346,-21.979648
3785247990.240000,0,1,299.680,293.916,38.057,3.120,0,0,300.000,300.000,13.370,100.000,4,90.026822,-21.979648
3785248110.240000,0,1,299.548,294.835,38.100,3.122,0,0,300.000,300.000,22.350,100.000,4,90.024943,-21.979648
3785248230.240000,0,1,300.030,295.746,38.145,3.122,0,0,300.000,300.000,22.730,100.000,4,90.023601,-21.979648
3785248350.240000,0,1,300.413,296.686,38.190,3.124,0,0,300.000,300.000,14.700,100.000,4,90.023869,-21.979648
3785248470.240000,0,1,300.220,297.642,38.236,3.126,0,0,300.000,300.000,8.320,100.000,4,90.024541,-21.979648
3785248590.240000,0,1,299.789,298.555,38.285,3.126,0,0,300.000,300.000,10.590,100.000,4,90.024138,-21.979648
3785248710.240000,0,1,299.684,299.405,38.329,3.124,0,0,300.000,300.000,16.210,100.000,4,90.024541,-21.979648
3785248830.240000,0,1,300.002,300.131,38.377,3.127,0,0,300.000,300.000,16.910,99.360,4,90.024272,-21.979648
3785248950.240000,0,1,300.273,300.008,38.418,3.127,0,0,300.000,300.000,11.970,94.810,1,90.023869,-21.979648
3785249070.240000,0,1,300.168,300.038,38.464,3.129,0,0,300.000,300.000,7.630,91.660,4,90.022796,-21.979648
3785249190.240000,0,1,299.877,300.046,38.508,3.130,0,0,300.000,300.000,8.990,88.850,4,90.022259,-21.979648
3785249310.240000,0,1,299.778,300.033,38.554,3.131,0,0,300.000,300.000,13.020,87.200,4,90.022259,-21.979648
3785249430.240000,0,1,299.973,300.012,38.601,3.132,0,0,300.000,300.000,14.250,85.130,1,90.022259,-21.979648
3785249550.240000,0,1,300.171,300.009,38.649,3.132,0,0,300.000,300.000,11.230,83.850,1,90.021856,-21.979648
3785249670.240000,0,1,300.133,300.024,38.698,3.133,0,0,300.000,300.000,8.020,82.190,4,90.022124,-21.979648
3785249790.240000,0,1,299.936,300.031,38.741,3.134,0,0,300.000,300.000,8.490,80.700,4,90.022527,-21.979648
3785249910.240000,0,1,299.847,300.024,38.788,3.134,0,0,300.000,300.000,11.190,78.980,4,90.022393,-21.979648
3785250030.240000,0,1,299.964,300.011,38.827,3.136,0,0,300.000,300.000,12.330,77.930,1,90.021453,-21.979648
3785250150.240000,0,1,300.107,300.011,38.872,3.136,0,0,300.000,300.000,10.490,76.470,1,90.020379,-21.979648
3785250270.240000,0,1,300.101,300.018,38.914,3.137,0,0,300.000,300.000,8.200,75.390,1,90.020111,-21.979648
3785250390.240000,0,1,299.976,300.022,38.960,3.138,0,0,300.000,300.000,8.130,74.090,4,90.019708,-21.979648
3785250510.240000,0,1,299.897,300.018,39.007,3.140,0,0,300.000,300.000,9.860,72.890,4,90.019708,-21.979648
3785250630.240000,0,1,299.959,300.010,39.054,3.140,0,0,300.000,300.000,10.930,71.740,1,90.019843,-21.979648
3785250750.240000,0,1,300.058,300.007,39.101,3.141,0,0,300.000,300.000,9.890,70.610,1,90.020111,-21.979648
3785250870.240000,0,1,300.077,300.012,39.145,3.141,0,0,300.000,300.000,8.220,69.650,1,90.019977,-21.979648
3785250990.240000,0,1,299.998,300.016,39.186,3.141,0,0,300.000,300.000,7.880,68.360,1,90.019977,-21.979648
3785251110.240000,0,1,299.936,300.014,39.225,3.141,0,0,300.000,300.000,8.870,67.550,1,90.020782,-21.979648
3785251230.240000,0,1,299.958,300.009,39.268,3.143,0,0,300.000,300.000,9.720,66.780,1,90.020111,-21.979648
3785251350.240000,0,1,300.029,300.005,39.308,3.144,0,0,300.000,300.000,9.350,65.980,1,90.020111,-21.979648
3785251470.240000,0,1,300.055,300.009,39.356,3.145,0,0,300.000,300.000,8.150,65.310,1,90.020245,-21.979648
3785251590.240000,0,1,300.011,300.014,39.395,3.146,0,0,300.000,300.000,7.710,64.060,1,90.020245,-21.979648
3785251710.240000,0,1,299.961,300.014,39.441,3.147,0,0,300.000,300.000,8.230,63.560,1,90.020111,-21.979648
3785251830.240000,0,1,299.963,300.007,39.480,3.146,0,0,300.000,300.000,8.940,62.740,1,90.020111,-21.979648
3785251950.240000,0,1,300.009,300.004,39.519,3.146,0,0,300.000,300.000,8.780,62.250,1,90.019574,-21.979648
3785252070.240000,0,1,300.036,300.006,39.559,3.147,0,0,300.000,300.000,8.050,61.510,1,90.019843,-21.979648
3785252190.240000,0,1,300.017,300.009,39.596,3.148,0,0,300.000,300.000,7.560,60.910,1,90.019306,-21.979648
3785252310.240000,0,1,299.980,300.010,39.640,3.149,0,0,300.000,300.000,7.800,60.260,1,90.018903,-21.979648
3785252430.240000,0,1,299.972,300.008,39.677,3.150,0,0,300.000,300.000,8.270,59.660,1,90.018769,-21.979648
3785252550.240000,0,1,300.003,300.005,39.723,3.151,0,0,300.000,300.000,8.360,59.260,1,90.019171,-21.979648
3785252670.240000,0,1,300.025,300.007,39.761,3.151,0,0,300.000,300.000,7.820,58.620,1,90.017829,-21.979648
3785252790.240000,0,1,300.014,300.006,39.802,3.152,0,0,300.000,300.000,7.450,58.150,1,90.017158,-21.979648
3785252910.240000,0,1,299.992,300.007,39.839,3.152,0,0,300.000,300.000,7.520,57.710,1,90.017158,-21.979648
3785253030.240000,0,1,299.980,300.006,39.875,3.151,0,0,300.000,300.000,7.770,57.200,1,90.017561,-21.979648
3785253150.240000,0,1,299.994,300.004,39.911,3.152,0,0,300.000,300.000,7.890,56.500,1,90.017829,-21.979648
3785253270.240000,0,1,300.013,300.004,39.944,3.153,0,0,300.000,300.000,7.630,56.380,1,90.017829,-21.979648
3785253390.240000,0,1,300.011,300.006,39.984,3.153,0,0,300.000,300.000,7.360,56.030,1,90.018232,-21.979648
3785253510.240000,0,1,299.998,300.006,40.020,3.155,0,0,300.000,300.000,7.310,55.530,1,90.017426,-21.979648
3785253630.240000,0,1,299.990,300.005,40.060,3.154,0,0,300.000,300.000,7.470,55.070,1,90.018366,-21.979648
3785253750.240000,0,1,299.995,300.001,40.096,3.155,0,0,300.000,300.000,7.540,54.840,1,90.017426,-21.979648
3785253870.240000,0,1,300.006,300.005,40.131,3.155,0,0,300.000,300.000,7.480,54.380,1,90.016755,-21.979648
3785253990.240000,0,1,300.010,300.001,40.169,3.155,0,0,300.000,300.000,7.220,54.070,1,90.016890,-21.979648
3785254110.240000,0,1,300.002,300.003,40.200,3.155,0,0,300.000,300.000,7.120,53.730,1,90.016084,-21.979648
3785254230.240000,0,1,299.992,300.001,40.235,3.155,0,0,300.000,300.000,7.210,53.460,1,90.015413,-21.979648
3785254350.240000,0,1,299.993,300.005,40.264,3.157,0,0,300.000,300.000,7.320,53.120,1,90.027359,-21.979648
3785254470.240000,0,1,300.002,300.000,40.301,3.157,0,0,300.000,300.000,7.270,52.900,1,90.015682,-21.979648
3785254590.240000,0,1,300.007,300.005,40.335,3.159,0,0,300.000,300.000,7.150,52.560,1,90.016084,-21.979648
3785254710.240000,0,1,300.005,300.004,40.371,3.159,0,0,300.000,300.000,6.960,52.370,1,90.016084,-21.979648
3785254830.240000,0,1,299.994,300.005,40.403,3.160,0,0,300.000,300.000,7.030,52.070,1,90.015682,-21.979648
3785254950.240000,0,1,299.992,300.004,40.435,3.158,0,0,300.000,300.000,7.090,51.920,1,90.015682,-21.979648
3785255070.240000,0,1,299.995,300.002,40.464,3.159,0,0,300.000,300.000,7.170,51.620,1,90.015682,-21.979648
3785255190.240000,0,1,300.006,300.001,40.491,3.158,0,0,300.000,300.000,7.050,51.360,1,90.015816,-21.979648
3785255310.240000,0,1,300.007,300.001,40.524,3.160,0,0,300.000,300.000,6.870,51.180,1,90.015547,-21.979648
3785255430.240000,0,1,299.997,300.002,40.552,3.161,0,0,300.000,300.000,6.880,50.960,1,90.015279,-21.979648
3785255550.240000,0,1,299.992,300.003,40.588,3.161,0,0,300.000,300.000,6.990,50.620,1,90.014742,-21.979648
3785255670.240000,0,1,300.000,300.002,40.616,3.163,0,0,300.000,300.000,7.000,50.400,1,90.014742,-21.979648
3785255790.240000,0,1,300.006,300.002,40.647,3.162,0,0,300.000,300.000,6.860,50.260,1,90.015010,-21.979648
3785255910.240000,0,1,300.003,300.001,40.676,3.163,0,0,300.000,300.000,6.750,50.110,1,90.014742,-21.979648
3785256030.240000,0,1,299.995,300.000,40.702,3.161,0,0,300.000,300.000,6.800,49.890,1,90.014608,-21.979648
3785256150.240000,0,1,299.996,300.001,40.731,3.162,0,0,300.000,300.000,6.860,49.710,1,90.014608,-21.979648
3785256270.240000,0,1,299.999,300.002,40.754,3.163,0,0,300.000,300.000,6.830,49.520,1,90.014608,-21.979648
3785256390.240000,0,1,300.004,300.001,40.785,3.163,0,0,300.000,300.000,6.700,49.450,1,90.014608,-21.979648
3785256510.240000,0,1,299.999,300.001,40.812,3.165,0,0,300.000,300.000,6.740,49.300,1,90.014339,-21.979648
3785256630.240000,0,1,299.999,300.001,40.843,3.165,0,0,300.000,300.000,6.750,49.050,1,90.014473,-21.979648
3785256750.240000,0,1,300.001,300.002,40.871,3.166,0,0,300.000,300.000,6.730,49.010,1,90.014742,-21.979648
3785256870.240000,0,1,300.002,300.002,40.898,3.164,0,0,300.000,300.000,6.680,48.720,1,90.014742,-21.979648
3785256990.240000,0,1,300.001,300.002,40.921,3.165,0,0,300.000,300.000,6.650,48.720,1,90.014742,-21.979648
3785257110.240000,0,1,299.998,300.003,40.943,3.164,0,0,300.000,300.000,6.610,48.220,1,90.014608,-21.979648
3785257230.240000,0,1,299.995,300.002,40.969,3.165,0,0,300.000,300.000,6.700,48.290,1,90.014339,-21.979648
3785257350.240000,0,1,300.001,300.001,40.989,3.165,0,0,300.000,300.000,6.690,48.220,1,90.013937,-21.979648
3785257470.240000,0,1,300.002,299.999,41.018,3.166,0,0,300.000,300.000,6.600,48.080,1,90.014876,-21.979648
3785257590.240000,0,1,300.002,300.001,41.040,3.167,0,0,300.000,300.000,6.570,47.970,1,90.014742,-21.979648
3785257710.240000,0,1,300.001,300.002,41.068,3.167,0,0,300.000,300.000,6.590,47.860,1,90.014205,-21.979648
3785257830.240000,0,1,299.999,300.002,41.092,3.167,0,0,300.000,300.000,6.560,47.720,1,90.014205,-21.979648
3785257950.240000,0,1,300.000,300.004,41.114,3.166,0,0,300.000,300.000,6.590,47.570,1,90.013534,-21.979648
3785258070.240000,0,1,300.002,299.999,41.135,3.167,0,0,300.000,300.000,6.550,47.470,1,90.013534,-21.979648
3785258190.240000,0,1,299.999,299.999,41.155,3.166,0,0,300.000,300.000,6.500,47.430,1,90.013265,-21.979648
3785258310.240000,0,1,299.998,300.002,41.179,3.166,0,0,300.000,300.000,6.500,47.250,1,90.014205,-21.979648
3785258430.240000,0,1,300.000,300.001,41.199,3.167,0,0,300.000,300.000,6.550,47.150,1,90.014071,-21.979648
3785258550.240000,0,1,299.999,299.999,41.224,3.168,0,0,300.000,300.000,6.500,47.070,1,90.013668,-21.979648
3785258670.240000,0,1,300.002,300.001,41.244,3.168,0,0,300.000,300.000,6.460,47.000,1,90.013668,-21.979648
3785258790.240000,0,1,299.999,300.002,41.271,3.170,0,0,300.000,300.000,6.450,46.860,1,90.013131,-21.979648
3785258910.240000,0,1,300.001,300.000,41.287,3.168,0,0,300.000,300.000,6.460,46.900,1,90.013802,-21.979648
3785259030.240000,0,1,300.000,300.002,41.308,3.168,0,0,300.000,300.000,6.400,46.680,1,90.013534,-21.979648
3785259150.240000,0,1,299.997,300.003,41.322,3.169,0,0,300.000,300.000,6.420,46.580,1,90.013534,-21.979648
3785259270.240000,0,1,299.997,300.002,41.342,3.169,0,0,300.000,300.000,6.500,46.470,1,90.013668,-21.979648
3785259390.240000,0,1,300.000,300.001,41.360,3.170,0,0,300.000,300.000,6.410,46.440,1,90.013400,-21.979648
3785259510.240000,0,1,300.002,299.999,41.383,3.170,0,0,300.000,300.000,6.370,46.330,1,90.012863,-21.979648
3785259630.240000,0,1,300.000,300.000,41.401,3.170,0,0,300.000,300.000,6.360,46.330,1,90.012997,-21.979648
3785259750.240000,0,1,300.000,300.000,41.423,3.170,0,0,300.000,300.000,6.410,46.150,1,90.012326,-21.979648
3785259870.240000,0,1,300.000,300.000,41.440,3.172,0,0,300.000,300.000,6.410,46.190,1,90.011923,-21.979648
3785259990.240000,0,1,300.002,300.002,41.458,3.171,0,0,300.000,300.000,6.380,46.150,1,90.012728,-21.979648
3785260110.240000,0,1,300.000,300.001,41.475,3.171,0,0,300.000,300.000,6.370,46.050,1,90.013534,-21.979648
3785260230.240000,0,1,300.002,300.003,41.492,3.171,0,0,300.000,300.000,6.320,46.010,1,90.013668,-21.979648
3785260350.240000,0,1,300.001,300.003,41.511,3.171,0,0,300.000,300.000,6.360,45.870,1,90.014071,-21.979648
3785260470.240000,0,1,299.999,300.000,41.528,3.171,0,0,300.000,300.000,6.330,45.770,1,90.013802,-21.979648
3785260590.240000,0,1,299.999,300.001,41.547,3.173,0,0,300.000,300.000,6.350,45.840,1,90.013668,-21.979648
3785260710.240000,0,1,300.000,300.000,41.564,3.173,0,0,300.000,300.000,6.350,45.630,1,90.013400,-21.979648
3785260830.240000,0,1,300.001,299.998,41.584,3.172,0,0,300.000,300.000,6.310,45.350,1,90.013534,-21.979648
3785260950.240000,0,1,300.000,300.003,41.597,3.172,0,0,300.000,300.000,6.320,45.520,1,90.013400,-21.979648
3785261070.240000,0,1,299.997,300.000,41.614,3.172,0,0,300.000,300.000,6.320,45.490,1,90.013534,-21.979648
3785261190.240000,0,1,300.001,299.999,41.624,3.172,0,0,300.000,300.000,6.310,45.420,1,90.013668,-21.979648
3785261310.240000,0,1,300.002,300.000,41.640,3.172,0,0,300.000,300.000,6.200,45.490,1,90.013802,-21.979648
3785261430.240000,0,1,300.000,300.002,41.652,3.173,0,0,300.000,300.000,6.260,45.280,1,90.013668,-21.979648
3785261550.240000,0,1,299.997,300.002,41.670,3.174,0,0,300.000,300.000,6.310,45.240,1,90.013131,-21.979648
3785261670.240000,0,1,300.000,300.001,41.681,3.174,0,0,300.000,300.000,6.310,45.170,1,90.012728,-21.979648
3785261790.240000,0,1,299.999,300.000,41.700,3.174,0,0,300.000,300.000,6.270,45.140,1,90.013131,-21.979648
3785261910.240000,0,1,300.000,299.998,41.712,3.174,0,0,300.000,300.000,6.230,45.210,1,90.013400,-21.979648
3785262030.240000,0,1,300.000,300.000,41.726,3.173,0,0,300.000,300.000,6.250,45.070,1,90.013265,-21.979648
3785262150.240000,0,1,300.001,300.001,41.736,3.174,0,0,300.000,300.000,6.310,45.140,1,90.013400,-21.979648
3785262270.240000,0,1,300.001,300.000,41.749,3.174,0,0,300.000,300.000,6.230,45.100,1,90.013265,-21.979648
3785262390.240000,0,1,299.999,300.002,41.762,3.174,0,0,300.000,300.000,6.250,44.970,1,90.013668,-21.979648
3785262510.240000,0,1,299.998,299.998,41.776,3.175,0,0,300.000,300.000,6.220,44.860,1,90.013400,-21.979648
3785262630.240000,0,1,299.998,299.998,41.790,3.175,0,0,300.000,300.000,6.270,44.930,1,90.013534,-21.979648
3785262750.240000,0,1,300.003,299.998,41.803,3.175,0,0,300.000,300.000,6.230,44.790,1,90.013534,-21.979648
3785262870.240000,0,1,300.004,299.999,41.820,3.174,0,0,300.000,300.000,6.160,44.760,1,90.013937,-21.979648
3785262990.240000,0,1,300.000,300.000,41.829,3.175,0,0,300.000,300.000,6.150,44.760,1,90.013802,-21.979648
3785263110.240000,0,1,299.994,300.001,41.842,3.176,0,0,300.000,300.000,6.230,44.690,1,90.014205,-21.979648
3785263230.240000,0,1,299.997,300.000,41.848,3.176,0,0,300.000,300.000,6.310,44.620,1,90.013534,-21.979648
3785263350.240000,0,1,300.005,300.002,41.862,3.175,0,0,300.000,300.000,6.260,44.620,1,90.013400,-21.979648
3785263470.240000,0,1,300.004,299.999,41.871,3.175,0,0,300.000,300.000,6.170,44.550,1,90.014339,-21.979648
3785263590.240000,0,1,300.001,300.002,41.885,3.176,0,0,300.000,300.000,6.170,44.480,1,90.014339,-21.979648
3785263710.240000,0,1,299.996,300.000,41.897,3.177,0,0,300.000,300.000,6.180,44.510,1,90.014339,-21.979648
3785263830.240000,0,1,299.996,300.001,41.906,3.177,0,0,300.000,300.000,6.300,44.450,1,90.014339,-21.979648
3785263950.240000,0,1,300.001,299.998,41.919,3.177,0,0,300.000,300.000,6.250,44.480,1,90.014608,-21.979648
3785264070.240000,0,1,300.005,299.999,41.926,3.176,0,0,300.000,300.000,6.160,44.510,1,90.014473,-21.979648
3785264190.240000,0,1,300.001,300.001,41.934,3.176,0,0,300.000,300.000,6.150,44.380,1,90.014608,-21.979648
3785264310.240000,0,1,299.998,299.999,41.942,3.177,0,0,300.000,300.000,6.180,44.410,1,90.014608,-21.979648
3785264430.240000,0,1,300.003,300.002,41.950,3.176,0,0,300.000,300.000,6.160,44.340,1,90.014742,-21.979648
3785264550.240000,0,1,299.998,300.003,41.962,3.176,0,0,300.000,300.000,6.170,44.270,1,90.014742,-21.979648
3785264670.240000,0,1,299.999,300.000,41.971,3.176,0,0,300.000,300.000,6.200,44.380,1,90.014608,-21.979648
3785264790.240000,0,1,299.999,300.001,41.985,3.178,0,0,300.000,300.000,6.210,44.200,1,90.014608,-21.979648
3785264910.240000,0,1,300.001,299.998,41.989,3.178,0,0,300.000,300.000,6.150,44.200,1,90.014742,-21.979648
3785265030.240000,0,1,299.999,299.999,41.999,3.177,0,0,300.000,300.000,6.110,44.140,1,90.014608,-21.979648
3785265150.240000,0,1,299.997,299.999,42.004,3.177,0,0,300.000,300.000,6.110,44.170,1,90.014742,-21.979648
3785265270.240000,0,1,299.997,299.998,42.012,3.176,0,0,300.000,300.000,6.160,44.140,1,90.015010,-21.979648
3785265390.240000,0,1,300.000,300.002,42.021,3.178,0,0,300.000,300.000,6.170,44.140,1,90.015010,-21.979648
3785265510.240000,0,1,300.001,300.001,42.029,3.178,0,0,300.000,300.000,6.160,44.070,1,90.014608,-21.979648
3785265630.240000,0,1,300.002,300.001,42.043,3.178,0,0,300.000,300.000,6.120,44.000,1,90.014876,-21.979648
3785265750.240000,0,1,299.997,300.000,42.052,3.178,0,0,300.000,300.000,6.100,44.000,1,90.015010,-21.979648
3785265870.240000,0,1,299.997,300.001,42.062,3.179,0,0,300.000,300.000,6.170,44.100,1,90.015145,-21.979648
3785265990.240000,0,1,300.001,300.000,42.065,3.178,0,0,300.000,300.000,6.170,44.030,1,90.015145,-21.979648
3785266110.240000,0,1,300.000,299.998,42.073,3.177,0,0,300.000,300.000,6.100,43.960,1,90.015413,-21.979648
3785266230.240000,0,1,299.998,299.999,42.075,3.178,0,0,300.000,300.000,6.110,44.070,1,90.015682,-21.979648
3785266350.240000,0,1,300.000,300.000,42.086,3.177,0,0,300.000,300.000,6.150,43.890,1,90.015816,-21.979648
3785266470.240000,0,1,299.998,299.997,42.089,3.179,0,0,300.000,300.000,6.170,43.930,1,90.015816,-21.979648
3785266590.240000,0,1,300.001,300.000,42.100,3.179,0,0,300.000,300.000,6.120,43.960,1,90.015682,-21.979648
3785266710.240000,0,1,300.002,300.000,42.108,3.180,0,0,300.000,300.000,6.060,43.860,1,90.015816,-21.979648
3785266830.240000,0,1,299.999,299.999,42.116,3.179,0,0,300.000,300.000,6.070,43.790,1,90.015547,-21.979648
3785266950.240000,0,1,299.998,300.001,42.124,3.178,0,0,300.000,300.000,6.140,43.830,1,90.015682,-21.979648
3785267070.240000,0,1,299.997,300.002,42.126,3.179,0,0,300.000,300.000,6.150,43.830,1,90.015547,-21.979648
3785267190.240000,0,1,300.000,300.001,42.131,3.179,0,0,300.000,300.000,6.120,43.790,1,90.015279,-21.979648
3785267310.240000,0,1,300.002,300.002,42.134,3.178,0,0,300.000,300.000,6.060,43.760,1,90.015950,-21.979648
3785267430.240000,0,1,299.999,300.001,42.140,3.179,0,0,300.000,300.000,6.110,43.830,1,90.015547,-21.979648
3785267550.240000,0,1,300.000,300.001,42.143,3.178,0,0,300.000,300.000,6.100,43.690,1,90.015145,-21.979648
3785267670.240000,0,1,299.999,299.999,42.154,3.179,0,0,300.000,300.000,6.120,43.690,1,90.031386,-21.979648
3785267790.240000,0,1,300.002,299.997,42.157,3.179,0,0,300.000,300.000,6.100,43.790,1,90.015145,-21.979648
3785267910.240000,0,1,300.000,300.001,42.165,3.180,0,0,300.000,300.000,6.110,43.690,1,90.015547,-21.979648
3785268030.240000,0,1,300.002,299.999,42.169,3.180,0,0,300.000,300.000,6.070,43.650,1,90.015816,-21.979648
3785268150.240000,0,1,299.995,300.000,42.171,3.179,0,0,300.000,300.000,6.110,43.620,1,90.015950,-21.979648
3785268270.240000,0,1,299.999,300.000,42.174,3.179,0,0,300.000,300.000,6.140,43.760,1,90.015816,-21.979648
3785268390.240000,0,1,300.003,300.000,42.177,3.179,0,0,300.000,300.000,6.120,43.620,1,90.015145,-21.979648
3785268510.240000,0,1,300.004,299.999,42.185,3.180,0,0,300.000,300.000,6.100,43.620,1,90.016353,-21.979648
3785268630.240000,0,1,300.000,300.000,42.191,3.179,0,0,300.000,300.000,6.030,43.690,1,90.016487,-21.979648
3785268750.240000,0,1,299.998,300.001,42.202,3.180,0,0,300.000,300.000,6.100,43.690,1,90.016353,-21.979648
3785268870.240000,0,1,299.997,300.000,42.205,3.179,0,0,300.000,300.000,6.180,43.550,1,90.016218,-21.979648
3785268990.240000,0,1,300.005,299.999,42.211,3.181,0,0,300.000,300.000,6.140,43.550,1,90.016890,-21.979648
3785269110.240000,0,1,300.004,299.998,42.212,3.180,0,0,300.000,300.000,6.030,43.520,1,90.017024,-21.979648
3785269230.240000,0,1,299.999,300.000,42.217,3.180,0,0,300.000,300.000,6.060,43.520,1,90.016621,-21.979648
3785269350.240000,0,1,299.999,300.000,42.222,3.181,0,0,300.000,300.000,6.090,43.590,1,90.016487,-21.979648
3785269470.240000,0,1,299.999,300.000,42.224,3.179,0,0,300.000,300.000,6.140,43.480,1,90.016890,-21.979648
3785269590.240000,0,1,300.003,300.000,42.230,3.181,0,0,300.000,300.000,6.100,43.480,1,90.017158,-21.979648
3785269710.240000,0,1,300.001,300.001,42.237,3.181,0,0,300.000,300.000,6.100,43.520,1,90.017158,-21.979648
3785269830.240000,0,1,300.001,300.002,42.244,3.181,0,0,300.000,300.000,6.050,43.550,1,90.017158,-21.979648
3785269950.240000,0,1,299.999,300.003,42.247,3.181,0,0,300.000,300.000,6.070,43.450,1,90.017292,-21.979648
3785270070.240000,0,1,299.998,300.001,42.254,3.181,0,0,300.000,300.000,6.100,43.480,1,90.017158,-21.979648
3785270190.240000,0,1,300.002,300.000,42.254,3.180,0,0,300.000,300.000,6.090,43.480,1,90.017158,-21.979648
3785270310.240000,0,1,300.002,300.000,42.259,3.181,0,0,300.000,300.000,6.090,43.420,1,90.017426,-21.979648
3785270430.240000,0,1,300.000,299.999,42.261,3.181,0,0,300.000,300.000,6.060,43.420,1,90.017829,-21.979648
3785270550.240000,0,1,299.999,300.000,42.266,3.181,0,0,300.000,300.000,6.010,43.480,1,90.017695,-21.979648
3785270670.240000,0,1,299.997,300.000,42.273,3.181,0,0,300.000,300.000,6.100,43.420,1,90.017829,-21.979648
3785270790.240000,0,1,299.996,300.000,42.278,3.180,0,0,300.000,300.000,6.110,43.380,1,90.017829,-21.979648
3785270910.240000,0,1,300.000,300.000,42.283,3.180,0,0,300.000,300.000,6.100,43.380,1,90.017561,-21.979648
3785271030.240000,0,1,300.001,300.000,42.284,3.179,0,0,300.000,300.000,6.090,43.350,1,90.017561,-21.979648
3785271150.240000,0,1,300.002,300.000,42.286,3.181,0,0,300.000,300.000,6.100,43.140,1,90.031923,-21.979648
3785271270.240000,0,1,300.002,299.998,42.283,3.181,0,0,300.000,300.000,6.060,43.380,1,90.017561,-21.979648
3785271390.240000,0,1,300.000,300.000,42.288,3.181,0,0,300.000,300.000,6.030,43.350,1,90.017963,-21.979648
3785271510.240000,0,1,300.001,300.000,42.291,3.179,0,0,300.000,300.000,6.050,43.310,1,90.017561,-21.979648
3785271630.240000,0,1,299.997,300.002,42.299,3.182,0,0,300.000,300.000,6.120,43.310,1,90.017963,-21.979648
3785271750.240000,0,1,299.998,300.000,42.305,3.182,0,0,300.000,300.000,6.090,43.310,1,90.018366,-21.979648
3785271870.240000,0,1,300.000,300.000,42.310,3.181,0,0,300.000,300.000,6.120,43.380,1,90.018098,-21.979648
3785271990.240000,0,1,300.002,300.000,42.313,3.181,0,0,300.000,300.000,6.060,43.350,1,90.018098,-21.979648
3785272110.240000,0,1,300.001,299.999,42.316,3.181,0,0,300.000,300.000,6.050,43.240,1,90.017829,-21.979648
3785272230.240000,0,1,299.997,300.000,42.318,3.181,0,0,300.000,300.000,6.090,43.280,1,90.017829,-21.979648
3785272350.240000,0,1,299.997,300.000,42.318,3.181,0,0,300.000,300.000,6.070,43.280,1,90.018098,-21.979648
3785272470.240000,0,1,300.000,299.999,42.321,3.182,0,0,300.000,300.000,6.090,43.310,1,90.018232,-21.979648
3785272590.240000,0,1,299.999,300.001,42.325,3.180,0,0,300.000,300.000,6.090,43.280,1,90.017426,-21.979648
3785272710.240000,0,1,300.000,300.000,42.332,3.181,0,0,300.000,300.000,6.090,43.280,1,90.017963,-21.979648
3785272830.240000,0,1,300.002,300.000,42.334,3.182,0,0,300.000,300.000,6.070,43.240,1,90.017426,-21.979648
3785272950.240000,0,1,300.002,299.999,42.341,3.181,0,0,300.000,300.000,6.030,43.280,1,90.017158,-21.979648
3785273070.240000,0,1,299.997,300.000,42.340,3.182,0,0,300.000,300.000,6.060,43.350,1,90.016755,-21.979648
3785273190.240000,0,1,299.996,300.002,42.339,3.182,0,0,300.000,300.000,6.120,43.210,1,90.017024,-21.979648
3785273310.240000,0,1,300.001,300.000,42.340,3.182,0,0,300.000,300.000,6.090,43.210,1,90.017024,-21.979648
3785273430.240000,0,1,300.002,299.998,42.342,3.182,0,0,300.000,300.000,6.030,43.240,1,90.017158,-21.979648
3785273550.240000,0,1,300.001,300.000,42.346,3.182,0,0,300.000,300.000,6.040,43.110,1,90.017829,-21.979648
3785273670.240000,0,1,300.000,300.000,42.349,3.182,0,0,300.000,300.000,6.000,43.180,1,90.017829,-21.979648
3785273790.240000,0,1,299.999,300.000,42.354,3.182,0,0,300.000,300.000,6.070,43.210,1,90.017292,-21.979648
3785273910.240000,0,1,300.002,299.999,42.356,3.181,0,0,300.000,300.000,6.030,43.180,1,90.016218,-21.979648
3785274030.240000,0,1,300.002,300.000,42.359,3.180,0,0,300.000,300.000,6.050,43.310,1,90.015816,-21.979648
3785274150.240000,0,1,300.000,300.002,42.358,3.182,0,0,300.000,300.000,6.040,43.280,1,90.015816,-21.979648
3785274270.240000,0,1,299.998,300.001,42.359,3.182,0,0,300.000,300.000,6.070,43.210,1,90.015950,-21.979648
3785274390.240000,0,1,299.999,299.997,42.359,3.182,0,0,300.000,300.000,6.040,43.280,1,90.015010,-21.979648
3785274510.240000,0,1,299.999,300.000,42.362,3.182,0,0,300.000,300.000,6.070,43.280,1,90.015279,-21.979648
3785274630.240000,0,1,299.998,300.001,42.365,3.182,0,0,300.000,300.000,6.060,43.140,1,90.014608,-21.979648
3785274750.240000,0,1,299.999,300.002,42.369,3.183,0,0,300.000,300.000,6.070,43.180,1,90.014205,-21.979648
3785274870.240000,0,1,300.000,299.998,42.368,3.182,0,0,300.000,300.000,6.090,43.280,1,90.014205,-21.979648
3785274990.240000,0,1,300.000,300.001,42.373,3.181,0,0,300.000,300.000,6.060,43.240,1,90.014742,-21.979648
3785275110.240000,0,1,300.000,299.999,42.370,3.181,0,0,300.000,300.000,6.030,43.110,1,90.014876,-21.979648
3785275230.240000,0,1,300.000,299.999,42.372,3.182,0,0,300.000,300.000,6.070,43.140,1,90.014473,-21.979648
3785275350.240000,0,1,300.000,300.003,42.371,3.181,0,0,300.000,300.000,6.070,43.140,1,90.015279,-21.979648
3785275470.240000,0,1,299.998,300.000,42.375,3.183,0,0,300.000,300.000,6.050,43.110,1,90.014205,-21.979648
3785275590.240000,0,1,299.999,299.999,42.376,3.181,0,0,300.000,300.000,6.060,43.180,1,90.014205,-21.979648
3785275710.240000,0,1,300.002,300.001,42.380,3.182,0,0,300.000,300.000,6.040,43.110,1,90.013400,-21.979648
3785275830.240000,0,1,300.001,300.000,42.382,3.182,0,0,300.000,300.000,6.010,43.240,1,90.012057,-21.979648
3785275950.240000,0,1,299.997,299.998,42.386,3.181,0,0,300.000,300.000,6.010,43.110,1,90.011923,-21.979648
3785276070.240000,0,1,299.998,300.000,42.387,3.182,0,0,300.000,300.000,6.070,43.110,1,90.011386,-21.979648
3785276190.240000,0,1,300.001,300.001,42.387,3.182,0,0,300.000,300.000,6.040,43.180,1,90.011923,-21.979648
3785276310.240000,0,1,300.000,299.998,42.386,3.181,0,0,300.000,300.000,6.030,43.110,1,90.012326,-21.979648
3785276430.240000,0,1,299.997,300.000,42.386,3.181,0,0,300.000,300.000,6.050,43.110,1,90.011923,-21.979648
3785276550.240000,0,1,299.997,299.998,42.390,3.182,0,0,300.000,300.000,6.090,43.210,1,90.011386,0.000000
3785276670.240000,0,1,300.004,300.000,42.390,3.182,0,0,300.000,300.000,6.060,43.210,1,90.011386,-21.979648
3785276790.240000,0,1,300.002,300.001,42.394,3.182,0,0,300.000,300.000,6.010,43.210,1,90.010715,-21.979648
3785276910.240000,0,1,300.000,300.001,42.394,3.182,0,0,300.000,300.000,6.010,43.070,1,90.011520,-21.979648
3785277030.240000,0,1,299.996,300.000,42.398,3.183,0,0,300.000,300.000,6.060,43.070,1,90.011789,-21.979648
3785277150.240000,0,1,300.001,300.001,42.395,3.180,0,0,300.000,300.000,6.070,43.140,1,90.011923,-21.979648
3785277270.240000,0,1,300.004,300.000,42.395,3.181,0,0,300.000,300.000,6.010,43.110,1,90.012326,-21.979648
3785277390.240000,0,1,300.000,300.001,42.391,3.181,0,0,300.000,300.000,5.980,43.180,1,90.012057,-21.979648
3785277510.240000,0,1,299.996,299.999,42.394,3.182,0,0,300.000,300.000,6.000,43.140,1,90.012460,-21.979648
3785277630.240000,0,1,299.998,300.000,42.394,3.181,0,0,300.000,300.000,6.050,43.110,1,90.012057,-21.979648
3785277750.240000,0,1,299.998,299.998,42.397,3.182,0,0,300.000,300.000,6.070,43.140,1,90.013400,-21.979648
3785277870.240000,0,1,300.002,300.000,42.399,3.183,0,0,300.000,300.000,6.060,43.110,1,90.012997,-21.979648
3785277990.240000,0,1,300.004,300.001,42.398,3.183,0,0,300.000,300.000,5.990,43.040,1,90.013131,-21.979648
3785278110.240000,0,1,300.000,300.000,42.401,3.182,0,0,300.000,300.000,5.990,43.070,1,90.013265,-21.979648
3785278230.240000,0,1,299.997,300.002,42.399,3.181,0,0,300.000,300.000,5.990,42.870,1,90.012997,-21.979648
3785278350.240000,0,1,299.997,299.999,42.401,3.181,0,0,300.000,300.000,6.060,43.070,1,90.013131,-21.979648
3785278470.240000,0,1,299.997,300.001,42.399,3.182,0,0,300.000,300.000,6.110,43.070,1,90.013400,-21.979648
3785278590.240000,0,1,300.001,299.998,42.405,3.182,0,0,300.000,300.000,6.070,42.870,1,90.013131,-21.979648
3785278710.240000,0,1,300.006,299.999,42.403,3.182,0,0,300.000,300.000,6.000,43.070,1,90.013265,-21.979648
3785278830.240000,0,1,299.999,300.000,42.408,3.183,0,0,300.000,300.000,6.030,43.010,1,90.013265,-21.979648
3785278950.240000,0,1,299.996,300.001,42.406,3.183,0,0,300.000,300.000,6.040,43.010,1,90.013131,-21.979648
3785279070.240000,0,1,299.997,300.002,42.404,3.182,0,0,300.000,300.000,6.110,43.070,1,90.012997,-21.979648
3785279190.240000,0,1,300.001,299.999,42.404,3.182,0,0,300.000,300.000,6.090,43.040,1,90.012594,-21.979648
3785279310.240000,0,1,300.003,299.998,42.400,3.181,0,0,300.000,300.000,5.990,43.070,1,90.013265,-21.979648
3785279430.240000,0,1,300.001,299.999,42.400,3.182,0,0,300.000,300.000,6.010,43.180,1,90.012997,-21.979648
3785279550.240000,0,1,299.999,299.999,42.396,3.182,0,0,300.000,300.000,6.030,43.040,1,90.012594,-21.979648
3785279670.240000,0,1,300.002,300.000,42.401,3.182,0,0,300.000,300.000,6.030,43.010,1,90.012863,-21.979648
3785279790.240000,0,1,300.000,299.999,42.400,3.182,0,0,300.000,300.000,6.050,43.010,1,90.012997,-21.979648
3785279910.240000,0,1,300.001,300.000,42.397,3.182,0,0,300.000,300.000,6.050,43.040,1,90.012594,-21.979648
3785280030.240000,0,1,300.000,300.000,42.397,3.182,0,0,300.000,300.000,6.000,43.110,1,90.012997,-21.979648
3785280150.240000,0,1,299.998,300.000,42.392,3.181,0,0,300.000,300.000,6.040,43.010,1,90.012594,-21.979648
3785280270.240000,0,1,299.997,300.000,42.394,3.181,0,0,300.000,300.000,6.070,43.140,1,90.013131,-21.979648
3785280390.240000,0,1,300.001,299.998,42.388,3.181,0,0,300.000,300.000,6.060,42.970,1,90.012997,-21.979648
3785280510.240000,0,1,300.002,300.000,42.390,3.182,0,0,300.000,300.000,6.060,43.010,1,90.013265,-21.979648
3785280630.240000,0,1,300.001,299.999,42.390,3.181,0,0,300.000,300.000,6.050,43.180,1,90.013265,-21.979648
3785280750.240000,0,1,300.000,299.999,42.390,3.182,0,0,300.000,300.000,6.030,43.010,1,90.013400,-21.979648
3785280870.240000,0,1,300.001,300.001,42.392,3.181,0,0,300.000,300.000,6.050,43.010,1,90.012997,-21.979648
3785280990.240000,0,1,300.001,299.999,42.389,3.182,0,0,300.000,300.000,6.030,43.070,1,90.012997,-21.979648
3785281110.240000,0,1,300.001,300.000,42.391,3.181,0,0,300.000,300.000,5.990,43.040,1,90.012728,-21.979648
3785281230.240000,0,1,299.997,300.000,42.384,3.183,0,0,300.000,300.000,6.050,42.840,1,90.012863,-21.979648
3785281350.240000,0,1,299.998,299.999,42.385,3.183,0,0,300.000,300.000,6.060,42.800,1,90.031386,-21.979648
3785281470.240000,0,1,299.999,299.998,42.385,3.182,0,0,300.000,300.000,6.070,43.010,1,90.013400,-21.979648
3785281590.240000,0,1,300.001,299.998,42.384,3.183,0,0,300.000,300.000,6.050,43.040,1,90.013265,-21.979648
3785281710.240000,0,1,300.002,299.999,42.387,3.181,0,0,300.000,300.000,6.010,42.970,1,90.012728,-21.979648
3785281830.240000,0,1,300.000,299.997,42.386,3.182,0,0,300.000,300.000,5.990,42.970,1,90.012326,-21.979648
3785281950.240000,0,1,299.997,300.002,42.391,3.181,0,0,300.000,300.000,6.060,43.110,1,90.012460,-21.979648
3785282070.240000,0,1,299.999,299.999,42.386,3.181,0,0,300.000,300.000,6.070,43.010,1,90.012326,-21.979648
3785282190.240000,0,1,300.001,300.000,42.385,3.181,0,0,300.000,300.000,6.050,42.970,1,90.012057,-21.979648
3785282310.240000,0,1,300.002,300.000,42.382,3.180,0,0,300.000,300.000,5.990,42.970,1,90.011252,-21.979648
3785282430.240000,0,1,299.999,299.999,42.379,3.182,0,0,300.000,300.000,6.000,42.970,1,90.011118,-21.979648
3785282550.240000,0,1,299.996,299.999,42.380,3.181,0,0,300.000,300.000,6.050,42.940,1,90.010849,-21.979648
3785282670.240000,0,1,300.001,299.999,42.377,3.181,0,0,300.000,300.000,6.050,42.970,1,90.011520,-21.979648
3785282790.240000,0,1,300.002,299.999,42.381,3.183,0,0,300.000,300.000,6.030,42.900,1,90.011655,-21.979648
3785282910.240000,0,1,300.001,300.000,42.379,3.181,0,0,300.000,300.000,6.030,42.970,1,90.010984,-21.979648
3785283030.240000,0,1,299.996,299.998,42.379,3.182,0,0,300.000,300.000,6.050,42.970,1,90.011386,-21.979648
3785283150.240000,0,1,299.995,300.000,42.372,3.182,0,0,300.000,300.000,6.100,42.970,1,90.011520,-21.979648
3785283270.240000,0,1,299.998,300.000,42.372,3.183,0,0,300.000,300.000,6.110,42.970,1,90.011252,-21.979648
3785283390.240000,0,1,300.005,299.998,42.368,3.181,0,0,300.000,300.000,6.010,42.970,1,90.011252,-21.979648
3785283510.240000,0,1,299.999,299.997,42.368,3.181,0,0,300.000,300.000,5.980,42.940,1,90.011252,-21.979648
3785283630.240000,0,1,299.998,299.999,42.369,3.182,0,0,300.000,300.000,6.070,43.070,1,90.011386,-21.979648
3785283750.240000,0,1,299.998,300.000,42.370,3.181,0,0,300.000,300.000,6.050,43.010,1,90.011386,-21.979648
3785283870.240000,0,1,300.004,300.000,42.372,3.182,0,0,300.000,300.000,6.050,43.070,1,90.011520,-21.979648
3785283990.240000,0,1,300.001,300.000,42.371,3.181,0,0,300.000,300.000,6.010,42.940,1,90.011252,-21.979648
3785284110.240000,0,1,299.998,299.999,42.370,3.180,0,0,300.000,300.000,6.030,43.070,1,90.011386,-21.979648
3785284230.240000,0,1,300.000,300.000,42.369,3.181,0,0,300.000,300.000,6.040,42.940,1,90.011386,-21.979648
3785284350.240000,0,1,300.000,300.000,42.366,3.181,0,0,300.000,300.000,5.990,42.970,1,90.012326,-21.979648
3785284470.240000,0,1,299.998,300.000,42.363,3.181,0,0,300.000,300.000,6.040,42.970,1,90.011655,-21.979648
3785284590.240000,0,1,300.001,300.000,42.364,3.182,0,0,300.000,300.000,6.030,43.010,1,90.012192,-21.979648
3785284710.240000,0,1,300.000,300.000,42.365,3.183,0,0,300.000,300.000,6.030,42.970,1,90.011789,-21.979648
3785284830.240000,0,1,299.998,299.997,42.368,3.182,0,0,300.000,300.000,6.010,42.970,1,90.012057,-21.979648
3785284950.240000,0,1,299.996,299.998,42.366,3.182,0,0,300.000,300.000,6.060,42.970,1,90.012997,-21.979648
3785285070.240000,0,1,299.998,299.999,42.369,3.182,0,0,300.000,300.000,6.090,42.940,1,90.013534,-21.979648
3785285190.240000,0,1,300.001,299.998,42.365,3.182,0,0,300.000,300.000,6.060,42.970,1,90.014071,-21.979648
3785285310.240000,0,1,300.005,300.002,42.365,3.181,0,0,300.000,300.000,6.010,42.940,1,90.013802,-21.979648
3785285430.240000,0,1,300.002,300.001,42.363,3.182,0,0,300.000,300.000,5.960,42.900,1,90.014339,-21.979648
3785285550.240000,0,1,299.998,300.000,42.369,3.181,0,0,300.000,300.000,5.990,43.070,1,90.014742,-21.979648
3785285670.240000,0,1,299.996,300.001,42.371,3.183,0,0,300.000,300.000,6.070,42.900,1,90.014339,-21.979648
3785285790.240000,0,1,300.003,299.997,42.377,3.182,0,0,300.000,300.000,6.100,42.940,1,90.014473,-21.979648
3785285910.240000,0,1,300.003,299.999,42.379,3.183,0,0,300.000,300.000,6.030,42.900,1,90.014608,-21.979648
3785286030.240000,0,1,300.000,300.000,42.379,3.182,0,0,300.000,300.000,5.980,43.040,1,90.014205,-21.979648
3785286150.240000,0,1,299.999,299.999,42.379,3.182,0,0,300.000,300.000,5.940,42.900,1,90.014339,-21.979648
3785286270.240000,0,1,299.994,300.000,42.378,3.181,0,0,300.000,300.000,6.000,43.040,1,90.014071,-21.979648
3785286390.240000,0,1,299.995,300.000,42.378,3.181,0,0,300.000,300.000,6.090,42.940,1,90.013668,-21.979648
3785286510.240000,0,1,300.000,299.996,42.379,3.181,0,0,300.000,300.000,6.100,43.010,1,90.013937,-21.979648
3785286630.240000,0,1,300.000,299.999,42.382,3.182,0,0,300.000,300.000,6.040,42.940,1,90.014205,-21.979648
3785286750.240000,0,1,300.002,299.999,42.384,3.182,0,0,300.000,300.000,6.000,42.970,1,90.014742,-21.979648
3785286870.240000,0,1,299.999,300.000,42.389,3.182,0,0,300.000,300.000,5.990,43.070,1,90.014071,-21.979648
3785286990.240000,0,1,299.995,299.999,42.390,3.181,0,0,300.000,300.000,6.050,42.940,1,90.014071,-21.979648
3785287110.240000,0,1,299.998,299.998,42.392,3.182,0,0,300.000,300.000,6.070,42.940,1,90.014071,-21.979648
3785287230.240000,0,1,300.004,300.001,42.389,3.182,0,0,300.000,300.000,6.010,42.900,1,90.014339,-21.979648
3785287350.240000,0,1,300.001,300.000,42.391,3.182,0,0,300.000,300.000,6.040,42.970,1,90.014473,-21.979648
3785287470.240000,0,1,300.001,300.000,42.386,3.182,0,0,300.000,300.000,6.030,43.110,1,90.014742,-21.979648
3785287590.240000,0,1,300.000,0.000,42.390,3.182,0,0,300.000,300.000,6.040,0.000,4,90.015145,-21.979648
3785287710.240000,0,1,299.959,0.000,42.389,3.182,0,0,300.000,300.000,8.830,0.000,4,90.016218,-21.979648
3785287830.240000,0,1,299.964,0.000,42.394,3.182,0,0,300.000,300.000,10.860,0.000,4,90.015950,-21.979648
3785287950.240000,0,1,299.998,0.000,42.393,3.181,0,0,300.000,300.000,11.820,0.000,4,90.016084,-21.979648
3785288070.240000,0,1,300.019,0.000,42.399,3.182,0,0,300.000,300.000,12.070,0.000,4,90.016084,-21.979648
3785288190.240000,0,1,300.005,0.000,42.397,3.180,0,0,300.000,300.000,12.280,0.000,4,90.015413,-21.979648
3785288310.240000,0,1,299.983,0.000,42.400,3.181,0,0,300.000,300.000,12.950,0.000,4,90.015279,-21.979648
3785288430.240000,0,1,299.983,0.000,42.400,3.181,0,0,300.000,300.000,13.550,0.000,4,90.015279,-21.979648
3785288550.240000,0,1,299.999,0.000,42.406,3.181,0,0,300.000,300.000,13.790,0.000,4,90.014876,-21.979648
3785288670.240000,0,1,300.013,0.000,42.408,3.182,0,0,300.000,300.000,13.790,0.000,4,90.014742,-21.979648
3785288790.240000,0,1,300.004,0.000,42.413,3.182,0,0,300.000,300.000,13.790,0.000,4,90.015279,-21.979648
3785288910.240000,0,1,299.990,0.000,42.416,3.182,0,0,300.000,300.000,14.050,0.000,4,90.014742,-21.979648
3785289030.240000,0,1,299.987,0.000,42.419,3.182,0,0,300.000,300.000,14.420,0.000,4,90.014876,-21.979648
3785289150.240000,0,1,300.000,0.000,42.415,3.181,0,0,300.000,300.000,14.530,0.000,4,90.015010,-21.979648
3785289270.240000,0,1,300.008,0.000,42.417,3.181,0,0,300.000,300.000,14.530,0.000,4,90.015279,-21.979648
3785289390.240000,0,1,300.005,0.000,42.416,3.179,0,0,300.000,300.000,14.480,0.000,4,90.015145,-21.979648
3785289510.240000,0,1,299.993,0.000,42.418,3.181,0,0,300.000,300.000,14.610,0.000,4,90.013534,-21.979648
3785289630.240000,0,1,299.990,0.000,42.419,3.180,0,0,300.000,300.000,14.860,0.000,4,90.013131,-21.979648
3785289750.240000,0,1,300.001,0.000,42.422,3.181,0,0,300.000,300.000,14.990,0.000,4,90.013131,-21.979648
3785289870.240000,0,1,300.021,0.000,42.444,3.180,0,0,300.000,300.000,12.880,0.000,4,90.047762,-21.979648
3785289990.240000,0,1,299.944,0.000,42.482,3.180,0,0,300.000,300.000,13.860,0.000,4,90.023467,-21.979648
3785290110.240000,0,1,299.949,0.000,42.490,3.178,0,0,300.000,300.000,15.140,0.000,4,90.050581,-21.979648
3785290230.240000,0,1,300.020,0.000,42.477,3.179,0,0,300.000,300.000,15.050,0.000,4,90.068299,-21.979648
3785290350.240000,0,1,300.057,0.000,42.449,3.178,0,0,300.000,300.000,13.990,0.000,4,90.048567,-21.979648
3785290470.240000,0,1,300.012,0.000,42.419,3.178,0,0,300.000,300.000,13.580,0.000,4,93.698629,-21.979648
3785290590.240000,0,1,299.960,0.000,42.388,3.178,0,0,300.000,300.000,14.340,0.000,4,104.357809,-21.979648
3785290710.240000,0,1,299.964,0.000,42.362,3.179,0,0,300.000,300.000,15.070,0.000,4,115.542357,0.000000
3785290830.240000,0,1,300.012,0.000,42.337,3.178,0,0,300.000,300.000,15.180,0.000,4,125.858316,-21.979648
3785290950.240000,0,1,300.037,0.000,42.315,3.180,0,0,300.000,300.000,14.440,0.000,4,137.306085,-21.979648
3785291070.240000,0,1,300.011,0.000,42.293,3.178,0,0,300.000,300.000,14.270,0.000,4,149.461907,-21.979648
3785291190.240000,0,1,299.976,0.000,42.272,3.178,0,0,300.000,300.000,14.720,0.000,4,160.723099,-21.979648
3785291310.240000,0,1,299.977,0.000,42.249,3.176,0,0,300.000,300.000,15.180,0.000,4,171.722815,-21.979648
3785291430.240000,0,1,300.008,0.000,42.230,3.178,0,0,300.000,300.000,15.240,0.000,4,180.091931,-21.979648
3785291550.240000,0,1,300.021,0.000,42.216,3.178,0,0,300.000,300.000,14.840,0.000,4,180.091797,-21.979648
3785291670.240000,0,1,300.007,0.000,42.201,3.177,0,0,300.000,300.000,14.740,0.000,4,180.092065,-21.979648
3785291790.240000,0,1,299.984,0.000,42.191,3.178,0,0,300.000,300.000,15.050,0.000,4,169.568590,-21.979648
3785291910.240000,0,1,299.985,0.000,42.178,3.178,0,0,300.000,300.000,15.420,0.000,4,156.119213,-21.979648
3785292030.240000,0,1,300.005,0.000,42.170,3.176,0,0,300.000,300.000,15.380,0.000,4,142.792655,-21.979648
3785292150.240000,0,1,300.015,0.000,42.161,3.176,0,0,300.000,300.000,15.090,0.000,4,130.336967,-21.979648
3785292270.240000,0,1,300.003,0.000,42.153,3.176,0,0,300.000,300.000,15.030,0.000,4,119.016581,-21.979648
3785292390.240000,0,1,299.988,0.000,42.141,3.177,0,0,300.000,300.000,15.300,0.000,4,107.298342,-21.979648
3785292510.240000,0,1,299.990,0.000,42.133,3.176,0,0,300.000,300.000,15.490,0.000,4,95.152184,-21.979648
3785292630.240000,0,1,300.003,0.000,42.121,3.176,0,0,300.000,300.000,15.530,0.000,4,90.055145,-21.979648
3785292750.240000,0,1,300.009,0.000,42.116,3.175,0,0,300.000,300.000,15.340,0.000,4,90.054742,-21.979648
3785292870.240000,0,1,300.002,0.000,42.110,3.176,0,0,300.000,300.000,15.340,0.000,4,86.498371,-21.979648
3785292990.240000,0,1,299.990,0.000,42.106,3.177,0,0,300.000,300.000,15.440,0.000,4,72.935034,-21.979648
3785293110.240000,0,1,299.994,0.000,42.101,3.175,0,0,300.000,300.000,15.630,0.000,4,61.666728,-21.979648
3785293230.240000,0,1,300.003,0.000,42.093,3.174,0,0,300.000,300.000,15.630,0.000,4,51.270232,-21.979648
3785293350.240000,0,1,300.008,0.000,42.081,3.175,0,0,300.000,300.000,15.480,0.000,4,43.278834,-21.979648
3785293470.240000,0,1,300.000,0.000,42.075,3.176,0,0,300.000,300.000,15.460,0.000,4,33.467439,-21.979648
3785293590.240000,0,1,299.992,0.000,42.066,3.176,0,0,300.000,300.000,15.630,0.000,4,21.091214,-21.979648
3785293710.240000,0,1,299.995,0.000,42.064,3.176,0,0,300.000,300.000,15.770,0.000,4,8.578346,-21.979648
3785293830.240000,0,1,300.005,0.000,42.060,3.175,0,0,300.000,300.000,15.750,0.000,4,-0.075736,-21.979648
3785293950.240000,0,1,300.004,0.000,42.058,3.176,0,0,300.000,300.000,15.630,0.000,4,-0.077078,-21.979648
3785294070.240000,0,1,299.999,0.000,42.055,3.176,0,0,300.000,300.000,15.630,0.000,4,-0.076407,-21.979648
3785294190.240000,0,1,299.996,0.000,42.052,3.176,0,0,300.000,300.000,15.710,0.000,4,-0.074662,-21.979648
3785294310.240000,0,1,299.998,0.000,42.045,3.174,0,0,300.000,300.000,15.770,0.000,4,-0.075736,-21.979648
3785294430.240000,0,1,300.000,0.000,42.040,3.175,0,0,300.000,300.000,15.790,0.000,4,-0.075333,-21.979648
3785294550.240000,0,1,299.999,0.000,42.033,3.175,0,0,300.000,300.000,15.790,0.000,4,-0.076139,-21.979648
3785294670.240000,0,1,300.001,0.000,42.032,3.174,0,0,300.000,300.000,15.790,0.000,4,-3.211034,-21.979648
3785294790.240000,0,1,299.999,0.000,42.028,3.175,0,0,300.000,300.000,15.830,0.000,4,-14.951554,-21.979648
3785294910.240000,0,1,300.002,0.000,42.028,3.175,0,0,300.000,300.000,15.830,0.000,4,-27.827241,-21.979648
3785295030.240000,0,1,300.001,0.000,42.025,3.175,0,0,300.000,300.000,15.830,0.000,4,-39.450983,-21.979648
3785295150.240000,0,1,299.317,0.000,42.021,3.176,0,0,300.000,300.000,0.000,0.000,4,-48.053655,-21.979648
3785295270.240000,0,1,293.071,0.000,42.015,3.173,0,0,300.000,300.000,0.000,0.000,4,-57.764246,-21.979648
3785295390.240000,0,1,288.091,0.000,42.006,3.172,0,0,300.000,300.000,0.000,0.000,4,-68.482620,-21.979648
3785295510.240000,0,1,283.680,0.000,41.994,3.171,0,0,300.000,300.000,0.000,0.000,4,-80.175087,-21.979648
3785295630.240000,0,1,279.783,0.000,41.981,3.172,0,0,300.000,300.000,0.000,0.000,4,-90.100308,-21.979648
3785295750.240000,0,1,276.240,0.000,41.967,3.172,0,0,300.000,300.000,0.000,0.000,4,-90.104201,-21.979648
3785295870.240000,0,1,273.054,0.000,41.955,3.172,0,0,300.000,300.000,0.000,0.000,4,-90.103932,-21.979648
3785295990.240000,0,1,270.132,0.000,41.942,3.170,0,0,300.000,300.000,0.000,0.000,4,-90.103529,-21.979648
3785296110.240000,0,1,267.474,0.000,41.929,3.169,0,0,300.000,300.000,0.000,0.000,4,-90.102992,-21.979648
3785296230.240000,0,1,265.002,0.000,41.914,3.169,0,0,300.000,300.000,0.000,0.000,4,-90.103932,-21.979648
3785296350.240000,0,1,262.708,0.000,41.899,3.167,0,0,300.000,300.000,0.000,0.000,4,-90.104603,-21.979648
3785296470.240000,0,1,260.568,0.000,41.879,3.167,0,0,300.000,300.000,0.000,0.000,4,-90.105946,-21.979648
3785296590.240000,0,1,258.578,0.000,41.862,3.166,0,0,300.000,300.000,0.000,0.000,4,-90.105409,-21.979648
3785296710.240000,0,1,256.703,0.000,41.846,3.166,0,0,300.000,300.000,0.000,0.000,4,-90.105543,-21.979648
3785296830.240000,0,1,254.915,0.000,41.831,3.164,0,0,300.000,300.000,0.000,0.000,4,-90.106214,-21.979648
3785296950.240000,0,1,253.226,0.000,41.816,3.165,0,0,300.000,300.000,0.000,0.000,4,-90.103798,-21.979648
3785297070.240000,0,1,251.598,0.000,41.801,3.163,0,0,300.000,300.000,0.000,0.000,4,203.372570,-21.979648
3785297190.240000,0,1,250.052,0.000,41.782,3.162,0,0,300.000,300.000,0.000,0.000,4,204.402501,-21.979648
3785297310.240000,0,1,248.562,0.000,41.765,3.161,0,0,300.000,300.000,0.000,0.000,4,204.523441,-21.979648
3785297430.240000,0,1,247.108,0.000,41.744,3.160,0,0,300.000,300.000,0.000,0.000,4,204.575790,-21.979648
3785297550.240000,0,1,245.712,0.000,41.724,3.161,0,0,300.000,300.000,0.000,0.000,4,204.599682,-21.979648
3785297754.740000,0,1,243.407,0.000,41.692,3.160,0,0,300.000,300.000,0.000,0.000,4,NaN,-21.979648