File: log/20230104.dat
[Header]
; Displex Transport Data File (default extension .dat)
; Copyright 2016, Hechang LEI, hlei@ruc.edu.cn. All rights reserved.
BYAPP, Displex, 2.0
INFO, 9T mag, Release 2.0.
INFO, Channel 1, Temperature Sensor
INFO, Sample 1 Length (cm): 0.000000; Width (cm): 0.000000; Thickness (cm): 0.000000.

[Data]
Timestamp(s),Field(Oe),Field Status,TempA(K),TempB(K),TempC(K),TempD(K),Ramp1,Ramp2,Setpoint1,Setpoint2,Output1(%),Output2(%),Temp Status
3755606554.954400,0,5,186.623,215.344,58.634,4.784,0,0,300.000,300.000,90.970,95.620,4
3755606764.954400,0,1,233.193,273.307,58.697,4.795,0,0,300.000,300.000,88.860,99.770,4
3755606974.954400,0,1,270.457,300.256,58.752,4.799,0,0,300.000,300.000,88.530,54.450,4
3755607184.954400,0,1,300.908,300.059,58.796,4.803,0,0,300.000,300.000,88.060,42.160,4
3755607394.954400,0,1,301.927,300.015,58.826,4.806,0,0,300.000,300.000,55.700,38.090,4
3755607604.954400,0,1,302.094,300.015,58.847,4.807,0,0,300.000,300.000,28.690,36.070,4
3755607814.954400,0,1,301.257,300.014,58.869,4.810,0,0,300.000,300.000,14.990,34.530,1
3755608024.954400,0,1,300.015,300.014,58.897,4.813,0,0,300.000,300.000,17.160,33.240,1
3755608234.954400,0,1,299.032,300.008,58.934,4.814,0,0,300.000,300.000,30.190,32.260,1
3755608444.954400,0,1,298.695,300.006,58.980,4.816,0,0,300.000,300.000,45.670,31.500,1
3755608654.954400,0,1,299.029,300.001,59.035,4.818,0,0,300.000,300.000,55.550,30.800,1
3755608864.954400,0,1,299.739,300.000,59.096,4.819,0,0,300.000,300.000,56.070,30.260,1
3755609074.954400,0,1,300.420,299.999,59.162,4.823,0,0,300.000,300.000,48.990,29.860,1
3755609284.954400,0,1,300.766,300.002,59.232,4.825,0,0,300.000,300.000,38.810,29.520,1
3755609494.954400,0,1,300.694,300.003,59.309,4.827,0,0,300.000,300.000,30.550,29.210,1
3755609704.954400,0,1,300.324,300.002,59.390,4.832,0,0,300.000,300.000,27.610,29.020,1
3755609914.954400,0,1,299.888,300.002,59.474,4.834,0,0,300.000,300.000,30.060,28.820,1
3755610124.954400,0,1,299.592,300.004,59.559,4.838,0,0,300.000,300.000,35.330,28.540,1
3755610334.954400,0,1,299.549,300.002,59.648,4.840,0,0,300.000,300.000,40.560,28.430,1
3755610544.954400,0,1,299.716,300.000,59.737,4.843,0,0,300.000,300.000,43.260,28.270,1
3755610754.954400,0,1,299.980,299.999,59.827,4.845,0,0,300.000,300.000,42.670,28.190,1
3755610964.954400,0,1,300.196,300.000,59.916,4.848,0,0,300.000,300.000,39.620,28.130,1
3755611174.954400,0,1,300.280,300.002,60.004,4.851,0,0,300.000,300.000,36.100,27.990,1
3755611384.954400,0,1,300.219,300.002,60.091,4.853,0,0,300.000,300.000,33.640,27.940,1
3755611594.954400,0,1,300.070,300.004,60.178,4.856,0,0,300.000,300.000,33.130,27.830,1
3755611804.954400,0,1,299.919,300.003,60.263,4.861,0,0,300.000,300.000,34.510,27.800,1
3755612014.954400,0,1,299.838,300.000,60.348,4.864,0,0,300.000,300.000,36.490,27.690,1
3755612224.954400,0,1,299.852,300.001,60.432,4.866,0,0,300.000,300.000,38.100,27.690,1
3755612434.954400,0,1,299.924,300.000,60.513,4.869,0,0,300.000,300.000,38.750,27.640,1
3755612644.954400,0,1,300.015,299.998,60.593,4.872,0,0,300.000,300.000,38.320,27.670,1
3755612854.954400,0,1,300.082,299.998,60.671,4.875,0,0,300.000,300.000,37.070,27.560,1
3755613064.954400,0,1,300.098,299.999,60.747,4.879,0,0,300.000,300.000,35.930,27.580,1
3755613274.954400,0,1,300.069,299.998,60.823,4.879,0,0,300.000,300.000,35.190,27.530,1
3755613484.954400,0,1,300.013,300.000,60.897,4.881,0,0,300.000,300.000,35.160,27.480,1
3755613694.954400,0,1,299.963,299.998,60.969,4.888,0,0,300.000,300.000,35.660,27.450,1
3755613904.954400,0,1,299.943,299.999,61.040,4.888,0,0,300.000,300.000,36.370,27.450,1
3755614114.954400,0,1,299.952,300.000,61.109,4.892,0,0,300.000,300.000,36.940,27.390,1
3755614324.954400,0,1,299.983,300.001,61.175,4.892,0,0,300.000,300.000,37.100,27.370,1
3755614534.954400,0,1,300.016,300.000,61.240,4.895,0,0,300.000,300.000,36.760,27.420,1
3755614744.954400,0,1,300.037,300.000,61.303,4.896,0,0,300.000,300.000,36.280,27.340,1
3755614954.954400,0,1,300.036,300.002,61.367,4.902,0,0,300.000,300.000,35.900,27.370,1
3755615164.954400,0,1,300.018,300.000,61.427,4.902,0,0,300.000,300.000,35.660,27.340,1
3755615374.954400,0,1,299.996,300.001,61.486,4.904,0,0,300.000,300.000,35.870,27.310,1
3755615584.954400,0,1,299.980,299.999,61.544,4.907,0,0,300.000,300.000,36.080,27.310,1
3755615794.954400,0,1,299.979,299.999,61.598,4.907,0,0,300.000,300.000,36.310,27.340,1
3755616004.954400,0,1,299.991,300.000,61.653,4.911,0,0,300.000,300.000,36.370,27.290,1
3755616214.954400,0,1,300.001,300.000,61.706,4.911,0,0,300.000,300.000,36.340,27.260,1
3755616424.954400,0,1,300.010,300.001,61.758,4.913,0,0,300.000,300.000,36.190,27.260,1
3755616634.954400,0,1,300.009,300.001,61.809,4.913,0,0,300.000,300.000,36.080,27.230,1
3755616844.954400,0,1,300.007,299.997,61.857,4.918,0,0,300.000,300.000,35.930,27.230,1
3755617054.954400,0,1,300.000,299.998,61.904,4.921,0,0,300.000,300.000,35.990,27.230,1
3755617264.954400,0,1,299.995,299.999,61.950,4.918,0,0,300.000,300.000,36.050,27.260,1
3755617474.954400,0,1,299.997,300.000,61.995,4.923,0,0,300.000,300.000,36.020,27.200,1
3755617684.954400,0,1,299.999,300.000,62.038,4.926,0,0,300.000,300.000,36.020,27.150,1
3755617894.954400,0,1,300.000,299.999,62.080,4.925,0,0,300.000,300.000,36.020,27.100,1
3755618104.954400,0,1,300.001,299.999,62.121,4.929,0,0,300.000,300.000,35.960,27.200,1
3755618314.954400,0,1,300.000,299.999,62.161,4.931,0,0,300.000,300.000,35.990,27.230,1
3755618524.954400,0,1,299.998,300.000,62.200,4.932,0,0,300.000,300.000,36.020,27.200,1
3755618734.954400,0,1,299.997,299.999,62.237,4.931,0,0,300.000,300.000,35.990,27.180,1
3755618944.954400,0,1,300.001,299.999,62.274,4.933,0,0,300.000,300.000,36.050,27.180,1
3755619154.954400,0,1,300.001,300.002,62.310,4.936,0,0,300.000,300.000,35.960,27.120,1
3755619364.954400,0,1,300.001,300.000,62.344,4.935,0,0,300.000,300.000,35.960,27.180,1
3755619574.954400,0,1,299.999,300.000,62.377,4.938,0,0,300.000,300.000,36.020,27.180,1
3755619784.954400,0,1,300.000,299.998,62.408,4.938,0,0,300.000,300.000,35.930,27.200,1
3755619994.954400,0,1,300.001,299.999,62.440,4.936,0,0,300.000,300.000,35.960,27.180,1
3755620204.954400,0,1,299.999,300.001,62.470,4.942,0,0,300.000,300.000,35.780,27.150,1
3755620414.954400,0,1,300.000,300.001,62.500,4.939,0,0,300.000,300.000,35.900,27.150,1
3755620624.954400,0,1,300.001,299.998,62.529,4.944,0,0,300.000,300.000,35.870,27.150,1
3755620834.954400,0,1,299.997,300.001,62.558,4.945,0,0,300.000,300.000,35.960,27.120,1
3755621044.954400,0,1,299.998,300.001,62.586,4.943,0,0,300.000,300.000,35.930,27.150,1
3755621254.954400,0,1,299.998,300.000,62.612,4.945,0,0,300.000,300.000,35.900,27.200,1
3755621464.954400,0,1,299.997,299.999,62.637,4.945,0,0,300.000,300.000,35.960,27.150,1
3755621674.954400,0,1,300.000,299.998,62.662,4.948,0,0,300.000,300.000,35.990,27.120,1
3755621884.954400,0,1,300.000,300.000,62.686,4.951,0,0,300.000,300.000,35.930,27.100,1
3755622094.954400,0,1,299.998,300.001,62.711,4.952,0,0,300.000,300.000,35.870,27.100,1
3755622304.954400,0,1,299.998,300.001,62.735,4.951,0,0,300.000,300.000,35.900,27.100,1
3755622514.954400,0,1,300.002,300.002,62.758,4.954,0,0,300.000,300.000,35.900,27.100,1
3755622724.954400,0,1,300.003,300.000,62.782,4.952,0,0,300.000,300.000,35.900,27.120,1
3755622934.954400,0,1,300.002,300.000,62.805,4.953,0,0,300.000,300.000,35.930,27.100,1
3755623144.954400,0,1,299.999,300.001,62.827,4.954,0,0,300.000,300.000,35.840,27.150,1
3755623354.954400,0,1,299.998,299.999,62.848,4.956,0,0,300.000,300.000,35.660,27.120,1
3755623564.954400,0,1,300.000,300.001,62.868,4.956,0,0,300.000,300.000,35.870,27.120,1
3755623774.954400,0,1,299.998,300.001,62.888,4.955,0,0,300.000,300.000,35.900,27.100,1
3755623984.954400,0,1,300.000,300.003,62.906,4.956,0,0,300.000,300.000,36.020,27.150,1
3755624194.954400,0,1,300.003,300.000,62.926,4.958,0,0,300.000,300.000,35.810,27.100,1
3755624404.954400,0,1,300.002,300.000,62.945,4.960,0,0,300.000,300.000,35.810,27.040,1
3755624614.954400,0,1,300.001,299.999,62.964,4.961,0,0,300.000,300.000,35.810,27.070,1
3755624824.954400,0,1,299.998,300.000,62.982,4.962,0,0,300.000,300.000,35.900,27.070,1
3755625034.954400,0,1,299.998,300.001,63.000,4.961,0,0,300.000,300.000,35.960,27.070,1
3755625244.954400,0,1,299.997,299.999,63.017,4.960,0,0,300.000,300.000,35.870,27.120,1
3755625454.954400,0,1,299.996,299.999,63.033,4.963,0,0,300.000,300.000,35.930,27.070,1
3755625664.954400,0,1,299.999,299.999,63.049,4.963,0,0,300.000,300.000,35.900,27.070,1
3755625874.954400,0,1,300.000,299.999,63.064,4.966,0,0,300.000,300.000,35.840,27.120,1
3755626084.954400,0,1,300.002,300.000,63.079,4.964,0,0,300.000,300.000,35.840,27.040,1
3755626294.954400,0,1,300.003,300.000,63.092,4.964,0,0,300.000,300.000,35.780,27.020,1
3755626504.954400,0,1,300.000,299.999,63.107,4.968,0,0,300.000,300.000,35.750,27.120,1
3755626714.954400,0,1,299.997,300.002,63.121,4.967,0,0,300.000,300.000,35.810,27.070,1
3755626924.954400,0,1,299.993,299.999,63.135,4.969,0,0,300.000,300.000,35.900,27.040,1
3755627134.954400,0,1,299.995,300.000,63.148,4.969,0,0,300.000,300.000,35.960,27.070,1
3755627344.954400,0,1,300.004,299.998,63.161,4.970,0,0,300.000,300.000,35.840,27.070,1
3755627554.954400,0,1,300.006,300.000,63.175,4.969,0,0,300.000,300.000,35.810,27.040,1
3755627764.954400,0,1,300.005,300.000,63.186,4.968,0,0,300.000,300.000,35.720,27.070,1
3755627974.954400,0,1,300.002,299.999,63.197,4.969,0,0,300.000,300.000,35.690,27.100,1
3755628184.954400,0,1,299.998,300.002,63.208,4.970,0,0,300.000,300.000,35.690,27.120,1
3755628394.954400,0,1,299.999,300.000,63.218,4.969,0,0,300.000,300.000,35.840,27.040,1
3755628604.954400,0,1,299.996,300.002,63.229,4.970,0,0,300.000,300.000,35.780,27.020,1
3755628814.954400,0,1,299.995,300.001,63.240,4.970,0,0,300.000,300.000,35.900,27.020,1
3755629024.954400,0,1,299.996,300.001,63.250,4.971,0,0,300.000,300.000,35.930,27.100,1
3755629234.954400,0,1,299.997,300.000,63.260,4.973,0,0,300.000,300.000,35.840,27.040,1
3755629444.954400,0,1,299.998,299.998,63.270,4.973,0,0,300.000,300.000,35.870,27.040,1
3755629654.954400,0,1,299.998,300.001,63.280,4.973,0,0,300.000,300.000,35.810,27.070,1
3755629864.954400,0,1,299.999,300.000,63.289,4.972,0,0,300.000,300.000,35.840,27.040,1
3755630074.954400,0,1,300.000,300.000,63.297,4.972,0,0,300.000,300.000,35.870,27.020,1
3755630284.954400,0,1,300.003,299.999,63.305,4.974,0,0,300.000,300.000,35.780,27.070,1
3755630494.954400,0,1,300.002,300.001,63.313,4.972,0,0,300.000,300.000,35.720,27.100,1
3755630704.954400,0,1,300.000,300.000,63.321,4.974,0,0,300.000,300.000,35.720,27.040,1
3755630914.954400,0,1,299.997,299.999,63.328,4.975,0,0,300.000,300.000,35.840,27.020,1
3755631124.954400,0,1,299.997,299.998,63.336,4.973,0,0,300.000,300.000,35.810,27.020,1
3755631334.954400,0,1,299.998,300.000,63.343,4.975,0,0,300.000,300.000,35.810,27.070,1
3755631544.954400,0,1,299.998,300.000,63.351,4.974,0,0,300.000,300.000,35.960,27.120,1
3755631754.954400,0,1,300.000,300.000,63.358,4.975,0,0,300.000,300.000,35.840,27.100,1
3755631964.954400,0,1,300.006,300.001,63.366,4.974,0,0,300.000,300.000,35.600,27.020,1
3755632174.954400,0,1,300.004,300.001,63.373,4.973,0,0,300.000,300.000,35.750,27.020,1
3755632384.954400,0,1,300.003,300.000,63.378,4.972,0,0,300.000,300.000,35.690,27.070,1
3755632594.954400,0,1,299.998,300.000,63.384,4.975,0,0,300.000,300.000,35.690,27.070,1
3755632804.954400,0,1,299.997,300.000,63.390,4.977,0,0,300.000,300.000,35.720,27.020,1
3755633014.954400,0,1,299.995,300.000,63.395,4.975,0,0,300.000,300.000,35.720,26.960,1
3755633224.954400,0,1,299.995,300.000,63.401,4.975,0,0,300.000,300.000,35.900,27.070,1
3755633434.954400,0,1,299.999,299.998,63.407,4.976,0,0,300.000,300.000,35.960,27.020,1
3755633644.954400,0,1,300.003,300.001,63.413,4.977,0,0,300.000,300.000,35.840,27.070,1
3755633854.954400,0,1,300.006,300.000,63.418,4.977,0,0,300.000,300.000,35.780,27.020,1
3755634064.954400,0,1,300.004,300.000,63.422,4.974,0,0,300.000,300.000,35.720,26.990,1
3755634274.954400,0,1,300.002,300.000,63.424,4.974,0,0,300.000,300.000,35.720,26.990,1
3755634484.954400,0,1,299.998,300.000,63.428,4.976,0,0,300.000,300.000,35.690,27.020,1
3755634694.954400,0,1,299.999,300.002,63.432,4.976,0,0,300.000,300.000,35.780,27.020,1
3755634904.954400,0,1,299.997,299.999,63.436,4.978,0,0,300.000,300.000,35.810,27.070,1
3755635114.954400,0,1,299.998,299.999,63.441,4.978,0,0,300.000,300.000,35.810,27.020,1
3755635324.954400,0,1,300.000,300.000,63.446,4.976,0,0,300.000,300.000,35.810,26.960,1
3755635534.954400,0,1,300.000,299.999,63.451,4.978,0,0,300.000,300.000,35.750,27.020,1
3755635744.954400,0,1,299.999,299.999,63.456,4.977,0,0,300.000,300.000,35.810,27.020,1
3755635954.954400,0,1,299.996,300.000,63.459,4.976,0,0,300.000,300.000,35.780,27.070,1
3755636164.954400,0,1,299.997,300.001,63.463,4.978,0,0,300.000,300.000,35.900,27.020,1
3755636374.954400,0,1,299.998,300.000,63.467,4.977,0,0,300.000,300.000,35.810,27.020,1
3755636584.954400,0,1,299.998,300.000,63.471,4.977,0,0,300.000,300.000,35.750,26.990,1
3755636794.954400,0,1,299.998,300.000,63.475,4.980,0,0,300.000,300.000,35.780,27.020,1
3755637004.954400,0,1,299.997,300.000,63.479,4.980,0,0,300.000,300.000,35.780,26.990,1
3755637214.954400,0,1,299.998,300.000,63.484,4.980,0,0,300.000,300.000,35.870,27.020,1
3755637424.954400,0,1,300.002,300.001,63.487,4.978,0,0,300.000,300.000,35.780,27.020,1
3755637634.954400,0,1,299.999,300.000,63.490,4.979,0,0,300.000,300.000,35.810,27.020,1
3755637844.954400,0,1,299.997,300.000,63.491,4.978,0,0,300.000,300.000,35.600,26.990,1
3755638054.954400,0,1,300.001,300.000,63.494,4.979,0,0,300.000,300.000,35.870,27.070,1
3755638264.954400,0,1,299.998,300.000,63.497,4.979,0,0,300.000,300.000,35.780,27.020,1
3755638474.954400,0,1,300.000,300.000,63.500,4.978,0,0,300.000,300.000,35.780,27.040,1
3755638684.954400,0,1,300.002,300.000,63.501,4.979,0,0,300.000,300.000,35.810,27.040,1
3755638894.954400,0,1,300.002,299.997,63.504,4.980,0,0,300.000,300.000,35.750,27.070,1
3755639104.954400,0,1,300.003,300.000,63.507,4.979,0,0,300.000,300.000,35.780,27.020,1
3755639314.954400,0,1,299.999,299.999,63.509,4.980,0,0,300.000,300.000,35.810,27.020,1
3755639524.954400,0,1,300.000,300.000,63.511,4.980,0,0,300.000,300.000,35.810,27.020,1
3755639734.954400,0,1,299.997,300.000,63.513,4.978,0,0,300.000,300.000,35.780,27.020,1
3755639944.954400,0,1,299.999,300.002,63.516,4.979,0,0,300.000,300.000,35.870,27.020,1
3755640154.954400,0,1,300.001,299.999,63.519,4.980,0,0,300.000,300.000,35.780,27.070,1
3755640358.451400,0,1,300.002,300.012,63.276,3.601,0,0,300.000,300.000,35.250,26.530,1
3755640568.451400,0,1,299.997,300.009,61.790,3.549,0,0,300.000,300.000,33.560,25.030,1
3755640832.513400,0,1,296.831,297.131,59.497,3.527,1,1,2.000,2.000,8.090,12.790,3
3755641042.513400,0,1,286.142,286.711,57.775,3.512,1,1,2.000,2.000,9.490,7.850,3
3755641252.513400,0,1,275.715,276.259,56.233,3.499,1,1,300.000,300.000,13.130,6.000,3
3755641462.513400,0,1,285.500,286.722,54.890,3.493,1,1,300.000,300.000,37.610,30.000,2
3755641672.513400,0,1,295.884,297.093,53.741,3.486,1,1,300.000,300.000,53.210,32.230,2
3755641882.513400,0,1,295.455,296.234,52.749,3.479,1,1,2.000,2.000,11.560,10.110,3
3755642092.513400,0,1,285.264,285.797,51.894,3.473,1,1,2.000,2.000,10.120,5.020,3
3755642302.513400,0,1,275.072,275.384,51.144,3.467,1,1,2.000,2.000,6.840,2.190,3
3755642512.513400,0,1,264.801,264.943,50.481,3.461,1,1,2.000,2.000,1.570,0.000,3
3755642722.513400,0,1,255.568,255.994,49.900,3.457,1,1,2.000,2.000,0.000,0.000,3
3755642932.513400,0,1,246.952,248.281,49.382,4.155,1,1,2.000,2.000,0.000,0.000,3
3755643142.513400,0,1,239.247,241.042,51.026,4.848,1,1,2.000,2.000,0.000,0.000,3
3755643352.513400,0,1,231.127,233.305,53.052,4.967,1,1,2.000,2.000,0.000,0.000,3
3755643562.513400,0,1,222.709,225.189,54.688,5.061,1,1,2.000,2.000,0.000,0.000,3
3755643772.513400,0,1,214.169,216.994,56.033,5.145,1,1,2.000,2.000,0.000,0.000,3
3755643982.513400,0,1,205.722,208.925,57.142,5.215,1,1,2.000,2.000,0.000,0.000,3
3755644192.513400,0,1,197.394,200.923,58.070,5.273,1,1,2.000,2.000,0.000,0.000,3
3755644402.513400,0,1,189.226,192.917,58.851,5.324,1,1,2.000,2.000,0.000,0.000,3
3755644612.513400,0,1,181.223,185.051,59.509,5.369,1,1,2.000,2.000,0.000,0.000,3
3755644822.513400,0,1,173.419,177.304,60.060,5.403,1,1,2.000,2.000,0.000,0.000,3
3755645032.513400,0,1,165.830,169.732,60.519,5.437,1,1,2.000,2.000,0.000,0.000,3
3755645242.513400,0,1,158.436,162.339,60.898,5.462,1,1,2.000,2.000,0.000,0.000,3
3755645452.513400,0,1,151.233,155.121,61.206,5.483,1,1,2.000,2.000,0.000,0.000,3
3755645662.513400,0,1,144.254,148.076,61.450,5.502,1,1,2.000,2.000,0.000,0.000,3
3755645872.513400,0,1,137.435,141.241,61.640,5.516,1,1,2.000,2.000,0.000,0.000,3
3755646082.513400,0,1,130.776,134.536,61.782,5.529,1,1,2.000,2.000,0.000,0.000,3
3755646292.513400,0,1,124.255,127.976,61.880,5.542,1,1,2.000,2.000,0.000,0.000,3
3755646502.513400,0,1,117.871,121.584,61.940,5.548,1,1,2.000,2.000,0.000,0.000,3
3755646712.513400,0,1,111.605,115.305,61.964,5.554,1,1,2.000,2.000,0.000,0.000,3
3755646922.513400,0,1,105.388,109.098,61.957,5.559,1,1,2.000,2.000,0.000,0.000,3
3755647132.513400,0,1,99.217,102.925,61.921,5.562,1,1,300.000,300.000,0.000,0.000,3
3755647342.513400,0,1,93.068,96.741,61.859,5.559,1,1,300.000,300.000,0.000,0.000,3
3755647552.513400,0,1,106.386,107.479,61.770,5.560,1,1,300.000,300.000,57.750,30.770,2
3755647762.513400,0,1,142.904,142.271,61.666,5.557,1,1,300.000,300.000,60.390,43.860,2
3755647972.513400,0,1,176.890,176.876,61.559,5.557,1,1,300.000,300.000,70.710,53.770,2
3755648182.513400,0,1,211.398,211.581,61.457,5.559,1,1,300.000,300.000,85.980,63.190,2
3755648392.513400,0,1,245.429,246.309,61.369,5.560,1,1,300.000,300.000,88.670,71.440,2
3755648602.513400,0,1,274.550,281.012,61.302,5.558,1,1,300.000,300.000,86.810,79.580,2
3755648812.513400,0,1,299.639,300.230,61.261,5.559,0,0,300.000,300.000,86.120,49.200,4
3755649022.513400,0,1,300.633,300.020,61.246,5.554,0,0,300.000,300.000,77.850,41.690,4
3755649232.513400,0,1,301.634,300.015,61.258,4.528,0,0,300.000,300.000,53.240,39.090,1
3755649442.513400,0,1,301.686,299.971,60.620,4.260,0,0,300.000,300.000,30.500,30.000,4
3755649652.513400,0,1,300.898,300.041,59.500,4.233,0,0,300.000,300.000,20.560,24.180,4
3755649862.513400,0,1,299.862,300.036,58.381,4.223,0,0,300.000,300.000,24.390,19.270,4
3755650072.513400,0,1,299.097,300.030,57.381,4.218,0,0,300.000,300.000,36.670,15.000,4
3755650282.513400,0,1,298.913,300.025,56.517,4.212,0,0,300.000,300.000,49.370,11.360,4
3755650492.513400,0,1,299.277,300.019,55.778,4.207,0,0,300.000,300.000,57.120,8.390,4
3755650702.513400,0,1,299.906,300.016,55.150,4.205,0,0,300.000,300.000,56.220,6.170,1
3755650912.513400,0,1,300.455,300.010,54.618,4.200,0,0,300.000,300.000,49.230,4.540,1
3755651122.513400,0,1,300.683,300.005,54.169,4.195,0,0,300.000,300.000,40.150,3.460,1
3755651332.513400,0,1,300.540,300.006,53.790,4.193,0,0,300.000,300.000,33.790,2.770,1
3755651542.513400,0,1,300.204,300.003,53.471,4.190,0,0,300.000,300.000,32.300,2.350,1
3755651752.513400,0,1,299.828,300.001,53.201,4.190,0,0,300.000,300.000,35.040,2.110,1
3755651962.513400,0,1,299.608,300.002,52.973,4.187,0,0,300.000,300.000,39.900,1.960,1
3755652172.513400,0,1,299.621,300.000,52.781,4.185,0,0,300.000,300.000,44.080,1.880,1
3755652382.513400,0,1,299.812,300.002,52.616,4.183,0,0,300.000,300.000,45.540,1.810,1
3755652592.513400,0,1,300.055,300.001,52.477,4.181,0,0,300.000,300.000,44.010,1.770,1
3755652802.513400,0,1,300.223,299.998,52.355,4.182,0,0,300.000,300.000,40.650,1.760,1
3755653012.513400,0,1,300.253,299.999,52.252,4.179,0,0,300.000,300.000,37.370,1.750,1
3755653222.513400,0,1,300.157,300.000,52.163,4.180,0,0,300.000,300.000,35.600,1.730,1
3755653432.513400,0,1,300.005,300.000,52.084,4.178,0,0,300.000,300.000,35.840,1.730,1
3755653642.513400,0,1,299.881,299.999,52.017,4.178,0,0,300.000,300.000,37.310,1.720,1
3755653852.513400,0,1,299.839,300.001,51.958,4.175,0,0,300.000,300.000,39.150,1.730,1
3755654062.513400,0,1,299.885,300.001,51.905,4.176,0,0,300.000,300.000,40.280,1.730,1
3755654272.513400,0,1,299.972,299.999,51.856,4.174,0,0,300.000,300.000,40.210,1.690,1
3755654482.513400,0,1,300.050,299.999,51.814,4.173,0,0,300.000,300.000,39.370,1.670,1
3755654692.513400,0,1,300.092,300.000,51.778,4.171,0,0,300.000,300.000,38.010,1.610,1
3755654902.513400,0,1,300.084,300.000,51.746,4.170,0,0,300.000,300.000,36.940,1.600,1
3755655112.513400,0,1,300.036,300.000,51.717,4.169,0,0,300.000,300.000,36.580,1.550,1
3755655322.513400,0,1,299.988,300.000,51.692,4.169,0,0,300.000,300.000,36.790,1.540,1
3755655532.513400,0,1,299.951,300.002,51.669,4.169,0,0,300.000,300.000,37.370,1.530,1
3755655742.513400,0,1,299.947,300.000,51.647,4.167,0,0,300.000,300.000,37.860,1.510,1
3755655952.513400,0,1,299.967,300.000,51.626,4.167,0,0,300.000,300.000,38.280,1.500,1
3755656162.513400,0,1,300.001,300.000,51.608,4.165,0,0,300.000,300.000,38.220,1.470,1
3755656372.513400,0,1,300.022,300.000,51.591,4.166,0,0,300.000,300.000,37.760,1.470,1
3755656582.513400,0,1,300.026,300.002,51.576,4.166,0,0,300.000,300.000,37.400,1.470,1
3755656792.513400,0,1,300.024,300.000,51.562,4.163,0,0,300.000,300.000,37.100,1.430,1
3755657002.513400,0,1,300.008,300.001,51.548,4.164,0,0,300.000,300.000,36.910,1.430,1
3755657212.513400,0,1,299.994,300.000,51.537,4.163,0,0,300.000,300.000,37.040,1.420,1
3755657422.513400,0,1,299.983,299.999,51.525,4.164,0,0,300.000,300.000,37.220,1.420,1
3755657632.513400,0,1,299.985,299.999,51.514,4.163,0,0,300.000,300.000,37.280,1.400,1
3755657842.513400,0,1,299.992,300.000,51.503,4.162,0,0,300.000,300.000,37.160,1.390,1
3755658052.513400,0,1,300.000,300.001,51.495,4.161,0,0,300.000,300.000,37.250,1.400,1
3755658262.513400,0,1,300.005,300.000,51.487,4.146,0,0,300.000,300.000,37.130,1.380,1
3755658544.643400,0,1,299.992,299.998,52.588,4.696,0,0,300.000,300.000,38.160,1.400,1
3755658730.159400,0,1,299.991,299.999,53.617,4.752,0,0,300.000,300.000,39.060,1.400,1
3755659197.720400,0,1,300.150,0.000,55.636,4.843,0,0,300.000,300.000,41.450,0.000,4
3755659407.720400,0,1,300.137,0.000,56.334,4.878,0,0,300.000,300.000,40.340,0.000,4
3755659617.720400,0,1,300.058,0.000,56.935,4.904,0,0,300.000,300.000,40.340,0.000,4
3755659827.720400,0,1,299.967,0.000,57.456,4.932,0,0,300.000,300.000,41.390,0.000,4
3755660037.720400,0,1,299.908,0.000,57.913,4.954,0,0,300.000,300.000,43.060,0.000,4
3755660247.720400,0,1,299.903,0.000,58.314,4.973,0,0,300.000,300.000,44.410,0.000,4
3755660457.720400,0,1,299.944,0.000,58.670,4.990,0,0,300.000,300.000,45.310,0.000,4
3755660667.720400,0,1,300.006,0.000,58.986,5.007,0,0,300.000,300.000,45.340,0.000,4
3755660877.720400,0,1,300.050,0.000,59.269,5.021,0,0,300.000,300.000,44.710,0.000,4
3755661087.720400,0,1,300.060,0.000,59.522,5.032,0,0,300.000,300.000,44.110,0.000,4
3755661297.720400,0,1,300.039,0.000,59.750,5.046,0,0,300.000,300.000,43.820,0.000,4
3755661507.720400,0,1,300.002,0.000,59.956,5.054,0,0,300.000,300.000,43.980,0.000,4
3755661717.720400,0,1,299.972,0.000,60.144,5.062,0,0,300.000,300.000,44.510,0.000,4
3755661927.720400,0,1,300.289,0.000,60.317,5.071,0,0,300.000,300.000,49.510,0.000,4
3755662137.720400,0,1,300.413,0.000,60.568,5.080,0,0,300.000,300.000,41.190,0.000,4
3755662347.720400,0,1,300.414,300.072,60.870,5.091,0,0,300.000,300.000,34.220,24.290,4
3755662557.720400,0,1,300.181,300.036,61.149,5.101,0,0,300.000,300.000,33.130,16.910,4
3755662767.720400,0,1,299.934,300.028,61.364,5.113,0,0,300.000,300.000,35.630,12.600,4
3755662969.610400,0,1,299.886,300.023,61.522,5.120,0,0,300.000,300.000,37.700,9.250,4
3755663163.027400,0,1,299.966,300.018,61.640,5.129,0,0,300.000,300.000,38.100,6.790,1
3755663373.027400,0,1,299.826,300.011,61.745,5.134,0,0,300.000,300.000,41.070,4.950,1
3755663617.919400,0,1,299.737,0.000,61.852,5.139,0,0,300.000,300.000,47.160,0.000,4
3755663982.176400,0,1,299.991,0.000,61.996,5.146,0,0,300.000,300.000,40.590,0.000,4
3755664192.176400,0,1,299.843,0.000,62.067,5.149,0,0,300.000,300.000,43.030,0.000,4
3755664402.176400,0,1,299.798,0.000,62.133,5.154,0,0,300.000,300.000,45.670,0.000,4
3755664612.176400,0,1,299.864,0.000,62.197,5.160,0,0,300.000,300.000,47.260,0.000,4
3755665005.527400,0,1,299.877,0.000,62.021,4.249,0,0,300.000,300.000,46.150,0.000,4
3755665221.143400,0,1,300.009,0.000,61.019,4.221,0,0,300.000,300.000,45.240,0.000,4
3755665431.143400,0,1,300.090,0.000,59.947,4.211,0,0,300.000,300.000,43.160,0.000,4
3755665640.433400,0,1,300.109,0.000,58.959,4.205,0,0,300.000,300.000,41.190,0.000,4
3755665915.888400,0,1,300.010,0.000,57.829,4.198,0,0,300.000,300.000,42.220,0.000,4
3755666125.888400,0,1,300.539,305.269,57.094,4.191,0,0,300.000,300.000,33.840,60.340,4
3755666335.888400,0,1,299.537,298.962,56.892,4.876,1,1,2.000,2.000,6.330,18.480,3
3755666545.888400,0,1,288.618,288.183,57.854,5.051,1,1,2.000,2.000,1.210,13.480,3
3755666755.888400,0,1,277.657,277.760,58.815,5.157,1,1,2.000,2.000,2.610,11.490,3
3755666965.888400,0,1,266.880,267.341,59.605,5.223,1,1,2.000,2.000,7.270,9.640,3
3755667175.888400,0,1,257.104,256.886,60.248,5.270,1,1,2.000,2.000,8.420,7.930,3
3755667385.888400,0,1,246.631,246.510,60.776,5.307,1,1,2.000,2.000,5.880,6.360,3
3755667595.888400,0,1,236.085,236.065,61.221,5.336,1,1,2.000,2.000,4.760,4.730,3
3755667805.888400,0,1,225.601,225.671,61.595,5.365,1,1,2.000,2.000,4.350,3.430,3
3755668015.888400,0,1,215.244,215.310,61.912,5.388,1,1,2.000,2.000,3.610,2.140,3
3755668225.888400,0,1,204.855,204.894,62.182,5.406,1,1,2.000,2.000,2.530,0.900,3
3755668435.888400,0,1,194.466,194.534,62.408,5.422,1,1,2.000,2.000,1.110,0.000,3
3755668645.888400,0,1,184.202,184.941,62.594,5.435,1,1,2.000,2.000,0.000,0.000,3
3755668855.888400,0,1,174.735,176.050,62.745,5.445,1,1,2.000,2.000,0.000,0.000,3
3755669065.888400,0,1,166.061,167.746,62.861,5.453,1,1,2.000,2.000,0.000,0.000,3
3755669275.888400,0,1,157.887,159.838,62.947,5.462,1,1,2.000,2.000,0.000,0.000,3
3755669485.888400,0,1,150.188,152.309,63.003,5.469,1,1,2.000,2.000,0.000,0.000,3
3755669695.888400,0,1,142.864,145.157,63.032,5.471,1,1,2.000,2.000,0.000,0.000,3
3755669905.888400,0,1,135.884,138.262,63.037,5.476,1,1,2.000,2.000,0.000,0.000,3
3755670115.888400,0,1,129.132,131.567,63.020,5.477,1,1,2.000,2.000,0.000,0.000,3
3755670325.888400,0,1,122.579,125.046,62.981,5.481,1,1,2.000,2.000,0.000,0.000,3
3755670535.888400,0,1,116.207,118.672,62.921,5.476,1,1,2.000,2.000,0.000,0.000,3
3755670745.888400,0,1,109.939,112.382,62.840,5.471,1,1,2.000,2.000,0.000,0.000,3
3755670955.888400,0,1,103.829,106.284,62.740,5.472,1,1,2.000,2.000,0.000,0.000,3
3755671165.888400,0,1,97.743,100.228,62.622,5.471,1,1,2.000,2.000,0.000,0.000,3
3755671375.888400,0,1,91.658,94.134,62.486,5.470,1,1,2.000,2.000,0.000,0.000,3
3755671585.888400,0,1,85.565,88.117,62.335,4.783,1,1,2.000,2.000,0.000,0.000,3
3755671795.888400,0,1,79.941,82.587,61.723,4.280,1,1,2.000,2.000,0.000,0.000,3
3755672005.888400,0,1,75.093,77.648,60.580,4.252,1,1,2.000,2.000,0.000,0.000,3
3755672215.888400,0,1,70.584,73.037,59.412,4.237,1,1,2.000,2.000,0.000,0.000,3
3755672425.888400,0,1,66.207,68.538,58.321,4.230,0,0,2.000,2.000,0.000,0.000,4
3755672635.888400,0,1,61.825,64.007,57.328,4.224,0,0,2.000,2.000,0.000,0.000,4
3755672845.888400,0,1,57.268,59.377,56.420,4.218,0,0,2.000,2.000,0.000,0.000,4
3755673055.888400,0,1,52.409,54.423,55.590,4.213,0,0,2.000,2.000,0.000,0.000,4
3755673265.888400,0,1,47.085,48.955,54.833,4.207,0,0,2.000,2.000,0.000,0.000,4
3755673475.888400,0,1,40.858,42.500,54.126,4.202,0,0,2.000,2.000,0.000,0.000,4
3755673685.888400,0,1,32.830,33.990,53.465,4.199,0,0,2.000,2.000,0.000,0.000,4
3755673895.888400,0,1,18.134,17.512,52.834,4.192,0,0,2.000,2.000,0.000,0.000,4
3755674105.888400,0,1,5.126,4.611,52.199,4.178,0,0,2.000,2.000,0.000,0.000,4
3755674315.888400,0,1,3.136,2.653,51.544,4.165,0,0,2.000,2.000,0.000,0.000,4
3755674525.888400,0,1,2.775,2.318,50.898,4.075,0,0,2.000,2.000,0.000,0.000,4
3755674735.888400,0,1,2.701,2.241,50.137,3.946,0,0,2.000,2.000,0.000,0.000,4
3755674945.888400,0,1,2.583,2.143,49.271,3.823,0,0,2.000,2.000,0.000,0.000,4
3755675155.888400,0,1,2.486,2.077,48.334,3.704,0,0,2.000,2.000,0.000,0.000,4
3755675365.888400,0,1,2.146,2.000,47.319,3.588,0,0,2.000,2.000,0.000,0.020,1
3755675575.888400,0,1,2.028,2.000,46.252,3.492,0,0,2.000,2.000,0.010,0.030,1
3755675785.888400,0,1,2.036,2.000,45.193,3.433,0,0,2.000,2.000,0.130,0.030,1
3755675995.888400,0,1,2.031,2.000,44.215,3.396,0,0,2.000,2.000,0.160,0.030,1
3755676205.888400,0,1,2.025,1.999,43.337,3.377,0,0,2.000,2.000,0.150,0.030,1
3755676415.888400,0,1,2.034,1.999,42.577,3.363,0,0,2.000,2.000,0.000,0.030,1
3755676625.888400,0,1,2.020,2.000,41.923,3.353,0,0,2.000,2.000,0.150,0.020,1
3755676835.888400,0,1,2.028,2.000,41.360,3.346,0,0,2.000,2.000,0.080,0.020,1
3755677045.888400,0,1,2.018,2.001,40.874,3.342,0,0,2.000,2.000,0.170,0.030,1
3755677255.888400,0,1,2.019,1.999,40.447,3.337,0,0,2.000,2.000,0.190,0.030,1
3755677465.888400,0,1,2.029,2.001,40.069,3.334,0,0,2.000,2.000,0.060,0.030,1
3755677675.888400,0,1,2.026,2.000,39.728,3.330,0,0,2.000,2.000,0.000,0.030,1
3755677885.888400,0,1,2.020,2.000,39.423,3.326,0,0,2.000,2.000,0.220,0.030,1
3755678095.888400,0,1,2.025,2.000,39.140,3.324,0,0,2.000,2.000,0.000,0.030,1
3755678305.888400,0,1,2.031,2.001,38.881,3.320,0,0,2.000,2.000,0.010,0.030,1
3755678515.888400,0,1,2.025,2.000,38.638,3.317,0,0,2.000,2.000,0.080,0.030,1
3755678725.888400,0,1,2.026,2.000,38.410,3.314,0,0,2.000,2.000,0.000,0.030,1
3755678935.888400,0,1,2.025,2.000,38.199,3.311,0,0,2.000,2.000,0.000,0.030,1
3755679145.888400,0,1,2.017,2.000,38.002,3.309,0,0,2.000,2.000,0.220,0.030,1
3755679355.888400,0,1,2.029,2.000,37.819,3.304,0,0,2.000,2.000,0.000,0.030,1
3755679565.888400,0,1,2.022,1.999,37.645,3.304,0,0,2.000,2.000,0.030,0.030,1
3755679775.888400,0,1,2.028,2.000,37.480,3.302,0,0,2.000,2.000,0.170,0.030,1
3755679985.888400,0,1,2.019,2.000,37.323,3.301,0,0,2.000,2.000,0.080,0.030,1
3755680195.888400,0,1,2.031,2.000,37.178,3.299,0,0,2.000,2.000,0.000,0.030,1
3755680405.888400,0,1,2.016,2.000,37.043,3.296,0,0,2.000,2.000,0.240,0.030,1
3755680615.888400,0,1,2.032,2.000,36.916,3.294,0,0,2.000,2.000,0.000,0.030,1
3755680825.888400,0,1,2.019,2.000,36.795,3.292,0,0,2.000,2.000,0.230,0.030,1
3755681035.888400,0,1,2.033,2.000,36.682,3.291,0,0,2.000,2.000,0.000,0.030,1
3755681245.888400,0,1,2.023,2.000,36.577,3.288,0,0,2.000,2.000,0.130,0.030,1
3755681455.888400,0,1,2.019,2.000,36.481,3.286,0,0,2.000,2.000,0.230,0.030,1
3755681665.888400,0,1,2.023,2.000,36.390,3.286,0,0,2.000,2.000,0.030,0.030,1
3755681875.888400,0,1,2.029,2.000,36.305,3.286,0,0,2.000,2.000,0.000,0.030,1
3755682085.888400,0,1,2.022,2.000,36.227,3.285,0,0,2.000,2.000,0.000,0.030,1
3755682295.888400,0,1,2.022,2.000,36.156,3.284,0,0,2.000,2.000,0.020,0.030,1
3755682505.888400,0,1,2.024,2.000,36.092,3.282,0,0,2.000,2.000,0.000,0.030,1
3755682738.561400,0,1,2.019,2.000,36.026,3.282,0,0,2.000,2.000,0.100,0.030,1
3755682948.561400,0,1,2.018,2.000,35.970,3.280,0,0,2.000,2.000,0.220,0.030,1
3755683158.561400,0,1,2.017,1.999,35.919,3.279,0,0,2.000,2.000,0.250,0.030,1
3755683368.561400,0,1,1.996,2.000,35.547,2.957,0,0,2.000,2.000,0.260,0.030,1
3755683578.561400,0,1,1.999,1.999,35.030,2.985,0,0,2.000,2.000,0.200,0.030,1
3755683788.561400,0,1,1.998,2.000,34.783,3.014,0,0,2.000,2.000,0.300,0.030,1
3755683998.561400,0,1,2.001,2.000,34.650,3.034,0,0,2.000,2.000,0.290,0.030,1
3755684208.561400,0,1,2.000,2.000,34.575,3.048,0,0,2.000,2.000,0.280,0.030,1
3755684418.561400,0,1,2.039,2.000,34.616,3.054,0,0,2.000,2.000,0.170,0.020,1
3755684628.561400,0,1,2.038,2.000,34.725,3.055,0,0,2.000,2.000,0.080,0.010,1
3755684838.561400,0,1,2.020,1.999,34.810,3.055,0,0,2.000,2.000,0.210,0.010,1
3755685048.561400,0,1,2.021,2.000,34.876,3.053,0,0,2.000,2.000,0.220,0.010,1
3755685258.561400,0,1,2.019,2.000,34.928,3.053,0,0,2.000,2.000,0.110,0.010,1
3755685468.561400,0,1,2.015,2.000,34.970,3.051,0,0,2.000,2.000,0.210,0.010,1
3755685678.561400,0,1,2.021,2.000,35.005,3.053,0,0,2.000,2.000,0.000,0.010,1
3755685888.561400,0,1,2.020,2.000,35.037,3.053,0,0,2.000,2.000,0.080,0.010,1
3755686098.561400,0,1,2.018,2.000,35.063,3.054,0,0,2.000,2.000,0.180,0.010,1
3755686308.561400,0,1,2.025,2.000,35.081,3.051,0,0,2.000,2.000,0.000,0.010,1
3755686518.561400,0,1,2.024,2.000,35.096,3.051,0,0,2.000,2.000,0.060,0.010,1
3755686728.561400,0,1,2.015,2.000,35.110,3.051,0,0,2.000,2.000,0.190,0.010,1
3755686938.561400,0,1,2.013,2.000,35.119,3.051,0,0,2.000,2.000,0.220,0.010,1
3755687148.561400,0,1,2.014,2.000,35.129,3.050,0,0,2.000,2.000,0.210,0.010,1
3755687358.561400,0,1,2.015,2.000,35.137,3.050,0,0,2.000,2.000,0.170,0.010,1
3755687568.561400,0,1,2.022,2.000,35.142,3.050,0,0,2.000,2.000,0.090,0.010,1
3755687778.561400,0,1,2.022,2.000,35.150,3.050,0,0,2.000,2.000,0.000,0.010,1
3755687988.561400,0,1,2.013,2.000,35.156,3.050,0,0,2.000,2.000,0.090,0.010,1
3755688198.561400,0,1,2.012,2.000,35.160,3.049,0,0,2.000,2.000,0.180,0.010,1
3755688408.561400,0,1,2.024,2.000,35.160,3.048,0,0,2.000,2.000,0.000,0.010,1
3755688618.561400,0,1,2.012,2.000,35.163,3.047,0,0,2.000,2.000,0.050,0.010,1
3755688828.561400,0,1,2.013,2.000,35.166,3.048,0,0,2.000,2.000,0.210,0.010,1
3755689038.561400,0,1,2.022,2.000,35.167,3.048,0,0,2.000,2.000,0.000,0.010,1
3755689248.561400,0,1,2.011,2.000,35.168,3.047,0,0,2.000,2.000,0.080,0.010,1
3755689458.561400,0,1,2.014,2.000,35.170,3.047,0,0,2.000,2.000,0.130,0.010,1
3755689668.561400,0,1,2.019,2.001,35.172,3.048,0,0,2.000,2.000,0.000,0.010,1
3755689878.561400,0,1,2.011,2.000,35.174,3.047,0,0,2.000,2.000,0.210,0.010,1
3755690088.561400,0,1,2.019,2.000,35.176,3.046,0,0,2.000,2.000,0.000,0.010,1
3755690298.561400,0,1,2.010,2.000,35.175,3.047,0,0,2.000,2.000,0.180,0.010,1
3755690508.561400,0,1,2.022,2.000,35.176,3.046,0,0,2.000,2.000,0.040,0.010,1
3755690718.561400,0,1,2.018,2.000,35.175,3.046,0,0,2.000,2.000,0.010,0.010,1
3755690928.561400,0,1,2.012,2.000,35.175,3.046,0,0,2.000,2.000,0.200,0.010,1
3755691138.561400,0,1,2.020,2.000,35.174,3.047,0,0,2.000,2.000,0.010,0.010,1
3755691348.561400,0,1,2.016,2.000,35.176,3.048,0,0,2.000,2.000,0.000,0.010,1
3755691558.561400,0,1,2.010,2.000,35.176,3.050,0,0,2.000,2.000,0.180,0.010,1
3755691768.561400,0,1,2.015,2.000,35.177,3.047,0,0,2.000,2.000,0.170,0.010,1
3755691978.561400,0,1,2.019,2.000,35.179,3.048,0,0,2.000,2.000,0.000,0.010,1
3755692188.561400,0,1,2.008,2.000,35.180,3.048,0,0,2.000,2.000,0.190,0.010,1
3755692398.561400,0,1,2.017,2.000,35.181,3.049,0,0,2.000,2.000,0.070,0.010,1
3755692608.561400,0,1,2.023,2.000,35.180,3.049,0,0,2.000,2.000,0.000,0.010,1
3755692818.561400,0,1,2.010,2.000,35.180,3.048,0,0,2.000,2.000,0.190,0.010,1
3755693028.561400,0,1,2.018,2.000,35.183,3.049,0,0,2.000,2.000,0.100,0.010,1
3755693238.561400,0,1,2.020,2.000,35.183,3.049,0,0,2.000,2.000,0.000,0.010,1
3755693448.561400,0,1,2.011,2.000,35.182,3.048,0,0,2.000,2.000,0.140,0.010,1
3755693658.561400,0,1,2.021,1.999,35.182,3.048,0,0,2.000,2.000,0.180,0.010,1
3755693868.561400,0,1,2.017,2.000,35.181,3.047,0,0,2.000,2.000,0.000,0.010,1
3755694078.561400,0,1,2.010,2.000,35.182,3.047,0,0,2.000,2.000,0.210,0.010,1
3755694288.561400,0,1,2.024,2.000,35.182,3.046,0,0,2.000,2.000,0.060,0.010,1
3755694498.561400,0,1,2.023,2.000,35.181,3.046,0,0,2.000,2.000,0.010,0.010,1
3755694708.561400,0,1,2.010,2.000,35.180,3.046,0,0,2.000,2.000,0.210,0.010,1
3755694918.561400,0,1,2.015,2.000,35.179,3.047,0,0,2.000,2.000,0.120,0.010,1
3755695128.561400,0,1,2.022,2.000,35.179,3.047,0,0,2.000,2.000,0.000,0.010,1
3755695338.561400,0,1,2.005,2.000,35.180,3.047,0,0,2.000,2.000,0.150,0.010,1
3755695548.561400,0,1,2.017,2.000,35.179,3.046,0,0,2.000,2.000,0.180,0.010,1
3755695758.561400,0,1,2.023,2.000,35.179,3.046,0,0,2.000,2.000,0.000,0.010,1
3755695968.561400,0,1,2.017,2.000,35.179,3.045,0,0,2.000,2.000,0.090,0.010,1
3755696178.561400,0,1,2.018,2.000,35.178,3.046,0,0,2.000,2.000,0.120,0.010,1
3755696388.561400,0,1,2.021,2.000,35.177,3.046,0,0,2.000,2.000,0.000,0.010,1
3755696598.561400,0,1,2.013,2.000,35.176,3.045,0,0,2.000,2.000,0.090,0.010,1
3755696808.561400,0,1,2.013,2.000,35.175,3.045,0,0,2.000,2.000,0.150,0.010,1
3755697018.561400,0,1,2.021,2.000,35.174,3.046,0,0,2.000,2.000,0.030,0.010,1
3755697228.561400,0,1,2.013,2.000,35.174,3.047,0,0,2.000,2.000,0.020,0.010,1
3755697438.561400,0,1,2.013,2.000,35.176,3.045,0,0,2.000,2.000,0.160,0.010,1
3755697648.561400,0,1,2.022,1.999,35.175,3.048,0,0,2.000,2.000,0.000,0.010,1
3755697858.561400,0,1,2.013,2.000,35.175,3.048,0,0,2.000,2.000,0.000,0.010,1
3755698068.561400,0,1,2.012,1.999,35.175,3.049,0,0,2.000,2.000,0.220,0.010,1
3755698278.561400,0,1,2.018,2.000,35.175,3.047,0,0,2.000,2.000,0.080,0.010,1
3755698488.561400,0,1,2.021,2.000,35.175,3.047,0,0,2.000,2.000,0.000,0.010,1
3755698698.561400,0,1,2.007,2.000,35.176,3.047,0,0,2.000,2.000,0.160,0.010,1
3755698908.561400,0,1,2.013,2.000,35.174,3.047,0,0,2.000,2.000,0.210,0.010,1
3755699118.561400,0,1,2.021,2.000,35.174,3.046,0,0,2.000,2.000,0.000,0.010,1
3755699328.561400,0,1,2.016,2.000,35.174,3.045,0,0,2.000,2.000,0.010,0.010,1
3755699538.561400,0,1,2.011,2.000,35.173,3.043,0,0,2.000,2.000,0.200,0.010,1
3755699748.561400,0,1,2.024,2.000,35.171,3.045,0,0,2.000,2.000,0.000,0.010,1
3755699958.561400,0,1,2.017,2.000,35.171,3.047,0,0,2.000,2.000,0.040,0.010,1
3755700168.561400,0,1,2.011,2.000,35.173,3.044,0,0,2.000,2.000,0.190,0.010,1
3755700378.561400,0,1,2.024,2.000,35.172,3.045,0,0,2.000,2.000,0.010,0.010,1
3755700588.561400,0,1,2.018,2.000,35.173,3.042,0,0,2.000,2.000,0.000,0.010,1
3755700798.561400,0,1,2.012,2.000,35.171,3.044,0,0,2.000,2.000,0.210,0.010,1
3755701008.561400,0,1,2.021,2.000,35.172,3.044,0,0,2.000,2.000,0.020,0.010,1
3755701218.561400,0,1,2.019,2.000,35.172,3.045,0,0,2.000,2.000,0.000,0.010,1
3755701428.561400,0,1,2.010,2.000,35.173,3.047,0,0,2.000,2.000,0.140,0.010,1
3755701638.561400,0,1,2.012,2.000,35.173,3.045,0,0,2.000,2.000,0.190,0.010,1
3755701848.561400,0,1,2.022,2.000,35.174,3.043,0,0,2.000,2.000,0.000,0.010,1
3755702058.561400,0,1,2.016,2.000,35.172,3.045,0,0,2.000,2.000,0.000,0.010,1
3755702268.561400,0,1,2.013,2.001,35.173,3.043,0,0,2.000,2.000,0.130,0.010,1
3755702478.561400,0,1,2.014,2.000,35.171,3.045,0,0,2.000,2.000,0.190,0.010,1
3755702688.561400,0,1,2.016,2.000,35.171,3.046,0,0,2.000,2.000,0.050,0.010,1
3755702898.561400,0,1,2.024,2.000,35.172,3.043,0,0,2.000,2.000,0.000,0.010,1
3755703108.561400,0,1,2.015,2.000,35.170,3.046,0,0,2.000,2.000,0.000,0.010,1
3755703318.561400,0,1,2.012,2.000,35.171,3.045,0,0,2.000,2.000,0.150,0.010,1
3755703528.561400,0,1,2.012,2.000,35.172,3.045,0,0,2.000,2.000,0.220,0.010,1
3755703738.561400,0,1,2.022,2.000,35.172,3.042,0,0,2.000,2.000,0.000,0.010,1
3755703948.561400,0,1,2.018,2.000,35.171,3.041,0,0,2.000,2.000,0.000,0.010,1
3755704158.561400,0,1,2.009,2.000,35.169,3.043,0,0,2.000,2.000,0.210,0.010,1
3755704368.561400,0,1,2.023,2.001,35.170,3.044,0,0,2.000,2.000,0.060,0.010,1
3755704578.561400,0,1,2.016,2.000,35.171,3.045,0,0,2.000,2.000,0.020,0.010,1
3755704788.561400,0,1,2.008,1.999,35.170,3.046,0,0,2.000,2.000,0.180,0.010,1
3755704998.561400,0,1,2.018,2.000,35.171,3.041,0,0,2.000,2.000,0.000,0.010,1
3755705208.561400,0,1,2.019,2.000,35.170,3.044,0,0,2.000,2.000,0.000,0.010,1
3755705418.561400,0,1,2.014,2.000,35.171,3.045,0,0,2.000,2.000,0.060,0.010,1
3755705628.561400,0,1,2.012,2.000,35.171,3.045,0,0,2.000,2.000,0.220,0.010,1
3755705838.561400,0,1,2.023,2.000,35.170,3.045,0,0,2.000,2.000,0.020,0.010,1
3755706048.561400,0,1,2.021,2.000,35.170,3.046,0,0,2.000,2.000,0.000,0.010,1
3755706258.561400,0,1,2.013,2.000,35.170,3.044,0,0,2.000,2.000,0.160,0.010,1
3755706468.561400,0,1,2.016,2.000,35.170,3.046,0,0,2.000,2.000,0.180,0.010,1
3755706678.561400,0,1,2.027,2.000,35.171,3.044,0,0,2.000,2.000,0.000,0.010,1
3755706888.561400,0,1,2.018,2.000,35.170,3.045,0,0,2.000,2.000,0.030,0.010,1
3755707098.561400,0,1,2.011,2.000,35.172,3.043,0,0,2.000,2.000,0.140,0.010,1
3755707308.561400,0,1,2.016,2.000,35.172,3.045,0,0,2.000,2.000,0.180,0.010,1
3755707518.561400,0,1,2.024,2.000,35.172,3.044,0,0,2.000,2.000,0.060,0.010,1
3755707728.561400,0,1,2.027,2.000,35.172,3.045,0,0,2.000,2.000,0.000,0.010,1
3755707938.561400,0,1,2.014,2.000,35.172,3.045,0,0,2.000,2.000,0.160,0.010,1
3755708148.561400,0,1,2.014,2.000,35.170,3.045,0,0,2.000,2.000,0.220,0.010,1
3755708358.561400,0,1,2.021,2.000,35.173,3.045,0,0,2.000,2.000,0.010,0.010,1
3755708568.561400,0,1,2.023,2.000,35.173,3.046,0,0,2.000,2.000,0.000,0.010,1
3755708778.561400,0,1,2.018,2.000,35.171,3.044,0,0,2.000,2.000,0.020,0.010,1
3755708988.561400,0,1,2.009,2.000,35.169,3.046,0,0,2.000,2.000,0.210,0.010,1
3755709198.561400,0,1,2.018,2.000,35.170,3.045,0,0,2.000,2.000,0.030,0.010,1
3755709408.561400,0,1,2.024,2.000,35.171,3.046,0,0,2.000,2.000,0.000,0.010,1
3755709618.561400,0,1,2.019,2.000,35.171,3.046,0,0,2.000,2.000,0.040,0.010,1
3755709828.561400,0,1,2.010,2.000,35.170,3.044,0,0,2.000,2.000,0.180,0.010,1
3755710038.561400,0,1,2.017,2.000,35.170,3.046,0,0,2.000,2.000,0.050,0.010,1
3755710248.561400,0,1,2.026,2.000,35.169,3.046,0,0,2.000,2.000,0.000,0.010,1
3755710458.561400,0,1,2.016,2.000,35.168,3.046,0,0,2.000,2.000,0.000,0.010,1
3755710668.561400,0,1,2.015,2.000,35.168,3.044,0,0,2.000,2.000,0.180,0.010,1
3755710878.561400,0,1,2.016,2.000,35.169,3.046,0,0,2.000,2.000,0.180,0.010,1
3755711088.561400,0,1,2.025,2.000,35.170,3.045,0,0,2.000,2.000,0.030,0.010,1
3755711298.561400,0,1,2.017,2.000,35.168,3.047,0,0,2.000,2.000,0.000,0.010,1
3755711508.561400,0,1,2.017,2.000,35.169,3.045,0,0,2.000,2.000,0.080,0.010,1
3755711718.561400,0,1,2.010,2.000,35.168,3.044,0,0,2.000,2.000,0.170,0.010,1
3755711928.561400,0,1,2.023,2.000,35.168,3.044,0,0,2.000,2.000,0.000,0.010,1
3755712138.561400,0,1,2.024,2.000,35.167,3.044,0,0,2.000,2.000,0.000,0.010,1
3755712348.561400,0,1,2.010,2.000,35.166,3.043,0,0,2.000,2.000,0.210,0.010,1
3755712558.561400,0,1,2.021,2.000,35.166,3.046,0,0,2.000,2.000,0.120,0.010,1
3755712768.561400,0,1,2.024,2.001,35.165,3.045,0,0,2.000,2.000,0.000,0.010,1
3755712978.561400,0,1,2.015,2.000,35.165,3.044,0,0,2.000,2.000,0.100,0.010,1
3755713188.561400,0,1,2.011,2.001,35.165,3.045,0,0,2.000,2.000,0.200,0.010,1
3755713398.561400,0,1,2.018,2.000,35.166,3.042,0,0,2.000,2.000,0.150,0.010,1
3755713608.561400,0,1,2.020,2.000,35.167,3.043,0,0,2.000,2.000,0.000,0.010,1
3755713818.561400,0,1,2.017,2.000,35.167,3.041,0,0,2.000,2.000,0.000,0.010,1
3755714028.561400,0,1,2.011,2.000,35.165,3.043,0,0,2.000,2.000,0.200,0.010,1
3755714238.561400,0,1,2.019,2.000,35.164,3.045,0,0,2.000,2.000,0.110,0.010,1
3755714448.561400,0,1,2.028,2.000,35.165,3.045,0,0,2.000,2.000,0.000,0.010,1
3755714658.561400,0,1,2.021,2.000,35.165,3.044,0,0,2.000,2.000,0.000,0.010,1
3755714868.561400,0,1,2.010,2.000,35.166,3.044,0,0,2.000,2.000,0.170,0.010,1
3755715078.561400,0,1,2.012,2.001,35.166,3.044,0,0,2.000,2.000,0.210,0.010,1
3755715288.561400,0,1,2.020,2.000,35.164,3.042,0,0,2.000,2.000,0.040,0.010,1
3755715498.561400,0,1,2.016,2.001,35.163,3.042,0,0,2.000,2.000,0.000,0.010,1
3755715708.561400,0,1,2.013,2.000,35.161,3.042,0,0,2.000,2.000,0.170,0.010,1
3755715918.561400,0,1,2.022,2.000,35.161,3.043,0,0,2.000,2.000,0.110,0.010,1
3755716128.561400,0,1,2.023,2.000,35.162,3.043,0,0,2.000,2.000,0.000,0.010,1
3755716338.561400,0,1,2.012,2.000,35.161,3.043,0,0,2.000,2.000,0.170,0.010,1
3755716548.561400,0,1,2.016,2.000,35.161,3.042,0,0,2.000,2.000,0.190,0.010,1
3755716758.561400,0,1,2.026,2.000,35.160,3.040,0,0,2.000,2.000,0.000,0.010,1
3755716968.561400,0,1,2.020,2.000,35.159,3.042,0,0,2.000,2.000,0.000,0.010,1
3755717178.561400,0,1,2.015,2.000,35.157,3.043,0,0,2.000,2.000,0.130,0.010,1
3755717388.561400,0,1,2.015,2.000,35.158,3.042,0,0,2.000,2.000,0.200,0.010,1
3755717598.561400,0,1,2.020,2.000,35.156,3.043,0,0,2.000,2.000,0.040,0.010,1
3755717808.561400,0,1,2.023,2.000,35.158,3.041,0,0,2.000,2.000,0.000,0.010,1
3755718018.561400,0,1,2.016,2.000,35.158,3.040,0,0,2.000,2.000,0.210,0.010,1
3755718228.561400,0,1,2.015,2.000,35.156,3.040,0,0,2.000,2.000,0.100,0.010,1
3755718438.561400,0,1,2.022,2.000,35.154,3.040,0,0,2.000,2.000,0.000,0.010,1
3755718648.561400,0,1,2.017,2.000,35.153,3.040,0,0,2.000,2.000,0.000,0.010,1
3755718858.561400,0,1,2.009,2.000,35.154,3.041,0,0,2.000,2.000,0.180,0.010,1
3755719068.561400,0,1,2.022,2.000,35.154,3.040,0,0,2.000,2.000,0.040,0.010,1
3755719278.561400,0,1,2.011,2.000,35.154,3.040,0,0,2.000,2.000,0.000,0.010,1
3755719488.561400,0,1,2.012,2.000,35.152,3.039,0,0,2.000,2.000,0.100,0.010,1
3755719698.561400,0,1,2.013,2.000,35.151,3.038,0,0,2.000,2.000,0.170,0.010,1
3755719908.561400,0,1,2.025,2.000,35.150,3.038,0,0,2.000,2.000,0.000,0.010,1
3755720118.561400,0,1,2.016,2.000,35.151,3.038,0,0,2.000,2.000,0.000,0.010,1
3755720328.561400,0,1,2.009,2.000,35.149,3.039,0,0,2.000,2.000,0.210,0.010,1
3755720538.561400,0,1,2.021,2.000,35.148,3.039,0,0,2.000,2.000,0.000,0.010,1
3755720748.561400,0,1,2.020,2.000,35.149,3.039,0,0,2.000,2.000,0.000,0.010,1
3755720958.561400,0,1,2.005,2.000,35.149,3.038,0,0,2.000,2.000,0.170,0.010,1
3755721168.561400,0,1,2.019,2.000,35.149,3.038,0,0,2.000,2.000,0.190,0.010,1
3755721378.561400,0,1,2.019,2.000,35.149,3.038,0,0,2.000,2.000,0.000,0.010,1
3755721588.561400,0,1,2.020,2.000,35.147,3.037,0,0,2.000,2.000,0.000,0.010,1
3755721798.561400,0,1,2.011,2.000,35.148,3.040,0,0,2.000,2.000,0.190,0.010,1
3755722008.561400,0,1,2.020,2.000,35.148,3.039,0,0,2.000,2.000,0.080,0.010,1
3755722218.561400,0,1,2.023,2.000,35.147,3.038,0,0,2.000,2.000,0.000,0.010,1
3755722428.561400,0,1,2.010,2.000,35.147,3.038,0,0,2.000,2.000,0.200,0.010,1
3755722638.561400,0,1,2.015,2.000,35.145,3.039,0,0,2.000,2.000,0.200,0.010,1
3755722848.561400,0,1,2.020,2.000,35.147,3.038,0,0,2.000,2.000,0.000,0.010,1
3755723058.561400,0,1,2.017,2.000,35.146,3.037,0,0,2.000,2.000,0.000,0.010,1
3755723268.561400,0,1,2.013,2.000,35.144,3.037,0,0,2.000,2.000,0.190,0.010,1
3755723478.561400,0,1,2.024,2.000,35.144,3.038,0,0,2.000,2.000,0.000,0.010,1
3755723688.561400,0,1,2.017,2.000,35.141,3.038,0,0,2.000,2.000,0.020,0.010,1
3755723898.561400,0,1,2.009,2.000,35.141,3.037,0,0,2.000,2.000,0.200,0.010,1
3755724108.561400,0,1,2.022,2.000,35.140,3.038,0,0,2.000,2.000,0.000,0.010,1
3755724318.561400,0,1,2.021,2.000,35.140,3.038,0,0,2.000,2.000,0.000,0.010,1
3755724528.561400,0,1,2.008,2.000,35.140,3.038,0,0,2.000,2.000,0.200,0.010,1
3755724738.561400,0,1,2.020,2.000,35.140,3.038,0,0,2.000,2.000,0.080,0.010,1
3755724948.561400,0,1,2.022,2.000,35.139,3.039,0,0,2.000,2.000,0.000,0.010,1
3755725158.561400,0,1,2.012,2.000,35.138,3.038,0,0,2.000,2.000,0.060,0.010,1
3755725368.561400,0,1,2.011,2.000,35.138,3.036,0,0,2.000,2.000,0.210,0.010,1
3755725578.561400,0,1,2.019,2.000,35.137,3.038,0,0,2.000,2.000,0.040,0.010,1
3755725788.561400,0,1,2.020,2.000,35.137,3.037,0,0,2.000,2.000,0.000,0.010,1
3755725998.561400,0,1,2.026,2.000,35.138,3.036,0,0,2.000,2.000,0.000,0.010,1
3755726208.561400,0,1,2.011,2.000,35.137,3.038,0,0,2.000,2.000,0.200,0.010,1
3755726418.561400,0,1,2.022,2.000,35.137,3.037,0,0,2.000,2.000,0.110,0.010,1
3755726628.561400,0,1,2.026,2.000,35.137,3.037,0,0,2.000,2.000,0.000,0.010,1
3755726838.561400,0,1,2.016,2.000,35.138,3.037,0,0,2.000,2.000,0.160,0.010,1
3755727048.561400,0,1,2.011,2.000,35.139,3.034,0,0,2.000,2.000,0.210,0.010,1
3755727258.561400,0,1,2.020,2.000,35.137,3.037,0,0,2.000,2.000,0.030,0.010,1
3755727468.561400,0,1,2.018,2.000,35.137,3.036,0,0,2.000,2.000,0.000,0.010,1
3755727678.561400,0,1,2.015,1.999,35.136,3.038,0,0,2.000,2.000,0.110,0.010,1
3755727768.561400,0,1,2.015,2.000,35.136,3.036,0,0,2.000,2.000,0.200,0.010,1