File: log/20230108.dat
[Header]
; Displex Transport Data File (default extension .dat)
; Copyright 2016, Hechang LEI, hlei@ruc.edu.cn. All rights reserved.
BYAPP, Displex, 2.0
INFO, 9T mag, Release 2.0.
INFO, Channel 1, Temperature Sensor
INFO, Sample 1 Length (cm): 0.000000; Width (cm): 0.000000; Thickness (cm): 0.000000.

[Data]
Timestamp(s),Field(Oe),Field Status,TempA(K),TempB(K),TempC(K),TempD(K),Ramp1,Ramp2,Setpoint1,Setpoint2,Output1(%),Output2(%),Temp Status
3755994194.856000,0,0,260.011,0.000,274.805,276.039,0,0,2.000,2.000,0.000,0.000,4
3755994374.856000,0,0,260.187,0.000,274.887,276.064,0,0,2.000,2.000,0.000,0.000,4
3755994554.856000,0,0,260.359,0.000,274.969,276.005,0,0,2.000,2.000,0.000,0.000,4
3755994734.856000,0,0,260.532,0.000,275.050,276.137,0,0,2.000,2.000,0.000,0.000,4
3755994914.856000,0,0,260.703,0.000,275.131,276.676,0,0,2.000,2.000,0.000,0.000,4
3755995094.856000,0,0,260.872,0.000,275.211,276.794,0,0,2.000,2.000,0.000,0.000,4
3755995274.856000,0,0,261.041,0.000,275.291,277.392,0,0,2.000,2.000,0.000,0.000,4
3755995454.856000,0,0,261.208,0.000,275.371,277.354,0,0,2.000,2.000,0.000,0.000,4
3755995634.856000,0,0,261.375,0.000,275.451,277.368,0,0,2.000,2.000,0.000,0.000,4
3755995814.856000,0,0,261.543,0.000,275.530,277.541,0,0,2.000,2.000,0.000,0.000,4
3755995994.856000,0,0,261.706,0.000,275.608,278.916,0,0,2.000,2.000,0.000,0.000,4
3755996174.856000,0,0,261.870,0.000,275.687,279.148,0,0,2.000,2.000,0.000,0.000,4
3755996354.856000,0,0,262.033,0.000,275.766,278.760,0,0,2.000,2.000,0.000,0.000,4
3755996534.856000,0,0,262.195,0.000,275.844,280.354,0,0,2.000,2.000,0.000,0.000,4
3755996714.856000,0,0,262.357,0.000,275.921,283.418,0,0,2.000,2.000,0.000,0.000,4
3755996894.856000,0,0,262.513,0.000,275.999,280.541,0,0,2.000,2.000,0.000,0.000,4
3755997074.856000,0,0,262.670,0.000,276.076,280.628,0,0,2.000,2.000,0.000,0.000,4
3755997254.856000,0,0,262.829,0.000,276.153,281.213,0,0,2.000,2.000,0.000,0.000,4
3755997434.856000,0,0,262.986,0.000,276.230,281.614,0,0,2.000,2.000,0.000,0.000,4
3755997614.856000,0,0,263.143,0.000,276.306,281.616,0,0,2.000,2.000,0.000,0.000,4
3755997794.856000,0,0,263.297,0.000,276.383,282.271,0,0,2.000,2.000,0.000,0.000,4
3755997974.856000,0,0,263.451,0.000,276.458,283.091,0,0,2.000,2.000,0.000,0.000,4
3755998154.856000,0,0,263.608,0.000,276.535,281.849,0,0,2.000,2.000,0.000,0.000,4
3755998334.856000,0,0,263.761,0.000,276.610,282.198,0,0,2.000,2.000,0.000,0.000,4
3755998514.856000,0,0,263.913,0.000,276.685,283.747,0,0,2.000,2.000,0.000,0.000,4
3755998694.856000,0,0,264.063,0.000,276.760,282.968,0,0,2.000,2.000,0.000,0.000,4
3755998874.856000,0,0,264.214,0.000,276.835,284.185,0,0,2.000,2.000,0.000,0.000,4
3755999054.856000,0,0,264.363,0.000,276.910,283.866,0,0,2.000,2.000,0.000,0.000,4
3755999234.856000,0,0,264.512,0.000,276.984,283.683,0,0,2.000,2.000,0.000,0.000,4
3755999414.856000,0,0,264.659,0.000,277.058,284.046,0,0,2.000,2.000,0.000,0.000,4
3755999594.856000,0,0,264.806,0.000,277.131,285.378,0,0,2.000,2.000,0.000,0.000,4
3755999774.856000,0,0,264.952,0.000,277.204,286.347,0,0,2.000,2.000,0.000,0.000,4
3755999954.856000,0,0,265.097,0.000,277.277,285.806,0,0,2.000,2.000,0.000,0.000,4
3756000134.856000,0,0,265.243,0.000,277.351,285.429,0,0,2.000,2.000,0.000,0.000,4
3756000314.856000,0,0,265.386,0.000,277.422,286.368,0,0,2.000,2.000,0.000,0.000,4
3756000494.856000,0,0,265.530,0.000,277.494,285.685,0,0,2.000,2.000,0.000,0.000,4
3756000674.856000,0,0,265.672,0.000,277.566,286.481,0,0,2.000,2.000,0.000,0.000,4
3756000854.856000,0,0,265.811,0.000,277.637,287.792,0,0,2.000,2.000,0.000,0.000,4
3756001034.856000,0,0,265.952,0.000,277.709,286.894,0,0,2.000,2.000,0.000,0.000,4
3756001214.856000,0,0,266.091,0.000,277.780,287.760,0,0,2.000,2.000,0.000,0.000,4
3756001394.856000,0,0,266.231,0.000,277.850,287.015,0,0,2.000,2.000,0.000,0.000,4
3756001574.856000,0,0,266.370,0.000,277.921,287.514,0,0,2.000,2.000,0.000,0.000,4
3756001754.856000,0,0,266.508,0.000,277.992,288.893,0,0,2.000,2.000,0.000,0.000,4
3756001934.856000,0,0,266.646,0.000,278.062,288.153,0,0,2.000,2.000,0.000,0.000,4
3756002114.856000,0,0,266.780,0.000,278.132,289.475,0,0,2.000,2.000,0.000,0.000,4
3756002294.856000,0,0,266.915,0.000,278.202,289.727,0,0,2.000,2.000,0.000,0.000,4
3756002474.856000,0,0,267.051,0.000,278.271,289.876,0,0,2.000,2.000,0.000,0.000,4
3756002654.856000,0,0,267.183,0.000,278.340,289.278,0,0,2.000,2.000,0.000,0.000,4
3756002834.856000,0,0,267.317,0.000,278.409,290.045,0,0,2.000,2.000,0.000,0.000,4
3756003014.856000,0,0,267.450,0.000,278.477,289.786,0,0,2.000,2.000,0.000,0.000,4
3756003194.856000,0,0,267.581,0.000,278.545,290.638,0,0,2.000,2.000,0.000,0.000,4
3756003374.856000,0,0,267.710,0.000,278.613,290.347,0,0,2.000,2.000,0.000,0.000,4
3756003554.856000,0,0,267.840,0.000,278.681,291.535,0,0,2.000,2.000,0.000,0.000,4
3756003734.856000,0,0,267.971,0.000,278.749,291.257,0,0,2.000,2.000,0.000,0.000,4
3756003914.856000,0,0,268.101,0.000,278.816,290.844,0,0,2.000,2.000,0.000,0.000,4
3756004094.856000,0,0,268.228,0.000,278.884,291.035,0,0,2.000,2.000,0.000,0.000,4
3756004274.856000,0,0,268.357,0.000,278.950,292.491,0,0,2.000,2.000,0.000,0.000,4
3756004454.856000,0,0,268.484,0.000,279.017,291.869,0,0,2.000,2.000,0.000,0.000,4
3756004634.856000,0,0,268.611,0.000,279.084,291.295,0,0,2.000,2.000,0.000,0.000,4
3756004814.856000,0,0,268.735,0.000,279.149,292.477,0,0,2.000,2.000,0.000,0.000,4
3756004994.856000,0,0,268.861,0.000,279.215,293.147,0,0,2.000,2.000,0.000,0.000,4
3756005174.856000,0,0,268.984,0.000,279.279,292.573,0,0,2.000,2.000,0.000,0.000,4
3756005354.856000,0,0,269.109,0.000,279.344,292.851,0,0,2.000,2.000,0.000,0.000,4
3756005534.856000,0,0,269.231,0.000,279.409,293.601,0,0,2.000,2.000,0.000,0.000,4
3756005714.856000,0,0,269.354,0.000,279.473,294.385,0,0,2.000,2.000,0.000,0.000,4
3756005894.856000,0,0,269.475,0.000,279.539,293.244,0,0,2.000,2.000,0.000,0.000,4
3756006074.856000,0,0,269.596,0.000,279.603,293.611,0,0,2.000,2.000,0.000,0.000,4
3756006254.856000,0,0,269.717,0.000,279.667,293.847,0,0,2.000,2.000,0.000,0.000,4
3756006434.856000,0,0,269.838,0.000,279.731,294.020,0,0,2.000,2.000,0.000,0.000,4
3756006614.856000,0,0,269.955,0.000,279.796,293.388,0,0,2.000,2.000,0.000,0.000,4
3756006794.856000,0,0,270.071,0.000,279.860,293.583,0,0,2.000,2.000,0.000,0.000,4
3756006974.856000,0,0,270.188,0.000,279.923,294.832,0,0,2.000,2.000,0.000,0.000,4
3756007154.856000,0,0,270.306,0.000,279.985,293.641,0,0,2.000,2.000,0.000,0.000,4
3756007334.856000,0,0,270.424,0.000,280.047,295.053,0,0,2.000,2.000,0.000,0.000,4
3756007514.856000,0,0,270.542,0.000,280.108,295.542,0,0,2.000,2.000,0.000,0.000,4
3756007694.856000,0,0,270.658,0.000,280.168,296.143,0,0,2.000,2.000,0.000,0.000,4
3756007874.856000,0,0,270.774,0.000,280.230,296.277,0,0,2.000,2.000,0.000,0.000,4
3756008054.856000,0,0,270.890,0.000,280.290,295.609,0,0,2.000,2.000,0.000,0.000,4
3756008234.856000,0,0,271.007,0.000,280.351,295.283,0,0,2.000,2.000,0.000,0.000,4
3756008414.856000,0,0,271.118,0.000,280.412,296.194,0,0,2.000,2.000,0.000,0.000,4
3756008594.856000,0,0,271.231,0.000,280.473,296.624,0,0,2.000,2.000,0.000,0.000,4
3756008774.856000,0,0,271.345,0.000,280.533,295.932,0,0,2.000,2.000,0.000,0.000,4
3756008954.856000,0,0,271.456,0.000,280.593,296.666,0,0,2.000,2.000,0.000,0.000,4
3756009134.856000,0,0,271.567,0.000,280.653,297.055,0,0,2.000,2.000,0.000,0.000,4
3756009314.856000,0,0,271.677,0.000,280.713,297.316,0,0,2.000,2.000,0.000,0.000,4
3756009494.856000,0,0,271.787,0.000,280.772,296.956,0,0,2.000,2.000,0.000,0.000,4
3756009674.856000,0,0,271.898,0.000,280.832,297.167,0,0,2.000,2.000,0.000,0.000,4
3756009854.856000,0,0,272.007,0.000,280.891,297.227,0,0,2.000,2.000,0.000,0.000,4
3756010034.856000,0,0,272.115,0.000,280.949,297.152,0,0,2.000,2.000,0.000,0.000,4
3756010214.856000,0,0,272.221,0.000,281.007,297.892,0,0,2.000,2.000,0.000,0.000,4
3756010394.856000,0,0,272.328,0.000,281.066,298.076,0,0,2.000,2.000,0.000,0.000,4
3756010574.856000,0,0,272.435,0.000,281.125,297.109,0,0,2.000,2.000,0.000,0.000,4
3756010754.856000,0,0,272.540,0.000,281.182,297.776,0,0,2.000,2.000,0.000,0.000,4
3756010934.856000,0,0,272.648,0.000,281.241,297.748,0,0,2.000,2.000,0.000,0.000,4
3756011114.856000,0,0,272.752,0.000,281.299,297.909,0,0,2.000,2.000,0.000,0.000,4
3756011294.856000,0,0,272.856,0.000,281.356,298.404,0,0,2.000,2.000,0.000,0.000,4
3756011474.856000,0,0,272.960,0.000,281.413,298.463,0,0,2.000,2.000,0.000,0.000,4
3756011654.856000,0,0,273.063,0.000,281.470,298.825,0,0,2.000,2.000,0.000,0.000,4
3756011834.856000,0,0,273.168,0.000,281.526,298.258,0,0,2.000,2.000,0.000,0.000,4
3756012014.856000,0,0,273.269,0.000,281.582,298.735,0,0,2.000,2.000,0.000,0.000,4
3756012194.856000,0,0,273.371,0.000,281.638,299.078,0,0,2.000,2.000,0.000,0.000,4
3756012374.856000,0,0,273.472,0.000,281.693,298.832,0,0,2.000,2.000,0.000,0.000,4
3756012554.856000,0,0,273.573,0.000,281.749,298.905,0,0,2.000,2.000,0.000,0.000,4
3756012734.856000,0,0,273.672,0.000,281.805,298.785,0,0,2.000,2.000,0.000,0.000,4
3756012914.856000,0,0,273.769,0.000,281.860,299.111,0,0,2.000,2.000,0.000,0.000,4
3756013094.856000,0,0,273.871,0.000,281.915,298.995,0,0,2.000,2.000,0.000,0.000,4
3756013274.856000,0,0,273.970,0.000,281.970,299.361,0,0,2.000,2.000,0.000,0.000,4
3756013454.856000,0,0,274.067,0.000,282.024,299.190,0,0,2.000,2.000,0.000,0.000,4
3756013634.856000,0,0,274.165,0.000,282.079,299.277,0,0,2.000,2.000,0.000,0.000,4
3756013814.856000,0,0,274.262,0.000,282.133,299.614,0,0,2.000,2.000,0.000,0.000,4
3756013994.856000,0,0,274.358,0.000,282.186,299.647,0,0,2.000,2.000,0.000,0.000,4
3756014174.856000,0,0,274.454,0.000,282.240,299.475,0,0,2.000,2.000,0.000,0.000,4
3756014354.856000,0,0,274.550,0.000,282.294,299.600,0,0,2.000,2.000,0.000,0.000,4
3756014534.856000,0,0,274.646,0.000,282.347,299.708,0,0,2.000,2.000,0.000,0.000,4
3756014714.856000,0,0,274.740,0.000,282.401,299.196,0,0,2.000,2.000,0.000,0.000,4
3756014894.856000,0,0,274.833,0.000,282.453,300.371,0,0,2.000,2.000,0.000,0.000,4
3756015074.856000,0,0,274.925,0.000,282.506,299.439,0,0,2.000,2.000,0.000,0.000,4
3756015254.856000,0,0,275.017,0.000,282.557,299.630,0,0,2.000,2.000,0.000,0.000,4
3756015434.856000,0,0,275.110,0.000,282.609,299.728,0,0,2.000,2.000,0.000,0.000,4
3756015614.856000,0,0,275.202,0.000,282.661,299.178,0,0,2.000,2.000,0.000,0.000,4
3756015794.856000,0,0,275.294,0.000,282.711,299.833,0,0,2.000,2.000,0.000,0.000,4
3756015974.856000,0,0,275.386,0.000,282.762,299.626,0,0,2.000,2.000,0.000,0.000,4
3756016154.856000,0,0,275.475,0.000,282.812,299.617,0,0,2.000,2.000,0.000,0.000,4
3756016334.856000,0,0,275.566,0.000,282.863,299.572,0,0,2.000,2.000,0.000,0.000,4
3756016514.856000,0,0,275.654,0.000,282.913,300.086,0,0,2.000,2.000,0.000,0.000,4
3756016694.856000,0,0,275.745,0.000,282.963,299.313,0,0,2.000,2.000,0.000,0.000,4
3756016874.856000,0,0,275.835,0.000,283.012,299.600,0,0,2.000,2.000,0.000,0.000,4
3756017054.856000,0,0,275.922,0.000,283.062,299.642,0,0,2.000,2.000,0.000,0.000,4
3756017234.856000,0,0,276.009,0.000,283.112,299.749,0,0,2.000,2.000,0.000,0.000,4
3756017414.856000,0,0,276.098,0.000,283.162,299.989,0,0,2.000,2.000,0.000,0.000,4
3756017594.856000,0,0,276.185,0.000,283.211,299.745,0,0,2.000,2.000,0.000,0.000,4
3756017774.856000,0,0,276.272,0.000,283.261,299.887,0,0,2.000,2.000,0.000,0.000,4
3756017954.856000,0,0,276.357,0.000,283.309,300.322,0,0,2.000,2.000,0.000,0.000,4
3756018134.856000,0,0,276.443,0.000,283.358,299.918,0,0,2.000,2.000,0.000,0.000,4
3756018314.856000,0,0,276.528,0.000,283.407,299.684,0,0,2.000,2.000,0.000,0.000,4
3756018494.856000,0,0,276.614,0.000,283.455,300.094,0,0,2.000,2.000,0.000,0.000,4
3756018674.856000,0,0,276.698,0.000,283.503,299.820,0,0,2.000,2.000,0.000,0.000,4
3756018854.856000,0,0,276.781,0.000,283.552,300.136,0,0,2.000,2.000,0.000,0.000,4
3756019034.856000,0,0,276.866,0.000,283.600,300.420,0,0,2.000,2.000,0.000,0.000,4
3756019214.856000,0,0,276.949,0.000,283.648,300.281,0,0,2.000,2.000,0.000,0.000,4
3756019394.856000,0,0,277.033,0.000,283.695,300.181,0,0,2.000,2.000,0.000,0.000,4
3756019574.856000,0,0,277.114,0.000,283.743,300.230,0,0,2.000,2.000,0.000,0.000,4
3756019754.856000,0,0,277.197,0.000,283.790,300.436,0,0,2.000,2.000,0.000,0.000,4
3756019934.856000,0,0,277.280,0.000,283.837,300.392,0,0,2.000,2.000,0.000,0.000,4
3756020114.856000,0,0,277.359,0.000,283.884,300.292,0,0,2.000,2.000,0.000,0.000,4
3756020294.856000,0,0,277.440,0.000,283.931,300.375,0,0,2.000,2.000,0.000,0.000,4
3756020474.856000,0,0,277.521,0.000,283.978,300.214,0,0,2.000,2.000,0.000,0.000,4
3756020654.856000,0,0,277.603,0.000,284.023,300.276,0,0,2.000,2.000,0.000,0.000,4
3756020834.856000,0,0,277.681,0.000,284.069,300.088,0,0,2.000,2.000,0.000,0.000,4
3756021014.856000,0,0,277.760,0.000,284.115,300.137,0,0,2.000,2.000,0.000,0.000,4
3756021194.856000,0,0,277.840,0.000,284.160,300.301,0,0,2.000,2.000,0.000,0.000,4
3756021374.856000,0,0,277.918,0.000,284.207,300.650,0,0,2.000,2.000,0.000,0.000,4
3756021554.856000,0,0,277.997,0.000,284.252,300.344,0,0,2.000,2.000,0.000,0.000,4
3756021734.856000,0,0,278.075,0.000,284.297,300.495,0,0,2.000,2.000,0.000,0.000,4
3756021914.856000,0,0,278.152,0.000,284.341,299.775,0,0,2.000,2.000,0.000,0.000,4
3756022094.856000,0,0,278.229,0.000,284.386,299.693,0,0,2.000,2.000,0.000,0.000,4
3756022274.856000,0,0,278.305,0.000,284.431,300.015,0,0,2.000,2.000,0.000,0.000,4
3756022454.856000,0,0,278.382,0.000,284.474,299.796,0,0,2.000,2.000,0.000,0.000,4
3756022634.856000,0,0,278.457,0.000,284.519,300.090,0,0,2.000,2.000,0.000,0.000,4
3756022814.856000,0,0,278.534,0.000,284.563,299.927,0,0,2.000,2.000,0.000,0.000,4
3756022994.856000,0,0,278.610,0.000,284.606,299.645,0,0,2.000,2.000,0.000,0.000,4
3756023174.856000,0,0,278.684,0.000,284.650,300.202,0,0,2.000,2.000,0.000,0.000,4
3756023354.856000,0,0,278.757,0.000,284.694,299.264,0,0,2.000,2.000,0.000,0.000,4
3756023534.856000,0,0,278.832,0.000,284.736,299.988,0,0,2.000,2.000,0.000,0.000,4
3756023714.856000,0,0,278.907,0.000,284.779,299.676,0,0,2.000,2.000,0.000,0.000,4
3756023894.856000,0,0,278.979,0.000,284.822,300.249,0,0,2.000,2.000,0.000,0.000,4
3756024074.856000,0,0,279.051,0.000,284.865,299.665,0,0,2.000,2.000,0.000,0.000,4
3756024254.856000,0,0,279.125,0.000,284.907,299.535,0,0,2.000,2.000,0.000,0.000,4
3756024434.856000,0,0,279.197,0.000,284.949,299.935,0,0,2.000,2.000,0.000,0.000,4
3756024614.856000,0,0,279.269,0.000,284.991,299.913,0,0,2.000,2.000,0.000,0.000,4
3756024794.856000,0,0,279.341,0.000,285.032,299.599,0,0,2.000,2.000,0.000,0.000,4
3756024974.856000,0,0,279.410,0.000,285.074,299.985,0,0,2.000,2.000,0.000,0.000,4
3756025154.856000,0,0,279.482,0.000,285.115,299.519,0,0,2.000,2.000,0.000,0.000,4
3756025334.856000,0,0,279.553,0.000,285.157,299.605,0,0,2.000,2.000,0.000,0.000,4
3756025514.856000,0,0,279.622,0.000,285.197,299.223,0,0,2.000,2.000,0.000,0.000,4
3756025694.856000,0,0,279.692,0.000,285.238,299.854,0,0,2.000,2.000,0.000,0.000,4
3756025874.856000,0,0,279.760,0.000,285.278,299.604,0,0,2.000,2.000,0.000,0.000,4
3756026054.856000,0,0,279.832,0.000,285.318,299.525,0,0,2.000,2.000,0.000,0.000,4
3756026234.856000,0,0,279.903,0.000,285.358,299.142,0,0,2.000,2.000,0.000,0.000,4
3756026414.856000,0,0,279.972,0.000,285.397,298.759,0,0,2.000,2.000,0.000,0.000,4
3756026594.856000,0,0,280.041,0.000,285.437,299.379,0,0,2.000,2.000,0.000,0.000,4
3756026774.856000,0,0,281.058,0.000,285.476,298.851,0,0,2.000,2.000,0.000,0.000,4
3756026954.856000,0,0,280.193,0.000,285.515,298.197,0,0,2.000,2.000,0.000,0.000,4
3756027134.856000,0,0,280.261,0.000,285.555,298.619,0,0,2.000,2.000,0.000,0.000,4
3756027314.856000,0,0,280.327,0.000,285.592,298.182,0,0,2.000,2.000,0.000,0.000,4
3756027494.856000,0,0,280.393,0.000,285.632,299.051,0,0,2.000,2.000,0.000,0.000,4
3756027674.856000,0,0,280.459,0.000,285.670,299.181,0,0,2.000,2.000,0.000,0.000,4
3756027854.856000,0,0,280.525,0.000,285.708,298.488,0,0,2.000,2.000,0.000,0.000,4
3756028034.856000,0,0,280.589,0.000,285.745,298.495,0,0,2.000,2.000,0.000,0.000,4
3756028214.856000,0,0,280.654,0.000,285.783,299.084,0,0,2.000,2.000,0.000,0.000,4
3756028394.856000,0,0,280.720,0.000,285.820,298.614,0,0,2.000,2.000,0.000,0.000,4
3756028574.856000,0,0,280.784,0.000,285.858,298.475,0,0,2.000,2.000,0.000,0.000,4
3756028754.856000,0,0,280.848,0.000,285.894,297.572,0,0,2.000,2.000,0.000,0.000,4
3756028934.856000,0,0,280.911,0.000,285.932,298.596,0,0,2.000,2.000,0.000,0.000,4
3756029114.856000,0,0,280.974,0.000,285.968,299.337,0,0,2.000,2.000,0.000,0.000,4
3756029294.856000,0,0,281.039,0.000,286.004,297.603,0,0,2.000,2.000,0.000,0.000,4
3756029474.856000,0,0,281.102,0.000,286.041,298.759,0,0,2.000,2.000,0.000,0.000,4
3756029654.856000,0,0,281.163,0.000,286.076,298.318,0,0,2.000,2.000,0.000,0.000,4
3756029834.856000,0,0,281.224,0.000,286.112,297.838,0,0,2.000,2.000,0.000,0.000,4
3756030014.856000,0,0,281.286,0.000,286.148,298.391,0,0,2.000,2.000,0.000,0.000,4
3756030194.856000,0,0,281.349,0.000,286.183,298.315,0,0,2.000,2.000,0.000,0.000,4
3756030374.856000,0,0,281.408,0.000,286.218,296.867,0,0,2.000,2.000,0.000,0.000,4
3756030554.856000,0,0,281.470,0.000,286.252,298.339,0,0,2.000,2.000,0.000,0.000,4
3756030734.856000,0,0,281.529,0.000,286.288,298.178,0,0,2.000,2.000,0.000,0.000,4
3756030914.856000,0,0,281.590,0.000,286.322,298.007,0,0,2.000,2.000,0.000,0.000,4
3756031094.856000,0,0,281.650,0.000,286.357,298.145,0,0,2.000,2.000,0.000,0.000,4
3756031274.856000,0,0,281.707,0.000,286.391,298.243,0,0,2.000,2.000,0.000,0.000,4
3756031454.856000,0,0,281.768,0.000,286.426,297.439,0,0,2.000,2.000,0.000,0.000,4
3756031634.856000,0,0,281.825,0.000,286.459,298.290,0,0,2.000,2.000,0.000,0.000,4
3756031814.856000,0,0,281.884,0.000,286.494,298.618,0,0,2.000,2.000,0.000,0.000,4
3756031994.856000,0,0,281.940,0.000,286.527,298.050,0,0,2.000,2.000,0.000,0.000,4
3756032174.856000,0,0,281.998,0.000,286.560,296.823,0,0,2.000,2.000,0.000,0.000,4
3756032354.856000,0,0,282.057,0.000,286.594,297.898,0,0,2.000,2.000,0.000,0.000,4
3756032534.856000,0,0,282.114,0.000,286.627,297.676,0,0,2.000,2.000,0.000,0.000,4
3756032714.856000,0,0,282.171,0.000,286.659,297.716,0,0,2.000,2.000,0.000,0.000,4
3756032894.856000,0,0,282.228,0.000,286.692,297.157,0,0,2.000,2.000,0.000,0.000,4
3756033074.856000,0,0,282.284,0.000,286.725,295.798,0,0,2.000,2.000,0.000,0.000,4
3756033254.856000,0,0,282.337,0.000,286.757,297.956,0,0,2.000,2.000,0.000,0.000,4
3756033434.856000,0,0,282.391,0.000,286.790,297.905,0,0,2.000,2.000,0.000,0.000,4
3756033614.856000,0,0,282.445,0.000,286.822,298.557,0,0,2.000,2.000,0.000,0.000,4
3756033794.856000,0,0,282.500,0.000,286.854,297.821,0,0,2.000,2.000,0.000,0.000,4
3756033974.856000,0,0,282.553,0.000,286.885,297.237,0,0,2.000,2.000,0.000,0.000,4
3756034154.856000,0,0,282.606,0.000,286.916,297.430,0,0,2.000,2.000,0.000,0.000,4
3756034334.856000,0,0,282.661,0.000,286.948,297.287,0,0,2.000,2.000,0.000,0.000,4
3756034514.856000,0,0,282.717,0.000,286.978,297.816,0,0,2.000,2.000,0.000,0.000,4
3756034694.856000,0,0,282.771,0.000,287.009,297.218,0,0,2.000,2.000,0.000,0.000,4
3756034874.856000,0,0,282.824,0.000,287.041,297.880,0,0,2.000,2.000,0.000,0.000,4
3756035054.856000,0,0,282.876,0.000,287.071,297.646,0,0,2.000,2.000,0.000,0.000,4
3756035234.856000,0,0,282.929,0.000,287.101,296.262,0,0,2.000,2.000,0.000,0.000,4
3756035414.856000,0,0,282.981,0.000,287.132,297.663,0,0,2.000,2.000,0.000,0.000,4
3756035594.856000,0,0,283.034,0.000,287.162,298.085,0,0,2.000,2.000,0.000,0.000,4
3756035774.856000,0,0,283.087,0.000,287.192,297.425,0,0,2.000,2.000,0.000,0.000,4
3756035954.856000,0,0,283.138,0.000,287.221,296.634,0,0,2.000,2.000,0.000,0.000,4
3756036134.856000,0,0,283.187,0.000,287.251,296.835,0,0,2.000,2.000,0.000,0.000,4
3756036314.856000,0,0,283.239,0.000,287.280,297.608,0,0,2.000,2.000,0.000,0.000,4
3756036494.856000,0,0,283.290,0.000,287.309,297.715,0,0,2.000,2.000,0.000,0.000,4
3756036674.856000,0,0,283.339,0.000,287.339,296.713,0,0,2.000,2.000,0.000,0.000,4
3756036854.856000,0,0,283.390,0.000,287.368,297.947,0,0,2.000,2.000,0.000,0.000,4
3756037034.856000,0,0,283.439,0.000,287.396,296.329,0,0,2.000,2.000,0.000,0.000,4
3756037214.856000,0,0,283.490,0.000,287.425,297.360,0,0,2.000,2.000,0.000,0.000,4
3756037394.856000,0,0,283.540,0.000,287.454,297.026,0,0,2.000,2.000,0.000,0.000,4
3756037574.856000,0,0,283.587,0.000,287.483,297.447,0,0,2.000,2.000,0.000,0.000,4
3756037754.856000,0,0,283.637,0.000,287.510,297.075,0,0,2.000,2.000,0.000,0.000,4
3756037934.856000,0,0,283.684,0.000,287.538,296.618,0,0,2.000,2.000,0.000,0.000,4
3756038114.856000,0,0,283.733,0.000,287.566,297.606,0,0,2.000,2.000,0.000,0.000,4
3756038294.856000,0,0,283.781,0.000,287.593,296.533,0,0,2.000,2.000,0.000,0.000,4
3756038474.856000,0,0,283.829,0.000,287.621,297.007,0,0,2.000,2.000,0.000,0.000,4
3756038654.856000,0,0,283.877,0.000,287.649,296.715,0,0,2.000,2.000,0.000,0.000,4
3756038834.856000,0,0,283.924,0.000,287.676,296.640,0,0,2.000,2.000,0.000,0.000,4
3756039014.856000,0,0,283.971,0.000,287.703,296.855,0,0,2.000,2.000,0.000,0.000,4
3756039194.856000,0,0,284.017,0.000,287.731,296.603,0,0,2.000,2.000,0.000,0.000,4
3756039374.856000,0,0,284.064,0.000,287.759,297.399,0,0,2.000,2.000,0.000,0.000,4
3756039554.856000,0,0,284.110,0.000,287.785,297.602,0,0,2.000,2.000,0.000,0.000,4
3756039734.856000,0,0,284.157,0.000,287.813,296.384,0,0,2.000,2.000,0.000,0.000,4
3756039914.856000,0,0,284.203,0.000,287.840,296.676,0,0,2.000,2.000,0.000,0.000,4
3756040094.856000,0,0,284.250,0.000,287.865,296.369,0,0,2.000,2.000,0.000,0.000,4
3756040274.856000,0,0,284.295,0.000,287.892,296.256,0,0,2.000,2.000,0.000,0.000,4
3756040454.856000,0,0,284.340,0.000,287.919,297.275,0,0,2.000,2.000,0.000,0.000,4
3756040634.856000,0,0,284.385,0.000,287.945,295.224,0,0,2.000,2.000,0.000,0.000,4
3756040814.856000,0,0,284.430,0.000,287.971,295.757,0,0,2.000,2.000,0.000,0.000,4
3756040994.856000,0,0,284.474,0.000,287.998,296.726,0,0,2.000,2.000,0.000,0.000,4
3756041174.856000,0,0,284.519,0.000,288.023,295.933,0,0,2.000,2.000,0.000,0.000,4
3756041354.856000,0,0,284.565,0.000,288.049,296.948,0,0,2.000,2.000,0.000,0.000,4
3756041534.856000,0,0,284.606,0.000,288.074,296.002,0,0,2.000,2.000,0.000,0.000,4
3756041714.856000,0,0,284.650,0.000,288.099,296.442,0,0,2.000,2.000,0.000,0.000,4
3756041894.856000,0,0,284.695,0.000,288.124,296.883,0,0,2.000,2.000,0.000,0.000,4
3756042074.856000,0,0,284.738,0.000,288.149,296.678,0,0,2.000,2.000,0.000,0.000,4
3756042254.856000,0,0,284.778,0.000,288.173,295.403,0,0,2.000,2.000,0.000,0.000,4
3756042434.856000,0,0,284.825,0.000,288.199,296.982,0,0,2.000,2.000,0.000,0.000,4
3756042614.856000,0,0,284.864,0.000,288.223,295.923,0,0,2.000,2.000,0.000,0.000,4
3756042794.856000,0,0,284.905,0.000,288.248,295.927,0,0,2.000,2.000,0.000,0.000,4
3756042974.856000,0,0,284.949,0.000,288.272,296.423,0,0,2.000,2.000,0.000,0.000,4
3756043154.856000,0,0,284.992,0.000,288.296,296.755,0,0,2.000,2.000,0.000,0.000,4
3756043334.856000,0,0,285.033,0.000,288.320,295.719,0,0,2.000,2.000,0.000,0.000,4
3756043514.856000,0,0,285.074,0.000,288.344,295.550,0,0,2.000,2.000,0.000,0.000,4
3756043694.856000,0,0,285.116,0.000,288.368,296.951,0,0,2.000,2.000,0.000,0.000,4
3756043874.856000,0,0,285.158,0.000,288.392,296.239,0,0,2.000,2.000,0.000,0.000,4
3756044054.856000,0,0,285.197,0.000,288.415,295.936,0,0,2.000,2.000,0.000,0.000,4
3756044234.856000,0,0,285.237,0.000,288.439,295.357,0,0,2.000,2.000,0.000,0.000,4
3756044414.856000,0,0,285.281,0.000,288.462,296.662,0,0,2.000,2.000,0.000,0.000,4
3756044594.856000,0,0,285.321,0.000,288.485,295.541,0,0,2.000,2.000,0.000,0.000,4
3756044774.856000,0,0,285.363,0.000,288.508,295.546,0,0,2.000,2.000,0.000,0.000,4
3756044954.856000,0,0,285.402,0.000,288.531,295.429,0,0,2.000,2.000,0.000,0.000,4
3756045134.856000,0,0,285.442,0.000,288.553,296.115,0,0,2.000,2.000,0.000,0.000,4
3756045314.856000,0,0,285.480,0.000,288.576,296.623,0,0,2.000,2.000,0.000,0.000,4
3756045494.856000,0,0,285.517,0.000,288.599,294.848,0,0,2.000,2.000,0.000,0.000,4
3756045674.856000,0,0,285.559,0.000,288.621,296.195,0,0,2.000,2.000,0.000,0.000,4
3756045854.856000,0,0,285.596,0.000,288.644,294.991,0,0,2.000,2.000,0.000,0.000,4
3756046034.856000,0,0,285.634,0.000,288.666,295.223,0,0,2.000,2.000,0.000,0.000,4
3756046214.856000,0,0,285.672,0.000,288.688,294.880,0,0,2.000,2.000,0.000,0.000,4
3756046394.856000,0,0,285.710,0.000,288.710,295.946,0,0,2.000,2.000,0.000,0.000,4
3756046574.856000,0,0,285.746,0.000,288.731,295.369,0,0,2.000,2.000,0.000,0.000,4
3756046754.856000,0,0,285.787,0.000,288.753,295.882,0,0,2.000,2.000,0.000,0.000,4
3756046934.856000,0,0,285.823,0.000,288.774,295.019,0,0,2.000,2.000,0.000,0.000,4
3756047114.856000,0,0,285.860,0.000,288.796,295.654,0,0,2.000,2.000,0.000,0.000,4
3756047294.856000,0,0,285.897,0.000,288.817,294.661,0,0,2.000,2.000,0.000,0.000,4
3756047474.856000,0,0,285.934,0.000,288.838,294.847,0,0,2.000,2.000,0.000,0.000,4
3756047654.856000,0,0,285.969,0.000,288.859,295.491,0,0,2.000,2.000,0.000,0.000,4
3756047834.856000,0,0,286.005,0.000,288.880,296.718,0,0,2.000,2.000,0.000,0.000,4
3756048014.856000,0,0,286.043,0.000,288.901,295.703,0,0,2.000,2.000,0.000,0.000,4
3756048194.856000,0,0,286.079,0.000,288.921,294.723,0,0,2.000,2.000,0.000,0.000,4
3756048374.856000,0,0,286.112,0.000,288.942,294.533,0,0,2.000,2.000,0.000,0.000,4
3756048554.856000,0,0,286.149,0.000,288.963,295.354,0,0,2.000,2.000,0.000,0.000,4
3756048734.856000,0,0,286.183,0.000,288.983,294.635,0,0,2.000,2.000,0.000,0.000,4
3756048914.856000,0,0,286.220,0.000,289.004,294.822,0,0,2.000,2.000,0.000,0.000,4
3756049094.856000,0,0,286.255,0.000,289.024,294.878,0,0,2.000,2.000,0.000,0.000,4
3756049274.856000,0,0,286.290,0.000,289.045,295.179,0,0,2.000,2.000,0.000,0.000,4
3756049454.856000,0,0,286.325,0.000,289.066,295.256,0,0,2.000,2.000,0.000,0.000,4
3756049634.856000,0,0,286.358,0.000,289.086,295.536,0,0,2.000,2.000,0.000,0.000,4
3756049814.856000,0,0,286.393,0.000,289.106,295.545,0,0,2.000,2.000,0.000,0.000,4
3756049994.856000,0,0,286.427,0.000,289.126,295.880,0,0,2.000,2.000,0.000,0.000,4
3756050174.856000,0,0,286.461,0.000,289.145,294.370,0,0,2.000,2.000,0.000,0.000,4
3756050354.856000,0,0,286.493,0.000,289.164,294.921,0,0,2.000,2.000,0.000,0.000,4
3756050534.856000,0,0,286.527,0.000,289.184,294.543,0,0,2.000,2.000,0.000,0.000,4
3756050714.856000,0,0,286.560,0.000,289.204,295.553,0,0,2.000,2.000,0.000,0.000,4
3756050894.856000,0,0,286.592,0.000,289.224,294.670,0,0,2.000,2.000,0.000,0.000,4
3756051074.856000,0,0,286.623,0.000,289.244,294.373,0,0,2.000,2.000,0.000,0.000,4
3756051254.856000,0,0,286.657,0.000,289.264,294.293,0,0,2.000,2.000,0.000,0.000,4
3756051434.856000,0,0,286.684,0.000,289.283,294.712,0,0,2.000,2.000,0.000,0.000,4
3756051614.856000,0,0,286.718,0.000,289.303,296.711,0,0,2.000,2.000,0.000,0.000,4
3756051794.856000,0,0,286.750,0.000,289.321,294.717,0,0,2.000,2.000,0.000,0.000,4
3756051974.856000,0,0,286.782,0.000,289.341,295.514,0,0,2.000,2.000,0.000,0.000,4
3756052154.856000,0,0,286.813,0.000,289.359,294.857,0,0,2.000,2.000,0.000,0.000,4
3756052334.856000,0,0,286.844,0.000,289.378,294.867,0,0,2.000,2.000,0.000,0.000,4
3756052514.856000,0,0,286.876,0.000,289.397,0.000,0,0,2.000,2.000,0.000,0.000,4
3756052694.856000,0,0,286.907,0.000,289.415,295.210,0,0,2.000,2.000,0.000,0.000,4
3756052874.856000,0,0,286.939,0.000,289.434,295.610,0,0,2.000,2.000,0.000,0.000,4
3756053054.856000,0,0,286.970,0.000,289.453,294.890,0,0,2.000,2.000,0.000,0.000,4
3756053234.856000,0,0,286.999,0.000,289.471,295.067,0,0,2.000,2.000,0.000,0.000,4
3756053414.856000,0,0,287.033,0.000,289.489,295.168,0,0,2.000,2.000,0.000,0.000,4
3756053594.856000,0,0,287.063,0.000,289.507,294.935,0,0,2.000,2.000,0.000,0.000,4
3756053774.856000,0,0,287.093,0.000,289.526,295.733,0,0,2.000,2.000,0.000,0.000,4
3756053954.856000,0,0,287.124,0.000,289.543,295.017,0,0,2.000,2.000,0.000,0.000,4
3756054134.856000,0,0,287.153,0.000,289.561,295.849,0,0,2.000,2.000,0.000,0.000,4
3756054314.856000,0,0,287.181,0.000,289.579,295.687,0,0,2.000,2.000,0.000,0.000,4
3756054494.856000,0,0,287.214,0.000,289.597,295.845,0,0,2.000,2.000,0.000,0.000,4
3756054674.856000,0,0,287.242,0.000,289.614,294.394,0,0,2.000,2.000,0.000,0.000,4
3756054854.856000,0,0,287.271,0.000,289.632,294.794,0,0,2.000,2.000,0.000,0.000,4
3756055034.856000,0,0,287.301,0.000,289.649,294.189,0,0,2.000,2.000,0.000,0.000,4
3756055214.856000,0,0,287.329,0.000,289.665,0.000,0,0,2.000,2.000,0.000,0.000,4
3756055394.856000,0,0,287.359,0.000,289.683,295.338,0,0,2.000,2.000,0.000,0.000,4
3756055574.856000,0,0,287.387,0.000,289.700,0.000,0,0,2.000,2.000,0.000,0.000,4
3756055754.856000,0,0,287.420,0.000,289.716,296.317,0,0,2.000,2.000,0.000,0.000,4
3756055934.856000,0,0,287.447,0.000,289.732,294.182,0,0,2.000,2.000,0.000,0.000,4
3756056114.856000,0,0,287.473,0.000,289.749,294.938,0,0,2.000,2.000,0.000,0.000,4
3756056294.856000,0,0,287.503,0.000,289.765,294.044,0,0,2.000,2.000,0.000,0.000,4
3756056474.856000,0,0,287.531,0.000,289.782,295.523,0,0,2.000,2.000,0.000,0.000,4
3756056654.856000,0,0,287.557,0.000,289.798,294.876,0,0,2.000,2.000,0.000,0.000,4
3756056834.856000,0,0,287.583,0.000,289.815,294.661,0,0,2.000,2.000,0.000,0.000,4
3756057014.856000,0,0,287.613,0.000,289.832,294.800,0,0,2.000,2.000,0.000,0.000,4
3756057194.856000,0,0,287.640,0.000,289.848,294.367,0,0,2.000,2.000,0.000,0.000,4
3756057374.856000,0,0,287.666,0.000,289.864,294.967,0,0,2.000,2.000,0.000,0.000,4
3756057554.856000,0,0,287.697,0.000,289.880,295.085,0,0,2.000,2.000,0.000,0.000,4
3756057734.856000,0,0,287.723,0.000,289.897,293.779,0,0,2.000,2.000,0.000,0.000,4
3756057914.856000,0,0,287.748,0.000,289.913,295.578,0,0,2.000,2.000,0.000,0.000,4
3756058094.856000,0,0,287.773,0.000,289.929,294.934,0,0,2.000,2.000,0.000,0.000,4
3756058274.856000,0,0,287.802,0.000,289.945,295.781,0,0,2.000,2.000,0.000,0.000,4
3756058454.856000,0,0,287.828,0.000,289.962,294.886,0,0,2.000,2.000,0.000,0.000,4
3756058634.856000,0,0,287.854,0.000,289.977,295.145,0,0,2.000,2.000,0.000,0.000,4
3756058814.856000,0,0,287.879,0.000,289.994,294.599,0,0,2.000,2.000,0.000,0.000,4
3756058994.856000,0,0,287.908,0.000,290.010,295.239,0,0,2.000,2.000,0.000,0.000,4
3756059174.856000,0,0,287.934,0.000,290.026,295.897,0,0,2.000,2.000,0.000,0.000,4
3756059354.856000,0,0,287.959,0.000,290.042,294.375,0,0,2.000,2.000,0.000,0.000,4
3756059534.856000,0,0,287.984,0.000,290.057,294.731,0,0,2.000,2.000,0.000,0.000,4
3756059714.856000,0,0,288.010,0.000,290.074,295.886,0,0,2.000,2.000,0.000,0.000,4
3756059894.856000,0,0,288.037,0.000,290.090,295.004,0,0,2.000,2.000,0.000,0.000,4
3756060074.856000,0,0,288.059,0.000,290.105,293.752,0,0,2.000,2.000,0.000,0.000,4
3756060254.856000,0,0,288.085,0.000,290.120,293.876,0,0,2.000,2.000,0.000,0.000,4
3756060434.856000,0,0,288.109,0.000,290.136,293.931,0,0,2.000,2.000,0.000,0.000,4
3756060614.856000,0,0,288.136,0.000,290.151,293.663,0,0,2.000,2.000,0.000,0.000,4
3756060794.856000,0,0,288.161,0.000,290.167,294.882,0,0,2.000,2.000,0.000,0.000,4
3756060974.856000,0,0,288.186,0.000,290.182,294.971,0,0,2.000,2.000,0.000,0.000,4
3756061154.856000,0,0,288.209,0.000,290.199,294.590,0,0,2.000,2.000,0.000,0.000,4
3756061334.856000,0,0,288.235,0.000,290.214,294.302,0,0,2.000,2.000,0.000,0.000,4
3756061514.856000,0,0,288.259,0.000,290.228,0.000,0,0,2.000,2.000,0.000,0.000,4
3756061694.856000,0,0,288.286,0.000,290.243,294.897,0,0,2.000,2.000,0.000,0.000,4
3756061874.856000,0,0,288.310,0.000,290.259,294.458,0,0,2.000,2.000,0.000,0.000,4
3756062054.856000,0,0,288.329,0.000,290.274,294.462,0,0,2.000,2.000,0.000,0.000,4
3756062234.856000,0,0,288.356,0.000,290.288,294.432,0,0,2.000,2.000,0.000,0.000,4
3756062414.856000,0,0,288.380,0.000,290.303,295.465,0,0,2.000,2.000,0.000,0.000,4
3756062594.856000,0,0,288.408,0.000,290.317,294.927,0,0,2.000,2.000,0.000,0.000,4
3756062774.856000,0,0,288.433,0.000,290.331,294.024,0,0,2.000,2.000,0.000,0.000,4
3756062954.856000,0,0,288.457,0.000,290.346,295.261,0,0,2.000,2.000,0.000,0.000,4
3756063134.856000,0,0,288.478,0.000,290.360,293.716,0,0,2.000,2.000,0.000,0.000,4
3756063314.856000,0,0,288.503,0.000,290.375,293.944,0,0,2.000,2.000,0.000,0.000,4
3756063494.856000,0,0,288.526,0.000,290.389,294.274,0,0,2.000,2.000,0.000,0.000,4
3756063674.856000,0,0,288.548,0.000,290.404,294.217,0,0,2.000,2.000,0.000,0.000,4
3756063854.856000,0,0,288.572,0.000,290.418,295.036,0,0,2.000,2.000,0.000,0.000,4
3756064034.856000,0,0,288.594,0.000,290.432,293.336,0,0,2.000,2.000,0.000,0.000,4
3756064214.856000,0,0,288.616,0.000,290.446,293.415,0,0,2.000,2.000,0.000,0.000,4
3756064394.856000,0,0,288.638,0.000,290.461,294.142,0,0,2.000,2.000,0.000,0.000,4
3756064574.856000,0,0,288.662,0.000,290.475,0.000,0,0,2.000,2.000,0.000,0.000,4
3756064754.856000,0,0,288.685,0.000,290.489,294.325,0,0,2.000,2.000,0.000,0.000,4
3756064934.856000,0,0,288.708,0.000,290.503,0.000,0,0,2.000,2.000,0.000,0.000,4
3756065114.856000,0,0,288.731,0.000,290.517,294.339,0,0,2.000,2.000,0.000,0.000,4
3756065294.856000,0,0,288.750,0.000,290.531,0.000,0,0,2.000,2.000,0.000,0.000,4
3756065474.856000,0,0,288.773,0.000,290.545,294.310,0,0,2.000,2.000,0.000,0.000,4
3756065654.856000,0,0,288.796,0.000,290.558,0.000,0,0,2.000,2.000,0.000,0.000,4
3756065834.856000,0,0,288.816,0.000,290.572,293.847,0,0,2.000,2.000,0.000,0.000,4
3756066014.856000,0,0,288.839,0.000,290.587,293.713,0,0,2.000,2.000,0.000,0.000,4
3756066194.856000,0,0,288.860,0.000,290.600,294.597,0,0,2.000,2.000,0.000,0.000,4
3756066374.856000,0,0,288.882,0.000,290.614,295.132,0,0,2.000,2.000,0.000,0.000,4
3756066554.856000,0,0,288.902,0.000,290.628,295.038,0,0,2.000,2.000,0.000,0.000,4
3756066734.856000,0,0,288.925,0.000,290.641,294.155,0,0,2.000,2.000,0.000,0.000,4
3756066914.856000,0,0,288.945,0.000,290.654,295.236,0,0,2.000,2.000,0.000,0.000,4
3756067094.856000,0,0,288.965,0.000,290.668,0.000,0,0,2.000,2.000,0.000,0.000,4
3756067274.856000,0,0,288.987,0.000,290.680,294.219,0,0,2.000,2.000,0.000,0.000,4
3756067454.856000,0,0,289.009,0.000,290.693,0.000,0,0,2.000,2.000,0.000,0.000,4
3756067634.856000,0,0,289.029,0.000,290.707,294.570,0,0,2.000,2.000,0.000,0.000,4
3756067814.856000,0,0,289.051,0.000,290.719,294.430,0,0,2.000,2.000,0.000,0.000,4
3756067994.856000,0,0,289.069,0.000,290.732,295.507,0,0,2.000,2.000,0.000,0.000,4
3756068174.856000,0,0,289.092,0.000,290.745,295.684,0,0,2.000,2.000,0.000,0.000,4
3756068354.856000,0,0,289.110,0.000,290.758,294.870,0,0,2.000,2.000,0.000,0.000,4
3756068534.856000,0,0,289.133,0.000,290.771,294.290,0,0,2.000,2.000,0.000,0.000,4
3756068714.856000,0,0,289.151,0.000,290.783,0.000,0,0,2.000,2.000,0.000,0.000,4
3756068894.856000,0,0,289.173,0.000,290.795,0.000,0,0,2.000,2.000,0.000,0.000,4
3756069074.856000,0,0,289.193,0.000,290.808,295.069,0,0,2.000,2.000,0.000,0.000,4
3756069254.856000,0,0,289.212,0.000,290.820,294.519,0,0,2.000,2.000,0.000,0.000,4
3756069434.856000,0,0,289.229,0.000,290.834,0.000,0,0,2.000,2.000,0.000,0.000,4
3756069614.856000,0,0,289.248,0.000,290.845,294.569,0,0,2.000,2.000,0.000,0.000,4
3756069794.856000,0,0,289.266,0.000,290.858,294.343,0,0,2.000,2.000,0.000,0.000,4
3756069974.856000,0,0,289.286,0.000,290.870,0.000,0,0,2.000,2.000,0.000,0.000,4
3756070154.856000,0,0,289.304,0.000,290.882,294.078,0,0,2.000,2.000,0.000,0.000,4
3756070334.856000,0,0,289.325,0.000,290.893,295.186,0,0,2.000,2.000,0.000,0.000,4
3756070514.856000,0,0,289.342,0.000,290.906,294.603,0,0,2.000,2.000,0.000,0.000,4
3756070694.856000,0,0,289.362,0.000,290.917,294.653,0,0,2.000,2.000,0.000,0.000,4
3756070874.856000,0,0,289.380,0.000,290.929,294.589,0,0,2.000,2.000,0.000,0.000,4
3756071054.856000,0,0,289.400,0.000,290.940,294.568,0,0,2.000,2.000,0.000,0.000,4
3756071234.856000,0,0,289.419,0.000,290.952,293.240,0,0,2.000,2.000,0.000,0.000,4
3756071414.856000,0,0,289.437,0.000,290.963,294.327,0,0,2.000,2.000,0.000,0.000,4
3756071594.856000,0,0,289.456,0.000,290.974,293.767,0,0,2.000,2.000,0.000,0.000,4
3756071774.856000,0,0,289.474,0.000,290.986,295.456,0,0,2.000,2.000,0.000,0.000,4
3756071954.856000,0,0,289.494,0.000,290.997,294.853,0,0,2.000,2.000,0.000,0.000,4
3756072134.856000,0,0,289.512,0.000,291.007,295.012,0,0,2.000,2.000,0.000,0.000,4
3756072314.856000,0,0,289.531,0.000,291.018,295.216,0,0,2.000,2.000,0.000,0.000,4
3756072494.856000,0,0,289.548,0.000,291.029,294.576,0,0,2.000,2.000,0.000,0.000,4
3756072674.856000,0,0,289.564,0.000,291.040,294.625,0,0,2.000,2.000,0.000,0.000,4
3756072854.856000,0,0,289.582,0.000,291.050,293.972,0,0,2.000,2.000,0.000,0.000,4
3756073034.856000,0,0,289.600,0.000,291.061,294.632,0,0,2.000,2.000,0.000,0.000,4
3756073214.856000,0,0,289.620,0.000,291.072,294.424,0,0,2.000,2.000,0.000,0.000,4
3756073394.856000,0,0,289.636,0.000,291.081,294.172,0,0,2.000,2.000,0.000,0.000,4
3756073574.856000,0,0,289.654,0.000,291.092,294.336,0,0,2.000,2.000,0.000,0.000,4
3756073754.856000,0,0,289.671,0.000,291.102,293.832,0,0,2.000,2.000,0.000,0.000,4
3756073934.856000,0,0,289.686,0.000,291.111,294.814,0,0,2.000,2.000,0.000,0.000,4
3756074114.856000,0,0,289.699,0.000,291.122,294.564,0,0,2.000,2.000,0.000,0.000,4
3756074294.856000,0,0,289.714,0.000,291.132,294.512,0,0,2.000,2.000,0.000,0.000,4
3756074474.856000,0,0,289.728,0.000,291.142,294.920,0,0,2.000,2.000,0.000,0.000,4
3756074654.856000,0,0,289.743,0.000,291.151,293.890,0,0,2.000,2.000,0.000,0.000,4
3756074834.856000,0,0,289.757,0.000,291.162,293.505,0,0,2.000,2.000,0.000,0.000,4
3756075014.856000,0,0,289.776,0.000,291.171,295.054,0,0,2.000,2.000,0.000,0.000,4
3756075194.856000,0,0,289.792,0.000,291.181,292.569,0,0,2.000,2.000,0.000,0.000,4
3756075374.856000,0,0,289.808,0.000,291.190,294.162,0,0,2.000,2.000,0.000,0.000,4
3756075554.856000,0,0,289.824,0.000,291.200,294.053,0,0,2.000,2.000,0.000,0.000,4
3756075734.856000,0,0,289.840,0.000,291.210,294.192,0,0,2.000,2.000,0.000,0.000,4
3756075914.856000,0,0,289.857,0.000,291.219,294.731,0,0,2.000,2.000,0.000,0.000,4
3756076094.856000,0,0,289.872,0.000,291.229,0.000,0,0,2.000,2.000,0.000,0.000,4
3756076274.856000,0,0,289.889,0.000,291.238,293.894,0,0,2.000,2.000,0.000,0.000,4
3756076454.856000,0,0,289.908,0.000,291.247,293.962,0,0,2.000,2.000,0.000,0.000,4
3756076634.856000,0,0,289.923,0.000,291.257,293.170,0,0,2.000,2.000,0.000,0.000,4
3756076814.856000,0,0,289.938,0.000,291.266,293.547,0,0,2.000,2.000,0.000,0.000,4
3756076994.856000,0,0,289.955,0.000,291.275,293.303,0,0,2.000,2.000,0.000,0.000,4
3756077174.856000,0,0,289.971,0.000,291.285,294.464,0,0,2.000,2.000,0.000,0.000,4
3756077354.856000,0,0,289.985,0.000,291.294,0.000,0,0,2.000,2.000,0.000,0.000,4
3756077534.856000,0,0,290.004,0.000,291.303,294.908,0,0,2.000,2.000,0.000,0.000,4
3756077714.856000,0,0,290.021,0.000,291.311,293.510,0,0,2.000,2.000,0.000,0.000,4
3756077894.856000,0,0,290.033,0.000,291.321,293.256,0,0,2.000,2.000,0.000,0.000,4
3756078074.856000,0,0,290.051,0.000,291.330,294.706,0,0,2.000,2.000,0.000,0.000,4
3756078254.856000,0,0,290.067,0.000,291.338,293.910,0,0,2.000,2.000,0.000,0.000,4
3756078434.856000,0,0,290.083,0.000,291.347,293.567,0,0,2.000,2.000,0.000,0.000,4
3756078614.856000,0,0,290.097,0.000,291.356,293.501,0,0,2.000,2.000,0.000,0.000,4
3756078794.856000,0,0,290.119,0.000,291.364,294.480,0,0,2.000,2.000,0.000,0.000,4
3756078974.856000,0,0,290.136,0.000,291.372,293.435,0,0,2.000,2.000,0.000,0.000,4
3756079154.856000,0,0,290.149,0.000,291.381,294.232,0,0,2.000,2.000,0.000,0.000,4
3756079334.856000,0,0,290.163,0.000,291.389,293.056,0,0,2.000,2.000,0.000,0.000,4
3756079514.856000,0,0,290.178,0.000,291.397,293.287,0,0,2.000,2.000,0.000,0.000,4
3756079694.856000,0,0,290.189,0.000,291.406,294.309,0,0,2.000,2.000,0.000,0.000,4
3756079874.856000,0,0,290.196,0.000,291.416,0.000,0,0,2.000,2.000,0.000,0.000,4
3756080054.856000,0,0,290.209,0.000,291.424,294.382,0,0,2.000,2.000,0.000,0.000,4
3756080234.856000,0,0,290.222,0.000,291.432,294.334,0,0,2.000,2.000,0.000,0.000,4
3756080414.856000,0,0,290.240,0.000,291.440,293.958,0,0,2.000,2.000,0.000,0.000,4
3756080594.856000,0,0,290.257,0.000,291.449,0.000,0,0,2.000,2.000,0.000,0.000,4
3756080774.856000,0,0,290.275,0.000,291.456,0.000,0,0,2.000,2.000,0.000,0.000,4
3756080954.856000,0,0,290.289,0.000,291.466,293.480,0,0,2.000,2.000,0.000,0.000,4
3756081134.856000,0,0,290.304,0.000,291.474,0.000,0,0,2.000,2.000,0.000,0.000,4
3756081314.856000,0,0,290.319,0.000,291.482,0.000,0,0,2.000,2.000,0.000,0.000,4
3756081494.856000,0,0,290.333,0.000,291.490,293.873,0,0,2.000,2.000,0.000,0.000,4
3756081674.856000,0,0,290.346,0.000,291.499,294.283,0,0,2.000,2.000,0.000,0.000,4
3756081854.856000,0,0,290.358,0.000,291.507,0.000,0,0,2.000,2.000,0.000,0.000,4
3756082034.856000,0,0,290.374,0.000,291.516,294.735,0,0,2.000,2.000,0.000,0.000,4
3756082214.856000,0,0,290.390,0.000,291.524,293.924,0,0,2.000,2.000,0.000,0.000,4
3756082394.856000,0,0,290.401,0.000,291.533,293.401,0,0,2.000,2.000,0.000,0.000,4
3756082574.856000,0,0,290.415,0.000,291.541,294.603,0,0,2.000,2.000,0.000,0.000,4
3756082754.856000,0,0,290.431,0.000,291.550,294.358,0,0,2.000,2.000,0.000,0.000,4
3756082934.856000,0,0,290.444,0.000,291.558,294.586,0,0,2.000,2.000,0.000,0.000,4
3756083114.856000,0,0,290.455,0.000,291.567,0.000,0,0,2.000,2.000,0.000,0.000,4
3756083294.856000,0,0,290.471,0.000,291.575,293.921,0,0,2.000,2.000,0.000,0.000,4
3756083474.856000,0,0,290.485,0.000,291.583,294.624,0,0,2.000,2.000,0.000,0.000,4
3756083654.856000,0,0,290.494,0.000,291.592,294.566,0,0,2.000,2.000,0.000,0.000,4
3756083834.856000,0,0,290.506,0.000,291.600,293.490,0,0,2.000,2.000,0.000,0.000,4
3756084014.856000,0,0,290.521,0.000,291.608,294.885,0,0,2.000,2.000,0.000,0.000,4
3756084194.856000,0,0,290.532,0.000,291.617,293.144,0,0,2.000,2.000,0.000,0.000,4
3756084374.856000,0,0,290.545,0.000,291.625,293.032,0,0,2.000,2.000,0.000,0.000,4
3756084554.856000,0,0,290.560,0.000,291.633,294.252,0,0,2.000,2.000,0.000,0.000,4
3756084734.856000,0,0,290.575,0.000,291.640,293.727,0,0,2.000,2.000,0.000,0.000,4
3756084914.856000,0,0,290.587,0.000,291.649,293.647,0,0,2.000,2.000,0.000,0.000,4
3756085094.856000,0,0,290.599,0.000,291.657,293.946,0,0,2.000,2.000,0.000,0.000,4
3756085274.856000,0,0,290.611,0.000,291.665,0.000,0,0,2.000,2.000,0.000,0.000,4
3756085454.856000,0,0,290.625,0.000,291.673,0.000,0,0,2.000,2.000,0.000,0.000,4
3756085634.856000,0,0,290.639,0.000,291.682,0.000,0,0,2.000,2.000,0.000,0.000,4
3756085814.856000,0,0,290.654,0.000,291.690,292.745,0,0,2.000,2.000,0.000,0.000,4
3756085994.856000,0,0,290.665,0.000,291.698,294.477,0,0,2.000,2.000,0.000,0.000,4
3756086174.856000,0,0,290.676,0.000,291.706,294.377,0,0,2.000,2.000,0.000,0.000,4
3756086354.856000,0,0,290.691,0.000,291.714,293.985,0,0,2.000,2.000,0.000,0.000,4
3756086534.856000,0,0,290.702,0.000,291.722,0.000,0,0,2.000,2.000,0.000,0.000,4
3756086714.856000,0,0,290.713,0.000,291.731,293.516,0,0,2.000,2.000,0.000,0.000,4
3756086894.856000,0,0,290.728,0.000,291.740,293.868,0,0,2.000,2.000,0.000,0.000,4
3756087074.856000,0,0,290.738,0.000,291.749,0.000,0,0,2.000,2.000,0.000,0.000,4
3756087254.856000,0,0,290.750,0.000,291.758,0.000,0,0,2.000,2.000,0.000,0.000,4
3756087434.856000,0,0,290.761,0.000,291.766,293.883,0,0,2.000,2.000,0.000,0.000,4
3756087614.856000,0,0,290.777,0.000,291.775,294.202,0,0,2.000,2.000,0.000,0.000,4
3756087794.856000,0,0,290.789,0.000,291.784,0.000,0,0,2.000,2.000,0.000,0.000,4
3756087974.856000,0,0,290.798,0.000,291.794,294.477,0,0,2.000,2.000,0.000,0.000,4
3756088154.856000,0,0,290.812,0.000,291.802,0.000,0,0,2.000,2.000,0.000,0.000,4
3756088334.856000,0,0,290.823,0.000,291.811,0.000,0,0,2.000,2.000,0.000,0.000,4
3756088514.856000,0,0,290.835,0.000,291.821,293.410,0,0,2.000,2.000,0.000,0.000,4
3756088694.856000,0,0,290.842,0.000,291.830,294.769,0,0,2.000,2.000,0.000,0.000,4
3756088874.856000,0,0,290.850,0.000,291.839,293.596,0,0,2.000,2.000,0.000,0.000,4
3756089054.856000,0,0,290.864,0.000,291.848,0.000,0,0,2.000,2.000,0.000,0.000,4
3756089234.856000,0,0,290.873,0.000,291.857,0.000,0,0,2.000,2.000,0.000,0.000,4
3756089414.856000,0,0,290.883,0.000,291.865,293.869,0,0,2.000,2.000,0.000,0.000,4
3756089594.856000,0,0,290.892,0.000,291.874,294.602,0,0,2.000,2.000,0.000,0.000,4
3756089774.856000,0,0,290.906,0.000,291.881,0.000,0,0,2.000,2.000,0.000,0.000,4
3756089954.856000,0,0,290.913,0.000,291.889,293.350,0,0,2.000,2.000,0.000,0.000,4
3756090134.856000,0,0,290.923,0.000,291.897,293.699,0,0,2.000,2.000,0.000,0.000,4
3756090314.856000,0,0,290.936,0.000,291.902,293.986,0,0,2.000,2.000,0.000,0.000,4
3756090494.856000,0,0,290.948,0.000,291.910,293.664,0,0,2.000,2.000,0.000,0.000,4
3756090674.856000,0,0,290.957,0.000,291.917,293.344,0,0,2.000,2.000,0.000,0.000,4
3756090854.856000,0,0,290.969,0.000,291.923,295.034,0,0,2.000,2.000,0.000,0.000,4
3756091034.856000,0,0,290.978,0.000,291.930,295.401,0,0,2.000,2.000,0.000,0.000,4
3756091214.856000,0,0,290.989,0.000,291.937,294.714,0,0,2.000,2.000,0.000,0.000,4
3756091394.856000,0,0,291.001,0.000,291.943,0.000,0,0,2.000,2.000,0.000,0.000,4
3756091574.856000,0,0,291.012,0.000,291.948,293.685,0,0,2.000,2.000,0.000,0.000,4
3756091754.856000,0,0,291.026,0.000,291.954,294.394,0,0,2.000,2.000,0.000,0.000,4
3756091934.856000,0,0,291.036,0.000,291.959,0.000,0,0,2.000,2.000,0.000,0.000,4
3756092114.856000,0,0,291.047,0.000,291.965,0.000,0,0,2.000,2.000,0.000,0.000,4
3756092294.856000,0,0,291.059,0.000,291.971,293.867,0,0,2.000,2.000,0.000,0.000,4
3756092474.856000,0,0,291.069,0.000,291.978,295.053,0,0,2.000,2.000,0.000,0.000,4
3756092654.856000,0,0,291.080,0.000,291.983,294.410,0,0,2.000,2.000,0.000,0.000,4
3756092834.856000,0,0,291.094,0.000,291.989,295.334,0,0,2.000,2.000,0.000,0.000,4
3756093014.856000,0,0,291.108,0.000,291.995,295.070,0,0,2.000,2.000,0.000,0.000,4
3756093194.856000,0,0,291.119,0.000,292.002,295.565,0,0,2.000,2.000,0.000,0.000,4
3756093374.856000,0,0,291.130,0.000,292.007,0.000,0,0,2.000,2.000,0.000,0.000,4
3756093554.856000,0,0,291.140,0.000,292.014,293.415,0,0,2.000,2.000,0.000,0.000,4
3756093734.856000,0,0,291.152,0.000,292.021,295.275,0,0,2.000,2.000,0.000,0.000,4
3756093914.856000,0,0,291.162,0.000,292.027,0.000,0,0,2.000,2.000,0.000,0.000,4
3756094094.856000,0,0,291.169,0.000,292.035,294.347,0,0,2.000,2.000,0.000,0.000,4
3756094274.856000,0,0,291.175,0.000,292.043,293.881,0,0,2.000,2.000,0.000,0.000,4
3756094454.856000,0,0,291.183,0.000,292.050,295.634,0,0,2.000,2.000,0.000,0.000,4
3756094634.856000,0,0,291.185,0.000,292.057,294.275,0,0,2.000,2.000,0.000,0.000,4
3756094814.856000,0,0,291.201,0.000,292.064,293.947,0,0,2.000,2.000,0.000,0.000,4
3756094994.856000,0,0,291.213,0.000,292.071,294.863,0,0,2.000,2.000,0.000,0.000,4
3756095174.856000,0,0,291.226,0.000,292.078,0.000,0,0,2.000,2.000,0.000,0.000,4
3756095354.856000,0,0,291.238,0.000,292.085,294.356,0,0,2.000,2.000,0.000,0.000,4
3756095534.856000,0,0,291.249,0.000,292.092,0.000,0,0,2.000,2.000,0.000,0.000,4
3756095714.856000,0,0,291.260,0.000,292.098,294.934,0,0,2.000,2.000,0.000,0.000,4
3756095894.856000,0,0,291.271,0.000,292.106,294.280,0,0,2.000,2.000,0.000,0.000,4
3756096074.856000,0,0,291.282,0.000,292.113,294.223,0,0,2.000,2.000,0.000,0.000,4
3756096254.856000,0,0,291.292,0.000,292.121,295.119,0,0,2.000,2.000,0.000,0.000,4
3756096434.856000,0,0,291.301,0.000,292.128,293.393,0,0,2.000,2.000,0.000,0.000,4
3756096614.856000,0,0,291.312,0.000,292.135,0.000,0,0,2.000,2.000,0.000,0.000,4
3756096794.856000,0,0,291.322,0.000,292.144,293.609,0,0,2.000,2.000,0.000,0.000,4
3756096974.856000,0,0,291.334,0.000,292.151,294.723,0,0,2.000,2.000,0.000,0.000,4
3756097154.856000,0,0,291.341,0.000,292.159,293.047,0,0,2.000,2.000,0.000,0.000,4
3756097334.856000,0,0,291.352,0.000,292.167,0.000,0,0,2.000,2.000,0.000,0.000,4
3756097514.856000,0,0,291.363,0.000,292.175,294.925,0,0,2.000,2.000,0.000,0.000,4
3756097694.856000,0,0,291.372,0.000,292.183,294.655,0,0,2.000,2.000,0.000,0.000,4
3756097874.856000,0,0,291.383,0.000,292.191,294.534,0,0,2.000,2.000,0.000,0.000,4
3756098054.856000,0,0,291.392,0.000,292.198,293.653,0,0,2.000,2.000,0.000,0.000,4
3756098234.856000,0,0,291.403,0.000,292.206,294.133,0,0,2.000,2.000,0.000,0.000,4
3756098414.856000,0,0,291.410,0.000,292.215,0.000,0,0,2.000,2.000,0.000,0.000,4
3756098594.856000,0,0,291.421,0.000,292.221,294.516,0,0,2.000,2.000,0.000,0.000,4
3756098774.856000,0,0,291.430,0.000,292.229,0.000,0,0,2.000,2.000,0.000,0.000,4
3756098954.856000,0,0,291.438,0.000,292.237,293.409,0,0,2.000,2.000,0.000,0.000,4
3756099134.856000,0,0,291.448,0.000,292.245,0.000,0,0,2.000,2.000,0.000,0.000,4
3756099314.856000,0,0,291.458,0.000,292.252,293.821,0,0,2.000,2.000,0.000,0.000,4
3756099494.856000,0,0,291.467,0.000,292.259,293.847,0,0,2.000,2.000,0.000,0.000,4
3756099674.856000,0,0,291.477,0.000,292.266,294.277,0,0,2.000,2.000,0.000,0.000,4
3756099854.856000,0,0,291.488,0.000,292.274,294.499,0,0,2.000,2.000,0.000,0.000,4