File: log/20230102.dat
[Header]
; Displex Transport Data File (default extension .dat)
; Copyright 2016, Hechang LEI, hlei@ruc.edu.cn. All rights reserved.
BYAPP, Displex, 2.0
INFO, 9T mag, Release 2.0.
INFO, Channel 1, Temperature Sensor
INFO, Sample 1 Length (cm): 0.000000; Width (cm): 0.000000; Thickness (cm): 0.000000.

[Data]
Timestamp(s),Field(Oe),Field Status,TempA(K),TempB(K),TempC(K),TempD(K),Ramp1,Ramp2,Setpoint1,Setpoint2,Output1(%),Output2(%),Temp Status
3755481258.718400,0,1,300.026,300.005,42.273,3.225,0,0,300.000,300.000,16.430,10.560,1
3755481408.718400,0,1,299.986,300.002,42.596,3.227,0,0,300.000,300.000,13.270,10.370,1
3755481558.718400,0,1,300.012,300.000,42.797,3.227,0,0,300.000,300.000,15.950,10.340,1
3755481708.718400,0,1,299.990,300.001,42.898,3.226,0,0,300.000,300.000,13.350,10.310,1
3755481858.718400,0,1,300.008,300.000,42.924,3.228,0,0,300.000,300.000,15.690,10.270,1
3755482008.718400,0,1,299.993,299.999,42.907,3.227,0,0,300.000,300.000,13.510,10.270,1
3755482158.718400,0,1,300.002,300.000,42.861,3.228,0,0,300.000,300.000,15.420,10.270,1
3755482308.718400,0,1,294.852,294.542,42.804,3.226,1,1,2.000,2.000,0.000,0.000,3
3755482458.718400,0,1,288.944,289.337,42.734,3.227,1,1,2.000,2.000,0.000,0.000,3
3755482608.718400,0,1,283.841,284.685,42.662,3.226,1,1,2.000,2.000,0.000,0.000,3
3755482758.718400,0,1,279.377,280.494,42.589,3.226,1,1,2.000,2.000,0.000,0.000,3
3755482908.718400,0,1,275.345,276.651,42.520,3.225,1,1,2.000,2.000,0.000,0.000,3
3755483058.718400,0,1,271.745,273.164,42.455,3.225,1,1,2.000,2.000,0.000,0.000,3
3755483208.718400,0,1,268.448,269.939,42.392,3.225,1,1,2.000,2.000,0.000,0.000,3
3755483358.718400,0,1,265.440,266.959,42.332,3.224,1,1,2.000,2.000,0.000,0.000,3
3755483508.718400,0,1,262.690,264.189,42.276,3.222,1,1,2.000,2.000,0.000,0.000,3
3755483658.718400,0,1,260.117,261.633,42.221,3.224,1,1,2.000,2.000,0.000,0.000,3
3755483808.718400,0,1,257.699,259.217,42.174,3.221,1,1,2.000,2.000,0.000,0.000,3
3755483958.718400,0,1,255.441,256.940,42.129,3.222,1,1,2.000,2.000,0.000,0.000,3
3755484108.718400,0,1,253.301,254.780,42.084,3.221,1,1,2.000,2.000,0.000,0.000,3
3755484258.718400,0,1,251.267,252.730,42.044,3.219,1,1,2.000,2.000,0.000,0.000,3
3755484408.718400,0,1,249.315,250.765,42.004,3.219,1,1,2.000,2.000,0.000,0.000,3
3755484558.718400,0,1,247.446,248.883,41.968,3.217,1,1,2.000,2.000,0.000,0.000,3
3755484708.718400,0,1,245.633,247.051,41.932,3.217,1,1,2.000,2.000,0.000,0.000,3
3755484858.718400,0,1,243.899,245.298,41.898,3.217,1,1,2.000,2.000,0.000,0.000,3
3755485008.718400,0,1,242.204,243.591,41.864,3.216,1,1,2.000,2.000,0.000,0.000,3
3755485158.718400,0,1,240.561,241.931,41.831,3.215,1,1,2.000,2.000,0.000,0.000,3
3755485308.718400,0,1,238.961,240.316,41.798,3.215,1,1,2.000,2.000,0.000,0.000,3
3755485458.718400,0,1,237.397,238.727,41.763,3.213,1,1,2.000,2.000,0.000,0.000,3
3755485608.718400,0,1,235.859,237.176,41.731,3.215,1,1,2.000,2.000,0.000,0.000,3
3755485758.718400,0,1,234.356,235.665,41.696,3.213,1,1,2.000,2.000,0.000,0.000,3
3755485908.718400,0,1,232.874,234.175,41.663,3.214,1,1,2.000,2.000,0.000,0.000,3
3755486058.718400,0,1,231.415,232.707,41.629,3.212,1,1,2.000,2.000,0.000,0.000,3
3755486208.718400,0,1,229.978,231.266,41.596,3.210,1,1,2.000,2.000,0.000,0.000,3
3755486358.718400,0,1,228.565,229.844,41.566,3.209,1,1,2.000,2.000,0.000,0.000,3
3755486508.718400,0,1,227.169,228.441,41.532,3.208,1,1,2.000,2.000,0.000,0.000,3
3755486658.718400,0,1,225.792,227.060,41.501,3.209,1,1,2.000,2.000,0.000,0.000,3
3755486808.718400,0,1,224.431,225.695,41.471,3.206,1,1,2.000,2.000,0.000,0.000,3
3755486958.718400,0,1,223.084,224.348,41.439,3.207,1,1,2.000,2.000,0.000,0.000,3
3755487108.718400,0,1,221.756,223.020,41.409,3.206,1,1,2.000,2.000,0.000,0.000,3
3755487258.718400,0,1,220.433,221.692,41.377,3.204,1,1,2.000,2.000,0.000,0.000,3
3755487408.718400,0,1,219.131,220.380,41.346,3.205,1,1,2.000,2.000,0.000,0.000,3
3755487558.718400,0,1,217.833,219.077,41.313,3.206,1,1,2.000,2.000,0.000,0.000,3
3755487708.718400,0,1,216.555,217.797,41.284,3.205,1,1,2.000,2.000,0.000,0.000,3
3755487858.718400,0,1,215.280,216.518,41.252,3.205,1,1,2.000,2.000,0.000,0.000,3
3755488008.718400,0,1,214.022,215.261,41.219,3.203,1,1,2.000,2.000,0.000,0.000,3
3755488158.718400,0,1,212.767,214.008,41.189,3.203,1,1,2.000,2.000,0.000,0.000,3
3755488308.718400,0,1,211.534,212.777,41.159,3.202,0,0,2.000,2.000,0.000,0.000,4
3755488458.718400,0,1,210.297,211.540,41.128,3.203,0,0,2.000,2.000,0.000,0.000,4
3755488608.718400,0,1,209.081,210.325,41.098,3.201,0,0,2.000,2.000,0.000,0.000,4
3755488758.718400,0,1,207.874,209.118,41.066,3.201,0,0,2.000,2.000,0.000,0.000,4
3755488908.718400,0,1,206.668,207.912,41.035,3.200,0,0,2.000,2.000,0.000,0.000,4
3755489058.718400,0,1,205.477,206.724,41.005,3.200,0,0,2.000,2.000,0.000,0.000,4
3755489208.718400,0,1,204.286,205.533,40.975,3.198,0,0,2.000,2.000,0.000,0.000,4
3755489358.718400,0,1,203.114,204.362,40.943,3.197,0,0,2.000,2.000,0.000,0.000,4
3755489508.718400,0,1,201.945,203.191,40.913,3.198,0,0,2.000,2.000,0.000,0.000,4
3755489658.718400,0,1,200.782,202.026,40.883,3.197,0,0,2.000,2.000,0.000,0.000,4
3755489808.718400,0,1,199.633,200.879,40.851,3.196,0,0,2.000,2.000,0.000,0.000,4
3755489958.718400,0,1,198.488,199.730,40.818,3.195,0,0,2.000,2.000,0.000,0.000,4
3755490108.718400,0,1,197.349,198.591,40.785,3.195,0,0,2.000,2.000,0.000,0.000,4
3755490258.718400,0,1,196.224,197.466,40.752,3.195,0,0,2.000,2.000,0.000,0.000,4
3755490408.718400,0,1,195.100,196.340,40.724,3.193,0,0,2.000,2.000,0.000,0.000,4
3755490558.718400,0,1,193.981,195.223,40.692,3.193,0,0,2.000,2.000,0.000,0.000,4
3755490708.718400,0,1,192.871,194.114,40.656,3.193,0,0,2.000,2.000,0.000,0.000,4
3755490858.718400,0,1,191.776,193.019,40.623,3.191,0,0,2.000,2.000,0.000,0.000,4
3755491008.718400,0,1,190.680,191.924,40.592,3.190,0,0,2.000,2.000,0.000,0.000,4
3755491158.718400,0,1,189.591,190.836,40.560,3.190,0,0,2.000,2.000,0.000,0.000,4
3755491308.718400,0,1,188.509,189.754,40.528,3.189,0,0,2.000,2.000,0.000,0.000,4
3755491458.718400,0,1,187.435,188.681,40.496,3.188,0,0,2.000,2.000,0.000,0.000,4
3755491608.718400,0,1,186.365,187.611,40.465,3.189,0,0,2.000,2.000,0.000,0.000,4
3755491758.718400,0,1,185.301,186.549,40.433,3.190,0,0,2.000,2.000,0.000,0.000,4
3755491908.718400,0,1,184.245,185.494,40.402,3.189,0,0,2.000,2.000,0.000,0.000,4
3755492058.718400,0,1,183.191,184.445,40.371,3.190,0,0,2.000,2.000,0.000,0.000,4
3755492208.718400,0,1,182.147,183.401,40.340,3.191,0,0,2.000,2.000,0.000,0.000,4
3755492358.718400,0,1,181.107,182.363,40.312,3.188,0,0,2.000,2.000,0.000,0.000,4
3755492508.718400,0,1,180.073,181.332,40.281,3.188,0,0,2.000,2.000,0.000,0.000,4
3755492658.718400,0,1,179.047,180.306,40.252,3.186,0,0,2.000,2.000,0.000,0.000,4
3755492808.718400,0,1,178.018,179.279,40.221,3.186,0,0,2.000,2.000,0.000,0.000,4
3755492958.718400,0,1,176.998,178.261,40.191,3.186,0,0,2.000,2.000,0.000,0.000,4
3755493108.718400,0,1,175.988,177.250,40.160,3.185,0,0,2.000,2.000,0.000,0.000,4
3755493258.718400,0,1,174.982,176.245,40.130,3.185,0,0,2.000,2.000,0.000,0.000,4
3755493408.718400,0,1,173.981,175.243,40.099,3.185,0,0,2.000,2.000,0.000,0.000,4
3755493558.718400,0,1,172.986,174.248,40.069,3.185,0,0,2.000,2.000,0.000,0.000,4
3755493708.718400,0,1,171.988,173.250,40.037,3.183,0,0,2.000,2.000,0.000,0.000,4
3755493858.718400,0,1,171.003,172.267,40.002,3.183,0,0,2.000,2.000,0.000,0.000,4
3755494008.718400,0,1,170.024,171.289,39.971,3.183,0,0,2.000,2.000,0.000,0.000,4
3755494158.718400,0,1,169.042,170.309,39.941,3.182,0,0,2.000,2.000,0.000,0.000,4
3755494308.718400,0,1,168.071,169.339,39.910,3.182,0,0,2.000,2.000,0.000,0.000,4
3755494458.718400,0,1,167.104,168.374,39.879,3.183,0,0,2.000,2.000,0.000,0.000,4
3755494608.718400,0,1,166.136,167.409,39.848,3.183,0,0,2.000,2.000,0.000,0.000,4
3755494758.718400,0,1,165.177,166.453,39.817,3.183,0,0,2.000,2.000,0.000,0.000,4
3755494908.718400,0,1,164.219,165.495,39.787,3.183,0,0,2.000,2.000,0.000,0.000,4
3755495058.718400,0,1,163.269,164.547,39.757,3.182,0,0,2.000,2.000,0.000,0.000,4
3755495208.718400,0,1,162.320,163.600,39.728,3.182,0,0,2.000,2.000,0.000,0.000,4
3755495358.718400,0,1,161.379,162.661,39.699,3.182,0,0,2.000,2.000,0.000,0.000,4
3755495508.718400,0,1,160.446,161.728,39.671,3.181,0,0,2.000,2.000,0.000,0.000,4
3755495658.718400,0,1,159.509,160.794,39.638,3.181,0,0,2.000,2.000,0.000,0.000,4
3755495808.718400,0,1,158.582,159.869,39.607,3.181,0,0,2.000,2.000,0.000,0.000,4
3755495958.718400,0,1,157.654,158.943,39.577,3.180,0,0,2.000,2.000,0.000,0.000,4
3755496108.718400,0,1,156.731,158.021,39.549,3.179,0,0,2.000,2.000,0.000,0.000,4
3755496258.718400,0,1,155.817,157.109,39.520,3.180,0,0,2.000,2.000,0.000,0.000,4
3755496408.718400,0,1,154.902,156.197,39.488,3.179,0,0,2.000,2.000,0.000,0.000,4
3755496558.718400,0,1,153.989,155.287,39.458,3.180,0,0,2.000,2.000,0.000,0.000,4
3755496708.718400,0,1,153.089,154.386,39.428,3.179,0,0,2.000,2.000,0.000,0.000,4
3755496858.718400,0,1,152.185,153.483,39.399,3.177,0,0,2.000,2.000,0.000,0.000,4
3755497008.718400,0,1,151.291,152.592,39.369,3.179,0,0,2.000,2.000,0.000,0.000,4
3755497158.718400,0,1,150.395,151.696,39.340,3.178,0,0,2.000,2.000,0.000,0.000,4
3755497308.718400,0,1,149.501,150.804,39.311,3.177,0,0,2.000,2.000,0.000,0.000,4
3755497458.718400,0,1,148.619,149.921,39.281,3.177,0,0,2.000,2.000,0.000,0.000,4
3755497608.718400,0,1,147.732,149.036,39.251,3.178,0,0,2.000,2.000,0.000,0.000,4
3755497758.718400,0,1,146.849,148.155,39.222,3.177,0,0,2.000,2.000,0.000,0.000,4
3755497908.718400,0,1,145.970,147.279,39.193,3.176,0,0,2.000,2.000,0.000,0.000,4
3755498058.718400,0,1,145.102,146.413,39.163,3.178,0,0,2.000,2.000,0.000,0.000,4
3755498208.718400,0,1,144.230,145.543,39.135,3.177,0,0,2.000,2.000,0.000,0.000,4
3755498358.718400,0,1,143.361,144.677,39.107,3.177,0,0,2.000,2.000,0.000,0.000,4
3755498508.718400,0,1,142.498,143.817,39.078,3.178,0,0,2.000,2.000,0.000,0.000,4
3755498658.718400,0,1,141.641,142.962,39.050,3.175,0,0,2.000,2.000,0.000,0.000,4
3755498808.718400,0,1,140.782,142.105,39.023,3.176,1,1,140.000,140.000,0.000,0.000,3
3755498958.718400,0,1,139.926,141.251,38.995,3.176,1,1,140.000,140.000,0.000,0.000,3
3755499108.718400,0,1,139.077,140.403,38.968,3.176,1,1,140.000,140.000,0.000,0.000,3
3755499258.718400,0,1,138.231,139.558,38.941,3.174,1,1,140.000,140.000,0.000,0.000,3
3755499408.718400,0,1,137.388,138.717,38.916,3.174,1,1,140.000,140.000,0.000,0.000,3
3755499558.718400,0,1,136.543,137.873,38.888,3.174,1,1,140.000,140.000,0.000,0.000,3
3755499691.681400,0,1,135.804,137.137,38.865,3.174,1,1,140.000,140.000,0.000,0.000,3
3755499841.681400,0,1,134.965,136.302,38.837,3.173,1,1,140.000,140.000,0.000,0.000,3
3755499991.681400,0,1,134.137,135.475,38.808,3.173,1,1,140.000,140.000,0.000,0.000,3
3755500141.681400,0,1,133.302,134.643,38.781,3.174,1,1,140.000,140.000,0.000,0.000,3
3755500291.681400,0,1,132.477,133.821,38.752,3.174,1,1,140.000,140.000,0.000,0.000,3
3755500441.681400,0,1,131.655,133.000,38.727,3.174,1,1,140.000,140.000,0.000,0.000,3
3755500591.681400,0,1,130.834,132.183,38.699,3.174,1,1,140.000,140.000,0.000,0.000,3
3755500741.681400,0,1,130.011,131.360,38.671,3.174,1,1,140.000,140.000,0.000,0.000,3
3755500891.681400,0,1,129.196,130.548,38.644,3.173,1,1,140.000,140.000,0.000,0.000,3
3755501017.116400,0,1,128.519,129.872,38.622,3.172,1,1,140.000,140.000,0.000,0.000,3
3755501167.116400,0,1,127.702,129.058,38.594,3.171,1,1,129.300,129.300,0.000,0.000,3
3755501317.116400,0,1,126.898,128.256,38.563,3.172,1,1,100.000,100.000,0.000,0.000,3
3755501467.116400,0,1,126.089,127.449,38.535,3.173,1,1,100.000,100.000,0.000,0.000,3
3755501617.116400,0,1,125.287,126.651,38.508,3.172,1,1,100.000,100.000,0.000,0.000,3
3755501767.116400,0,1,124.488,125.853,38.482,3.173,0,0,100.000,100.000,0.000,0.000,4
3755501917.116400,0,1,123.686,125.052,38.457,3.172,0,0,100.000,100.000,0.000,0.000,4
3755502067.116400,0,1,122.891,124.259,38.433,3.171,0,0,100.000,100.000,0.000,0.000,4
3755502217.116400,0,1,122.099,123.469,38.407,3.170,0,0,100.000,100.000,0.000,0.000,4
3755502367.116400,0,1,121.309,122.681,38.384,3.171,0,0,100.000,100.000,0.000,0.000,4
3755502517.116400,0,1,120.518,121.891,38.360,3.170,0,0,100.000,100.000,0.000,0.000,4
3755502667.116400,0,1,119.732,121.106,38.335,3.170,0,0,100.000,100.000,0.000,0.000,4
3755502817.116400,0,1,118.950,120.326,38.313,3.169,0,0,100.000,100.000,0.000,0.000,4
3755502967.116400,0,1,118.168,119.546,38.288,3.170,0,0,100.000,100.000,0.000,0.000,4
3755503117.116400,0,1,117.384,118.765,38.263,3.171,0,0,100.000,100.000,0.000,0.000,4
3755503267.116400,0,1,116.606,117.990,38.238,3.170,0,0,100.000,100.000,0.000,0.000,4
3755503417.116400,0,1,115.831,117.218,38.214,3.169,0,0,100.000,100.000,0.000,0.000,4
3755503567.116400,0,1,115.057,116.449,38.190,3.169,0,0,100.000,100.000,0.000,0.000,4
3755503717.116400,0,1,114.280,115.676,38.166,3.168,0,0,100.000,100.000,0.000,0.000,4
3755503867.116400,0,1,113.512,114.908,38.142,3.168,0,0,100.000,100.000,0.000,0.000,4
3755504017.116400,0,1,112.745,114.144,38.118,3.168,0,0,100.000,100.000,0.000,0.000,4
3755504167.116400,0,1,111.980,113.382,38.096,3.168,0,0,100.000,100.000,0.000,0.000,4
3755504317.116400,0,1,111.210,112.616,38.072,3.167,0,0,100.000,100.000,0.000,0.000,4
3755504467.116400,0,1,110.448,111.857,38.049,3.168,0,0,100.000,100.000,0.000,0.000,4
3755504617.116400,0,1,109.689,111.101,38.027,3.168,0,0,100.000,100.000,0.000,0.000,4
3755504767.116400,0,1,108.932,110.346,38.006,3.169,0,0,100.000,100.000,0.000,0.000,4
3755504917.116400,0,1,108.170,109.586,37.983,3.168,0,0,100.000,100.000,0.000,0.000,4
3755505067.116400,0,1,107.414,108.834,37.959,3.169,0,0,100.000,100.000,0.000,0.000,4
3755505217.116400,0,1,106.661,108.083,37.936,3.170,0,0,100.000,100.000,0.000,0.000,4
3755505367.116400,0,1,105.908,107.333,37.915,3.170,0,0,100.000,100.000,0.000,0.000,4
3755505517.116400,0,1,105.157,106.586,37.896,3.169,0,0,100.000,100.000,0.000,0.000,4
3755505667.116400,0,1,104.403,105.835,37.872,3.167,0,0,100.000,100.000,0.000,0.000,4
3755505817.116400,0,1,103.655,105.090,37.853,3.168,0,0,100.000,100.000,0.000,0.000,4
3755505967.116400,0,1,102.909,104.347,37.829,3.170,0,0,100.000,100.000,0.000,0.000,4
3755506117.116400,0,1,102.163,103.606,37.808,3.168,0,0,100.000,100.000,0.000,0.000,4
3755506267.116400,0,1,101.417,102.862,37.786,3.167,0,0,100.000,100.000,0.000,0.000,4
3755506417.116400,0,1,100.675,102.123,37.764,3.168,0,0,100.000,100.000,0.000,0.000,4
3755506567.116400,0,1,99.943,101.385,37.744,3.168,0,0,100.000,100.000,0.590,0.000,4
3755506717.116400,0,1,100.021,100.668,37.724,3.167,0,0,100.000,100.000,0.840,0.000,4
3755506867.116400,0,1,100.010,100.013,37.705,3.169,0,0,100.000,100.000,1.490,0.000,4
3755507017.116400,2410,2,99.995,99.999,37.686,3.313,0,0,100.000,100.000,1.700,0.670,1
3755507167.116400,9805,2,99.996,99.999,37.660,3.725,0,0,100.000,100.000,1.780,0.730,1
3755507317.116400,8813,3,100.000,99.999,37.656,3.188,0,0,100.000,100.000,1.890,0.790,1
3755507467.116400,1355,3,99.999,100.000,37.627,3.689,0,0,100.000,100.000,2.040,0.850,1
3755507617.116400,-5934,3,99.999,99.999,37.598,3.926,0,0,100.000,100.000,2.170,0.900,1
3755507767.116400,-10000,1,100.000,100.000,37.590,3.240,0,0,100.000,100.000,2.280,0.940,1
3755507917.116400,-5319,2,99.999,99.999,37.576,3.439,0,0,100.000,100.000,2.370,0.990,1
3755508067.116400,2016,2,99.999,100.000,37.552,3.827,0,0,100.000,100.000,2.500,1.040,1
3755508217.116400,9487,2,99.999,99.999,37.532,3.752,0,0,100.000,100.000,2.580,1.070,1
3755508367.116400,3771,3,100.000,99.999,37.526,3.714,0,0,100.000,100.000,2.660,1.110,1
3755508517.116400,-6999,3,99.999,99.999,37.486,3.747,0,0,100.000,100.000,2.750,1.150,1
3755508667.116400,4895,2,99.999,100.000,37.476,4.067,0,0,100.000,100.000,2.820,1.170,1
3755508817.116400,-1948,2,100.000,99.999,37.463,3.765,0,0,100.000,100.000,2.880,1.210,1
3755508967.116400,-1665,3,100.000,99.999,37.453,3.396,0,0,100.000,100.000,2.970,1.240,1
3755509117.116400,-814,3,99.999,100.000,37.434,3.199,0,0,100.000,100.000,3.030,1.260,1
3755509267.116400,-240,2,99.998,99.999,37.411,3.170,0,0,100.000,100.000,3.080,1.290,1
3755509417.116400,0,1,100.000,100.000,37.390,3.167,0,0,100.000,100.000,3.140,1.310,1
3755509567.116400,1270,2,100.000,99.999,37.370,3.181,0,0,100.000,100.000,3.200,1.340,1
3755509717.116400,4221,2,100.000,99.999,37.351,3.531,0,0,100.000,100.000,3.260,1.360,1
3755509867.116400,7218,2,99.999,99.999,37.336,3.458,0,0,100.000,100.000,3.320,1.380,1
3755510017.116400,9998,2,99.999,100.001,37.322,3.368,0,0,100.000,100.000,3.360,1.390,1
3755510167.116400,9043,3,100.000,100.000,37.309,3.174,0,0,100.000,100.000,3.390,1.420,1
3755510317.116400,6051,3,99.999,100.000,37.293,3.268,0,0,100.000,100.000,3.460,1.440,1
3755510467.116400,3079,3,99.999,99.999,37.273,3.377,0,0,100.000,100.000,3.480,1.460,1
3755510617.116400,131,3,100.001,100.000,37.257,3.417,0,0,100.000,100.000,3.530,1.470,1
3755510767.116400,-2761,3,100.000,100.000,37.241,3.567,0,0,100.000,100.000,3.560,1.480,1
3755510917.116400,-5739,3,100.000,100.000,37.226,3.522,0,0,100.000,100.000,3.600,1.500,1
3755511067.116400,-8740,3,100.000,99.999,37.215,3.432,0,0,100.000,100.000,3.630,1.510,1
3755511217.116400,-10000,1,100.000,99.999,37.206,3.177,0,0,100.000,100.000,3.660,1.520,1
3755511367.116400,-7567,2,100.000,100.000,37.191,3.207,0,0,100.000,100.000,3.690,1.530,1
3755511517.116400,-4574,2,99.999,100.000,37.175,3.331,0,0,100.000,100.000,3.700,1.540,1
3755511667.116400,-1595,2,99.998,100.000,37.160,3.403,0,0,100.000,100.000,3.730,1.550,1
3755511817.116400,1276,2,99.999,100.000,37.147,3.551,0,0,100.000,100.000,3.770,1.560,1
3755511967.116400,4229,2,100.000,100.000,37.133,3.595,0,0,100.000,100.000,3.790,1.570,1
3755512117.116400,7241,2,100.000,99.999,37.124,3.469,0,0,100.000,100.000,3.800,1.580,1
3755512267.116400,10000,2,100.002,100.000,37.115,3.365,0,0,100.000,100.000,3.810,1.590,1
3755512411.348400,10000,1,100.000,100.000,37.107,3.169,0,0,100.000,100.000,3.830,1.590,1
3755512625.375400,10000,1,100.000,100.000,37.087,3.167,0,0,100.000,100.000,3.860,1.610,1
3755512775.375400,10000,1,100.000,100.000,37.075,3.165,0,0,100.000,100.000,3.870,1.620,1
3755512925.375400,3113,4,100.000,100.000,37.060,3.749,0,0,100.000,100.000,3.900,1.630,1
3755513075.375400,1043,2,99.999,100.000,37.051,3.192,0,0,100.000,100.000,3.920,1.630,1
3755513225.375400,3997,2,100.000,100.000,37.041,3.245,0,0,100.000,100.000,3.930,1.640,1
3755513497.436400,-1,4,100.001,100.000,37.018,3.230,0,0,100.000,100.000,3.950,1.640,1
3755513682.525400,1668,2,99.999,100.000,37.004,3.175,0,0,100.000,100.000,3.970,1.660,1
3755513964.798400,5000,1,100.000,100.000,36.984,3.167,0,0,100.000,100.000,4.010,1.670,1
3755514114.798400,5000,1,100.000,100.000,36.975,3.166,0,0,100.000,100.000,4.020,1.670,1
3755514264.798400,-3105,2,99.999,100.000,36.955,3.938,0,0,100.000,100.000,4.020,1.670,1
3755514414.798400,-1455,3,100.000,100.000,36.957,3.425,0,0,100.000,100.000,4.020,1.680,1
3755514564.798400,-681,3,100.000,100.000,36.954,3.210,0,0,100.000,100.000,4.020,1.680,1
3755514714.798400,-410,3,100.001,100.000,36.943,3.168,0,0,100.000,100.000,4.050,1.690,1
3755514864.798400,142,2,100.000,99.999,36.934,3.165,0,0,100.000,100.000,4.050,1.700,1
3755515014.798400,0,1,106.522,106.408,36.924,3.166,1,1,300.000,300.000,19.410,10.210,2
3755515164.798400,0,1,113.737,113.873,36.921,3.164,1,1,300.000,300.000,20.580,11.540,2
3755515314.798400,0,1,121.258,121.300,36.920,3.165,1,1,300.000,300.000,20.000,12.820,2
3755515464.798400,0,1,128.816,128.759,36.921,3.165,1,1,300.000,300.000,22.500,14.100,2
3755515614.798400,0,1,136.168,136.169,36.926,3.167,1,1,300.000,300.000,25.310,15.290,2
3755515764.798400,0,1,143.619,143.630,36.932,3.167,1,1,300.000,300.000,26.570,16.420,2
3755515914.798400,0,1,151.056,151.038,36.937,3.167,1,1,300.000,300.000,28.210,17.450,2
3755516064.798400,0,1,158.496,158.493,36.946,3.167,1,1,300.000,300.000,30.090,18.500,2
3755516214.798400,0,1,165.910,165.905,36.957,3.168,1,1,300.000,300.000,31.300,19.400,2
3755516364.798400,0,1,173.378,173.369,36.971,3.168,1,1,300.000,300.000,32.930,20.440,2
3755516514.798400,0,1,180.790,180.786,36.985,3.168,1,1,300.000,300.000,34.280,21.390,2
3755516664.798400,0,1,188.211,188.202,37.001,3.169,1,1,300.000,300.000,35.540,22.380,2
3755516814.798400,0,1,195.612,195.606,37.017,3.168,1,1,300.000,300.000,36.910,23.300,2
3755516964.798400,0,1,203.062,203.056,37.036,3.169,1,1,300.000,300.000,37.920,24.260,2
3755517114.798400,0,1,210.468,210.458,37.057,3.171,1,1,300.000,300.000,39.400,25.240,2
3755517264.798400,0,1,217.921,217.916,37.082,3.171,1,1,300.000,300.000,40.460,26.240,2
3755517414.798400,0,1,225.324,225.318,37.108,3.171,1,1,300.000,300.000,41.640,27.260,2
3755517564.798400,0,1,232.774,232.763,37.138,3.172,1,1,300.000,300.000,42.740,28.240,2
3755517714.798400,0,1,240.179,240.169,37.171,3.174,1,1,300.000,300.000,43.820,29.130,2
3755517864.798400,0,1,247.634,247.622,37.206,3.174,1,1,300.000,300.000,44.840,30.140,2
3755518014.798400,0,1,255.034,255.029,37.243,3.173,1,1,300.000,300.000,45.940,31.240,2
3755518164.798400,0,1,262.484,262.463,37.282,3.175,1,1,300.000,300.000,46.960,32.050,2
3755518314.798400,0,1,269.878,269.871,37.323,3.175,1,1,300.000,300.000,47.980,33.150,2
3755518464.798400,0,1,277.339,277.322,37.370,3.174,1,1,300.000,300.000,48.780,34.200,2
3755518614.798400,0,1,284.904,284.731,37.416,3.177,1,1,300.000,300.000,42.870,35.140,2
3755518764.798400,0,1,292.083,292.174,37.467,3.175,1,1,300.000,300.000,57.040,36.200,2
3755518914.798400,0,1,299.660,299.575,37.519,3.177,1,1,300.000,300.000,46.150,37.170,2
3755519064.798400,0,1,300.332,300.018,37.571,3.177,0,0,300.000,300.000,29.030,25.270,1
3755519214.798400,0,1,299.736,300.008,37.619,3.176,0,0,300.000,300.000,39.930,24.030,1
3755519364.798400,0,1,300.266,0.000,37.667,3.175,0,0,300.000,300.000,26.620,0.000,4
3755519514.798400,0,1,299.717,0.000,37.797,3.178,0,0,300.000,300.000,44.670,0.000,4
3755519664.798400,0,1,300.239,0.000,37.910,3.179,0,0,300.000,300.000,29.870,0.000,4
3755519814.798400,0,1,299.807,0.000,37.959,3.179,0,0,300.000,300.000,41.710,0.000,4
3755519964.798400,0,1,300.170,0.000,37.987,3.180,0,0,300.000,300.000,29.110,0.000,4
3755520114.798400,0,1,299.867,0.000,38.012,3.181,0,0,300.000,300.000,39.180,0.000,4
3755520264.798400,0,1,300.118,0.000,38.039,3.180,0,0,300.000,300.000,28.550,0.000,4
3755520414.798400,0,1,299.926,0.000,38.071,3.181,0,0,300.000,300.000,36.850,0.000,4
3755520564.798400,0,1,300.069,0.000,38.106,3.181,0,0,300.000,300.000,28.000,0.000,4
3755520714.798400,0,1,299.950,0.000,38.143,3.182,0,0,300.000,300.000,34.950,0.000,4
3755520864.798400,0,1,300.046,0.000,38.183,3.182,0,0,300.000,300.000,27.500,0.000,4
3755521014.798400,0,1,299.981,0.000,38.224,3.183,0,0,300.000,300.000,33.070,0.000,4
3755521164.798400,0,1,300.020,0.000,38.268,3.185,0,0,300.000,300.000,26.910,0.000,4
3755521314.798400,0,1,299.991,0.000,38.309,3.186,0,0,300.000,300.000,31.550,0.000,4
3755521464.798400,0,1,300.011,0.000,38.354,3.187,0,0,300.000,300.000,26.500,0.000,4
3755521614.798400,0,1,300.008,0.000,38.398,3.186,0,0,300.000,300.000,30.170,0.000,4
3755521764.798400,0,1,299.996,0.000,38.441,3.188,0,0,300.000,300.000,26.040,0.000,4
3755521914.798400,0,1,300.009,0.000,38.485,3.188,0,0,300.000,300.000,28.980,0.000,4
3755522064.798400,0,1,299.995,0.000,38.530,3.190,0,0,300.000,300.000,25.530,0.000,4
3755522214.798400,0,1,300.018,0.000,38.574,3.190,0,0,300.000,300.000,27.840,0.000,4
3755522364.798400,0,1,299.989,0.000,38.616,3.190,0,0,300.000,300.000,25.090,0.000,4
3755522514.798400,0,1,300.014,0.000,38.662,3.192,0,0,300.000,300.000,26.960,0.000,4
3755522664.798400,0,1,299.991,0.000,38.707,3.194,0,0,300.000,300.000,24.740,0.000,4
3755522814.798400,0,1,300.015,0.000,38.753,3.191,0,0,300.000,300.000,26.140,0.000,4
3755522964.798400,0,1,299.992,0.000,38.797,3.192,0,0,300.000,300.000,24.350,0.000,4
3755523114.798400,0,1,300.011,0.000,38.842,3.194,0,0,300.000,300.000,25.360,0.000,4
3755523264.798400,0,1,299.990,0.000,38.884,3.194,0,0,300.000,300.000,23.860,0.000,4
3755523414.798400,0,1,300.014,0.000,38.928,3.195,0,0,300.000,300.000,24.740,0.000,4
3755523564.798400,0,1,299.986,0.000,38.973,3.196,0,0,300.000,300.000,23.540,0.000,4
3755523714.798400,0,1,300.014,0.000,39.016,3.195,0,0,300.000,300.000,24.200,0.000,4
3755523864.798400,0,1,299.988,0.000,39.058,3.197,0,0,300.000,300.000,23.110,0.000,4
3755524014.798400,0,1,300.018,0.000,39.100,3.198,0,0,300.000,300.000,23.620,0.000,4
3755524164.798400,0,1,299.983,0.000,39.144,3.198,0,0,300.000,300.000,22.870,0.000,4
3755524314.798400,0,1,300.021,0.000,39.186,3.198,0,0,300.000,300.000,23.210,0.000,4
3755524464.798400,0,1,299.983,0.000,39.226,3.199,0,0,300.000,300.000,22.520,0.000,4
3755524614.798400,0,1,300.016,0.000,39.266,3.200,0,0,300.000,300.000,22.800,0.000,4
3755524764.798400,0,1,299.987,0.000,39.308,3.200,0,0,300.000,300.000,22.190,0.000,4
3755524914.798400,0,1,300.014,0.000,39.349,3.201,0,0,300.000,300.000,22.470,0.000,4
3755525064.798400,0,1,299.988,0.000,39.390,3.200,0,0,300.000,300.000,21.840,0.000,4
3755525214.798400,0,1,300.014,0.000,39.432,3.201,0,0,300.000,300.000,22.120,0.000,4
3755525364.798400,0,1,299.990,0.000,39.472,3.202,0,0,300.000,300.000,21.630,0.000,4
3755525514.798400,0,1,300.010,0.000,39.511,3.203,0,0,300.000,300.000,21.840,0.000,4
3755525664.798400,0,1,299.996,0.000,39.549,3.202,0,0,300.000,300.000,21.360,0.000,4
3755525814.798400,0,1,300.007,0.000,39.587,3.203,0,0,300.000,300.000,21.610,0.000,4
3755525964.798400,0,1,299.994,0.000,39.625,3.205,0,0,300.000,300.000,21.170,0.000,4
3755526114.798400,0,1,300.007,0.000,39.664,3.205,0,0,300.000,300.000,21.360,0.000,4
3755526264.798400,0,1,299.997,0.000,39.701,3.204,0,0,300.000,300.000,20.950,0.000,4
3755526414.798400,0,1,300.005,0.000,39.739,3.206,0,0,300.000,300.000,21.010,0.000,4
3755526564.798400,0,1,299.996,0.000,39.776,3.207,0,0,300.000,300.000,20.790,0.000,4
3755526714.798400,0,1,300.005,0.000,39.814,3.206,0,0,300.000,300.000,20.810,0.000,4
3755526864.798400,0,1,299.995,0.000,39.849,3.207,0,0,300.000,300.000,20.610,0.000,4
3755527014.798400,0,1,300.005,0.000,39.884,3.206,0,0,300.000,300.000,20.540,0.000,4
3755527164.798400,0,1,299.996,0.000,39.917,3.207,0,0,300.000,300.000,20.470,0.000,4
3755527314.798400,0,1,300.005,0.000,39.950,3.207,0,0,300.000,300.000,20.380,0.000,4
3755527464.798400,0,1,299.996,0.000,39.982,3.207,0,0,300.000,300.000,20.340,0.000,4
3755527614.798400,0,1,300.002,0.000,40.015,3.209,0,0,300.000,300.000,20.230,0.000,4
3755527764.798400,0,1,299.994,0.000,40.046,3.209,0,0,300.000,300.000,20.200,0.000,4
3755527914.798400,0,1,300.002,0.000,40.080,3.209,0,0,300.000,300.000,20.090,0.000,4
3755528064.798400,0,1,299.996,0.000,40.110,3.210,0,0,300.000,300.000,20.070,0.000,4
3755528214.798400,0,1,300.003,0.000,40.142,3.210,0,0,300.000,300.000,19.960,0.000,4
3755528364.798400,0,1,299.997,0.000,40.171,3.211,0,0,300.000,300.000,19.910,0.000,4
3755528514.798400,0,1,300.006,0.000,40.202,3.211,0,0,300.000,300.000,19.850,0.000,4
3755528664.798400,0,1,299.994,0.000,40.232,3.211,0,0,300.000,300.000,19.830,0.000,4
3755528814.798400,0,1,300.006,0.000,40.262,3.212,0,0,300.000,300.000,19.670,0.000,4
3755528964.798400,0,1,299.996,0.000,40.293,3.211,0,0,300.000,300.000,19.720,0.000,4
3755529114.798400,0,1,300.005,0.000,40.322,3.211,0,0,300.000,300.000,19.650,0.000,4
3755529264.798400,0,1,299.997,0.000,40.351,3.211,0,0,300.000,300.000,19.560,0.000,4
3755529414.798400,0,1,300.003,0.000,40.377,3.214,0,0,300.000,300.000,19.520,0.000,4
3755529564.798400,0,1,299.999,0.000,40.403,3.212,0,0,300.000,300.000,19.520,0.000,4
3755529714.798400,0,1,300.001,0.000,40.429,3.213,0,0,300.000,300.000,19.450,0.000,4
3755529864.798400,0,1,300.001,0.000,40.454,3.214,0,0,300.000,300.000,19.360,0.000,4
3755530014.798400,0,1,299.998,0.000,40.478,3.215,0,0,300.000,300.000,19.430,0.000,4
3755530164.798400,0,1,300.004,0.000,40.501,3.213,0,0,300.000,300.000,19.280,0.000,4
3755530314.798400,0,1,299.997,0.000,40.526,3.214,0,0,300.000,300.000,19.280,0.000,4
3755530464.798400,0,1,300.002,0.000,40.550,3.216,0,0,300.000,300.000,19.150,0.000,4
3755530614.798400,0,1,300.000,0.000,40.574,3.215,0,0,300.000,300.000,19.190,0.000,4
3755530764.798400,0,1,300.002,0.000,40.598,3.214,0,0,300.000,300.000,19.150,0.000,4
3755530914.798400,0,1,300.000,0.000,40.622,3.215,0,0,300.000,300.000,19.150,0.000,4
3755531064.798400,0,1,300.001,0.000,40.645,3.216,0,0,300.000,300.000,19.040,0.000,4
3755531214.798400,0,1,300.001,0.000,40.668,3.217,0,0,300.000,300.000,18.990,0.000,4
3755531364.798400,0,1,300.002,0.000,40.692,3.216,0,0,300.000,300.000,19.040,0.000,4
3755531514.798400,0,1,299.998,0.000,40.711,3.218,0,0,300.000,300.000,18.970,0.000,4
3755531664.798400,0,1,300.001,0.000,40.729,3.219,0,0,300.000,300.000,18.970,0.000,4
3755531814.798400,0,1,300.001,0.000,40.749,3.219,0,0,300.000,300.000,18.840,0.000,4
3755531964.798400,0,1,300.000,0.000,40.769,3.217,0,0,300.000,300.000,18.970,0.000,4
3755532114.798400,0,1,300.001,0.000,40.789,3.218,0,0,300.000,300.000,18.820,0.000,4
3755532264.798400,0,1,300.001,0.000,40.808,3.219,0,0,300.000,300.000,18.890,0.000,4
3755532414.798400,0,1,299.999,0.000,40.827,3.219,0,0,300.000,300.000,18.740,0.000,4
3755532564.798400,0,1,300.000,0.000,40.846,3.219,0,0,300.000,300.000,18.860,0.000,4
3755532714.798400,0,1,299.998,0.000,40.864,3.219,0,0,300.000,300.000,18.760,0.000,4
3755532864.798400,0,1,300.001,0.000,40.882,3.218,0,0,300.000,300.000,18.800,0.000,4
3755533014.798400,0,1,299.999,0.000,40.898,3.218,0,0,300.000,300.000,18.650,0.000,4
3755533164.798400,0,1,299.998,0.000,40.915,3.219,0,0,300.000,300.000,18.690,0.000,4
3755533314.798400,0,1,300.003,0.000,40.929,3.219,0,0,300.000,300.000,18.650,0.000,4
3755533464.798400,0,1,299.999,0.000,40.944,3.219,0,0,300.000,300.000,18.740,0.000,4
3755533614.798400,0,1,300.002,0.000,40.960,3.219,0,0,300.000,300.000,18.520,0.000,4
3755533764.798400,0,1,299.998,0.000,40.975,3.219,0,0,300.000,300.000,18.670,0.000,4
3755533914.798400,0,1,300.000,0.000,40.990,3.221,0,0,300.000,300.000,18.560,0.000,4
3755534064.798400,0,1,299.998,0.000,41.004,3.220,0,0,300.000,300.000,18.560,0.000,4
3755534214.798400,0,1,300.002,0.000,41.023,3.219,0,0,300.000,300.000,18.500,0.000,4
3755534364.798400,0,1,300.000,0.000,41.038,3.220,0,0,300.000,300.000,18.590,0.000,4
3755534514.798400,0,1,300.002,0.000,41.052,3.221,0,0,300.000,300.000,18.460,0.000,4
3755534664.798400,0,1,299.999,0.000,41.065,3.220,0,0,300.000,300.000,18.540,0.000,4
3755534814.798400,0,1,300.002,0.000,41.078,3.221,0,0,300.000,300.000,18.390,0.000,4
3755534964.798400,0,1,299.998,0.000,41.090,3.220,0,0,300.000,300.000,18.520,0.000,4
3755535114.798400,0,1,300.004,0.000,41.102,3.219,0,0,300.000,300.000,18.370,0.000,4
3755535264.798400,0,1,299.997,0.000,41.117,3.222,0,0,300.000,300.000,18.500,0.000,4
3755535414.798400,0,1,300.001,0.000,41.131,3.220,0,0,300.000,300.000,18.350,0.000,4
3755535564.798400,0,1,300.000,0.000,41.143,3.219,0,0,300.000,300.000,18.390,0.000,4
3755535714.798400,0,1,300.004,0.000,41.152,3.220,0,0,300.000,300.000,18.350,0.000,4
3755535864.798400,0,1,299.995,0.000,41.163,3.220,0,0,300.000,300.000,18.390,0.000,4
3755536014.798400,0,1,300.003,0.000,41.173,3.222,0,0,300.000,300.000,18.310,0.000,4
3755536164.798400,0,1,299.995,0.000,41.184,3.220,0,0,300.000,300.000,18.390,0.000,4
3755536314.798400,0,1,300.009,0.000,41.194,3.221,0,0,300.000,300.000,18.120,0.000,4
3755536464.798400,0,1,299.993,0.000,41.205,3.221,0,0,300.000,300.000,18.410,0.000,4
3755536614.798400,0,1,300.005,0.000,41.215,3.221,0,0,300.000,300.000,18.220,0.000,4
3755536764.798400,0,1,299.995,0.000,41.226,3.221,0,0,300.000,300.000,18.440,0.000,4
3755536914.798400,0,1,300.002,0.000,41.236,3.221,0,0,300.000,300.000,18.180,0.000,4
3755537064.798400,0,1,299.998,0.000,41.246,3.221,0,0,300.000,300.000,18.350,0.000,4
3755537214.798400,0,1,300.003,0.000,41.254,3.220,0,0,300.000,300.000,18.180,0.000,4
3755537364.798400,0,1,299.999,0.000,41.262,3.221,0,0,300.000,300.000,18.390,0.000,4
3755537514.798400,0,1,300.001,0.000,41.273,3.222,0,0,300.000,300.000,18.140,0.000,4
3755537664.798400,0,1,299.999,0.000,41.279,3.222,0,0,300.000,300.000,18.270,0.000,4
3755537814.798400,0,1,300.000,0.000,41.287,3.221,0,0,300.000,300.000,18.180,0.000,4
3755537964.798400,0,1,300.000,0.000,41.294,3.221,0,0,300.000,300.000,18.240,0.000,4
3755538114.798400,0,1,300.001,0.000,41.302,3.222,0,0,300.000,300.000,18.140,0.000,4
3755538264.798400,0,1,299.999,0.000,41.311,3.221,0,0,300.000,300.000,18.240,0.000,4
3755538414.798400,0,1,300.003,0.000,41.321,3.221,0,0,300.000,300.000,18.140,0.000,4
3755538564.798400,0,1,299.998,0.000,41.326,3.222,0,0,300.000,300.000,18.220,0.000,4
3755538714.798400,0,1,300.002,0.000,41.329,3.223,0,0,300.000,300.000,18.200,0.000,4
3755538864.798400,0,1,299.995,0.000,41.335,3.224,0,0,300.000,300.000,18.180,0.000,4
3755539014.798400,0,1,300.004,0.000,41.343,3.224,0,0,300.000,300.000,18.160,0.000,4
3755539164.798400,0,1,299.994,0.000,41.348,3.223,0,0,300.000,300.000,18.180,0.000,4
3755539314.798400,0,1,300.004,0.000,41.353,3.224,0,0,300.000,300.000,18.180,0.000,4
3755539464.798400,0,1,300.000,0.000,41.361,3.223,0,0,300.000,300.000,18.080,0.000,4
3755539614.798400,0,1,300.002,0.000,41.367,3.224,0,0,300.000,300.000,18.220,0.000,4
3755539764.798400,0,1,299.998,0.000,41.372,3.224,0,0,300.000,300.000,18.100,0.000,4
3755539914.798400,0,1,299.999,0.000,41.379,3.224,0,0,300.000,300.000,18.140,0.000,4
3755540064.798400,0,1,300.000,0.000,41.384,3.225,0,0,300.000,300.000,18.030,0.000,4
3755540214.798400,0,1,300.000,0.000,41.390,3.224,0,0,300.000,300.000,18.220,0.000,4
3755540364.798400,0,1,299.999,0.000,41.395,3.224,0,0,300.000,300.000,18.030,0.000,4
3755540514.798400,0,1,299.999,0.000,41.401,3.224,0,0,300.000,300.000,18.180,0.000,4
3755540664.798400,0,1,300.002,0.000,41.406,3.225,0,0,300.000,300.000,18.030,0.000,4
3755540814.798400,0,1,299.998,0.000,41.413,3.224,0,0,300.000,300.000,18.160,0.000,4
3755540964.798400,0,1,300.003,0.000,41.419,3.225,0,0,300.000,300.000,17.990,0.000,4
3755541114.798400,0,1,300.000,0.000,41.424,3.224,0,0,300.000,300.000,18.100,0.000,4
3755541264.798400,0,1,300.000,0.000,41.429,3.223,0,0,300.000,300.000,18.010,0.000,4
3755541414.798400,0,1,300.003,0.000,41.435,3.225,0,0,300.000,300.000,18.080,0.000,4
3755541564.798400,0,1,300.000,0.000,41.439,3.223,0,0,300.000,300.000,18.080,0.000,4
3755541714.798400,0,1,299.999,0.000,41.443,3.226,0,0,300.000,300.000,18.080,0.000,4
3755541864.798400,0,1,299.998,0.000,41.445,3.225,0,0,300.000,300.000,18.100,0.000,4
3755542014.798400,0,1,300.000,0.000,41.449,3.226,0,0,300.000,300.000,18.030,0.000,4
3755542164.798400,0,1,300.000,0.000,41.451,3.226,0,0,300.000,300.000,18.080,0.000,4
3755542314.798400,0,1,299.998,0.000,41.453,3.225,0,0,300.000,300.000,18.080,0.000,4
3755542464.798400,0,1,300.000,0.000,41.456,3.226,0,0,300.000,300.000,18.010,0.000,4
3755542614.798400,0,1,300.001,0.000,41.458,3.224,0,0,300.000,300.000,18.050,0.000,4
3755542764.798400,0,1,299.999,0.000,41.461,3.226,0,0,300.000,300.000,18.050,0.000,4
3755542914.798400,0,1,300.002,0.000,41.468,3.225,0,0,300.000,300.000,17.970,0.000,4
3755543064.798400,0,1,299.998,0.000,41.471,3.224,0,0,300.000,300.000,18.050,0.000,4
3755543214.798400,0,1,300.001,0.000,41.477,3.224,0,0,300.000,300.000,17.990,0.000,4
3755543364.798400,0,1,300.000,0.000,41.483,3.223,0,0,300.000,300.000,17.990,0.000,4
3755543514.798400,0,1,300.000,0.000,41.487,3.224,0,0,300.000,300.000,18.010,0.000,4
3755543664.798400,0,1,299.999,0.000,41.489,3.223,0,0,300.000,300.000,18.050,0.000,4
3755543814.798400,0,1,300.001,0.000,41.489,3.224,0,0,300.000,300.000,17.950,0.000,4
3755543964.798400,0,1,300.000,0.000,41.493,3.224,0,0,300.000,300.000,17.990,0.000,4
3755544114.798400,0,1,300.000,0.000,41.494,3.224,0,0,300.000,300.000,17.950,0.000,4
3755544264.798400,0,1,299.999,0.000,41.495,3.223,0,0,300.000,300.000,18.050,0.000,4
3755544414.798400,0,1,300.003,0.000,41.497,3.224,0,0,300.000,300.000,17.970,0.000,4
3755544564.798400,0,1,299.998,0.000,41.500,3.223,0,0,300.000,300.000,17.990,0.000,4
3755544714.798400,0,1,300.004,0.000,41.501,3.223,0,0,300.000,300.000,17.950,0.000,4
3755544864.798400,0,1,299.995,0.000,41.503,3.225,0,0,300.000,300.000,17.970,0.000,4
3755545014.798400,0,1,300.005,0.000,41.502,3.224,0,0,300.000,300.000,17.970,0.000,4
3755545164.798400,0,1,299.994,0.000,41.504,3.223,0,0,300.000,300.000,17.990,0.000,4
3755545314.798400,0,1,300.004,0.000,41.506,3.223,0,0,300.000,300.000,18.030,0.000,4
3755545464.798400,0,1,299.997,0.000,41.507,3.224,0,0,300.000,300.000,17.950,0.000,4
3755545614.798400,0,1,300.004,0.000,41.510,3.223,0,0,300.000,300.000,18.050,0.000,4
3755545764.798400,0,1,299.995,0.000,41.511,3.224,0,0,300.000,300.000,17.890,0.000,4
3755545914.798400,0,1,300.003,0.000,41.511,3.225,0,0,300.000,300.000,18.050,0.000,4
3755546064.798400,0,1,299.996,0.000,41.511,3.225,0,0,300.000,300.000,17.870,0.000,4
3755546214.798400,0,1,300.002,0.000,41.514,3.224,0,0,300.000,300.000,18.050,0.000,4
3755546364.798400,0,1,300.000,0.000,41.520,3.224,0,0,300.000,300.000,17.840,0.000,4
3755546514.798400,0,1,299.995,0.000,41.522,3.224,0,0,300.000,300.000,18.140,0.000,4
3755546664.798400,0,1,300.006,0.000,41.523,3.225,0,0,300.000,300.000,17.890,0.000,4
3755546814.798400,0,1,299.993,0.000,41.527,3.225,0,0,300.000,300.000,18.100,0.000,4
3755546964.798400,0,1,300.003,0.000,41.530,3.224,0,0,300.000,300.000,17.870,0.000,4
3755547114.798400,0,1,299.997,0.000,41.532,3.224,0,0,300.000,300.000,18.030,0.000,4
3755547264.798400,0,1,300.000,0.000,41.535,3.222,0,0,300.000,300.000,17.870,0.000,4
3755547414.798400,0,1,299.995,0.000,41.538,3.224,0,0,300.000,300.000,18.080,0.000,4
3755547564.798400,0,1,300.005,0.000,41.541,3.224,0,0,300.000,300.000,17.910,0.000,4
3755547714.798400,0,1,299.995,0.000,41.542,3.224,0,0,300.000,300.000,18.080,0.000,4
3755547864.798400,0,1,300.006,0.000,41.541,3.225,0,0,300.000,300.000,17.870,0.000,4
3755548014.798400,0,1,299.996,0.000,41.541,3.224,0,0,300.000,300.000,18.050,0.000,4
3755548164.798400,0,1,300.003,0.000,41.545,3.224,0,0,300.000,300.000,17.890,0.000,4
3755548314.798400,0,1,299.996,0.000,41.547,3.224,0,0,300.000,300.000,17.990,0.000,4
3755548464.798400,0,1,300.002,0.000,41.548,3.225,0,0,300.000,300.000,17.870,0.000,4
3755548614.798400,0,1,300.000,0.000,41.546,3.224,0,0,300.000,300.000,17.990,0.000,4
3755548764.798400,0,1,299.999,0.000,41.545,3.224,0,0,300.000,300.000,17.890,0.000,4
3755548914.798400,0,1,299.999,0.000,41.548,3.223,0,0,300.000,300.000,18.050,0.000,4
3755549064.798400,0,1,299.999,0.000,41.549,3.224,0,0,300.000,300.000,17.930,0.000,4
3755549214.798400,0,1,299.998,0.000,41.550,3.224,0,0,300.000,300.000,18.050,0.000,4
3755549364.798400,0,1,299.999,0.000,41.551,3.223,0,0,300.000,300.000,17.820,0.000,4
3755549514.798400,0,1,299.999,0.000,41.552,3.223,0,0,300.000,300.000,18.030,0.000,4
3755549664.798400,0,1,299.999,0.000,41.553,3.224,0,0,300.000,300.000,17.870,0.000,4
3755549814.798400,0,1,300.000,0.000,41.554,3.224,0,0,300.000,300.000,18.050,0.000,4
3755549964.798400,0,1,300.000,0.000,41.554,3.224,0,0,300.000,300.000,17.840,0.000,4
3755550114.798400,0,1,300.000,0.000,41.557,3.223,0,0,300.000,300.000,18.030,0.000,4
3755550264.798400,0,1,300.000,0.000,41.557,3.225,0,0,300.000,300.000,17.870,0.000,4
3755550414.798400,0,1,299.996,0.000,41.559,3.224,0,0,300.000,300.000,18.010,0.000,4
3755550564.798400,0,1,300.005,0.000,41.559,3.224,0,0,300.000,300.000,17.820,0.000,4
3755550714.798400,0,1,299.993,0.000,41.559,3.224,0,0,300.000,300.000,18.010,0.000,4
3755550864.798400,0,1,300.003,0.000,41.561,3.225,0,0,300.000,300.000,17.890,0.000,4
3755551014.798400,0,1,299.996,0.000,41.563,3.225,0,0,300.000,300.000,18.050,0.000,4
3755551164.798400,0,1,300.004,0.000,41.564,3.224,0,0,300.000,300.000,17.720,0.000,4
3755551314.798400,0,1,299.998,0.000,41.562,3.225,0,0,300.000,300.000,17.990,0.000,4
3755551464.798400,0,1,300.004,0.000,41.562,3.224,0,0,300.000,300.000,17.910,0.000,4
3755551614.798400,0,1,299.995,0.000,41.562,3.225,0,0,300.000,300.000,17.950,0.000,4
3755551764.798400,0,1,300.003,0.000,41.562,3.224,0,0,300.000,300.000,17.840,0.000,4
3755551914.798400,0,1,299.995,0.000,41.563,3.226,0,0,300.000,300.000,18.080,0.000,4
3755552064.798400,0,1,300.004,0.000,41.565,3.226,0,0,300.000,300.000,17.760,0.000,4
3755552214.798400,0,1,299.994,0.000,41.567,3.225,0,0,300.000,300.000,18.030,0.000,4
3755552364.798400,0,1,300.005,0.000,41.569,3.224,0,0,300.000,300.000,17.840,0.000,4
3755552514.798400,0,1,299.994,0.000,41.571,3.226,0,0,300.000,300.000,17.970,0.000,4
3755552664.798400,0,1,300.004,0.000,41.575,3.226,0,0,300.000,300.000,17.820,0.000,4
3755552814.798400,0,1,299.993,0.000,41.573,3.227,0,0,300.000,300.000,17.990,0.000,4
3755552964.798400,0,1,300.003,0.000,41.570,3.225,0,0,300.000,300.000,17.800,0.000,4
3755553114.798400,0,1,299.997,0.000,41.571,3.225,0,0,300.000,300.000,17.970,0.000,4
3755553264.798400,0,1,300.002,0.000,41.571,3.225,0,0,300.000,300.000,17.780,0.000,4
3755553414.798400,0,1,299.999,0.000,41.573,3.225,0,0,300.000,300.000,17.990,0.000,4
3755553564.798400,0,1,300.000,0.000,41.572,3.225,0,0,300.000,300.000,17.800,0.000,4
3755553714.798400,0,1,299.999,0.000,41.570,3.224,0,0,300.000,300.000,18.050,0.000,4
3755553864.798400,0,1,300.001,0.000,41.571,3.225,0,0,300.000,300.000,17.740,0.000,4
3755554014.798400,0,1,300.000,0.000,41.574,3.226,0,0,300.000,300.000,18.010,0.000,4
3755554164.798400,0,1,299.997,0.000,41.578,3.225,0,0,300.000,300.000,17.820,0.000,4
3755554314.798400,0,1,300.001,0.000,41.578,3.224,0,0,300.000,300.000,17.990,0.000,4
3755554464.798400,0,1,300.002,0.000,41.578,3.225,0,0,300.000,300.000,17.840,0.000,4
3755554614.798400,0,1,299.998,0.000,41.579,3.226,0,0,300.000,300.000,17.950,0.000,4
3755554764.798400,0,1,300.002,0.000,41.580,3.225,0,0,300.000,300.000,17.840,0.000,4
3755554914.798400,0,1,300.001,0.000,41.581,3.224,0,0,300.000,300.000,17.970,0.000,4
3755555064.798400,0,1,299.999,0.000,41.583,3.225,0,0,300.000,300.000,17.950,0.000,4
3755555214.798400,0,1,300.002,0.000,41.585,3.225,0,0,300.000,300.000,17.970,0.000,4
3755555364.798400,0,1,300.000,0.000,41.585,3.226,0,0,300.000,300.000,17.820,0.000,4
3755555514.798400,0,1,300.000,0.000,41.585,3.224,0,0,300.000,300.000,17.950,0.000,4
3755555664.798400,0,1,300.000,0.000,41.585,3.226,0,0,300.000,300.000,17.840,0.000,4
3755555814.798400,0,1,299.998,0.000,41.584,3.226,0,0,300.000,300.000,17.970,0.000,4
3755555964.798400,0,1,300.002,0.000,41.585,3.225,0,0,300.000,300.000,17.800,0.000,4
3755556024.798400,0,1,300.002,0.000,41.586,3.227,0,0,300.000,300.000,17.970,0.000,4