File: log/20230106.dat
[Header]
; Displex Transport Data File (default extension .dat)
; Copyright 2016, Hechang LEI, hlei@ruc.edu.cn. All rights reserved.
BYAPP, Displex, 2.0
INFO, 9T mag, Release 2.0.
INFO, Channel 1, Temperature Sensor
INFO, Sample 1 Length (cm): 0.000000; Width (cm): 0.000000; Thickness (cm): 0.000000.

[Data]
Timestamp(s),Field(Oe),Field Status,TempA(K),TempB(K),TempC(K),TempD(K),Ramp1,Ramp2,Setpoint1,Setpoint2,Output1(%),Output2(%),Temp Status
3755815594.576400,5000,2,299.999,0.000,40.478,3.123,0,0,300.000,300.000,14.820,0.000,4
3755815654.576400,4582,3,300.001,0.000,40.477,3.124,0,0,300.000,300.000,14.780,0.000,4
3755815714.576400,-1144,3,300.000,0.000,40.475,3.621,0,0,300.000,300.000,14.800,0.000,4
3755815774.576400,-2235,2,299.998,0.000,40.467,3.739,0,0,300.000,300.000,14.800,0.000,4
3755815834.576400,2418,2,300.002,0.000,40.473,3.730,0,0,300.000,300.000,14.780,0.000,4
3755815894.576400,122,3,299.999,0.000,40.481,3.275,0,0,300.000,300.000,14.820,0.000,4
3755815954.576400,-1715,3,299.999,0.000,40.487,3.217,0,0,300.000,300.000,14.760,0.000,4
3755816014.576400,1193,2,299.999,0.000,40.489,3.184,0,0,300.000,300.000,14.800,0.000,4
3755816074.576400,-824,3,300.000,0.000,40.488,3.158,0,0,300.000,300.000,14.740,0.000,4
3755816134.576400,560,2,300.002,0.000,40.487,3.140,0,0,300.000,300.000,14.740,0.000,4
3755816194.576400,-390,3,300.002,0.000,40.486,3.131,0,0,300.000,300.000,14.780,0.000,4
3755816254.576400,279,2,300.000,0.000,40.484,3.126,0,0,300.000,300.000,14.780,0.000,4
3755816314.576400,-196,3,300.001,0.000,40.483,3.123,0,0,300.000,300.000,14.820,0.000,4
3755816374.576400,140,2,299.999,0.000,40.482,3.122,0,0,300.000,300.000,14.820,0.000,4
3755816434.576400,70,2,300.000,0.000,40.480,3.123,0,0,300.000,300.000,14.800,0.000,4
3755816494.576400,-47,1,300.001,0.000,40.478,3.123,0,0,300.000,300.000,14.820,0.000,4
3755816554.576400,0,1,299.998,0.000,40.479,3.123,0,0,300.000,300.000,14.820,0.000,4
3755816614.576400,0,1,300.000,0.000,40.479,3.123,0,0,300.000,300.000,14.800,0.000,4
3755816674.576400,0,1,300.001,0.000,40.479,3.122,0,0,300.000,300.000,14.820,0.000,4
3755816734.576400,0,1,300.001,0.000,40.480,3.124,0,0,300.000,300.000,14.780,0.000,4
3755816794.576400,0,1,299.997,0.000,40.480,3.123,0,0,300.000,300.000,14.840,0.000,4
3755816854.576400,0,1,300.000,0.000,40.480,3.122,0,0,300.000,300.000,14.720,0.000,4
3755816914.576400,0,1,300.000,0.000,40.479,3.123,0,0,300.000,300.000,14.820,0.000,4
3755816974.576400,0,1,299.997,0.000,40.479,3.122,0,0,300.000,300.000,14.760,0.000,4
3755817034.576400,0,1,300.001,0.000,40.479,3.123,0,0,300.000,300.000,14.740,0.000,4
3755817094.576400,0,1,299.998,0.000,40.479,3.123,0,0,300.000,300.000,14.860,0.000,4
3755817154.576400,0,1,299.998,0.000,40.478,3.123,0,0,300.000,300.000,14.720,0.000,4
3755817214.576400,0,1,300.003,0.000,40.478,3.122,0,0,300.000,300.000,14.760,0.000,4
3755817274.576400,0,1,299.997,0.000,40.479,3.122,0,0,300.000,300.000,14.820,0.000,4
3755817334.576400,0,1,300.002,0.000,40.480,3.123,0,0,300.000,300.000,14.740,0.000,4
3755817394.576400,0,1,300.000,0.000,40.481,3.123,0,0,300.000,300.000,14.740,0.000,4
3755817454.576400,0,1,300.000,0.000,40.481,3.123,0,0,300.000,300.000,14.780,0.000,4
3755817514.576400,0,1,300.003,0.000,40.482,3.121,0,0,300.000,300.000,14.820,0.000,4
3755817574.576400,0,1,299.998,0.000,40.481,3.123,0,0,300.000,300.000,14.800,0.000,4
3755817634.576400,0,1,300.001,0.000,40.480,3.122,0,0,300.000,300.000,14.760,0.000,4
3755817694.576400,0,1,300.002,0.000,40.480,3.122,0,0,300.000,300.000,14.760,0.000,4
3755817754.576400,0,1,299.997,0.000,40.479,3.124,0,0,300.000,300.000,14.780,0.000,4
3755817814.576400,0,1,300.004,0.000,40.480,3.122,0,0,300.000,300.000,14.680,0.000,4
3755818100.169400,0,1,300.001,0.000,40.480,3.122,0,0,300.000,300.000,14.740,0.000,4
3755818160.169400,0,1,299.999,0.000,40.480,3.121,0,0,300.000,300.000,14.840,0.000,4
3755818220.169400,0,1,299.997,0.000,40.479,3.122,0,0,300.000,300.000,14.760,0.000,4
3755818280.169400,0,1,300.004,0.000,40.479,3.121,0,0,300.000,300.000,14.820,0.000,4
3755818555.807400,0,1,299.996,0.000,40.477,3.123,0,0,300.000,300.000,14.840,0.000,4
3755818889.118400,0,1,300.003,0.000,40.476,3.121,0,0,300.000,300.000,14.740,0.000,4
3755818949.118400,0,1,299.998,0.000,40.475,3.121,0,0,300.000,300.000,14.840,0.000,4
3755819009.118400,0,1,300.000,0.000,40.476,3.121,0,0,300.000,300.000,14.700,0.000,4
3755819069.118400,0,1,300.001,0.000,40.476,3.123,0,0,300.000,300.000,14.800,0.000,4
3755819267.010400,0,1,300.001,0.000,40.476,3.123,0,0,300.000,300.000,14.840,0.000,4
3755819494.599400,0,1,299.998,0.000,40.477,3.122,0,0,300.000,300.000,14.820,0.000,4
3755819771.300400,0,1,300.010,0.000,40.481,3.124,0,0,300.000,300.000,14.570,0.000,4
3755819831.300400,0,1,299.997,0.000,40.483,3.123,0,0,300.000,300.000,15.070,0.000,4
3755819891.300400,0,1,299.993,0.000,40.485,3.123,0,0,300.000,300.000,14.670,0.000,4
3755819951.300400,0,1,300.011,0.000,40.486,3.123,0,0,300.000,300.000,14.800,0.000,4
3755820011.300400,0,1,299.988,0.000,40.486,3.123,0,0,300.000,300.000,14.880,0.000,4
3755820071.300400,0,1,300.009,0.000,40.487,3.123,0,0,300.000,300.000,14.570,0.000,4
3755820131.300400,0,1,299.999,0.000,40.488,3.123,0,0,300.000,300.000,14.950,0.000,4
3755820191.300400,0,1,299.997,0.000,40.488,3.123,0,0,300.000,300.000,14.570,0.000,4
3755820251.300400,0,1,300.009,0.000,40.488,3.122,0,0,300.000,300.000,14.820,0.000,4
3755820311.300400,0,1,299.986,0.000,40.488,3.124,0,0,300.000,300.000,14.890,0.000,4
3755820371.300400,0,1,300.009,0.000,40.488,3.123,0,0,300.000,300.000,14.590,0.000,4
3755820431.300400,0,1,299.999,0.000,40.488,3.122,0,0,300.000,300.000,14.970,0.000,4
3755820491.300400,0,1,299.993,0.000,40.487,3.123,0,0,300.000,300.000,14.670,0.000,4
3755820551.300400,0,1,300.010,0.000,40.488,3.123,0,0,300.000,300.000,14.760,0.000,4
3755820611.300400,0,1,299.990,0.000,40.488,3.124,0,0,300.000,300.000,14.890,0.000,4
3755820671.300400,0,1,300.005,0.000,40.488,3.124,0,0,300.000,300.000,14.650,0.000,4
3755820731.300400,0,1,300.001,0.000,40.489,3.125,0,0,300.000,300.000,14.930,0.000,4
3755820791.300400,0,1,299.992,0.000,40.490,3.124,0,0,300.000,300.000,14.720,0.000,4
3755820851.300400,0,1,300.011,0.000,40.489,3.124,0,0,300.000,300.000,14.700,0.000,4
3755820911.300400,0,1,299.993,0.000,40.489,3.125,0,0,300.000,300.000,14.890,0.000,4
3755820971.300400,0,1,300.003,0.000,40.490,3.124,0,0,300.000,300.000,14.650,0.000,4
3755821031.300400,0,1,300.003,0.000,40.491,3.124,0,0,300.000,300.000,14.880,0.000,4
3755821091.300400,0,1,299.993,0.000,40.493,3.124,0,0,300.000,300.000,14.780,0.000,4
3755821151.300400,0,1,300.009,0.000,40.493,3.124,0,0,300.000,300.000,14.720,0.000,4
3755821211.300400,0,1,299.995,0.000,40.494,3.124,0,0,300.000,300.000,14.890,0.000,4
3755821271.300400,0,1,300.001,0.000,40.495,3.124,0,0,300.000,300.000,14.700,0.000,4
3755821331.300400,0,1,300.002,0.000,40.494,3.124,0,0,300.000,300.000,14.880,0.000,4
3755821391.300400,0,1,299.994,0.000,40.493,3.125,0,0,300.000,300.000,14.760,0.000,4
3755821451.300400,0,1,300.006,0.000,40.493,3.125,0,0,300.000,300.000,14.720,0.000,4
3755821511.300400,0,1,299.994,0.000,40.493,3.124,0,0,300.000,300.000,14.880,0.000,4
3755821571.300400,0,1,300.000,0.000,40.492,3.124,0,0,300.000,300.000,14.670,0.000,4
3755821631.300400,0,1,299.999,0.000,40.492,3.124,0,0,300.000,300.000,14.890,0.000,4
3755821691.300400,0,1,299.998,0.000,40.492,3.125,0,0,300.000,300.000,14.740,0.000,4
3755821751.300400,0,1,300.004,0.000,40.493,3.126,0,0,300.000,300.000,14.800,0.000,4
3755821811.300400,0,1,299.999,0.000,40.496,3.124,0,0,300.000,300.000,14.840,0.000,4
3755821871.300400,0,1,299.998,0.000,40.497,3.124,0,0,300.000,300.000,14.760,0.000,4
3755821931.300400,0,1,300.000,0.000,40.498,3.124,0,0,300.000,300.000,14.780,0.000,4
3755821991.300400,0,1,299.999,0.000,40.498,3.124,0,0,300.000,300.000,14.740,0.000,4
3755822051.300400,0,1,300.002,0.000,40.497,3.124,0,0,300.000,300.000,14.780,0.000,4
3755822111.300400,0,1,299.998,0.000,40.498,3.126,0,0,300.000,300.000,14.820,0.000,4
3755822171.300400,0,1,300.000,0.000,40.498,3.124,0,0,300.000,300.000,14.760,0.000,4
3755822231.300400,0,1,300.002,0.000,40.499,3.125,0,0,300.000,300.000,14.820,0.000,4
3755822291.300400,0,1,299.999,0.000,40.499,3.125,0,0,300.000,300.000,14.780,0.000,4
3755822351.300400,0,1,300.000,0.000,40.499,3.124,0,0,300.000,300.000,14.820,0.000,4
3755822411.300400,0,1,300.000,0.000,40.499,3.123,0,0,300.000,300.000,14.800,0.000,4
3755822471.300400,0,1,300.000,0.000,40.499,3.123,0,0,300.000,300.000,14.800,0.000,4
3755822531.300400,0,1,300.000,0.000,40.500,3.124,0,0,300.000,300.000,14.820,0.000,4
3755822591.300400,0,1,299.998,0.000,40.500,3.124,0,0,300.000,300.000,14.780,0.000,4
3755822651.300400,0,1,300.001,0.000,40.499,3.125,0,0,300.000,300.000,14.700,0.000,4
3755822711.300400,0,1,299.999,0.000,40.501,3.124,0,0,300.000,300.000,14.800,0.000,4
3755822771.300400,0,1,300.002,0.000,40.500,3.124,0,0,300.000,300.000,14.720,0.000,4
3755822831.300400,0,1,300.000,0.000,40.500,3.125,0,0,300.000,300.000,14.800,0.000,4
3755822891.300400,0,1,299.999,0.000,40.500,3.124,0,0,300.000,300.000,14.820,0.000,4
3755822951.300400,0,1,300.001,0.000,40.500,3.124,0,0,300.000,300.000,14.820,0.000,4
3755823011.300400,0,1,299.999,0.000,40.501,3.124,0,0,300.000,300.000,14.760,0.000,4
3755823071.300400,0,1,299.998,0.000,40.501,3.125,0,0,300.000,300.000,14.780,0.000,4
3755823131.300400,0,1,300.001,0.000,40.501,3.124,0,0,300.000,300.000,14.780,0.000,4
3755823191.300400,0,1,299.997,0.000,40.501,3.126,0,0,300.000,300.000,14.800,0.000,4
3755823251.300400,0,1,300.001,0.000,40.501,3.123,0,0,300.000,300.000,14.740,0.000,4
3755823311.300400,0,1,300.002,0.000,40.501,3.124,0,0,300.000,300.000,14.800,0.000,4
3755823371.300400,0,1,299.997,0.000,40.502,3.124,0,0,300.000,300.000,14.820,0.000,4
3755823431.300400,0,1,300.001,0.000,40.503,3.123,0,0,300.000,300.000,14.760,0.000,4
3755823491.300400,0,1,299.999,0.000,40.504,3.123,0,0,300.000,300.000,14.820,0.000,4
3755823551.300400,0,1,299.998,0.000,40.505,3.124,0,0,300.000,300.000,14.760,0.000,4
3755823611.300400,0,1,300.000,0.000,40.505,3.125,0,0,300.000,300.000,14.800,0.000,4
3755823671.300400,0,1,299.998,0.000,40.505,3.125,0,0,300.000,300.000,14.820,0.000,4
3755823731.300400,0,1,300.001,0.000,40.505,3.124,0,0,300.000,300.000,14.780,0.000,4
3755823791.300400,0,1,299.998,0.000,40.505,3.124,0,0,300.000,300.000,14.780,0.000,4
3755823851.300400,0,1,300.002,0.000,40.504,3.124,0,0,300.000,300.000,14.760,0.000,4
3755823911.300400,0,1,299.997,0.000,40.503,3.125,0,0,300.000,300.000,14.820,0.000,4
3755823971.300400,0,1,300.001,0.000,40.503,3.125,0,0,300.000,300.000,14.740,0.000,4
3755824031.300400,0,1,300.000,0.000,40.505,3.125,0,0,300.000,300.000,14.780,0.000,4
3755824091.300400,0,1,300.000,0.000,40.505,3.125,0,0,300.000,300.000,14.780,0.000,4
3755824151.300400,0,1,300.000,0.000,40.505,3.126,0,0,300.000,300.000,14.820,0.000,4
3755824211.300400,0,1,299.997,0.000,40.505,3.126,0,0,300.000,300.000,14.760,0.000,4
3755824271.300400,0,1,300.003,0.000,40.505,3.125,0,0,300.000,300.000,14.820,0.000,4
3755824331.300400,0,1,299.999,0.000,40.505,3.125,0,0,300.000,300.000,14.840,0.000,4
3755824391.300400,0,1,300.000,0.000,40.505,3.125,0,0,300.000,300.000,14.740,0.000,4
3755824451.300400,0,1,300.000,0.000,40.506,3.125,0,0,300.000,300.000,14.780,0.000,4
3755824511.300400,0,1,300.000,0.000,40.506,3.126,0,0,300.000,300.000,14.780,0.000,4
3755824571.300400,0,1,300.000,0.000,40.507,3.126,0,0,300.000,300.000,14.820,0.000,4
3755824631.300400,0,1,300.000,0.000,40.507,3.125,0,0,300.000,300.000,14.780,0.000,4
3755824691.300400,0,1,300.000,0.000,40.507,3.126,0,0,300.000,300.000,14.800,0.000,4
3755824751.300400,0,1,299.999,0.000,40.508,3.125,0,0,300.000,300.000,14.740,0.000,4
3755824811.300400,0,1,300.000,0.000,40.509,3.125,0,0,300.000,300.000,14.780,0.000,4
3755824871.300400,0,1,300.000,0.000,40.509,3.125,0,0,300.000,300.000,14.820,0.000,4
3755824931.300400,0,1,299.998,0.000,40.509,3.126,0,0,300.000,300.000,14.840,0.000,4
3755824991.300400,0,1,300.000,0.000,40.510,3.126,0,0,300.000,300.000,14.800,0.000,4
3755825051.300400,0,1,299.997,0.000,40.510,3.126,0,0,300.000,300.000,14.840,0.000,4
3755825111.300400,0,1,299.999,0.000,40.511,3.126,0,0,300.000,300.000,14.720,0.000,4
3755825171.300400,0,1,299.999,0.000,40.510,3.126,0,0,300.000,300.000,14.820,0.000,4
3755825231.300400,0,1,299.998,0.000,40.510,3.126,0,0,300.000,300.000,14.740,0.000,4
3755825291.300400,0,1,300.004,0.000,40.509,3.127,0,0,300.000,300.000,14.800,0.000,4
3755825351.300400,0,1,299.998,0.000,40.510,3.126,0,0,300.000,300.000,14.820,0.000,4
3755825411.300400,0,1,300.000,0.000,40.510,3.127,0,0,300.000,300.000,14.760,0.000,4
3755825471.300400,0,1,299.999,0.000,40.510,3.126,0,0,300.000,300.000,14.820,0.000,4
3755825531.300400,0,1,300.003,0.000,40.510,3.127,0,0,300.000,300.000,14.760,0.000,4
3755825591.300400,0,1,300.000,0.000,40.509,3.126,0,0,300.000,300.000,14.800,0.000,4
3755825651.300400,0,1,299.997,0.000,40.508,3.126,0,0,300.000,300.000,14.800,0.000,4
3755825711.300400,0,1,300.002,0.000,40.508,3.126,0,0,300.000,300.000,14.760,0.000,4
3755825771.300400,0,1,299.998,0.000,40.508,3.125,0,0,300.000,300.000,14.820,0.000,4
3755825831.300400,0,1,299.999,0.000,40.507,3.124,0,0,300.000,300.000,14.760,0.000,4
3755825891.300400,0,1,300.001,0.000,40.507,3.124,0,0,300.000,300.000,14.780,0.000,4
3755825951.300400,0,1,299.998,0.000,40.507,3.123,0,0,300.000,300.000,14.800,0.000,4
3755826011.300400,0,1,300.001,0.000,40.507,3.124,0,0,300.000,300.000,14.740,0.000,4
3755826071.300400,0,1,299.999,0.000,40.506,3.124,0,0,300.000,300.000,14.860,0.000,4
3755826131.300400,0,1,299.999,0.000,40.506,3.124,0,0,300.000,300.000,14.740,0.000,4
3755826191.300400,0,1,300.003,0.000,40.506,3.124,0,0,300.000,300.000,14.820,0.000,4
3755826251.300400,0,1,299.999,0.000,40.506,3.123,0,0,300.000,300.000,14.820,0.000,4
3755826311.300400,0,1,300.002,0.000,40.506,3.125,0,0,300.000,300.000,14.820,0.000,4
3755826371.300400,0,1,299.999,0.000,40.504,3.125,0,0,300.000,300.000,14.820,0.000,4
3755826431.300400,0,1,299.999,0.000,40.504,3.124,0,0,300.000,300.000,14.780,0.000,4
3755826491.300400,0,1,300.000,0.000,40.504,3.124,0,0,300.000,300.000,14.760,0.000,4
3755826551.300400,0,1,299.999,0.000,40.503,3.124,0,0,300.000,300.000,14.820,0.000,4
3755826611.300400,0,1,300.000,0.000,40.504,3.125,0,0,300.000,300.000,14.760,0.000,4
3755826671.300400,0,1,300.001,0.000,40.504,3.124,0,0,300.000,300.000,14.760,0.000,4
3755826731.300400,0,1,299.998,0.000,40.505,3.124,0,0,300.000,300.000,14.760,0.000,4
3755826791.300400,0,1,300.001,0.000,40.504,3.124,0,0,300.000,300.000,14.740,0.000,4
3755826851.300400,0,1,300.000,0.000,40.503,3.122,0,0,300.000,300.000,14.860,0.000,4
3755826911.300400,0,1,300.003,0.000,40.502,3.122,0,0,300.000,300.000,14.740,0.000,4
3755826971.300400,0,1,300.000,0.000,40.501,3.122,0,0,300.000,300.000,14.860,0.000,4
3755827031.300400,0,1,299.999,0.000,40.500,3.122,0,0,300.000,300.000,14.740,0.000,4
3755827091.300400,0,1,300.006,0.000,40.500,3.122,0,0,300.000,300.000,14.720,0.000,4
3755827151.300400,0,1,299.997,0.000,40.499,3.122,0,0,300.000,300.000,14.880,0.000,4
3755827211.300400,0,1,300.000,0.000,40.499,3.122,0,0,300.000,300.000,14.720,0.000,4
3755827271.300400,0,1,300.002,0.000,40.497,3.124,0,0,300.000,300.000,14.840,0.000,4
3755827331.300400,0,1,299.997,0.000,40.498,3.125,0,0,300.000,300.000,14.760,0.000,4
3755827391.300400,0,1,300.003,0.000,40.498,3.122,0,0,300.000,300.000,14.780,0.000,4
3755827451.300400,0,1,299.997,0.000,40.498,3.122,0,0,300.000,300.000,14.840,0.000,4
3755827511.300400,0,1,300.000,0.000,40.497,3.124,0,0,300.000,300.000,14.740,0.000,4
3755827571.300400,0,1,300.001,0.000,40.496,3.123,0,0,300.000,300.000,14.860,0.000,4
3755827631.300400,0,1,299.996,0.000,40.496,3.123,0,0,300.000,300.000,14.740,0.000,4
3755827691.300400,0,1,300.005,0.000,40.496,3.123,0,0,300.000,300.000,14.760,0.000,4
3755827751.300400,0,1,299.996,0.000,40.495,3.124,0,0,300.000,300.000,14.840,0.000,4
3755827811.300400,0,1,299.999,0.000,40.496,3.123,0,0,300.000,300.000,14.700,0.000,4
3755827871.300400,0,1,300.005,0.000,40.497,3.123,0,0,300.000,300.000,14.820,0.000,4
3755827931.300400,0,1,299.997,0.000,40.497,3.124,0,0,300.000,300.000,14.780,0.000,4
3755827991.300400,0,1,300.002,0.000,40.497,3.125,0,0,300.000,300.000,14.780,0.000,4
3755828051.300400,0,1,300.000,0.000,40.498,3.125,0,0,300.000,300.000,14.820,0.000,4
3755828111.300400,0,1,300.000,0.000,40.498,3.125,0,0,300.000,300.000,14.780,0.000,4
3755828171.300400,0,1,300.003,0.000,40.499,3.124,0,0,300.000,300.000,14.800,0.000,4
3755828231.300400,0,1,299.995,0.000,40.499,3.125,0,0,300.000,300.000,14.800,0.000,4
3755828291.300400,0,1,300.001,0.000,40.499,3.125,0,0,300.000,300.000,14.800,0.000,4
3755828351.300400,0,1,299.998,0.000,40.498,3.125,0,0,300.000,300.000,14.840,0.000,4
3755828411.300400,0,1,300.000,0.000,40.499,3.124,0,0,300.000,300.000,14.740,0.000,4
3755828471.300400,0,1,300.000,0.000,40.498,3.125,0,0,300.000,300.000,14.780,0.000,4
3755828531.300400,0,1,299.997,0.000,40.499,3.124,0,0,300.000,300.000,14.820,0.000,4
3755828591.300400,0,1,300.000,0.000,40.500,3.124,0,0,300.000,300.000,14.740,0.000,4
3755828651.300400,0,1,299.998,0.000,40.499,3.125,0,0,300.000,300.000,14.840,0.000,4
3755828711.300400,0,1,299.998,0.000,40.500,3.124,0,0,300.000,300.000,14.760,0.000,4
3755828771.300400,0,1,300.003,0.000,40.501,3.123,0,0,300.000,300.000,14.780,0.000,4
3755828831.300400,0,1,299.998,0.000,40.501,3.124,0,0,300.000,300.000,14.840,0.000,4
3755828891.300400,0,1,300.001,0.000,40.501,3.125,0,0,300.000,300.000,14.760,0.000,4
3755828951.300400,0,1,300.000,0.000,40.501,3.125,0,0,300.000,300.000,14.820,0.000,4
3755829011.300400,0,1,299.998,0.000,40.502,3.123,0,0,300.000,300.000,14.760,0.000,4
3755829071.300400,0,1,300.003,0.000,40.501,3.125,0,0,300.000,300.000,14.760,0.000,4
3755829131.300400,0,1,299.997,0.000,40.502,3.126,0,0,300.000,300.000,14.860,0.000,4
3755829191.300400,0,1,300.001,0.000,40.503,3.124,0,0,300.000,300.000,14.720,0.000,4
3755829251.300400,0,1,300.001,0.000,40.503,3.124,0,0,300.000,300.000,14.890,0.000,4
3755829311.300400,0,1,299.996,0.000,40.504,3.124,0,0,300.000,300.000,14.800,0.000,4
3755829371.300400,0,1,300.004,0.000,40.506,3.124,0,0,300.000,300.000,14.780,0.000,4
3755829431.300400,0,1,299.996,0.000,40.506,3.124,0,0,300.000,300.000,14.860,0.000,4
3755829491.300400,0,1,300.000,0.000,40.506,3.123,0,0,300.000,300.000,14.780,0.000,4
3755829551.300400,0,1,300.000,0.000,40.506,3.123,0,0,300.000,300.000,14.820,0.000,4
3755829611.300400,0,1,299.998,0.000,40.506,3.124,0,0,300.000,300.000,14.740,0.000,4
3755829671.300400,0,1,300.002,0.000,40.505,3.124,0,0,300.000,300.000,14.780,0.000,4
3755829731.300400,0,1,300.000,0.000,40.505,3.124,0,0,300.000,300.000,14.800,0.000,4
3755829791.300400,0,1,300.002,0.000,40.504,3.124,0,0,300.000,300.000,14.800,0.000,4
3755829851.300400,0,1,300.000,0.000,40.503,3.125,0,0,300.000,300.000,14.840,0.000,4
3755829911.300400,0,1,299.999,0.000,40.505,3.124,0,0,300.000,300.000,14.760,0.000,4
3755829971.300400,0,1,299.999,0.000,40.505,3.125,0,0,300.000,300.000,14.800,0.000,4
3755830031.300400,0,1,299.998,0.000,40.506,3.124,0,0,300.000,300.000,14.780,0.000,4
3755830091.300400,0,1,300.001,0.000,40.506,3.125,0,0,300.000,300.000,14.760,0.000,4
3755830151.300400,0,1,299.998,0.000,40.506,3.124,0,0,300.000,300.000,14.820,0.000,4
3755830211.300400,0,1,299.998,0.000,40.507,3.124,0,0,300.000,300.000,14.740,0.000,4
3755830271.300400,0,1,299.999,0.000,40.507,3.125,0,0,300.000,300.000,14.820,0.000,4
3755830331.300400,0,1,299.999,0.000,40.507,3.124,0,0,300.000,300.000,14.760,0.000,4
3755830391.300400,0,1,300.002,0.000,40.506,3.124,0,0,300.000,300.000,14.820,0.000,4
3755830451.300400,0,1,299.997,0.000,40.506,3.125,0,0,300.000,300.000,14.800,0.000,4
3755830511.300400,0,1,300.001,0.000,40.507,3.124,0,0,300.000,300.000,14.720,0.000,4
3755830571.300400,0,1,300.002,0.000,40.506,3.124,0,0,300.000,300.000,14.820,0.000,4
3755830631.300400,0,1,299.996,0.000,40.505,3.124,0,0,300.000,300.000,14.800,0.000,4
3755830691.300400,0,1,300.002,0.000,40.506,3.124,0,0,300.000,300.000,14.720,0.000,4
3755830751.300400,0,1,300.001,0.000,40.505,3.123,0,0,300.000,300.000,14.800,0.000,4
3755830811.300400,0,1,299.999,0.000,40.505,3.124,0,0,300.000,300.000,14.760,0.000,4
3755830871.300400,0,1,300.002,0.000,40.507,3.124,0,0,300.000,300.000,14.800,0.000,4
3755830931.300400,0,1,300.000,0.000,40.507,3.124,0,0,300.000,300.000,14.840,0.000,4
3755830991.300400,0,1,300.001,0.000,40.508,3.124,0,0,300.000,300.000,14.740,0.000,4
3755831051.300400,0,1,300.000,0.000,40.508,3.123,0,0,300.000,300.000,14.860,0.000,4
3755831111.300400,0,1,299.997,0.000,40.507,3.124,0,0,300.000,300.000,14.720,0.000,4
3755831171.300400,0,1,300.005,0.000,40.506,3.124,0,0,300.000,300.000,14.800,0.000,4
3755831231.300400,0,1,299.996,0.000,40.506,3.123,0,0,300.000,300.000,14.820,0.000,4
3755831291.300400,0,1,300.005,0.000,40.506,3.123,0,0,300.000,300.000,14.720,0.000,4
3755831351.300400,0,1,299.997,0.000,40.505,3.124,0,0,300.000,300.000,14.840,0.000,4
3755831411.300400,0,1,300.000,0.000,40.505,3.124,0,0,300.000,300.000,14.740,0.000,4
3755831471.300400,0,1,299.979,0.000,40.506,3.124,0,0,300.000,300.000,14.510,0.000,4
3755831531.300400,0,1,300.032,0.000,40.515,3.125,0,0,300.000,300.000,14.780,0.000,4
3755831591.300400,0,1,299.969,0.000,40.527,3.125,0,0,300.000,300.000,15.200,0.000,4
3755831651.300400,0,1,300.018,0.000,40.541,3.125,0,0,300.000,300.000,14.380,0.000,4
3755831711.300400,0,1,300.000,0.000,40.553,3.124,0,0,300.000,300.000,15.340,0.000,4
3755831771.300400,0,1,299.980,0.000,40.562,3.125,0,0,300.000,300.000,14.630,0.000,4
3755831831.300400,0,1,300.027,0.000,40.570,3.125,0,0,300.000,300.000,14.820,0.000,4
3755831891.300400,0,1,299.975,0.000,40.578,3.124,0,0,300.000,300.000,15.130,0.000,4
3755831951.300400,0,1,300.015,0.000,40.583,3.125,0,0,300.000,300.000,14.480,0.000,4
3755832011.300400,0,1,300.003,0.000,40.589,3.124,0,0,300.000,300.000,15.220,0.000,4
3755832071.300400,0,1,299.984,0.000,40.593,3.124,0,0,300.000,300.000,14.700,0.000,4
3755832131.300400,0,1,300.022,0.000,40.597,3.126,0,0,300.000,300.000,14.780,0.000,4
3755832191.300400,0,1,299.981,0.000,40.600,3.126,0,0,300.000,300.000,15.090,0.000,4
3755832242.379400,0,1,300.018,0.000,40.603,3.125,0,0,300.000,300.000,14.590,0.000,4
3755832302.379400,0,1,299.993,0.000,40.605,3.126,0,0,300.000,300.000,15.160,0.000,4
3755832332.031400,0,1,300.019,0.000,40.607,3.126,0,0,300.000,300.000,14.720,0.000,4
3755832392.031400,0,1,299.982,0.000,40.609,3.125,0,0,300.000,300.000,15.110,0.000,4
3755832452.031400,0,1,300.005,0.000,40.612,3.125,0,0,300.000,300.000,14.530,0.000,4
3755832512.031400,0,1,300.007,0.000,40.613,3.124,0,0,300.000,300.000,15.030,0.000,4
3755832734.909400,0,4,300.015,0.000,40.617,3.125,0,0,300.000,300.000,14.700,0.000,4
3755832794.909400,0,1,299.992,0.000,40.617,3.125,0,0,300.000,300.000,15.050,0.000,4
3755833004.908400,0,1,300.000,0.000,40.611,3.124,0,0,300.000,300.000,15.010,0.000,4
3755833277.062400,0,1,299.989,0.000,40.601,3.125,0,0,300.000,300.000,14.880,0.000,4
3755833337.062400,0,1,300.010,0.000,40.599,3.125,0,0,300.000,300.000,14.680,0.000,4
3755833397.062400,0,1,299.993,0.000,40.597,3.123,0,0,300.000,300.000,15.030,0.000,4
3755833457.062400,0,1,300.000,0.000,40.594,3.125,0,0,300.000,300.000,14.670,0.000,4
3755833517.062400,0,1,300.006,0.000,40.591,3.125,0,0,300.000,300.000,14.910,0.000,4
3755833577.062400,0,1,299.990,0.000,40.589,3.125,0,0,300.000,300.000,14.820,0.000,4
3755833637.062400,0,1,300.005,0.000,40.586,3.126,0,0,300.000,300.000,14.680,0.000,4
3755833697.062400,0,1,299.997,0.000,40.585,3.126,0,0,300.000,300.000,14.990,0.000,4
3755833757.062400,0,1,299.996,0.000,40.583,3.127,0,0,300.000,300.000,14.670,0.000,4
3755833817.062400,0,1,300.030,0.000,40.582,3.127,0,0,300.000,300.000,14.380,0.000,4
3755833877.062400,0,1,299.980,0.000,40.587,3.127,0,0,300.000,300.000,15.300,0.000,4
3755833937.062400,0,1,299.998,0.000,40.595,3.127,0,0,300.000,300.000,14.360,0.000,4
3755833997.062400,0,1,300.017,0.000,40.604,3.128,0,0,300.000,300.000,15.110,0.000,4
3755834057.062400,0,1,299.973,0.000,40.613,3.129,0,0,300.000,300.000,14.950,0.000,4
3755834117.062400,0,1,300.001,0.000,40.623,3.126,0,0,300.000,300.000,13.400,0.000,4
3755834177.062400,0,1,300.116,0.000,40.658,3.127,0,0,300.000,300.000,15.260,0.000,4
3755834237.062400,0,1,299.822,305.853,40.759,3.129,0,0,300.000,300.000,14.120,5.870,4
3755834297.062400,0,1,300.175,299.914,40.920,3.130,0,0,300.000,300.000,10.590,12.840,4
3755834357.062400,0,1,299.922,299.943,41.113,3.128,0,0,300.000,300.000,15.480,8.890,4
3755834417.062400,0,1,299.973,300.005,41.306,3.090,0,0,300.000,300.000,10.060,8.650,1
3755834477.062400,0,1,300.113,300.003,41.511,4.024,0,0,300.000,300.000,13.600,8.620,1
3755834537.062400,0,1,299.834,299.993,42.233,4.465,0,0,300.000,300.000,12.950,8.760,1
3755834597.062400,0,1,300.127,299.988,43.200,3.596,0,0,300.000,300.000,11.440,9.100,1
3755834657.062400,0,1,299.927,299.993,43.527,3.333,0,0,300.000,300.000,16.050,9.410,1
3755834717.062400,0,1,299.984,299.999,43.633,3.429,0,0,300.000,300.000,11.600,9.490,1
3755834777.062400,0,1,300.096,299.997,43.735,3.446,0,0,300.000,300.000,14.740,9.570,1
3755834837.062400,0,1,299.862,299.999,43.830,3.452,0,0,300.000,300.000,14.210,9.600,1
3755834897.062400,0,1,300.122,299.996,43.914,3.450,0,0,300.000,300.000,12.400,9.700,1
3755834957.062400,0,1,299.931,299.998,43.986,3.448,0,0,300.000,300.000,16.010,9.760,1
3755835017.062400,0,1,299.987,299.998,44.044,3.449,0,0,300.000,300.000,12.300,9.850,1
3755835077.062400,0,1,300.071,299.996,44.093,3.452,0,0,300.000,300.000,15.140,9.930,1
3755835137.062400,0,1,299.886,299.996,44.138,3.451,0,0,300.000,300.000,14.440,10.010,1
3755835197.062400,0,1,300.104,299.996,44.177,3.450,0,0,300.000,300.000,13.180,10.070,1
3755835257.062400,0,1,299.939,299.996,44.212,3.451,0,0,300.000,300.000,16.190,10.160,1
3755835317.062400,0,1,299.999,300.000,44.242,3.450,0,0,300.000,300.000,13.080,10.240,1
3755835377.062400,0,1,300.059,299.998,44.270,3.450,0,0,300.000,300.000,15.570,10.340,1
3755835437.062400,0,1,299.906,299.998,44.295,3.450,0,0,300.000,300.000,14.890,10.360,1
3755835497.062400,0,1,300.087,299.998,44.317,3.451,0,0,300.000,300.000,13.950,10.440,1
3755835557.062400,0,1,299.942,299.999,44.344,3.368,0,0,300.000,300.000,16.350,10.490,1
3755835617.062400,0,1,300.001,299.999,44.304,3.224,0,0,300.000,300.000,13.770,10.590,1
3755835677.062400,0,1,300.043,299.999,44.204,3.212,0,0,300.000,300.000,15.850,10.610,1
3755835737.062400,0,1,299.926,299.997,44.090,3.213,0,0,300.000,300.000,15.010,10.640,1
3755835797.062400,0,1,300.074,299.999,43.982,3.213,0,0,300.000,300.000,14.360,10.690,1
3755835870.985400,400.000000,TemperatureUnknown,0.000000,MagnetUnknown,ChamberUnknown
3755835879.109400,0,4,300.046,300.001,43.849,3.214,0,0,300.000,300.000,15.690,10.780,4
3755835999.109400,259,4,300.066,300.003,43.683,3.232,0,0,300.000,300.000,14.500,10.410,1
3755836119.109400,0,1,299.954,299.857,43.541,3.217,1,1,280.000,280.000,4.820,5.660,3
3755836239.109400,0,1,294.146,294.125,43.422,3.216,1,1,280.000,280.000,0.000,0.000,3
3755836359.109400,0,1,289.243,290.065,43.318,3.218,0,0,280.000,280.000,0.000,0.000,4
3755836479.109400,0,1,284.871,286.310,43.221,3.217,0,0,280.000,280.000,0.000,0.000,4
3755836599.109400,0,1,280.978,282.841,43.138,3.215,0,0,280.000,280.000,0.000,0.000,4
3755836719.109400,0,1,280.330,279.709,43.061,3.216,0,0,280.000,280.000,2.500,2.320,4
3755836839.109400,0,1,279.840,279.993,42.995,3.215,0,0,280.000,280.000,4.890,5.940,1
3755836959.109400,0,1,279.615,279.996,42.936,3.216,0,0,280.000,280.000,12.320,6.210,1
3755837079.109400,0,1,279.884,279.997,42.882,3.217,0,0,280.000,280.000,15.650,6.360,1
3755837199.109400,0,1,280.247,279.998,42.834,3.216,0,0,280.000,280.000,11.660,6.490,1
3755837319.109400,0,1,280.233,280.000,42.790,3.217,0,0,280.000,280.000,6.880,6.540,1
3755837439.109400,0,1,279.925,279.999,42.750,3.216,0,0,280.000,280.000,7.470,6.620,1
3755837559.109400,0,1,279.768,279.996,42.715,3.216,0,0,280.000,280.000,11.780,6.670,1
3755837679.109400,0,1,279.913,279.996,42.680,3.215,0,0,280.000,280.000,14.210,6.750,1
3755837799.109400,4994,2,280.146,279.999,42.647,3.879,0,0,280.000,280.000,11.820,6.850,1
3755837919.109400,241,3,280.149,280.001,42.620,3.541,0,0,280.000,280.000,9.050,6.900,1
3755838039.109400,0,1,279.970,280.000,42.583,3.424,0,0,280.000,280.000,9.110,6.970,1
3755838159.109400,0,1,279.862,280.000,42.566,3.217,0,0,280.000,280.000,11.850,7.000,1
3755838279.109400,0,1,276.251,276.292,42.541,3.214,1,1,2.000,2.000,0.000,0.000,3
3755838399.109400,0,1,272.394,273.238,42.516,3.213,1,1,2.000,2.000,0.000,0.000,3
3755838519.109400,0,1,268.970,270.336,43.488,4.964,1,1,2.000,2.000,0.000,0.000,3
3755838639.109400,0,1,265.389,267.120,46.313,5.169,1,1,2.000,2.000,0.000,0.000,3
3755838759.109400,0,1,261.401,263.425,48.556,5.299,1,1,2.000,2.000,0.000,0.000,3
3755838879.109400,0,1,256.875,259.253,50.314,5.420,1,1,2.000,2.000,0.000,0.000,3
3755838999.109400,0,1,252.063,254.606,51.743,5.518,1,1,2.000,2.000,0.000,0.000,3
3755839119.109400,0,1,247.008,249.661,52.936,4.535,1,1,2.000,2.000,0.000,0.000,3
3755839239.109400,0,1,241.862,244.617,53.600,4.957,1,1,2.000,2.000,0.000,0.000,3
3755839359.109400,0,1,236.752,239.537,54.244,4.993,1,1,2.000,2.000,0.000,0.000,3
3755839479.109400,0,1,231.686,234.472,54.858,5.025,1,1,2.000,2.000,0.000,0.000,3
3755839599.109400,0,1,226.622,229.370,55.432,5.054,1,1,2.000,2.000,0.000,0.000,3
3755839719.109400,0,1,221.596,224.295,55.962,5.083,1,1,2.000,2.000,0.000,0.000,3
3755839839.109400,0,1,216.613,219.367,56.451,5.112,1,1,2.000,2.000,0.000,0.000,3
3755839959.109400,0,1,211.775,214.749,56.900,5.139,1,1,2.000,2.000,0.000,0.000,3
3755840079.109400,0,1,206.943,209.933,57.316,5.163,1,1,2.000,2.000,0.000,0.000,3
3755840199.109400,0,1,202.170,205.163,57.697,5.185,1,1,2.000,2.000,0.000,0.000,3
3755840319.109400,0,1,197.478,200.455,58.046,5.206,1,1,2.000,2.000,0.000,0.000,3
3755840439.109400,0,1,192.899,195.955,58.364,5.223,1,1,2.000,2.000,0.000,0.000,3
3755840559.109400,0,1,188.368,191.731,58.660,5.241,1,1,2.000,2.000,0.000,0.000,3
3755840679.109400,0,1,183.910,187.469,58.832,3.656,1,1,187.000,187.000,0.000,0.000,3
3755840799.109400,0,1,193.280,195.516,58.274,3.424,1,1,300.000,300.000,44.080,24.850,2
3755840919.109400,0,1,205.179,205.454,57.248,3.437,1,1,300.000,300.000,68.140,27.750,2
3755841039.109400,0,1,216.855,215.357,56.131,3.429,1,1,300.000,300.000,38.720,29.920,2
3755841159.109400,0,1,225.603,225.324,55.033,3.426,1,1,300.000,300.000,26.040,32.170,2
3755841279.109400,0,1,234.189,235.209,54.023,3.420,1,1,300.000,300.000,49.260,34.200,2
3755841399.109400,0,1,244.820,245.175,53.096,3.417,1,1,300.000,300.000,65.670,36.320,2
3755841519.109400,0,1,255.724,255.036,52.270,3.415,1,1,300.000,300.000,56.330,38.220,2
3755841639.109400,0,1,265.545,265.035,51.514,3.412,1,1,300.000,300.000,44.240,40.040,2
3755841759.109400,0,1,274.543,274.917,50.833,3.409,1,1,300.000,300.000,51.340,42.060,2
3755841879.109400,0,1,284.816,284.811,50.215,3.409,1,1,300.000,300.000,71.380,43.890,2
3755841999.109400,0,1,295.422,294.713,49.653,3.406,1,1,300.000,300.000,60.230,45.700,2
3755842119.109400,0,1,299.975,300.007,49.143,3.407,0,0,300.000,300.000,12.070,29.780,4
3755842239.109400,0,1,298.396,300.025,48.675,3.406,0,0,300.000,300.000,39.990,26.290,4
3755842359.109400,0,1,299.253,300.007,48.253,3.405,0,0,300.000,300.000,59.240,25.110,1
3755842479.109400,0,1,301.055,300.006,47.865,3.407,0,0,300.000,300.000,42.030,24.290,1
3755842599.109400,0,1,301.205,300.011,47.517,3.405,0,0,300.000,300.000,16.050,23.480,1
3755842719.109400,0,1,299.721,300.013,47.198,3.406,0,0,300.000,300.000,14.990,22.700,1
3755842839.109400,0,1,298.834,300.010,46.910,3.404,0,0,300.000,300.000,36.220,22.040,1
3755842959.109400,0,1,299.634,300.004,46.646,3.404,0,0,300.000,300.000,47.880,21.510,1
3755843079.109400,0,1,300.815,300.002,46.407,3.403,0,0,300.000,300.000,34.160,21.010,1
3755843199.109400,0,1,300.770,300.008,46.187,3.403,0,0,300.000,300.000,15.970,20.490,1
3755843319.109400,0,1,299.729,300.007,45.988,3.403,0,0,300.000,300.000,17.470,19.980,1
3755843439.109400,0,1,299.175,300.002,45.805,3.402,0,0,300.000,300.000,33.470,19.540,1
3755843559.109400,0,1,299.786,300.000,45.637,3.402,0,0,300.000,300.000,40.020,19.420,1
3755843679.109400,0,1,300.622,299.999,45.484,3.402,0,0,300.000,300.000,29.170,20.050,1
3755843799.109400,0,1,300.524,300.008,45.344,3.402,0,0,300.000,300.000,17.340,19.840,1
3755843919.109400,0,1,299.747,300.007,45.212,3.402,0,0,300.000,300.000,19.280,19.400,1
3755844039.109400,0,1,299.422,300.005,45.093,3.401,0,0,300.000,300.000,30.140,19.020,1
3755844159.109400,0,1,299.903,300.003,44.981,3.399,0,0,300.000,300.000,34.190,18.700,1
3755844279.109400,0,1,300.443,300.001,44.876,3.399,0,0,300.000,300.000,26.390,18.460,1
3755844399.109400,0,1,300.342,300.004,44.780,3.401,0,0,300.000,300.000,17.970,18.080,1
3755844519.109400,0,1,299.812,300.005,44.692,3.399,0,0,300.000,300.000,19.760,17.820,1
3755844639.109400,0,1,299.591,300.003,44.611,3.400,0,0,300.000,300.000,27.480,17.530,1
3755844759.109400,0,1,299.943,300.003,44.534,3.399,0,0,300.000,300.000,30.090,17.290,1
3755844879.109400,0,1,300.317,300.004,44.465,3.399,0,0,300.000,300.000,24.350,17.080,1
3755844999.109400,0,1,300.228,300.005,44.400,3.399,0,0,300.000,300.000,18.560,16.870,1
3755845119.109400,0,1,299.858,300.002,44.340,3.397,0,0,300.000,300.000,20.090,16.630,1
3755845239.109400,0,1,299.716,299.999,44.284,3.396,0,0,300.000,300.000,25.640,16.400,1
3755845359.109400,0,1,299.968,299.999,44.233,3.397,0,0,300.000,300.000,27.060,16.250,1
3755845479.109400,0,1,300.232,300.002,44.184,3.395,0,0,300.000,300.000,22.760,16.090,1
3755845599.109400,0,1,300.156,300.003,44.137,3.395,0,0,300.000,300.000,19.020,15.940,1
3755845719.109400,0,1,299.884,300.002,44.094,3.395,0,0,300.000,300.000,20.230,15.780,1
3755845839.109400,0,1,299.806,300.002,44.055,3.394,0,0,300.000,300.000,23.950,15.610,1
3755845959.109400,0,1,299.995,300.004,44.017,3.394,0,0,300.000,300.000,24.810,15.510,1
3755846079.109400,0,1,300.162,300.000,43.981,3.394,0,0,300.000,300.000,21.890,15.370,1
3755846199.109400,0,1,300.101,300.003,43.949,3.395,0,0,300.000,300.000,19.250,15.250,1
3755846319.109400,0,1,299.922,300.003,43.917,3.392,0,0,300.000,300.000,20.140,15.130,1
3755846439.109400,0,1,299.865,300.003,43.889,3.393,0,0,300.000,300.000,22.760,15.020,1
3755846559.109400,0,1,299.990,300.001,43.862,3.394,0,0,300.000,300.000,23.380,14.900,1
3755846679.109400,0,1,300.111,300.003,43.836,3.395,0,0,300.000,300.000,21.200,14.840,1
3755846799.109400,0,1,300.070,300.004,43.812,3.394,0,0,300.000,300.000,19.360,14.670,1
3755846919.109400,0,1,299.948,300.002,43.790,3.391,0,0,300.000,300.000,19.980,14.570,1
3755847039.109400,0,1,299.905,299.999,43.770,3.392,0,0,300.000,300.000,21.700,14.550,1
3755847159.109400,0,1,299.993,299.999,43.750,3.392,0,0,300.000,300.000,22.170,14.490,1
3755847279.109400,0,1,300.076,300.002,43.732,3.392,0,0,300.000,300.000,20.790,14.410,1
3755847399.109400,0,1,300.053,300.000,43.714,3.392,0,0,300.000,300.000,19.390,14.330,1
3755847519.109400,0,1,299.964,300.000,43.699,3.392,0,0,300.000,300.000,19.740,14.270,1
3755847639.109400,0,1,299.935,300.002,43.684,3.391,0,0,300.000,300.000,21.040,14.190,1
3755847759.109400,0,1,299.991,299.999,43.670,3.387,0,0,300.000,300.000,21.330,14.130,1
3755847879.109400,0,1,300.053,300.002,43.655,3.388,0,0,300.000,300.000,20.360,14.080,1
3755847999.109400,0,1,300.036,299.999,43.642,3.391,0,0,300.000,300.000,19.450,14.040,1
3755848119.109400,0,1,299.980,300.000,43.632,3.391,0,0,300.000,300.000,19.600,13.980,1
3755848239.109400,0,1,299.957,299.999,43.621,3.391,0,0,300.000,300.000,20.430,13.900,1
3755848359.109400,0,1,299.994,299.998,43.611,3.390,0,0,300.000,300.000,20.700,13.840,1
3755848479.109400,0,1,300.037,300.002,43.603,3.389,0,0,300.000,300.000,20.020,13.810,1
3755848599.109400,0,1,300.024,300.001,43.595,3.389,0,0,300.000,300.000,19.340,13.750,1
3755848719.109400,0,1,299.986,300.002,43.588,3.388,0,0,300.000,300.000,19.450,13.690,1
3755848839.109400,0,1,299.971,300.002,43.580,3.388,0,0,300.000,300.000,19.980,13.630,1
3755848959.109400,0,1,299.995,300.001,43.573,3.389,0,0,300.000,300.000,20.110,13.630,1
3755849079.109400,0,1,300.020,300.000,43.567,3.388,0,0,300.000,300.000,19.760,13.580,1
3755849199.109400,0,1,300.017,300.000,43.562,3.390,0,0,300.000,300.000,19.250,13.540,1
3755849319.109400,0,1,299.990,300.003,43.558,3.387,0,0,300.000,300.000,19.320,13.460,1
3755849439.109400,0,1,299.979,299.999,43.554,3.386,0,0,300.000,300.000,19.650,13.420,1
3755849559.109400,0,1,299.993,300.000,43.548,3.388,0,0,300.000,300.000,19.830,13.400,1
3755849679.109400,0,1,300.016,299.999,43.543,3.389,0,0,300.000,300.000,19.520,13.370,1
3755849799.109400,0,1,300.015,300.000,43.539,3.387,0,0,300.000,300.000,19.080,13.330,1
3755849919.109400,0,1,299.999,300.002,43.534,3.389,0,0,300.000,300.000,18.950,13.270,1
3755850039.109400,0,1,299.985,300.000,43.529,3.387,0,0,300.000,300.000,19.280,13.250,1
3755850159.109400,0,1,299.989,300.000,43.525,3.388,0,0,300.000,300.000,19.450,13.210,1
3755850279.109400,0,1,300.005,300.000,43.521,3.387,0,0,300.000,300.000,19.340,13.200,1
3755850399.109400,0,1,300.015,300.002,43.517,3.388,0,0,300.000,300.000,19.040,13.200,1
3755850519.109400,0,1,300.000,300.000,43.512,3.389,0,0,300.000,300.000,18.930,13.120,1
3755850639.109400,0,1,299.989,300.002,43.511,3.388,0,0,300.000,300.000,19.080,13.120,1
3755850759.109400,0,1,299.991,300.001,43.508,3.387,0,0,300.000,300.000,19.320,13.100,1
3755850879.109400,0,1,300.006,300.000,43.506,3.389,0,0,300.000,300.000,19.150,13.080,1
3755850999.109400,0,1,300.011,300.001,43.507,3.387,0,0,300.000,300.000,18.910,13.030,1
3755851119.109400,0,1,299.997,299.998,43.505,3.387,0,0,300.000,300.000,18.820,13.030,1
3755851239.109400,0,1,299.991,299.998,43.504,3.388,0,0,300.000,300.000,18.970,13.010,1
3755851359.109400,0,1,299.995,299.999,43.505,3.385,0,0,300.000,300.000,19.080,12.970,1
3755851479.109400,0,1,300.005,300.001,43.503,3.388,0,0,300.000,300.000,18.970,12.970,1
3755851599.109400,0,1,300.008,299.998,43.504,3.388,0,0,300.000,300.000,18.670,12.930,1
3755851719.109400,0,1,299.998,299.998,43.506,3.388,0,0,300.000,300.000,18.780,12.930,1
3755851839.109400,0,1,299.990,300.000,43.508,3.387,0,0,300.000,300.000,18.860,12.930,1
3755851959.109400,0,1,299.998,300.001,43.509,3.387,0,0,300.000,300.000,19.020,12.860,1
3755852079.109400,0,1,300.008,299.999,43.511,3.387,0,0,300.000,300.000,18.860,12.860,1
3755852199.109400,0,1,300.006,299.999,43.513,3.387,0,0,300.000,300.000,18.630,12.860,1
3755852319.109400,0,1,299.999,299.999,43.515,3.386,0,0,300.000,300.000,18.630,12.820,1
3755852439.109400,0,1,299.993,299.997,43.519,3.387,0,0,300.000,300.000,18.740,12.820,1
3755852559.109400,0,1,299.996,300.001,43.522,3.387,0,0,300.000,300.000,18.840,12.800,1
3755852679.109400,0,1,300.004,299.999,43.524,3.387,0,0,300.000,300.000,18.780,12.800,1
3755852799.109400,0,1,300.010,300.002,43.529,3.386,0,0,300.000,300.000,18.560,12.790,1
3755852919.109400,0,1,300.000,300.000,43.532,3.387,0,0,300.000,300.000,18.500,12.750,1
3755853039.109400,0,1,299.993,300.000,43.537,3.388,0,0,300.000,300.000,18.650,12.750,1
3755853159.109400,0,1,299.997,300.000,43.540,3.387,0,0,300.000,300.000,18.760,12.750,1
3755853279.109400,0,1,300.005,300.001,43.544,3.387,0,0,300.000,300.000,18.650,12.690,1
3755853399.109400,0,1,300.006,300.001,43.549,3.387,0,0,300.000,300.000,18.540,12.670,1
3755853519.109400,0,1,300.004,300.001,43.553,3.386,0,0,300.000,300.000,18.500,12.690,1
3755853639.109400,0,1,299.996,299.998,43.557,3.385,0,0,300.000,300.000,18.560,12.670,1
3755853759.109400,0,1,299.994,299.999,43.560,3.387,0,0,300.000,300.000,18.630,12.660,1
3755853879.109400,0,1,299.998,299.999,43.563,3.387,0,0,300.000,300.000,18.590,12.690,1
3755853999.109400,0,1,300.003,299.998,43.567,3.385,0,0,300.000,300.000,18.500,12.660,1
3755854119.109400,0,1,299.998,299.999,43.570,3.387,0,0,300.000,300.000,18.500,12.640,1
3755854239.109400,0,1,300.000,299.999,43.575,3.384,0,0,300.000,300.000,18.500,12.660,1
3755854359.109400,0,1,299.997,299.999,43.576,3.384,0,0,300.000,300.000,18.480,12.620,1
[...]
3755869706.445400,0,1,141.777,0.000,41.083,3.346,0,0,2.000,2.000,0.000,0.000,4
3755869826.445400,0,1,140.713,0.000,41.046,3.346,0,0,2.000,2.000,0.000,0.000,4
3755869946.445400,0,1,139.662,0.000,41.005,3.340,0,0,2.000,2.000,0.000,0.000,4
3755870066.445400,0,1,138.607,0.000,40.964,3.345,0,0,2.000,2.000,0.000,0.000,4
3755870186.445400,0,1,137.567,0.000,40.925,3.345,0,0,2.000,2.000,0.000,0.000,4
3755870306.445400,0,1,136.521,0.000,40.885,3.344,0,0,2.000,2.000,0.000,0.000,4
3755870426.445400,0,1,135.489,0.000,40.847,3.345,0,0,2.000,2.000,0.000,0.000,4
3755870546.445400,0,1,134.453,0.000,40.808,3.345,0,0,2.000,2.000,0.000,0.000,4
3755870666.445400,0,1,133.421,0.000,40.771,3.345,0,0,2.000,2.000,0.000,0.000,4
3755870786.445400,0,1,132.403,0.000,40.731,3.344,0,0,2.000,2.000,0.000,0.000,4
3755870906.445400,0,1,131.379,0.000,40.691,3.345,0,0,2.000,2.000,0.000,0.000,4
3755871026.445400,0,1,130.369,0.000,40.653,3.345,0,0,2.000,2.000,0.000,0.000,4
3755871146.445400,0,1,129.355,0.000,40.612,3.345,0,0,2.000,2.000,0.000,0.000,4
3755871266.445400,0,1,128.352,0.000,40.573,3.344,0,0,2.000,2.000,0.000,0.000,4
3755871386.445400,0,1,127.347,0.000,40.534,3.345,0,0,2.000,2.000,0.000,0.000,4
3755871506.445400,0,1,126.353,0.000,40.496,3.345,0,0,2.000,2.000,0.000,0.000,4
3755871626.445400,0,1,125.354,0.000,40.457,3.346,0,0,2.000,2.000,0.000,0.000,4
3755871746.445400,0,1,124.359,0.000,40.422,3.345,0,0,2.000,2.000,0.000,0.000,4
3755871866.445400,0,1,123.377,0.000,40.385,3.345,0,0,2.000,2.000,0.000,0.000,4
3755871986.445400,0,1,122.389,0.000,40.347,3.344,0,0,2.000,2.000,0.000,0.000,4
3755872106.445400,0,1,121.404,0.000,40.309,3.344,0,0,2.000,2.000,0.000,0.000,4
3755872226.445400,0,1,120.432,0.000,40.271,3.343,0,0,2.000,2.000,0.000,0.000,4
3755872346.445400,0,1,119.454,0.000,40.234,3.344,0,0,2.000,2.000,0.000,0.000,4
3755872466.445400,0,1,118.486,0.000,40.194,3.343,0,0,2.000,2.000,0.000,0.000,4
3755872586.445400,0,1,117.515,0.000,40.156,3.344,0,0,2.000,2.000,0.000,0.000,4
3755872706.445400,0,1,116.554,0.000,40.117,3.342,0,0,2.000,2.000,0.000,0.000,4
3755872826.445400,0,1,115.587,0.000,40.078,3.344,0,0,2.000,2.000,0.000,0.000,4
3755872946.445400,0,1,114.632,0.000,40.039,3.342,0,0,2.000,2.000,0.000,0.000,4
3755873066.445400,0,1,113.673,0.000,40.002,3.342,0,0,2.000,2.000,0.000,0.000,4
3755873186.445400,0,1,112.722,0.000,39.962,3.343,0,0,2.000,2.000,0.000,0.000,4
3755873306.445400,0,1,111.770,0.000,39.923,3.343,0,0,2.000,2.000,0.000,0.000,4
3755873426.445400,0,1,110.819,0.000,39.885,3.342,0,0,2.000,2.000,0.000,0.000,4
3755873546.445400,0,1,109.870,0.000,39.847,3.342,0,0,2.000,2.000,0.000,0.000,4
3755873666.445400,0,1,108.930,0.000,39.808,3.341,0,0,2.000,2.000,0.000,0.000,4
3755873786.445400,0,1,107.985,0.000,39.770,3.342,0,0,2.000,2.000,0.000,0.000,4
3755873906.445400,0,1,107.051,0.000,39.732,3.341,0,0,2.000,2.000,0.000,0.000,4
3755874026.445400,0,1,106.110,0.000,39.695,3.341,0,0,2.000,2.000,0.000,0.000,4
3755874146.445400,0,1,105.174,0.000,39.657,3.342,0,0,2.000,2.000,0.000,0.000,4
3755874266.445400,0,1,104.245,0.000,39.621,3.342,0,0,2.000,2.000,0.000,0.000,4
3755874386.445400,0,1,103.310,0.000,39.584,3.341,0,0,2.000,2.000,0.000,0.000,4
3755874506.445400,0,1,102.385,0.000,39.547,3.339,0,0,2.000,2.000,0.000,0.000,4
3755874626.445400,0,1,101.454,0.000,39.508,3.340,0,0,2.000,2.000,0.000,0.000,4
3755874746.445400,0,1,100.534,0.000,39.470,3.340,0,0,2.000,2.000,0.000,0.000,4
3755874866.445400,0,1,99.608,0.000,39.435,3.340,0,0,2.000,2.000,0.000,0.000,4
3755874986.445400,0,1,98.685,0.000,39.399,3.339,0,0,2.000,2.000,0.000,0.000,4
3755875106.445400,0,1,97.764,0.000,39.361,3.341,0,0,2.000,2.000,0.000,0.000,4
3755875226.445400,0,1,96.844,0.000,39.325,3.340,0,0,2.000,2.000,0.000,0.000,4
3755875346.445400,0,1,95.924,0.000,39.287,3.341,0,0,2.000,2.000,0.000,0.000,4
3755875466.445400,0,1,95.003,0.000,39.252,3.340,0,0,2.000,2.000,0.000,0.000,4
3755875586.445400,0,1,94.085,0.000,39.215,3.340,0,0,2.000,2.000,0.000,0.000,4
3755875706.445400,0,1,93.170,0.000,39.179,3.340,0,0,2.000,2.000,0.000,0.000,4
3755875826.445400,0,1,92.254,0.000,39.143,3.340,0,0,2.000,2.000,0.000,0.000,4
3755875946.445400,0,1,91.338,0.000,39.107,3.340,0,0,2.000,2.000,0.000,0.000,4
3755876066.445400,0,1,90.421,0.000,39.072,3.337,0,0,2.000,2.000,0.000,0.000,4
3755876186.445400,0,1,89.506,0.000,39.035,3.338,0,0,2.000,2.000,0.000,0.000,4
3755876306.445400,0,1,88.589,0.000,38.998,3.337,0,0,2.000,2.000,0.000,0.000,4
3755876426.445400,0,1,87.673,0.000,38.960,3.338,0,0,2.000,2.000,0.000,0.000,4
3755876546.445400,0,1,86.756,0.000,38.923,3.338,0,0,2.000,2.000,0.000,0.000,4
3755876666.445400,0,1,85.839,0.000,38.885,3.337,0,0,2.000,2.000,0.000,0.000,4
3755876786.445400,0,1,84.920,0.000,38.850,3.339,0,0,2.000,2.000,0.000,0.000,4
3755876906.445400,0,1,84.001,0.000,38.812,3.338,0,0,2.000,2.000,0.000,0.000,4
3755877026.445400,0,1,83.083,0.000,38.777,3.339,0,0,2.000,2.000,0.000,0.000,4
3755877146.445400,0,1,82.162,0.000,38.740,3.338,0,0,2.000,2.000,0.000,0.000,4
3755877266.445400,0,1,81.240,0.000,38.705,3.338,0,0,2.000,2.000,0.000,0.000,4
3755877386.445400,0,1,80.315,0.000,38.669,3.338,0,0,2.000,2.000,0.000,0.000,4
3755877506.445400,0,1,79.389,0.000,38.634,3.337,0,0,2.000,2.000,0.000,0.000,4
3755877626.445400,0,1,78.460,0.000,38.599,3.338,0,0,2.000,2.000,0.000,0.000,4
3755877746.445400,0,1,77.527,0.000,38.564,3.338,0,0,2.000,2.000,0.000,0.000,4
3755877866.445400,0,1,76.591,0.000,38.528,3.339,0,0,2.000,2.000,0.000,0.000,4
3755877986.445400,0,1,75.661,0.000,38.494,3.337,0,0,2.000,2.000,0.000,0.000,4
3755878106.445400,0,1,74.721,0.000,38.458,3.335,0,0,2.000,2.000,0.000,0.000,4
3755878226.445400,0,1,73.780,0.000,38.424,3.334,0,0,2.000,2.000,0.000,0.000,4
3755878346.445400,0,1,72.832,0.000,38.388,3.336,0,0,2.000,2.000,0.000,0.000,4
3755878466.445400,0,1,71.882,0.000,38.353,3.336,0,0,2.000,2.000,0.000,0.000,4
3755878586.445400,0,1,70.927,0.000,38.317,3.337,0,0,2.000,2.000,0.000,0.000,4
3755878706.445400,0,1,69.968,0.000,38.282,3.335,0,0,2.000,2.000,0.000,0.000,4
3755878826.445400,0,1,69.003,0.000,38.247,3.336,0,0,2.000,2.000,0.000,0.000,4
3755878946.445400,0,1,68.032,0.000,38.211,3.335,0,0,2.000,2.000,0.000,0.000,4
3755879066.445400,0,1,67.055,0.000,38.177,3.336,0,0,2.000,2.000,0.000,0.000,4
3755879186.445400,0,1,66.069,0.000,38.143,3.337,0,0,2.000,2.000,0.000,0.000,4
3755879306.445400,0,1,65.078,0.000,38.109,3.336,0,0,2.000,2.000,0.000,0.000,4
3755879426.445400,0,1,64.077,0.000,38.074,3.335,0,0,2.000,2.000,0.000,0.000,4
3755879546.445400,0,1,63.069,0.000,38.040,3.336,0,0,2.000,2.000,0.000,0.000,4
3755879666.445400,0,1,62.052,0.000,38.006,3.335,0,0,2.000,2.000,0.000,0.000,4
3755879786.445400,0,1,61.024,0.000,37.970,3.335,0,0,2.000,2.000,0.000,0.000,4
3755879906.445400,0,1,59.992,0.000,37.935,3.336,0,0,2.000,2.000,0.000,0.000,4
3755880026.445400,0,1,58.940,0.000,37.899,3.336,0,0,2.000,2.000,0.000,0.000,4
3755880146.445400,0,1,57.875,0.000,37.863,3.336,0,0,2.000,2.000,0.000,0.000,4
3755880266.445400,0,1,56.795,0.000,37.826,3.336,0,0,2.000,2.000,0.000,0.000,4
3755880386.445400,0,1,55.700,0.000,37.793,3.336,0,0,2.000,2.000,0.000,0.000,4
3755880506.445400,0,1,54.587,0.000,37.757,3.336,0,0,2.000,2.000,0.000,0.000,4
3755880626.445400,0,1,53.454,0.000,37.721,3.337,0,0,2.000,2.000,0.000,0.000,4
3755880746.445400,0,1,52.298,0.000,37.687,3.336,0,0,2.000,2.000,0.000,0.000,4
3755880866.445400,0,1,51.120,0.000,37.652,3.337,0,0,2.000,2.000,0.000,0.000,4
3755880986.445400,0,1,49.915,0.000,37.615,3.336,0,0,2.000,2.000,0.000,0.000,4
3755881106.445400,0,1,48.679,0.000,37.579,3.334,0,0,2.000,2.000,0.000,0.000,4
3755881226.445400,0,1,47.409,0.000,37.542,3.335,0,0,2.000,2.000,0.000,0.000,4
3755881346.445400,0,1,46.103,0.000,37.505,3.335,0,0,2.000,2.000,0.000,0.000,4
3755881466.445400,0,1,44.748,0.000,37.466,3.333,0,0,2.000,2.000,0.000,0.000,4
3755881586.445400,0,1,43.346,0.000,37.426,3.336,0,0,2.000,2.000,0.000,0.000,4
3755881706.445400,0,1,41.882,0.000,37.388,3.336,0,0,2.000,2.000,0.000,0.000,4
3755881826.445400,0,1,40.346,0.000,37.348,3.332,0,0,2.000,2.000,0.000,0.000,4
3755881946.445400,0,1,38.725,0.000,37.307,3.331,0,0,2.000,2.000,0.000,0.000,4
3755882066.445400,0,1,37.000,0.000,37.265,3.332,0,0,2.000,2.000,0.000,0.000,4
3755882186.445400,0,1,35.141,0.000,37.225,3.333,0,0,2.000,2.000,0.000,0.000,4
3755882306.445400,0,1,33.111,0.000,37.184,3.334,0,0,2.000,2.000,0.000,0.000,4
3755882426.445400,0,1,30.861,0.000,37.143,3.334,0,0,2.000,2.000,0.000,0.000,4
3755882546.445400,0,1,28.237,0.000,37.100,3.332,0,0,2.000,2.000,0.000,0.000,4
3755882666.445400,0,1,25.123,0.000,37.057,3.333,0,0,2.000,2.000,0.000,0.000,4
3755882786.445400,0,1,20.988,0.000,37.013,3.333,0,0,2.000,2.000,0.000,0.000,4
3755882906.445400,0,1,14.872,0.000,36.965,3.333,0,0,2.000,2.000,0.000,0.000,4
3755883026.445400,0,1,7.710,0.000,36.917,3.332,0,0,2.000,2.000,0.000,0.000,4
3755883146.445400,0,1,6.337,0.000,36.863,3.334,0,0,2.000,2.000,0.000,0.000,4
3755883266.445400,0,1,5.680,0.000,36.800,3.333,0,0,2.000,2.000,0.000,0.000,4
3755883386.445400,0,1,5.094,0.000,36.735,3.332,0,0,2.000,2.000,0.000,0.000,4
3755883506.445400,0,1,4.598,0.000,36.663,3.334,0,0,2.000,2.000,0.000,0.000,4
3755883626.445400,0,1,4.158,0.000,36.588,3.330,0,0,2.000,2.000,0.000,0.000,4
3755883746.445400,0,1,3.772,0.000,36.514,3.330,0,0,2.000,2.000,0.000,0.000,4
3755883866.445400,0,1,3.621,0.000,36.444,3.329,0,0,2.000,2.000,0.000,0.000,4
3755883986.445400,0,1,3.571,0.000,36.392,3.323,0,0,2.000,2.000,0.000,0.000,4
3755884106.445400,0,1,3.525,0.000,36.362,3.312,0,0,2.000,2.000,0.000,0.000,4
3755884226.445400,0,1,3.487,0.000,36.351,3.294,0,0,2.000,2.000,0.000,0.000,4
3755884346.445400,0,1,3.468,0.000,36.347,3.277,0,0,2.000,2.000,0.000,0.000,4
3755884466.445400,0,1,3.453,0.000,36.330,3.258,0,0,2.000,2.000,0.000,0.000,4
3755884586.445400,0,1,3.439,0.000,36.305,3.242,0,0,2.000,2.000,0.000,0.000,4
3755884706.445400,0,1,3.426,0.000,36.273,3.225,0,0,2.000,2.000,0.000,0.000,4
3755884826.445400,0,1,3.415,0.000,36.238,3.211,0,0,2.000,2.000,0.000,0.000,4
3755884946.445400,0,1,3.404,0.000,36.201,3.196,0,0,2.000,2.000,0.000,0.000,4
3755885066.445400,0,1,3.394,0.000,36.162,3.181,0,0,2.000,2.000,0.000,0.000,4
3755885186.445400,0,1,3.385,0.000,36.123,3.167,0,0,2.000,2.000,0.000,0.000,4
3755885306.445400,0,1,3.376,0.000,36.083,3.152,0,0,2.000,2.000,0.000,0.000,4
3755885426.445400,0,1,3.368,0.000,36.041,3.140,0,0,2.000,2.000,0.000,0.000,4
3755885546.445400,0,1,3.360,0.000,35.999,3.127,0,0,2.000,2.000,0.000,0.000,4
3755885666.445400,0,1,3.353,0.000,35.957,3.114,0,0,2.000,2.000,0.000,0.000,4
3755885786.445400,0,1,3.346,0.000,35.918,3.103,0,0,2.000,2.000,0.000,0.000,4
3755885906.445400,0,1,3.340,0.000,35.876,3.091,0,0,2.000,2.000,0.000,0.000,4
3755886026.445400,0,1,3.334,0.000,35.837,3.082,0,0,2.000,2.000,0.000,0.000,4
3755886146.445400,0,1,3.328,0.000,35.799,3.072,0,0,2.000,2.000,0.000,0.000,4
3755886266.445400,0,1,3.322,0.000,35.760,3.063,0,0,2.000,2.000,0.000,0.000,4
3755886386.445400,0,1,3.317,0.000,35.724,3.054,0,0,2.000,2.000,0.000,0.000,4
3755886506.445400,0,1,3.312,0.000,35.689,3.047,0,0,2.000,2.000,0.000,0.000,4
3755886626.445400,0,1,3.307,0.000,35.655,3.041,0,0,2.000,2.000,0.000,0.000,4
3755886746.445400,0,1,3.302,0.000,35.622,3.034,0,0,2.000,2.000,0.000,0.000,4
3755886866.445400,0,1,3.298,0.000,35.591,3.029,0,0,2.000,2.000,0.000,0.000,4
3755886986.445400,0,1,3.294,0.000,35.563,3.023,0,0,2.000,2.000,0.000,0.000,4
3755887106.445400,0,1,3.290,0.000,35.535,3.018,0,0,2.000,2.000,0.000,0.000,4
3755887226.445400,0,1,3.286,0.000,35.509,3.014,0,0,2.000,2.000,0.000,0.000,4
3755887346.445400,0,1,3.282,0.000,35.484,3.011,0,0,2.000,2.000,0.000,0.000,4
3755887466.445400,0,1,3.279,0.000,35.462,3.010,0,0,2.000,2.000,0.000,0.000,4
3755887586.445400,0,1,3.276,0.000,35.443,3.008,0,0,2.000,2.000,0.000,0.000,4
3755887706.445400,0,1,3.273,0.000,35.422,3.006,0,0,2.000,2.000,0.000,0.000,4
3755887826.445400,0,1,3.270,0.000,35.405,3.003,0,0,2.000,2.000,0.000,0.000,4
3755887946.445400,0,1,3.268,0.000,35.389,3.001,0,0,2.000,2.000,0.000,0.000,4
3755888066.445400,0,1,3.265,0.000,35.375,2.999,0,0,2.000,2.000,0.000,0.000,4
3755888186.445400,0,1,3.263,0.000,35.360,2.999,0,0,2.000,2.000,0.000,0.000,4
3755888306.445400,0,1,3.260,0.000,35.346,2.998,0,0,2.000,2.000,0.000,0.000,4
3755888426.445400,0,1,3.258,0.000,35.333,2.997,0,0,2.000,2.000,0.000,0.000,4
3755888546.445400,0,1,3.256,0.000,35.321,2.995,0,0,2.000,2.000,0.000,0.000,4
3755888666.445400,0,1,3.254,0.000,35.310,2.995,0,0,2.000,2.000,0.000,0.000,4
3755888786.445400,0,1,3.252,0.000,35.299,2.995,0,0,2.000,2.000,0.000,0.000,4
3755888906.445400,0,1,3.251,0.000,35.289,2.993,0,0,2.000,2.000,0.000,0.000,4
3755889026.445400,0,1,3.249,0.000,35.280,2.992,0,0,2.000,2.000,0.000,0.000,4
3755889146.445400,0,1,3.248,0.000,35.271,2.991,0,0,2.000,2.000,0.000,0.000,4
3755889266.445400,0,1,3.246,0.000,35.262,2.992,0,0,2.000,2.000,0.000,0.000,4
3755889386.445400,0,1,3.245,0.000,35.255,2.993,0,0,2.000,2.000,0.000,0.000,4
3755889506.445400,0,1,3.244,0.000,35.250,2.990,0,0,2.000,2.000,0.000,0.000,4
3755889626.445400,0,1,3.243,0.000,35.243,2.990,0,0,2.000,2.000,0.000,0.000,4
3755889746.445400,0,1,3.241,0.000,35.236,2.991,0,0,2.000,2.000,0.000,0.000,4
3755889866.445400,0,1,3.241,0.000,35.230,2.991,0,0,2.000,2.000,0.000,0.000,4
3755889986.445400,0,1,3.240,0.000,35.224,2.991,0,0,2.000,2.000,0.000,0.000,4
3755890106.445400,0,1,3.239,0.000,35.218,2.991,0,0,2.000,2.000,0.000,0.000,4
3755890226.445400,0,1,3.238,0.000,35.213,2.991,0,0,2.000,2.000,0.000,0.000,4
3755890346.445400,0,1,3.237,0.000,35.209,2.990,0,0,2.000,2.000,0.000,0.000,4
3755890466.445400,0,1,3.237,0.000,35.205,2.990,0,0,2.000,2.000,0.000,0.000,4
3755890586.445400,0,1,3.236,0.000,35.202,2.990,0,0,2.000,2.000,0.000,0.000,4
3755890706.445400,0,1,3.235,0.000,35.199,2.989,0,0,2.000,2.000,0.000,0.000,4
3755890826.445400,0,1,3.235,0.000,35.197,2.989,0,0,2.000,2.000,0.000,0.000,4
3755890946.445400,0,1,3.234,0.000,35.192,2.990,0,0,2.000,2.000,0.000,0.000,4
3755891066.445400,0,1,3.234,0.000,35.189,2.989,0,0,2.000,2.000,0.000,0.000,4
3755891186.445400,0,1,3.234,0.000,35.188,2.990,0,0,2.000,2.000,0.000,0.000,4
3755891306.445400,0,1,3.233,0.000,35.187,2.988,0,0,2.000,2.000,0.000,0.000,4
3755891426.445400,0,1,3.233,0.000,35.183,2.989,0,0,2.000,2.000,0.000,0.000,4
3755891546.445400,0,1,3.232,0.000,35.181,2.989,0,0,2.000,2.000,0.000,0.000,4
3755891666.445400,0,1,3.232,0.000,35.180,2.982,0,0,2.000,2.000,0.000,0.000,4
3755891786.445400,0,1,3.232,0.000,35.176,2.986,0,0,2.000,2.000,0.000,0.000,4
3755891906.445400,0,1,3.231,0.000,35.172,2.987,0,0,2.000,2.000,0.000,0.000,4
3755892026.445400,0,1,3.231,0.000,35.171,2.987,0,0,2.000,2.000,0.000,0.000,4
3755892146.445400,0,1,3.231,0.000,35.169,2.987,0,0,2.000,2.000,0.000,0.000,4
3755892266.445400,0,1,3.231,0.000,35.167,2.988,0,0,2.000,2.000,0.000,0.000,4
3755892386.445400,0,1,3.231,0.000,35.166,2.988,0,0,2.000,2.000,0.000,0.000,4
3755892506.445400,0,1,3.231,0.000,35.164,2.987,0,0,2.000,2.000,0.000,0.000,4
3755892626.445400,0,1,3.231,0.000,35.164,2.988,0,0,2.000,2.000,0.000,0.000,4
3755892746.445400,0,1,3.231,0.000,35.164,2.989,0,0,2.000,2.000,0.000,0.000,4
3755892866.445400,0,1,3.231,0.000,35.163,2.989,0,0,2.000,2.000,0.000,0.000,4
3755892986.445400,0,1,3.231,0.000,35.163,2.989,0,0,2.000,2.000,0.000,0.000,4
3755893106.445400,0,1,3.231,0.000,35.162,2.989,0,0,2.000,2.000,0.000,0.000,4
3755893226.445400,0,1,3.230,0.000,35.160,2.989,0,0,2.000,2.000,0.000,0.000,4
3755893346.445400,0,1,3.231,0.000,35.159,2.989,0,0,2.000,2.000,0.000,0.000,4
3755893466.445400,0,1,3.231,0.000,35.158,2.989,0,0,2.000,2.000,0.000,0.000,4
3755893586.445400,0,1,3.231,0.000,35.157,2.990,0,0,2.000,2.000,0.000,0.000,4
3755893706.445400,0,1,3.231,0.000,35.156,2.988,0,0,2.000,2.000,0.000,0.000,4
3755893826.445400,0,1,3.231,0.000,35.156,2.989,0,0,2.000,2.000,0.000,0.000,4
3755893946.445400,0,1,3.231,0.000,35.156,2.990,0,0,2.000,2.000,0.000,0.000,4
3755894066.445400,0,1,3.231,0.000,35.157,2.989,0,0,2.000,2.000,0.000,0.000,4
3755894186.445400,0,1,3.231,0.000,35.156,2.989,0,0,2.000,2.000,0.000,0.000,4
3755894306.445400,0,1,3.231,0.000,35.155,2.989,0,0,2.000,2.000,0.000,0.000,4
3755894426.445400,0,1,3.231,0.000,35.155,2.990,0,0,2.000,2.000,0.000,0.000,4
3755894546.445400,0,1,3.231,0.000,35.155,2.989,0,0,2.000,2.000,0.000,0.000,4
3755894666.445400,0,1,3.231,0.000,35.155,2.988,0,0,2.000,2.000,0.000,0.000,4
3755894786.445400,0,1,3.231,0.000,35.155,2.989,0,0,2.000,2.000,0.000,0.000,4
3755894906.445400,0,1,3.231,0.000,35.155,2.987,0,0,2.000,2.000,0.000,0.000,4
3755895026.445400,0,1,3.231,0.000,35.153,2.989,0,0,2.000,2.000,0.000,0.000,4
3755895146.445400,0,1,3.231,0.000,35.152,2.987,0,0,2.000,2.000,0.000,0.000,4
3755895266.445400,0,1,3.231,0.000,35.150,2.988,0,0,2.000,2.000,0.000,0.000,4
3755895386.445400,0,1,3.231,0.000,35.150,2.989,0,0,2.000,2.000,0.000,0.000,4
3755895506.445400,0,1,3.231,0.000,35.150,2.987,0,0,2.000,2.000,0.000,0.000,4
3755895626.445400,0,1,3.231,0.000,35.150,2.987,0,0,2.000,2.000,0.000,0.000,4
3755895746.445400,0,1,3.231,0.000,35.148,2.988,0,0,2.000,2.000,0.000,0.000,4
3755895866.445400,0,1,3.231,0.000,35.149,2.988,0,0,2.000,2.000,0.000,0.000,4
3755895986.445400,0,1,3.231,0.000,35.149,2.988,0,0,2.000,2.000,0.000,0.000,4
3755896106.445400,0,1,3.231,0.000,35.148,2.988,0,0,2.000,2.000,0.000,0.000,4
3755896226.445400,0,1,3.231,0.000,35.146,2.987,0,0,2.000,2.000,0.000,0.000,4
3755896346.445400,0,1,3.231,0.000,35.147,2.989,0,0,2.000,2.000,0.000,0.000,4
3755896466.445400,0,1,3.231,0.000,35.148,2.989,0,0,2.000,2.000,0.000,0.000,4
3755896586.445400,0,1,3.231,0.000,35.149,2.988,0,0,2.000,2.000,0.000,0.000,4
3755896706.445400,0,1,3.231,0.000,35.149,2.987,0,0,2.000,2.000,0.000,0.000,4
3755896826.445400,0,1,3.230,0.000,35.149,2.987,0,0,2.000,2.000,0.000,0.000,4
3755896946.445400,0,1,3.230,0.000,35.149,2.987,0,0,2.000,2.000,0.000,0.000,4
3755897066.445400,0,1,3.230,0.000,35.148,2.987,0,0,2.000,2.000,0.000,0.000,4
3755897186.445400,0,1,3.230,0.000,35.147,2.988,0,0,2.000,2.000,0.000,0.000,4
3755897306.445400,0,1,3.230,0.000,35.146,2.988,0,0,2.000,2.000,0.000,0.000,4
3755897426.445400,0,1,3.230,0.000,35.145,2.988,0,0,2.000,2.000,0.000,0.000,4
3755897546.445400,0,1,3.230,0.000,35.142,2.988,0,0,2.000,2.000,0.000,0.000,4
3755897666.445400,0,1,3.230,0.000,35.142,2.986,0,0,2.000,2.000,0.000,0.000,4
3755897786.445400,0,1,3.230,0.000,35.142,2.988,0,0,2.000,2.000,0.000,0.000,4
3755897906.445400,0,1,3.230,0.000,35.142,2.986,0,0,2.000,2.000,0.000,0.000,4
3755898026.445400,0,1,3.230,0.000,35.143,2.986,0,0,2.000,2.000,0.000,0.000,4
3755898146.445400,0,1,3.230,0.000,35.142,2.987,0,0,2.000,2.000,0.000,0.000,4
3755898266.445400,0,1,3.230,0.000,35.141,2.986,0,0,2.000,2.000,0.000,0.000,4
3755898386.445400,0,1,3.230,0.000,35.141,2.987,0,0,2.000,2.000,0.000,0.000,4
3755898506.445400,0,1,3.230,0.000,35.141,2.987,0,0,2.000,2.000,0.000,0.000,4
3755898626.445400,0,1,3.230,0.000,35.141,2.986,0,0,2.000,2.000,0.000,0.000,4
3755898746.445400,0,1,3.230,0.000,35.140,2.987,0,0,2.000,2.000,0.000,0.000,4
3755898866.445400,0,1,3.230,0.000,35.139,2.988,0,0,2.000,2.000,0.000,0.000,4
3755898986.445400,0,1,3.230,0.000,35.141,2.986,0,0,2.000,2.000,0.000,0.000,4
3755899106.445400,0,1,3.230,0.000,35.140,2.985,0,0,2.000,2.000,0.000,0.000,4
3755899226.445400,0,1,3.230,0.000,35.140,2.987,0,0,2.000,2.000,0.000,0.000,4
3755899346.445400,0,1,3.230,0.000,35.140,2.986,0,0,2.000,2.000,0.000,0.000,4
3755899466.445400,0,1,3.229,0.000,35.141,2.986,0,0,2.000,2.000,0.000,0.000,4
3755899586.445400,0,1,3.229,0.000,35.140,2.986,0,0,2.000,2.000,0.000,0.000,4
3755899706.445400,0,1,3.229,0.000,35.139,2.985,0,0,2.000,2.000,0.000,0.000,4
3755899826.445400,0,1,3.229,0.000,35.139,2.987,0,0,2.000,2.000,0.000,0.000,4
3755899946.445400,0,1,3.229,0.000,35.139,2.987,0,0,2.000,2.000,0.000,0.000,4
3755900066.445400,0,1,3.192,0.000,35.188,2.927,0,0,2.000,2.000,0.000,0.000,4
3755900186.445400,0,1,3.185,0.000,35.089,2.869,0,0,2.000,2.000,0.000,0.000,4
3755900306.445400,0,1,3.245,0.000,35.065,2.996,0,0,2.000,2.000,0.000,0.000,4
3755900396.445400,0,1,3.236,0.000,35.058,2.957,0,0,2.000,2.000,0.000,0.000,4