File: log/20231211.dat
[Header]
; Displex Transport Data File (default extension .dat)
; Copyright 2016, Hechang LEI, hlei@ruc.edu.cn. All rights reserved.
BYAPP, Displex, 2.0
INFO, 9T mag, Release 2.0.
INFO, Channel 1, Temperature Sensor
INFO, Sample 1 Length (cm): 0.000000; Width (cm): 0.000000; Thickness (cm): 0.000000.

[Data]
Timestamp(s),Field(Oe),Field Status,TempA(K),TempB(K),TempC(K),TempD(K),Ramp1,Ramp2,Setpoint1,Setpoint2,Output1(%),Output2(%),Temp Status,in plane position,out plane position
3785149620.189000,0,4,12.000,12.005,36.129,3.104,0,0,12.000,12.000,0.160,0.970,4,0.000000,0.000000
3785149751.219000,0,4,12.000,11.999,36.126,3.102,0,0,12.000,12.000,0.160,0.990,4,0.000000,0.000000
3785149872.752000,0,4,12.000,12.003,36.122,3.104,0,0,12.000,12.000,0.160,0.970,4,89.965614,-21.979648
3785150187.491000,0,1,12.000,11.997,36.107,3.101,0,0,12.000,12.000,0.160,0.950,1,92.127625,-21.979648
3785150277.491000,0,1,12.000,12.000,36.104,3.103,0,0,12.000,12.000,0.160,0.950,1,100.380097,-21.979648
3785150392.478000,0,1,12.000,12.001,36.100,3.101,0,0,12.000,12.000,0.160,0.940,1,100.587345,-21.979648
3785150482.478000,0,1,12.000,12.001,36.098,3.101,0,0,12.000,12.000,0.160,0.980,1,100.003587,-21.979648
3785150572.478000,0,1,12.000,12.004,36.092,3.103,0,0,12.000,12.000,0.160,0.960,1,100.002379,-21.979648
3785150662.478000,0,1,12.000,12.001,36.092,3.102,0,0,12.000,12.000,0.160,0.980,1,102.005866,-21.979648
3785150752.478000,0,1,12.000,12.001,36.088,3.103,0,0,12.000,12.000,0.160,0.980,1,104.002776,-21.979648
3785150842.478000,0,1,12.000,12.002,36.085,3.102,0,0,12.000,12.000,0.160,0.970,1,105.005593,-21.979648
3785150932.478000,0,1,12.000,12.002,36.084,3.103,0,0,12.000,12.000,0.160,0.970,1,105.226667,-21.979648
3785151022.478000,0,1,12.000,11.996,36.079,3.102,0,0,12.000,12.000,0.160,0.990,1,106.994181,-21.979648
3785151112.478000,0,1,12.000,12.000,36.079,3.102,0,0,12.000,12.000,0.160,0.940,1,106.328813,-21.979648
3785151202.478000,0,1,12.000,11.993,36.076,3.102,0,0,12.000,12.000,0.160,0.980,1,110.979545,-21.979648
3785151292.478000,0,1,12.000,11.994,36.073,3.100,0,0,12.000,12.000,0.160,0.980,1,113.002227,-21.979648
3785151382.478000,0,1,12.000,11.999,36.071,3.102,0,0,12.000,12.000,0.160,0.940,1,113.628266,-21.979648
3785151472.478000,0,1,12.000,11.998,36.066,3.103,0,0,12.000,12.000,0.160,0.950,1,117.555911,-21.979648
3785151562.478000,0,1,12.000,12.008,36.065,3.101,0,0,12.000,12.000,0.160,0.940,1,117.197120,-21.979648
3785151652.478000,0,1,12.000,12.003,36.062,3.103,0,0,12.000,12.000,0.160,0.970,1,119.013896,-21.979648
3785151742.478000,0,1,12.000,12.000,36.062,3.102,0,0,12.000,12.000,0.160,0.940,1,120.428391,-21.979648
3785151832.478000,0,1,12.000,11.998,36.063,3.103,0,0,12.000,12.000,0.160,0.980,1,121.998456,-21.979648
3785151922.478000,0,1,12.000,12.002,36.060,3.102,0,0,12.000,12.000,0.160,0.950,1,125.127847,-21.979648
3785152012.478000,0,1,12.000,11.995,36.056,3.099,0,0,12.000,12.000,0.160,0.980,1,125.994155,-21.979648
3785152102.478000,0,1,12.000,12.003,36.054,3.100,0,0,12.000,12.000,0.160,0.970,1,126.948247,-21.979648
3785152209.643000,0,1,12.000,11.999,36.048,3.099,0,0,12.000,12.000,0.160,0.980,1,126.982073,-21.979648
3785152299.643000,0,1,12.000,12.002,36.046,3.101,0,0,12.000,12.000,0.160,0.960,1,128.385426,-21.979648
3785152389.643000,0,1,12.000,12.006,36.044,3.102,0,0,12.000,12.000,0.160,0.950,1,130.795222,-21.979648
3785152479.643000,0,1,12.000,12.003,36.042,3.099,0,0,12.000,12.000,0.160,0.950,1,132.923407,-21.979648
3785152569.643000,0,1,12.000,12.009,36.041,3.100,0,0,12.000,12.000,0.160,0.940,1,134.717095,-21.979648
3785152659.643000,0,1,12.000,12.002,36.038,3.100,0,0,12.000,12.000,0.160,0.960,1,135.434410,-21.979648
3785152734.093000,0,1,12.000,11.999,36.039,3.101,0,0,12.000,12.000,0.160,0.980,1,135.771993,-21.979648
3785152824.093000,0,1,11.999,11.994,36.039,3.101,0,0,12.000,12.000,0.160,0.990,1,136.073469,-21.979648
3785152914.093000,0,1,11.999,11.994,36.038,3.099,0,0,12.000,12.000,0.160,0.980,1,137.052394,-21.979648
3785153004.093000,0,1,12.000,12.006,36.039,3.100,0,0,12.000,12.000,0.160,0.960,1,138.026353,-21.979648
3785153094.093000,0,1,12.000,12.002,36.036,3.100,0,0,12.000,12.000,0.160,0.970,1,139.472793,-21.979648
3785153184.097000,0,1,12.000,11.994,36.033,3.098,0,0,12.000,12.000,0.160,0.980,1,141.104469,-21.979648
3785153274.097000,0,1,12.000,12.001,36.031,3.100,0,0,12.000,12.000,0.160,0.970,1,142.070105,-21.979648
3785153491.535000,0,1,12.000,12.002,36.026,3.101,0,0,12.000,12.000,0.160,0.970,1,142.024870,-21.979648
3785153581.535000,0,1,12.000,12.000,36.023,3.100,0,0,12.000,12.000,0.160,0.980,1,142.024602,-21.979648
3785153671.535000,0,1,12.000,11.998,36.023,3.100,0,0,12.000,12.000,0.160,0.980,1,141.059503,-21.979648
3785153761.535000,0,1,12.000,11.997,36.024,3.100,0,0,12.000,12.000,0.160,0.990,1,142.036011,-21.979648
3785153851.535000,0,1,12.000,11.999,36.023,3.099,0,0,12.000,12.000,0.160,0.980,1,143.004064,-21.979648
3785153941.535000,0,1,12.000,12.000,36.023,3.100,0,0,12.000,12.000,0.160,0.980,1,145.026074,-21.979648
3785154031.535000,0,1,12.000,11.997,36.020,3.101,0,0,12.000,12.000,0.160,0.990,1,146.020301,-21.979648
3785154121.535000,0,1,12.000,11.995,36.017,3.099,0,0,12.000,12.000,0.160,0.990,1,147.004192,-21.979648
3785154211.535000,0,1,12.000,11.993,36.016,3.099,0,0,12.000,12.000,0.160,0.990,1,150.010765,-21.979648
3785154301.535000,0,1,12.001,12.003,36.012,3.099,0,0,12.000,12.000,0.160,0.980,1,151.003918,0.000000
3785154391.535000,0,1,12.000,11.998,36.011,3.099,0,0,12.000,12.000,0.160,0.960,1,153.138546,-21.979648
3785154481.535000,0,1,12.000,12.005,36.009,3.100,0,0,12.000,12.000,0.160,0.960,1,153.387271,-21.979648
3785154571.535000,0,1,12.001,12.004,36.008,3.098,0,0,12.000,12.000,0.160,0.970,1,154.010089,-21.979648
3785154661.535000,0,1,12.000,11.999,36.008,3.100,0,0,12.000,12.000,0.160,0.970,1,155.033846,-21.979648
3785154751.535000,0,1,12.000,12.000,36.006,3.099,0,0,12.000,12.000,0.160,0.980,1,156.108206,-21.979648
3785154841.535000,0,1,12.000,11.999,36.010,3.100,0,0,12.000,12.000,0.160,0.980,1,157.105789,-21.979648
3785154931.535000,0,1,12.000,12.000,36.011,3.100,0,0,12.000,12.000,0.160,0.990,1,157.018004,-21.979648
3785155021.535000,0,1,12.001,12.007,36.011,3.098,0,0,12.000,12.000,0.160,0.960,1,158.076123,-21.979648
3785155111.535000,0,1,12.000,12.004,36.011,3.099,0,0,12.000,12.000,0.160,0.960,1,159.058806,-21.979648
3785155201.535000,0,1,12.000,11.998,36.007,3.098,0,0,12.000,12.000,0.160,0.980,1,160.003369,-21.979648
3785155291.535000,0,1,12.000,12.002,36.007,3.099,0,0,12.000,12.000,0.160,0.970,1,160.003369,-21.979648
3785155381.535000,0,1,12.000,12.003,36.005,3.099,0,0,12.000,12.000,0.160,0.980,1,160.002161,-21.979648
3785155471.535000,0,1,12.000,11.997,36.004,3.097,0,0,12.000,12.000,0.160,1.000,1,160.001624,-21.979648
3785155561.535000,0,1,12.001,12.004,36.006,3.099,0,0,12.000,12.000,0.160,0.980,1,160.003906,-21.979648
3785155651.535000,0,1,12.000,11.996,36.004,3.100,0,0,12.000,12.000,0.160,0.990,1,160.004040,-21.979648
3785155741.535000,0,1,12.000,12.003,36.005,3.098,0,0,12.000,12.000,0.160,0.980,1,160.004577,-21.979648
3785155831.535000,0,1,12.000,12.001,36.005,3.099,0,0,12.000,12.000,0.160,0.970,1,160.004174,-21.979648
3785155921.535000,0,1,12.000,11.998,36.005,3.097,0,0,12.000,12.000,0.160,0.990,1,160.003906,-21.979648
3785156011.535000,0,1,12.000,11.998,36.007,3.099,0,0,12.000,12.000,0.160,0.990,1,160.002832,-21.979648
3785156101.535000,0,1,12.000,12.000,36.006,3.099,0,0,12.000,12.000,0.160,0.980,1,160.001624,-21.979648
3785156191.535000,0,1,12.000,12.001,36.006,3.097,0,0,12.000,12.000,0.160,0.990,1,160.002563,-21.979648
3785156281.535000,0,1,12.000,12.000,36.004,3.099,0,0,12.000,12.000,0.160,0.980,1,160.002832,-21.979648
3785156371.535000,0,1,12.000,12.001,36.003,3.098,0,0,12.000,12.000,0.160,0.980,1,160.002698,-21.979648
3785156461.535000,0,1,12.000,11.999,36.003,3.098,0,0,12.000,12.000,0.160,0.980,1,160.001490,-21.979648
3785156551.535000,0,1,12.000,12.001,36.002,3.100,0,0,12.000,12.000,0.160,0.980,1,160.002429,-21.979648
3785156641.535000,0,1,12.000,12.000,36.002,3.098,0,0,12.000,12.000,0.160,0.960,1,160.002832,-21.979648
3785156731.535000,0,1,12.000,12.000,36.004,3.098,0,0,12.000,12.000,0.160,0.980,1,160.002698,-21.979648
3785156821.535000,0,1,12.000,12.001,36.004,3.099,0,0,12.000,12.000,0.160,0.980,1,160.003771,-21.979648
3785156911.535000,0,1,12.000,12.001,36.006,3.098,0,0,12.000,12.000,0.160,0.980,1,160.003906,-21.979648
3785157001.535000,0,1,12.000,12.003,36.006,3.099,0,0,12.000,12.000,0.160,0.980,1,160.003906,-21.979648
3785157091.535000,0,1,12.000,12.000,36.004,3.098,0,0,12.000,12.000,0.160,0.980,1,160.003771,-21.979648
3785157181.535000,0,1,11.999,11.993,36.003,3.099,0,0,12.000,12.000,0.160,0.990,1,160.004040,-21.979648
3785157271.535000,0,1,12.000,12.001,36.000,3.100,0,0,12.000,12.000,0.160,0.980,1,160.005248,-21.979648
3785157361.535000,0,1,11.999,11.997,36.001,3.097,0,0,12.000,12.000,0.160,0.990,1,160.005382,-21.979648
3785157451.535000,0,1,12.000,12.003,36.001,3.098,0,0,12.000,12.000,0.160,0.980,1,160.005651,-21.979648
3785157541.535000,0,1,12.000,11.996,35.999,3.098,0,0,12.000,12.000,0.160,0.990,1,160.005651,-21.979648
3785157631.535000,0,1,12.000,12.000,36.002,3.098,0,0,12.000,12.000,0.160,0.980,1,160.005516,-21.979648
3785157721.535000,0,1,11.999,11.998,36.001,3.098,0,0,12.000,12.000,0.160,0.980,1,160.006188,-21.979648
3785157811.535000,0,1,11.999,11.996,36.002,3.098,0,0,12.000,12.000,0.160,0.990,1,160.004980,-21.979648
3785157901.535000,0,1,12.000,12.001,36.004,3.099,0,0,12.000,12.000,0.160,0.980,1,160.005114,-21.979648
3785157991.535000,0,1,12.000,11.999,36.002,3.099,0,0,12.000,12.000,0.160,0.970,1,160.005651,-21.979648
3785158081.535000,0,1,12.000,12.001,36.002,3.098,0,0,12.000,12.000,0.160,0.970,1,160.006053,-21.979648
3785158171.535000,0,1,12.000,12.006,36.001,3.100,0,0,12.000,12.000,0.160,0.940,1,154.840289,-21.979648
3785158261.535000,0,1,12.000,12.003,36.000,3.098,0,0,12.000,12.000,0.160,0.940,1,145.223524,-21.979648
3785158351.535000,0,1,12.000,11.996,35.998,3.098,0,0,12.000,12.000,0.160,0.960,1,136.633334,-21.979648
3785158441.535000,0,1,12.000,12.000,35.995,3.099,0,0,12.000,12.000,0.160,0.940,1,127.079791,-21.979648
3785158531.535000,0,1,12.000,11.994,35.995,3.097,0,0,12.000,12.000,0.160,0.950,1,116.714436,-21.979648
3785158621.535000,0,1,12.000,12.000,35.996,3.098,0,0,12.000,12.000,0.160,0.940,1,106.124115,-21.979648
3785158711.535000,0,1,12.000,12.000,35.996,3.099,0,0,12.000,12.000,0.160,0.940,1,96.618491,-21.979648
3785158801.535000,0,1,12.000,12.001,35.999,3.098,0,0,12.000,12.000,0.160,0.930,1,88.727630,-21.979648
3785158891.535000,0,1,12.000,12.002,35.999,3.100,0,0,12.000,12.000,0.160,0.930,1,81.157036,-21.979648
3785158981.535000,0,1,12.000,12.002,36.000,3.098,0,0,12.000,12.000,0.160,0.940,1,73.635436,-21.979648
3785159071.535000,0,1,12.000,12.004,36.001,3.098,0,0,12.000,12.000,0.160,0.920,1,67.068600,-21.979648
3785159161.535000,0,1,12.000,11.996,35.999,3.099,0,0,12.000,12.000,0.160,0.950,1,61.263104,-21.979648
3785159251.535000,0,1,12.000,12.000,35.999,3.097,0,0,12.000,12.000,0.160,0.940,1,55.639756,-21.979648
3785159341.535000,0,1,12.000,12.000,35.997,3.098,0,0,12.000,12.000,0.160,0.940,1,49.427685,-21.979648
3785159431.535000,0,1,12.000,12.004,35.996,3.097,0,0,12.000,12.000,0.160,0.930,1,44.162994,-21.979648
3785159521.535000,0,1,12.000,12.000,35.997,3.098,0,0,12.000,12.000,0.160,0.940,1,38.608639,-21.979648
3785159611.535000,0,1,12.000,12.002,35.995,3.100,0,0,12.000,12.000,0.160,0.940,1,31.792139,-21.979648
3785159701.535000,0,1,12.001,12.002,35.997,3.097,0,0,12.000,12.000,0.160,0.940,1,25.526242,-21.979648
3785159791.535000,0,1,12.000,12.001,35.997,3.099,0,0,12.000,12.000,0.160,0.940,1,18.898331,-21.979648
3785159881.535000,0,1,12.000,12.000,35.998,3.099,0,0,12.000,12.000,0.160,0.940,1,12.036999,-21.979648
3785159971.535000,0,1,12.000,12.000,35.999,3.099,0,0,12.000,12.000,0.160,0.960,1,11.967200,-21.979648
3785160061.535000,0,1,11.999,11.992,35.997,3.099,0,0,12.000,12.000,0.160,0.990,1,13.996593,-21.979648
3785160151.535000,0,1,12.000,12.001,35.998,3.098,0,0,12.000,12.000,0.160,0.970,1,16.466657,-21.979648
3785160241.535000,0,1,12.000,11.998,35.999,3.098,0,0,12.000,12.000,0.160,0.980,1,18.976855,-21.979648
3785160331.535000,0,1,12.000,12.002,35.999,3.097,0,0,12.000,12.000,0.160,0.950,1,20.982355,-21.979648
3785160421.535000,0,1,12.000,11.995,35.999,3.097,0,0,12.000,12.000,0.160,0.980,1,23.000742,-21.979648
3785160511.535000,0,1,12.000,12.001,35.996,3.099,0,0,12.000,12.000,0.160,0.960,1,25.989865,-21.979648
3785160601.535000,0,1,12.000,12.001,35.997,3.097,0,0,12.000,12.000,0.160,0.960,1,28.983015,-21.979648
3785160691.535000,0,1,12.001,12.006,35.997,3.098,0,0,12.000,12.000,0.160,0.960,1,31.572676,-21.979648
3785160781.535000,0,1,12.000,11.995,35.996,3.098,0,0,12.000,12.000,0.160,0.980,1,33.994418,-21.979648
3785160871.535000,0,1,12.000,12.000,35.999,3.098,0,0,12.000,12.000,0.160,0.980,1,36.949984,-21.979648
3785160975.831000,0,1,11.999,11.996,35.997,3.098,0,0,12.000,12.000,0.160,0.990,1,38.257230,-21.979648
3785161065.831000,0,1,12.000,12.003,35.998,3.099,0,0,12.000,12.000,0.160,0.950,1,40.966488,-21.979648
3785161155.831000,0,1,12.000,11.998,35.995,3.098,0,0,12.000,12.000,0.160,0.990,1,42.993197,-21.979648
3785161245.831000,0,1,12.000,11.994,35.994,3.097,0,0,12.000,12.000,0.160,1.000,1,45.121919,-21.979648
3785161335.831000,0,1,12.000,11.999,35.992,3.097,0,0,12.000,12.000,0.160,0.960,1,47.959365,-21.979648
3785161425.831000,0,1,12.000,11.995,35.991,3.097,0,0,12.000,12.000,0.160,0.980,1,49.969429,-21.979648
3785161515.831000,0,1,11.999,11.998,35.994,3.097,0,0,12.000,12.000,0.160,0.980,1,51.996943,-21.979648
3785161605.831000,0,1,12.000,12.006,35.993,3.098,0,0,12.000,12.000,0.160,0.950,1,54.777610,-21.979648
3785161695.831000,0,1,12.000,12.004,35.992,3.097,0,0,12.000,12.000,0.160,0.950,1,57.016667,-21.979648
3785161785.831000,0,1,12.000,12.000,35.993,3.098,0,0,12.000,12.000,0.160,0.980,1,58.998141,-21.979648
3785161875.831000,0,1,12.000,11.997,35.993,3.099,0,0,12.000,12.000,0.160,0.980,1,61.958271,-21.979648
3785161965.831000,0,1,12.000,12.006,35.996,3.098,0,0,12.000,12.000,0.160,0.950,1,63.819477,-21.979648
3785162055.831000,0,1,11.999,11.990,35.997,3.097,0,0,12.000,12.000,0.160,1.000,1,65.984037,-21.979648
3785162145.831000,0,1,12.000,11.998,35.996,3.096,0,0,12.000,12.000,0.160,0.960,1,68.988194,-21.979648
3785162235.831000,0,1,12.000,11.999,35.994,3.098,0,0,12.000,12.000,0.160,0.980,1,70.997722,-21.979648
3785162325.831000,0,1,12.000,12.002,35.991,3.096,0,0,12.000,12.000,0.160,0.980,1,73.979462,-21.979648
3785162415.831000,0,1,12.000,11.992,35.993,3.098,0,0,12.000,12.000,0.160,0.970,1,75.983352,-21.979648
3785162505.831000,0,1,12.000,12.002,35.990,3.097,0,0,12.000,12.000,0.160,0.980,1,77.983349,-21.979648
3785162595.831000,0,1,12.000,12.003,35.994,3.098,0,0,12.000,12.000,0.160,0.960,1,80.414353,-21.979648
3785162685.831000,0,1,12.000,11.998,35.995,3.098,0,0,12.000,12.000,0.160,0.980,1,82.994483,-21.979648
3785162775.831000,0,1,11.999,11.995,35.995,3.098,0,0,12.000,12.000,0.160,0.980,1,85.964412,-21.979648
3785162865.831000,0,1,12.000,11.997,35.997,3.098,0,0,12.000,12.000,0.160,0.980,1,87.995819,-21.979648
3785162955.831000,0,1,12.000,11.998,35.996,3.097,0,0,12.000,12.000,0.160,0.960,1,90.971116,-21.979648
3785163045.831000,0,1,12.000,12.002,36.000,3.098,0,0,12.000,12.000,0.160,0.970,1,92.649369,-21.979648
3785163135.831000,0,1,12.000,11.995,35.997,3.099,0,0,12.000,12.000,0.160,0.980,1,94.995138,-21.979648
3785163225.831000,0,1,12.000,11.997,35.997,3.097,0,0,12.000,12.000,0.160,0.990,1,98.008959,-21.979648
3785163315.831000,0,1,12.000,12.002,35.997,3.097,0,0,12.000,12.000,0.160,0.970,1,100.399694,-21.979648
3785163405.831000,0,1,12.000,11.998,35.996,3.098,0,0,12.000,12.000,0.160,0.990,1,102.997274,-21.979648
3785163495.831000,0,1,12.000,11.998,35.999,3.098,0,0,12.000,12.000,0.160,0.960,1,105.993780,-21.979648
3785163585.831000,0,1,12.000,11.997,35.997,3.099,0,0,12.000,12.000,0.160,0.980,1,108.003173,-21.979648
3785163675.831000,0,1,12.000,11.998,35.998,3.098,0,0,12.000,12.000,0.160,0.960,1,111.054847,-21.979648
3785163765.831000,0,1,12.000,11.999,35.999,3.098,0,0,12.000,12.000,0.160,0.970,1,113.002898,-21.979648
3785163855.831000,0,1,12.000,12.000,35.999,3.098,0,0,12.000,12.000,0.160,0.980,1,115.014841,-21.979648
3785163945.831000,0,1,12.000,12.002,36.001,3.099,0,0,12.000,12.000,0.160,0.980,1,117.003966,0.000000
3785164035.831000,0,1,12.000,11.998,35.999,3.099,0,0,12.000,12.000,0.160,0.990,1,119.003829,-21.979648
3785164125.831000,0,1,12.000,12.001,35.999,3.098,0,0,12.000,12.000,0.160,0.980,1,121.004497,-21.979648
3785164215.831000,0,1,12.000,12.001,35.998,3.099,0,0,12.000,12.000,0.160,0.980,1,123.003823,-21.979648
3785164305.831000,0,1,12.000,11.994,35.996,3.098,0,0,12.000,12.000,0.160,0.990,1,125.998987,-21.979648
3785164395.831000,0,1,12.000,12.001,35.997,3.098,0,0,12.000,12.000,0.160,0.960,1,128.516030,-21.979648
3785164485.831000,0,1,12.000,12.001,35.995,3.098,0,0,12.000,12.000,0.160,0.980,1,131.204483,-21.979648
3785164575.831000,0,1,12.000,11.996,35.997,3.098,0,0,12.000,12.000,0.160,0.990,1,134.002466,-21.979648
3785164665.831000,0,1,12.000,11.994,35.997,3.098,0,0,12.000,12.000,0.160,0.990,1,137.072931,-21.979648
3785164755.831000,0,1,12.000,11.998,35.998,3.097,0,0,12.000,12.000,0.160,0.970,1,139.629303,-21.979648
3785164845.831000,0,1,12.000,11.995,35.998,3.098,0,0,12.000,12.000,0.160,0.980,1,142.040709,-21.979648
3785164935.831000,0,1,12.000,12.002,35.997,3.097,0,0,12.000,12.000,0.160,0.950,1,144.775336,-21.979648
3785165025.831000,0,1,12.000,11.999,35.997,3.099,0,0,12.000,12.000,0.160,0.990,1,147.003521,-21.979648
3785165115.831000,0,1,12.000,11.991,35.997,3.099,0,0,12.000,12.000,0.160,0.980,1,150.097611,-21.979648
3785165205.831000,0,1,12.000,11.999,35.996,3.096,0,0,12.000,12.000,0.160,0.980,1,152.001232,-21.979648
3785165295.831000,0,1,12.000,11.998,35.995,3.098,0,0,12.000,12.000,0.160,0.980,1,154.374115,-21.979648
3785165385.831000,0,1,12.000,11.998,35.992,3.098,0,0,12.000,12.000,0.160,0.970,1,157.025252,-21.979648
3785165475.831000,0,1,12.000,11.998,35.993,3.098,0,0,12.000,12.000,0.160,0.990,1,158.001090,-21.979648
3785165565.831000,0,1,12.000,12.002,35.992,3.099,0,0,12.000,12.000,0.160,0.970,1,160.000416,-21.979648
3785165655.831000,0,1,12.000,12.001,35.993,3.097,0,0,12.000,12.000,0.160,0.970,1,160.000013,-21.979648
3785165745.831000,0,1,12.000,12.000,35.996,3.098,0,0,12.000,12.000,0.160,0.980,1,160.002026,-21.979648
3785165835.831000,0,1,12.000,11.999,35.995,3.099,0,0,12.000,12.000,0.160,0.980,1,160.000550,-21.979648
3785165925.831000,0,1,12.000,12.002,35.997,3.098,0,0,12.000,12.000,0.160,0.970,1,160.000147,-21.979648
3785166015.831000,0,1,12.001,12.001,35.995,3.099,0,0,12.000,12.000,0.160,0.980,1,160.000550,-21.979648
3785166105.831000,0,1,12.000,12.000,35.995,3.098,0,0,12.000,12.000,0.160,0.980,1,160.000550,-21.979648
3785166195.831000,0,1,12.000,12.002,35.997,3.098,0,0,12.000,12.000,0.160,0.980,1,159.999879,-21.979648
3785166285.831000,0,1,12.000,11.995,35.994,3.098,0,0,12.000,12.000,0.160,0.990,1,159.999610,-21.979648
3785166375.831000,0,1,12.000,12.000,35.995,3.098,0,0,12.000,12.000,0.160,0.980,1,159.999745,-21.979648
3785166465.831000,0,1,12.000,12.000,35.995,3.097,0,0,12.000,12.000,0.160,0.990,1,160.001758,-21.979648
3785166555.831000,0,1,12.000,12.001,35.994,3.098,0,0,12.000,12.000,0.160,0.980,1,160.000013,-21.979648
3785166645.831000,0,1,12.000,11.999,35.998,3.097,0,0,12.000,12.000,0.160,0.990,1,160.000684,-21.979648
3785166735.831000,0,1,11.999,11.998,35.997,3.099,0,0,12.000,12.000,0.160,0.990,1,160.000282,-21.979648
3785166825.831000,0,1,12.000,11.999,35.998,3.097,0,0,12.000,12.000,0.160,0.980,1,160.001355,-21.979648
3785166915.831000,0,1,12.000,11.998,35.999,3.099,0,0,12.000,12.000,0.160,0.990,1,160.000147,-21.979648
3785167005.831000,0,1,12.000,11.999,35.998,3.098,0,0,12.000,12.000,0.160,0.990,1,160.000013,-21.979648
3785167095.831000,0,1,11.999,11.998,35.999,3.097,0,0,12.000,12.000,0.160,0.970,1,160.001490,-21.979648
3785167185.831000,0,1,11.999,11.994,35.995,3.099,0,0,12.000,12.000,0.160,1.010,1,160.000953,-21.979648
3785167275.831000,0,1,12.000,12.000,35.995,3.096,0,0,12.000,12.000,0.160,0.980,1,160.000013,-21.979648
3785167365.831000,0,1,12.000,11.997,35.994,3.097,0,0,12.000,12.000,0.160,0.980,1,160.002295,-21.979648
3785167455.831000,0,1,11.999,11.998,35.993,3.096,0,0,12.000,12.000,0.160,0.980,1,160.003235,-21.979648
3785167545.831000,0,1,12.000,12.003,35.994,3.097,0,0,12.000,12.000,0.160,0.970,1,160.002563,-21.979648
3785167635.831000,0,1,12.000,12.006,35.995,3.099,0,0,12.000,12.000,0.160,0.960,1,160.002563,-21.979648
3785167725.831000,0,1,12.000,12.001,35.996,3.097,0,0,12.000,12.000,0.160,0.980,1,160.003100,-21.979648
3785167815.831000,0,1,12.000,12.002,35.996,3.099,0,0,12.000,12.000,0.160,0.980,1,160.003906,-21.979648
3785167905.831000,0,1,12.000,12.004,35.997,3.096,0,0,12.000,12.000,0.160,0.970,1,160.003637,-21.979648
3785167995.831000,0,1,12.000,11.999,35.999,3.099,0,0,12.000,12.000,0.160,0.980,1,160.003369,-21.979648
3785168085.831000,0,1,12.000,11.996,35.996,3.097,0,0,12.000,12.000,0.160,0.990,1,160.002563,-21.979648
3785168175.831000,0,1,12.000,11.998,35.997,3.097,0,0,12.000,12.000,0.160,0.990,1,160.000684,-21.979648
3785168265.831000,0,1,12.000,12.001,35.995,3.098,0,0,12.000,12.000,0.160,0.980,1,159.999476,-21.979648
3785168355.831000,0,1,12.000,11.999,35.995,3.096,0,0,12.000,12.000,0.160,0.990,1,160.000416,-21.979648
3785168445.831000,0,1,12.000,12.000,35.996,3.098,0,0,12.000,12.000,0.160,0.980,1,159.999073,-21.979648
3785168535.831000,0,1,12.000,12.001,35.994,3.097,0,0,12.000,12.000,0.160,0.980,1,159.999879,-21.979648
3785168625.831000,0,1,12.000,12.000,35.995,3.099,0,0,12.000,12.000,0.160,0.980,1,159.998805,-21.979648
3785168715.831000,0,1,12.000,11.999,35.994,3.099,0,0,12.000,12.000,0.160,0.980,1,160.000684,-21.979648
3785168805.831000,0,1,12.000,11.999,35.994,3.097,0,0,12.000,12.000,0.160,0.980,1,159.999342,-21.979648
3785168895.831000,0,1,12.000,12.000,35.996,3.098,0,0,12.000,12.000,0.160,0.980,1,160.003503,-21.979648
3785168985.831000,0,1,12.000,11.996,35.994,3.099,0,0,12.000,12.000,0.160,0.980,1,160.000550,-21.979648
3785169075.831000,0,1,12.000,11.999,35.996,3.097,0,0,12.000,12.000,0.160,0.980,1,160.001624,-21.979648
3785169165.831000,0,1,12.000,12.007,35.994,3.098,0,0,12.000,12.000,0.160,0.960,1,160.000416,-21.979648
3785169255.831000,0,1,12.000,12.003,35.991,3.096,0,0,12.000,12.000,0.160,0.980,1,160.003235,-21.979648
3785169345.831000,0,1,12.000,11.997,35.992,3.097,0,0,12.000,12.000,0.160,0.980,1,160.000282,-21.979648
3785169435.831000,0,1,12.000,12.003,35.990,3.097,0,0,12.000,12.000,0.160,0.960,1,160.001758,-21.979648
3785169525.831000,0,1,12.000,11.998,35.990,3.097,0,0,12.000,12.000,0.160,0.990,1,160.001355,-21.979648
3785169615.831000,0,1,12.000,12.003,35.989,3.099,0,0,12.000,12.000,0.160,0.980,1,160.002563,-21.979648
3785169705.831000,0,1,12.000,12.004,35.991,3.096,0,0,12.000,12.000,0.160,0.970,1,160.002832,-21.979648
3785169795.831000,0,1,12.001,12.003,35.992,3.098,0,0,12.000,12.000,0.160,0.980,1,160.003637,-21.979648
3785169885.831000,0,1,12.000,11.999,35.991,3.098,0,0,12.000,12.000,0.160,0.980,1,160.003100,-21.979648
3785169975.831000,0,1,12.000,12.000,35.993,3.099,0,0,12.000,12.000,0.160,0.990,1,160.004174,-21.979648
3785170065.831000,0,1,12.000,12.001,35.991,3.098,0,0,12.000,12.000,0.160,0.980,1,160.004577,-21.979648
3785170155.831000,0,1,12.000,12.001,35.989,3.095,0,0,12.000,12.000,0.160,0.980,1,160.004308,-21.979648
3785170245.831000,0,1,12.000,12.003,35.987,3.097,0,0,12.000,12.000,0.160,0.980,1,160.004577,-21.979648
3785170335.831000,0,1,12.000,11.999,35.985,3.097,0,0,12.000,12.000,0.160,0.980,1,160.004308,-21.979648
3785170425.831000,0,1,12.000,11.998,35.987,3.097,0,0,12.000,12.000,0.160,0.990,1,160.004711,-21.979648
3785170515.831000,0,1,12.000,11.999,35.987,3.100,0,0,12.000,12.000,0.160,0.990,1,160.002026,-21.979648
3785170605.831000,0,1,12.000,12.000,35.989,3.096,0,0,12.000,12.000,0.160,0.980,1,160.003235,-21.979648
3785170695.831000,0,1,12.000,12.004,35.989,3.098,0,0,12.000,12.000,0.160,0.970,1,160.004040,-21.979648
3785170785.831000,0,1,12.000,11.993,35.990,3.097,0,0,12.000,12.000,0.160,1.000,1,160.005382,-21.979648
3785170875.831000,0,1,12.000,12.002,35.992,3.097,0,0,12.000,12.000,0.160,0.980,1,160.003637,-21.979648
3785170965.831000,0,1,12.000,12.002,35.990,3.099,0,0,12.000,12.000,0.160,0.980,1,160.004040,-21.979648
3785171055.831000,0,1,12.000,12.001,35.992,3.095,0,0,12.000,12.000,0.160,0.960,1,160.004845,-21.979648
3785171145.831000,0,1,12.001,12.004,35.989,3.098,0,0,12.000,12.000,0.150,0.960,1,160.002026,-21.979648
3785171235.831000,0,1,12.000,11.999,35.987,3.097,0,0,12.000,12.000,0.160,0.990,1,160.004845,-21.979648
3785171325.831000,0,1,12.000,12.000,35.989,3.098,0,0,12.000,12.000,0.160,0.980,1,160.000684,-21.979648
3785171415.831000,0,1,12.000,11.998,35.987,3.098,0,0,12.000,12.000,0.160,0.990,1,160.001758,-21.979648
3785171505.831000,0,1,12.000,12.003,35.988,3.098,0,0,12.000,12.000,0.160,0.970,1,160.001355,-21.979648
3785171595.831000,0,1,12.000,11.998,35.988,3.098,0,0,12.000,12.000,0.160,0.990,1,160.003235,-21.979648
3785171685.831000,0,1,12.000,12.003,35.988,3.098,0,0,12.000,12.000,0.160,0.980,1,160.002295,-21.979648
3785171775.831000,0,1,12.000,12.003,35.990,3.098,0,0,12.000,12.000,0.160,0.970,1,160.002429,-21.979648
3785171865.831000,0,1,12.000,12.003,35.989,3.097,0,0,12.000,12.000,0.160,0.980,1,160.003637,-21.979648
3785171955.831000,0,1,12.000,12.002,35.991,3.097,0,0,12.000,12.000,0.160,0.980,1,160.004577,-21.979648
3785172045.831000,0,1,12.000,12.002,35.989,3.097,0,0,12.000,12.000,0.160,0.980,1,160.002698,-21.979648
3785172135.831000,0,1,12.000,12.007,35.988,3.096,0,0,12.000,12.000,0.160,0.960,1,160.002429,-21.979648
3785172225.831000,0,1,12.000,11.999,35.986,3.097,0,0,12.000,12.000,0.160,0.980,1,160.003100,-21.979648
3785172315.831000,0,1,12.000,12.001,35.984,3.098,0,0,12.000,12.000,0.160,0.980,1,160.003503,-21.979648
3785172405.831000,0,1,12.000,11.997,35.985,3.098,0,0,12.000,12.000,0.160,0.990,1,160.004308,-21.979648
3785172495.831000,0,1,11.999,11.995,35.985,3.099,0,0,12.000,12.000,0.160,0.990,1,160.003369,-21.979648
3785172585.831000,0,1,12.000,12.001,35.987,3.096,0,0,12.000,12.000,0.160,0.980,1,160.005785,-21.979648
3785172675.831000,0,1,12.000,12.005,35.988,3.100,0,0,12.000,12.000,0.160,0.970,1,160.004040,-21.979648
3785172765.831000,0,1,12.000,12.002,35.988,3.099,0,0,12.000,12.000,0.160,0.970,1,160.003369,-21.979648
3785172855.831000,0,1,12.000,12.002,35.990,3.097,0,0,12.000,12.000,0.160,0.980,1,160.003369,-21.979648
3785172945.831000,0,1,12.000,12.001,35.988,3.099,0,0,12.000,12.000,0.160,0.980,1,160.003771,-21.979648
3785173035.831000,0,1,12.000,11.999,35.987,3.096,0,0,12.000,12.000,0.160,0.980,1,160.004443,-21.979648
3785173125.831000,0,1,12.000,12.003,35.986,3.098,0,0,12.000,12.000,0.160,0.980,1,160.004040,-21.979648
3785173215.831000,0,1,12.000,11.994,35.982,3.099,0,0,12.000,12.000,0.160,1.000,1,160.005114,-21.979648
3785173305.831000,0,1,12.000,11.999,35.983,3.098,0,0,12.000,12.000,0.160,0.980,1,160.004040,-21.979648
3785173395.831000,0,1,12.000,12.000,35.982,3.099,0,0,12.000,12.000,0.160,0.980,1,160.004308,-21.979648
3785173485.831000,0,1,12.000,11.997,35.984,3.098,0,0,12.000,12.000,0.160,0.990,1,160.004711,-21.979648
3785173575.831000,0,1,12.000,12.000,35.985,3.098,0,0,12.000,12.000,0.160,0.980,1,160.004577,-21.979648
3785173665.831000,0,1,12.000,12.003,35.984,3.099,0,0,12.000,12.000,0.160,0.980,1,160.003235,-21.979648
3785173755.831000,0,1,12.000,11.997,35.988,3.098,0,0,12.000,12.000,0.160,0.990,1,160.004308,-21.979648
3785173845.831000,0,1,12.000,12.002,35.987,3.100,0,0,12.000,12.000,0.160,0.980,1,160.003503,-21.979648
3785173935.831000,0,1,12.000,12.000,35.987,3.098,0,0,12.000,12.000,0.160,0.980,1,160.004308,-21.979648
3785174025.831000,0,1,11.999,11.994,35.986,3.099,0,0,12.000,12.000,0.160,0.990,1,160.002161,-21.979648
3785174115.831000,0,1,12.000,12.001,35.985,3.097,0,0,12.000,12.000,0.160,0.980,1,160.002966,-21.979648
3785174205.831000,0,1,12.000,12.001,35.985,3.097,0,0,12.000,12.000,0.160,0.980,1,160.002966,-21.979648
3785174295.831000,0,1,12.000,11.999,35.983,3.099,0,0,12.000,12.000,0.160,0.980,1,160.000147,-21.979648
3785174385.831000,0,1,12.000,11.999,35.984,3.098,0,0,12.000,12.000,0.160,0.980,1,160.001490,-21.979648
3785174475.831000,0,1,12.000,11.996,35.985,3.099,0,0,12.000,12.000,0.160,0.990,1,160.002161,-21.979648
3785174565.831000,0,1,12.000,11.999,35.985,3.098,0,0,12.000,12.000,0.160,0.980,1,160.003235,-21.979648
3785174655.831000,0,1,12.000,11.996,35.985,3.098,0,0,12.000,12.000,0.160,0.980,1,160.002429,-21.979648
3785174745.831000,0,1,12.000,11.999,35.983,3.099,0,0,12.000,12.000,0.160,0.980,1,160.002698,-21.979648
3785174835.831000,0,1,12.000,11.999,35.985,3.099,0,0,12.000,12.000,0.160,0.980,1,160.002966,-21.979648
3785174925.831000,0,1,12.000,12.001,35.985,3.098,0,0,12.000,12.000,0.160,0.990,1,160.002698,-21.979648
3785175015.831000,0,1,12.000,12.000,35.984,3.099,0,0,12.000,12.000,0.160,0.980,1,160.002026,-21.979648
3785175105.831000,0,1,12.000,11.998,35.984,3.099,0,0,12.000,12.000,0.160,0.990,1,160.000953,-21.979648
3785175195.831000,0,1,12.000,12.002,35.981,3.099,0,0,12.000,12.000,0.160,0.980,1,160.003503,-21.979648
3785175285.831000,0,1,12.000,12.002,35.982,3.097,0,0,12.000,12.000,0.160,0.980,1,160.002563,-21.979648
3785175375.831000,0,1,11.999,11.996,35.983,3.098,0,0,12.000,12.000,0.160,0.990,1,160.004711,-21.979648
3785175465.831000,0,1,12.000,12.001,35.983,3.098,0,0,12.000,12.000,0.160,0.980,1,159.999879,-21.979648
3785175555.831000,0,1,12.000,11.995,35.984,3.099,0,0,12.000,12.000,0.160,1.000,1,160.003369,-21.979648
3785175645.831000,0,1,12.000,11.999,35.984,3.100,0,0,12.000,12.000,0.160,0.980,1,160.001892,-21.979648
3785175735.831000,0,1,12.000,12.003,35.986,3.098,0,0,12.000,12.000,0.160,0.970,1,160.002026,-21.979648
3785175825.831000,0,1,12.000,11.996,35.987,3.100,0,0,12.000,12.000,0.160,0.990,1,160.002295,-21.979648
3785175915.831000,0,1,12.000,12.001,35.986,3.098,0,0,12.000,12.000,0.160,0.980,1,160.003369,-21.979648
3785176005.831000,0,1,12.000,11.997,35.985,3.097,0,0,12.000,12.000,0.160,1.000,1,160.000953,-21.979648
3785176095.831000,0,1,12.000,12.000,35.981,3.099,0,0,12.000,12.000,0.160,0.980,1,160.003369,-21.979648
3785176185.831000,0,1,12.000,12.002,35.982,3.098,0,0,12.000,12.000,0.160,0.980,1,160.002026,-21.979648
3785176275.831000,0,1,12.000,11.995,35.980,3.099,0,0,12.000,12.000,0.160,0.990,1,160.002161,-21.979648
3785176365.831000,0,1,12.000,11.997,35.982,3.098,0,0,12.000,12.000,0.160,0.980,1,160.002161,-21.979648
3785176455.831000,0,1,12.000,12.003,35.984,3.099,0,0,12.000,12.000,0.160,0.980,1,159.998402,-21.979648
3785176545.831000,0,1,12.000,11.999,35.984,3.099,0,0,12.000,12.000,0.160,0.980,1,159.997597,-21.979648
3785176635.831000,0,1,12.000,11.999,35.987,3.099,0,0,12.000,12.000,0.160,0.980,1,159.999208,-21.979648
3785176725.831000,0,1,12.000,12.002,35.988,3.099,0,0,12.000,12.000,0.160,0.960,1,160.001892,-21.979648
3785176815.831000,0,1,12.000,11.997,35.987,3.098,0,0,12.000,12.000,0.160,0.990,1,160.001624,-21.979648
3785176905.831000,0,1,12.000,12.000,35.988,3.099,0,0,12.000,12.000,0.160,0.980,1,160.003369,-21.979648
3785176995.831000,0,1,12.000,11.997,35.986,3.098,0,0,12.000,12.000,0.160,0.990,1,160.001490,-21.979648
3785177085.831000,0,1,12.000,11.998,35.986,3.098,0,0,12.000,12.000,0.160,0.980,1,160.004174,-21.979648
3785177175.831000,0,1,12.000,11.999,35.983,3.098,0,0,12.000,12.000,0.160,0.980,1,160.004040,-21.979648
3785177265.831000,0,1,12.000,12.001,35.985,3.098,0,0,12.000,12.000,0.160,0.980,1,160.002966,-21.979648
3785177355.831000,0,1,12.000,12.000,35.985,3.098,0,0,12.000,12.000,0.160,0.980,1,160.003637,-21.979648
3785177445.831000,0,1,12.000,11.998,35.984,3.098,0,0,12.000,12.000,0.160,0.990,1,159.999610,-21.979648
3785177535.831000,0,1,12.000,11.998,35.986,3.098,0,0,12.000,12.000,0.160,0.980,1,160.002966,-21.979648
3785177625.831000,0,1,12.000,12.002,35.985,3.099,0,0,12.000,12.000,0.160,0.980,1,160.001221,-21.979648
3785177715.831000,0,1,12.000,11.996,35.987,3.098,0,0,12.000,12.000,0.160,0.990,1,160.003369,-21.979648
3785177805.831000,0,1,12.000,11.999,35.987,3.099,0,0,12.000,12.000,0.160,0.980,1,160.000416,-21.979648
3785177895.831000,0,1,12.000,12.001,35.984,3.098,0,0,12.000,12.000,0.160,0.990,1,160.000282,-21.979648
3785177985.831000,0,1,12.000,11.997,35.985,3.098,0,0,12.000,12.000,0.160,0.990,1,159.999879,-21.979648
3785178075.831000,0,1,12.001,11.997,35.983,3.098,0,0,12.000,12.000,0.160,1.000,1,160.001624,-21.979648
3785178165.831000,0,1,11.999,11.995,35.982,3.098,0,0,12.000,12.000,0.160,0.980,1,160.002295,-21.979648
3785178255.831000,0,1,12.000,11.999,35.983,3.098,0,0,12.000,12.000,0.160,0.980,1,160.002563,-21.979648
3785178345.831000,0,1,12.000,12.001,35.983,3.098,0,0,12.000,12.000,0.160,0.980,1,160.003503,-21.979648
3785178435.831000,0,1,12.000,12.000,35.986,3.098,0,0,12.000,12.000,0.160,0.980,1,160.001490,-21.979648
3785178525.831000,0,1,12.000,12.001,35.985,3.099,0,0,12.000,12.000,0.160,0.980,1,159.999745,-21.979648
3785178615.831000,0,1,12.000,12.001,35.987,3.098,0,0,12.000,12.000,0.160,0.980,1,159.999745,-21.979648
3785178705.831000,0,1,12.000,11.998,35.987,3.099,0,0,12.000,12.000,0.160,0.990,1,159.996657,-21.979648
3785178795.831000,0,1,11.999,11.999,35.987,3.097,0,0,12.000,12.000,0.160,0.980,1,159.997463,-21.979648
3785178885.831000,0,1,12.000,11.998,35.990,3.098,0,0,12.000,12.000,0.160,0.980,1,159.998537,-21.979648
3785178975.831000,0,1,12.000,11.999,35.989,3.099,0,0,12.000,12.000,0.160,0.980,1,159.999208,-21.979648
3785179065.831000,0,1,12.000,11.997,35.988,3.098,0,0,12.000,12.000,0.160,0.980,1,159.998402,-21.979648
3785179155.831000,0,1,12.000,12.003,35.986,3.098,0,0,12.000,12.000,0.160,0.970,1,159.999476,-21.979648
3785179245.831000,0,1,12.000,11.996,35.985,3.098,0,0,12.000,12.000,0.160,1.000,1,160.002966,-21.979648
3785179335.831000,0,1,12.000,12.000,35.986,3.099,0,0,12.000,12.000,0.160,0.960,1,159.999073,-21.979648
3785179425.831000,0,1,12.000,12.001,35.985,3.099,0,0,12.000,12.000,0.160,0.980,1,160.000818,-21.979648
3785179515.831000,0,1,12.000,11.999,35.987,3.099,0,0,12.000,12.000,0.160,0.980,1,159.998671,-21.979648
3785179605.831000,0,1,12.000,11.996,35.988,3.098,0,0,12.000,12.000,0.160,0.990,1,159.997060,-21.979648
3785179695.831000,0,1,12.000,12.006,35.988,3.098,0,0,12.000,12.000,0.160,0.980,1,159.999208,-21.979648
3785179785.831000,0,1,12.000,11.995,35.987,3.099,0,0,12.000,12.000,0.160,1.000,1,160.002698,-21.979648
3785179875.831000,0,1,12.000,12.001,35.986,3.097,0,0,12.000,12.000,0.160,0.980,1,160.000818,-21.979648
3785179965.831000,0,1,12.000,12.000,35.988,3.098,0,0,12.000,12.000,0.160,0.970,1,160.001758,-21.979648
3785180055.831000,0,1,12.000,11.998,35.987,3.098,0,0,12.000,12.000,0.160,0.990,1,160.002161,-21.979648
3785180145.831000,0,1,12.000,12.000,35.986,3.098,0,0,12.000,12.000,0.160,0.980,1,160.000013,-21.979648
3785180235.831000,0,1,12.000,12.000,35.987,3.099,0,0,12.000,12.000,0.160,0.980,1,160.003637,-21.979648
3785180325.831000,0,1,12.000,11.993,35.986,3.098,0,0,12.000,12.000,0.160,1.000,1,160.002698,-21.979648
3785180415.831000,0,1,12.000,12.000,35.988,3.097,0,0,12.000,12.000,0.160,0.980,1,160.004577,-21.979648
3785180505.831000,0,1,12.000,12.002,35.987,3.098,0,0,12.000,12.000,0.160,0.970,1,160.000684,-21.979648
3785180595.831000,0,1,12.000,12.000,35.989,3.099,0,0,12.000,12.000,0.160,0.980,1,160.002966,-21.979648
3785180685.831000,0,1,12.000,12.000,35.990,3.098,0,0,12.000,12.000,0.160,0.990,1,160.002295,-21.979648
3785180775.831000,0,1,12.000,11.999,35.990,3.098,0,0,12.000,12.000,0.160,0.980,1,159.999745,-21.979648
3785180865.831000,0,1,12.000,12.000,35.991,3.097,0,0,12.000,12.000,0.160,0.980,1,160.004040,-21.979648
3785180955.831000,0,1,12.000,11.997,35.989,3.098,0,0,12.000,12.000,0.160,0.980,1,160.002161,-21.979648
3785181045.831000,0,1,12.000,12.002,35.989,3.097,0,0,12.000,12.000,0.160,0.980,1,160.001490,-21.979648
3785181135.831000,0,1,12.000,12.000,35.988,3.097,0,0,12.000,12.000,0.160,0.980,1,160.000550,-21.979648
3785181225.831000,0,1,12.000,12.004,35.987,3.097,0,0,12.000,12.000,0.160,0.970,1,160.000818,-21.979648
3785181315.831000,0,1,12.000,12.002,35.988,3.098,0,0,12.000,12.000,0.160,0.960,1,160.001087,-21.979648
3785181405.831000,0,1,12.000,12.001,35.988,3.099,0,0,12.000,12.000,0.160,0.980,1,160.001221,-21.979648
3785181495.831000,0,1,12.000,12.004,35.989,3.098,0,0,12.000,12.000,0.160,0.980,1,159.999879,-21.979648
3785181585.831000,0,1,12.000,11.998,35.988,3.098,0,0,12.000,12.000,0.160,0.990,1,160.000953,-21.979648
3785181675.831000,0,1,12.000,12.002,35.987,3.098,0,0,12.000,12.000,0.160,0.970,1,160.001221,-21.979648
3785181765.831000,0,1,12.000,11.995,35.988,3.100,0,0,12.000,12.000,0.160,0.990,1,159.998402,-21.979648
3785181855.831000,0,1,12.000,12.000,35.985,3.099,0,0,12.000,12.000,0.160,0.980,1,160.002698,-21.979648
3785181945.831000,0,1,12.000,12.003,35.985,3.098,0,0,12.000,12.000,0.160,0.980,1,159.999745,-21.979648
3785182035.831000,0,1,12.000,12.003,35.983,3.098,0,0,12.000,12.000,0.160,0.980,1,160.001490,-21.979648
3785182125.831000,0,1,12.000,11.999,35.983,3.098,0,0,12.000,12.000,0.160,0.990,1,160.001087,-21.979648
3785182215.831000,0,1,12.000,12.000,35.984,3.099,0,0,12.000,12.000,0.160,0.980,1,160.003100,-21.979648
3785182305.831000,0,1,12.000,12.000,35.983,3.098,0,0,12.000,12.000,0.160,0.980,1,160.001221,-21.979648
3785182395.831000,0,1,12.000,11.999,35.986,3.098,0,0,12.000,12.000,0.160,0.980,1,159.999745,-21.979648
3785182485.831000,0,1,12.000,12.003,35.985,3.099,0,0,12.000,12.000,0.160,0.970,1,160.002563,-21.979648
3785182575.831000,0,1,12.000,12.002,35.986,3.098,0,0,12.000,12.000,0.160,0.980,1,160.002966,-21.979648
3785182665.831000,0,1,12.000,11.996,35.987,3.099,0,0,12.000,12.000,0.160,0.990,1,160.004443,-21.979648
3785182755.831000,0,1,12.000,12.002,35.985,3.099,0,0,12.000,12.000,0.160,0.960,1,160.000818,-21.979648
3785182845.831000,0,1,12.000,12.002,35.985,3.097,0,0,12.000,12.000,0.160,0.980,1,160.000953,-21.979648
3785182935.831000,0,1,12.000,12.001,35.985,3.098,0,0,12.000,12.000,0.160,0.960,1,160.001758,-21.979648
3785183025.831000,0,1,12.000,12.003,35.984,3.098,0,0,12.000,12.000,0.160,0.980,1,160.004308,-21.979648
3785183115.831000,0,1,12.000,11.996,35.985,3.098,0,0,12.000,12.000,0.160,0.990,1,160.002966,-21.979648
3785183205.831000,0,1,12.000,11.999,35.983,3.100,0,0,12.000,12.000,0.160,0.980,1,160.004174,-21.979648
3785183295.831000,0,1,12.000,12.004,35.984,3.098,0,0,12.000,12.000,0.160,0.970,1,160.003637,-21.979648
3785183385.831000,0,1,12.000,11.995,35.983,3.099,0,0,12.000,12.000,0.160,0.990,1,160.003906,-21.979648
3785183475.831000,0,1,12.000,12.002,35.983,3.099,0,0,12.000,12.000,0.160,0.980,1,160.002966,-21.979648
3785183565.831000,0,1,12.000,12.002,35.987,3.099,0,0,12.000,12.000,0.160,0.980,1,160.004040,-21.979648
3785183655.831000,0,1,12.000,11.999,35.987,3.100,0,0,12.000,12.000,0.160,0.990,1,160.004443,-21.979648
3785183745.831000,0,1,12.000,11.999,35.989,3.098,0,0,12.000,12.000,0.160,0.980,1,160.004980,-21.979648
3785183835.831000,0,1,12.000,11.995,35.990,3.098,0,0,12.000,12.000,0.160,0.990,1,160.004711,-21.979648
3785183925.831000,0,1,12.000,12.001,35.989,3.097,0,0,12.000,12.000,0.160,0.980,1,160.003906,-21.979648
3785184015.831000,0,1,12.000,11.997,35.989,3.098,0,0,12.000,12.000,0.160,1.000,1,160.005382,-21.979648
3785184105.831000,0,1,12.000,12.002,35.986,3.098,0,0,12.000,12.000,0.160,0.980,1,160.004711,-21.979648
3785184195.831000,0,1,12.000,12.002,35.988,3.097,0,0,12.000,12.000,0.160,0.980,1,160.003369,-21.979648
3785184285.831000,0,1,12.000,11.998,35.988,3.098,0,0,12.000,12.000,0.160,0.990,1,160.003906,-21.979648
3785184375.831000,0,1,12.000,12.000,35.987,3.098,0,0,12.000,12.000,0.160,0.980,1,160.002698,-21.979648
3785184465.831000,0,1,12.000,12.003,35.988,3.098,0,0,12.000,12.000,0.160,0.970,1,160.003771,-21.979648
3785184555.831000,0,1,12.000,11.997,35.988,3.099,0,0,12.000,12.000,0.160,0.990,1,160.003906,-21.979648
3785184645.831000,0,1,12.000,12.000,35.989,3.098,0,0,12.000,12.000,0.160,0.980,1,160.002966,-21.979648
3785184735.831000,0,1,12.000,12.001,35.991,3.098,0,0,12.000,12.000,0.160,0.980,1,160.002295,-21.979648
3785184825.831000,0,1,12.000,12.001,35.989,3.100,0,0,12.000,12.000,0.160,0.980,1,160.003100,-21.979648
3785184915.831000,0,1,12.000,11.999,35.989,3.096,0,0,12.000,12.000,0.160,0.980,1,160.002429,-21.979648
3785185005.831000,0,1,12.000,12.000,35.988,3.099,0,0,12.000,12.000,0.160,0.980,1,160.004577,-21.979648
3785185095.831000,0,1,12.000,11.998,35.986,3.097,0,0,12.000,12.000,0.160,0.980,1,160.004308,-21.979648
3785185185.831000,0,1,12.000,11.999,35.987,3.099,0,0,12.000,12.000,0.160,0.980,1,160.004040,-21.979648
3785185275.831000,0,1,12.000,11.999,35.986,3.099,0,0,12.000,12.000,0.160,0.990,1,160.004980,-21.979648
3785185365.831000,0,1,12.000,12.002,35.986,3.098,0,0,12.000,12.000,0.160,0.960,1,160.005651,-21.979648
3785185455.831000,0,1,12.000,12.002,35.988,3.099,0,0,12.000,12.000,0.160,0.980,1,160.004845,-21.979648
3785185545.831000,0,1,12.000,11.996,35.988,3.099,0,0,12.000,12.000,0.160,1.000,1,160.005114,-21.979648
3785185635.831000,0,1,12.000,12.002,35.989,3.099,0,0,12.000,12.000,0.160,0.980,1,160.004443,-21.979648
3785185725.831000,0,1,12.000,12.000,35.988,3.100,0,0,12.000,12.000,0.160,0.980,1,160.006188,-21.979648
3785185815.831000,0,1,12.000,12.001,35.988,3.099,0,0,12.000,12.000,0.160,0.980,1,160.004577,-21.979648
3785185905.831000,0,1,12.000,12.000,35.987,3.099,0,0,12.000,12.000,0.160,0.980,1,160.006724,-21.979648
3785185995.831000,0,1,12.000,11.999,35.984,3.099,0,0,12.000,12.000,0.160,0.980,1,160.006188,-21.979648
3785186085.831000,0,1,12.000,11.999,35.985,3.097,0,0,12.000,12.000,0.160,0.980,1,160.004711,-21.979648
3785186175.831000,0,1,12.000,12.002,35.986,3.099,0,0,12.000,12.000,0.160,0.970,1,160.004308,-21.979648
3785186265.831000,0,1,12.001,12.004,35.984,3.099,0,0,12.000,12.000,0.160,0.960,1,160.004711,-21.979648
3785186355.831000,0,1,12.000,11.998,35.986,3.099,0,0,12.000,12.000,0.160,0.980,1,160.005785,-21.979648
3785186445.831000,0,1,12.000,12.000,35.987,3.099,0,0,12.000,12.000,0.160,0.990,1,160.005382,-21.979648
3785186535.831000,0,1,12.000,12.002,35.987,3.098,0,0,12.000,12.000,0.160,0.960,1,160.005516,-21.979648
3785186625.831000,0,1,12.000,12.000,35.987,3.100,0,0,12.000,12.000,0.160,0.980,1,160.004711,-21.979648
3785186715.831000,0,1,12.000,12.002,35.985,3.100,0,0,12.000,12.000,0.160,0.980,1,160.005516,-21.979648
3785186805.831000,0,1,12.000,11.998,35.986,3.098,0,0,12.000,12.000,0.160,0.990,1,160.006053,-21.979648
3785186895.831000,0,1,12.000,11.996,35.984,3.099,0,0,12.000,12.000,0.160,0.990,1,160.005785,-21.979648
3785186985.831000,0,1,12.000,12.002,35.982,3.098,0,0,12.000,12.000,0.160,0.970,1,160.005919,-21.979648
3785187075.831000,0,1,12.000,11.997,35.983,3.099,0,0,12.000,12.000,0.160,0.990,1,160.006188,-21.979648
3785187165.831000,0,1,12.000,12.001,35.982,3.100,0,0,12.000,12.000,0.160,0.980,1,160.006724,-21.979648
3785187255.831000,0,1,12.000,12.002,35.983,3.098,0,0,12.000,12.000,0.160,0.970,1,160.006322,-21.979648
3785187345.831000,0,1,12.000,11.999,35.983,3.099,0,0,12.000,12.000,0.160,0.980,1,160.006993,-21.979648
3785187435.831000,0,1,12.000,12.001,35.983,3.100,0,0,12.000,12.000,0.160,0.980,1,160.006993,-21.979648
3785187525.831000,0,1,12.000,12.003,35.985,3.100,0,0,12.000,12.000,0.160,0.970,1,160.007798,-21.979648
3785187615.831000,0,1,12.000,12.000,35.985,3.100,0,0,12.000,12.000,0.160,0.980,1,160.007127,-21.979648
3785187705.831000,0,1,12.000,11.999,35.986,3.099,0,0,12.000,12.000,0.160,0.980,1,160.006322,-21.979648
3785187795.831000,0,1,12.000,12.002,35.987,3.099,0,0,12.000,12.000,0.160,0.980,1,160.006590,-21.979648
3785187885.831000,0,1,12.000,12.000,35.982,3.100,0,0,12.000,12.000,0.160,0.980,1,160.007396,-21.979648
3785187975.831000,0,1,12.000,12.003,35.983,3.099,0,0,12.000,12.000,0.160,0.980,1,160.006590,-21.979648
3785188065.831000,0,1,12.000,12.001,35.983,3.099,0,0,12.000,12.000,0.160,0.980,1,160.006859,-21.979648
3785188155.831000,0,1,12.000,12.000,35.982,3.098,0,0,12.000,12.000,0.160,0.970,1,160.006859,-21.979648
3785188245.831000,0,1,12.000,12.003,35.983,3.099,0,0,12.000,12.000,0.160,0.980,1,160.007396,-21.979648
3785188335.831000,0,1,12.000,12.001,35.983,3.100,0,0,12.000,12.000,0.160,0.980,1,160.006188,-21.979648
3785188425.831000,0,1,12.000,11.997,35.984,3.098,0,0,12.000,12.000,0.160,0.980,1,160.007261,-21.979648
3785188515.831000,0,1,12.000,11.999,35.987,3.101,0,0,12.000,12.000,0.160,0.990,1,160.007933,-21.979648
3785188605.831000,0,1,12.000,11.996,35.986,3.100,0,0,12.000,12.000,0.160,0.990,1,160.006859,-21.979648
3785188695.831000,0,1,11.999,11.994,35.989,3.099,0,0,12.000,12.000,0.160,0.990,1,160.006993,-21.979648
3785188785.831000,0,1,12.000,12.001,35.986,3.100,0,0,12.000,12.000,0.160,0.980,1,160.008067,-21.979648
3785188875.831000,0,1,12.000,12.000,35.988,3.098,0,0,12.000,12.000,0.160,0.980,1,160.007261,-21.979648
3785188965.831000,0,1,12.000,11.999,35.987,3.100,0,0,12.000,12.000,0.160,0.980,1,160.007396,-21.979648
3785189055.831000,0,1,12.000,12.003,35.984,3.099,0,0,12.000,12.000,0.160,0.970,1,160.008201,-21.979648
3785189145.831000,0,1,12.000,12.001,35.983,3.098,0,0,12.000,12.000,0.160,0.980,1,160.007530,-21.979648
3785189235.831000,0,1,12.000,11.999,35.984,3.098,0,0,12.000,12.000,0.160,0.980,1,160.006724,-21.979648
3785189325.831000,0,1,10.490,10.504,35.984,3.099,1,1,2.000,2.000,0.080,0.340,3,160.009543,-21.979648
3785189415.831000,0,1,7.525,7.537,35.986,3.100,1,1,2.000,2.000,0.040,0.270,3,160.007396,-21.979648
3785189505.831000,0,1,4.563,4.575,35.988,3.100,1,1,2.000,2.000,0.000,0.200,3,160.002295,-21.979648
3785189595.831000,0,1,2.112,1.998,35.996,3.098,0,0,2.000,2.000,0.000,0.130,1,159.935181,-21.979648
3785189685.831000,0,1,2.139,1.999,36.006,3.097,0,0,2.000,2.000,0.000,0.120,1,159.931288,-21.979648
3785189775.831000,0,1,2.121,2.000,36.019,3.098,0,0,2.000,2.000,0.000,0.120,1,159.924711,-21.979648
3785189865.831000,0,1,2.125,2.000,36.037,3.093,0,0,2.000,2.000,0.000,0.100,1,156.332099,-21.979648
3785189955.831000,0,1,2.112,2.000,36.049,3.092,0,0,2.000,2.000,0.000,0.100,1,146.947682,-21.979648