File: log/20230103.dat
[Header]
; Displex Transport Data File (default extension .dat)
; Copyright 2016, Hechang LEI, hlei@ruc.edu.cn. All rights reserved.
BYAPP, Displex, 2.0
INFO, 9T mag, Release 2.0.
INFO, Channel 1, Temperature Sensor
INFO, Sample 1 Length (cm): 0.000000; Width (cm): 0.000000; Thickness (cm): 0.000000.

[Data]
Timestamp(s),Field(Oe),Field Status,TempA(K),TempB(K),TempC(K),TempD(K),Ramp1,Ramp2,Setpoint1,Setpoint2,Output1(%),Output2(%),Temp Status
3755556116.274400,0,1,300.001,0.000,41.587,3.225,0,0,300.000,300.000,17.990,0.000,4
3755556206.274400,7373,2,299.998,0.000,41.583,4.087,0,0,300.000,300.000,18.010,0.000,4
3755556296.274400,6134,3,299.994,0.000,41.577,3.651,0,0,300.000,300.000,17.910,0.000,4
3755556386.274400,-2697,3,299.995,0.000,41.580,4.227,0,0,300.000,300.000,17.930,0.000,4
3755556476.274400,-6750,2,299.997,0.000,41.574,3.711,0,0,300.000,300.000,17.840,0.000,4
3755556566.274400,1819,2,300.000,0.000,41.587,4.038,0,0,300.000,300.000,17.800,0.000,4
3755556656.274400,3752,3,300.001,0.000,41.576,3.641,0,0,300.000,300.000,17.820,0.000,4
3755556746.274400,-3427,3,300.003,0.000,41.585,4.077,0,0,300.000,300.000,17.780,0.000,4
3755556836.274400,2395,2,300.002,0.000,41.584,3.700,0,0,300.000,300.000,17.870,0.000,4
3755556926.274400,-1674,3,300.001,0.000,41.588,3.403,0,0,300.000,300.000,17.870,0.000,4
3755557092.566400,1176,2,299.999,0.000,41.588,3.230,0,0,300.000,300.000,17.820,0.000,4
3755557211.836400,4179,2,299.999,0.000,41.585,3.815,0,0,300.000,300.000,17.840,0.000,4
3755557296.970400,9993,2,299.998,0.000,41.571,3.798,0,0,300.000,300.000,17.780,0.000,4
3755557386.970400,4281,3,300.000,0.000,41.581,3.740,0,0,300.000,300.000,17.780,0.000,4
3755557476.970400,-4474,3,300.003,0.000,41.573,4.396,0,0,300.000,300.000,17.800,0.000,4
3755557566.970400,-5143,2,300.005,0.000,41.569,3.565,0,0,300.000,300.000,17.760,0.000,4
3755557656.970400,3481,2,300.007,0.000,41.575,4.282,0,0,300.000,300.000,17.820,0.000,4
3755557746.970400,2021,3,300.005,0.000,41.570,3.566,0,0,300.000,300.000,17.840,0.000,4
3755557836.970400,-2329,2,300.001,0.000,41.573,3.858,0,0,300.000,300.000,17.930,0.000,4
3755557926.970400,2400,2,300.000,0.000,41.577,3.516,0,0,300.000,300.000,17.840,0.000,4
3755558016.970400,-1680,3,299.998,0.000,41.581,3.318,0,0,300.000,300.000,17.890,0.000,4
3755558106.970400,540,3,299.996,0.000,41.581,3.251,0,0,300.000,300.000,17.820,0.000,4
3755558196.970400,543,2,299.991,0.000,41.581,3.243,0,0,300.000,300.000,17.760,0.000,4
3755558286.970400,-404,2,299.994,0.000,41.582,3.228,0,0,300.000,300.000,17.740,0.000,4
3755558376.970400,-191,3,299.998,0.000,41.584,3.227,0,0,300.000,300.000,17.680,0.000,4
3755558466.970400,-89,3,300.001,0.000,41.582,3.226,0,0,300.000,300.000,17.680,0.000,4
3755558556.970400,-47,1,300.005,0.000,41.580,3.227,0,0,300.000,300.000,17.700,0.000,4
3755558646.970400,0,1,300.005,0.000,41.581,3.227,0,0,300.000,300.000,17.780,0.000,4
3755558736.970400,0,1,300.002,0.000,41.582,3.226,0,0,300.000,300.000,17.820,0.000,4
3755558826.970400,0,1,299.999,0.000,41.584,3.225,0,0,300.000,300.000,17.890,0.000,4
3755558916.970400,0,1,299.998,0.000,41.585,3.225,0,0,300.000,300.000,17.890,0.000,4
3755559006.970400,0,1,299.993,0.000,41.587,3.227,0,0,300.000,300.000,17.890,0.000,4
3755559096.970400,0,1,299.995,0.000,41.589,3.226,0,0,300.000,300.000,17.870,0.000,4
3755559186.970400,0,1,299.995,0.000,41.590,3.226,0,0,300.000,300.000,17.820,0.000,4
3755559276.970400,0,1,299.998,0.000,41.592,3.226,0,0,300.000,300.000,17.800,0.000,4
3755559366.970400,0,1,299.999,0.000,41.593,3.227,0,0,300.000,300.000,17.740,0.000,4
3755559456.970400,0,1,300.003,0.000,41.593,3.226,0,0,300.000,300.000,17.760,0.000,4
3755559539.911400,0,1,300.003,0.000,41.595,3.227,0,0,300.000,300.000,17.840,0.000,4
3755559629.911400,0,1,299.999,0.000,41.594,3.226,0,0,300.000,300.000,17.820,0.000,4
3755559719.911400,0,1,300.000,0.000,41.594,3.227,0,0,300.000,300.000,17.870,0.000,4
3755559809.911400,0,1,299.999,0.000,41.594,3.226,0,0,300.000,300.000,17.870,0.000,4
3755559899.911400,0,1,299.997,0.000,41.593,3.227,0,0,300.000,300.000,17.820,0.000,4
3755559989.911400,0,1,299.997,0.000,41.594,3.225,0,0,300.000,300.000,17.820,0.000,4
3755560079.911400,0,1,300.000,0.000,41.593,3.226,0,0,300.000,300.000,17.800,0.000,4
3755560169.911400,0,1,300.000,0.000,41.592,3.224,0,0,300.000,300.000,17.840,0.000,4
3755560259.911400,0,1,300.000,0.000,41.592,3.226,0,0,300.000,300.000,17.840,0.000,4
3755560349.911400,0,1,300.000,0.000,41.595,3.225,0,0,300.000,300.000,17.840,0.000,4
3755560439.911400,0,1,300.000,0.000,41.597,3.226,0,0,300.000,300.000,17.840,0.000,4
3755560529.911400,0,1,300.000,0.000,41.599,3.226,0,0,300.000,300.000,17.840,0.000,4
3755560619.911400,0,1,300.003,0.000,41.601,3.226,0,0,300.000,300.000,17.840,0.000,4
3755560709.911400,0,1,300.000,0.000,41.602,3.226,0,0,300.000,300.000,17.870,0.000,4
3755560799.911400,0,1,299.998,0.000,41.604,3.226,0,0,300.000,300.000,17.870,0.000,4
3755560889.911400,0,1,299.998,0.000,41.605,3.226,0,0,300.000,300.000,17.870,0.000,4
3755560979.911400,0,1,299.998,0.000,41.604,3.226,0,0,300.000,300.000,17.800,0.000,4
3755561069.911400,0,1,300.000,0.000,41.604,3.227,0,0,300.000,300.000,17.840,0.000,4
3755561159.911400,0,1,300.003,0.000,41.605,3.225,0,0,300.000,300.000,17.820,0.000,4
3755561249.911400,0,1,300.001,0.000,41.605,3.226,0,0,300.000,300.000,17.840,0.000,4
3755561339.911400,0,1,300.001,0.000,41.605,3.225,0,0,300.000,300.000,17.870,0.000,4
3755561429.911400,0,1,300.002,0.000,41.605,3.227,0,0,300.000,300.000,17.840,0.000,4
3755561519.911400,0,1,299.998,0.000,41.604,3.225,0,0,300.000,300.000,17.890,0.000,4
3755561609.911400,0,1,299.999,0.000,41.605,3.225,0,0,300.000,300.000,17.930,0.000,4
3755561699.911400,0,1,299.999,0.000,41.605,3.226,0,0,300.000,300.000,17.840,0.000,4
3755561789.911400,0,1,299.998,0.000,41.605,3.225,0,0,300.000,300.000,17.870,0.000,4
3755561879.911400,0,1,299.997,0.000,41.606,3.226,0,0,300.000,300.000,17.840,0.000,4
3755561969.911400,0,1,299.998,0.000,41.608,3.226,0,0,300.000,300.000,17.870,0.000,4
3755562059.911400,0,1,299.999,0.000,41.607,3.225,0,0,300.000,300.000,17.840,0.000,4
3755562149.911400,0,1,300.002,0.000,41.609,3.226,0,0,300.000,300.000,17.800,0.000,4
3755562239.911400,0,1,300.005,0.000,41.611,3.226,0,0,300.000,300.000,17.780,0.000,4
3755562329.911400,0,1,300.003,0.000,41.610,3.225,0,0,300.000,300.000,17.910,0.000,4
3755562419.911400,0,1,300.001,0.000,41.611,3.225,0,0,300.000,300.000,17.910,0.000,4
3755562509.911400,0,1,300.001,0.000,41.613,3.225,0,0,300.000,300.000,17.910,0.000,4
3755562599.911400,0,1,299.997,0.000,41.613,3.225,0,0,300.000,300.000,17.910,0.000,4
3755562689.911400,0,1,299.995,0.000,41.615,3.225,0,0,300.000,300.000,17.890,0.000,4
3755562779.911400,0,1,299.998,0.000,41.614,3.226,0,0,300.000,300.000,17.890,0.000,4
3755562869.911400,0,1,300.000,0.000,41.615,3.228,0,0,300.000,300.000,17.820,0.000,4
3755562959.911400,0,1,300.003,0.000,41.616,3.226,0,0,300.000,300.000,17.840,0.000,4
3755563049.911400,0,1,300.006,0.000,41.616,3.226,0,0,300.000,300.000,17.820,0.000,4
3755563139.911400,0,1,300.003,0.000,41.616,3.227,0,0,300.000,300.000,17.840,0.000,4
3755563229.911400,0,1,300.001,0.000,41.616,3.226,0,0,300.000,300.000,17.950,0.000,4
3755563319.911400,0,1,299.999,0.000,41.617,3.224,0,0,300.000,300.000,17.910,0.000,4
3755563409.911400,0,1,299.997,0.000,41.616,3.225,0,0,300.000,300.000,17.930,0.000,4
3755563499.911400,0,1,299.997,0.000,41.617,3.225,0,0,300.000,300.000,17.870,0.000,4
3755563589.911400,0,1,299.998,0.000,41.617,3.226,0,0,300.000,300.000,17.930,0.000,4
3755563679.911400,0,1,300.000,0.000,41.617,3.225,0,0,300.000,300.000,17.870,0.000,4
3755563769.911400,0,1,299.998,0.000,41.617,3.226,0,0,300.000,300.000,17.890,0.000,4
3755563859.911400,0,1,300.002,0.000,41.618,3.225,0,0,300.000,300.000,17.870,0.000,4
3755563949.911400,0,1,300.001,0.000,41.622,3.225,0,0,300.000,300.000,17.890,0.000,4
3755564039.911400,0,1,300.002,0.000,41.623,3.226,0,0,300.000,300.000,17.870,0.000,4
3755564129.911400,0,1,300.002,0.000,41.625,3.225,0,0,300.000,300.000,17.870,0.000,4
3755564219.911400,0,1,300.002,0.000,41.627,3.225,0,0,300.000,300.000,17.870,0.000,4
3755564309.911400,0,1,300.001,0.000,41.628,3.226,0,0,300.000,300.000,17.870,0.000,4
3755564399.911400,0,1,300.000,0.000,41.629,3.225,0,0,300.000,300.000,17.910,0.000,4
3755564489.911400,0,1,299.999,0.000,41.628,3.225,0,0,300.000,300.000,17.840,0.000,4
3755564579.911400,0,1,299.999,0.000,41.629,3.226,0,0,300.000,300.000,17.870,0.000,4
3755564669.911400,0,1,300.001,0.000,41.631,3.226,0,0,300.000,300.000,17.840,0.000,4
3755564759.911400,0,1,299.999,0.000,41.631,3.225,0,0,300.000,300.000,17.870,0.000,4
3755564849.911400,0,1,300.000,0.000,41.632,3.225,0,0,300.000,300.000,17.910,0.000,4
3755564939.911400,0,1,300.001,0.000,41.632,3.226,0,0,300.000,300.000,17.910,0.000,4
3755565029.911400,0,1,299.999,0.000,41.632,3.225,0,0,300.000,300.000,17.910,0.000,4
3755565119.911400,0,1,299.997,0.000,41.630,3.225,0,0,300.000,300.000,17.910,0.000,4
3755565209.911400,0,1,299.998,0.000,41.631,3.225,0,0,300.000,300.000,17.910,0.000,4
3755565299.911400,0,1,299.999,0.000,41.631,3.225,0,0,300.000,300.000,17.870,0.000,4
3755565389.911400,0,1,300.001,0.000,41.630,3.226,0,0,300.000,300.000,17.870,0.000,4
3755565479.911400,0,1,300.001,0.000,41.630,3.224,0,0,300.000,300.000,17.870,0.000,4
3755565569.911400,0,1,300.002,0.000,41.630,3.225,0,0,300.000,300.000,17.870,0.000,4
3755565659.911400,0,1,300.004,0.000,41.629,3.225,0,0,300.000,300.000,17.890,0.000,4
3755565749.911400,0,1,300.001,0.000,41.628,3.225,0,0,300.000,300.000,17.930,0.000,4
3755565839.911400,0,1,300.003,0.000,41.629,3.225,0,0,300.000,300.000,17.890,0.000,4
3755565929.911400,0,1,300.001,0.000,41.630,3.226,0,0,300.000,300.000,17.910,0.000,4
3755566019.911400,0,1,300.001,0.000,41.630,3.225,0,0,300.000,300.000,17.970,0.000,4
3755566109.911400,0,1,299.998,0.000,41.630,3.225,0,0,300.000,300.000,17.970,0.000,4
3755566199.911400,0,1,299.994,0.000,41.629,3.225,0,0,300.000,300.000,17.930,0.000,4
3755566289.911400,0,1,299.996,0.000,41.632,3.225,0,0,300.000,300.000,17.930,0.000,4
3755566379.911400,0,1,299.994,0.000,41.632,3.226,0,0,300.000,300.000,17.840,0.000,4
3755566469.911400,0,1,300.000,0.000,41.633,3.225,0,0,300.000,300.000,17.820,0.000,4
3755566559.911400,0,1,300.001,0.000,41.635,3.226,0,0,300.000,300.000,17.840,0.000,4
3755566649.911400,0,1,300.002,0.000,41.635,3.225,0,0,300.000,300.000,17.840,0.000,4
3755566739.911400,0,1,300.004,0.000,41.637,3.224,0,0,300.000,300.000,17.870,0.000,4
3755566829.911400,0,1,300.002,0.000,41.637,3.224,0,0,300.000,300.000,17.890,0.000,4
3755566919.911400,0,1,300.000,0.000,41.638,3.225,0,0,300.000,300.000,17.930,0.000,4
3755567009.911400,0,1,300.000,0.000,41.639,3.225,0,0,300.000,300.000,17.910,0.000,4
3755567099.911400,0,1,299.998,0.000,41.641,3.225,0,0,300.000,300.000,17.950,0.000,4
3755567189.911400,0,1,299.999,0.000,41.643,3.226,0,0,300.000,300.000,17.910,0.000,4
3755567279.911400,0,1,299.999,0.000,41.644,3.225,0,0,300.000,300.000,17.910,0.000,4
3755567369.911400,0,1,299.998,0.000,41.644,3.226,0,0,300.000,300.000,17.930,0.000,4
3755567459.911400,0,1,299.995,0.000,41.645,3.225,0,0,300.000,300.000,17.840,0.000,4
3755567549.911400,0,1,300.001,0.000,41.645,3.226,0,0,300.000,300.000,17.800,0.000,4
3755567639.911400,0,1,300.002,0.000,41.645,3.226,0,0,300.000,300.000,17.870,0.000,4
3755567729.911400,0,1,300.003,0.000,41.644,3.226,0,0,300.000,300.000,17.890,0.000,4
3755567819.911400,0,1,300.003,0.000,41.645,3.225,0,0,300.000,300.000,17.930,0.000,4
3755567909.911400,0,1,299.998,0.000,41.645,3.226,0,0,300.000,300.000,17.930,0.000,4
3755567999.911400,0,1,299.998,0.000,41.645,3.227,0,0,300.000,300.000,17.930,0.000,4
3755568089.911400,0,1,299.999,0.000,41.646,3.227,0,0,300.000,300.000,17.910,0.000,4
3755568179.911400,0,1,300.000,0.000,41.648,3.226,0,0,300.000,300.000,17.870,0.000,4
3755568269.911400,0,1,300.000,0.000,41.648,3.225,0,0,300.000,300.000,17.890,0.000,4
3755568359.911400,0,1,300.002,0.000,41.649,3.225,0,0,300.000,300.000,17.930,0.000,4
3755568449.911400,0,1,299.999,0.000,41.648,3.225,0,0,300.000,300.000,17.890,0.000,4
3755568539.911400,0,1,299.998,0.000,41.650,3.225,0,0,300.000,300.000,17.910,0.000,4
3755568629.911400,0,1,300.000,0.000,41.651,3.225,0,0,300.000,300.000,17.910,0.000,4
3755568719.911400,0,1,300.003,0.000,41.652,3.226,0,0,300.000,300.000,17.910,0.000,4
3755568809.911400,0,1,300.001,0.000,41.653,3.226,0,0,300.000,300.000,17.930,0.000,4
3755568899.911400,0,1,299.997,0.000,41.652,3.226,0,0,300.000,300.000,17.950,0.000,4
3755568989.911400,0,1,299.998,0.000,41.652,3.226,0,0,300.000,300.000,17.910,0.000,4
3755569079.911400,0,1,299.999,0.000,41.654,3.225,0,0,300.000,300.000,17.910,0.000,4
3755569169.911400,0,1,300.001,0.000,41.654,3.226,0,0,300.000,300.000,17.870,0.000,4
3755569259.911400,0,1,300.002,0.000,41.655,3.225,0,0,300.000,300.000,17.870,0.000,4
3755569349.911400,0,1,300.003,0.000,41.656,3.225,0,0,300.000,300.000,17.910,0.000,4
3755569439.911400,0,1,299.999,0.000,41.656,3.225,0,0,300.000,300.000,17.950,0.000,4
3755569529.911400,0,1,300.000,0.000,41.655,3.225,0,0,300.000,300.000,17.970,0.000,4
3755569619.911400,0,1,299.997,0.000,41.656,3.225,0,0,300.000,300.000,17.970,0.000,4
3755569709.911400,0,1,299.998,0.000,41.655,3.227,0,0,300.000,300.000,17.930,0.000,4
3755569799.911400,0,1,300.000,0.000,41.654,3.227,0,0,300.000,300.000,17.870,0.000,4
3755569889.911400,0,1,300.000,0.000,41.654,3.226,0,0,300.000,300.000,17.820,0.000,4
3755569979.911400,0,1,300.003,0.000,41.653,3.226,0,0,300.000,300.000,17.910,0.000,4
3755570069.911400,0,1,300.004,0.000,41.653,3.225,0,0,300.000,300.000,17.840,0.000,4
3755570159.911400,0,1,300.003,0.000,41.651,3.226,0,0,300.000,300.000,17.870,0.000,4
3755570249.911400,0,1,300.002,0.000,41.651,3.224,0,0,300.000,300.000,17.910,0.000,4
3755570339.911400,0,1,300.000,0.000,41.652,3.225,0,0,300.000,300.000,17.950,0.000,4
3755570429.911400,0,1,300.000,0.000,41.654,3.226,0,0,300.000,300.000,17.970,0.000,4
3755570519.911400,0,1,299.997,0.000,41.655,3.225,0,0,300.000,300.000,17.930,0.000,4
3755570609.911400,0,1,300.000,0.000,41.656,3.224,0,0,300.000,300.000,17.870,0.000,4
3755570699.911400,0,1,299.999,0.000,41.656,3.224,0,0,300.000,300.000,17.890,0.000,4
3755570789.911400,0,1,300.000,0.000,41.656,3.225,0,0,300.000,300.000,17.890,0.000,4
3755570879.911400,0,1,300.002,0.000,41.656,3.227,0,0,300.000,300.000,17.910,0.000,4
3755570969.911400,0,1,300.002,0.000,41.656,3.227,0,0,300.000,300.000,17.910,0.000,4
3755571059.911400,0,1,300.001,0.000,41.655,3.225,0,0,300.000,300.000,17.890,0.000,4
3755571149.911400,0,1,300.000,0.000,41.655,3.225,0,0,300.000,300.000,17.970,0.000,4
3755571239.911400,0,1,299.997,0.000,41.654,3.226,0,0,300.000,300.000,17.950,0.000,4
3755571329.911400,0,1,299.996,0.000,41.654,3.226,0,0,300.000,300.000,17.910,0.000,4
3755571419.911400,0,1,299.998,0.000,41.654,3.227,0,0,300.000,300.000,17.870,0.000,4
3755571509.911400,0,1,299.998,0.000,41.654,3.226,0,0,300.000,300.000,17.890,0.000,4
3755571599.911400,0,1,300.002,0.000,41.655,3.227,0,0,300.000,300.000,17.820,0.000,4
3755571689.911400,0,1,300.004,0.000,41.656,3.225,0,0,300.000,300.000,17.840,0.000,4
3755571779.911400,0,1,300.005,0.000,41.658,3.226,0,0,300.000,300.000,17.870,0.000,4
3755571869.911400,0,1,300.003,0.000,41.658,3.226,0,0,300.000,300.000,17.870,0.000,4
3755571959.911400,0,1,300.002,0.000,41.659,3.225,0,0,300.000,300.000,17.950,0.000,4
3755572049.911400,0,1,299.999,0.000,41.658,3.226,0,0,300.000,300.000,17.970,0.000,4
3755572139.911400,0,1,299.996,0.000,41.658,3.227,0,0,300.000,300.000,17.970,0.000,4
3755572229.911400,0,1,299.995,0.000,41.658,3.224,0,0,300.000,300.000,17.890,0.000,4
3755572319.911400,0,1,299.995,0.000,41.657,3.225,0,0,300.000,300.000,17.870,0.000,4
3755572409.911400,0,1,299.999,0.000,41.656,3.225,0,0,300.000,300.000,17.870,0.000,4
3755572499.911400,0,1,300.004,0.000,41.656,3.225,0,0,300.000,300.000,17.780,0.000,4
3755572589.911400,0,1,300.006,0.000,41.657,3.225,0,0,300.000,300.000,17.820,0.000,4
3755572679.911400,0,1,300.008,0.000,41.661,3.225,0,0,300.000,300.000,17.870,0.000,4
3755572769.911400,0,1,300.007,0.000,41.662,3.225,0,0,300.000,300.000,17.970,0.000,4
3755572859.911400,0,1,300.002,0.000,41.661,3.224,0,0,300.000,300.000,17.990,0.000,4
3755572949.911400,0,1,299.998,0.000,41.661,3.226,0,0,300.000,300.000,18.030,0.000,4
3755573039.911400,0,1,299.993,0.000,41.662,3.225,0,0,300.000,300.000,17.970,0.000,4
3755573129.911400,0,1,299.995,0.000,41.661,3.225,0,0,300.000,300.000,17.950,0.000,4
3755573219.911400,0,1,299.997,0.000,41.661,3.226,0,0,300.000,300.000,17.800,0.000,4
3755573309.911400,0,1,300.001,0.000,41.660,3.225,0,0,300.000,300.000,17.800,0.000,4
3755573399.911400,0,1,300.003,0.000,41.659,3.227,0,0,300.000,300.000,17.840,0.000,4
3755573489.911400,0,1,300.007,0.000,41.660,3.225,0,0,300.000,300.000,17.800,0.000,4
3755573579.911400,0,1,300.008,0.000,41.661,3.226,0,0,300.000,300.000,17.890,0.000,4
3755573669.911400,0,1,300.003,0.000,41.663,3.225,0,0,300.000,300.000,17.930,0.000,4
3755573759.911400,0,1,300.000,0.000,41.662,3.227,0,0,300.000,300.000,17.950,0.000,4
3755573849.911400,0,1,299.996,0.000,41.665,3.225,0,0,300.000,300.000,18.010,0.000,4
3755573939.911400,0,1,299.995,0.000,41.667,3.225,0,0,300.000,300.000,17.970,0.000,4
3755574029.911400,0,1,299.995,0.000,41.668,3.226,0,0,300.000,300.000,17.930,0.000,4
3755574119.911400,0,1,299.996,0.000,41.671,3.225,0,0,300.000,300.000,17.890,0.000,4
3755574209.911400,0,1,300.000,0.000,41.672,3.225,0,0,300.000,300.000,17.890,0.000,4
3755574299.911400,0,1,300.004,0.000,41.671,3.225,0,0,300.000,300.000,17.820,0.000,4
3755574389.911400,0,1,300.007,0.000,41.672,3.226,0,0,300.000,300.000,17.840,0.000,4
3755574479.911400,0,1,300.004,0.000,41.671,3.225,0,0,300.000,300.000,17.870,0.000,4
3755574569.911400,0,1,300.002,0.000,41.671,3.225,0,0,300.000,300.000,18.010,0.000,4
3755574659.911400,0,1,299.998,0.000,41.672,3.225,0,0,300.000,300.000,17.930,0.000,4
3755574749.911400,0,1,299.997,0.000,41.672,3.226,0,0,300.000,300.000,17.890,0.000,4
3755574839.911400,0,1,299.998,0.000,41.671,3.224,0,0,300.000,300.000,17.890,0.000,4
3755574929.911400,0,1,299.998,0.000,41.670,3.225,0,0,300.000,300.000,17.890,0.000,4
3755575019.911400,0,1,300.000,0.000,41.671,3.225,0,0,300.000,300.000,17.930,0.000,4
3755575109.911400,0,1,300.000,0.000,41.671,3.224,0,0,300.000,300.000,17.890,0.000,4
3755575199.911400,0,1,300.001,0.000,41.671,3.226,0,0,300.000,300.000,17.930,0.000,4
3755575289.911400,0,1,299.998,0.000,41.672,3.226,0,0,300.000,300.000,17.910,0.000,4
3755575379.911400,0,1,299.998,0.000,41.672,3.225,0,0,300.000,300.000,17.930,0.000,4
3755575469.911400,0,1,299.996,0.000,41.673,3.226,0,0,300.000,300.000,17.910,0.000,4
3755575559.911400,0,1,299.998,0.000,41.674,3.226,0,0,300.000,300.000,17.890,0.000,4
3755575649.911400,0,1,300.000,0.000,41.674,3.224,0,0,300.000,300.000,17.870,0.000,4
3755575739.911400,0,1,300.002,0.000,41.673,3.225,0,0,300.000,300.000,17.820,0.000,4
3755575829.911400,0,1,300.002,0.000,41.673,3.226,0,0,300.000,300.000,17.910,0.000,4
3755575919.911400,0,1,300.002,0.000,41.673,3.226,0,0,300.000,300.000,17.970,0.000,4
3755576009.911400,0,1,300.001,0.000,41.673,3.225,0,0,300.000,300.000,17.970,0.000,4
3755576099.911400,0,1,299.999,0.000,41.674,3.225,0,0,300.000,300.000,17.910,0.000,4
3755576189.911400,0,1,299.997,0.000,41.675,3.226,0,0,300.000,300.000,17.970,0.000,4
3755576279.911400,0,1,299.995,0.000,41.676,3.226,0,0,300.000,300.000,17.930,0.000,4
3755576369.911400,0,1,299.996,0.000,41.676,3.225,0,0,300.000,300.000,17.870,0.000,4
3755576459.911400,0,1,299.998,0.000,41.676,3.226,0,0,300.000,300.000,17.870,0.000,4
3755576549.911400,0,1,300.000,0.000,41.676,3.226,0,0,300.000,300.000,17.800,0.000,4
3755576639.911400,0,1,300.005,0.000,41.676,3.226,0,0,300.000,300.000,17.740,0.000,4
3755576729.911400,0,1,300.004,0.000,41.676,3.226,0,0,300.000,300.000,17.890,0.000,4
3755576819.911400,0,1,300.005,0.000,41.676,3.226,0,0,300.000,300.000,17.910,0.000,4
3755576909.911400,0,1,300.000,0.000,41.676,3.226,0,0,300.000,300.000,17.970,0.000,4
3755576999.911400,0,1,299.999,0.000,41.676,3.226,0,0,300.000,300.000,17.990,0.000,4
3755577089.911400,0,1,299.997,0.000,41.675,3.225,0,0,300.000,300.000,17.950,0.000,4
3755577179.911400,0,1,299.997,0.000,41.676,3.225,0,0,300.000,300.000,17.890,0.000,4
3755577269.911400,0,1,299.999,0.000,41.676,3.224,0,0,300.000,300.000,17.890,0.000,4
3755577359.911400,0,1,300.002,0.000,41.677,3.224,0,0,300.000,300.000,17.870,0.000,4
3755577449.911400,0,1,300.002,0.000,41.676,3.225,0,0,300.000,300.000,17.820,0.000,4
3755577539.911400,0,1,300.002,0.000,41.676,3.226,0,0,300.000,300.000,17.840,0.000,4
3755577629.911400,0,1,300.003,0.000,41.676,3.227,0,0,300.000,300.000,17.870,0.000,4
3755577719.911400,0,1,300.004,0.000,41.674,3.227,0,0,300.000,300.000,17.890,0.000,4
3755577809.911400,0,1,300.001,0.000,41.675,3.227,0,0,300.000,300.000,17.930,0.000,4
3755577899.911400,0,1,299.998,0.000,41.676,3.227,0,0,300.000,300.000,17.930,0.000,4
3755577989.911400,0,1,299.997,0.000,41.676,3.228,0,0,300.000,300.000,17.930,0.000,4
3755578079.911400,0,1,299.996,0.000,41.674,3.226,0,0,300.000,300.000,17.930,0.000,4
3755578169.911400,0,1,299.999,0.000,41.673,3.228,0,0,300.000,300.000,17.910,0.000,4
3755578259.911400,0,1,299.998,0.000,41.673,3.227,0,0,300.000,300.000,17.870,0.000,4
3755578349.911400,0,1,299.999,0.000,41.672,3.228,0,0,300.000,300.000,17.870,0.000,4
3755578439.911400,0,1,300.002,0.000,41.671,3.228,0,0,300.000,300.000,17.870,0.000,4
3755578529.911400,0,1,300.004,0.000,41.671,3.228,0,0,300.000,300.000,17.870,0.000,4
3755578619.911400,0,1,300.002,0.000,41.668,3.229,0,0,300.000,300.000,17.930,0.000,4
3755578709.911400,0,1,300.000,0.000,41.666,3.228,0,0,300.000,300.000,17.950,0.000,4
3755578799.911400,0,1,299.998,0.000,41.666,3.226,0,0,300.000,300.000,17.950,0.000,4
3755578889.911400,0,1,300.000,0.000,41.664,3.227,0,0,300.000,300.000,17.990,0.000,4
3755578979.911400,0,1,299.998,0.000,41.662,3.227,0,0,300.000,300.000,17.950,0.000,4
3755579069.911400,0,1,299.996,0.000,41.660,3.227,0,0,300.000,300.000,17.890,0.000,4
3755579159.911400,0,1,300.001,0.000,41.660,3.226,0,0,300.000,300.000,17.890,0.000,4
3755579249.911400,0,1,300.000,0.000,41.657,3.226,0,0,300.000,300.000,17.910,0.000,4
3755579339.911400,0,1,300.002,0.000,41.656,3.225,0,0,300.000,300.000,17.930,0.000,4
3755579429.911400,0,1,300.001,0.000,41.655,3.225,0,0,300.000,300.000,17.950,0.000,4
3755579519.911400,0,1,299.999,0.000,41.655,3.225,0,0,300.000,300.000,17.930,0.000,4
3755579609.911400,0,1,300.000,0.000,41.654,3.225,0,0,300.000,300.000,17.950,0.000,4
3755579699.911400,0,1,299.996,0.000,41.654,3.225,0,0,300.000,300.000,17.890,0.000,4
3755579789.911400,0,1,299.995,0.000,41.654,3.226,0,0,300.000,300.000,17.950,0.000,4
3755579879.911400,0,1,299.997,0.000,41.653,3.226,0,0,300.000,300.000,17.910,0.000,4
3755579969.911400,0,1,299.998,0.000,41.651,3.226,0,0,300.000,300.000,17.840,0.000,4
3755580059.911400,0,1,300.001,0.000,41.648,3.225,0,0,300.000,300.000,17.870,0.000,4
3755580149.911400,0,1,300.003,0.000,41.646,3.226,0,0,300.000,300.000,17.870,0.000,4
3755580239.911400,0,1,300.001,0.000,41.646,3.224,0,0,300.000,300.000,17.950,0.000,4
3755580329.911400,0,1,300.001,0.000,41.645,3.224,0,0,300.000,300.000,17.970,0.000,4
3755580419.911400,0,1,299.998,0.000,41.644,3.227,0,0,300.000,300.000,17.970,0.000,4
3755580509.911400,0,1,299.996,0.000,41.644,3.226,0,0,300.000,300.000,17.970,0.000,4
3755580599.911400,0,1,299.996,0.000,41.643,3.225,0,0,300.000,300.000,17.890,0.000,4
3755580689.911400,0,1,299.999,0.000,41.643,3.224,0,0,300.000,300.000,17.870,0.000,4
3755580779.911400,0,1,300.000,0.000,41.642,3.223,0,0,300.000,300.000,17.870,0.000,4
3755580869.911400,0,1,300.004,0.000,41.641,3.224,0,0,300.000,300.000,17.840,0.000,4
3755580959.911400,0,1,300.003,0.000,41.640,3.224,0,0,300.000,300.000,17.910,0.000,4
3755581049.911400,0,1,300.001,0.000,41.638,3.225,0,0,300.000,300.000,17.950,0.000,4
3755581139.911400,0,1,299.999,0.000,41.636,3.225,0,0,300.000,300.000,17.930,0.000,4
3755581229.911400,0,1,299.997,0.000,41.635,3.224,0,0,300.000,300.000,17.970,0.000,4
3755581319.911400,0,1,299.997,0.000,41.635,3.224,0,0,300.000,300.000,17.930,0.000,4
3755581409.911400,0,1,299.995,0.000,41.633,3.225,0,0,300.000,300.000,17.870,0.000,4
3755581499.911400,0,1,299.999,0.000,41.633,3.224,0,0,300.000,300.000,17.840,0.000,4
3755581589.911400,0,1,300.000,0.000,41.633,3.224,0,0,300.000,300.000,17.840,0.000,4
3755581679.911400,0,1,300.000,0.000,41.633,3.224,0,0,300.000,300.000,17.930,0.000,4
3755581781.134400,653,2,300.000,0.000,41.635,3.226,0,0,300.000,300.000,17.870,0.000,4
3755581871.134400,1529,0,300.000,0.000,41.634,3.231,0,0,300.000,300.000,17.910,0.000,4
3755582650.529400,394,4,299.995,0.000,41.632,3.246,0,0,300.000,300.000,17.970,0.000,4
3755582758.526400,0,1,299.998,0.000,41.633,3.227,0,0,300.000,300.000,17.910,0.000,4
3755582947.768400,4396,5,300.000,0.000,41.631,3.238,0,0,300.000,300.000,17.890,0.000,4
3755583037.768400,-2873,3,300.002,0.000,41.632,4.011,0,0,300.000,300.000,17.890,0.000,4
3755583127.768400,2150,2,300.001,0.000,41.627,3.655,0,0,300.000,300.000,17.840,0.000,4
3755583217.768400,-1501,3,300.002,0.000,41.629,3.355,0,0,300.000,300.000,17.910,0.000,4
3755583307.768400,1055,2,299.999,0.000,41.630,3.249,0,0,300.000,300.000,17.800,0.000,4
3755583397.768400,220,2,299.998,0.000,41.629,3.244,0,0,300.000,300.000,17.890,0.000,4
3755583487.768400,-359,3,300.000,0.000,41.628,3.228,0,0,300.000,300.000,17.890,0.000,4
3755583577.768400,-165,3,300.000,0.000,41.628,3.226,0,0,300.000,300.000,17.820,0.000,4
3755583667.768400,-84,3,300.002,0.000,41.626,3.226,0,0,300.000,300.000,17.870,0.000,4
3755583757.768400,-39,4,300.003,0.000,41.626,3.225,0,0,300.000,300.000,17.820,0.000,4
3755583847.768400,0,1,300.005,0.000,41.625,3.225,0,0,300.000,300.000,17.820,0.000,4
3755583937.768400,0,1,300.000,0.000,41.625,3.224,0,0,300.000,300.000,17.930,0.000,4
3755584027.768400,0,1,299.999,0.000,41.625,3.224,0,0,300.000,300.000,17.970,0.000,4
3755584117.768400,0,1,299.997,0.000,41.624,3.225,0,0,300.000,300.000,17.950,0.000,4
3755584207.768400,0,1,299.997,0.000,41.624,3.224,0,0,300.000,300.000,17.950,0.000,4
3755584297.768400,0,1,300.000,0.000,41.623,3.224,0,0,300.000,300.000,17.890,0.000,4
3755584387.768400,0,1,299.998,0.000,41.620,3.226,0,0,300.000,300.000,17.890,0.000,4
3755584477.768400,0,1,299.997,0.000,41.620,3.224,0,0,300.000,300.000,17.840,0.000,4
3755584567.768400,0,1,300.000,0.000,41.620,3.224,0,0,300.000,300.000,17.930,0.000,4
3755584657.768400,0,1,300.001,0.000,41.619,3.224,0,0,300.000,300.000,17.870,0.000,4
3755584747.768400,0,1,299.999,0.000,41.618,3.225,0,0,300.000,300.000,17.870,0.000,4
3755584837.768400,0,1,300.000,0.000,41.618,3.225,0,0,300.000,300.000,17.840,0.000,4
3755584927.768400,0,1,300.000,0.000,41.618,3.225,0,0,300.000,300.000,17.820,0.000,4
3755585017.768400,0,1,300.000,0.000,41.618,3.225,0,0,300.000,300.000,17.890,0.000,4
3755585107.768400,0,1,300.000,0.000,41.618,3.225,0,0,300.000,300.000,17.910,0.000,4
3755585197.768400,0,1,299.998,0.000,41.618,3.225,0,0,300.000,300.000,17.990,0.000,4
3755585287.768400,0,1,299.996,0.000,41.620,3.225,0,0,300.000,300.000,17.950,0.000,4
3755585377.768400,0,1,299.998,0.000,41.619,3.224,0,0,300.000,300.000,17.930,0.000,4
3755585467.768400,0,1,299.995,0.000,41.619,3.225,0,0,300.000,300.000,17.930,0.000,4
3755585557.768400,0,1,299.996,0.000,41.618,3.225,0,0,300.000,300.000,17.870,0.000,4
3755585647.768400,0,1,299.999,0.000,41.617,3.224,0,0,300.000,300.000,17.820,0.000,4
3755585737.768400,0,1,300.000,0.000,41.618,3.226,0,0,300.000,300.000,17.820,0.000,4
3755585827.768400,0,1,300.002,0.000,41.618,3.225,0,0,300.000,300.000,17.820,0.000,4
3755585917.768400,0,1,300.004,0.000,41.619,3.225,0,0,300.000,300.000,17.780,0.000,4
3755586007.768400,0,1,300.004,0.000,41.621,3.224,0,0,300.000,300.000,17.840,0.000,4
3755586097.768400,0,1,300.006,0.000,41.623,3.224,0,0,300.000,300.000,17.840,0.000,4
3755586187.768400,0,1,300.002,0.000,41.624,3.225,0,0,300.000,300.000,17.890,0.000,4
3755586277.768400,0,1,300.002,0.000,41.624,3.225,0,0,300.000,300.000,17.950,0.000,4
3755586367.768400,0,1,299.997,0.000,41.626,3.225,0,0,300.000,300.000,17.970,0.000,4
3755586457.768400,0,1,299.995,0.000,41.628,3.226,0,0,300.000,300.000,17.990,0.000,4
3755586547.768400,0,1,299.996,0.000,41.630,3.226,0,0,300.000,300.000,17.950,0.000,4
3755586637.768400,0,1,299.994,0.000,41.631,3.227,0,0,300.000,300.000,17.890,0.000,4
3755586727.768400,0,1,299.999,0.000,41.632,3.227,0,0,300.000,300.000,17.800,0.000,4
3755586817.768400,0,1,300.002,0.000,41.632,3.226,0,0,300.000,300.000,17.760,0.000,4
3755586907.768400,0,1,300.005,0.000,41.633,3.225,0,0,300.000,300.000,17.870,0.000,4
3755586997.768400,0,1,300.005,0.000,41.632,3.226,0,0,300.000,300.000,17.890,0.000,4
3755587087.768400,0,1,300.003,0.000,41.634,3.226,0,0,300.000,300.000,17.930,0.000,4
3755587177.768400,0,1,300.004,0.000,41.635,3.226,0,0,300.000,300.000,17.950,0.000,4
3755587267.768400,0,1,299.998,0.000,41.637,3.226,0,0,300.000,300.000,17.950,0.000,4
3755587357.768400,0,1,299.995,0.000,41.638,3.226,0,0,300.000,300.000,17.950,0.000,4
3755587447.768400,0,1,299.995,0.000,41.640,3.226,0,0,300.000,300.000,17.930,0.000,4
3755587537.768400,0,1,299.994,0.000,41.641,3.225,0,0,300.000,300.000,17.840,0.000,4
3755587627.768400,0,1,299.997,0.000,41.642,3.225,0,0,300.000,300.000,17.870,0.000,4
3755587717.768400,0,1,300.002,0.000,41.641,3.225,0,0,300.000,300.000,17.740,0.000,4
3755587807.768400,0,1,300.002,0.000,41.641,3.226,0,0,300.000,300.000,17.840,0.000,4
3755587897.768400,0,1,300.001,0.000,41.641,3.227,0,0,300.000,300.000,17.910,0.000,4
3755587987.768400,0,1,300.000,0.000,41.642,3.227,0,0,300.000,300.000,17.950,0.000,4
3755588077.768400,0,1,299.998,0.000,41.643,3.225,0,0,300.000,300.000,17.930,0.000,4
3755588167.768400,0,1,299.998,0.000,41.644,3.226,0,0,300.000,300.000,17.930,0.000,4
3755588257.768400,0,1,299.997,0.000,41.645,3.227,0,0,300.000,300.000,17.890,0.000,4
3755588347.768400,0,1,299.999,0.000,41.647,3.226,0,0,300.000,300.000,17.890,0.000,4
3755588437.768400,0,1,299.998,0.000,41.647,3.225,0,0,300.000,300.000,17.890,0.000,4
3755588527.768400,0,1,300.000,0.000,41.647,3.226,0,0,300.000,300.000,17.800,0.000,4
3755588617.768400,0,1,300.001,0.000,41.649,3.226,0,0,300.000,300.000,17.840,0.000,4
3755588707.768400,0,1,300.003,0.000,41.650,3.226,0,0,300.000,300.000,17.840,0.000,4
3755588797.768400,0,1,300.003,0.000,41.650,3.226,0,0,300.000,300.000,17.930,0.000,4
3755588887.768400,0,1,300.003,0.000,41.652,3.225,0,0,300.000,300.000,17.910,0.000,4
3755588977.768400,0,1,300.001,0.000,41.654,3.225,0,0,300.000,300.000,17.970,0.000,4
3755589067.768400,0,1,299.997,0.000,41.657,3.226,0,0,300.000,300.000,17.970,0.000,4
3755589157.768400,0,1,299.998,0.000,41.658,3.225,0,0,300.000,300.000,17.930,0.000,4
3755589247.768400,0,1,299.999,0.000,41.660,3.225,0,0,300.000,300.000,17.870,0.000,4
3755589413.142400,0,1,300.002,0.000,41.661,3.225,0,0,300.000,300.000,17.870,0.000,4
3755589503.142400,0,1,300.002,0.000,41.662,3.226,0,0,300.000,300.000,17.870,0.000,4
3755589593.142400,0,1,300.000,0.000,41.663,3.226,0,0,300.000,300.000,17.820,0.000,4
3755589683.142400,0,1,300.002,0.000,41.664,3.225,0,0,300.000,300.000,17.970,0.000,4
3755589773.142400,0,1,299.999,0.000,41.666,3.226,0,0,300.000,300.000,17.970,0.000,4
3755589863.142400,0,1,299.999,0.000,41.668,3.224,0,0,300.000,300.000,17.930,0.000,4
3755589953.142400,0,1,299.999,0.000,41.667,3.224,0,0,300.000,300.000,17.890,0.000,4
3755590043.142400,0,1,300.000,0.000,41.668,3.226,0,0,300.000,300.000,17.890,0.000,4
3755590133.142400,0,1,299.999,0.000,41.667,3.225,0,0,300.000,300.000,17.890,0.000,4
3755590223.142400,0,1,299.998,0.000,41.665,3.226,0,0,300.000,300.000,17.890,0.000,4
3755600787.307400,0,4,299.969,299.996,42.793,3.228,0,0,300.000,300.000,17.320,7.530,4
3755600869.713400,0,1,299.926,300.001,42.908,3.227,0,0,300.000,300.000,16.470,7.640,1
3755600959.713400,0,1,299.945,299.999,43.003,3.228,0,0,300.000,300.000,15.810,7.570,1
3755601049.713400,0,1,299.982,300.001,43.068,3.229,0,0,300.000,300.000,15.260,7.640,1
3755601139.713400,0,1,300.019,299.998,43.112,3.230,0,0,300.000,300.000,15.140,7.830,1
3755601229.713400,0,1,300.050,299.991,43.138,3.228,0,0,300.000,300.000,15.340,7.760,1
3755601319.713400,0,1,300.060,299.990,43.151,3.229,0,0,300.000,300.000,15.790,7.770,1
3755601409.713400,0,1,300.043,300.005,43.157,3.229,0,0,300.000,300.000,16.430,7.850,1
3755601499.713400,0,1,300.069,299.822,43.154,3.230,0,0,300.000,300.000,15.400,9.080,4
3755601589.713400,0,1,300.050,299.994,43.148,3.228,0,0,300.000,300.000,15.750,10.610,1
3755601679.713400,0,1,299.998,300.001,43.137,3.230,0,0,300.000,300.000,16.010,10.590,1
3755601769.713400,0,1,299.956,299.998,43.120,3.228,0,0,300.000,300.000,15.930,10.590,1
3755601859.713400,0,1,299.934,299.997,43.099,3.228,0,0,300.000,300.000,15.400,10.560,1
3755601949.713400,0,1,299.942,300.000,43.073,3.229,0,0,300.000,300.000,14.740,10.540,1
3755602039.713400,0,1,299.971,299.999,43.045,3.229,0,0,300.000,300.000,14.120,10.540,1
3755602129.713400,0,1,300.007,299.999,43.017,3.229,0,0,300.000,300.000,13.920,10.510,1
3755602219.713400,0,1,300.035,300.000,42.988,3.230,0,0,300.000,300.000,13.930,10.510,1
3755602309.713400,0,1,300.047,299.999,42.959,3.231,0,0,300.000,300.000,14.310,10.510,1
3755602399.713400,0,1,300.039,299.997,42.935,3.855,0,0,300.000,300.000,14.800,10.510,1
3755602489.713400,0,1,298.424,297.871,43.837,4.366,1,1,2.000,2.000,0.000,0.280,3
3755602579.713400,0,1,293.940,293.650,45.323,4.408,1,1,2.000,2.000,0.000,0.000,3
3755602669.713400,0,1,289.729,289.856,46.668,4.427,1,1,2.000,2.000,0.000,0.000,3
3755602759.713400,0,1,285.533,286.012,47.809,4.441,1,1,2.000,2.000,0.000,0.000,3
3755602849.713400,0,1,281.406,282.182,48.767,4.455,1,1,2.000,2.000,0.000,0.000,3
3755602939.713400,0,1,277.306,278.339,49.590,4.469,1,1,2.000,2.000,0.000,0.000,3
3755603029.713400,0,1,273.241,274.509,50.307,4.482,1,1,2.000,2.000,0.000,0.000,3
3755603119.713400,0,1,269.173,270.660,50.950,4.494,1,1,2.000,2.000,0.000,0.000,3
3755603209.713400,0,1,265.126,266.804,51.532,4.511,1,1,2.000,2.000,0.000,0.000,3
3755603299.713400,0,1,261.228,262.959,52.061,4.526,1,1,2.000,2.000,0.000,0.000,3
3755603389.713400,0,1,257.226,259.132,52.548,4.538,1,1,2.000,2.000,0.000,0.000,3
3755603479.713400,0,1,253.273,255.311,52.998,4.550,1,1,2.000,2.000,0.000,0.000,3
3755603569.713400,0,1,249.417,251.575,53.412,4.565,1,1,2.000,2.000,0.000,0.000,3
3755603659.713400,0,1,245.541,247.808,53.803,4.577,1,1,2.000,2.000,0.000,0.000,3
3755603749.713400,0,1,241.711,244.060,54.170,4.589,1,1,2.000,2.000,0.000,0.000,3
3755603839.713400,0,1,237.971,240.382,54.510,4.601,1,1,2.000,2.000,0.000,0.000,3
3755603929.713400,0,1,234.247,236.712,54.830,4.614,1,1,2.000,2.000,0.000,0.000,3
3755604019.713400,0,1,230.567,233.107,55.130,4.624,1,1,2.000,2.000,0.000,0.000,3
3755604109.713400,0,1,226.939,229.565,55.409,4.634,1,1,2.000,2.000,0.000,0.000,3
3755604199.713400,0,1,223.363,226.080,55.672,4.643,1,1,2.000,2.000,0.000,0.000,3
3755604289.713400,0,1,219.840,222.663,55.918,4.653,1,1,2.000,2.000,0.000,0.000,3
3755604379.713400,0,1,216.367,219.274,56.147,4.664,1,1,2.000,2.000,0.000,0.000,3
3755604469.713400,0,1,212.941,215.945,56.362,4.670,1,1,2.000,2.000,0.000,0.000,3
3755604559.713400,0,1,209.558,212.662,56.564,4.679,1,1,2.000,2.000,0.000,0.000,3
3755604649.713400,0,1,206.221,209.425,56.752,4.690,1,1,2.000,2.000,0.000,0.000,3
3755604739.713400,0,1,202.929,206.225,56.928,4.698,1,1,2.000,2.000,0.000,0.000,3
3755604829.713400,0,1,199.686,203.064,57.093,4.708,1,1,2.000,2.000,0.000,0.000,3
3755604919.713400,0,1,196.486,199.942,57.246,4.715,1,1,2.000,2.000,0.000,0.000,3
3755605009.713400,0,1,193.326,196.859,57.388,4.721,1,1,2.000,2.000,0.000,0.000,3
3755605099.713400,0,1,190.210,193.811,57.521,4.727,1,1,2.000,2.000,0.000,0.000,3
3755605189.713400,0,1,187.135,190.749,57.644,4.730,1,1,2.000,2.000,0.000,0.000,3
3755605279.713400,0,1,184.095,187.738,57.759,4.735,1,1,2.000,2.000,0.000,0.000,3
3755605369.713400,0,1,181.094,184.760,57.866,4.739,1,1,2.000,2.000,0.000,0.000,3
3755606002.323400,0,1,161.013,164.660,58.407,4.770,1,1,2.000,2.000,0.000,0.000,3
3755606092.323400,0,1,158.292,161.945,58.458,4.771,1,1,300.000,300.000,0.000,0.000,3
3755606182.323400,0,1,155.599,159.236,58.503,4.774,1,1,300.000,300.000,0.000,0.000,3
3755606212.323400,0,1,154.706,158.346,58.516,4.775,1,1,300.000,300.000,0.000,0.000,3