File: log/20230105.dat
[Header]
; Displex Transport Data File (default extension .dat)
; Copyright 2016, Hechang LEI, hlei@ruc.edu.cn. All rights reserved.
BYAPP, Displex, 2.0
INFO, 9T mag, Release 2.0.
INFO, Channel 1, Temperature Sensor
INFO, Sample 1 Length (cm): 0.000000; Width (cm): 0.000000; Thickness (cm): 0.000000.

[Data]
Timestamp(s),Field(Oe),Field Status,TempA(K),TempB(K),TempC(K),TempD(K),Ramp1,Ramp2,Setpoint1,Setpoint2,Output1(%),Output2(%),Temp Status
3755727794.311400,0,1,2.021,2.000,35.136,3.038,0,0,2.000,2.000,0.010,0.010,1
3755727944.311400,0,4,2.012,2.000,35.138,3.039,0,0,2.000,2.000,0.200,0.010,1
3755728094.311400,2448,2,2.012,2.000,35.138,3.112,0,0,2.000,2.000,0.170,0.010,1
3755728244.311400,5432,2,2.015,2.000,35.138,3.336,0,0,2.000,2.000,0.140,0.010,1
3755728394.311400,8410,2,2.022,2.000,35.146,3.316,0,0,2.000,2.000,0.000,0.010,1
3755728544.311400,11403,2,2.022,2.000,35.152,3.271,0,0,2.000,2.000,0.160,0.010,1
3755728694.311400,14407,2,2.022,2.000,35.159,3.246,0,0,2.000,2.000,0.160,0.010,1
3755728844.311400,17401,2,2.024,2.000,35.164,3.228,0,0,2.000,2.000,0.000,0.010,1
3755728994.311400,20001,2,2.009,2.000,35.171,3.145,0,0,2.000,2.000,0.210,0.010,1
3755729144.311400,20000,1,2.018,2.000,35.176,3.038,0,0,2.000,2.000,0.000,0.010,1
3755729294.311400,20000,1,2.010,2.000,35.175,3.039,0,0,2.000,2.000,0.210,0.010,1
3755729444.311400,20000,1,2.015,2.000,35.175,3.037,0,0,2.000,2.000,0.000,0.010,1
3755729594.311400,20000,1,2.009,2.000,35.174,3.041,0,0,2.000,2.000,0.160,0.010,1
3755729744.311400,20000,1,2.011,2.000,35.176,3.042,0,0,2.000,2.000,0.130,0.010,1
3755729894.311400,20000,1,2.022,2.000,35.178,3.040,0,0,2.000,2.000,0.000,0.010,1
3755730044.311400,20000,1,2.018,2.000,35.179,3.040,0,0,2.000,2.000,0.020,0.010,1
3755730194.311400,20000,1,2.009,2.000,35.181,3.039,0,0,2.000,2.000,0.210,0.010,1
3755730344.311400,20000,1,2.019,2.000,35.182,3.040,0,0,2.000,2.000,0.000,0.010,1
3755730494.311400,20000,1,2.018,2.000,35.183,3.039,0,0,2.000,2.000,0.000,0.010,1
3755730644.311400,20000,1,2.010,2.000,35.184,3.038,0,0,2.000,2.000,0.200,0.010,1
3755730796.523400,20000,1,2.006,2.000,35.185,3.038,0,0,2.000,2.000,0.210,0.010,1
3755730946.523400,20000,1,2.005,2.000,35.186,3.039,0,0,2.000,2.000,0.210,0.010,1
3755731096.523400,22557,2,2.007,2.000,35.185,3.205,0,0,2.000,2.000,0.170,0.010,1
3755731246.523400,25550,2,2.021,2.000,35.191,3.197,0,0,2.000,2.000,0.000,0.010,1
3755731396.523400,28555,2,2.008,2.000,35.198,3.188,0,0,2.000,2.000,0.130,0.010,1
3755731546.523400,31550,2,2.020,2.000,35.207,3.181,0,0,2.000,2.000,0.000,0.000,1
3755731696.523400,34546,2,2.016,2.000,35.216,3.176,0,0,2.000,2.000,0.000,0.000,1
3755731846.523400,37544,2,2.013,2.000,35.226,3.171,0,0,2.000,2.000,0.100,0.000,1
3755731996.523400,40529,2,2.004,2.000,35.240,3.167,0,0,2.000,2.000,0.180,0.000,1
3755732146.523400,43548,2,1.999,2.000,35.256,3.163,0,0,2.000,2.000,0.200,0.000,1
3755732296.523400,46547,2,2.003,2.000,35.274,3.159,0,0,2.000,2.000,0.160,0.000,1
3755732446.523400,49545,2,2.006,2.000,35.292,3.155,0,0,2.000,2.000,0.050,0.000,1
3755732596.523400,48734,3,2.010,2.000,35.312,3.059,0,0,2.000,2.000,0.000,0.000,1
3755732746.523400,45746,3,2.007,2.000,35.321,3.146,0,0,2.000,2.000,0.020,0.000,1
3755732896.523400,42757,3,2.000,2.000,35.324,3.157,0,0,2.000,2.000,0.210,0.000,1
3755733046.523400,39753,3,2.012,2.000,35.319,3.162,0,0,2.000,2.000,0.000,0.000,1
3755733196.523400,36746,3,2.008,2.000,35.312,3.166,0,0,2.000,2.000,0.030,0.000,1
3755733346.523400,33750,3,2.006,2.000,35.304,3.170,0,0,2.000,2.000,0.200,0.000,1
3755733496.523400,30744,3,2.010,2.000,35.295,3.177,0,0,2.000,2.000,0.200,0.000,1
3755733646.524000,27759,3,2.012,2.000,35.285,3.183,0,0,2.000,2.000,0.090,0.010,1
3755733796.524000,24763,3,2.013,2.000,35.274,3.187,0,0,2.000,2.000,0.140,0.010,1
3755733946.524000,21756,3,2.012,2.000,35.263,3.198,0,0,2.000,2.000,0.210,0.010,1
3755734096.524000,18759,3,2.021,2.000,35.257,3.209,0,0,2.000,2.000,0.130,0.010,1
3755734246.524000,15750,3,2.022,2.000,35.250,3.222,0,0,2.000,2.000,0.080,0.010,1
3755734396.524000,12775,3,2.022,2.000,35.242,3.236,0,0,2.000,2.000,0.000,0.010,1
3755734546.524000,9770,3,2.027,2.000,35.237,3.250,0,0,2.000,2.000,0.000,0.010,1
3755734696.524000,6766,3,2.025,2.000,35.232,3.270,0,0,2.000,2.000,0.000,0.010,1
3755734846.524000,3777,3,2.023,2.000,35.228,3.293,0,0,2.000,2.000,0.120,0.010,1
3755734996.524000,790,3,2.024,2.000,35.225,3.316,0,0,2.000,2.000,0.120,0.010,1
3755735146.524000,-2073,3,2.022,1.999,35.224,3.485,0,0,2.000,2.000,0.010,0.010,1
3755735296.524000,-5034,3,2.033,2.000,35.222,3.447,0,0,2.000,2.000,0.070,0.010,1
3755735446.524000,-8034,3,2.017,2.000,35.226,3.341,0,0,2.000,2.000,0.110,0.010,1
3755735596.524000,-11027,3,2.028,2.000,35.224,3.288,0,0,2.000,2.000,0.000,0.010,1
3755735746.524000,-14030,3,2.023,2.000,35.224,3.260,0,0,2.000,2.000,0.000,0.010,1
3755735896.524000,-17025,3,2.014,2.000,35.226,3.239,0,0,2.000,2.000,0.100,0.010,1
3755736046.524000,-20031,3,2.019,2.000,35.227,3.226,0,0,2.000,2.000,0.050,0.010,1
3755736196.524000,-23015,3,2.009,2.000,35.231,3.213,0,0,2.000,2.000,0.200,0.010,1
3755736346.524000,-26009,3,2.007,2.000,35.237,3.203,0,0,2.000,2.000,0.120,0.010,1
3755736496.524000,-29013,3,2.009,2.000,35.243,3.194,0,0,2.000,2.000,0.210,0.010,1
3755736646.524000,-32018,3,2.004,2.001,35.249,3.190,0,0,2.000,2.000,0.130,0.000,1
3755736796.524000,-35013,3,2.018,2.000,35.259,3.182,0,0,2.000,2.000,0.000,0.000,1
3755736946.524000,-37998,3,2.008,2.000,35.271,3.179,0,0,2.000,2.000,0.130,0.000,1
3755737096.524000,-41002,3,2.006,2.000,35.284,3.174,0,0,2.000,2.000,0.130,0.000,1
3755737246.524000,-43998,3,2.013,2.000,35.298,3.169,0,0,2.000,2.000,0.000,0.000,1
3755737396.524000,-47005,3,2.001,2.000,35.313,3.167,0,0,2.000,2.000,0.200,0.000,1
3755737546.524000,-49934,3,2.002,2.000,35.331,3.161,0,0,2.000,2.000,0.050,0.000,1
3755737696.524000,-40672,2,9.453,9.441,35.344,3.522,1,1,300.000,300.000,0.550,0.720,2
3755737846.524000,-25797,2,34.035,34.020,35.320,3.655,1,1,300.000,300.000,8.290,5.930,2
3755737996.524000,-10767,2,58.880,58.865,35.306,3.789,1,1,300.000,300.000,24.640,16.420,2
3755738146.524000,4068,2,83.717,83.714,35.308,4.301,1,1,300.000,300.000,39.870,26.510,2
3755738296.524000,19048,2,108.576,108.548,35.351,3.829,1,1,300.000,300.000,52.060,35.390,2
3755738446.524000,34081,2,133.444,133.426,35.418,3.665,1,1,300.000,300.000,62.020,42.840,2
3755738596.524000,25906,3,158.089,158.004,35.502,3.609,1,1,300.000,300.000,70.620,50.000,2
3755738746.524000,10927,3,182.899,182.833,35.572,3.791,1,1,300.000,300.000,77.370,56.690,2
3755738896.524000,-3910,3,207.731,207.703,35.649,4.299,1,1,300.000,300.000,83.330,62.940,2
3755739046.524000,-18893,3,232.456,232.510,35.748,3.834,1,1,300.000,300.000,90.930,68.020,2
3755739196.524000,-19919,2,255.300,257.172,35.862,3.461,1,1,300.000,300.000,86.020,77.200,2
3755739346.524000,-5055,2,275.582,281.942,35.946,3.881,1,1,300.000,300.000,85.890,79.310,2
3755739496.524000,9787,2,294.257,300.554,36.041,4.114,0,0,300.000,300.000,89.230,50.990,4
3755739646.524000,14286,3,300.033,300.062,36.165,3.310,0,0,300.000,300.000,85.890,42.260,4
3755739796.524000,-492,3,300.031,300.037,36.237,3.992,0,0,300.000,300.000,14.190,38.900,4
3755739946.524000,-12002,3,300.116,300.033,36.319,3.596,0,0,300.000,300.000,73.920,36.510,4
3755740096.524000,1454,2,299.710,300.022,36.408,4.015,0,0,300.000,300.000,16.770,34.470,4
3755740246.524000,5229,3,300.382,300.007,36.497,3.380,0,0,300.000,300.000,63.590,32.880,1
3755740396.524000,-5882,3,299.628,300.026,36.573,3.757,0,0,300.000,300.000,18.560,31.000,4
3755740546.524000,4117,2,300.445,300.017,36.667,3.755,0,0,300.000,300.000,55.810,29.860,4
3755740696.524000,-730,2,299.509,300.034,36.763,3.274,0,0,300.000,300.000,20.760,28.300,4
3755740846.524000,2018,1,300.502,300.012,36.852,3.074,0,0,300.000,300.000,49.090,27.450,1
3755740996.524000,2018,1,299.529,300.027,36.931,3.065,0,0,300.000,300.000,21.750,26.320,4
3755741146.524000,2018,1,300.470,300.001,37.012,3.067,0,0,300.000,300.000,44.110,25.480,1
3755741296.524000,2018,1,299.513,300.015,37.098,3.069,0,0,300.000,300.000,23.160,24.620,1
3755741446.524000,2018,1,300.472,299.994,37.185,3.069,0,0,300.000,300.000,39.460,23.960,1
3755741596.524000,2018,1,299.561,300.009,37.272,3.071,0,0,300.000,300.000,23.230,23.130,1
3755741746.524000,2018,1,300.415,300.012,37.358,3.071,0,0,300.000,300.000,36.280,22.380,1
3755741896.524000,2018,1,299.588,300.009,37.445,3.069,0,0,300.000,300.000,23.710,21.870,1
3755742046.524000,2018,1,300.392,300.002,37.526,3.072,0,0,300.000,300.000,33.100,21.220,1
3755742196.524000,2018,1,299.649,300.010,37.606,3.072,0,0,300.000,300.000,23.380,20.700,1
3755742346.524000,2018,1,300.330,300.002,37.686,3.070,0,0,300.000,300.000,30.960,20.120,1
3755742496.524000,2018,1,299.701,299.998,37.765,3.073,0,0,300.000,300.000,23.040,19.860,1
3755742646.524000,2018,1,300.301,300.003,37.843,3.075,0,0,300.000,300.000,29.010,19.330,1
3755742796.524000,2018,1,299.733,300.006,37.920,3.076,0,0,300.000,300.000,22.870,18.840,1
3755742946.524000,2018,1,300.246,300.010,37.996,3.079,0,0,300.000,300.000,27.500,18.660,1
3755743096.524000,2018,1,299.778,300.004,38.071,3.080,0,0,300.000,300.000,22.280,18.190,1
3755743246.524000,2018,1,300.225,299.999,38.147,3.078,0,0,300.000,300.000,26.010,17.920,1
3755743396.524000,2018,1,299.802,300.009,38.218,3.076,0,0,300.000,300.000,22.070,17.790,1
3755743546.524000,2018,1,300.185,300.002,38.288,3.079,0,0,300.000,300.000,24.810,17.530,1
3755743696.524000,-170,4,299.828,300.005,38.357,3.158,0,0,300.000,300.000,21.610,17.170,1
3755743846.524000,0,1,300.158,300.002,38.423,3.084,0,0,300.000,300.000,23.690,16.870,1
3755743996.524000,0,1,299.850,300.003,38.489,3.085,0,0,300.000,300.000,21.330,16.510,1
3755744146.524000,0,1,300.140,300.004,38.552,3.086,0,0,300.000,300.000,22.730,16.230,1
3755744296.524000,0,1,299.875,300.004,38.616,3.085,0,0,300.000,300.000,20.790,15.900,1
3755744446.524000,0,1,300.115,300.001,38.680,3.086,0,0,300.000,300.000,21.860,15.670,1
3755744596.524000,0,1,299.894,300.002,38.740,3.087,0,0,300.000,300.000,20.360,15.430,1
3755744746.524000,0,1,300.099,300.003,38.797,3.087,0,0,300.000,300.000,21.110,15.170,1
3755744896.524000,0,1,299.913,300.003,38.854,3.088,0,0,300.000,300.000,19.800,14.920,1
3755745046.524000,0,1,300.082,300.003,38.910,3.090,0,0,300.000,300.000,20.520,14.690,1
3755745196.524000,0,1,299.925,300.002,38.965,3.091,0,0,300.000,300.000,19.450,14.450,1
3755745346.524000,0,1,300.069,300.002,39.020,3.090,0,0,300.000,300.000,19.960,14.250,1
3755745496.524000,0,1,299.940,300.002,39.074,3.090,0,0,300.000,300.000,18.910,14.020,1
3755745646.524000,0,1,300.056,300.001,39.122,3.092,0,0,300.000,300.000,19.500,13.840,1
3755745796.524000,0,1,299.949,300.003,39.173,3.091,0,0,300.000,300.000,18.500,13.670,1
3755745946.524000,0,1,300.051,300.002,39.223,3.094,0,0,300.000,300.000,18.910,13.480,1
3755746096.524000,0,1,299.957,300.002,39.270,3.094,0,0,300.000,300.000,18.180,13.290,1
3755746246.524000,0,1,300.038,300.001,39.315,3.097,0,0,300.000,300.000,18.480,13.180,1
3755746396.524000,0,1,299.965,300.003,39.364,3.096,0,0,300.000,300.000,17.780,13.030,1
3755746546.524000,0,1,300.035,300.000,39.410,3.096,0,0,300.000,300.000,18.120,12.860,1
3755746696.524000,0,1,299.971,300.000,39.453,3.097,0,0,300.000,300.000,17.470,12.750,1
3755746846.524000,0,1,300.028,300.000,39.495,3.097,0,0,300.000,300.000,17.760,12.600,1
3755746996.524000,0,1,299.977,300.000,39.537,3.097,0,0,300.000,300.000,17.160,12.470,1
3755747146.524000,0,1,300.021,300.002,39.577,3.097,0,0,300.000,300.000,17.470,12.330,1
3755747296.524000,0,1,299.981,300.002,39.616,3.099,0,0,300.000,300.000,16.890,12.200,1
3755747446.524000,0,1,300.019,300.002,39.655,3.100,0,0,300.000,300.000,17.120,12.140,1
3755747596.524000,0,1,299.984,300.001,39.694,3.100,0,0,300.000,300.000,16.650,12.020,1
3755747746.524000,0,1,300.016,300.000,39.733,3.100,0,0,300.000,300.000,16.830,11.950,1
3755747896.524000,0,1,299.986,299.999,39.771,3.100,0,0,300.000,300.000,16.430,11.820,1
3755748046.524000,0,1,300.016,300.000,39.808,3.101,0,0,300.000,300.000,16.630,11.730,1
3755748196.524000,0,1,299.988,300.002,39.843,3.102,0,0,300.000,300.000,16.190,11.680,1
3755748346.524000,0,1,300.014,300.004,39.882,3.103,0,0,300.000,300.000,16.310,11.570,1
3755748496.524000,0,1,299.993,300.001,39.916,3.103,0,0,300.000,300.000,16.010,11.490,1
3755748646.524000,0,1,300.008,300.004,39.949,3.107,0,0,300.000,300.000,16.110,11.430,1
3755748796.524000,0,1,299.997,300.003,39.982,3.106,0,0,300.000,300.000,15.750,11.330,1
3755748946.524000,0,1,300.002,300.000,40.015,3.106,0,0,300.000,300.000,15.950,11.280,1
3755749096.524000,0,1,299.997,300.002,40.047,3.107,0,0,300.000,300.000,15.570,11.190,1
3755749246.524000,0,1,300.000,300.000,40.076,3.107,0,0,300.000,300.000,15.730,11.140,1
3755749396.524000,0,1,300.002,300.001,40.102,3.107,0,0,300.000,300.000,15.440,11.070,1
3755749546.524000,0,1,300.001,300.000,40.129,3.108,0,0,300.000,300.000,15.550,11.000,1
3755749696.524000,0,1,299.999,299.998,40.157,3.109,0,0,300.000,300.000,15.300,10.930,1
3755749846.524000,0,1,299.986,299.996,40.184,3.109,0,0,300.000,300.000,15.340,10.900,1
3755749996.524000,0,1,300.016,300.001,40.210,3.108,0,0,300.000,300.000,15.200,10.810,1
3755750146.524000,0,1,299.985,300.000,40.231,3.109,0,0,300.000,300.000,15.160,10.760,1
3755754427.885400,0,4,299.998,300.000,40.717,3.117,0,0,300.000,300.000,13.680,9.750,4
3755754577.885400,0,1,300.002,300.000,40.729,3.115,0,0,300.000,300.000,13.790,9.750,1
3755754727.885400,0,1,299.999,300.002,40.742,3.117,0,0,300.000,300.000,13.690,9.750,1
3755754877.885400,0,1,299.998,300.001,40.755,3.118,0,0,300.000,300.000,13.690,9.680,1
3755755027.885400,0,1,299.998,299.999,40.769,3.118,0,0,300.000,300.000,13.620,9.670,1
3755755177.885400,0,1,300.002,300.001,40.781,3.119,0,0,300.000,300.000,13.710,9.640,1
3755755327.885400,0,1,300.000,299.999,40.794,3.118,0,0,300.000,300.000,13.510,9.600,1
3755755477.885400,0,1,299.999,299.999,40.804,3.118,0,0,300.000,300.000,13.660,9.620,1
3755755627.885400,0,1,300.000,299.998,40.814,3.118,0,0,300.000,300.000,13.440,9.600,1
3755755777.885400,0,1,300.000,300.002,40.825,3.119,0,0,300.000,300.000,13.680,9.590,1
3755755927.885400,0,1,300.001,299.998,40.835,3.120,0,0,300.000,300.000,13.420,9.570,1
3755756077.885400,0,1,299.999,299.999,40.846,3.119,0,0,300.000,300.000,13.600,9.540,1
3755756227.885400,0,1,300.001,300.002,40.860,3.119,0,0,300.000,300.000,13.420,9.560,1
3755756377.885400,0,1,300.001,300.002,40.871,3.119,0,0,300.000,300.000,13.550,9.540,1
3755756527.885400,0,1,300.001,300.000,40.882,3.120,0,0,300.000,300.000,13.350,9.490,1
3755756677.885400,0,1,299.998,300.001,40.893,3.120,0,0,300.000,300.000,13.490,9.480,1
3755756827.885400,0,1,300.003,300.000,40.904,3.119,0,0,300.000,300.000,13.310,9.480,1
3755756977.885400,0,1,299.997,300.000,40.915,3.120,0,0,300.000,300.000,13.510,9.480,1
3755757127.885400,0,1,300.001,300.000,40.927,3.119,0,0,300.000,300.000,13.310,9.480,1
3755757277.885400,0,1,300.000,300.000,40.936,3.119,0,0,300.000,300.000,13.400,9.440,1
3755757427.885400,0,1,299.999,300.001,40.945,3.120,0,0,300.000,300.000,13.330,9.380,1
3755757577.885400,0,1,300.002,300.001,40.953,3.120,0,0,300.000,300.000,13.310,9.410,1
3755757727.885400,0,1,299.996,300.000,40.961,3.119,0,0,300.000,300.000,13.330,9.430,1
3755757877.885400,0,1,300.002,300.000,40.966,3.120,0,0,300.000,300.000,13.270,9.360,1
3755758027.885400,0,1,299.998,300.000,40.975,3.118,0,0,300.000,300.000,13.270,9.380,1
3755758177.885400,0,1,299.998,299.999,40.983,3.120,0,0,300.000,300.000,13.240,9.360,1
3755758327.885400,0,1,299.999,300.000,40.993,3.120,0,0,300.000,300.000,13.270,9.400,1
3755758477.885400,0,1,300.000,299.998,40.999,3.120,0,0,300.000,300.000,13.200,9.380,1
3755758627.885400,0,1,299.997,300.001,41.005,3.122,0,0,300.000,300.000,13.240,9.320,1
3755758777.885400,0,1,300.002,300.002,41.010,3.119,0,0,300.000,300.000,13.220,9.330,1
3755758927.885400,0,1,300.001,299.998,41.016,3.119,0,0,300.000,300.000,13.200,9.280,1
3755759077.885400,0,1,300.000,300.002,41.024,3.118,0,0,300.000,300.000,13.240,9.330,1
3755759227.885400,0,1,299.998,299.998,41.031,3.121,0,0,300.000,300.000,13.200,9.330,1
3755759377.885400,0,1,300.002,300.002,41.038,3.121,0,0,300.000,300.000,13.170,9.320,1
3755759527.885400,0,1,299.999,300.000,41.044,3.120,0,0,300.000,300.000,13.200,9.300,1
3755759677.885400,0,1,300.002,299.999,41.049,3.120,0,0,300.000,300.000,13.170,9.320,1
3755759827.885400,0,1,299.998,300.002,41.055,3.120,0,0,300.000,300.000,13.150,9.320,1
3755759977.885400,0,1,300.002,300.000,41.058,3.120,0,0,300.000,300.000,13.170,9.270,1
3755760127.885400,0,1,299.998,300.001,41.062,3.122,0,0,300.000,300.000,13.130,9.300,1
3755760277.885400,0,1,300.001,300.004,41.068,3.121,0,0,300.000,300.000,13.180,9.250,1
3755760427.885400,0,1,299.995,300.002,41.073,3.121,0,0,300.000,300.000,13.080,9.250,1
3755760577.885400,0,1,300.001,299.998,41.077,3.121,0,0,300.000,300.000,13.090,9.240,1
3755760727.885400,0,1,300.000,299.999,41.084,3.125,0,0,300.000,300.000,13.060,9.250,1
3755760877.885400,0,1,300.000,300.001,41.093,3.123,0,0,300.000,300.000,13.080,9.240,1
3755761027.885400,0,1,300.000,299.997,41.100,3.122,0,0,300.000,300.000,13.040,9.220,1
3755761177.885400,0,1,300.000,300.000,41.104,3.122,0,0,300.000,300.000,13.040,9.240,1
3755761327.885400,0,1,300.000,300.002,41.109,3.124,0,0,300.000,300.000,13.110,9.220,1
3755761477.885400,0,1,300.000,300.001,41.115,3.122,0,0,300.000,300.000,13.020,9.210,1
3755761627.885400,0,1,300.000,300.000,41.119,3.124,0,0,300.000,300.000,13.040,9.220,1
3755761777.885400,0,1,299.999,299.999,41.124,3.124,0,0,300.000,300.000,13.020,9.190,1
3755761927.885400,0,1,300.000,300.000,41.126,3.124,0,0,300.000,300.000,13.020,9.210,1
3755762077.885400,0,1,300.002,300.002,41.129,3.124,0,0,300.000,300.000,13.040,9.190,1
3755762227.885400,0,1,299.999,300.001,41.134,3.123,0,0,300.000,300.000,13.000,9.170,1
3755762377.885400,0,1,300.001,300.000,41.138,3.124,0,0,300.000,300.000,13.040,9.140,1
3755762527.885400,0,1,300.001,300.003,41.143,3.124,0,0,300.000,300.000,13.000,9.210,1
3755762677.885400,0,1,300.001,300.000,41.148,3.124,0,0,300.000,300.000,13.080,9.170,1
3755762827.885400,0,1,300.001,299.999,41.156,3.122,0,0,300.000,300.000,12.930,9.170,1
3755762977.885400,0,1,300.002,299.998,41.160,3.122,0,0,300.000,300.000,13.000,9.190,1
3755763127.885400,0,1,300.002,300.000,41.164,3.122,0,0,300.000,300.000,12.970,9.190,1
3755763277.885400,0,1,299.999,300.001,41.169,3.122,0,0,300.000,300.000,13.000,9.170,1
3755763427.885400,0,1,300.001,300.000,41.172,3.122,0,0,300.000,300.000,13.000,9.190,1
3755763577.885400,0,1,299.999,300.000,41.177,3.122,0,0,300.000,300.000,12.990,9.170,1
3755763727.885400,0,1,299.999,299.999,41.182,3.123,0,0,300.000,300.000,13.020,9.170,1
3755763877.885400,0,1,299.998,299.999,41.185,3.123,0,0,300.000,300.000,12.990,9.140,1
3755764027.885400,0,1,300.000,300.001,41.187,3.124,0,0,300.000,300.000,12.930,9.160,1
3755764177.885400,0,1,300.001,300.000,41.191,3.124,0,0,300.000,300.000,13.020,9.160,1
3755764327.885400,0,1,300.002,299.999,41.195,3.124,0,0,300.000,300.000,12.900,9.140,1
3755764477.885400,0,1,300.000,299.998,41.199,3.124,0,0,300.000,300.000,12.970,9.140,1
3755764627.885400,0,1,300.001,299.999,41.201,3.124,0,0,300.000,300.000,12.950,9.140,1
3755764777.885400,0,1,299.997,300.002,41.200,3.123,0,0,300.000,300.000,12.990,9.140,1
3755764927.885400,0,1,300.000,300.001,41.202,3.123,0,0,300.000,300.000,12.950,9.130,1
3755765077.885400,0,1,300.000,299.999,41.203,3.124,0,0,300.000,300.000,12.930,9.140,1
3755765227.885400,0,1,299.998,300.000,41.205,3.123,0,0,300.000,300.000,12.950,9.110,1
3755765377.885400,0,1,300.000,300.000,41.207,3.124,0,0,300.000,300.000,12.950,9.140,1
3755765527.885400,0,1,300.000,299.999,41.210,3.125,0,0,300.000,300.000,12.920,9.130,1
3755765677.885400,0,1,300.002,300.001,41.214,3.123,0,0,300.000,300.000,12.920,9.130,1
3755765827.885400,0,1,300.000,299.999,41.217,3.124,0,0,300.000,300.000,12.920,9.140,1
3755765977.885400,0,1,299.998,300.002,41.220,3.125,0,0,300.000,300.000,12.930,9.130,1
3755766127.885400,0,1,300.003,299.999,41.223,3.124,0,0,300.000,300.000,12.880,9.100,1
3755766277.885400,0,1,299.998,300.002,41.224,3.124,0,0,300.000,300.000,12.920,9.110,1
3755766427.885400,0,1,300.002,300.000,41.224,3.125,0,0,300.000,300.000,12.880,9.110,1
3755766756.784400,0,1,300.000,300.000,41.231,3.124,0,0,300.000,300.000,12.880,9.130,1
3755766906.784400,0,1,299.999,299.998,41.234,3.125,0,0,300.000,300.000,12.920,9.130,1
3755767056.784400,0,1,299.990,299.985,41.237,3.126,0,0,300.000,300.000,13.040,9.280,4
3755767206.784400,0,1,300.014,300.002,41.238,3.124,0,0,300.000,300.000,12.920,9.130,1
3755769785.382400,676,2,299.970,0.000,40.970,3.139,0,0,300.000,300.000,14.500,0.000,4
3755769935.382400,4813,2,300.028,0.000,40.939,3.237,0,0,300.000,300.000,14.860,0.000,4
3755770085.382400,-2419,2,299.975,0.000,40.895,3.761,0,0,300.000,300.000,14.510,0.000,4
3755770235.382400,-1627,3,300.022,0.000,40.867,3.391,0,0,300.000,300.000,14.880,0.000,4
3755770385.382400,-811,3,299.974,0.000,40.830,3.164,0,0,300.000,300.000,14.530,0.000,4
3755770535.382400,-411,2,300.025,0.000,40.791,3.126,0,0,300.000,300.000,14.840,0.000,4
3755770685.382400,140,2,299.978,0.000,40.757,3.125,0,0,300.000,300.000,14.610,0.000,4
3755770835.382400,0,1,300.019,0.000,40.724,3.125,0,0,300.000,300.000,14.880,0.000,4
3755770985.382400,0,1,299.982,0.000,40.692,3.123,0,0,300.000,300.000,14.550,0.000,4
3755771135.382400,0,1,300.016,0.000,40.664,3.124,0,0,300.000,300.000,14.890,0.000,4
3755771285.382400,0,1,299.986,0.000,40.638,3.123,0,0,300.000,300.000,14.570,0.000,4
3755771435.382400,0,1,300.010,0.000,40.614,3.124,0,0,300.000,300.000,14.890,0.000,4
3755771585.382400,0,1,299.988,0.000,40.594,3.122,0,0,300.000,300.000,14.570,0.000,4
3755771735.382400,0,1,300.012,0.000,40.576,3.124,0,0,300.000,300.000,14.880,0.000,4
3755771885.382400,0,1,299.988,0.000,40.562,3.124,0,0,300.000,300.000,14.650,0.000,4
3755772035.382400,0,1,300.009,0.000,40.549,3.125,0,0,300.000,300.000,14.860,0.000,4
3755772185.382400,0,1,299.990,0.000,40.536,3.124,0,0,300.000,300.000,14.700,0.000,4
3755772335.382400,0,1,300.010,0.000,40.525,3.125,0,0,300.000,300.000,14.820,0.000,4
3755772485.382400,0,1,299.993,0.000,40.516,3.124,0,0,300.000,300.000,14.740,0.000,4
3755772635.382400,0,1,300.003,0.000,40.508,3.126,0,0,300.000,300.000,14.860,0.000,4
3755772785.382400,0,1,299.997,0.000,40.500,3.124,0,0,300.000,300.000,14.760,0.000,4
3755772935.382400,0,1,300.003,0.000,40.493,3.124,0,0,300.000,300.000,14.860,0.000,4
3755773085.382400,0,1,299.997,0.000,40.485,3.124,0,0,300.000,300.000,14.720,0.000,4
3755773235.382400,0,1,300.005,0.000,40.478,3.125,0,0,300.000,300.000,14.860,0.000,4
3755773385.382400,0,1,299.996,0.000,40.474,3.123,0,0,300.000,300.000,14.800,0.000,4
3755773535.382400,0,1,300.004,0.000,40.467,3.122,0,0,300.000,300.000,14.800,0.000,4
3755773685.382400,0,1,299.995,0.000,40.462,3.123,0,0,300.000,300.000,14.860,0.000,4
3755773835.382400,0,1,300.002,0.000,40.456,3.123,0,0,300.000,300.000,14.820,0.000,4
3755773985.382400,0,1,299.998,0.000,40.453,3.123,0,0,300.000,300.000,14.800,0.000,4
3755774135.382400,0,1,300.003,0.000,40.450,3.122,0,0,300.000,300.000,14.840,0.000,4
3755774285.382400,0,1,299.998,0.000,40.447,3.121,0,0,300.000,300.000,14.760,0.000,4
3755774435.382400,0,1,300.003,0.000,40.444,3.123,0,0,300.000,300.000,14.820,0.000,4
3755774585.382400,0,1,299.997,0.000,40.440,3.125,0,0,300.000,300.000,14.860,0.000,4
3755774735.382400,0,1,300.001,0.000,40.438,3.124,0,0,300.000,300.000,14.880,0.000,4
3755774885.382400,0,1,299.998,0.000,40.437,3.124,0,0,300.000,300.000,14.820,0.000,4
3755775035.382400,0,1,300.003,0.000,40.434,3.123,0,0,300.000,300.000,14.860,0.000,4
3755775185.382400,0,1,299.998,0.000,40.435,3.124,0,0,300.000,300.000,14.840,0.000,4
3755775335.382400,0,1,300.001,0.000,40.434,3.125,0,0,300.000,300.000,14.880,0.000,4
3755775485.382400,0,1,300.002,0.000,40.434,3.123,0,0,300.000,300.000,14.800,0.000,4
3755775635.382400,0,1,299.999,0.000,40.433,3.125,0,0,300.000,300.000,14.840,0.000,4
3755775785.382400,0,1,300.002,0.000,40.434,3.124,0,0,300.000,300.000,14.800,0.000,4
3755775935.382400,0,1,299.998,0.000,40.433,3.124,0,0,300.000,300.000,14.880,0.000,4
3755776085.382400,0,1,300.003,0.000,40.433,3.125,0,0,300.000,300.000,14.800,0.000,4
3755776235.382400,0,1,299.998,0.000,40.433,3.126,0,0,300.000,300.000,14.860,0.000,4
3755776385.382400,0,1,300.004,0.000,40.434,3.123,0,0,300.000,300.000,14.820,0.000,4
3755776535.382400,0,1,299.998,0.000,40.435,3.124,0,0,300.000,300.000,14.860,0.000,4
3755776685.382400,0,1,300.000,0.000,40.434,3.125,0,0,300.000,300.000,14.820,0.000,4
3755776835.382400,0,1,299.995,0.000,40.435,3.126,0,0,300.000,300.000,14.890,0.000,4
3755776985.382400,0,1,300.001,0.000,40.435,3.123,0,0,300.000,300.000,14.760,0.000,4
3755777135.382400,0,1,299.996,0.000,40.432,3.116,0,0,300.000,300.000,14.880,0.000,4
3755777285.382400,0,1,300.003,0.000,40.428,3.122,0,0,300.000,300.000,14.720,0.000,4
3755777435.382400,0,1,299.995,0.000,40.429,3.122,0,0,300.000,300.000,14.890,0.000,4
3755777585.382400,0,1,300.003,0.000,40.428,3.123,0,0,300.000,300.000,14.800,0.000,4
3755777735.382400,0,1,299.996,0.000,40.430,3.124,0,0,300.000,300.000,14.860,0.000,4
3755777885.382400,0,1,300.003,0.000,40.431,3.126,0,0,300.000,300.000,14.780,0.000,4
3755778035.382400,0,1,300.003,0.000,40.432,3.125,0,0,300.000,300.000,14.820,0.000,4
3755778185.382400,0,1,299.995,0.000,40.434,3.125,0,0,300.000,300.000,14.820,0.000,4
3755778335.382400,0,1,300.004,0.000,40.435,3.126,0,0,300.000,300.000,14.800,0.000,4
3755778485.382400,0,1,299.995,0.000,40.437,3.126,0,0,300.000,300.000,14.840,0.000,4
3755778635.382400,0,1,300.004,0.000,40.439,3.125,0,0,300.000,300.000,14.820,0.000,4
3755778785.382400,0,1,299.996,0.000,40.441,3.126,0,0,300.000,300.000,14.760,0.000,4
3755778935.382400,0,1,300.004,0.000,40.440,3.124,0,0,300.000,300.000,14.820,0.000,4
3755779085.382400,0,1,299.997,0.000,40.440,3.126,0,0,300.000,300.000,14.800,0.000,4
3755779235.382400,0,1,300.001,0.000,40.439,3.125,0,0,300.000,300.000,14.840,0.000,4
3755779385.382400,0,1,299.996,0.000,40.441,3.123,0,0,300.000,300.000,14.760,0.000,4
3755779535.382400,0,1,300.006,0.000,40.442,3.123,0,0,300.000,300.000,14.880,0.000,4
3755779685.382400,0,1,299.995,0.000,40.441,3.125,0,0,300.000,300.000,14.760,0.000,4
3755779835.382400,0,1,300.001,0.000,40.440,3.124,0,0,300.000,300.000,14.840,0.000,4
3755779985.382400,0,1,299.997,0.000,40.442,3.124,0,0,300.000,300.000,14.860,0.000,4
3755780135.382400,0,1,300.001,0.000,40.442,3.125,0,0,300.000,300.000,14.820,0.000,4
3755780285.382400,0,1,299.999,0.000,40.444,3.124,0,0,300.000,300.000,14.800,0.000,4
3755780435.382400,0,1,300.000,0.000,40.445,3.126,0,0,300.000,300.000,14.840,0.000,4
3755780585.382400,0,1,299.998,0.000,40.446,3.125,0,0,300.000,300.000,14.820,0.000,4
3755780735.382400,0,1,300.001,0.000,40.449,3.126,0,0,300.000,300.000,14.820,0.000,4
3755780885.382400,0,1,299.997,0.000,40.452,3.126,0,0,300.000,300.000,14.800,0.000,4
3755781035.382400,0,1,300.002,0.000,40.455,3.126,0,0,300.000,300.000,14.880,0.000,4
3755781185.382400,0,1,299.995,0.000,40.455,3.126,0,0,300.000,300.000,14.800,0.000,4
3755781335.382400,0,1,300.001,0.000,40.456,3.126,0,0,300.000,300.000,14.880,0.000,4
3755781485.382400,0,1,299.998,0.000,40.456,3.127,0,0,300.000,300.000,14.800,0.000,4
3755781635.382400,0,1,300.002,0.000,40.457,3.126,0,0,300.000,300.000,14.840,0.000,4
3755781785.382400,0,1,299.996,0.000,40.458,3.125,0,0,300.000,300.000,14.760,0.000,4
3755781935.382400,0,1,300.001,0.000,40.456,3.124,0,0,300.000,300.000,14.890,0.000,4
3755782085.382400,0,1,299.997,0.000,40.456,3.125,0,0,300.000,300.000,14.780,0.000,4
3755782235.382400,0,1,300.003,0.000,40.456,3.124,0,0,300.000,300.000,14.860,0.000,4
3755782385.382400,0,1,299.999,0.000,40.455,3.123,0,0,300.000,300.000,14.740,0.000,4
3755782535.382400,0,1,299.999,0.000,40.455,3.123,0,0,300.000,300.000,14.820,0.000,4
3755782685.382400,0,1,300.001,0.000,40.455,3.125,0,0,300.000,300.000,14.800,0.000,4
3755782835.382400,0,1,299.998,0.000,40.456,3.126,0,0,300.000,300.000,14.880,0.000,4
3755782985.382400,0,1,300.001,0.000,40.456,3.126,0,0,300.000,300.000,14.800,0.000,4
3755783135.382400,0,1,300.000,0.000,40.458,3.125,0,0,300.000,300.000,14.860,0.000,4
3755783285.382400,0,1,300.001,0.000,40.458,3.126,0,0,300.000,300.000,14.740,0.000,4
3755783435.382400,0,1,299.998,0.000,40.459,3.125,0,0,300.000,300.000,14.880,0.000,4
3755783585.382400,0,1,300.000,0.000,40.458,3.123,0,0,300.000,300.000,14.780,0.000,4
3755783735.382400,0,1,299.999,0.000,40.458,3.120,0,0,300.000,300.000,14.880,0.000,4
3755783885.382400,0,1,300.000,0.000,40.453,3.123,0,0,300.000,300.000,14.760,0.000,4
3755784035.382400,0,1,300.003,0.000,40.453,3.122,0,0,300.000,300.000,14.820,0.000,4
3755784185.382400,0,1,299.998,0.000,40.453,3.124,0,0,300.000,300.000,14.780,0.000,4
3755784335.382400,0,1,300.002,0.000,40.456,3.124,0,0,300.000,300.000,14.820,0.000,4
3755784485.382400,0,1,299.995,0.000,40.455,3.124,0,0,300.000,300.000,14.820,0.000,4
3755784635.382400,0,1,300.004,0.000,40.455,3.123,0,0,300.000,300.000,14.800,0.000,4
3755784785.382400,0,1,299.998,0.000,40.456,3.124,0,0,300.000,300.000,14.880,0.000,4
3755784935.382400,0,1,300.005,0.000,40.458,3.125,0,0,300.000,300.000,14.800,0.000,4
3755785085.382400,0,1,299.998,0.000,40.458,3.125,0,0,300.000,300.000,14.840,0.000,4
3755785235.382400,0,1,300.004,0.000,40.458,3.123,0,0,300.000,300.000,14.800,0.000,4
3755785385.382400,0,1,299.999,0.000,40.459,3.124,0,0,300.000,300.000,14.860,0.000,4
3755785535.382400,0,1,300.002,0.000,40.457,3.124,0,0,300.000,300.000,14.780,0.000,4
3755785685.382400,0,1,299.998,0.000,40.457,3.124,0,0,300.000,300.000,14.800,0.000,4
3755785835.382400,0,1,300.001,0.000,40.456,3.124,0,0,300.000,300.000,14.780,0.000,4
3755785985.382400,0,1,300.000,0.000,40.458,3.122,0,0,300.000,300.000,14.760,0.000,4
3755786135.382400,0,1,299.998,0.000,40.457,3.124,0,0,300.000,300.000,14.780,0.000,4
3755786285.382400,0,1,299.998,0.000,40.458,3.122,0,0,300.000,300.000,14.820,0.000,4
3755786435.382400,0,1,299.999,0.000,40.460,3.121,0,0,300.000,300.000,14.760,0.000,4
3755786585.382400,0,1,299.997,0.000,40.459,3.124,0,0,300.000,300.000,14.820,0.000,4
3755786735.382400,0,1,300.003,0.000,40.461,3.123,0,0,300.000,300.000,14.820,0.000,4
3755786885.382400,0,1,299.997,0.000,40.462,3.124,0,0,300.000,300.000,14.820,0.000,4
3755787035.382400,0,1,300.002,0.000,40.462,3.124,0,0,300.000,300.000,14.840,0.000,4
3755787185.382400,0,1,299.995,0.000,40.462,3.123,0,0,300.000,300.000,14.780,0.000,4
3755787335.382400,0,1,300.003,0.000,40.462,3.122,0,0,300.000,300.000,14.820,0.000,4
3755787485.382400,0,1,299.996,0.000,40.462,3.124,0,0,300.000,300.000,14.820,0.000,4
3755787635.382400,0,1,300.001,0.000,40.463,3.123,0,0,300.000,300.000,14.800,0.000,4
3755787785.382400,0,1,299.997,0.000,40.462,3.122,0,0,300.000,300.000,14.820,0.000,4
3755787935.382400,0,1,300.002,0.000,40.462,3.121,0,0,300.000,300.000,14.800,0.000,4
3755788085.382400,0,1,299.996,0.000,40.462,3.125,0,0,300.000,300.000,14.820,0.000,4
3755788235.382400,0,1,300.002,0.000,40.463,3.126,0,0,300.000,300.000,14.760,0.000,4
3755788385.382400,0,1,299.995,0.000,40.465,3.126,0,0,300.000,300.000,14.740,0.000,4
3755788535.382400,0,1,300.003,0.000,40.466,3.126,0,0,300.000,300.000,14.760,0.000,4
3755788685.382400,0,1,299.997,0.000,40.469,3.124,0,0,300.000,300.000,14.780,0.000,4
3755788835.382400,0,1,300.002,0.000,40.469,3.125,0,0,300.000,300.000,14.860,0.000,4
3755788985.382400,0,1,299.999,0.000,40.470,3.126,0,0,300.000,300.000,14.800,0.000,4
3755789135.382400,0,1,300.001,0.000,40.470,3.125,0,0,300.000,300.000,14.800,0.000,4
3755789285.382400,0,1,300.000,0.000,40.469,3.124,0,0,300.000,300.000,14.800,0.000,4
3755789435.382400,0,1,299.999,0.000,40.469,3.124,0,0,300.000,300.000,14.760,0.000,4
3755789585.382400,0,1,300.000,0.000,40.468,3.125,0,0,300.000,300.000,14.800,0.000,4
3755789735.382400,0,1,299.999,0.000,40.467,3.125,0,0,300.000,300.000,14.760,0.000,4
3755789885.382400,0,1,300.003,0.000,40.468,3.123,0,0,300.000,300.000,14.890,0.000,4
3755790035.382400,0,1,299.996,0.000,40.467,3.123,0,0,300.000,300.000,14.760,0.000,4
3755790185.382400,0,1,300.003,0.000,40.466,3.122,0,0,300.000,300.000,14.800,0.000,4
3755790335.382400,0,1,299.999,0.000,40.467,3.123,0,0,300.000,300.000,14.780,0.000,4
3755790485.382400,0,1,299.998,0.000,40.465,3.122,0,0,300.000,300.000,14.760,0.000,4
3755790635.382400,0,1,300.000,0.000,40.464,3.122,0,0,300.000,300.000,14.840,0.000,4
3755790785.382400,0,1,300.000,0.000,40.463,3.124,0,0,300.000,300.000,14.780,0.000,4
3755790935.382400,0,1,300.004,0.000,40.463,3.123,0,0,300.000,300.000,14.820,0.000,4
3755791085.382400,0,1,299.999,0.000,40.464,3.123,0,0,300.000,300.000,14.780,0.000,4
3755791235.382400,0,1,300.001,0.000,40.465,3.122,0,0,300.000,300.000,14.820,0.000,4
3755791385.382400,0,1,300.000,0.000,40.465,3.125,0,0,300.000,300.000,14.800,0.000,4
3755791535.382400,0,1,300.000,0.000,40.466,3.125,0,0,300.000,300.000,14.780,0.000,4
3755791685.382400,0,1,300.001,0.000,40.468,3.124,0,0,300.000,300.000,14.820,0.000,4
3755791835.382400,0,1,299.999,0.000,40.467,3.125,0,0,300.000,300.000,14.780,0.000,4
3755791985.382400,0,1,299.999,0.000,40.467,3.125,0,0,300.000,300.000,14.780,0.000,4
3755792135.382400,0,1,300.000,0.000,40.469,3.123,0,0,300.000,300.000,14.780,0.000,4
3755792285.382400,0,1,299.998,0.000,40.471,3.123,0,0,300.000,300.000,14.800,0.000,4
3755792435.382400,0,1,300.000,0.000,40.471,3.124,0,0,300.000,300.000,14.780,0.000,4
3755792585.382400,0,1,299.999,0.000,40.471,3.124,0,0,300.000,300.000,14.740,0.000,4
3755792735.382400,0,1,299.999,0.000,40.470,3.125,0,0,300.000,300.000,14.800,0.000,4
3755792885.382400,0,1,300.000,0.000,40.471,3.124,0,0,300.000,300.000,14.820,0.000,4
3755793035.382400,0,1,300.001,0.000,40.469,3.125,0,0,300.000,300.000,14.720,0.000,4
3755793185.382400,0,1,299.998,0.000,40.469,3.124,0,0,300.000,300.000,14.860,0.000,4
3755793335.382400,0,1,300.003,0.000,40.470,3.125,0,0,300.000,300.000,14.740,0.000,4
3755793485.382400,0,1,299.997,0.000,40.471,3.125,0,0,300.000,300.000,14.840,0.000,4
3755793635.382400,0,1,300.003,0.000,40.472,3.125,0,0,300.000,300.000,14.780,0.000,4
3755793785.382400,0,1,300.001,0.000,40.472,3.125,0,0,300.000,300.000,14.860,0.000,4
3755793935.382400,0,1,299.999,0.000,40.471,3.124,0,0,300.000,300.000,14.760,0.000,4
3755794085.382400,0,1,300.001,0.000,40.471,3.124,0,0,300.000,300.000,14.840,0.000,4
3755794235.382400,0,1,299.997,0.000,40.470,3.124,0,0,300.000,300.000,14.700,0.000,4
3755794385.382400,0,1,299.999,0.000,40.467,3.124,0,0,300.000,300.000,14.890,0.000,4
3755794535.382400,0,1,300.000,0.000,40.466,3.124,0,0,300.000,300.000,14.650,0.000,4
3755794685.382400,0,1,299.999,0.000,40.468,3.125,0,0,300.000,300.000,14.820,0.000,4
3755794835.382400,0,1,300.000,0.000,40.468,3.124,0,0,300.000,300.000,14.680,0.000,4
3755794985.382400,0,1,299.998,0.000,40.469,3.125,0,0,300.000,300.000,14.880,0.000,4
3755795135.382400,0,1,300.001,0.000,40.467,3.124,0,0,300.000,300.000,14.780,0.000,4
3755795285.382400,0,1,300.001,0.000,40.467,3.123,0,0,300.000,300.000,14.800,0.000,4
3755795435.382400,0,1,299.999,0.000,40.465,3.124,0,0,300.000,300.000,14.780,0.000,4
3755795585.382400,0,1,299.997,0.000,40.464,3.124,0,0,300.000,300.000,14.820,0.000,4
3755795735.382400,0,1,300.003,0.000,40.465,3.124,0,0,300.000,300.000,14.800,0.000,4
3755795885.382400,0,1,299.996,0.000,40.465,3.123,0,0,300.000,300.000,14.820,0.000,4
3755796035.382400,0,1,300.004,0.000,40.465,3.122,0,0,300.000,300.000,14.740,0.000,4
3755796185.382400,0,1,299.994,0.000,40.464,3.123,0,0,300.000,300.000,14.840,0.000,4
3755796335.382400,0,1,300.004,0.000,40.464,3.123,0,0,300.000,300.000,14.760,0.000,4
3755796485.382400,0,1,299.994,0.000,40.465,3.124,0,0,300.000,300.000,14.800,0.000,4
3755796635.382400,0,1,300.004,0.000,40.463,3.123,0,0,300.000,300.000,14.800,0.000,4
3755796785.382400,0,1,299.996,0.000,40.464,3.123,0,0,300.000,300.000,14.780,0.000,4
3755796935.382400,0,1,300.003,0.000,40.464,3.124,0,0,300.000,300.000,14.760,0.000,4
3755797085.382400,0,1,299.996,0.000,40.464,3.122,0,0,300.000,300.000,14.780,0.000,4
3755797235.382400,0,1,300.004,0.000,40.464,3.122,0,0,300.000,300.000,14.760,0.000,4
3755797385.382400,0,1,299.998,0.000,40.464,3.124,0,0,300.000,300.000,14.820,0.000,4
3755797535.382400,0,1,300.001,0.000,40.465,3.125,0,0,300.000,300.000,14.800,0.000,4
3755797685.382400,0,1,299.998,0.000,40.465,3.125,0,0,300.000,300.000,14.740,0.000,4
3755797835.382400,0,1,300.002,0.000,40.466,3.124,0,0,300.000,300.000,14.800,0.000,4
3755797985.382400,0,1,299.998,0.000,40.466,3.123,0,0,300.000,300.000,14.780,0.000,4
3755798135.382400,0,1,300.001,0.000,40.465,3.123,0,0,300.000,300.000,14.760,0.000,4
3755798285.382400,0,1,300.000,0.000,40.466,3.123,0,0,300.000,300.000,14.780,0.000,4
3755798435.382400,0,1,300.002,0.000,40.466,3.123,0,0,300.000,300.000,14.780,0.000,4
3755798585.382400,0,1,299.998,0.000,40.467,3.124,0,0,300.000,300.000,14.780,0.000,4
3755798735.382400,0,1,300.000,0.000,40.467,3.124,0,0,300.000,300.000,14.800,0.000,4
3755798885.382400,0,1,299.999,0.000,40.466,3.124,0,0,300.000,300.000,14.760,0.000,4
3755799035.382400,0,1,299.998,0.000,40.468,3.124,0,0,300.000,300.000,14.780,0.000,4
3755799185.382400,0,1,299.999,0.000,40.468,3.125,0,0,300.000,300.000,14.800,0.000,4
3755799335.382400,0,1,300.002,0.000,40.468,3.123,0,0,300.000,300.000,14.820,0.000,4
3755799485.382400,0,1,299.997,0.000,40.468,3.123,0,0,300.000,300.000,14.840,0.000,4
3755799635.382400,0,1,300.003,0.000,40.468,3.124,0,0,300.000,300.000,14.760,0.000,4
3755799785.382400,0,1,299.993,0.000,40.468,3.123,0,0,300.000,300.000,14.880,0.000,4
3755799935.382400,0,1,300.003,0.000,40.468,3.122,0,0,300.000,300.000,14.720,0.000,4
3755800085.382400,0,1,299.995,0.000,40.467,3.125,0,0,300.000,300.000,14.820,0.000,4
3755800235.382400,0,1,300.002,0.000,40.468,3.126,0,0,300.000,300.000,14.740,0.000,4
3755800385.382400,0,1,299.996,0.000,40.472,3.125,0,0,300.000,300.000,14.860,0.000,4
3755800535.382400,0,1,300.002,0.000,40.474,3.126,0,0,300.000,300.000,14.740,0.000,4
3755800685.382400,0,1,299.997,0.000,40.477,3.124,0,0,300.000,300.000,14.820,0.000,4
3755800835.382400,0,1,300.004,0.000,40.476,3.126,0,0,300.000,300.000,14.800,0.000,4
3755800985.382400,0,1,299.995,0.000,40.478,3.124,0,0,300.000,300.000,14.820,0.000,4
3755801135.382400,0,1,300.004,0.000,40.477,3.125,0,0,300.000,300.000,14.740,0.000,4
3755801285.382400,0,1,299.994,0.000,40.478,3.125,0,0,300.000,300.000,14.840,0.000,4
3755801435.382400,0,1,300.005,0.000,40.476,3.126,0,0,300.000,300.000,14.760,0.000,4
3755801585.382400,0,1,299.994,0.000,40.474,3.126,0,0,300.000,300.000,14.780,0.000,4
3755801735.382400,0,1,300.006,0.000,40.474,3.121,0,0,300.000,300.000,14.820,0.000,4
3755801885.382400,0,1,299.994,0.000,40.473,3.122,0,0,300.000,300.000,14.800,0.000,4
3755802035.382400,0,1,300.005,0.000,40.469,3.124,0,0,300.000,300.000,14.800,0.000,4
3755802185.382400,0,1,299.997,0.000,40.471,3.124,0,0,300.000,300.000,14.820,0.000,4
3755802335.382400,0,1,300.001,0.000,40.470,3.124,0,0,300.000,300.000,14.780,0.000,4
3755802485.382400,0,1,299.996,0.000,40.470,3.124,0,0,300.000,300.000,14.860,0.000,4
3755802635.382400,0,1,300.002,0.000,40.468,3.123,0,0,300.000,300.000,14.700,0.000,4
3755802785.382400,0,1,299.997,0.000,40.469,3.122,0,0,300.000,300.000,14.880,0.000,4
3755802935.382400,0,1,300.004,0.000,40.468,3.123,0,0,300.000,300.000,14.760,0.000,4
3755803085.382400,0,1,299.997,0.000,40.468,3.124,0,0,300.000,300.000,14.860,0.000,4
3755803235.382400,0,1,300.003,0.000,40.467,3.125,0,0,300.000,300.000,14.780,0.000,4
3755803385.382400,0,1,299.996,0.000,40.470,3.124,0,0,300.000,300.000,14.840,0.000,4
3755803535.382400,0,1,300.001,0.000,40.471,3.123,0,0,300.000,300.000,14.760,0.000,4
3755803685.382400,0,1,300.000,0.000,40.472,3.124,0,0,300.000,300.000,14.760,0.000,4
3755803835.382400,0,1,300.000,0.000,40.473,3.125,0,0,300.000,300.000,14.800,0.000,4
3755803985.382400,0,1,300.001,0.000,40.473,3.124,0,0,300.000,300.000,14.720,0.000,4
3755804135.382400,0,1,299.999,0.000,40.474,3.123,0,0,300.000,300.000,14.800,0.000,4
3755804285.382400,0,1,300.001,0.000,40.472,3.125,0,0,300.000,300.000,14.740,0.000,4
3755804435.382400,0,1,300.000,0.000,40.473,3.123,0,0,300.000,300.000,14.740,0.000,4
3755804585.382400,0,1,299.999,0.000,40.472,3.124,0,0,300.000,300.000,14.820,0.000,4
3755804735.382400,0,1,299.998,0.000,40.474,3.124,0,0,300.000,300.000,14.800,0.000,4
3755804885.382400,0,1,300.001,0.000,40.475,3.123,0,0,300.000,300.000,14.740,0.000,4
3755805035.382400,0,1,299.997,0.000,40.474,3.123,0,0,300.000,300.000,14.840,0.000,4
3755805185.382400,0,1,300.001,0.000,40.475,3.124,0,0,300.000,300.000,14.740,0.000,4
3755805335.382400,0,1,299.997,0.000,40.476,3.123,0,0,300.000,300.000,14.860,0.000,4
3755805485.382400,0,1,300.000,0.000,40.475,3.123,0,0,300.000,300.000,14.720,0.000,4
3755805635.382400,0,1,299.999,0.000,40.474,3.120,0,0,300.000,300.000,14.860,0.000,4
3755805785.382400,0,1,299.999,0.000,40.472,3.122,0,0,300.000,300.000,14.720,0.000,4
3755805935.382400,0,1,300.000,0.000,40.472,3.123,0,0,300.000,300.000,14.860,0.000,4
3755806085.382400,0,1,299.999,0.000,40.470,3.123,0,0,300.000,300.000,14.720,0.000,4
3755806235.382400,0,1,300.002,0.000,40.469,3.123,0,0,300.000,300.000,14.840,0.000,4
3755806385.382400,0,1,299.997,0.000,40.469,3.122,0,0,300.000,300.000,14.800,0.000,4
3755806535.382400,0,1,300.002,0.000,40.473,3.125,0,0,300.000,300.000,14.820,0.000,4
3755806685.382400,0,1,299.996,0.000,40.474,3.123,0,0,300.000,300.000,14.780,0.000,4
3755806835.382400,0,1,300.005,0.000,40.475,3.123,0,0,300.000,300.000,14.800,0.000,4
3755806985.382400,0,1,299.995,0.000,40.473,3.124,0,0,300.000,300.000,14.820,0.000,4
3755807135.382400,0,1,300.005,0.000,40.475,3.124,0,0,300.000,300.000,14.760,0.000,4
3755807285.382400,0,1,299.993,0.000,40.477,3.123,0,0,300.000,300.000,14.840,0.000,4
3755807435.382400,0,1,300.007,0.000,40.478,3.122,0,0,300.000,300.000,14.740,0.000,4
3755807585.382400,0,1,299.993,0.000,40.476,3.121,0,0,300.000,300.000,14.880,0.000,4
3755807735.382400,0,1,300.005,0.000,40.473,3.124,0,0,300.000,300.000,14.700,0.000,4
3755807885.382400,0,1,299.992,0.000,40.474,3.124,0,0,300.000,300.000,14.880,0.000,4
3755808035.382400,0,1,300.005,0.000,40.474,3.122,0,0,300.000,300.000,14.680,0.000,4
3755808185.382400,0,1,299.996,0.000,40.474,3.122,0,0,300.000,300.000,14.820,0.000,4
3755808335.382400,0,1,300.003,0.000,40.474,3.121,0,0,300.000,300.000,14.740,0.000,4
3755808485.382400,0,1,299.995,0.000,40.474,3.122,0,0,300.000,300.000,14.880,0.000,4
3755808635.382400,0,1,300.003,0.000,40.475,3.121,0,0,300.000,300.000,14.680,0.000,4
3755808785.382400,0,1,299.996,0.000,40.472,3.122,0,0,300.000,300.000,14.860,0.000,4
3755808935.382400,0,1,300.003,0.000,40.472,3.122,0,0,300.000,300.000,14.700,0.000,4
3755809085.382400,0,1,299.998,0.000,40.472,3.122,0,0,300.000,300.000,14.820,0.000,4
3755809235.382400,0,1,300.003,0.000,40.472,3.122,0,0,300.000,300.000,14.740,0.000,4
3755809385.382400,0,1,299.997,0.000,40.473,3.121,0,0,300.000,300.000,14.820,0.000,4
3755809535.382400,0,1,300.002,0.000,40.473,3.121,0,0,300.000,300.000,14.760,0.000,4
3755809685.382400,0,1,299.995,0.000,40.471,3.122,0,0,300.000,300.000,14.780,0.000,4
3755809835.382400,0,1,300.003,0.000,40.473,3.122,0,0,300.000,300.000,14.760,0.000,4
3755809985.382400,0,1,299.998,0.000,40.473,3.121,0,0,300.000,300.000,14.780,0.000,4
3755810135.382400,0,1,300.000,0.000,40.473,3.123,0,0,300.000,300.000,14.800,0.000,4
3755810285.382400,0,1,300.000,0.000,40.473,3.123,0,0,300.000,300.000,14.760,0.000,4
3755810435.382400,0,1,300.000,0.000,40.473,3.117,0,0,300.000,300.000,14.800,0.000,4
3755810585.382400,0,1,300.000,0.000,40.469,3.123,0,0,300.000,300.000,14.760,0.000,4
3755810735.382400,0,1,300.002,0.000,40.472,3.123,0,0,300.000,300.000,14.820,0.000,4
3755810885.382400,0,1,300.000,0.000,40.472,3.120,0,0,300.000,300.000,14.740,0.000,4
3755811035.382400,0,1,299.998,0.000,40.471,3.122,0,0,300.000,300.000,14.860,0.000,4
3755811185.382400,0,1,300.001,0.000,40.468,3.120,0,0,300.000,300.000,14.760,0.000,4
3755811335.382400,0,1,299.998,0.000,40.466,3.121,0,0,300.000,300.000,14.860,0.000,4
3755811485.382400,0,1,300.003,0.000,40.467,3.121,0,0,300.000,300.000,14.720,0.000,4
3755811635.382400,0,1,299.996,0.000,40.466,3.122,0,0,300.000,300.000,14.840,0.000,4
3755811785.382400,0,1,300.004,0.000,40.468,3.122,0,0,300.000,300.000,14.700,0.000,4
3755811935.382400,0,1,299.995,0.000,40.468,3.122,0,0,300.000,300.000,14.890,0.000,4
3755812085.382400,0,1,300.003,0.000,40.467,3.122,0,0,300.000,300.000,14.720,0.000,4
3755812235.382400,0,1,299.995,0.000,40.468,3.124,0,0,300.000,300.000,14.880,0.000,4
3755812385.382400,0,1,300.003,0.000,40.468,3.122,0,0,300.000,300.000,14.700,0.000,4
3755812535.382400,0,1,299.996,0.000,40.466,3.124,0,0,300.000,300.000,14.880,0.000,4
3755812685.382400,0,1,300.006,0.000,40.467,3.120,0,0,300.000,300.000,14.680,0.000,4
3755812835.382400,0,1,299.997,0.000,40.464,3.119,0,0,300.000,300.000,14.860,0.000,4
3755812985.382400,0,1,300.003,0.000,40.463,3.119,0,0,300.000,300.000,14.740,0.000,4
3755813135.382400,0,1,299.994,0.000,40.462,3.123,0,0,300.000,300.000,14.860,0.000,4
3755813285.382400,0,1,300.004,0.000,40.467,3.123,0,0,300.000,300.000,14.700,0.000,4
3755813435.382400,0,1,299.997,0.000,40.468,3.124,0,0,300.000,300.000,14.800,0.000,4
3755813585.382400,0,1,300.002,0.000,40.471,3.123,0,0,300.000,300.000,14.740,0.000,4
3755813735.382400,0,1,299.995,0.000,40.473,3.123,0,0,300.000,300.000,14.840,0.000,4
3755813885.382400,0,1,300.004,0.000,40.473,3.123,0,0,300.000,300.000,14.700,0.000,4
3755814035.382400,0,1,299.995,0.000,40.474,3.124,0,0,300.000,300.000,14.820,0.000,4
3755814185.382400,0,1,300.004,0.000,40.474,3.124,0,0,300.000,300.000,14.780,0.000,4
3755814335.382400,0,1,299.995,0.000,40.474,3.124,0,0,300.000,300.000,14.860,0.000,4
3755814485.382400,0,1,300.003,0.000,40.477,3.123,0,0,300.000,300.000,14.720,0.000,4
3755814635.382400,0,1,299.996,0.000,40.477,3.123,0,0,300.000,300.000,14.890,0.000,4
3755814785.382400,0,1,300.000,0.000,40.473,3.123,0,0,300.000,300.000,14.700,0.000,4
3755814935.382400,0,1,299.999,0.000,40.472,3.122,0,0,300.000,300.000,14.890,0.000,4
3755815085.382400,4990,2,300.000,0.000,40.469,3.832,0,0,300.000,300.000,14.720,0.000,4
3755815235.382400,5000,1,299.997,0.000,40.479,3.129,0,0,300.000,300.000,14.840,0.000,4
3755815385.382400,5000,1,299.999,0.000,40.479,3.123,0,0,300.000,300.000,14.700,0.000,4
3755815535.382400,5000,1,300.000,0.000,40.477,3.124,0,0,300.000,300.000,14.780,0.000,4