File: log/20231220.dat
[Header]
; Displex Transport Data File (default extension .dat)
; Copyright 2016, Hechang LEI, hlei@ruc.edu.cn. All rights reserved.
BYAPP, Displex, 2.0
INFO, 9T mag, Release 2.0.
INFO, Channel 1, Temperature Sensor
INFO, Sample 1 Length (cm): 0.000000; Width (cm): 0.000000; Thickness (cm): 0.000000.

[Data]
Timestamp(s),Field(Oe),Field Status,TempA(K),TempB(K),TempC(K),TempD(K),Ramp1,Ramp2,Setpoint1,Setpoint2,Output1(%),Output2(%),Temp Status,in plane position,out plane position
3785908994.141000,0,4,10.000,10.000,35.827,3.087,0,0,10.000,10.000,0.130,0.690,4,-91.957352,-21.979648
3785909051.670000,0,1,10.000,10.003,35.823,3.086,0,0,10.000,10.000,0.130,0.690,1,-91.957889,-21.979648
3785909111.670000,0,1,10.000,10.003,35.816,3.086,0,0,10.000,10.000,0.140,0.700,1,-91.956413,-21.979648
3785909171.670000,0,1,10.000,9.998,35.808,3.086,0,0,10.000,10.000,0.140,0.700,1,-91.955339,-21.979648
3785909231.670000,0,1,10.000,10.002,35.800,3.086,0,0,10.000,10.000,0.130,0.690,1,-91.957084,-21.979648
3785909291.670000,0,1,10.000,9.998,35.795,3.086,0,0,10.000,10.000,0.130,0.710,1,-91.959768,-21.979648
3785909351.670000,0,1,10.000,9.999,35.789,3.085,0,0,10.000,10.000,0.140,0.700,1,-91.959366,-21.979648
3785909411.670000,0,1,10.000,9.999,35.781,3.087,0,0,10.000,10.000,0.130,0.700,1,-91.959366,-21.979648
3785909471.670000,0,1,10.000,10.001,35.774,3.086,0,0,10.000,10.000,0.130,0.690,1,-91.958829,-21.979648
3785909531.670000,0,1,11.156,11.120,35.766,3.087,1,1,12.000,12.000,0.200,1.410,2,-92.001513,-21.979648
3785909591.670000,20,2,12.000,12.002,35.760,3.085,0,0,12.000,12.000,0.170,1.010,1,-92.018829,-21.979648
3785909651.670000,2757,2,12.000,12.001,35.752,3.778,0,0,12.000,12.000,0.160,0.960,1,-92.018695,-21.979648
3785909711.670000,5778,2,12.000,12.000,35.735,3.884,0,0,12.000,12.000,0.160,0.950,1,-92.019231,-21.979648
3785909771.670000,8731,2,12.000,12.004,35.733,3.727,0,0,12.000,12.000,0.150,0.900,1,-92.018963,-21.979648
3785909831.670000,11739,2,12.000,11.998,35.737,3.631,0,0,12.000,12.000,0.150,0.910,1,-92.021111,-21.979648
3785909891.670000,14775,2,12.000,12.000,35.740,3.570,0,0,12.000,12.000,0.150,0.900,1,-92.023258,-21.979648
3785909951.670000,17783,2,12.000,12.002,35.738,3.527,0,0,12.000,12.000,0.150,0.890,1,-92.051446,-21.979648
3785910011.670000,20740,2,12.000,12.000,35.738,3.493,0,0,12.000,12.000,0.150,0.900,1,-92.027822,-21.979648
3785910071.670000,23749,2,12.000,12.001,35.738,3.467,0,0,12.000,12.000,0.150,0.900,1,-92.029164,-21.979648
3785910131.670000,26760,2,12.000,12.003,35.741,3.445,0,0,12.000,12.000,0.150,0.890,1,-92.030775,-21.979648
3785910191.670000,29718,2,12.000,12.000,35.743,3.427,0,0,12.000,12.000,0.150,0.900,1,-92.033191,-21.979648
3785910251.670000,32730,2,12.000,12.000,35.744,3.413,0,0,12.000,12.000,0.150,0.890,1,-92.036010,-21.979648
3785910311.670000,35742,2,12.000,12.002,35.747,3.399,0,0,12.000,12.000,0.150,0.890,1,-92.034265,-21.979648
3785910371.670000,38701,2,12.000,12.001,35.751,3.387,0,0,12.000,12.000,0.150,0.890,1,-92.034533,-21.979648
3785910431.670000,41714,2,12.000,12.002,35.759,3.375,0,0,12.000,12.000,0.150,0.890,1,-92.036144,-21.979648
3785910491.670000,44728,2,11.999,11.999,35.766,3.366,0,0,12.000,12.000,0.150,0.890,1,-92.036950,-21.979648
3785910551.670000,47770,2,12.000,12.002,35.772,3.356,0,0,12.000,12.000,0.150,0.890,1,-92.039231,-21.979648
3785910611.670000,50734,2,12.000,12.001,35.780,3.347,0,0,12.000,12.000,0.150,0.880,1,-92.041647,-21.979648
3785910671.670000,53751,2,12.000,12.000,35.790,3.339,0,0,12.000,12.000,0.150,0.890,1,-92.043661,-21.979648
3785910731.670000,56770,2,12.000,12.001,35.802,3.333,0,0,12.000,12.000,0.150,0.880,1,-92.045137,-21.979648
3785910791.670000,59734,2,12.000,11.996,35.817,3.325,0,0,12.000,12.000,0.150,0.900,1,-92.044735,-21.979648
3785910851.670000,62752,2,12.000,11.998,35.832,3.320,0,0,12.000,12.000,0.150,0.890,1,-92.049567,-21.979648
3785910911.670000,65772,2,12.000,11.998,35.850,3.314,0,0,12.000,12.000,0.150,0.900,1,-92.048359,-21.979648
3785910971.670000,68738,2,12.000,12.003,35.869,3.307,0,0,12.000,12.000,0.150,0.880,1,-92.051178,-21.979648
3785911031.670000,71757,2,11.999,11.995,35.894,3.300,0,0,12.000,12.000,0.160,0.900,1,-92.050775,-21.979648
3785911091.670000,74780,2,12.000,11.999,35.918,3.296,0,0,12.000,12.000,0.150,0.890,1,-92.053191,-21.979648
3785911151.670000,77826,2,12.000,12.003,35.945,3.290,0,0,12.000,12.000,0.150,0.880,1,-92.054668,-21.979648
3785911211.670000,80788,2,12.000,11.997,35.973,3.284,0,0,12.000,12.000,0.150,0.890,1,-92.055741,-21.979648
3785911271.670000,83806,2,12.000,11.998,36.006,3.279,0,0,12.000,12.000,0.150,0.890,1,-92.057218,-21.979648
3785911331.670000,86820,2,12.000,12.001,36.043,3.273,0,0,12.000,12.000,0.150,0.880,1,-92.057755,-21.979648
3785911391.670000,89775,2,12.000,11.998,36.079,3.269,0,0,12.000,12.000,0.150,0.890,1,-92.058158,-21.979648
3785911451.670000,90000,1,12.000,12.005,36.122,3.133,0,0,12.000,12.000,0.150,0.840,1,-93.285404,-21.979648
3785911511.670000,90000,1,12.000,11.999,36.161,3.105,0,0,12.000,12.000,0.150,0.840,1,-98.024995,-21.979648
3785911571.670000,90000,1,12.000,11.996,36.197,3.099,0,0,12.000,12.000,0.160,0.890,1,-101.460292,-21.979648
3785911631.670000,90000,1,12.000,12.000,36.229,3.100,0,0,12.000,12.000,0.150,0.890,1,-100.496535,-21.979648
3785911691.670000,90000,1,12.000,12.001,36.259,3.100,0,0,12.000,12.000,0.150,0.850,1,-98.452779,-21.979648
3785911751.670000,90000,1,12.000,12.003,36.280,3.099,0,0,12.000,12.000,0.150,0.890,1,-98.799490,-21.979648
3785911811.670000,90000,1,12.000,11.998,36.303,3.100,0,0,12.000,12.000,0.150,0.890,1,-96.523386,-21.979648
3785911871.670000,90000,1,12.000,11.991,36.327,3.099,0,0,12.000,12.000,0.150,0.890,1,-95.905400,-21.979648
3785911931.670000,90000,1,12.000,11.996,36.346,3.100,0,0,12.000,12.000,0.150,0.890,1,-93.251042,-21.979648
3785911991.670000,90000,1,12.000,12.004,36.365,3.101,0,0,12.000,12.000,0.150,0.890,1,-94.037752,-21.979648
3785912051.670000,90000,1,12.000,12.002,36.382,3.101,0,0,12.000,12.000,0.150,0.890,1,-94.832113,-21.979648
3785912111.670000,90000,1,12.000,12.002,36.400,3.101,0,0,12.000,12.000,0.150,0.880,1,-93.126210,-21.979648
3785912171.670000,90000,1,12.000,12.000,36.416,3.099,0,0,12.000,12.000,0.150,0.890,1,-93.901242,-21.979648
3785912231.670000,90000,1,12.000,11.997,36.428,3.101,0,0,12.000,12.000,0.150,0.880,1,-90.714938,-21.979648
3785912291.670000,90000,1,12.000,12.002,36.440,3.100,0,0,12.000,12.000,0.150,0.880,1,-91.520306,-21.979648
3785912351.670000,90000,1,12.000,11.998,36.451,3.102,0,0,12.000,12.000,0.150,0.890,1,-92.367553,-21.979648
3785912411.670000,90000,1,12.001,12.010,36.464,3.100,0,0,12.000,12.000,0.150,0.850,1,-92.452251,-21.979648
3785912471.670000,90000,1,12.000,11.996,36.472,3.099,0,0,12.000,12.000,0.150,0.880,1,-89.998832,-21.979648
3785912531.670000,90000,1,12.000,12.000,36.480,3.100,0,0,12.000,12.000,0.150,0.890,1,-90.836951,-21.979648
3785912591.670000,90000,1,12.000,12.002,36.491,3.100,0,0,12.000,12.000,0.150,0.850,1,-87.471587,-21.979648
3785912651.670000,90000,1,11.999,12.000,36.497,3.101,0,0,12.000,12.000,0.150,0.890,1,-88.255210,-21.979648
3785912711.670000,90000,1,12.000,11.998,36.507,3.100,0,0,12.000,12.000,0.150,0.890,1,-88.911987,-21.979648
3785912771.670000,90000,1,12.000,12.001,36.517,3.100,0,0,12.000,12.000,0.150,0.840,1,-84.632933,-21.979648
3785912831.670000,90000,1,12.000,11.997,36.523,3.100,0,0,12.000,12.000,0.150,0.890,1,-85.351321,-21.979648
3785912891.670000,90000,1,12.000,12.000,36.529,3.099,0,0,12.000,12.000,0.150,0.880,1,-86.097226,-21.979648
3785912951.670000,90000,1,12.000,12.000,36.536,3.101,0,0,12.000,12.000,0.150,0.900,1,-86.906890,-21.979648
3785913018.549000,90000,1,12.000,11.993,36.546,3.100,0,0,12.000,12.000,0.150,0.870,1,-81.661259,-21.979648
3785913078.549000,90000,1,12.000,12.002,36.552,3.103,0,0,12.000,12.000,0.150,0.890,1,-82.384077,-21.979648
3785913138.549000,90000,1,12.000,12.002,36.559,3.102,0,0,12.000,12.000,0.150,0.890,1,-83.117902,-21.979648
3785913198.549000,90000,1,12.000,11.999,36.563,3.101,0,0,12.000,12.000,0.150,0.890,1,-83.920853,-21.979648
3785913258.549000,90000,1,12.000,11.996,36.568,3.101,0,0,12.000,12.000,0.150,0.890,1,-84.936288,-21.979648
3785913318.549000,90000,1,12.000,11.999,36.575,3.101,0,0,12.000,12.000,0.150,0.890,1,-85.814408,-21.979648
3785913378.549000,90000,1,12.000,12.002,36.581,3.100,0,0,12.000,12.000,0.150,0.890,1,-84.348907,-21.979648
3785913438.549000,90000,1,12.000,12.000,36.586,3.100,0,0,12.000,12.000,0.150,0.860,1,-83.462733,-21.979648
3785913498.549000,90000,1,12.000,12.000,36.587,3.100,0,0,12.000,12.000,0.150,0.890,1,-83.510653,-21.979648
3785913558.549000,90000,1,12.000,12.003,36.592,3.100,0,0,12.000,12.000,0.150,0.870,1,-81.075220,-21.979648
3785913618.549000,90000,1,11.999,11.999,36.596,3.101,0,0,12.000,12.000,0.150,0.890,1,-78.809988,-21.979648
3785913678.549000,90000,1,12.000,12.003,36.599,3.101,0,0,12.000,12.000,0.150,0.880,1,-79.588511,-21.979648
3785913738.549000,90000,1,12.000,12.001,36.603,3.101,0,0,12.000,12.000,0.160,0.860,1,-78.832002,-21.979648
3785913798.549000,90000,1,12.000,12.006,36.607,3.101,0,0,12.000,12.000,0.150,0.850,1,-76.649052,-21.979648
3785913858.549000,90000,1,12.000,12.007,36.612,3.101,0,0,12.000,12.000,0.150,0.860,1,-75.219121,-21.979648
3785913919.409000,90000,1,12.000,11.997,36.617,3.101,0,0,12.000,12.000,0.150,0.850,1,-68.720472,-21.979648
3785913979.409000,90001,1,12.000,12.000,36.621,3.102,0,0,12.000,12.000,0.150,0.890,1,-69.388122,-21.979648
3785914039.409000,90001,1,12.000,12.002,36.625,3.104,0,0,12.000,12.000,0.150,0.890,1,-70.123960,-21.979648
3785914099.409000,90001,1,12.000,11.999,36.630,3.102,0,0,12.000,12.000,0.150,0.890,1,-71.044764,-21.979648
3785914159.409000,90000,1,12.000,12.002,36.636,3.102,0,0,12.000,12.000,0.150,0.890,1,-72.021139,-21.979648
3785914219.409000,90000,1,12.000,11.999,36.639,3.100,0,0,12.000,12.000,0.150,0.890,1,-73.017245,-21.979648
3785914279.409000,90001,1,12.000,12.002,36.641,3.101,0,0,12.000,12.000,0.150,0.890,1,-74.054827,-21.979648
3785914339.409000,90001,1,12.000,12.000,36.642,3.101,0,0,12.000,12.000,0.150,0.890,1,-74.911873,-21.979648
3785914399.409000,90001,1,12.000,12.000,36.644,3.101,0,0,12.000,12.000,0.150,0.890,1,-73.747579,-21.979648
3785914459.409000,90001,1,12.000,12.008,36.649,3.100,0,0,12.000,12.000,0.150,0.860,1,-72.306373,-21.979648
3785914519.409000,90001,1,12.000,12.002,36.648,3.102,0,0,12.000,12.000,0.150,0.880,1,-68.524633,-21.979648
3785914579.409000,90000,1,12.000,12.001,36.648,3.101,0,0,12.000,12.000,0.150,0.890,1,-69.140069,-21.979648
3785914639.409000,90000,1,12.000,12.003,36.650,3.101,0,0,12.000,12.000,0.150,0.890,1,-70.080739,-21.979648
3785914699.409000,90000,1,12.000,12.000,36.653,3.102,0,0,12.000,12.000,0.150,0.890,1,-70.996308,-21.979648
3785914759.409000,90000,1,12.000,12.003,36.656,3.102,0,0,12.000,12.000,0.150,0.890,1,-71.901676,-21.979648
3785914819.409000,90000,1,12.000,12.000,36.658,3.102,0,0,12.000,12.000,0.150,0.880,1,-70.182752,-21.979648
3785914879.409000,90000,1,12.000,11.998,36.660,3.102,0,0,12.000,12.000,0.150,0.900,1,-70.903556,-21.979648
3785914939.409000,90000,1,12.000,11.999,36.665,3.101,0,0,12.000,12.000,0.150,0.890,1,-68.964230,-21.979648
3785914999.409000,90000,1,12.000,12.000,36.669,3.102,0,0,12.000,12.000,0.150,0.890,1,-69.625437,-21.979648
3785915059.409000,90000,1,12.000,11.996,36.672,3.103,0,0,12.000,12.000,0.150,0.870,1,-68.485036,-21.979648
3785915119.409000,90000,1,12.000,12.000,36.674,3.101,0,0,12.000,12.000,0.150,0.890,1,-68.699533,-21.979648
3785915179.409000,90000,1,12.000,12.009,36.675,3.101,0,0,12.000,12.000,0.150,0.850,1,-65.565309,-21.979648
3785915239.409000,90000,1,12.000,11.999,36.679,3.100,0,0,12.000,12.000,0.150,0.850,1,-62.116589,-21.979648
3785915299.409000,90000,1,12.000,12.000,36.680,3.102,0,0,12.000,12.000,0.150,0.890,1,-62.587326,-21.979648
3785915359.409000,90000,1,12.000,11.998,36.681,3.101,0,0,12.000,12.000,0.150,0.890,1,-63.466520,-21.979648
3785915419.409000,90000,1,12.000,11.998,36.680,3.100,0,0,12.000,12.000,0.150,0.890,1,-64.277123,-21.979648
3785915479.409000,90000,1,12.000,12.010,36.683,3.101,0,0,12.000,12.000,0.150,0.850,1,-64.267324,-21.979648
3785915539.409000,90000,1,12.000,12.000,36.685,3.101,0,0,12.000,12.000,0.150,0.890,1,-62.582897,-21.979648
3785915599.409000,90000,1,12.000,12.001,36.686,3.101,0,0,12.000,12.000,0.150,0.880,1,-58.560084,-21.979648
3785915659.409000,90000,1,12.001,12.004,36.686,3.102,0,0,12.000,12.000,0.150,0.880,1,-59.328807,-21.979648
3785915719.409000,90000,1,12.000,11.999,36.689,3.100,0,0,12.000,12.000,0.150,0.890,1,-60.295652,-21.979648
3785915779.409000,90000,1,11.999,12.000,36.691,3.101,0,0,12.000,12.000,0.150,0.890,1,-61.363570,-21.979648
3785915839.409000,90000,1,12.000,12.006,36.695,3.102,0,0,12.000,12.000,0.150,0.860,1,-61.592563,-21.979648
3785915899.409000,90000,1,12.000,12.000,36.696,3.102,0,0,12.000,12.000,0.150,0.890,1,-60.499410,-21.979648
3785915959.409000,90000,1,11.999,11.998,36.698,3.102,0,0,12.000,12.000,0.160,0.870,1,-59.742364,-21.979648
3785916019.409000,90000,1,12.000,11.999,36.701,3.102,0,0,12.000,12.000,0.150,0.880,1,-58.191225,-21.979648
3785916079.409000,90000,1,12.000,11.997,36.703,3.102,0,0,12.000,12.000,0.150,0.900,1,-58.919949,-21.979648
3785916139.409000,90000,1,12.000,12.001,36.705,3.101,0,0,12.000,12.000,0.150,0.880,1,-56.486127,-21.979648
3785916199.409000,90000,1,12.000,11.998,36.704,3.103,0,0,12.000,12.000,0.150,0.900,1,-57.409750,-21.979648
3785916259.409000,90000,1,12.000,11.995,36.706,3.101,0,0,12.000,12.000,0.150,0.870,1,-53.864251,-21.979648
3785916319.409000,90000,1,12.000,12.002,36.707,3.102,0,0,12.000,12.000,0.150,0.880,1,-54.241700,-21.979648
3785916379.409000,90000,1,12.000,11.997,36.708,3.101,0,0,12.000,12.000,0.150,0.900,1,-55.081162,-21.979648
3785916439.409000,90000,1,12.000,12.004,36.708,3.100,0,0,12.000,12.000,0.150,0.870,1,-56.008007,-21.979648
3785916499.409000,90000,1,12.000,11.997,36.708,3.101,0,0,12.000,12.000,0.150,0.900,1,-56.918609,-21.979648
3785916559.409000,90000,1,12.000,11.999,36.709,3.101,0,0,12.000,12.000,0.150,0.890,1,-55.867067,-21.979648
3785916629.963000,90000,1,12.000,12.000,36.711,3.102,0,0,12.000,12.000,0.150,0.890,1,-52.994857,-21.979648
3785916689.963000,90000,1,12.000,11.998,36.712,3.102,0,0,12.000,12.000,0.150,0.890,1,-53.660225,-21.979648
3785916749.963000,90000,1,12.000,11.999,36.713,3.102,0,0,12.000,12.000,0.150,0.890,1,-54.485190,-21.979648
3785916809.963000,90000,1,12.000,11.996,36.716,3.101,0,0,12.000,12.000,0.150,0.860,1,-51.760764,-21.979648
3785916869.963000,90000,1,12.000,11.999,36.718,3.101,0,0,12.000,12.000,0.150,0.890,1,-52.106938,-21.979648
3785916929.963000,90000,1,12.000,12.000,36.719,3.100,0,0,12.000,12.000,0.150,0.880,1,-53.108548,-21.979648
3785916989.963000,90000,1,12.000,12.000,36.719,3.102,0,0,12.000,12.000,0.160,0.890,1,-53.900627,-21.979648
3785917049.963000,90000,1,12.000,11.999,36.721,3.101,0,0,12.000,12.000,0.150,0.890,1,-50.923718,-21.979648
3785917109.963000,90000,1,12.000,11.999,36.722,3.102,0,0,12.000,12.000,0.150,0.890,1,-51.723583,-21.979648
3785917169.963000,90000,1,12.000,12.002,36.723,3.101,0,0,12.000,12.000,0.150,0.890,1,-52.529757,-21.979648
3785917229.963000,90001,1,11.999,11.995,36.721,3.102,0,0,12.000,12.000,0.150,0.880,1,-51.928147,-21.979648
3785917289.963000,90001,2,12.000,11.999,36.720,3.101,0,0,12.000,12.000,0.150,0.890,1,-50.577813,-21.979648
3785917349.963000,90000,1,12.000,12.002,36.722,3.101,0,0,12.000,12.000,0.150,0.850,1,-49.655667,-21.979648
3785917409.963000,90000,1,12.000,11.995,36.722,3.102,0,0,12.000,12.000,0.150,0.870,1,-47.752448,-21.979648
3785917469.963000,90000,1,12.000,12.000,36.721,3.102,0,0,12.000,12.000,0.150,0.880,1,-48.234729,-21.979648
3785917529.963000,90000,1,12.000,12.003,36.721,3.102,0,0,12.000,12.000,0.150,0.890,1,-48.399427,-21.979648
3785917589.963000,90000,1,12.000,11.998,36.723,3.101,0,0,12.000,12.000,0.150,0.890,1,-46.914999,-21.979648
3785917649.963000,90000,1,12.000,12.002,36.726,3.102,0,0,12.000,12.000,0.150,0.880,1,-45.748558,-21.979648
3785917709.963000,90000,1,12.000,11.997,36.728,3.103,0,0,12.000,12.000,0.150,0.850,1,-36.229914,-21.979648
3785917788.877000,90000,1,12.000,12.000,36.727,3.102,0,0,12.000,12.000,0.150,0.890,1,-36.749242,-21.979648
3785917848.877000,90000,1,12.000,11.999,36.731,3.103,0,0,12.000,12.000,0.150,0.890,1,-37.272597,-21.979648
3785917908.877000,90000,1,12.000,11.999,36.734,3.103,0,0,12.000,12.000,0.150,0.880,1,-38.110314,-21.979648
3785917968.877000,90000,1,12.000,11.999,36.735,3.102,0,0,12.000,12.000,0.150,0.890,1,-38.844675,-21.979648
3785918028.877000,90000,1,12.000,11.999,36.734,3.103,0,0,12.000,12.000,0.150,0.890,1,-39.627895,-21.979648
3785918088.877000,90001,1,12.000,12.002,36.734,3.101,0,0,12.000,12.000,0.150,0.890,1,-40.398633,-21.979648
3785918148.877000,90000,1,12.000,11.999,36.734,3.101,0,0,12.000,12.000,0.150,0.890,1,-41.124135,-21.979648
3785918208.877000,90000,1,12.000,12.002,36.734,3.101,0,0,12.000,12.000,0.150,0.880,1,-41.941449,-21.979648
3785918268.877000,90000,1,12.000,12.001,36.732,3.102,0,0,12.000,12.000,0.150,0.880,1,-42.877018,-21.979648
3785918328.877000,90000,1,12.000,12.002,36.730,3.101,0,0,12.000,12.000,0.150,0.880,1,-43.563595,-21.979648
3785918388.877000,90000,1,12.000,12.001,36.732,3.101,0,0,12.000,12.000,0.150,0.840,1,-38.834339,-21.979648
3785918448.877000,90000,1,12.000,12.001,36.733,3.101,0,0,12.000,12.000,0.160,0.880,1,-39.424137,-21.979648
3785918508.877000,90000,1,12.000,12.003,36.732,3.102,0,0,12.000,12.000,0.150,0.880,1,-39.929506,-21.979648
3785918568.877000,90000,1,11.999,11.993,36.731,3.103,0,0,12.000,12.000,0.150,0.900,1,-40.798095,-21.979648
3785918628.877000,90000,1,12.000,12.000,36.735,3.102,0,0,12.000,12.000,0.150,0.890,1,-41.526148,-21.979648
3785918688.877000,90000,1,12.000,12.002,36.737,3.102,0,0,12.000,12.000,0.150,0.890,1,-42.252455,-21.979648
3785918748.880000,90000,1,12.000,12.002,36.738,3.102,0,0,12.000,12.000,0.150,0.860,1,-41.744268,-21.979648
3785918808.880000,90000,1,12.000,11.997,36.738,3.102,0,0,12.000,12.000,0.150,0.860,1,-39.093936,-21.979648
3785918868.880000,90000,1,12.000,12.001,36.738,3.102,0,0,12.000,12.000,0.150,0.890,1,-39.559171,-21.979648
3785918928.880000,90000,1,12.000,12.001,36.740,3.101,0,0,12.000,12.000,0.150,0.890,1,-40.274740,-21.979648
3785918988.880000,90000,1,12.000,11.999,36.740,3.102,0,0,12.000,12.000,0.150,0.890,1,-40.787894,-21.979648
3785919048.880000,90000,1,12.000,11.999,36.738,3.101,0,0,12.000,12.000,0.150,0.890,1,-38.380649,-21.979648
3785919108.880000,90000,1,12.000,11.998,36.738,3.100,0,0,12.000,12.000,0.150,0.890,1,-39.021051,-21.979648
3785919168.880000,90000,1,12.000,11.999,36.739,3.100,0,0,12.000,12.000,0.150,0.890,1,-39.832325,-21.979648
3785919228.880000,90000,1,11.999,11.996,36.738,3.102,0,0,12.000,12.000,0.150,0.890,1,-38.917427,-21.979648
3785919288.880000,90000,1,12.000,11.992,36.737,3.101,0,0,12.000,12.000,0.150,0.890,1,-35.531391,-21.979648
3785919348.880000,90000,1,12.000,12.000,36.736,3.102,0,0,12.000,12.000,0.150,0.890,1,-36.131122,-21.979648
3785919408.880000,90000,1,12.000,12.001,36.739,3.101,0,0,12.000,12.000,0.150,0.890,1,-36.828973,-21.979648
3785919468.880000,90000,1,12.000,11.999,36.742,3.103,0,0,12.000,12.000,0.150,0.890,1,-37.548301,-21.979648
3785919528.880000,90000,1,12.000,11.999,36.743,3.104,0,0,12.000,12.000,0.150,0.860,1,-35.109781,-21.979648
3785919588.880000,90000,1,12.000,11.997,36.742,3.104,0,0,12.000,12.000,0.150,0.900,1,-35.476089,-21.979648
3785919648.880000,90000,1,12.000,11.998,36.743,3.104,0,0,12.000,12.000,0.150,0.890,1,-36.150987,-21.979648
3785919708.880000,90000,1,12.000,12.002,36.746,3.104,0,0,12.000,12.000,0.150,0.890,1,-36.844544,-21.979648
3785919768.880000,90000,1,12.000,11.994,36.746,3.104,0,0,12.000,12.000,0.150,0.890,1,-34.520788,-21.979648
3785919828.880000,90000,1,12.000,12.001,36.745,3.103,0,0,12.000,12.000,0.150,0.890,1,-35.165486,-21.979648
3785919888.880000,90000,1,12.000,12.000,36.744,3.102,0,0,12.000,12.000,0.150,0.890,1,-35.896625,-21.979648
3785919948.880000,90000,1,12.000,11.997,36.745,3.103,0,0,12.000,12.000,0.150,0.860,1,-32.407234,-21.979648
3785920008.880000,90000,1,12.001,12.000,36.745,3.104,0,0,12.000,12.000,0.150,0.890,1,-32.945220,-21.979648
3785920068.880000,90000,1,12.000,12.001,36.744,3.101,0,0,12.000,12.000,0.160,0.890,1,-33.541595,-21.979648
3785920128.880000,90000,1,12.000,11.996,36.742,3.103,0,0,12.000,12.000,0.150,0.870,1,-31.704819,-21.979648
3785920188.880000,90000,1,12.000,11.998,36.743,3.101,0,0,12.000,12.000,0.150,0.890,1,-32.087772,-21.979648
3785920248.880000,90000,1,12.000,11.999,36.744,3.102,0,0,12.000,12.000,0.150,0.900,1,-32.631664,-21.979648
3785920308.880000,90000,1,12.000,11.998,36.745,3.104,0,0,12.000,12.000,0.150,0.870,1,-29.109252,-21.979648
3785920368.880000,90000,1,12.000,12.002,36.744,3.103,0,0,12.000,12.000,0.150,0.890,1,-29.448715,-21.979648
3785920428.880000,90000,1,12.000,12.000,36.744,3.102,0,0,12.000,12.000,0.150,0.890,1,-30.373143,-21.979648
3785920488.880000,90000,1,12.000,12.000,36.746,3.103,0,0,12.000,12.000,0.150,0.890,1,-31.113545,-21.979648
3785920548.880000,90000,1,12.001,12.011,36.749,3.104,0,0,12.000,12.000,0.150,0.860,1,-31.121464,-21.979648
3785920608.880000,90000,1,12.000,11.998,36.748,3.104,0,0,12.000,12.000,0.150,0.890,1,-29.583883,-21.979648
3785920668.880000,90000,1,12.000,12.004,36.748,3.104,0,0,12.000,12.000,0.150,0.860,1,-29.086434,-21.979648
3785920728.880000,90000,1,12.000,11.991,36.750,3.103,0,0,12.000,12.000,0.150,0.900,1,-26.043888,-21.979648
3785920788.880000,90000,1,12.000,11.999,36.752,3.103,0,0,12.000,12.000,0.150,0.890,1,-26.544424,-21.979648
3785920848.880000,90000,1,12.000,12.000,36.751,3.105,0,0,12.000,12.000,0.160,0.900,1,-27.389926,-21.979648
3785920908.880000,90000,1,12.001,12.010,36.752,3.104,0,0,12.000,12.000,0.150,0.860,1,-27.535161,-21.979648
3785920968.880000,90000,1,12.000,12.001,36.751,3.101,0,0,12.000,12.000,0.150,0.890,1,-26.702007,-21.979648
3785921028.880000,90000,1,12.000,11.989,36.750,3.103,0,0,12.000,12.000,0.150,0.890,1,-25.689391,-21.979648
3785921088.880000,90000,1,12.000,11.996,36.750,3.103,0,0,12.000,12.000,0.150,0.870,1,-21.769934,-21.979648
3785921148.880000,90000,1,12.000,11.999,36.748,3.104,0,0,12.000,12.000,0.150,0.890,1,-22.277853,-21.979648
3785921208.880000,90000,1,12.000,12.003,36.747,3.102,0,0,12.000,12.000,0.150,0.890,1,-22.951543,-21.979648
3785921268.880000,90000,1,12.000,12.000,36.747,3.103,0,0,12.000,12.000,0.150,0.890,1,-23.884159,-21.979648
3785921328.880000,90000,1,12.000,11.995,36.749,3.103,0,0,12.000,12.000,0.150,0.900,1,-24.799728,-21.979648
3785921388.880000,90000,1,12.000,11.997,36.750,3.103,0,0,12.000,12.000,0.150,0.890,1,-22.736241,-21.979648
3785921448.880000,90000,1,12.000,11.997,36.751,3.104,0,0,12.000,12.000,0.150,0.900,1,-23.198120,-21.979648
3785921508.880000,90000,1,12.001,12.009,36.756,3.103,0,0,12.000,12.000,0.150,0.860,1,-23.311811,-21.979648
3785921568.880000,90000,1,12.000,12.001,36.758,3.104,0,0,12.000,12.000,0.150,0.890,1,-21.025908,-21.979648
3785921628.880000,90000,1,12.000,11.997,36.759,3.104,0,0,12.000,12.000,0.150,0.900,1,-21.738256,-21.979648
3785921688.880000,90000,1,12.000,11.998,36.759,3.104,0,0,12.000,12.000,0.150,0.890,1,-22.549396,-21.979648
3785921748.880000,90000,1,12.000,11.997,36.762,3.103,0,0,12.000,12.000,0.150,0.860,1,-20.089668,-21.979648
3785921808.880000,90000,1,12.000,12.001,36.761,3.103,0,0,12.000,12.000,0.160,0.890,1,-20.662284,-21.979648
3785921868.880000,90000,1,12.000,11.999,36.759,3.103,0,0,12.000,12.000,0.150,0.900,1,-21.429532,-21.979648
3785921928.880000,90000,1,12.000,11.997,36.758,3.103,0,0,12.000,12.000,0.150,0.870,1,-19.319870,-21.979648
3785921988.880000,90000,1,12.000,12.002,36.758,3.103,0,0,12.000,12.000,0.150,0.890,1,-19.769131,-21.979648
3785922048.880000,90000,1,12.000,12.000,36.759,3.103,0,0,12.000,12.000,0.150,0.890,1,-20.656781,-21.979648
3785922108.880000,90000,1,12.000,12.001,36.759,3.103,0,0,12.000,12.000,0.150,0.890,1,-20.910338,-21.979648
3785922174.746000,90000,1,12.000,12.003,36.759,3.103,0,0,12.000,12.000,0.150,0.900,1,-20.911009,-21.979648
3785922234.746000,90000,1,12.000,12.003,36.759,3.103,0,0,12.000,12.000,0.150,0.840,1,-24.613688,-21.979648
3785922294.746000,90000,1,12.000,12.000,36.762,3.102,0,0,12.000,12.000,0.150,0.840,1,-25.678519,-21.979648
3785922354.746000,90000,1,12.000,12.005,36.763,3.104,0,0,12.000,12.000,0.150,0.830,1,-22.272618,-21.979648
3785922414.746000,90000,1,12.000,12.006,36.762,3.105,0,0,12.000,12.000,0.150,0.880,1,-19.551816,-21.979648
3785922488.307000,90000,1,12.000,12.000,36.763,3.105,0,0,12.000,12.000,0.150,0.870,1,-19.093025,-21.979648
3785922548.307000,90000,1,12.000,11.998,36.766,3.104,0,0,12.000,12.000,0.150,0.860,1,-14.817863,-21.979648
3785922608.307000,90000,1,12.001,12.011,36.767,3.105,0,0,12.000,12.000,0.150,0.850,1,-17.472356,-21.979648
3785922668.307000,90000,1,12.000,12.011,36.769,3.105,0,0,12.000,12.000,0.150,0.840,1,-16.528330,-21.979648
3785922728.307000,90000,1,12.000,11.998,36.769,3.103,0,0,12.000,12.000,0.150,0.860,1,-13.830750,-21.979648
3785922788.307000,90000,1,12.000,11.996,36.767,3.103,0,0,12.000,12.000,0.150,0.870,1,-13.947126,-21.979648
3785922848.307000,90000,1,11.999,11.996,36.768,3.102,0,0,12.000,12.000,0.150,0.890,1,-12.098269,-21.979648
3785922908.307000,90000,1,11.999,11.988,36.767,3.104,0,0,12.000,12.000,0.150,0.910,1,-10.994915,-21.979648
3785922968.307000,90000,1,11.999,11.996,36.766,3.104,0,0,12.000,12.000,0.150,0.870,1,-9.013710,-21.979648
3785923028.307000,90000,1,12.000,11.992,36.765,3.103,0,0,12.000,12.000,0.150,0.890,1,-7.980960,-21.979648
3785923088.307000,90000,1,12.001,12.010,36.765,3.103,0,0,12.000,12.000,0.150,0.850,1,-6.142573,-21.979648
3785923148.307000,90000,1,12.000,11.992,36.766,3.102,0,0,12.000,12.000,0.150,0.890,1,-4.909689,-21.979648
3785923178.307000,90000,1,12.000,11.994,36.767,3.102,0,0,12.000,12.000,0.160,0.870,1,-3.926469,-21.979648