File: lib/Lake Shore 335/20220810-ch1_Cernox-1050.dat
[Header]
; AC Transport Data File (default extension .dat)
; Copyright 1998, Quantum Design, Inc. All rights reserved.
TITLE,AC Transport Datafile
FILEOPENTIME,19082565.45,08/10/2022,8:45 am
BYAPP,ACTRANSPORT,2.0,1.1
INFO,PPMS AC Transport Option Release 2.2.5. Build 2,APPNAME
INFO,Cernox-1050,SAMPLE1_MATERIAL
INFO,SN-X180867,SAMPLE1_COMMENT
INFO,1,SAMPLE1_LEAD_SEPARATION
INFO,1,SAMPLE1_CROSS_SECTION
INFO,,SAMPLE2_MATERIAL
INFO,,SAMPLE2_COMMENT
INFO,1,SAMPLE2_LEAD_SEPARATION
INFO,1,SAMPLE2_CROSS_SECTION
DATATYPE,COMMENT,1
DATATYPE,TIME,2
FIELDGROUP,ACResist,2,4,5,6,7,8,9,10,13,14,15,16,53
FIELDGROUP,ACHall,2,4,5,6,7,8,9,10,17,18,19,20,53
FIELDGROUP,ACIVcurve,2,4,5,6,7,8,9,10,53
FIELDGROUP,ACCritCurrent,2,4,5,6,7,8,9,21,22,23,24,53
STARTUPGROUP,All
STARTUPAXIS,X,2
STARTUPAXIS,Y1,3
[Data]
Comment,Time Stamp (sec),Status (code),Temperature (K),Magnetic Field (Oe),Sample Position (deg),Excitation (mA),Frequency (Hz),Volts ch1,Volts ch2,V Std.Dev. ch1,V Std.Dev. ch2,Res. ch1 (ohm-cm),Res. ch2 (ohm-cm),Res. Std.Dev. ch1,Res. Std.Dev. ch2,Hall ch1 (cm^3/coul),Hall ch2 (cm^3/coul),Hall Std.Dev. ch1,Hall Std.Dev. ch2,Crit.Cur. ch1 (mA),Crit.Cur. ch2 (mA),C.Cur. Std.Dev. ch1,C.Cur. Std.Dev. ch2,ACT Status (code),ACT Gain,2nd Harm. ch1 (dB),2nd Harm. ch2 (dB),3rd Harm. ch1 (dB),3rd Harm. ch2 (dB),Quad.Error ch1 (ohm-cm-rad),Quad.Error ch2 (ohm-cm-rad),Drive Signal ch1 (V),Drive Signal ch2 (V),Bridge 1 Resistance (ohms),Bridge 1 Excitation (uA),Bridge 2 Resistance (ohms),Bridge 2 Excitation (uA),Bridge 3 Resistance (ohms),Bridge 3 Excitation (uA),Bridge 4 Resistance (ohms),Bridge 4 Excitation (uA),Signal 1 Vin (V),Signal 2 Vin (V),Digital Inputs (code),Drive 1 Iout (mA),Drive 1 Ipower (watts),Drive 2 Iout (mA),Drive 2 Ipower (watts),Pressure (),Map 20 (),Map 21 (),Map 22 (),Map 23 (),Map 24 (),Map 25 (),Map 26 (),Map 27 (),Map 28 (),Map 29 ()
,19083705.795,4370,350.00955,0,0,0.0102198995029309,17,0.000570455729242511,,3.03709786234352E-7,,56.2579010944816,,0.0299515788237834,,,,,,,,,,0,5000,-75.3924300888781,,-73.4608503503067,,0.000167901441520811,,0.000570456576460367,,,,,,,,,,,,,,,,,,,,,,,,,,,
,19083852.83,4370,340.3696,0,0,0.0102198995029309,17,0.000576770088502516,,3.04908220682931E-7,,56.8855791512921,,0.0300723907935216,,,,,,,,,,0,5000,-74.9230690170739,,-73.4854344101846,,0.000167978503067584,,0.000576770927214576,,,,,,,,,,,,,,,,,,,,,,,,,,,
,19083993.165,4374,329.36965,0,0,0.0102198995029309,17,0.000594802217416623,,3.13096962273826E-7,,58.6786634914485,,0.0308877207450982,,,,,,,,,,0,5000,-75.5954887962758,,-73.3955953061465,,0.000172526856068952,,0.000594803075341071,,,,,,,,,,,,,,,,,,,,,,,,,,,
,19084270.925,4370,318.97545,0,0,0.0102198995029309,17,0.00061505105249599,,3.21781149781287E-7,,60.6932385301238,,0.0317533190139204,,,,,,,,,,0,5000,-76.9294160165647,,-73.6310040760543,,0.000177221731090129,,0.000615051927945277,,,,,,,,,,,,,,,,,,,,,,,,,,,
,19084402.185,4370,307.735,0,0,0.0102198995029309,17,0.000628977531140403,,3.26931149701212E-7,,62.0794510755359,,0.0322677291114948,,,,,,,,,,0,5000,-75.9469217226863,,-73.6235236285929,,0.000183827367313456,,0.000628978452212031,,,,,,,,,,,,,,,,,,,,,,,,,,,
,19084530.4,4370,296.93205,0,0,0.0102198995029309,17,0.000647295111413336,,3.36685352960893E-7,,63.9035575049575,,0.0332388730957437,,,,,,,,,,0,5000,-75.7820897852273,,-73.6505818806588,,0.000189909851575991,,0.000647296066627736,,,,,,,,,,,,,,,,,,,,,,,,,,,
,19084659.01,4370,286.0113,0,0,0.0102198995029309,17,0.000667538867487985,,3.49218130656368E-7,,65.9205519741876,,0.0344858098493791,,,,,,,,,,0,5000,-75.9272424986387,,-73.7677322581598,,0.000194429957286468,,0.000667539838351114,,,,,,,,,,,,,,,,,,,,,,,,,,,
,19084791.705,4370,275.15975,0,0,0.0102198995029309,17,0.000690072702214066,,3.57474208352221E-7,,68.1670479569638,,0.0353121133125105,,,,,,,,,,0,5000,-76.2490023489571,,-73.7974955638262,,0.000202713241040011,,0.000690073723100858,,,,,,,,,,,,,,,,,,,,,,,,,,,
,19084927.825,4370,263.77905,0,0,0.0102198995029309,17,0.000714168094587785,,3.76939722222529E-7,,70.5707724787313,,0.0372473835053792,,,,,,,,,,0,5000,-76.5988651504568,,-72.6588671153409,,0.000196340979794443,,0.000714169019988226,,,,,,,,,,,,,,,,,,,,,,,,,,,
,19085064.335,4370,252.42545,0,0,0.0102198995029309,17,0.000742211160642746,,3.93779523947768E-7,,73.3703309646847,,0.038926518190151,,,,,,,,,,0,5000,-76.8662674262988,,-73.3527163847202,,0.000204911005474715,,0.000742212130507828,,,,,,,,,,,,,,,,,,,,,,,,,,,
,19085198.945,4370,241.22675,0,0,0.0102198995029309,17,0.000771185168094524,,4.0065335400948E-7,,76.2651100290215,,0.0396219147854594,,,,,,,,,,0,5000,-76.5373855980721,,-73.7802958389952,,0.000210725904177292,,0.000771186155249696,,,,,,,,,,,,,,,,,,,,,,,,,,,
,19085330.655,4370,230.21005,0,0,0.0102198995029309,17,0.000803117684242167,,4.11513792261223E-7,,79.4581645821887,,0.0407139440722199,,,,,,,,,,0,5000,-77.1506475064334,,-74.1671446284633,,0.000220232631192876,,0.000803118719604558,,,,,,,,,,,,,,,,,,,,,,,,,,,
,19085457.775,4370,219.6677,0,0,0.0102198995029309,17,0.000845097469145657,,4.36308083062218E-7,,82.6984977007268,,0.0426956262475236,,,,,,,,,,0,2500,-75.0588778266814,,-71.9113088750491,,0.000257249920045487,,0.000845098811638164,,,,,,,,,,,,,,,,,,,,,,,,,,,
,19085565.11,4370,210.69235,0,0,0.0102198995029309,17,0.000875695153852981,,4.12579905042076E-7,,85.692955413203,,0.0403737892288442,,,,,,,,,,0,2500,-73.7697046267768,,-74.1203834422118,,0.000275141896021675,,0.000875696635922778,,,,,,,,,,,,,,,,,,,,,,,,,,,
,19085674.64,4370,201.55385,0,0,0.0102198995029309,17,0.000910412332374779,,4.33326713581497E-7,,89.0905920889141,,0.0424041559293473,,,,,,,,,,0,2500,-77.8100435622123,,-73.2378421748734,,0.000289620822087037,,0.000910413911910947,,,,,,,,,,,,,,,,,,,,,,,,,,,
,19085782.825,4370,192.55745,0,0,0.0102198995029309,17,0.000946573020963563,,4.47701395675772E-7,,92.6295251321183,,0.0438109844171947,,,,,,,,,,0,2500,-79.3175897699129,,-74.1812640402025,,0.000300834584675552,,0.000946574660079021,,,,,,,,,,,,,,,,,,,,,,,,,,,
,19085892.685,4370,183.40045,0,0,0.0102198995029309,17,0.000987050111371574,,4.67374311040068E-7,,96.5909218420939,,0.0457363187347195,,,,,,,,,,0,2500,-76.0849209139852,,-74.7811066919836,,0.000311433384866891,,0.000987051795981205,,,,,,,,,,,,,,,,,,,,,,,,,,,
,19086004.68,4370,174.07465,0,0,0.0102198995029309,17,0.00103172944595068,,4.69371108546818E-7,,100.963620200653,,0.0459319286427115,,,,,,,,,,0,2500,-76.368114934958,,-76.7307666321642,,0.000329861888979309,,0.00103173125398469,,,,,,,,,,,,,,,,,,,,,,,,,,,
,19086121.57,4370,164.29055,0,0,0.0102198995029309,17,0.00108365853790553,,4.94873201771962E-7,,106.045891355648,,0.0484277809613062,,,,,,,,,,0,2500,-76.3361791816705,,-75.5131057589775,,0.000345546508590253,,0.00108366042689137,,,,,,,,,,,,,,,,,,,,,,,,,,,
,19086232.805,4370,155.0516,0,0,0.0102198995029309,17,0.0011380425102033,,5.12453613840773E-7,,111.368478009299,,0.0501484609923982,,,,,,,,,,0,2500,-76.6346195965174,,-75.0739931976357,,0.000361259957377071,,0.00113804447622955,,,,,,,,,,,,,,,,,,,,,,,,,,,
,19086348.07,4370,145.43855,0,0,0.0102198995029309,17,0.00120134412879613,,5.46519060525063E-7,,117.563913570733,,0.0534824344549367,,,,,,,,,,0,2500,-77.1528932216958,,-75.1883934491513,,0.000381309104087874,,0.00120134620368606,,,,,,,,,,,,,,,,,,,,,,,,,,,
,19086462.64,4370,135.9161,0,0,0.0102198995029309,17,0.00127106005336447,,5.7681039837927E-7,,124.387220618232,,0.0564471509596735,,,,,,,,,,0,2500,-75.7404990254724,,-77.8471990158748,,0.000402864714992796,,0.00127106224243895,,,,,,,,,,,,,,,,,,,,,,,,,,,
,19086576.105,4370,126.44505,0,0,0.0102198995029309,17,0.0013499731174548,,6.35937964005477E-7,,132.110796475444,,0.0622339275437015,,,,,,,,,,0,2500,-76.2345670375988,,-74.8501549235975,,0.000423512049767704,,0.00134997539524948,,,,,,,,,,,,,,,,,,,,,,,,,,,
,19086683.415,4370,117.52985,0,0,0.0102198995029309,17,0.00143334158078587,,6.68004594078881E-7,,140.270577366273,,0.0653725780392995,,,,,,,,,,0,2500,-74.9835735356261,,-74.5690105367015,,0.000446307332948399,,0.00143334396325073,,,,,,,,,,,,,,,,,,,,,,,,,,,
,19086794.54,4370,108.2196,0,0,0.0102198995029309,17,0.00153304790844142,,7.1014885860163E-7,,150.029627157445,,0.0694976244966126,,,,,,,,,,0,2500,-76.1657994726143,,-76.0569603368591,,0.000482064360832314,,0.00153305050717929,,,,,,,,,,,,,,,,,,,,,,,,,,,
,19086906.21,4370,98.9251,0,0,0.0102198995029309,17,0.00164861022752972,,7.57674862890888E-7,,161.340877146029,,0.0741495573684218,,,,,,,,,,0,2500,-77.3256439069646,,-77.1526209842256,,0.000519783278787779,,0.00164861303706681,,,,,,,,,,,,,,,,,,,,,,,,,,,
,19087025.92,4370,88.96385,0,0,0.0102198995029309,17,0.00179389824996495,,8.18195816708488E-7,,175.56206010569,,0.080073607169436,,,,,,,,,,0,2500,-77.5850665916662,,-75.5958002788516,,0.000559300851756351,,0.00179390123948392,,,,,,,,,,,,,,,,,,,,,,,,,,,
,19087151.885,4370,78.5857,0,0,0.0102198995029309,17,0.00196871571645954,,9.31754398818486E-7,,192.67422350253,,0.0911887627100959,,,,,,,,,,0,1250,-74.9813851924285,,-75.8604428246829,,0.000619725378145331,,0.00196871906090181,,,,,,,,,,,,,,,,,,,,,,,,,,,
,19087260.915,4370,70.15235,0,0,0.0102198995029309,17,0.00215490571364122,,1.00109224585793E-6,,210.9002685676,,0.0979765797919186,,,,,,,,,,0,1250,-77.5972919287274,,-76.265963388885,,0.000652548565449076,,0.00215490910134621,,,,,,,,,,,,,,,,,,,,,,,,,,,
,19087372.685,4370,61.54315,0,0,0.0102198995029309,17,0.00238936083597001,,1.13193329461875E-6,,233.851947559226,,0.110784596272683,,,,,,,,,,0,1250,-78.2558011448953,,-75.4412093466234,,0.000735404509076799,,0.00238936471639241,,,,,,,,,,,,,,,,,,,,,,,,,,,
,19087484.12,4370,53.11685,0,0,0.0102198995029309,17,0.00269117737218443,,1.25602107965999E-6,,263.399501354762,,0.122933109577194,,,,,,,,,,0,1250,-75.9069841126755,,-75.707198040651,,0.000817433917938632,,0.00269118162886599,,,,,,,,,,,,,,,,,,,,,,,,,,,
,19087587.94,4370,45.50635,0,0,0.0102198995029309,17,0.00304058254634416,,1.39839416750468E-6,,297.608211104923,,0.136872753103031,,,,,,,,,,0,1250,-77.5086542222661,,-76.1238307139549,,0.000940379119553577,,0.00304058753240209,,,,,,,,,,,,,,,,,,,,,,,,,,,
,19087695.855,4370,37.6161,0,0,0.0102198995029309,17,0.00353214732791134,,1.63349689542609E-6,,345.739267522248,,0.159892290363687,,,,,,,,,,0,1250,-77.1136389871911,,-75.1521721505476,,0.0010732756316403,,0.00353215291894239,,,,,,,,,,,,,,,,,,,,,,,,,,,
,19087823.23,4370,28.25355,0,0,0.0102198995029309,17,0.00416830805575167,,2.25705990351927E-6,,432.569634696594,,0.234227776483204,,,,,,,,,,0,1000,-68.1832694603089,,-74.3158965864531,,0.00145888652795609,,0.00416831680944411,,,,,,,,,,,,,,,,,,,,,,,,,,,
,19087942.94,4370,19.46705,0,0,0.0102198995029309,17,0.00584331670792968,,2.68258832079378E-6,,572.099766533059,,0.262642881892176,,,,,,,,,,0,500,-76.0274864942304,,-76.0937729370968,,0.00184112660187488,,0.00584332665318714,,,,,,,,,,,,,,,,,,,,,,,,,,,
,19088049.5,4370,11.76625,0,0,0.0102198995029309,17,0.00861039393673026,,3.87460065239628E-6,,843.253309404438,,0.379455870891206,,,,,,,,,,0,500,-75.5049396374111,,-77.324807296359,,0.00264678412931616,,0.0086104078850595,,,,,,,,,,,,,,,,,,,,,,,,,,,
,19088836.945,4375,8.39165,0,0,0.0102198995029309,17,0.0115255789711005,,5.45721486276979E-6,,1129.08613927993,,0.534607196074514,,,,,,,,,,0,250,-75.6017890788941,,-75.8191619785608,,0.0032119300505787,,0.0115255943164801,,,,,,,,,,,,,,,,,,,,,,,,,,,
,19089319.635,4375,7.29625,0,0,0.0102198995029309,17,0.0130350653818789,,6.14879445827147E-6,,1277.15762914419,,0.602449571643992,,,,,,,,,,0,250,-75.9160847159484,,-75.5878272601915,,0.00358734514824902,,0.0130350823073728,,,,,,,,,,,,,,,,,,,,,,,,,,,
,19089824.515,4370,5.675,0,0,0.0102198995029309,17,0.016236851731098,,7.55895870350291E-6,,1591.38471658315,,0.740857724530193,,,,,,,,,,0,250,-75.7869045467804,,-76.4781984833318,,0.00427963806060213,,0.016236871069497,,,,,,,,,,,,,,,,,,,,,,,,,,,
,19089969.93,4370,4.5674,0,0,0.0102198995029309,17,0.0201971861902568,,1.00631049224131E-5,,1980.34118495867,,0.986689946733949,,,,,,,,,,0,125,-75.9466924994339,,-74.6754262887508,,0.00495466548689153,,0.0201972070277803,,,,,,,,,,,,,,,,,,,,,,,,,,,
,19090113.405,4370,3.48415,0,0,0.0102198995029309,17,0.0273487819767669,,1.25591342323811E-5,,2683.51957150928,,1.23232734307376,,,,,,,,,,0,125,-75.56749200717,,-81.3566103685062,,0.00630243395104196,,0.0273488068760555,,,,,,,,,,,,,,,,,,,,,,,,,,,
,19090260.53,4370,2.38365,0,0,0.0102198995029309,17,0.0443581402495152,,3.20401681607254E-5,,4360.10037797688,,3.14932638497281,,,,,,,,,,0,100,-75.7341685302342,,-61.0925539914023,,0.0084947337969338,,0.0443581681386217,,,,,,,,,,,,,,,,,,,,,,,,,,,
,19091401.675,4370,2.6253,0,0,0.0102198995029309,17,0.0389311220596709,,1.34881039478584E-5,,3824.53469156634,,1.32505002705425,,,,,,,,,,0,100,-86.2203348299282,,-65.6589554407116,,0.00797740747968418,,0.0389311500839852,,,,,,,,,,,,,,,,,,,,,,,,,,,
,19091728.145,4370,3.71165,0,0,0.0102198995029309,17,0.0254228794609817,,1.21374781098405E-5,,2494.054602723,,1.19071880315653,,,,,,,,,,0,100,-75.7318685750272,,-80.0860683563075,,0.00636600871998932,,0.0254229067896209,,,,,,,,,,,,,,,,,,,,,,,,,,,
,19092059.275,4370,4.80665,0,0,0.0102198995029309,17,0.0191818931634225,,9.17059817622465E-6,,1880.59615718416,,0.899085925531732,,,,,,,,,,0,100,-75.7979446524495,,-77.7705379251171,,0.00517514175591548,,0.0191819170999574,,,,,,,,,,,,,,,,,,,,,,,,,,,
,19092389.77,4370,5.9074,0,0,0.0102198995029309,17,0.015667367983595,,7.52044070408217E-6,,1535.47987735956,,0.73703954832394,,,,,,,,,,0,100,-75.8097209711668,,-77.6349005910503,,0.004390711905163,,0.0156673890787183,,,,,,,,,,,,,,,,,,,,,,,,,,,
,19092719.61,4370,7.0066,0,0,0.0102198995029309,17,0.0133881037754165,,6.4222536200833E-6,,1311.7951501729,,0.629265306500915,,,,,,,,,,0,100,-75.6309783453068,,-77.5891897998899,,0.00384717054018877,,0.0133881227281571,,,,,,,,,,,,,,,,,,,,,,,,,,,
,19093050.06,4370,8.11095,0,0,0.0102198995029309,17,0.0117790588153904,,5.55737230702764E-6,,1153.94778945932,,0.544432968130968,,,,,,,,,,0,100,-76.1240589236284,,-77.60887915919,,0.0034691068977535,,0.0117790763313112,,,,,,,,,,,,,,,,,,,,,,,,,,,
,19093380.935,4370,9.2142,0,0,0.0102198995029309,17,0.0105780916603973,,5.12285188499357E-6,,1036.16668479484,,0.501803213945664,,,,,,,,,,0,100,-76.1979998342022,,-76.7789336510859,,0.00314845898538059,,0.0105781077259971,,,,,,,,,,,,,,,,,,,,,,,,,,,
,19093713.485,4370,10.458,0,0,0.0102198995029309,17,0.00954663756339012,,4.61195330583095E-6,,935.033104690346,,0.451711118767793,,,,,,,,,,0,100,-76.2894622378987,,-76.7406500565441,,0.00287051109685629,,0.00954665236047647,,,,,,,,,,,,,,,,,,,,,,,,,,,
,19093844.41,4370,12.6416,0,0,0.0102198995029309,17,0.00821046744867922,,4.01849262185326E-6,,804.05393590514,,0.393531759704687,,,,,,,,,,0,100,-76.4462161899986,,-75.2288224432171,,0.00249274235041481,,0.00821048042331207,,,,,,,,,,,,,,,,,,,,,,,,,,,
,19093983,4370,14.94655,0,0,0.0102198995029309,17,0.00721556877961112,,3.45211509517013E-6,,706.551389567866,,0.338031944786138,,,,,,,,,,0,500,-75.8204583418369,,-75.5514858296383,,0.00222333408340506,,0.00721558052444955,,,,,,,,,,,,,,,,,,,,,,,,,,,
,19094115.72,4370,17.1552,0,0,0.0102198995029309,17,0.00649974047372579,,3.12354935641129E-6,,636.410685108613,,0.305836351961744,,,,,,,,,,0,500,-75.5841897618322,,-75.2880179182837,,0.00201358447896802,,0.00649975116801331,,,,,,,,,,,,,,,,,,,,,,,,,,,
,19094248.385,4370,19.3599,0,0,0.0102198995029309,17,0.00593391099813071,,2.87000175427174E-6,,580.974925850105,,0.280994484157761,,,,,,,,,,0,500,-75.7279573078271,,-75.0249506570208,,0.00185596050502545,,0.00593392094999826,,,,,,,,,,,,,,,,,,,,,,,,,,,
,19094379.63,4370,21.54575,0,0,0.0102198995029309,17,0.00547665343056345,,2.63061705760784E-6,,536.180912186737,,0.257544917659379,,,,,,,,,,0,500,-75.9468268556322,,-75.2956457823094,,0.00172419908600916,,0.0054766627366634,,,,,,,,,,,,,,,,,,,,,,,,,,,
,19094511.7,4370,23.74485,0,0,0.0102198995029309,17,0.00509279628754748,,2.43275901888285E-6,,498.580603032544,,0.238164719116865,,,,,,,,,,0,500,-75.8329549494334,,-76.202334949316,,0.00160346146277536,,0.00509280494258389,,,,,,,,,,,,,,,,,,,,,,,,,,,
,19094643.745,4370,25.9446,0,0,0.0102198995029309,17,0.00476573182058606,,2.26553331890476E-6,,466.545683408296,,0.221786077693154,,,,,,,,,,0,500,-76.1658601568849,,-76.1121556131368,,0.00151148713320897,,0.00476574003898945,,,,,,,,,,,,,,,,,,,,,,,,,,,
,19094776.74,4370,28.16135,0,0,0.0102198995029309,17,0.00448101572866165,,2.10129901224891E-6,,438.660393119965,,0.20570226073458,,,,,,,,,,0,500,-76.1295621082458,,-76.8356284541854,,0.00141915438640635,,0.00448102343398672,,,,,,,,,,,,,,,,,,,,,,,,,,,
,19094907.76,4370,30.3458,0,0,0.0102198995029309,17,0.00423544848382271,,1.99098336643281E-6,,414.610669583066,,0.194898252710384,,,,,,,,,,0,500,-76.1708219092706,,-76.389602504803,,0.00134999566717637,,0.00423545586071576,,,,,,,,,,,,,,,,,,,,,,,,,,,
,19095053.205,4370,32.7638,0,0,0.0102198995029309,17,0.0038022097274904,,1.9833645891932E-6,,392.489215720405,,0.204735589799387,,,,,,,,,,0,1000,-70.4580069154491,,-73.8693544264066,,0.00130037604092586,,0.00380221735196521,,,,,,,,,,,,,,,,,,,,,,,,,,,
,19095202.75,4370,35.2534,0,0,0.0102198995029309,17,0.00360661465488094,,1.86058428510908E-6,,371.24886949485,,0.19151989270401,,,,,,,,,,0,1000,-71.6606278811148,,-73.7490902556064,,0.00122256828267135,,0.00360662175972578,,,,,,,,,,,,,,,,,,,,,,,,,,,
,19095348.03,4370,37.67355,0,0,0.0102198995029309,17,0.00343701645583353,,1.75162185756263E-6,,352.92833363225,,0.179864075068067,,,,,,,,,,0,1000,-72.7734323343381,,-73.9235738587222,,0.00115533024933594,,0.00343702311375665,,,,,,,,,,,,,,,,,,,,,,,,,,,
,19095509.25,4370,40.35755,0,0,0.0102198995029309,17,0.00326890371581504,,1.64898955335775E-6,,334.856241361681,,0.16891699501541,,,,,,,,,,0,1000,-73.8284464740021,,-74.0587724004985,,0.0010893199703233,,0.00326890993906018,,,,,,,,,,,,,,,,,,,,,,,,,,,
,19095665.75,4370,42.9628,0,0,0.0102198995029309,17,0.00312235339425989,,1.55639169332985E-6,,319.17307111779,,0.159097104288548,,,,,,,,,,0,1000,-74.8719124326654,,-74.1861271157451,,0.00103348373682989,,0.00312235925879175,,,,,,,,,,,,,,,,,,,,,,,,,,,
,19095815.915,4370,45.46295,0,0,0.0102198995029309,17,0.00299718391612933,,1.50975499529063E-6,,305.829995763254,,0.154053779132559,,,,,,,,,,0,1000,-74.2115895903965,,-74.1337699113947,,0.000984902382694942,,0.00299718946469973,,,,,,,,,,,,,,,,,,,,,,,,,,,
,19095959.715,4370,47.86265,0,0,0.0102198995029309,17,0.0028839901824312,,1.44076881781213E-6,,293.804569909282,,0.14677708854217,,,,,,,,,,0,1000,-77.1417020963142,,-74.1659961629425,,0.00094579852203494,,0.00288399549998146,,,,,,,,,,,,,,,,,,,,,,,,,,,
,19096103.765,4370,50.25745,0,0,0.0102198995029309,17,0.00278143532901516,,1.37555959737254E-6,,282.942879624407,,0.139929225093563,,,,,,,,,,0,1000,-77.9958231743032,,-74.4266276132948,,0.000903043018902189,,0.0027814403554035,,,,,,,,,,,,,,,,,,,,,,,,,,,
,19096248.655,4370,52.6726,0,0,0.0102198995029309,17,0.00268636396719646,,1.32813592943523E-6,,272.902083689569,,0.13492230204586,,,,,,,,,,0,1000,-78.7131104808182,,-74.5245205942953,,0.000870168146819639,,0.00268636879944917,,,,,,,,,,,,,,,,,,,,,,,,,,,
,19096398.215,4370,55.16385,0,0,0.0102198995029309,17,0.00259544631886308,,1.26860405047705E-6,,263.325349454968,,0.128708117482711,,,,,,,,,,0,1000,-79.7603263488618,,-75.0551406024729,,0.000836709023794685,,0.00259545094315228,,,,,,,,,,,,,,,,,,,,,,,,,,,
,19096553.99,4370,57.75995,0,0,0.0102198995029309,17,0.00250759868184363,,1.21651702988191E-6,,254.095466140191,,0.123269690863366,,,,,,,,,,0,1000,-81.2728208999956,,-75.1998217057346,,0.00080597401214196,,0.00250760312296026,,,,,,,,,,,,,,,,,,,,,,,,,,,
,19096709.49,4370,60.34925,0,0,0.0102198995029309,17,0.00242611110266736,,1.18307058611235E-6,,245.554364373687,,0.119742098652822,,,,,,,,,,0,1000,-81.3688138613625,,-75.3304973293442,,0.0007769558918143,,0.0024261153683661,,,,,,,,,,,,,,,,,,,,,,,,,,,
,19096854.165,4370,62.7611,0,0,0.0102198995029309,17,0.00235560203351117,,1.14454675141552E-6,,238.179878838785,,0.115727329833586,,,,,,,,,,0,1000,-81.9947921307422,,-75.3447658102456,,0.000749462990775145,,0.00235560612147087,,,,,,,,,,,,,,,,,,,,,,,,,,,
,19097015.935,4370,65.4598,0,0,0.0102198995029309,17,0.00228172781655018,,1.11587821680588E-6,,230.469215322728,,0.112710697611256,,,,,,,,,,0,1000,-83.4568913538948,,-75.2318283137001,,0.000723313951046532,,0.00228173174750446,,,,,,,,,,,,,,,,,,,,,,,,,,,
,19097172.855,4370,68.06995,0,0,0.0102198995029309,17,0.00221491953073423,,1.08581261306797E-6,,223.509925842324,,0.109570337931117,,,,,,,,,,0,1000,-83.1016440857305,,-75.1342415892456,,0.000699652411545818,,0.00221492331964926,,,,,,,,,,,,,,,,,,,,,,,,,,,
,19097334.705,4370,70.7656,0,0,0.0102198995029309,17,0.00215045333478229,,1.04856509500568E-6,,216.807053991354,,0.105715347327154,,,,,,,,,,0,1000,-83.882532968396,,-75.1737120666652,,0.000678485279479203,,0.00215045700472247,,,,,,,,,,,,,,,,,,,,,,,,,,,
,19097479.445,4370,73.17585,0,0,0.0102198995029309,17,0.00209582362238434,,1.01154581000216E-6,,211.136474290507,,0.10190449832223,,,,,,,,,,0,1000,-83.8898338916054,,-75.4028864369366,,0.000658170014314297,,0.00209582716586124,,,,,,,,,,,,,,,,,,,,,,,,,,,
,19097634.62,4370,75.75825,0,0,0.0102198995029309,17,0.00204068665719318,,9.94646953779325E-7,,205.42209777114,,0.100124199880665,,,,,,,,,,0,1000,-83.6856295640188,,-75.5539025193465,,0.000640459960321024,,0.00204069010319733,,,,,,,,,,,,,,,,,,,,,,,,,,,
,19097772.85,4370,78.0642,0,0,0.0102198995029309,17,0.00199405970461009,,9.76432584117855E-7,,200.596624053642,,0.0982261219334007,,,,,,,,,,0,1000,-84.9268666856864,,-75.4684533611503,,0.000623503075202666,,0.0019940630469237,,,,,,,,,,,,,,,,,,,,,,,,,,,
,19097904.8,4370,80.261,0,0,0.0102198995029309,17,0.00195159686425452,,9.50997572561877E-7,,196.207611057721,,0.0956102429457898,,,,,,,,,,0,1000,-83.8623897706884,,-75.7099905745787,,0.000609010906242897,,0.00195160012238285,,,,,,,,,,,,,,,,,,,,,,,,,,,
,19098103.12,4370,83.5676,0,0,0.0102198995029309,17,0.00189129398314211,,9.31110777172581E-7,,189.983639658867,,0.0935314771668073,,,,,,,,,,0,1000,-83.8433307591899,,-75.7337914680251,,0.000589244359025234,,0.00189129713045546,,,,,,,,,,,,,,,,,,,,,,,,,,,
,19098300.99,4370,86.8609,0,0,0.0102198995029309,17,0.00183483818259155,,8.84412726558145E-7,,184.166295715611,,0.0887700875755247,,,,,,,,,,0,1000,-83.080700864462,,-76.0233386664189,,0.000570103906633809,,0.00183484121940718,,,,,,,,,,,,,,,,,,,,,,,,,,,
,19098499.545,4370,90.1759,0,0,0.0102198995029309,17,0.00178137869072426,,8.56826817715275E-7,,178.666203246377,,0.0859366644479797,,,,,,,,,,0,1000,-82.7639376709898,,-76.4450087208179,,0.000551514231894788,,0.00178138161801162,,,,,,,,,,,,,,,,,,,,,,,,,,,
,19098697.33,4370,93.4703,0,0,0.0102198995029309,17,0.00173114635432552,,8.53976864674417E-7,,173.5056530926,,0.0855904361601398,,,,,,,,,,0,1000,-82.874476258337,,-75.9921708901365,,0.000534446645419076,,0.00173114918300077,,,,,,,,,,,,,,,,,,,,,,,,,,,
,19098894.66,4370,96.76225,0,0,0.0102198995029309,17,0.00168396530970157,,8.14533400164567E-7,,168.665196202686,,0.0815831601570287,,,,,,,,,,0,1000,-81.8444262686703,,-76.7270100906716,,0.000519544093088787,,0.0016839680577213,,,,,,,,,,,,,,,,,,,,,,,,,,,
,19099092.37,4370,100.05095,0,0,0.0102198995029309,17,0.00163975926928037,,8.02765404812134E-7,,164.135764610386,,0.0803546609327107,,,,,,,,,,0,1000,-81.7085384234019,,-76.2324367706462,,0.000504028882665224,,0.00163976192534673,,,,,,,,,,,,,,,,,,,,,,,,,,,
,19099236.475,4370,102.4544,0,0,0.0102198995029309,17,0.00160902384301674,,7.77086015305659E-7,,160.989863644383,,0.0777507242235551,,,,,,,,,,0,1000,-81.4976483089077,,-77.0127360997783,,0.000494479193090137,,0.00160902644822071,,,,,,,,,,,,,,,,,,,,,,,,,,,
,19099386.775,4370,104.9592,0,0,0.0102198995029309,17,0.00157826286148791,,7.77984542758187E-7,,157.844058851096,,0.077807090156592,,,,,,,,,,0,1000,-81.2849289152724,,-76.1578213231486,,0.000483033223051437,,0.00157826539593272,,,,,,,,,,,,,,,,,,,,,,,,,,,
,19099530.75,4370,107.3576,0,0,0.0102198995029309,17,0.00154976529790028,,7.57005729111935E-7,,154.932142770337,,0.0756787691160017,,,,,,,,,,0,1000,-80.9061090619444,,-76.7253883442755,,0.000475815725836943,,0.00154976780239327,,,,,,,,,,,,,,,,,,,,,,,,,,,
,19099693.255,4370,110.0678,0,0,0.0102198995029309,17,0.00151900253478374,,7.34057084479459E-7,,151.79137264321,,0.0733529738953325,,,,,,,,,,0,1000,-80.5258549786311,,-77.1966813673505,,0.000465210774597676,,0.00151900497736602,,,,,,,,,,,,,,,,,,,,,,,,,,,
,19099831.065,4370,112.361,0,0,0.0102198995029309,17,0.00149863681000094,,7.26140071202617E-7,,149.713590942866,,0.0725411689358922,,,,,,,,,,0,1000,-87.1420484536436,,-76.6876714186082,,0.000454709933683292,,0.00149863917527062,,,,,,,,,,,,,,,,,,,,,,,,,,,
,19099980.82,4370,114.85765,0,0,0.0102198995029309,17,0.00146742267020034,,7.23894613989638E-7,,146.531313457494,,0.0722852805770458,,,,,,,,,,0,1000,-79.7639995722879,,-76.7050731005689,,0.000447545671747534,,0.001467425010264,,,,,,,,,,,,,,,,,,,,,,,,,,,
,19100125.36,4370,117.26795,0,0,0.0102198995029309,17,0.00144310068940788,,7.00105853967049E-7,,144.053615777726,,0.0698860591343888,,,,,,,,,,0,1000,-80.3582600251946,,-76.5732512075597,,0.000438409933639277,,0.00144310297275698,,,,,,,,,,,,,,,,,,,,,,,,,,,
,19100274.57,4370,119.7567,0,0,0.0102198995029309,17,0.0014185467796873,,7.02413666527298E-7,,141.553999796567,,0.0700923705024628,,,,,,,,,,0,1000,-80.044007587203,,-76.2704851743281,,0.000431264832508819,,0.00141854902746109,,,,,,,,,,,,,,,,,,,,,,,,,,,
,19100418.78,4370,122.1629,0,0,0.0102198995029309,17,0.00139566406957951,,6.94976243093007E-7,,139.22605758793,,0.0693280360867419,,,,,,,,,,0,1000,-79.0405460700207,,-76.5836792315642,,0.000424505000189352,,0.00139566628314766,,,,,,,,,,,,,,,,,,,,,,,,,,,
,19100562.415,4370,124.5487,0,0,0.0102198995029309,17,0.00137378342221746,,6.71978970849647E-7,,137.001450515328,,0.0670134364761354,,,,,,,,,,0,1000,-79.8650724526924,,-76.4631436176631,,0.000417294594927192,,0.00137378559529601,,,,,,,,,,,,,,,,,,,,,,,,,,,
,19100724.35,4370,127.24725,0,0,0.0102198995029309,17,0.00135384168842891,,6.68271216663068E-7,,134.975156828982,,0.0666251254917074,,,,,,,,,,0,1000,-84.6945615149765,,-75.9597582571453,,0.00040719066968021,,0.00135384378802587,,,,,,,,,,,,,,,,,,,,,,,,,,,
,19100874.305,4370,129.7491,0,0,0.0102198995029309,17,0.00132832675212311,,6.55213410080739E-7,,132.384210938032,,0.0653000279628549,,,,,,,,,,0,1000,-80.1798409023496,,-76.0368229410789,,0.000402051257985972,,0.00132832883837196,,,,,,,,,,,,,,,,,,,,,,,,,,,
,19101019.275,4370,132.1643,0,0,0.0102198995029309,17,0.00130829868007036,,6.45548105558565E-7,,130.351727892998,,0.0643187833766761,,,,,,,,,,0,1000,-78.9841094787375,,-75.5208362482029,,0.000395149996811038,,0.00130830072616276,,,,,,,,,,,,,,,,,,,,,,,,,,,
,19101168.505,4370,134.6501,0,0,0.0102198995029309,17,0.00128829569197168,,6.36494339131817E-7,,128.322923936428,,0.0633990215533023,,,,,,,,,,0,1000,-79.7960106256932,,-75.6935810057954,,0.000390001630561011,,0.0012882977160414,,,,,,,,,,,,,,,,,,,,,,,,,,,
,19101307.195,4370,136.9657,0,0,0.0102198995029309,17,0.00127023129855702,,6.32337780795708E-7,,126.491714698062,,0.0629691330143208,,,,,,,,,,0,1000,-79.5799799264923,,-75.4991825527226,,0.000385902481005681,,0.00127023330848506,,,,,,,,,,,,,,,,,,,,,,,,,,,
,19101451.275,4370,139.36475,0,0,0.0102198995029309,17,0.00125195931268651,,6.27482320024273E-7,,124.640399932195,,0.0624697020763941,,,,,,,,,,0,1000,-79.1620999684565,,-75.3790647089677,,0.000377713565879921,,0.00125196126632018,,,,,,,,,,,,,,,,,,,,,,,,,,,
,19101589.375,4370,141.66955,0,0,0.0102198995029309,17,0.00123499019210794,,6.21153046585724E-7,,122.921935838412,,0.061824956705615,,,,,,,,,,0,1000,-79.0553580142052,,-76.0273967181492,,0.000373582618289496,,0.00123499212950213,,,,,,,,,,,,,,,,,,,,,,,,,,,
,19101738.945,4370,144.15585,0,0,0.0102198995029309,17,0.00121715745192939,,6.06332267956004E-7,,121.116888759594,,0.0603348105590537,,,,,,,,,,0,1000,-78.7680942202113,,-76.4040858251838,,0.000365561774047953,,0.00121715933420396,,,,,,,,,,,,,,,,,,,,,,,,,,,
,19101870.535,4370,146.3532,0,0,0.0102198995029309,17,0.00120187869267624,,5.91972524656882E-7,,119.571071535454,,0.0588933635300671,,,,,,,,,,0,1000,-79.1822811403579,,-76.3061038733008,,0.000362394737226205,,0.00120188056599339,,,,,,,,,,,,,,,,,,,,,,,,,,,
,19102015.11,4370,148.75925,0,0,0.0102198995029309,17,0.00118555445937844,,5.88917822028543E-7,,117.9202062883,,0.0585761402042475,,,,,,,,,,0,1000,-78.8919923608302,,-75.6540368915011,,0.000355131436586065,,0.0011855562831268,,,,,,,,,,,,,,,,,,,,,,,,,,,
,19102159.355,4370,151.16445,0,0,0.0102198995029309,17,0.0011696942547443,,5.85721238227103E-7,,116.316987031015,,0.0582453267846417,,,,,,,,,,0,1000,-79.0852334676452,,-75.5858194338277,,0.000351650647659125,,0.00116969606716356,,,,,,,,,,,,,,,,,,,,,,,,,,,
,19102315.455,4370,153.7627,0,0,0.0102198995029309,17,0.00115298532058122,,5.77371039987589E-7,,114.628740358849,,0.0574016094040713,,,,,,,,,,0,1000,-79.055999850978,,-75.3734051264678,,0.000345718921245101,,0.0011529870977583,,,,,,,,,,,,,,,,,,,,,,,,,,,
,19102476.305,4370,156.44505,0,0,0.0102198995029309,17,0.00113637596550119,,5.65055587897473E-7,,112.951333328137,,0.0561642328903224,,,,,,,,,,0,1000,-79.2795440067526,,-75.6698201381579,,0.000339531593111305,,0.00113637770468919,,,,,,,,,,,,,,,,,,,,,,,,,,,
,19102621.46,4370,158.8674,0,0,0.0102198995029309,17,0.0011216828055947,,5.55640462561402E-7,,111.468092541593,,0.0552171143147051,,,,,,,,,,0,1000,-78.466242793935,,-75.2670222676073,,0.000335155706761931,,0.00112168452244078,,,,,,,,,,,,,,,,,,,,,,,,,,,
,19102765.12,4370,161.2597,0,0,0.0102198995029309,17,0.00110758607781196,,5.39852447231178E-7,,110.045630259843,,0.0536376478135561,,,,,,,,,,0,1000,-79.2096382134283,,-75.839863371854,,0.000330775675568364,,0.0011075877713612,,,,,,,,,,,,,,,,,,,,,,,,,,,
,19102909.525,4370,163.6656,0,0,0.0102198995029309,17,0.00109377071738627,,5.5671882229656E-7,,108.652101306454,,0.055302794939666,,,,,,,,,,0,1000,-78.3644004715304,,-75.0137860843293,,0.000326110704611268,,0.00109377238429571,,,,,,,,,,,,,,,,,,,,,,,,,,,
,19103071.7,4370,166.3743,0,0,0.0102198995029309,17,0.0010786887444659,,5.42688378657284E-7,,107.131423015338,,0.0538977438071264,,,,,,,,,,0,1000,-79.0632208699775,,-75.5294336720894,,0.000321720613063549,,0.00107869038948073,,,,,,,,,,,,,,,,,,,,,,,,,,,
,19103214.695,4370,168.75565,0,0,0.0102198995029309,17,0.00106565119301318,,5.37037462017156E-7,,105.817392749735,,0.0533268461582119,,,,,,,,,,0,1000,-78.3972139907832,,-75.4261215340673,,0.000318103925018117,,0.00106565282092609,,,,,,,,,,,,,,,,,,,,,,,,,,,
,19103377.29,4370,171.46325,0,0,0.0102198995029309,17,0.00105127154851503,,5.18010902974751E-7,,104.368647910004,,0.05142725982371,,,,,,,,,,0,1000,-78.3522709508754,,-76.2041876757895,,0.000313594744621941,,0.00105127315224346,,,,,,,,,,,,,,,,,,,,,,,,,,,
,19103527.67,4370,173.97115,0,0,0.0102198995029309,17,0.00103835105371437,,5.13955892789821E-7,,103.067405962613,,0.0510155205627692,,,,,,,,,,0,1000,-78.3245068618227,,-75.7169569338731,,0.000310329127749758,,0.00103835264375807,,,,,,,,,,,,,,,,,,,,,,,,,,,
,19103670.53,4370,176.35,0,0,0.0102198995029309,17,0.00102641520076848,,5.11482904164874E-7,,101.865744014843,,0.050761628870894,,,,,,,,,,0,1000,-78.5782278699523,,-75.3428744354625,,0.000305431316008182,,0.00102641675892916,,,,,,,,,,,,,,,,,,,,,,,,,,,
,19103827.455,4370,178.96155,0,0,0.0102198995029309,17,0.00101359467546959,,5.11144572212852E-7,,100.575460229244,,0.0507190138858042,,,,,,,,,,0,1000,-78.4238967832192,,-74.9657346627251,,0.0003018732131373,,0.00101359621679034,,,,,,,,,,,,,,,,,,,,,,,,,,,
,19103976.825,4370,181.45315,0,0,0.0102198995029309,17,0.00100168357437326,,5.0468313356022E-7,,99.3771146586402,,0.0500695818337666,,,,,,,,,,0,1000,-78.6420233890447,,-75.1174186827926,,0.000297670031313507,,0.0010016850908923,,,,,,,,,,,,,,,,,,,,,,,,,,,
,19104121.07,4370,183.8612,0,0,0.0102198995029309,17,0.000990528385864116,,5.01887945580161E-7,,98.2551791436106,,0.0497845557658522,,,,,,,,,,0,1000,-78.5014524677423,,-74.7869667778611,,0.000293725221984183,,0.000990529879083943,,,,,,,,,,,,,,,,,,,,,,,,,,,
,19104271.51,4370,186.36585,0,0,0.0102198995029309,17,0.000979050795081757,,4.95148579080854E-7,,97.1011808287356,,0.0491082160688755,,,,,,,,,,0,1000,-78.0733430042749,,-75.2706548493165,,0.000292809484491757,,0.00097905229640166,,,,,,,,,,,,,,,,,,,,,,,,,,,
,19104421.555,4370,188.8641,0,0,0.0102198995029309,17,0.000967902054190777,,4.8768344662363E-7,,95.9805984826105,,0.0483603458203837,,,,,,,,,,0,1000,-77.9248693678143,,-75.4389142208686,,0.000287935515706777,,0.000967903522668126,,,,,,,,,,,,,,,,,,,,,,,,,,,
,19104576.95,4370,191.45715,0,0,0.0102198995029309,17,0.0009566788060631,,4.78188104006684E-7,,94.852877684086,,0.0474113657271482,,,,,,,,,,0,1000,-78.0213492511427,,-75.1920225057709,,0.000284940758119126,,0.000956680261023548,,,,,,,,,,,,,,,,,,,,,,,,,,,
,19104714.665,4370,193.75645,0,0,0.0102198995029309,17,0.00094695006449073,,4.7158510893706E-7,,93.8756104298804,,0.0467503776506773,,,,,,,,,,0,1000,-77.706123636471,,-75.0392708869371,,0.000281018272982634,,0.000946951494208235,,,,,,,,,,,,,,,,,,,,,,,,,,,
,19104853.35,4370,196.0651,0,0,0.0102198995029309,17,0.000937301602368659,,4.72992148575759E-7,,92.906668068795,,0.046883583872897,,,,,,,,,,0,1000,-77.7871910332868,,-74.6685320078348,,0.000277967753332022,,0.000937303015614339,,,,,,,,,,,,,,,,,,,,,,,,,,,
,19104997.555,4370,198.46325,0,0,0.0102198995029309,17,0.000927535915468911,,4.67720793629247E-7,,91.9262177241838,,0.0463547953820726,,,,,,,,,,0,1000,-78.2207475124759,,-74.2107537662989,,0.000277416636473418,,0.000927537337936746,,,,,,,,,,,,,,,,,,,,,,,,,,,
,19105141.735,4370,200.869,0,0,0.0102198995029309,17,0.000917967327803611,,4.69684367354861E-7,,90.9658134040106,,0.0465432214935935,,,,,,,,,,0,1000,-77.7978528270103,,-74.2583704036553,,0.00027104291429676,,0.000917968699813013,,,,,,,,,,,,,,,,,,,,,,,,,,,
,19105291.465,4370,203.3673,0,0,0.0102198995029309,17,0.000908259734857043,,4.6317456684413E-7,,89.9917176604782,,0.0458919521754082,,,,,,,,,,0,1000,-78.1189223033774,,-74.6768520170725,,0.000268679156558893,,0.000908261097449828,,,,,,,,,,,,,,,,,,,,,,,,,,,
,19105429.315,4370,205.66215,0,0,0.0102198995029309,17,0.000899497958322898,,4.639914042872E-7,,89.1127539177862,,0.0459672966946772,,,,,,,,,,0,1000,-77.6368305869603,,-74.4279297375008,,0.000266672683121723,,0.000899499313715378,,,,,,,,,,,,,,,,,,,,,,,,,,,
,19105562.275,4370,207.87375,0,0,0.0102198995029309,17,0.000891216825082673,,4.45890388222031E-7,,88.2822037511849,,0.0441689668933039,,,,,,,,,,0,1000,-77.9262990176792,,-75.3942943588099,,0.000264988752518375,,0.000891218175847349,,,,,,,,,,,,,,,,,,,,,,,,,,,
,19105723.095,4370,210.559,0,0,0.0102198995029309,17,0.000881401515474134,,4.3433525579554E-7,,87.2980315909939,,0.0430184823826556,,,,,,,,,,0,1000,-77.4946097677155,,-75.2205447053335,,0.000261723904384701,,0.000881402847832886,,,,,,,,,,,,,,,,,,,,,,,,,,,
,19105861.17,4370,212.8627,0,0,0.0102198995029309,17,0.000873159987573289,,4.37739619243083E-7,,86.4718680377668,,0.0433507104170417,,,,,,,,,,0,1000,-77.0801035640062,,-74.8711704048299,,0.00025837431896303,,0.000873161298302738,,,,,,,,,,,,,,,,,,,,,,,,,,,
,19105999.21,4370,215.16205,0,0,0.0102198995029309,17,0.000865013188128612,,4.34419079276982E-7,,85.6553860406305,,0.0430170070385058,,,,,,,,,,0,1000,-76.8163497286197,,-74.9962790952344,,0.000255227476576587,,0.000865014479170461,,,,,,,,,,,,,,,,,,,,,,,,,,,
,19106143.26,4370,217.5635,0,0,0.0102198995029309,17,0.000856820990659483,,4.31647481075759E-7,,84.8345402068415,,0.0427377026295235,,,,,,,,,,0,1000,-77.3827507638561,,-73.9420120238952,,0.000253340221871394,,0.000856822274840926,,,,,,,,,,,,,,,,,,,,,,,,,,,
,19106287.125,4370,219.9559,0,0,0.0102198995029309,17,0.00084873193321317,,4.32088702920179E-7,,84.0242118026448,,0.0427765904938896,,,,,,,,,,0,1000,-77.1993412176412,,-74.182984916227,,0.000250789920367307,,0.000848733203663841,,,,,,,,,,,,,,,,,,,,,,,,,,,
,19106431.865,4370,222.36685,0,0,0.0102198995029309,17,0.000840849200439894,,4.37600652597009E-7,,83.2347269938915,,0.0433175373928713,,,,,,,,,,0,1000,-77.2701802712871,,-74.412142145259,,0.000247656797053735,,0.000840850450959729,,,,,,,,,,,,,,,,,,,,,,,,,,,
,19106576.115,4370,224.77365,0,0,0.0102198995029309,17,0.000833115876935108,,4.29526531507268E-7,,82.4603737268252,,0.0425137319708002,,,,,,,,,,0,1000,-76.8239938267654,,-74.0925957047612,,0.000246646903594395,,0.000833117128790365,,,,,,,,,,,,,,,,,,,,,,,,,,,
,19106724.425,4370,227.25385,0,0,0.0102198995029309,17,0.000825262274431413,,4.22282411643858E-7,,81.6741465673443,,0.0417921735525733,,,,,,,,,,0,5000,-76.4245416494833,,-73.883121263053,,0.000243276326933239,,0.00082526350389566,,,,,,,,,,,,,,,,,,,,,,,,,,,
,19106869.345,4370,229.66175,0,0,0.0102198995029309,17,0.000817716281029988,,4.22994914552543E-7,,80.9188754916623,,0.0418583113159414,,,,,,,,,,0,5000,-75.7420880672214,,-74.1538684346827,,0.000239087011667523,,0.000817717479473378,,,,,,,,,,,,,,,,,,,,,,,,,,,
,19107012.925,4370,232.0522,0,0,0.0102198995029309,17,0.000810383575657354,,4.10693604859137E-7,,80.1851035204008,,0.040636880477241,,,,,,,,,,0,5000,-76.2926886382547,,-74.377983909139,,0.000238049484228745,,0.000810384774472048,,,,,,,,,,,,,,,,,,,,,,,,,,,
,19107157.385,4370,234.4575,0,0,0.0102198995029309,17,0.000803224746042155,,4.08545534558303E-7,,79.4688748539382,,0.0404203252295171,,,,,,,,,,0,5000,-76.3099488470925,,-74.0080202959362,,0.000237078953171171,,0.000803225945699224,,,,,,,,,,,,,,,,,,,,,,,,,,,
,19107302.035,4370,236.87055,0,0,0.0102198995029309,17,0.000796180708595834,,4.06497330644113E-7,,78.7642696194886,,0.0402137569416173,,,,,,,,,,0,5000,-76.0314311114493,,-74.5206226896677,,0.000235082717677691,,0.000796181898571143,,,,,,,,,,,,,,,,,,,,,,,,,,,
,19107463.93,4370,239.5709,0,0,0.0102198995029309,17,0.000788432578900334,,4.08997255472259E-7,,77.9893938333467,,0.0404567252359231,,,,,,,,,,0,5000,-75.8891123476648,,-73.2513168750628,,0.000233156446681563,,0.000788433760957523,,,,,,,,,,,,,,,,,,,,,,,,,,,
,19107619.155,4370,242.1557,0,0,0.0102198995029309,17,0.000781121377185597,,3.98195878124762E-7,,77.2583669050873,,0.0393842988376233,,,,,,,,,,0,5000,-76.7610409934356,,-74.2354774844462,,0.000229441429793812,,0.000781122532588237,,,,,,,,,,,,,,,,,,,,,,,,,,,
,19107763.55,4370,244.5628,0,0,0.0102198995029309,17,0.000774509818333981,,3.95434250322206E-7,,76.5974228149772,,0.0391075735245472,,,,,,,,,,0,5000,-76.848700155293,,-73.8072505224934,,0.000227496688434329,,0.000774510963929824,,,,,,,,,,,,,,,,,,,,,,,,,,,
,19107895.01,4370,246.75175,0,0,0.0102198995029309,17,0.000768520531257163,,3.94121015128922E-7,,75.9987904524782,,0.0389744644024225,,,,,,,,,,0,5000,-76.0336567418361,,-73.7677042447041,,0.000225864734956054,,0.00076852166927634,,,,,,,,,,,,,,,,,,,,,,,,,,,
,19108040.165,4370,249.1721,0,0,0.0102198995029309,17,0.000762041114192406,,3.89379263866362E-7,,75.3512811619269,,0.038502099754265,,,,,,,,,,0,5000,-76.2642493072688,,-73.648892986474,,0.000223826444374933,,0.000762042241266808,,,,,,,,,,,,,,,,,,,,,,,,,,,
,19108183.985,4370,251.56875,0,0,0.0102198995029309,17,0.000755748049826862,,3.87670455099054E-7,,74.7225059252178,,0.0383297919242863,,,,,,,,,,0,5000,-76.1314330169087,,-73.9380874219671,,0.00022077628016915,,0.000755749155523503,,,,,,,,,,,,,,,,,,,,,,,,,,,
,19108332.99,4370,254.05445,0,0,0.0102198995029309,17,0.0007493245494813,,3.82716674312591E-7,,74.0808110993857,,0.0378366354229544,,,,,,,,,,0,5000,-75.8891036397519,,-73.6784070376618,,0.000219905125883791,,0.000749325655873087,,,,,,,,,,,,,,,,,,,,,,,,,,,
,19108478.035,4370,256.47095,0,0,0.0102198995029309,17,0.000743171935175975,,3.81364546789518E-7,,73.4662842567963,,0.0376997486408494,,,,,,,,,,0,5000,-76.9686624728483,,-73.6740576148127,,0.000217250688245302,,0.000743173023958702,,,,,,,,,,,,,,,,,,,,,,,,,,,
,19108627.235,4370,258.9686,0,0,0.0102198995029309,17,0.000736916671438623,,3.78050892475259E-7,,72.8416120388176,,0.0373689407654439,,,,,,,,,,0,5000,-76.0279705334871,,-73.9612649414781,,0.000217156770012283,,0.000736917768514236,,,,,,,,,,,,,,,,,,,,,,,,,,,
,19108777.22,4370,261.46135,0,0,0.0102198995029309,17,0.000730761151444389,,3.76010630543331E-7,,72.2270061736304,,0.0371641020638231,,,,,,,,,,0,5000,-76.1697569951623,,-73.7264000095357,,0.000214504440103769,,0.000730762230901322,,,,,,,,,,,,,,,,,,,,,,,,,,,
,19108926.625,4370,263.9555,0,0,0.0102198995029309,17,0.000724758369477771,,3.69687733655507E-7,,71.6277514921776,,0.0365361240724054,,,,,,,,,,0,5000,-76.0898907962916,,-73.7977124353495,,0.00021353237118831,,0.000724759448033035,,,,,,,,,,,,,,,,,,,,,,,,,,,
,19109064.77,4370,266.2612,0,0,0.0102198995029309,17,0.000719330691377304,,3.72799006488862E-7,,71.0859948528723,,0.036840842325529,,,,,,,,,,0,5000,-76.2467568844903,,-73.6892691831487,,0.000212572219469325,,0.000719331768320057,,,,,,,,,,,,,,,,,,,,,,,,,,,
,19109220.19,4370,268.8612,0,0,0.0102198995029309,17,0.000713292950969496,,3.67830196159198E-7,,70.4834412541414,,0.0363467774449528,,,,,,,,,,0,5000,-76.4716770343081,,-73.4394556945169,,0.000208235617112066,,0.000713293993167647,,,,,,,,,,,,,,,,,,,,,,,,,,,
,19109365.22,4370,271.27075,0,0,0.0102198995029309,17,0.000707846719434667,,3.62020341386323E-7,,69.9400053469292,,0.0357699859185506,,,,,,,,,,0,5000,-75.4867766039649,,-73.6705781070929,,0.00020784540797404,,0.00070784776571929,,,,,,,,,,,,,,,,,,,,,,,,,,,
,19109513.405,4370,273.7491,0,0,0.0102198995029309,17,0.000702369073502816,,3.63001468447016E-7,,69.393517459478,,0.03586420898791,,,,,,,,,,0,5000,-76.1027500846743,,-73.6945385563155,,0.000206972248357528,,0.00070237011910637,,,,,,,,,,,,,,,,,,,,,,,,,,,
,19109658.29,4370,276.16605,0,0,0.0102198995029309,17,0.000697153586664095,,3.5983158606714E-7,,68.8732613573215,,0.0355484633219826,,,,,,,,,,0,5000,-76.125594967649,,-73.5542710551636,,0.000203400953011363,,0.00069715460404997,,,,,,,,,,,,,,,,,,,,,,,,,,,
,19109790.31,4370,278.37155,0,0,0.0102198995029309,17,0.000692380451011684,,3.6070906247624E-7,,68.3971965378478,,0.0356327970918285,,,,,,,,,,0,5000,-75.5656511767513,,-73.2688683738594,,0.000203444695868337,,0.000692381475851864,,,,,,,,,,,,,,,,,,,,,,,,,,,
,19109940.04,4370,280.86575,0,0,0.0102198995029309,17,0.000687133115684849,,3.56427808844106E-7,,67.8739083569797,,0.0352073161519207,,,,,,,,,,0,5000,-75.0918874731943,,-73.6536397368659,,0.000201288949250129,,0.000687134126582497,,,,,,,,,,,,,,,,,,,,,,,,,,,
,19110089.455,4370,283.36805,0,0,0.0102198995029309,17,0.000681987216532687,,3.53443298314873E-7,,67.3608096283196,,0.0349100264111044,,,,,,,,,,0,5000,-76.1491025040517,,-74.0160421314877,,0.000199681171848025,,0.000681988218852234,,,,,,,,,,,,,,,,,,,,,,,,,,,
,19110227.32,4370,285.654,0,0,0.0102198995029309,17,0.000677565631441071,,3.51723370914101E-7,,66.9199907550863,,0.0347380230122973,,,,,,,,,,0,5000,-75.9629915683939,,-73.5325759418049,,0.000197350774536452,,0.00067756661689087,,,,,,,,,,,,,,,,,,,,,,,,,,,
,19110394.925,4370,288.46225,0,0,0.0102198995029309,17,0.000671697785678767,,3.47471590418483E-7,,66.3350672476791,,0.0343153091958133,,,,,,,,,,0,5000,-76.3835736509024,,-73.7377422495745,,0.000197362150164993,,0.000671698779851888,,,,,,,,,,,,,,,,,,,,,,,,,,,
,19110550.705,4370,291.067,0,0,0.0102198995029309,17,0.000666573746458014,,3.42539214461236E-7,,65.8243661295906,,0.0338258046228792,,,,,,,,,,0,5000,-75.8796147274906,,-73.8330407507595,,0.000195797407550163,,0.000666574732451096,,,,,,,,,,,,,,,,,,,,,,,,,,,
,19110700.465,4370,293.55825,0,0,0.0102198995029309,17,0.000661754429587152,,3.44680453801793E-7,,65.3441020279781,,0.0340349840165243,,,,,,,,,,0,5000,-75.0476498721094,,-73.7382568260018,,0.000194354890905044,,0.000661755408180568,,,,,,,,,,,,,,,,,,,,,,,,,,,
,19110849.915,4370,296.05305,0,0,0.0102198995029309,17,0.000657008787888735,,3.40611524483762E-7,,64.8712424989152,,0.0336309964552537,,,,,,,,,,0,5000,-75.9954612720216,,-73.5580952543993,,0.00019269843176667,,0.000657009756820918,,,,,,,,,,,,,,,,,,,,,,,,,,,
,19110994.535,4370,298.46405,0,0,0.0102198995029309,17,0.000653737095980865,,3.44560521039888E-7,,64.5452846421763,,0.0340193704196069,,,,,,,,,,0,5000,-76.9245773651325,,-73.0094950075202,,0.000190811320706891,,0.000653738050782926,,,,,,,,,,,,,,,,,,,,,,,,,,,
,19111132.525,4370,300.76545,0,0,0.0102198995029309,17,0.000648297443578811,,3.39630895990676E-7,,64.0033986903732,,0.033530132931136,,,,,,,,,,0,5000,-76.4809961337604,,-73.5892804809246,,0.000190510481650914,,0.000648298403358685,,,,,,,,,,,,,,,,,,,,,,,,,,,
,19111270.75,4370,303.07365,0,0,0.0102198995029309,17,0.000644133106115704,,3.36273711586507E-7,,63.5886118286242,,0.0331967828614274,,,,,,,,,,0,5000,-76.4776904050642,,-73.9733608792515,,0.000189285913286296,,0.000644134059722125,,,,,,,,,,,,,,,,,,,,,,,,,,,
,19111407.395,4370,305.35645,0,0,0.0102198995029309,17,0.00064004266262116,,3.40638361417193E-7,,63.1812316346631,,0.0336257586855003,,,,,,,,,,0,5000,-75.6348859422256,,-73.2626067307256,,0.000185804827145632,,0.000640043587347584,,,,,,,,,,,,,,,,,,,,,,,,,,,
,19111545.22,4370,307.6543,0,0,0.0102198995029309,17,0.000636181660162161,,3.34994425425653E-7,,62.7967444648386,,0.0330668576852642,,,,,,,,,,0,5000,-75.8078972125533,,-72.8688768539853,,0.000186253251217625,,0.000636182594996766,,,,,,,,,,,,,,,,,,,,,,,,,,,
,19111701.705,4370,310.2702,0,0,0.0102198995029309,17,0.000631542531253008,,3.3148354518355E-7,,62.3348240203925,,0.0327182052910093,,,,,,,,,,0,5000,-75.3441923272377,,-73.1197747656038,,0.000184602724199113,,0.000631543456338371,,,,,,,,,,,,,,,,,,,,,,,,,,,
,19111845.93,4370,312.66405,0,0,0.0102198995029309,17,0.000627418740840367,,3.26618350502996E-7,,61.924265827065,,0.0322361614205825,,,,,,,,,,0,5000,-75.3292581388062,,-73.3343589355344,,0.000183787019057902,,0.000627419663795057,,,,,,,,,,,,,,,,,,,,,,,,,,,
,19111988.86,4370,315.0561,0,0,0.0102198995029309,17,0.000623436955075541,,3.28795285789717E-7,,61.5278898069349,,0.0324492315400388,,,,,,,,,,0,5000,-76.3075772933115,,-72.9627297284916,,0.000183380450725182,,0.000623437879819977,,,,,,,,,,,,,,,,,,,,,,,,,,,
,19112150.79,4370,317.7591,0,0,0.0102198995029309,17,0.000619005259879225,,3.22445372014527E-7,,61.0867778147534,,0.0318206016354627,,,,,,,,,,0,5000,-75.2880658665732,,-73.5725217344759,,0.000181440195042353,,0.000619006171639925,,,,,,,,,,,,,,,,,,,,,,,,,,,
,19112293.82,4370,320.14645,0,0,0.0102198995029309,17,0.000615115760475254,,3.22726808207592E-7,,60.6996781931526,,0.0318466639799667,,,,,,,,,,0,5000,-75.7696142829039,,-73.9457581971715,,0.000179095664208324,,0.000615116654442266,,,,,,,,,,,,,,,,,,,,,,,,,,,
,19112444.165,4370,322.65315,0,0,0.0102198995029309,17,0.00061113732026241,,3.2020187616982E-7,,60.3037698515657,,0.0315957659446417,,,,,,,,,,0,5000,-75.8362995384727,,-73.4933861665361,,0.000179366627359879,,0.000611138222773771,,,,,,,,,,,,,,,,,,,,,,,,,,,
,19112605.885,4370,325.3565,0,0,0.0102198995029309,17,0.000606911051558504,,3.22800894009209E-7,,59.8832469209343,,0.0318503636687994,,,,,,,,,,0,5000,-75.5517133879348,,-73.186950517414,,0.000176209552000744,,0.000606911928644251,,,,,,,,,,,,,,,,,,,,,,,,,,,
,19112750.345,4370,327.75795,0,0,0.0102198995029309,17,0.000603201515448371,,3.18335264114883E-7,,59.5141804804634,,0.0314081353365884,,,,,,,,,,0,5000,-75.8546502603792,,-73.5722091345446,,0.000175612060674173,,0.000603202391953493,,,,,,,,,,,,,,,,,,,,,,,,,,,
,19112893.985,4370,330.1576,0,0,0.0102198995029309,17,0.00059956852687865,,3.21251963739397E-7,,59.152766520167,,0.0316943165363128,,,,,,,,,,0,5000,-76.1956041398753,,-73.5145743575784,,0.000174921282365027,,0.000599569401771124,,,,,,,,,,,,,,,,,,,,,,,,,,,
,19113042.765,4370,332.64255,0,0,0.0102198995029309,17,0.000595851051871804,,3.15935957920686E-7,,58.7829853062074,,0.0311682461397882,,,,,,,,,,0,5000,-74.9788220009363,,-73.67968503166,,0.000171982523666056,,0.000595851902890564,,,,,,,,,,,,,,,,,,,,,,,,,,,
,19113181.365,4370,334.954,0,0,0.0102198995029309,17,0.000592465132044381,,3.13806424362542E-7,,58.4462172923389,,0.0309567101032625,,,,,,,,,,0,5000,-75.6289666173107,,-73.0359408507551,,0.000174020763717508,,0.00059246600833375,,,,,,,,,,,,,,,,,,,,,,,,,,,
,19113337.12,4370,337.5542,0,0,0.0102198995029309,17,0.000588656494150895,,3.07919086686275E-7,,58.0674428365382,,0.0303743324089968,,,,,,,,,,0,5000,-76.3281936859219,,-73.5040632540468,,0.000171229338899879,,0.000588657348042266,,,,,,,,,,,,,,,,,,,,,,,,,,,
,19113481.085,4370,339.9447,0,0,0.0102198995029309,17,0.000585234407251322,,3.10362315583829E-7,,57.7271454204945,,0.0306138943920033,,,,,,,,,,0,5000,-75.3635113481641,,-73.1441086165401,,0.000170879912502579,,0.000585235262633853,,,,,,,,,,,,,,,,,,,,,,,,,,,
,19113637.205,4370,342.5572,0,0,0.0102198995029309,17,0.000581525365872562,,3.02348808967705E-7,,57.3583491549239,,0.0298219203930475,,,,,,,,,,0,5000,-75.9886073979253,,-73.8177368257073,,0.000169918383019955,,0.00058152621705033,,,,,,,,,,,,,,,,,,,,,,,,,,,
,19113787.86,4370,345.05755,0,0,0.0102198995029309,17,0.000578078340228383,,3.05367244818611E-7,,57.0156394352768,,0.030118208272405,,,,,,,,,,0,5000,-75.6710569715969,,-73.0665090378449,,0.000166887977956834,,0.00057807916621235,,,,,,,,,,,,,,,,,,,,,,,,,,,
,19113942.85,4370,347.661,0,0,0.0102198995029309,17,0.000574519090076542,,3.07547870940314E-7,,56.6618063891104,,0.0303317912275765,,,,,,,,,,0,5000,-75.7249333165203,,-73.4403797985351,,0.000165603208012397,,0.000574519908430594,,,,,,,,,,,,,,,,,,,,,,,,,,,
,19114086.75,4370,350.0515,0,0,0.0102198995029309,17,0.000571218227556613,,3.03567758802379E-7,,56.3336913278708,,0.029937888433982,,,,,,,,,,0,5000,-75.3985177234262,,-73.5518998456664,,0.000166314235308888,,0.000571219057722709,,,,,,,,,,,,,,,,,,,,,,,,,,,